Workbook

Sheet Summary
A1: Greyhaven PB-4 Bore Release Decision
A2: For Blackmarsh Regional Office quality board | Tuesday review 2026-06-16 09:00
A4: PROVISIONAL DETERMINATION
A5: Most-likely cause: Second-shift gauge technique (GM-22 single-sweep handling).
A6: Moderate, provisional confidence. The evidence aligns all four explanations with the timing; it does not prove causation or replace a formal measurement-system study.
A8: What the source records show
A9: Item | B9: Value | C9: Unit | D9: Evidence
A10: Second-shift change | B10: =Model!C32 -> 0.03 | C10: mm | D10: E01
A11: First-shift change | B11: =Model!C31 -> 0.001 | C11: mm | D11: E01
A12: W6 shift gap | B12: =Model!C33 -> 0.035 | C12: mm | D12: E01
A13: Bore specification | B13: LSL 49.960 | USL 50.040 | C13: mm | D13: E02
A14: Why technique leads | B14: GM-22 technique difference is documented; no commanded offset change or corresponding first-shift rise. | C14: Interpretation | D14: E04; E12; E14
A15: Why not proven | B15: Fixture use, new MM-204, and night ambient each track the period; screening is not a completed study. | C15: Limitation | D15: E05; E08; E10; E13
A17: One containment recommended for the pending shipment
A18: Independent verification gate
A19: Measure 50 pending H-0624 parts independently before release. This protects shipment quality even if the provisional cause is wrong; it also directly counters the selected technique risk.
A20: Cost: | B20: =Model!E53 -> 405 | C20: USD | D20: within $600.00 budget | E20: Completion: | F20: =Model!H53 -> 46190.625 | G20: before 2026-06-18 17:00 cutoff
A22: One field-ready disconfirming check
A23: Check: Independent paired remeasurement of 20 H-0624 second-shift parts.
A24: Sample | B24: 20 of the 60 H-0624 second-shift parts; retain identifiers for paired comparison. | C24: E17
A25: Comparison | B25: Compare recorded GM-22 values with blinded SB-09 measurements using the standardized three-point hold. | C25: E12; E14; E17
A26: Decision threshold | B26: Disconfirm gauge-technique cause if mean (GM-22 recorded - SB-09 independent) is less than +0.018 mm. This is half of the W6 shift gap, rounded to 0.001 mm gauge resolution. | C26: E01; E03; E19
A27: Owner and timing | B27: Quality Technician completes by 2026-06-17 12:00, before shipment cutoff. | C27: E15; E17
A28: Consequence | B28: If disconfirmed, keep the independent verification gate for release, do not attribute the trend to technique, and reprioritize fixture, material, and ambient causes for the board. | C28: E16; E18
A30: Sources and assumptions: blue/green sections quote or derive supplied records; yellow text marks the decision rule and uncertainty. See Evidence keys for tab and record locators; Model retains the cleaned population and formulas.

Sheet Evidence
A1: Evidence | claim-to-source locator
A2: Use the key in Summary or Model to retrieve the source record. Source text is paraphrased only where marked as an interpretation.
A4: Key | B4: Claim / value used | C4: Source tab | D4: Record-level locator | E4: Classification | F4: Source-grounded detail
A5: E01 | B5: 300 valid production readings; six W1-W6 weeks and source shifts | C5: Bore Measurement Export | D5: ProductionBoreReadings A5:L304; Reading IDs BR-001 to BR-300 | E5: Sourced fact | F5: Adjacent visitor log M5:P9 excluded; Week and Shift are source fields; stale helper omitted.
A6: E02 | B6: USL 50.040 mm; LSL 49.960 mm | C6: Shift & Process Log | D6: Cell A18 | E6: Sourced fact | F6: Job traveler specification.
A7: E03 | B7: Gauge display resolution 0.001 mm | C7: Shift & Process Log | D7: Cell A18 | E7: Sourced fact | F7: Job traveler specification.
A8: E04 | B8: No commanded offset changes | C8: Shift & Process Log | D8: SP-01A through SP-06B, rows 5:16 | E8: Sourced fact | F8: Both shift entries state 0.000 mm.
A9: E05 | B9: FX-B cycles increase 840 to 1,090 | C9: Material & Fixture History | D9: FH-01 through FH-06, rows 8:13 | E9: Sourced fact | F9: Second shift / FX-B weekly history.
A10: E06 | B10: FX-B mandatory service not overdue and visual inspection passed | C10: Material & Fixture History | D10: FH-01 through FH-06, rows 8:13 | E10: Sourced fact | F10: Weakening evidence for wear.
A11: E07 | B11: FX-A history has no matching second-shift condition | C11: Material & Fixture History | D11: FH-07, row 14 | E11: Sourced fact | F11: First shift / FX-A history.
A12: E08 | B12: New Meridian MM-204 used second shift from W3 | C12: Material & Fixture History | D12: MH-03, row 7; measurement records BR-101:BR-300 | E12: Sourced fact | F12: Explicit interval and material lot identifiers.
A13: E09 | B13: MM-204 incoming chemistry and acceptance within internal statement | C13: Material & Fixture History | D13: MH-03, row 7 | E13: Sourced fact | F13: Does not eliminate machinability effect.
A14: E10 | B14: Second-shift ambient rises 19 C to 24 C | C14: Environment & Gauge Obs | D14: EN-01B through EN-06B, rows 6,8,10,12,14,16 | E14: Sourced fact | F14: Date-range/shift matched ambient entries.
A15: E11 | B15: Facility operating band 18 C to 26 C | C15: Environment & Gauge Obs | D15: EN-01A through EN-06B, rows 5:16 | E15: Sourced fact | F15: All listed readings are in band.
... A23: E19 | B23: Check threshold equals half W6 shift gap, rounded to 0.001 mm | C23: Model | D23: Trend measures row 36 | E23: Assumption / derived rule | F23: Source-derived comparator; no external limit.

Sheet Model
A1: Model | PB-4 bore review
A2: Sourced facts are blue; assumptions and decision rules are yellow. All derived measures recompute from the 300 rows below.
A4: Source controls and recomputed scope
A5: Control | B5: Value | C5: Unit / status | D5: Evidence key
A6: Valid production-reading count | B6: =COUNTA(AE8:AE307) -> 300 | C6: records | D6: E01
A7: Distinct reading IDs | B7: =SUMPRODUCT(1/COUNTIF(AE8:AE307,AE8:AE307)) -> 300 | C7: records | D7: E01 | AE7: Reading ID | AF7: Date | AG7: Week (recomputed) | AH7: Shift | AI7: Lot | AJ7: Part ID | AK7: Fixture | AL7: Material Lot | AM7: Gauge | AN7: Measured Bore | AO7: Unit
A8: USL | B8: 50.04 | C8: mm | D8: E02 | AE8: BR-001 | AF8: 46146 | AG8: ="W"&INT((AF8-MIN($AF$8:$AF$307))/7)+1 -> W1 | AH8: First | AI8: PB-01-F | AJ8: P1F01 | AK8: FX-A | AL8: CL-771 | AM8: GM-17 | AN8: 49.992 | AO8: mm
A9: LSL | B9: 49.96 | C9: mm | D9: E02 | AE9: BR-002 | AF9: 46147 | AG9: ="W"&INT((AF9-MIN($AF$8:$AF$307))/7)+1 -> W1 | AH9: First | AI9: PB-01-F | AJ9: P1F02 | AK9: FX-A | AL9: CL-771 | AM9: GM-17 | AN9: 49.993 | AO9: mm
A10: Gauge resolution | B10: 0.001 | C10: mm | D10: E03 | AE10: BR-003 | AF10: 46148 | AG10: ="W"&INT((AF10-MIN($AF$8:$AF$307))/7)+1 -> W1 | AH10: First | AI10: PB-01-F | AJ10: P1F03 | AK10: FX-A | AL10: CL-771 | AM10: GM-17 | AN10: 49.994 | AO10: mm
A11: Weeks modeled | B11: 6 (W1-W6 from Date; retired helper excluded) | C11: weeks | D11: E01 | AE11: BR-004 | AF11: 46149 | AG11: ="W"&INT((AF11-MIN($AF$8:$AF$307))/7)+1 -> W1 | AH11: First | AI11: PB-01-F | AJ11: P1F04 | AK11: FX-A | AL11: CL-771 | AM11: GM-17 | AN11: 49.995 | AO11: mm
A12: Shifts modeled | B12: First; Second (source Shift field) | C12: categories | D12: E01 | AE12: BR-005 | AF12: 46150 | AG12: ="W"&INT((AF12-MIN($AF$8:$AF$307))/7)+1 -> W1 | AH12: First | AI12: PB-01-F | AJ12: P1F05 | AK12: FX-A | AL12: CL-771 | AM12: GM-17 | AN12: 49.996 | AO12: mm
AE13: BR-006 | AF13: 46146 | AG13: ="W"&INT((AF13-MIN($AF$8:$AF$307))/7)+1 -> W1 | AH13: First | AI13: PB-01-F | AJ13: P1F06 | AK13: FX-A | AL13: CL-771 | AM13: GM-17 | AN13: 49.997 | AO13: mm
A14: Weekly bore statistics (derived from cleaned source population) | AE14: BR-007 | AF14: 46147 | AG14: ="W"&INT((AF14-MIN($AF$8:$AF$307))/7)+1 -> W1 | AH14: First | AI14: PB-01-F | AJ14: P1F07 | AK14: FX-A | AL14: CL-771 | AM14: GM-17 | AN14: 49.998 | AO14: mm
A15: Week | B15: Shift | C15: n | D15: Mean bore (mm) | E15: Min (mm) | F15: Max (mm) | G15: Sample SD (mm) | H15: Distance to USL (mm) | I15: Above USL (n) | J15: Below LSL (n) | K15: Material lot | L15: Fixture | AE15: BR-008 | AF15: 46148 | AG15: ="W"&INT((AF15-MIN($AF$8:$AF$307))/7)+1 -> W1 | AH15: First | AI15: PB-01-F | AJ15: P1F08 | AK15: FX-A | AL15: CL-771 | AM15: GM-17 | AN15: 49.999 | AO15: mm
A16: W1 | B16: First | C16: =COUNTIFS($AG$8:$AG$307,A16,$AH$8:$AH$307,B16) -> 25 | D16: =AVERAGEIFS($AN$8:$AN$307,$AG$8:$AG$307,A16,$AH$8:$AH$307,B16) -> 49.9976 | E16: =MIN(IF(($AG$8:$AG$307=A16)*($AH$8:$AH$307=B16),$AN$8:$AN$307)) -> 49.992 | F16: =MAX(IF(($AG$8:$AG$307=A16)*($AH$8:$AH$307=B16),$AN$8:$AN$307)) -> 50.039 | G16: =SQRT(SUMPRODUCT(($AG$8:$AG$307=A16)*($AH$8:$AH$307=B16)*($AN$8:$AN$307-D16)^2)/(C16-1)) -> 0.0034880749 | H16: =$B$8-D16 -> 0.0424 | I16: =COUNTIFS($AG$8:$AG$307,A16,$AH$8:$AH$307,B16,$AN$8:$AN$307,">"&$B$8) -> 0 | J16: =COUNTIFS($AG$8:$AG$307,A16,$AH$8:$AH$307,B16,$AN$8:$AN$307,"<"&$B$9) -> 0 | K16: =INDEX($AL$8:$AL$307,MATCH(1,($AG$8:$AG$307=A16)*($AH$8:$AH$307=B16),0)) -> CL-771 | L16: =INDEX($AK$8:$AK$307,MATCH(1,($AG$8:$AG$307=A16)*($AH$8:$AH$307=B16),0)) -> FX-A | AE16: BR-009 | AF16: 46149 | AG16: ="W"&INT((AF16-MIN($AF$8:$AF$307))/7)+1 -> W1 | AH16: First | AI16: PB-01-F | AJ16: P1F09 | AK16: FX-A | AL16: CL-771 | AM16: GM-17 | AN16: 50 | AO16: mm
A17: W1 | B17: Second | C17: =COUNTIFS($AG$8:$AG$307,A17,$AH$8:$AH$307,B17) -> 25 | D17: =AVERAGEIFS($AN$8:$AN$307,$AG$8:$AG$307,A17,$AH$8:$AH$307,B17) -> 50.0036 | E17: =MIN(IF(($AG$8:$AG$307=A17)*($AH$8:$AH$307=B17),$AN$8:$AN$307)) -> 0 | F17: =MAX(IF(($AG$8:$AG$307=A17)*($AH$8:$AH$307=B17),$AN$8:$AN$307)) -> 0 | G17: =SQRT(SUMPRODUCT(($AG$8:$AG$307=A17)*($AH$8:$AH$307=B17)*($AN$8:$AN$307-D17)^2)/(C17-1)) -> 0.0034880749 | H17: =$B$8-D17 -> 0.0364 | I17: =COUNTIFS($AG$8:$AG$307,A17,$AH$8:$AH$307,B17,$AN$8:$AN$307,">"&$B$8) -> 0 | J17: =COUNTIFS($AG$8:$AG$307,A17,$AH$8:$AH$307,B17,$AN$8:$AN$307,"<"&$B$9) -> 0 | K17: =INDEX($AL$8:$AL$307,MATCH(1,($AG$8:$AG$307=A17)*($AH$8:$AH$307=B17),0)) -> CL-771 | L17: =INDEX($AK$8:$AK$307,MATCH(1,($AG$8:$AG$307=A17)*($AH$8:$AH$307=B17),0)) -> FX-B | AE17: BR-010 | AF17: 46150 | AG17: ="W"&INT((AF17-MIN($AF$8:$AF$307))/7)+1 -> W1 | AH17: First | AI17: PB-01-F | AJ17: P1F10 | AK17: FX-A | AL17: CL-771 | AM17: GM-17 | AN17: 50.001 | AO17: mm
A18: W2 | B18: First | C18: =COUNTIFS($AG$8:$AG$307,A18,$AH$8:$AH$307,B18) -> 25 | D18: =AVERAGEIFS($AN$8:$AN$307,$AG$8:$AG$307,A18,$AH$8:$AH$307,B18) -> 49.9986 | E18: =MIN(IF(($AG$8:$AG$307=A18)*($AH$8:$AH$307=B18),$AN$8:$AN$307)) -> 0 | F18: =MAX(IF(($AG$8:$AG$307=A18)*($AH$8:$AH$307=B18),$AN$8:$AN$307)) -> 0 | G18: =SQRT(SUMPRODUCT(($AG$8:$AG$307=A18)*($AH$8:$AH$307=B18)*($AN$8:$AN$307-D18)^2)/(C18-1)) -> 0.0034880749 | H18: =$B$8-D18 -> 0.0414 | I18: =COUNTIFS($AG$8:$AG$307,A18,$AH$8:$AH$307,B18,$AN$8:$AN$307,">"&$B$8) -> 0 | J18: =COUNTIFS($AG$8:$AG$307,A18,$AH$8:$AH$307,B18,$AN$8:$AN$307,"<"&$B$9) -> 0 | K18: =INDEX($AL$8:$AL$307,MATCH(1,($AG$8:$AG$307=A18)*($AH$8:$AH$307=B18),0)) -> CL-771 | L18: =INDEX($AK$8:$AK$307,MATCH(1,($AG$8:$AG$307=A18)*($AH$8:$AH$307=B18),0)) -> FX-A | AE18: BR-011 | AF18: 46146 | AG18: ="W"&INT((AF18-MIN($AF$8:$AF$307))/7)+1 -> W1 | AH18: First | AI18: PB-01-F | AJ18: P1F11 | AK18: FX-A | AL18: CL-771 | AM18: GM-17 | AN18: 50.002 | AO18: mm
A19: W2 | B19: Second | C19: =COUNTIFS($AG$8:$AG$307,A19,$AH$8:$AH$307,B19) -> 25 | D19: =AVERAGEIFS($AN$8:$AN$307,$AG$8:$AG$307,A19,$AH$8:$AH$307,B19) -> 50.0096 | E19: =MIN(IF(($AG$8:$AG$307=A19)*($AH$8:$AH$307=B19),$AN$8:$AN$307)) -> 0 | F19: =MAX(IF(($AG$8:$AG$307=A19)*($AH$8:$AH$307=B19),$AN$8:$AN$307)) -> 0 | G19: =SQRT(SUMPRODUCT(($AG$8:$AG$307=A19)*($AH$8:$AH$307=B19)*($AN$8:$AN$307-D19)^2)/(C19-1)) -> 0.0034880749 | H19: =$B$8-D19 -> 0.0304 | I19: =COUNTIFS($AG$8:$AG$307,A19,$AH$8:$AH$307,B19,$AN$8:$AN$307,">"&$B$8) -> 0 | J19: =COUNTIFS($AG$8:$AG$307,A19,$AH$8:$AH$307,B19,$AN$8:$AN$307,"<"&$B$9) -> 0 | K19: =INDEX($AL$8:$AL$307,MATCH(1,($AG$8:$AG$307=A19)*($AH$8:$AH$307=B19),0)) -> CL-771 | L19: =INDEX($AK$8:$AK$307,MATCH(1,($AG$8:$AG$307=A19)*($AH$8:$AH$307=B19),0)) -> FX-B | AE19: BR-012 | AF19: 46147 | AG19: ="W"&INT((AF19-MIN($AF$8:$AF$307))/7)+1 -> W1 | AH19: First | AI19: PB-01-F | AJ19: P1F12 | AK19: FX-A | AL19: CL-771 | AM19: GM-17 | AN19: 50.003 | AO19: mm
A20: W3 | B20: First | C20: =COUNTIFS($AG$8:$AG$307,A20,$AH$8:$AH$307,B20) -> 25 | D20: =AVERAGEIFS($AN$8:$AN$307,$AG$8:$AG$307,A20,$AH$8:$AH$307,B20) -> 49.9976 | E20: =MIN(IF(($AG$8:$AG$307=A20)*($AH$8:$AH$307=B20),$AN$8:$AN$307)) -> 0 | F20: =MAX(IF(($AG$8:$AG$307=A20)*($AH$8:$AH$307=B20),$AN$8:$AN$307)) -> 0 | G20: =SQRT(SUMPRODUCT(($AG$8:$AG$307=A20)*($AH$8:$AH$307=B20)*($AN$8:$AN$307-D20)^2)/(C20-1)) -> 0.0034880749 | H20: =$B$8-D20 -> 0.0424 | I20: =COUNTIFS($AG$8:$AG$307,A20,$AH$8:$AH$307,B20,$AN$8:$AN$307,">"&$B$8) -> 0 | J20: =COUNTIFS($AG$8:$AG$307,A20,$AH$8:$AH$307,B20,$AN$8:$AN$307,"<"&$B$9) -> 0 | K20: =INDEX($AL$8:$AL$307,MATCH(1,($AG$8:$AG$307=A20)*($AH$8:$AH$307=B20),0)) -> CL-772 | L20: =INDEX($AK$8:$AK$307,MATCH(1,($AG$8:$AG$307=A20)*($AH$8:$AH$307=B20),0)) -> FX-A | AE20: BR-013 | AF20: 46148 | AG20: ="W"&INT((AF20-MIN($AF$8:$AF$307))/7)+1 -> W1 | AH20: First | AI20: PB-01-F | AJ20: P1F13 | AK20: FX-A | AL20: CL-771 | AM20: GM-17 | AN20: 49.992 | AO20: mm
A21: W3 | B21: Second | C21: =COUNTIFS($AG$8:$AG$307,A21,$AH$8:$AH$307,B21) -> 25 | D21: =AVERAGEIFS($AN$8:$AN$307,$AG$8:$AG$307,A21,$AH$8:$AH$307,B21) -> 50.0156 | E21: =MIN(IF(($AG$8:$AG$307=A21)*($AH$8:$AH$307=B21),$AN$8:$AN$307)) -> 0 | F21: =MAX(IF(($AG$8:$AG$307=A21)*($AH$8:$AH$307=B21),$AN$8:$AN$307)) -> 0 | G21: =SQRT(SUMPRODUCT(($AG$8:$AG$307=A21)*($AH$8:$AH$307=B21)*($AN$8:$AN$307-D21)^2)/(C21-1)) -> 0.0034880749 | H21: =$B$8-D21 -> 0.0244 | I21: =COUNTIFS($AG$8:$AG$307,A21,$AH$8:$AH$307,B21,$AN$8:$AN$307,">"&$B$8) -> 0 | J21: =COUNTIFS($AG$8:$AG$307,A21,$AH$8:$AH$307,B21,$AN$8:$AN$307,"<"&$B$9) -> 0 | K21: =INDEX($AL$8:$AL$307,MATCH(1,($AG$8:$AG$307=A21)*($AH$8:$AH$307=B21),0)) -> MM-204 | L21: =INDEX($AK$8:$AK$307,MATCH(1,($AG$8:$AG$307=A21)*($AH$8:$AH$307=B21),0)) -> FX-B | AE21: BR-014 | AF21: 46149 | AG21: ="W"&INT((AF21-MIN($AF$8:$AF$307))/7)+1 -> W1 | AH21: First | AI21: PB-01-F | AJ21: P1F14 | AK21: FX-A | AL21: CL-771 | AM21: GM-17 | AN21: 49.993 | AO21: mm
A22: W4 | B22: First | C22: =COUNTIFS($AG$8:$AG$307,A22,$AH$8:$AH$307,B22) -> 25 | D22: =AVERAGEIFS($AN$8:$AN$307,$AG$8:$AG$307,A22,$AH$8:$AH$307,B22) -> 49.9986 | E22: =MIN(IF(($AG$8:$AG$307=A22)*($AH$8:$AH$307=B22),$AN$8:$AN$307)) -> 0 | F22: =MAX(IF(($AG$8:$AG$307=A22)*($AH$8:$AH$307=B22),$AN$8:$AN$307)) -> 0 | G22: =SQRT(SUMPRODUCT(($AG$8:$AG$307=A22)*($AH$8:$AH$307=B22)*($AN$8:$AN$307-D22)^2)/(C22-1)) -> 0.0034880749 | H22: =$B$8-D22 -> 0.0414 | I22: =COUNTIFS($AG$8:$AG$307,A22,$AH$8:$AH$307,B22,$AN$8:$AN$307,">"&$B$8) -> 0 | J22: =COUNTIFS($AG$8:$AG$307,A22,$AH$8:$AH$307,B22,$AN$8:$AN$307,"<"&$B$9) -> 0 | K22: =INDEX($AL$8:$AL$307,MATCH(1,($AG$8:$AG$307=A22)*($AH$8:$AH$307=B22),0)) -> CL-772 | L22: =INDEX($AK$8:$AK$307,MATCH(1,($AG$8:$AG$307=A22)*($AH$8:$AH$307=B22),0)) -> FX-A | AE22: BR-015 | AF22: 46150 | AG22: ="W"&INT((AF22-MIN($AF$8:$AF$307))/7)+1 -> W1 | AH22: First | AI22: PB-01-F | AJ22: P1F15 | AK22: FX-A | AL22: CL-771 | AM22: GM-17 | AN22: 49.994 | AO22: mm
A23: W4 | B23: Second | C23: =COUNTIFS($AG$8:$AG$307,A23,$AH$8:$AH$307,B23) -> 25 | D23: =AVERAGEIFS($AN$8:$AN$307,$AG$8:$AG$307,A23,$AH$8:$AH$307,B23) -> 50.0216 | E23: =MIN(IF(($AG$8:$AG$307=A23)*($AH$8:$AH$307=B23),$AN$8:$AN$307)) -> 0 | F23: =MAX(IF(($AG$8:$AG$307=A23)*($AH$8:$AH$307=B23),$AN$8:$AN$307)) -> 0 | G23: =SQRT(SUMPRODUCT(($AG$8:$AG$307=A23)*($AH$8:$AH$307=B23)*($AN$8:$AN$307-D23)^2)/(C23-1)) -> 0.0034880749 | H23: =$B$8-D23 -> 0.0184 | I23: =COUNTIFS($AG$8:$AG$307,A23,$AH$8:$AH$307,B23,$AN$8:$AN$307,">"&$B$8) -> 0 | J23: =COUNTIFS($AG$8:$AG$307,A23,$AH$8:$AH$307,B23,$AN$8:$AN$307,"<"&$B$9) -> 0 | K23: =INDEX($AL$8:$AL$307,MATCH(1,($AG$8:$AG$307=A23)*($AH$8:$AH$307=B23),0)) -> MM-204 | L23: =INDEX($AK$8:$AK$307,MATCH(1,($AG$8:$AG$307=A23)*($AH$8:$AH$307=B23),0)) -> FX-B | AE23: BR-016 | AF23: 46146 | AG23: ="W"&INT((AF23-MIN($AF$8:$AF$307))/7)+1 -> W1 | AH23: First | AI23: PB-01-F | AJ23: P1F16 | AK23: FX-A | AL23: CL-771 | AM23: GM-17 | AN23: 49.995 | AO23: mm
A24: W5 | B24: First | C24: =COUNTIFS($AG$8:$AG$307,A24,$AH$8:$AH$307,B24) -> 25 | D24: =AVERAGEIFS($AN$8:$AN$307,$AG$8:$AG$307,A24,$AH$8:$AH$307,B24) -> 49.9976 | E24: =MIN(IF(($AG$8:$AG$307=A24)*($AH$8:$AH$307=B24),$AN$8:$AN$307)) -> 0 | F24: =MAX(IF(($AG$8:$AG$307=A24)*($AH$8:$AH$307=B24),$AN$8:$AN$307)) -> 0 | G24: =SQRT(SUMPRODUCT(($AG$8:$AG$307=A24)*($AH$8:$AH$307=B24)*($AN$8:$AN$307-D24)^2)/(C24-1)) -> 0.0034880749 | H24: =$B$8-D24 -> 0.0424 | I24: =COUNTIFS($AG$8:$AG$307,A24,$AH$8:$AH$307,B24,$AN$8:$AN$307,">"&$B$8) -> 0 | J24: =COUNTIFS($AG$8:$AG$307,A24,$AH$8:$AH$307,B24,$AN$8:$AN$307,"<"&$B$9) -> 0 | K24: =INDEX($AL$8:$AL$307,MATCH(1,($AG$8:$AG$307=A24)*($AH$8:$AH$307=B24),0)) -> CL-772 | L24: =INDEX($AK$8:$AK$307,MATCH(1,($AG$8:$AG$307=A24)*($AH$8:$AH$307=B24),0)) -> FX-A | AE24: BR-017 | AF24: 46147 | AG24: ="W"&INT((AF24-MIN($AF$8:$AF$307))/7)+1 -> W1 | AH24: First | AI24: PB-01-F | AJ24: P1F17 | AK24: FX-A | AL24: CL-771 | AM24: GM-17 | AN24: 49.996 | AO24: mm
A25: W5 | B25: Second | C25: =COUNTIFS($AG$8:$AG$307,A25,$AH$8:$AH$307,B25) -> 25 | D25: =AVERAGEIFS($AN$8:$AN$307,$AG$8:$AG$307,A25,$AH$8:$AH$307,B25) -> 50.0276 | E25: =MIN(IF(($AG$8:$AG$307=A25)*($AH$8:$AH$307=B25),$AN$8:$AN$307)) -> 0 | F25: =MAX(IF(($AG$8:$AG$307=A25)*($AH$8:$AH$307=B25),$AN$8:$AN$307)) -> 0 | G25: =SQRT(SUMPRODUCT(($AG$8:$AG$307=A25)*($AH$8:$AH$307=B25)*($AN$8:$AN$307-D25)^2)/(C25-1)) -> 0.0034880749 | H25: =$B$8-D25 -> 0.0124 | I25: =COUNTIFS($AG$8:$AG$307,A25,$AH$8:$AH$307,B25,$AN$8:$AN$307,">"&$B$8) -> 0 | J25: =COUNTIFS($AG$8:$AG$307,A25,$AH$8:$AH$307,B25,$AN$8:$AN$307,"<"&$B$9) -> 0 | K25: =INDEX($AL$8:$AL$307,MATCH(1,($AG$8:$AG$307=A25)*($AH$8:$AH$307=B25),0)) -> MM-204 | L25: =INDEX($AK$8:$AK$307,MATCH(1,($AG$8:$AG$307=A25)*($AH$8:$AH$307=B25),0)) -> FX-B | AE25: BR-018 | AF25: 46148 | AG25: ="W"&INT((AF25-MIN($AF$8:$AF$307))/7)+1 -> W1 | AH25: First | AI25: PB-01-F | AJ25: P1F18 | AK25: FX-A | AL25: CL-771 | AM25: GM-17 | AN25: 49.997 | AO25: mm
A26: W6 | B26: First | C26: =COUNTIFS($AG$8:$AG$307,A26,$AH$8:$AH$307,B26) -> 25 | D26: =AVERAGEIFS($AN$8:$AN$307,$AG$8:$AG$307,A26,$AH$8:$AH$307,B26) -> 49.9986 | E26: =MIN(IF(($AG$8:$AG$307=A26)*($AH$8:$AH$307=B26),$AN$8:$AN$307)) -> 0 | F26: =MAX(IF(($AG$8:$AG$307=A26)*($AH$8:$AH$307=B26),$AN$8:$AN$307)) -> 0 | G26: =SQRT(SUMPRODUCT(($AG$8:$AG$307=A26)*($AH$8:$AH$307=B26)*($AN$8:$AN$307-D26)^2)/(C26-1)) -> 0.0034880749 | H26: =$B$8-D26 -> 0.0414 | I26: =COUNTIFS($AG$8:$AG$307,A26,$AH$8:$AH$307,B26,$AN$8:$AN$307,">"&$B$8) -> 0 | J26: =COUNTIFS($AG$8:$AG$307,A26,$AH$8:$AH$307,B26,$AN$8:$AN$307,"<"&$B$9) -> 0 | K26: =INDEX($AL$8:$AL$307,MATCH(1,($AG$8:$AG$307=A26)*($AH$8:$AH$307=B26),0)) -> CL-772 | L26: =INDEX($AK$8:$AK$307,MATCH(1,($AG$8:$AG$307=A26)*($AH$8:$AH$307=B26),0)) -> FX-A | AE26: BR-019 | AF26: 46149 | AG26: ="W"&INT((AF26-MIN($AF$8:$AF$307))/7)+1 -> W1 | AH26: First | AI26: PB-01-F | AJ26: P1F19 | AK26: FX-A | AL26: CL-771 | AM26: GM-17 | AN26: 49.998 | AO26: mm
A27: W6 | B27: Second | C27: =COUNTIFS($AG$8:$AG$307,A27,$AH$8:$AH$307,B27) -> 25 | D27: =AVERAGEIFS($AN$8:$AN$307,$AG$8:$AG$307,A27,$AH$8:$AH$307,B27) -> 50.0336 | E27: =MIN(IF(($AG$8:$AG$307=A27)*($AH$8:$AH$307=B27),$AN$8:$AN$307)) -> 0 | F27: =MAX(IF(($AG$8:$AG$307=A27)*($AH$8:$AH$307=B27),$AN$8:$AN$307)) -> 0 | G27: =SQRT(SUMPRODUCT(($AG$8:$AG$307=A27)*($AH$8:$AH$307=B27)*($AN$8:$AN$307-D27)^2)/(C27-1)) -> 0.0034880749 | H27: =$B$8-D27 -> 0.0064 | I27: =COUNTIFS($AG$8:$AG$307,A27,$AH$8:$AH$307,B27,$AN$8:$AN$307,">"&$B$8) -> 0 | J27: =COUNTIFS($AG$8:$AG$307,A27,$AH$8:$AH$307,B27,$AN$8:$AN$307,"<"&$B$9) -> 0 | K27: =INDEX($AL$8:$AL$307,MATCH(1,($AG$8:$AG$307=A27)*($AH$8:$AH$307=B27),0)) -> MM-204 | L27: =INDEX($AK$8:$AK$307,MATCH(1,($AG$8:$AG$307=A27)*($AH$8:$AH$307=B27),0)) -> FX-B | AE27: BR-020 | AF27: 46150 | AG27: ="W"&INT((AF27-MIN($AF$8:$AF$307))/7)+1 -> W1 | AH27: First | AI27: PB-01-F | AJ27: P1F20 | AK27: FX-A | AL27: CL-771 | AM27: GM-17 | AN27: 49.999 | AO27: mm
AE28: BR-021 | AF28: 46146 | AG28: ="W"&INT((AF28-MIN($AF$8:$AF$307))/7)+1 -> W1 | AH28: First | AI28: PB-01-F | AJ28: P1F21 | AK28: FX-A | AL28: CL-771 | AM28: GM-17 | AN28: 50 | AO28: mm
A29: Trend measures and check-threshold derivation | AE29: BR-022 | AF29: 46147 | AG29: ="W"&INT((AF29-MIN($AF$8:$AF$307))/7)+1 -> W1 | AH29: First | AI29: PB-01-F | AJ29: P1F22 | AK29: FX-A | AL29: CL-771 | AM29: GM-17 | AN29: 50.001 | AO29: mm
A30: Measure | B30: Formula / rule | C30: Result | D30: Unit | E30: Evidence key | AE30: BR-023 | AF30: 46148 | AG30: ="W"&INT((AF30-MIN($AF$8:$AF$307))/7)+1 -> W1 | AH30: First | AI30: PB-01-F | AJ30: P1F23 | AK30: FX-A | AL30: CL-771 | AM30: GM-17 | AN30: 50.002 | AO30: mm
A31: Six-week First change | B31: W6 First mean - W1 First mean | C31: =D26-D16 -> 0.001 | D31: mm | E31: E01 | AE31: BR-024 | AF31: 46149 | AG31: ="W"&INT((AF31-MIN($AF$8:$AF$307))/7)+1 -> W1 | AH31: First | AI31: PB-01-F | AJ31: P1F24 | AK31: FX-A | AL31: CL-771 | AM31: GM-17 | AN31: 50.003 | AO31: mm
A32: Six-week Second change | B32: W6 Second mean - W1 Second mean | C32: =D27-D17 -> 0.03 | D32: mm | E32: E01 | AE32: BR-025 | AF32: 46150 | AG32: ="W"&INT((AF32-MIN($AF$8:$AF$307))/7)+1 -> W1 | AH32: First | AI32: PB-01-F | AJ32: P1F25 | AK32: FX-A | AL32: CL-771 | AM32: GM-17 | AN32: 50 | AO32: mm
A33: W6 shift gap | B33: W6 Second mean - W6 First mean | C33: =D27-D26 -> 0.035 | D33: mm | E33: E01 | AE33: BR-026 | AF33: 46146 | AG33: ="W"&INT((AF33-MIN($AF$8:$AF$307))/7)+1 -> W1 | AH33: Second | AI33: PB-01-S | AJ33: P1S01 | AK33: FX-B | AL33: CL-771 | AM33: GM-22 | AN33: 49.998 | AO33: mm
A34: First weekly slope | B34: Least-squares slope for six ordered weekly means | C34: =(-2.5*D16-1.5*D18-0.5*D20+0.5*D22+1.5*D24+2.5*D26)/17.5 -> 8.5714286e-05 | D34: mm/week | E34: E01 | AE34: BR-027 | AF34: 46147 | AG34: ="W"&INT((AF34-MIN($AF$8:$AF$307))/7)+1 -> W1 | AH34: Second | AI34: PB-01-S | AJ34: P1S02 | AK34: FX-B | AL34: CL-771 | AM34: GM-22 | AN34: 49.999 | AO34: mm
A35: Second weekly slope | B35: Least-squares slope for six ordered weekly means | C35: =(-2.5*D17-1.5*D19-0.5*D21+0.5*D23+1.5*D25+2.5*D27)/17.5 -> 0.006 | D35: mm/week | E35: E01 | AE35: BR-028 | AF35: 46148 | AG35: ="W"&INT((AF35-MIN($AF$8:$AF$307))/7)+1 -> W1 | AH35: Second | AI35: PB-01-S | AJ35: P1S03 | AK35: FX-B | AL35: CL-771 | AM35: GM-22 | AN35: 50 | AO35: mm
A36: Check threshold | B36: ASSUMPTION: half of W6 shift gap, rounded to source gauge resolution | C36: =ROUND(C33/2/$B$10,0)*$B$10 -> 0.018 | D36: mm | E36: E01; E03 | AE36: BR-029 | AF36: 46149 | AG36: ="W"&INT((AF36-MIN($AF$8:$AF$307))/7)+1 -> W1 | AH36: Second | AI36: PB-01-S | AJ36: P1S04 | AK36: FX-B | AL36: CL-771 | AM36: GM-22 | AN36: 50.001 | AO36: mm
AE37: BR-030 | AF37: 46150 | AG37: ="W"&INT((AF37-MIN($AF$8:$AF$307))/7)+1 -> W1 | AH37: Second | AI37: PB-01-S | AJ37: P1S05 | AK37: FX-B | AL37: CL-771 | AM37: GM-22 | AN37: 50.002 | AO37: mm
A38: Hypothesis comparison (source facts vs. provisional decision rule) | AE38: BR-031 | AF38: 46146 | AG38: ="W"&INT((AF38-MIN($AF$8:$AF$307))/7)+1 -> W1 | AH38: Second | AI38: PB-01-S | AJ38: P1S06 | AK38: FX-B | AL38: CL-771 | AM38: GM-22 | AN38: 50.003 | AO38: mm
A39: Candidate cause | B39: Supporting sourced fact | C39: Weakening sourced fact | D39: Separate criterion score | E39: Why it remains live | F39: Evidence keys | H39: Decision rule (assumption) | AE39: BR-032 | AF39: 46147 | AG39: ="W"&INT((AF39-MIN($AF$8:$AF$307))/7)+1 -> W1 | AH39: Second | AI39: PB-01-S | AJ39: P1S07 | AK39: FX-B | AL39: CL-771 | AM39: GM-22 | AN39: 50.004 | AO39: mm
A40: Fixture wear | B40: FX-B cycles rise 840 to 1,090 during second-shift drift. | C40: Mandatory service was not overdue and visual inspection passed; FX-A has no comparable rise. | D40: =1+1 -> 2 | E40: Temporal fit; direct physical path remains untested. | F40: E05; E06; E07 | H40: Score = 1 per independently stated supporting fact, plus 1 only where source directly documents shift-specific technique / no competing offset record. Equal weighting; not a causal probability. | AE40: BR-033 | AF40: 46148 | AG40: ="W"&INT((AF40-MIN($AF$8:$AF$307))/7)+1 -> W1 | AH40: Second | AI40: PB-01-S | AJ40: P1S08 | AK40: FX-B | AL40: CL-771 | AM40: GM-22 | AN40: 50.005 | AO40: mm
A41: Recent coil-supplier change | B41: MM-204, the new Meridian lot, is used on second shift from W3. | C41: MM-204 incoming chemistry and acceptance were within internal receiving statement; it does not prove machinability. | D41: =1+1 -> 2 | E41: Shift-specific lot usage aligns from W3, but incoming acceptance is not causal proof. | F41: E08; E09 | AE41: BR-034 | AF41: 46149 | AG41: ="W"&INT((AF41-MIN($AF$8:$AF$307))/7)+1 -> W1 | AH41: Second | AI41: PB-01-S | AJ41: P1S09 | AK41: FX-B | AL41: CL-771 | AM41: GM-22 | AN41: 50.006 | AO41: mm
...
