Workbook

Sheet Read_Me
A1: Foxglove Utilities | Shared Laboratory Cost Allocation Model
A2: Blank controlled instrument for Quillhaven Bureau policy in force 31 August 2026
A4: Policy boundary
A5: Apply only the Quillhaven Bureau Shared Laboratory Cost Allocation Policy as in force on 31 August 2026. Use METERED when complete metered evidence exists. Where metered evidence is incomplete for a cost pool, select exactly one documented proxy for the whole pool: EQUIPMENT_HOURS, STAFF_HOURS, or FLOOR_AREA. Unsupported estimates are prohibited.
A7: Scope and exclusion boundary
A8: Recognized scope codes are CHARGEABLE, NON_PUBLIC_RESEARCH, CAPITAL, PENALTIES, and RECOVERED_ELSEWHERE. Only CHARGEABLE activity participates in an allocation denominator. The other four codes are excluded, require a supporting note, and receive no allocated cost.
A10: Use the blank instrument
A11: Enter controlled cost-pool and program/activity records on Inputs. Capture one approved proxy judgment in Assumptions whenever the pool basis is not METERED. Use Allocation to inspect exact calculations and row-level corrective action, Checks to resolve pool controls, and Publication_Import only after its formula-driven Reviewer_Status is READY.
A13: Precision, range review, and release gate
A14: Exact Allocation Share displays six decimals and Exact Allocated Cost displays two decimals; their formulas retain full precision and do not round. Public Allocation Share is a one-decimal percentage and Public Allocated Cost is rounded to the nearest whole currency unit. Exact CHARGEABLE shares must total 1 within ±0.000001; exact allocated cost must agree to pool cost within ±0.01 currency unit. A nonnegative quantity outside entered expected limits is accepted, visibly flagged, and continues calculating, but remains HOLD until its review flag is Y. HOLD means a required input, evidence item, control, review, or sign-off is unresolved. READY is formula-driven only after controls and reviewer release sign-off pass.
A16: Navigation and entry key
A17: Read_Me states the policy boundary. Inputs holds editable entry cells. Allocation shows calculated exact and public figures. Assumptions records proxy support. Checks names failed controls and actions. Publication_Import is the fixed machine-parsed range. Pale gold cells are editable entries; pale gray cells are calculated; blue headers and the import structure are fixed controls.

Sheet Inputs
A1: Inputs | Controlled entry area
A2: Pale gold cells are editable. Do not type over calculated range flags or fixed headers.
A4: Enter one controlled record per cost pool. Select METERED only where complete metered evidence exists. For a permitted proxy, create a matching approved Assumptions record before release. Reviewer release requires Y, reviewer name, and review date.
A6: Methodology ID | B6: Effective Date | C6: Cost Pool ID | D6: Cost Pool Description | E6: Total Shared Cost | F6: Allocation Basis Code | G6: Expected Minimum Quantity | H6: Expected Maximum Quantity | I6: Preparer / Owner | J6: Reviewer Sign-off (Y/N) | K6: Reviewer Name | L6: Review Date
A160: Program and activity records
A161: Enter the observed usage quantity and its evidence reference for every CHARGEABLE record. Expected limits are review thresholds, not rejection limits: an out-of-range nonnegative quantity remains stored and must have a Y review before release. Excluded scope codes require an exclusion or evidence note.
A163: Cost Pool ID | B163: Program Code | C163: Program Description | D163: Scope Code | E163: Usage Quantity | F163: Evidence Reference | G163: Out-of-Range Review (Y/N) | H163: Exclusion / Evidence Note | I163: Range Exception (formula)
I164: =IF(COUNTA(A164:H164)=0,"",IF(OR(E164="",IFERROR(VLOOKUP(A164,$C$7:$H$156,5,FALSE),"")="",IFERROR(VLOOKUP(A164,$C$7:$H$156,6,FALSE),"")=""),"",IF(OR(E164<IFERROR(VLOOKUP(A164,$C$7:$H$156,5,FALSE),E164),E164>IFERROR(VLOOKUP(A164,$C$7:$H$156,6,FALSE),E164)),"OUT OF RANGE","WITHIN RANGE")))
I165: =IF(COUNTA(A165:H165)=0,"",IF(OR(E165="",IFERROR(VLOOKUP(A165,$C$7:$H$156,5,FALSE),"")="",IFERROR(VLOOKUP(A165,$C$7:$H$156,6,FALSE),"")=""),"",IF(OR(E165<IFERROR(VLOOKUP(A165,$C$7:$H$156,5,FALSE),E165),E165>IFERROR(VLOOKUP(A165,$C$7:$H$156,6,FALSE),E165)),"OUT OF RANGE","WITHIN RANGE")))
I166: =IF(COUNTA(A166:H166)=0,"",IF(OR(E166="",IFERROR(VLOOKUP(A166,$C$7:$H$156,5,FALSE),"")="",IFERROR(VLOOKUP(A166,$C$7:$H$156,6,FALSE),"")=""),"",IF(OR(E166<IFERROR(VLOOKUP(A166,$C$7:$H$156,5,FALSE),E166),E166>IFERROR(VLOOKUP(A166,$C$7:$H$156,6,FALSE),E166)),"OUT OF RANGE","WITHIN RANGE")))
I167: =IF(COUNTA(A167:H167)=0,"",IF(OR(E167="",IFERROR(VLOOKUP(A167,$C$7:$H$156,5,FALSE),"")="",IFERROR(VLOOKUP(A167,$C$7:$H$156,6,FALSE),"")=""),"",IF(OR(E167<IFERROR(VLOOKUP(A167,$C$7:$H$156,5,FALSE),E167),E167>IFERROR(VLOOKUP(A167,$C$7:$H$156,6,FALSE),E167)),"OUT OF RANGE","WITHIN RANGE")))
I168: =IF(COUNTA(A168:H168)=0,"",IF(OR(E168="",IFERROR(VLOOKUP(A168,$C$7:$H$156,5,FALSE),"")="",IFERROR(VLOOKUP(A168,$C$7:$H$156,6,FALSE),"")=""),"",IF(OR(E168<IFERROR(VLOOKUP(A168,$C$7:$H$156,5,FALSE),E168),E168>IFERROR(VLOOKUP(A168,$C$7:$H$156,6,FALSE),E168)),"OUT OF RANGE","WITHIN RANGE")))
I169: =IF(COUNTA(A169:H169)=0,"",IF(OR(E169="",IFERROR(VLOOKUP(A169,$C$7:$H$156,5,FALSE),"")="",IFERROR(VLOOKUP(A169,$C$7:$H$156,6,FALSE),"")=""),"",IF(OR(E169<IFERROR(VLOOKUP(A169,$C$7:$H$156,5,FALSE),E169),E169>IFERROR(VLOOKUP(A169,$C$7:$H$156,6,FALSE),E169)),"OUT OF RANGE","WITHIN RANGE")))
I170: =IF(COUNTA(A170:H170)=0,"",IF(OR(E170="",IFERROR(VLOOKUP(A170,$C$7:$H$156,5,FALSE),"")="",IFERROR(VLOOKUP(A170,$C$7:$H$156,6,FALSE),"")=""),"",IF(OR(E170<IFERROR(VLOOKUP(A170,$C$7:$H$156,5,FALSE),E170),E170>IFERROR(VLOOKUP(A170,$C$7:$H$156,6,FALSE),E170)),"OUT OF RANGE","WITHIN RANGE")))
I171: =IF(COUNTA(A171:H171)=0,"",IF(OR(E171="",IFERROR(VLOOKUP(A171,$C$7:$H$156,5,FALSE),"")="",IFERROR(VLOOKUP(A171,$C$7:$H$156,6,FALSE),"")=""),"",IF(OR(E171<IFERROR(VLOOKUP(A171,$C$7:$H$156,5,FALSE),E171),E171>IFERROR(VLOOKUP(A171,$C$7:$H$156,6,FALSE),E171)),"OUT OF RANGE","WITHIN RANGE")))
I172: =IF(COUNTA(A172:H172)=0,"",IF(OR(E172="",IFERROR(VLOOKUP(A172,$C$7:$H$156,5,FALSE),"")="",IFERROR(VLOOKUP(A172,$C$7:$H$156,6,FALSE),"")=""),"",IF(OR(E172<IFERROR(VLOOKUP(A172,$C$7:$H$156,5,FALSE),E172),E172>IFERROR(VLOOKUP(A172,$C$7:$H$156,6,FALSE),E172)),"OUT OF RANGE","WITHIN RANGE")))
I173: =IF(COUNTA(A173:H173)=0,"",IF(OR(E173="",IFERROR(VLOOKUP(A173,$C$7:$H$156,5,FALSE),"")="",IFERROR(VLOOKUP(A173,$C$7:$H$156,6,FALSE),"")=""),"",IF(OR(E173<IFERROR(VLOOKUP(A173,$C$7:$H$156,5,FALSE),E173),E173>IFERROR(VLOOKUP(A173,$C$7:$H$156,6,FALSE),E173)),"OUT OF RANGE","WITHIN RANGE")))
I174: =IF(COUNTA(A174:H174)=0,"",IF(OR(E174="",IFERROR(VLOOKUP(A174,$C$7:$H$156,5,FALSE),"")="",IFERROR(VLOOKUP(A174,$C$7:$H$156,6,FALSE),"")=""),"",IF(OR(E174<IFERROR(VLOOKUP(A174,$C$7:$H$156,5,FALSE),E174),E174>IFERROR(VLOOKUP(A174,$C$7:$H$156,6,FALSE),E174)),"OUT OF RANGE","WITHIN RANGE")))
I175: =IF(COUNTA(A175:H175)=0,"",IF(OR(E175="",IFERROR(VLOOKUP(A175,$C$7:$H$156,5,FALSE),"")="",IFERROR(VLOOKUP(A175,$C$7:$H$156,6,FALSE),"")=""),"",IF(OR(E175<IFERROR(VLOOKUP(A175,$C$7:$H$156,5,FALSE),E175),E175>IFERROR(VLOOKUP(A175,$C$7:$H$156,6,FALSE),E175)),"OUT OF RANGE","WITHIN RANGE")))
... I313: =IF(COUNTA(A313:H313)=0,"",IF(OR(E313="",IFERROR(VLOOKUP(A313,$C$7:$H$156,5,FALSE),"")="",IFERROR(VLOOKUP(A313,$C$7:$H$156,6,FALSE),"")=""),"",IF(OR(E313<IFERROR(VLOOKUP(A313,$C$7:$H$156,5,FALSE),E313),E313>IFERROR(VLOOKUP(A313,$C$7:$H$156,6,FALSE),E313)),"OUT OF RANGE","WITHIN RANGE")))

Sheet Allocation
A1: Allocation | Calculated results
A2: Exact values retain full precision. Public values are derived presentation fields and never drive exact controls.
A4: This sheet is formula-controlled. CHARGEABLE records with complete quantity and evidence feed the pool denominator. Excluded records receive zero output and an exclusion flag. Resolve the named action; do not overwrite calculated fields.
A6: Source Row In Use | B6: Cost Pool ID | C6: Program Code | D6: Scope Code | E6: Usage Quantity | F6: Evidence Reference | G6: Methodology ID | H6: Effective Date | I6: Pool Cost | J6: Allocation Basis Code | K6: Expected Minimum | L6: Expected Maximum | M6: Range Exception | N6: Range Review | O6: Eligible Denominator | P6: Exact Allocation Share | Q6: Exact Allocated Cost | R6: Public Allocation Share | S6: Public Allocated Cost | T6: Assumption Flag | U6: Exclusion Flag | V6: Publication Key | W6: Record Check | X6: Pool Share Control | Y6: Pool Cost Control | Z6: Import Exact Link | AA6: Reviewer Status | AB6: Action Required
A7: =IF(COUNTA(Inputs!$A$164:$H$164)>0,"Y","") | B7: =IF(Inputs!A164="","",Inputs!A164) | C7: =IF(Inputs!B164="","",Inputs!B164) | D7: =IF(Inputs!D164="","",Inputs!D164) | E7: =IF(Inputs!E164="","",Inputs!E164) | F7: =IF(Inputs!F164="","",Inputs!F164) | G7: =IF($B7="","",IFERROR(INDEX(Inputs!$A$7:$A$156,MATCH($B7,Inputs!$C$7:$C$156,0)),"")) | H7: =IF($B7="","",IFERROR(INDEX(Inputs!$B$7:$B$156,MATCH($B7,Inputs!$C$7:$C$156,0)),"")) | I7: =IF($B7="","",IFERROR(INDEX(Inputs!$E$7:$E$156,MATCH($B7,Inputs!$C$7:$C$156,0)),"")) | J7: =IF($B7="","",IFERROR(INDEX(Inputs!$F$7:$F$156,MATCH($B7,Inputs!$C$7:$C$156,0)),"")) | K7: =IF($B7="","",IFERROR(INDEX(Inputs!$G$7:$G$156,MATCH($B7,Inputs!$C$7:$C$156,0)),"")) | L7: =IF($B7="","",IFERROR(INDEX(Inputs!$H$7:$H$156,MATCH($B7,Inputs!$C$7:$C$156,0)),"")) | M7: =IF($A7="","",IF(OR($E7="",$K7="",$L7=""),"N",IF(OR($E7<$K7,$E7>$L7),"Y","N"))) | N7: =IF($A7="","",IF(Inputs!G164="","",Inputs!G164)) | O7: =IF($A7="","",IF($D7<>"CHARGEABLE","",SUMIFS($E$7:$E$156,$B$7:$B$156,$B7,$D$7:$D$156,"CHARGEABLE",$C$7:$C$156,"<>",$E$7:$E$156,">=0",$F$7:$F$156,"<>"))) | P7: =IF($A7="","",IF($D7<>"CHARGEABLE",IF(OR($D7="NON_PUBLIC_RESEARCH",$D7="CAPITAL",$D7="PENALTIES",$D7="RECOVERED_ELSEWHERE"),0,""),IF(OR($C7="",$E7="",$F7="",$I7="",$J7="",$O7<=0),"",$E7/$O7))) | Q7: =IF($A7="","",IF($D7<>"CHARGEABLE",IF(OR($D7="NON_PUBLIC_RESEARCH",$D7="CAPITAL",$D7="PENALTIES",$D7="RECOVERED_ELSEWHERE"),0,""),IF(OR($P7="",$I7=""),"",$I7*$P7))) | R7: =IF($A7="","",IF($D7<>"CHARGEABLE",IF(OR($D7="NON_PUBLIC_RESEARCH",$D7="CAPITAL",$D7="PENALTIES",$D7="RECOVERED_ELSEWHERE"),0,""),IF($P7="","",ROUND($P7*100,1)/100))) | S7: =IF($A7="","",IF($D7<>"CHARGEABLE",IF(OR($D7="NON_PUBLIC_RESEARCH",$D7="CAPITAL",$D7="PENALTIES",$D7="RECOVERED_ELSEWHERE"),0,""),IF($Q7="","",ROUND($Q7,0)))) | T7: =IF($A7="","",IF(OR($J7="EQUIPMENT_HOURS",$J7="STAFF_HOURS",$J7="FLOOR_AREA"),"Y",IF($J7="METERED","N",""))) | U7: =IF($A7="","",IF($D7="CHARGEABLE","N",IF(OR($D7="NON_PUBLIC_RESEARCH",$D7="CAPITAL",$D7="PENALTIES",$D7="RECOVERED_ELSEWHERE"),"Y",""))) | V7: =IF(OR($G7="",$C7=""),"",$G7&"|"&$C7) | W7: =IF($A7="","",IF($B7="","Missing Cost Pool ID",IF($C7="","Missing Program Code",IF($D7="","Missing Scope Code",IF(AND($D7<>"CHARGEABLE",$D7<>"NON_PUBLIC_RESEARCH",$D7<>"CAPITAL",$D7<>"PENALTIES",$D7<>"RECOVERED_ELSEWHERE"),"Invalid Scope Code",IF($G7="","Missing Methodology ID",IF($J7="","Pool basis unresolved",IF(AND($B7<>"",$C7<>"",COUNTIFS($B$7:$B$156,$B7,$C$7:$C$156,$C7)>1),"Duplicate Cost Pool / Program",IF(AND($V7<>"",COUNTIF($V$7:$V$156,$V7)>1),"Duplicate Methodology / Program",IF(AND($D7="CHARGEABLE",$E7=""),"Missing usage quantity",IF(AND($D7="CHARGEABLE",$F7=""),"Missing evidence reference",IF(AND($D7="CHARGEABLE",NOT(ISNUMBER($E7))),"Usage quantity not numeric",IF(AND($D7="CHARGEABLE",$E7<0),"Usage quantity is negative",IF(AND($U7="Y",Inputs!$H$164=""),"Missing exclusion note","OK")))))))))))))) | X7: =IF($A7="","",IFERROR(INDEX(Checks!$O$7:$O$156,MATCH($B7,Checks!$B$7:$B$156,0)),"FAIL")) | Y7: =IF($A7="","",IFERROR(INDEX(Checks!$Q$7:$Q$156,MATCH($B7,Checks!$B$7:$B$156,0)),"FAIL")) | Z7: =IF($A7="","",IF(OR($Q7="",Publication_Import!$F7=""),"FAIL",IF(ABS($Q7-Publication_Import!$F7)<=0.000001,"PASS","FAIL"))) | AA7: =IF($A7="","",IF(AND($W7="OK",$X7="PASS",$Y7="PASS",$Z7="PASS",IFERROR(INDEX(Checks!$S$7:$S$156,MATCH($B7,Checks!$B$7:$B$156,0)),"HOLD")="READY"),"READY","HOLD")) | AB7: =IF($A7="","",IF($AA7="READY","Ready for publication import",IF($W7<>"OK",$W7,IFERROR(INDEX(Checks!$T$7:$T$156,MATCH($B7,Checks!$B$7:$B$156,0)),"Add a valid cost pool"))))
A8: =IF(COUNTA(Inputs!$A$165:$H$165)>0,"Y","") | B8: =IF(Inputs!A165="","",Inputs!A165) | C8: =IF(Inputs!B165="","",Inputs!B165) | D8: =IF(Inputs!D165="","",Inputs!D165) | E8: =IF(Inputs!E165="","",Inputs!E165) | F8: =IF(Inputs!F165="","",Inputs!F165) | G8: =IF($B8="","",IFERROR(INDEX(Inputs!$A$7:$A$156,MATCH($B8,Inputs!$C$7:$C$156,0)),"")) | H8: =IF($B8="","",IFERROR(INDEX(Inputs!$B$7:$B$156,MATCH($B8,Inputs!$C$7:$C$156,0)),"")) | I8: =IF($B8="","",IFERROR(INDEX(Inputs!$E$7:$E$156,MATCH($B8,Inputs!$C$7:$C$156,0)),"")) | J8: =IF($B8="","",IFERROR(INDEX(Inputs!$F$7:$F$156,MATCH($B8,Inputs!$C$7:$C$156,0)),"")) | K8: =IF($B8="","",IFERROR(INDEX(Inputs!$G$7:$G$156,MATCH($B8,Inputs!$C$7:$C$156,0)),"")) | L8: =IF($B8="","",IFERROR(INDEX(Inputs!$H$7:$H$156,MATCH($B8,Inputs!$C$7:$C$156,0)),"")) | M8: =IF($A8="","",IF(OR($E8="",$K8="",$L8=""),"N",IF(OR($E8<$K8,$E8>$L8),"Y","N"))) | N8: =IF($A8="","",IF(Inputs!G165="","",Inputs!G165)) | O8: =IF($A8="","",IF($D8<>"CHARGEABLE","",SUMIFS($E$7:$E$156,$B$7:$B$156,$B8,$D$7:$D$156,"CHARGEABLE",$C$7:$C$156,"<>",$E$7:$E$156,">=0",$F$7:$F$156,"<>"))) | P8: =IF($A8="","",IF($D8<>"CHARGEABLE",IF(OR($D8="NON_PUBLIC_RESEARCH",$D8="CAPITAL",$D8="PENALTIES",$D8="RECOVERED_ELSEWHERE"),0,""),IF(OR($C8="",$E8="",$F8="",$I8="",$J8="",$O8<=0),"",$E8/$O8))) | Q8: =IF($A8="","",IF($D8<>"CHARGEABLE",IF(OR($D8="NON_PUBLIC_RESEARCH",$D8="CAPITAL",$D8="PENALTIES",$D8="RECOVERED_ELSEWHERE"),0,""),IF(OR($P8="",$I8=""),"",$I8*$P8))) | R8: =IF($A8="","",IF($D8<>"CHARGEABLE",IF(OR($D8="NON_PUBLIC_RESEARCH",$D8="CAPITAL",$D8="PENALTIES",$D8="RECOVERED_ELSEWHERE"),0,""),IF($P8="","",ROUND($P8*100,1)/100))) | S8: =IF($A8="","",IF($D8<>"CHARGEABLE",IF(OR($D8="NON_PUBLIC_RESEARCH",$D8="CAPITAL",$D8="PENALTIES",$D8="RECOVERED_ELSEWHERE"),0,""),IF($Q8="","",ROUND($Q8,0)))) | T8: =IF($A8="","",IF(OR($J8="EQUIPMENT_HOURS",$J8="STAFF_HOURS",$J8="FLOOR_AREA"),"Y",IF($J8="METERED","N",""))) | U8: =IF($A8="","",IF($D8="CHARGEABLE","N",IF(OR($D8="NON_PUBLIC_RESEARCH",$D8="CAPITAL",$D8="PENALTIES",$D8="RECOVERED_ELSEWHERE"),"Y",""))) | V8: =IF(OR($G8="",$C8=""),"",$G8&"|"&$C8) | W8: =IF($A8="","",IF($B8="","Missing Cost Pool ID",IF($C8="","Missing Program Code",IF($D8="","Missing Scope Code",IF(AND($D8<>"CHARGEABLE",$D8<>"NON_PUBLIC_RESEARCH",$D8<>"CAPITAL",$D8<>"PENALTIES",$D8<>"RECOVERED_ELSEWHERE"),"Invalid Scope Code",IF($G8="","Missing Methodology ID",IF($J8="","Pool basis unresolved",IF(AND($B8<>"",$C8<>"",COUNTIFS($B$7:$B$156,$B8,$C$7:$C$156,$C8)>1),"Duplicate Cost Pool / Program",IF(AND($V8<>"",COUNTIF($V$7:$V$156,$V8)>1),"Duplicate Methodology / Program",IF(AND($D8="CHARGEABLE",$E8=""),"Missing usage quantity",IF(AND($D8="CHARGEABLE",$F8=""),"Missing evidence reference",IF(AND($D8="CHARGEABLE",NOT(ISNUMBER($E8))),"Usage quantity not numeric",IF(AND($D8="CHARGEABLE",$E8<0),"Usage quantity is negative",IF(AND($U8="Y",Inputs!$H$165=""),"Missing exclusion note","OK")))))))))))))) | X8: =IF($A8="","",IFERROR(INDEX(Checks!$O$7:$O$156,MATCH($B8,Checks!$B$7:$B$156,0)),"FAIL")) | Y8: =IF($A8="","",IFERROR(INDEX(Checks!$Q$7:$Q$156,MATCH($B8,Checks!$B$7:$B$156,0)),"FAIL")) | Z8: =IF($A8="","",IF(OR($Q8="",Publication_Import!$F8=""),"FAIL",IF(ABS($Q8-Publication_Import!$F8)<=0.000001,"PASS","FAIL"))) | AA8: =IF($A8="","",IF(AND($W8="OK",$X8="PASS",$Y8="PASS",$Z8="PASS",IFERROR(INDEX(Checks!$S$7:$S$156,MATCH($B8,Checks!$B$7:$B$156,0)),"HOLD")="READY"),"READY","HOLD")) | AB8: =IF($A8="","",IF($AA8="READY","Ready for publication import",IF($W8<>"OK",$W8,IFERROR(INDEX(Checks!$T$7:$T$156,MATCH($B8,Checks!$B$7:$B$156,0)),"Add a valid cost pool"))))
A9: =IF(COUNTA(Inputs!$A$166:$H$166)>0,"Y","") | B9: =IF(Inputs!A166="","",Inputs!A166) | C9: =IF(Inputs!B166="","",Inputs!B166) | D9: =IF(Inputs!D166="","",Inputs!D166) | E9: =IF(Inputs!E166="","",Inputs!E166) | F9: =IF(Inputs!F166="","",Inputs!F166) | G9: =IF($B9="","",IFERROR(INDEX(Inputs!$A$7:$A$156,MATCH($B9,Inputs!$C$7:$C$156,0)),"")) | H9: =IF($B9="","",IFERROR(INDEX(Inputs!$B$7:$B$156,MATCH($B9,Inputs!$C$7:$C$156,0)),"")) | I9: =IF($B9="","",IFERROR(INDEX(Inputs!$E$7:$E$156,MATCH($B9,Inputs!$C$7:$C$156,0)),"")) | J9: =IF($B9="","",IFERROR(INDEX(Inputs!$F$7:$F$156,MATCH($B9,Inputs!$C$7:$C$156,0)),"")) | K9: =IF($B9="","",IFERROR(INDEX(Inputs!$G$7:$G$156,MATCH($B9,Inputs!$C$7:$C$156,0)),"")) | L9: =IF($B9="","",IFERROR(INDEX(Inputs!$H$7:$H$156,MATCH($B9,Inputs!$C$7:$C$156,0)),"")) | M9: =IF($A9="","",IF(OR($E9="",$K9="",$L9=""),"N",IF(OR($E9<$K9,$E9>$L9),"Y","N"))) | N9: =IF($A9="","",IF(Inputs!G166="","",Inputs!G166)) | O9: =IF($A9="","",IF($D9<>"CHARGEABLE","",SUMIFS($E$7:$E$156,$B$7:$B$156,$B9,$D$7:$D$156,"CHARGEABLE",$C$7:$C$156,"<>",$E$7:$E$156,">=0",$F$7:$F$156,"<>"))) | P9: =IF($A9="","",IF($D9<>"CHARGEABLE",IF(OR($D9="NON_PUBLIC_RESEARCH",$D9="CAPITAL",$D9="PENALTIES",$D9="RECOVERED_ELSEWHERE"),0,""),IF(OR($C9="",$E9="",$F9="",$I9="",$J9="",$O9<=0),"",$E9/$O9))) | Q9: =IF($A9="","",IF($D9<>"CHARGEABLE",IF(OR($D9="NON_PUBLIC_RESEARCH",$D9="CAPITAL",$D9="PENALTIES",$D9="RECOVERED_ELSEWHERE"),0,""),IF(OR($P9="",$I9=""),"",$I9*$P9))) | R9: =IF($A9="","",IF($D9<>"CHARGEABLE",IF(OR($D9="NON_PUBLIC_RESEARCH",$D9="CAPITAL",$D9="PENALTIES",$D9="RECOVERED_ELSEWHERE"),0,""),IF($P9="","",ROUND($P9*100,1)/100))) | S9: =IF($A9="","",IF($D9<>"CHARGEABLE",IF(OR($D9="NON_PUBLIC_RESEARCH",$D9="CAPITAL",$D9="PENALTIES",$D9="RECOVERED_ELSEWHERE"),0,""),IF($Q9="","",ROUND($Q9,0)))) | T9: =IF($A9="","",IF(OR($J9="EQUIPMENT_HOURS",$J9="STAFF_HOURS",$J9="FLOOR_AREA"),"Y",IF($J9="METERED","N",""))) | U9: =IF($A9="","",IF($D9="CHARGEABLE","N",IF(OR($D9="NON_PUBLIC_RESEARCH",$D9="CAPITAL",$D9="PENALTIES",$D9="RECOVERED_ELSEWHERE"),"Y",""))) | V9: =IF(OR($G9="",$C9=""),"",$G9&"|"&$C9) | W9: =IF($A9="","",IF($B9="","Missing Cost Pool ID",IF($C9="","Missing Program Code",IF($D9="","Missing Scope Code",IF(AND($D9<>"CHARGEABLE",$D9<>"NON_PUBLIC_RESEARCH",$D9<>"CAPITAL",$D9<>"PENALTIES",$D9<>"RECOVERED_ELSEWHERE"),"Invalid Scope Code",IF($G9="","Missing Methodology ID",IF($J9="","Pool basis unresolved",IF(AND($B9<>"",$C9<>"",COUNTIFS($B$7:$B$156,$B9,$C$7:$C$156,$C9)>1),"Duplicate Cost Pool / Program",IF(AND($V9<>"",COUNTIF($V$7:$V$156,$V9)>1),"Duplicate Methodology / Program",IF(AND($D9="CHARGEABLE",$E9=""),"Missing usage quantity",IF(AND($D9="CHARGEABLE",$F9=""),"Missing evidence reference",IF(AND($D9="CHARGEABLE",NOT(ISNUMBER($E9))),"Usage quantity not numeric",IF(AND($D9="CHARGEABLE",$E9<0),"Usage quantity is negative",IF(AND($U9="Y",Inputs!$H$166=""),"Missing exclusion note","OK")))))))))))))) | X9: =IF($A9="","",IFERROR(INDEX(Checks!$O$7:$O$156,MATCH($B9,Checks!$B$7:$B$156,0)),"FAIL")) | Y9: =IF($A9="","",IFERROR(INDEX(Checks!$Q$7:$Q$156,MATCH($B9,Checks!$B$7:$B$156,0)),"FAIL")) | Z9: =IF($A9="","",IF(OR($Q9="",Publication_Import!$F9=""),"FAIL",IF(ABS($Q9-Publication_Import!$F9)<=0.000001,"PASS","FAIL"))) | AA9: =IF($A9="","",IF(AND($W9="OK",$X9="PASS",$Y9="PASS",$Z9="PASS",IFERROR(INDEX(Checks!$S$7:$S$156,MATCH($B9,Checks!$B$7:$B$156,0)),"HOLD")="READY"),"READY","HOLD")) | AB9: =IF($A9="","",IF($AA9="READY","Ready for publication import",IF($W9<>"OK",$W9,IFERROR(INDEX(Checks!$T$7:$T$156,MATCH($B9,Checks!$B$7:$B$156,0)),"Add a valid cost pool"))))
A10: =IF(COUNTA(Inputs!$A$167:$H$167)>0,"Y","") | B10: =IF(Inputs!A167="","",Inputs!A167) | C10: =IF(Inputs!B167="","",Inputs!B167) | D10: =IF(Inputs!D167="","",Inputs!D167) | E10: =IF(Inputs!E167="","",Inputs!E167) | F10: =IF(Inputs!F167="","",Inputs!F167) | G10: =IF($B10="","",IFERROR(INDEX(Inputs!$A$7:$A$156,MATCH($B10,Inputs!$C$7:$C$156,0)),"")) | H10: =IF($B10="","",IFERROR(INDEX(Inputs!$B$7:$B$156,MATCH($B10,Inputs!$C$7:$C$156,0)),"")) | I10: =IF($B10="","",IFERROR(INDEX(Inputs!$E$7:$E$156,MATCH($B10,Inputs!$C$7:$C$156,0)),"")) | J10: =IF($B10="","",IFERROR(INDEX(Inputs!$F$7:$F$156,MATCH($B10,Inputs!$C$7:$C$156,0)),"")) | K10: =IF($B10="","",IFERROR(INDEX(Inputs!$G$7:$G$156,MATCH($B10,Inputs!$C$7:$C$156,0)),"")) | L10: =IF($B10="","",IFERROR(INDEX(Inputs!$H$7:$H$156,MATCH($B10,Inputs!$C$7:$C$156,0)),"")) | M10: =IF($A10="","",IF(OR($E10="",$K10="",$L10=""),"N",IF(OR($E10<$K10,$E10>$L10),"Y","N"))) | N10: =IF($A10="","",IF(Inputs!G167="","",Inputs!G167)) | O10: =IF($A10="","",IF($D10<>"CHARGEABLE","",SUMIFS($E$7:$E$156,$B$7:$B$156,$B10,$D$7:$D$156,"CHARGEABLE",$C$7:$C$156,"<>",$E$7:$E$156,">=0",$F$7:$F$156,"<>"))) | P10: =IF($A10="","",IF($D10<>"CHARGEABLE",IF(OR($D10="NON_PUBLIC_RESEARCH",$D10="CAPITAL",$D10="PENALTIES",$D10="RECOVERED_ELSEWHERE"),0,""),IF(OR($C10="",$E10="",$F10="",$I10="",$J10="",$O10<=0),"",$E10/$O10))) | Q10: =IF($A10="","",IF($D10<>"CHARGEABLE",IF(OR($D10="NON_PUBLIC_RESEARCH",$D10="CAPITAL",$D10="PENALTIES",$D10="RECOVERED_ELSEWHERE"),0,""),IF(OR($P10="",$I10=""),"",$I10*$P10))) | R10: =IF($A10="","",IF($D10<>"CHARGEABLE",IF(OR($D10="NON_PUBLIC_RESEARCH",$D10="CAPITAL",$D10="PENALTIES",$D10="RECOVERED_ELSEWHERE"),0,""),IF($P10="","",ROUND($P10*100,1)/100))) | S10: =IF($A10="","",IF($D10<>"CHARGEABLE",IF(OR($D10="NON_PUBLIC_RESEARCH",$D10="CAPITAL",$D10="PENALTIES",$D10="RECOVERED_ELSEWHERE"),0,""),IF($Q10="","",ROUND($Q10,0)))) | T10: =IF($A10="","",IF(OR($J10="EQUIPMENT_HOURS",$J10="STAFF_HOURS",$J10="FLOOR_AREA"),"Y",IF($J10="METERED","N",""))) | U10: =IF($A10="","",IF($D10="CHARGEABLE","N",IF(OR($D10="NON_PUBLIC_RESEARCH",$D10="CAPITAL",$D10="PENALTIES",$D10="RECOVERED_ELSEWHERE"),"Y",""))) | V10: =IF(OR($G10="",$C10=""),"",$G10&"|"&$C10) | W10: =IF($A10="","",IF($B10="","Missing Cost Pool ID",IF($C10="","Missing Program Code",IF($D10="","Missing Scope Code",IF(AND($D10<>"CHARGEABLE",$D10<>"NON_PUBLIC_RESEARCH",$D10<>"CAPITAL",$D10<>"PENALTIES",$D10<>"RECOVERED_ELSEWHERE"),"Invalid Scope Code",IF($G10="","Missing Methodology ID",IF($J10="","Pool basis unresolved",IF(AND($B10<>"",$C10<>"",COUNTIFS($B$7:$B$156,$B10,$C$7:$C$156,$C10)>1),"Duplicate Cost Pool / Program",IF(AND($V10<>"",COUNTIF($V$7:$V$156,$V10)>1),"Duplicate Methodology / Program",IF(AND($D10="CHARGEABLE",$E10=""),"Missing usage quantity",IF(AND($D10="CHARGEABLE",$F10=""),"Missing evidence reference",IF(AND($D10="CHARGEABLE",NOT(ISNUMBER($E10))),"Usage quantity not numeric",IF(AND($D10="CHARGEABLE",$E10<0),"Usage quantity is negative",IF(AND($U10="Y",Inputs!$H$167=""),"Missing exclusion note","OK")))))))))))))) | X10: =IF($A10="","",IFERROR(INDEX(Checks!$O$7:$O$156,MATCH($B10,Checks!$B$7:$B$156,0)),"FAIL")) | Y10: =IF($A10="","",IFERROR(INDEX(Checks!$Q$7:$Q$156,MATCH($B10,Checks!$B$7:$B$156,0)),"FAIL")) | Z10: =IF($A10="","",IF(OR($Q10="",Publication_Import!$F10=""),"FAIL",IF(ABS($Q10-Publication_Import!$F10)<=0.000001,"PASS","FAIL"))) | AA10: =IF($A10="","",IF(AND($W10="OK",$X10="PASS",$Y10="PASS",$Z10="PASS",IFERROR(INDEX(Checks!$S$7:$S$156,MATCH($B10,Checks!$B$7:$B$156,0)),"HOLD")="READY"),"READY","HOLD")) | AB10: =IF($A10="","",IF($AA10="READY","Ready for publication import",IF($W10<>"OK",$W10,IFERROR(INDEX(Checks!$T$7:$T$156,MATCH($B10,Checks!$B$7:$B$156,0)),"Add a valid cost pool"))))
A11: =IF(COUNTA(Inputs!$A$168:$H$168)>0,"Y","") | B11: =IF(Inputs!A168="","",Inputs!A168) | C11: =IF(Inputs!B168="","",Inputs!B168) | D11: =IF(Inputs!D168="","",Inputs!D168) | E11: =IF(Inputs!E168="","",Inputs!E168) | F11: =IF(Inputs!F168="","",Inputs!F168) | G11: =IF($B11="","",IFERROR(INDEX(Inputs!$A$7:$A$156,MATCH($B11,Inputs!$C$7:$C$156,0)),"")) | H11: =IF($B11="","",IFERROR(INDEX(Inputs!$B$7:$B$156,MATCH($B11,Inputs!$C$7:$C$156,0)),"")) | I11: =IF($B11="","",IFERROR(INDEX(Inputs!$E$7:$E$156,MATCH($B11,Inputs!$C$7:$C$156,0)),"")) | J11: =IF($B11="","",IFERROR(INDEX(Inputs!$F$7:$F$156,MATCH($B11,Inputs!$C$7:$C$156,0)),"")) | K11: =IF($B11="","",IFERROR(INDEX(Inputs!$G$7:$G$156,MATCH($B11,Inputs!$C$7:$C$156,0)),"")) | L11: =IF($B11="","",IFERROR(INDEX(Inputs!$H$7:$H$156,MATCH($B11,Inputs!$C$7:$C$156,0)),"")) | M11: =IF($A11="","",IF(OR($E11="",$K11="",$L11=""),"N",IF(OR($E11<$K11,$E11>$L11),"Y","N"))) | N11: =IF($A11="","",IF(Inputs!G168="","",Inputs!G168)) | O11: =IF($A11="","",IF($D11<>"CHARGEABLE","",SUMIFS($E$7:$E$156,$B$7:$B$156,$B11,$D$7:$D$156,"CHARGEABLE",$C$7:$C$156,"<>",$E$7:$E$156,">=0",$F$7:$F$156,"<>"))) | P11: =IF($A11="","",IF($D11<>"CHARGEABLE",IF(OR($D11="NON_PUBLIC_RESEARCH",$D11="CAPITAL",$D11="PENALTIES",$D11="RECOVERED_ELSEWHERE"),0,""),IF(OR($C11="",$E11="",$F11="",$I11="",$J11="",$O11<=0),"",$E11/$O11))) | Q11: =IF($A11="","",IF($D11<>"CHARGEABLE",IF(OR($D11="NON_PUBLIC_RESEARCH",$D11="CAPITAL",$D11="PENALTIES",$D11="RECOVERED_ELSEWHERE"),0,""),IF(OR($P11="",$I11=""),"",$I11*$P11))) | R11: =IF($A11="","",IF($D11<>"CHARGEABLE",IF(OR($D11="NON_PUBLIC_RESEARCH",$D11="CAPITAL",$D11="PENALTIES",$D11="RECOVERED_ELSEWHERE"),0,""),IF($P11="","",ROUND($P11*100,1)/100))) | S11: =IF($A11="","",IF($D11<>"CHARGEABLE",IF(OR($D11="NON_PUBLIC_RESEARCH",$D11="CAPITAL",$D11="PENALTIES",$D11="RECOVERED_ELSEWHERE"),0,""),IF($Q11="","",ROUND($Q11,0)))) | T11: =IF($A11="","",IF(OR($J11="EQUIPMENT_HOURS",$J11="STAFF_HOURS",$J11="FLOOR_AREA"),"Y",IF($J11="METERED","N",""))) | U11: =IF($A11="","",IF($D11="CHARGEABLE","N",IF(OR($D11="NON_PUBLIC_RESEARCH",$D11="CAPITAL",$D11="PENALTIES",$D11="RECOVERED_ELSEWHERE"),"Y",""))) | V11: =IF(OR($G11="",$C11=""),"",$G11&"|"&$C11) | W11: =IF($A11="","",IF($B11="","Missing Cost Pool ID",IF($C11="","Missing Program Code",IF($D11="","Missing Scope Code",IF(AND($D11<>"CHARGEABLE",$D11<>"NON_PUBLIC_RESEARCH",$D11<>"CAPITAL",$D11<>"PENALTIES",$D11<>"RECOVERED_ELSEWHERE"),"Invalid Scope Code",IF($G11="","Missing Methodology ID",IF($J11="","Pool basis unresolved",IF(AND($B11<>"",$C11<>"",COUNTIFS($B$7:$B$156,$B11,$C$7:$C$156,$C11)>1),"Duplicate Cost Pool / Program",IF(AND($V11<>"",COUNTIF($V$7:$V$156,$V11)>1),"Duplicate Methodology / Program",IF(AND($D11="CHARGEABLE",$E11=""),"Missing usage quantity",IF(AND($D11="CHARGEABLE",$F11=""),"Missing evidence reference",IF(AND($D11="CHARGEABLE",NOT(ISNUMBER($E11))),"Usage quantity not numeric",IF(AND($D11="CHARGEABLE",$E11<0),"Usage quantity is negative",IF(AND($U11="Y",Inputs!$H$168=""),"Missing exclusion note","OK")))))))))))))) | X11: =IF($A11="","",IFERROR(INDEX(Checks!$O$7:$O$156,MATCH($B11,Checks!$B$7:$B$156,0)),"FAIL")) | Y11: =IF($A11="","",IFERROR(INDEX(Checks!$Q$7:$Q$156,MATCH($B11,Checks!$B$7:$B$156,0)),"FAIL")) | Z11: =IF($A11="","",IF(OR($Q11="",Publication_Import!$F11=""),"FAIL",IF(ABS($Q11-Publication_Import!$F11)<=0.000001,"PASS","FAIL"))) | AA11: =IF($A11="","",IF(AND($W11="OK",$X11="PASS",$Y11="PASS",$Z11="PASS",IFERROR(INDEX(Checks!$S$7:$S$156,MATCH($B11,Checks!$B$7:$B$156,0)),"HOLD")="READY"),"READY","HOLD")) | AB11: =IF($A11="","",IF($AA11="READY","Ready for publication import",IF($W11<>"OK",$W11,IFERROR(INDEX(Checks!$T$7:$T$156,MATCH($B11,Checks!$B$7:$B$156,0)),"Add a valid cost pool"))))
A12: =IF(COUNTA(Inputs!$A$169:$H$169)>0,"Y","") | B12: =IF(Inputs!A169="","",Inputs!A169) | C12: =IF(Inputs!B169="","",Inputs!B169) | D12: =IF(Inputs!D169="","",Inputs!D169) | E12: =IF(Inputs!E169="","",Inputs!E169) | F12: =IF(Inputs!F169="","",Inputs!F169) | G12: =IF($B12="","",IFERROR(INDEX(Inputs!$A$7:$A$156,MATCH($B12,Inputs!$C$7:$C$156,0)),"")) | H12: =IF($B12="","",IFERROR(INDEX(Inputs!$B$7:$B$156,MATCH($B12,Inputs!$C$7:$C$156,0)),"")) | I12: =IF($B12="","",IFERROR(INDEX(Inputs!$E$7:$E$156,MATCH($B12,Inputs!$C$7:$C$156,0)),"")) | J12: =IF($B12="","",IFERROR(INDEX(Inputs!$F$7:$F$156,MATCH($B12,Inputs!$C$7:$C$156,0)),"")) | K12: =IF($B12="","",IFERROR(INDEX(Inputs!$G$7:$G$156,MATCH($B12,Inputs!$C$7:$C$156,0)),"")) | L12: =IF($B12="","",IFERROR(INDEX(Inputs!$H$7:$H$156,MATCH($B12,Inputs!$C$7:$C$156,0)),"")) | M12: =IF($A12="","",IF(OR($E12="",$K12="",$L12=""),"N",IF(OR($E12<$K12,$E12>$L12),"Y","N"))) | N12: =IF($A12="","",IF(Inputs!G169="","",Inputs!G169)) | O12: =IF($A12="","",IF($D12<>"CHARGEABLE","",SUMIFS($E$7:$E$156,$B$7:$B$156,$B12,$D$7:$D$156,"CHARGEABLE",$C$7:$C$156,"<>",$E$7:$E$156,">=0",$F$7:$F$156,"<>"))) | P12: =IF($A12="","",IF($D12<>"CHARGEABLE",IF(OR($D12="NON_PUBLIC_RESEARCH",$D12="CAPITAL",$D12="PENALTIES",$D12="RECOVERED_ELSEWHERE"),0,""),IF(OR($C12="",$E12="",$F12="",$I12="",$J12="",$O12<=0),"",$E12/$O12))) | Q12: =IF($A12="","",IF($D12<>"CHARGEABLE",IF(OR($D12="NON_PUBLIC_RESEARCH",$D12="CAPITAL",$D12="PENALTIES",$D12="RECOVERED_ELSEWHERE"),0,""),IF(OR($P12="",$I12=""),"",$I12*$P12))) | R12: =IF($A12="","",IF($D12<>"CHARGEABLE",IF(OR($D12="NON_PUBLIC_RESEARCH",$D12="CAPITAL",$D12="PENALTIES",$D12="RECOVERED_ELSEWHERE"),0,""),IF($P12="","",ROUND($P12*100,1)/100))) | S12: =IF($A12="","",IF($D12<>"CHARGEABLE",IF(OR($D12="NON_PUBLIC_RESEARCH",$D12="CAPITAL",$D12="PENALTIES",$D12="RECOVERED_ELSEWHERE"),0,""),IF($Q12="","",ROUND($Q12,0)))) | T12: =IF($A12="","",IF(OR($J12="EQUIPMENT_HOURS",$J12="STAFF_HOURS",$J12="FLOOR_AREA"),"Y",IF($J12="METERED","N",""))) | U12: =IF($A12="","",IF($D12="CHARGEABLE","N",IF(OR($D12="NON_PUBLIC_RESEARCH",$D12="CAPITAL",$D12="PENALTIES",$D12="RECOVERED_ELSEWHERE"),"Y",""))) | V12: =IF(OR($G12="",$C12=""),"",$G12&"|"&$C12) | W12: =IF($A12="","",IF($B12="","Missing Cost Pool ID",IF($C12="","Missing Program Code",IF($D12="","Missing Scope Code",IF(AND($D12<>"CHARGEABLE",$D12<>"NON_PUBLIC_RESEARCH",$D12<>"CAPITAL",$D12<>"PENALTIES",$D12<>"RECOVERED_ELSEWHERE"),"Invalid Scope Code",IF($G12="","Missing Methodology ID",IF($J12="","Pool basis unresolved",IF(AND($B12<>"",$C12<>"",COUNTIFS($B$7:$B$156,$B12,$C$7:$C$156,$C12)>1),"Duplicate Cost Pool / Program",IF(AND($V12<>"",COUNTIF($V$7:$V$156,$V12)>1),"Duplicate Methodology / Program",IF(AND($D12="CHARGEABLE",$E12=""),"Missing usage quantity",IF(AND($D12="CHARGEABLE",$F12=""),"Missing evidence reference",IF(AND($D12="CHARGEABLE",NOT(ISNUMBER($E12))),"Usage quantity not numeric",IF(AND($D12="CHARGEABLE",$E12<0),"Usage quantity is negative",IF(AND($U12="Y",Inputs!$H$169=""),"Missing exclusion note","OK")))))))))))))) | X12: =IF($A12="","",IFERROR(INDEX(Checks!$O$7:$O$156,MATCH($B12,Checks!$B$7:$B$156,0)),"FAIL")) | Y12: =IF($A12="","",IFERROR(INDEX(Checks!$Q$7:$Q$156,MATCH($B12,Checks!$B$7:$B$156,0)),"FAIL")) | Z12: =IF($A12="","",IF(OR($Q12="",Publication_Import!$F12=""),"FAIL",IF(ABS($Q12-Publication_Import!$F12)<=0.000001,"PASS","FAIL"))) | AA12: =IF($A12="","",IF(AND($W12="OK",$X12="PASS",$Y12="PASS",$Z12="PASS",IFERROR(INDEX(Checks!$S$7:$S$156,MATCH($B12,Checks!$B$7:$B$156,0)),"HOLD")="READY"),"READY","HOLD")) | AB12: =IF($A12="","",IF($AA12="READY","Ready for publication import",IF($W12<>"OK",$W12,IFERROR(INDEX(Checks!$T$7:$T$156,MATCH($B12,Checks!$B$7:$B$156,0)),"Add a valid cost pool"))))
A13: =IF(COUNTA(Inputs!$A$170:$H$170)>0,"Y","") | B13: =IF(Inputs!A170="","",Inputs!A170) | C13: =IF(Inputs!B170="","",Inputs!B170) | D13: =IF(Inputs!D170="","",Inputs!D170) | E13: =IF(Inputs!E170="","",Inputs!E170) | F13: =IF(Inputs!F170="","",Inputs!F170) | G13: =IF($B13="","",IFERROR(INDEX(Inputs!$A$7:$A$156,MATCH($B13,Inputs!$C$7:$C$156,0)),"")) | H13: =IF($B13="","",IFERROR(INDEX(Inputs!$B$7:$B$156,MATCH($B13,Inputs!$C$7:$C$156,0)),"")) | I13: =IF($B13="","",IFERROR(INDEX(Inputs!$E$7:$E$156,MATCH($B13,Inputs!$C$7:$C$156,0)),"")) | J13: =IF($B13="","",IFERROR(INDEX(Inputs!$F$7:$F$156,MATCH($B13,Inputs!$C$7:$C$156,0)),"")) | K13: =IF($B13="","",IFERROR(INDEX(Inputs!$G$7:$G$156,MATCH($B13,Inputs!$C$7:$C$156,0)),"")) | L13: =IF($B13="","",IFERROR(INDEX(Inputs!$H$7:$H$156,MATCH($B13,Inputs!$C$7:$C$156,0)),"")) | M13: =IF($A13="","",IF(OR($E13="",$K13="",$L13=""),"N",IF(OR($E13<$K13,$E13>$L13),"Y","N"))) | N13: =IF($A13="","",IF(Inputs!G170="","",Inputs!G170)) | O13: =IF($A13="","",IF($D13<>"CHARGEABLE","",SUMIFS($E$7:$E$156,$B$7:$B$156,$B13,$D$7:$D$156,"CHARGEABLE",$C$7:$C$156,"<>",$E$7:$E$156,">=0",$F$7:$F$156,"<>"))) | P13: =IF($A13="","",IF($D13<>"CHARGEABLE",IF(OR($D13="NON_PUBLIC_RESEARCH",$D13="CAPITAL",$D13="PENALTIES",$D13="RECOVERED_ELSEWHERE"),0,""),IF(OR($C13="",$E13="",$F13="",$I13="",$J13="",$O13<=0),"",$E13/$O13))) | Q13: =IF($A13="","",IF($D13<>"CHARGEABLE",IF(OR($D13="NON_PUBLIC_RESEARCH",$D13="CAPITAL",$D13="PENALTIES",$D13="RECOVERED_ELSEWHERE"),0,""),IF(OR($P13="",$I13=""),"",$I13*$P13))) | R13: =IF($A13="","",IF($D13<>"CHARGEABLE",IF(OR($D13="NON_PUBLIC_RESEARCH",$D13="CAPITAL",$D13="PENALTIES",$D13="RECOVERED_ELSEWHERE"),0,""),IF($P13="","",ROUND($P13*100,1)/100))) | S13: =IF($A13="","",IF($D13<>"CHARGEABLE",IF(OR($D13="NON_PUBLIC_RESEARCH",$D13="CAPITAL",$D13="PENALTIES",$D13="RECOVERED_ELSEWHERE"),0,""),IF($Q13="","",ROUND($Q13,0)))) | T13: =IF($A13="","",IF(OR($J13="EQUIPMENT_HOURS",$J13="STAFF_HOURS",$J13="FLOOR_AREA"),"Y",IF($J13="METERED","N",""))) | U13: =IF($A13="","",IF($D13="CHARGEABLE","N",IF(OR($D13="NON_PUBLIC_RESEARCH",$D13="CAPITAL",$D13="PENALTIES",$D13="RECOVERED_ELSEWHERE"),"Y",""))) | V13: =IF(OR($G13="",$C13=""),"",$G13&"|"&$C13) | W13: =IF($A13="","",IF($B13="","Missing Cost Pool ID",IF($C13="","Missing Program Code",IF($D13="","Missing Scope Code",IF(AND($D13<>"CHARGEABLE",$D13<>"NON_PUBLIC_RESEARCH",$D13<>"CAPITAL",$D13<>"PENALTIES",$D13<>"RECOVERED_ELSEWHERE"),"Invalid Scope Code",IF($G13="","Missing Methodology ID",IF($J13="","Pool basis unresolved",IF(AND($B13<>"",$C13<>"",COUNTIFS($B$7:$B$156,$B13,$C$7:$C$156,$C13)>1),"Duplicate Cost Pool / Program",IF(AND($V13<>"",COUNTIF($V$7:$V$156,$V13)>1),"Duplicate Methodology / Program",IF(AND($D13="CHARGEABLE",$E13=""),"Missing usage quantity",IF(AND($D13="CHARGEABLE",$F13=""),"Missing evidence reference",IF(AND($D13="CHARGEABLE",NOT(ISNUMBER($E13))),"Usage quantity not numeric",IF(AND($D13="CHARGEABLE",$E13<0),"Usage quantity is negative",IF(AND($U13="Y",Inputs!$H$170=""),"Missing exclusion note","OK")))))))))))))) | X13: =IF($A13="","",IFERROR(INDEX(Checks!$O$7:$O$156,MATCH($B13,Checks!$B$7:$B$156,0)),"FAIL")) | Y13: =IF($A13="","",IFERROR(INDEX(Checks!$Q$7:$Q$156,MATCH($B13,Checks!$B$7:$B$156,0)),"FAIL")) | Z13: =IF($A13="","",IF(OR($Q13="",Publication_Import!$F13=""),"FAIL",IF(ABS($Q13-Publication_Import!$F13)<=0.000001,"PASS","FAIL"))) | AA13: =IF($A13="","",IF(AND($W13="OK",$X13="PASS",$Y13="PASS",$Z13="PASS",IFERROR(INDEX(Checks!$S$7:$S$156,MATCH($B13,Checks!$B$7:$B$156,0)),"HOLD")="READY"),"READY","HOLD")) | AB13: =IF($A13="","",IF($AA13="READY","Ready for publication import",IF($W13<>"OK",$W13,IFERROR(INDEX(Checks!$T$7:$T$156,MATCH($B13,Checks!$B$7:$B$156,0)),"Add a valid cost pool"))))
A14: =IF(COUNTA(Inputs!$A$171:$H$171)>0,"Y","") | B14: =IF(Inputs!A171="","",Inputs!A171) | C14: =IF(Inputs!B171="","",Inputs!B171) | D14: =IF(Inputs!D171="","",Inputs!D171) | E14: =IF(Inputs!E171="","",Inputs!E171) | F14: =IF(Inputs!F171="","",Inputs!F171) | G14: =IF($B14="","",IFERROR(INDEX(Inputs!$A$7:$A$156,MATCH($B14,Inputs!$C$7:$C$156,0)),"")) | H14: =IF($B14="","",IFERROR(INDEX(Inputs!$B$7:$B$156,MATCH($B14,Inputs!$C$7:$C$156,0)),"")) | I14: =IF($B14="","",IFERROR(INDEX(Inputs!$E$7:$E$156,MATCH($B14,Inputs!$C$7:$C$156,0)),"")) | J14: =IF($B14="","",IFERROR(INDEX(Inputs!$F$7:$F$156,MATCH($B14,Inputs!$C$7:$C$156,0)),"")) | K14: =IF($B14="","",IFERROR(INDEX(Inputs!$G$7:$G$156,MATCH($B14,Inputs!$C$7:$C$156,0)),"")) | L14: =IF($B14="","",IFERROR(INDEX(Inputs!$H$7:$H$156,MATCH($B14,Inputs!$C$7:$C$156,0)),"")) | M14: =IF($A14="","",IF(OR($E14="",$K14="",$L14=""),"N",IF(OR($E14<$K14,$E14>$L14),"Y","N"))) | N14: =IF($A14="","",IF(Inputs!G171="","",Inputs!G171)) | O14: =IF($A14="","",IF($D14<>"CHARGEABLE","",SUMIFS($E$7:$E$156,$B$7:$B$156,$B14,$D$7:$D$156,"CHARGEABLE",$C$7:$C$156,"<>",$E$7:$E$156,">=0",$F$7:$F$156,"<>"))) | P14: =IF($A14="","",IF($D14<>"CHARGEABLE",IF(OR($D14="NON_PUBLIC_RESEARCH",$D14="CAPITAL",$D14="PENALTIES",$D14="RECOVERED_ELSEWHERE"),0,""),IF(OR($C14="",$E14="",$F14="",$I14="",$J14="",$O14<=0),"",$E14/$O14))) | Q14: =IF($A14="","",IF($D14<>"CHARGEABLE",IF(OR($D14="NON_PUBLIC_RESEARCH",$D14="CAPITAL",$D14="PENALTIES",$D14="RECOVERED_ELSEWHERE"),0,""),IF(OR($P14="",$I14=""),"",$I14*$P14))) | R14: =IF($A14="","",IF($D14<>"CHARGEABLE",IF(OR($D14="NON_PUBLIC_RESEARCH",$D14="CAPITAL",$D14="PENALTIES",$D14="RECOVERED_ELSEWHERE"),0,""),IF($P14="","",ROUND($P14*100,1)/100))) | S14: =IF($A14="","",IF($D14<>"CHARGEABLE",IF(OR($D14="NON_PUBLIC_RESEARCH",$D14="CAPITAL",$D14="PENALTIES",$D14="RECOVERED_ELSEWHERE"),0,""),IF($Q14="","",ROUND($Q14,0)))) | T14: =IF($A14="","",IF(OR($J14="EQUIPMENT_HOURS",$J14="STAFF_HOURS",$J14="FLOOR_AREA"),"Y",IF($J14="METERED","N",""))) | U14: =IF($A14="","",IF($D14="CHARGEABLE","N",IF(OR($D14="NON_PUBLIC_RESEARCH",$D14="CAPITAL",$D14="PENALTIES",$D14="RECOVERED_ELSEWHERE"),"Y",""))) | V14: =IF(OR($G14="",$C14=""),"",$G14&"|"&$C14) | W14: =IF($A14="","",IF($B14="","Missing Cost Pool ID",IF($C14="","Missing Program Code",IF($D14="","Missing Scope Code",IF(AND($D14<>"CHARGEABLE",$D14<>"NON_PUBLIC_RESEARCH",$D14<>"CAPITAL",$D14<>"PENALTIES",$D14<>"RECOVERED_ELSEWHERE"),"Invalid Scope Code",IF($G14="","Missing Methodology ID",IF($J14="","Pool basis unresolved",IF(AND($B14<>"",$C14<>"",COUNTIFS($B$7:$B$156,$B14,$C$7:$C$156,$C14)>1),"Duplicate Cost Pool / Program",IF(AND($V14<>"",COUNTIF($V$7:$V$156,$V14)>1),"Duplicate Methodology / Program",IF(AND($D14="CHARGEABLE",$E14=""),"Missing usage quantity",IF(AND($D14="CHARGEABLE",$F14=""),"Missing evidence reference",IF(AND($D14="CHARGEABLE",NOT(ISNUMBER($E14))),"Usage quantity not numeric",IF(AND($D14="CHARGEABLE",$E14<0),"Usage quantity is negative",IF(AND($U14="Y",Inputs!$H$171=""),"Missing exclusion note","OK")))))))))))))) | X14: =IF($A14="","",IFERROR(INDEX(Checks!$O$7:$O$156,MATCH($B14,Checks!$B$7:$B$156,0)),"FAIL")) | Y14: =IF($A14="","",IFERROR(INDEX(Checks!$Q$7:$Q$156,MATCH($B14,Checks!$B$7:$B$156,0)),"FAIL")) | Z14: =IF($A14="","",IF(OR($Q14="",Publication_Import!$F14=""),"FAIL",IF(ABS($Q14-Publication_Import!$F14)<=0.000001,"PASS","FAIL"))) | AA14: =IF($A14="","",IF(AND($W14="OK",$X14="PASS",$Y14="PASS",$Z14="PASS",IFERROR(INDEX(Checks!$S$7:$S$156,MATCH($B14,Checks!$B$7:$B$156,0)),"HOLD")="READY"),"READY","HOLD")) | AB14: =IF($A14="","",IF($AA14="READY","Ready for publication import",IF($W14<>"OK",$W14,IFERROR(INDEX(Checks!$T$7:$T$156,MATCH($B14,Checks!$B$7:$B$156,0)),"Add a valid cost pool"))))
A15: =IF(COUNTA(Inputs!$A$172:$H$172)>0,"Y","") | B15: =IF(Inputs!A172="","",Inputs!A172) | C15: =IF(Inputs!B172="","",Inputs!B172) | D15: =IF(Inputs!D172="","",Inputs!D172) | E15: =IF(Inputs!E172="","",Inputs!E172) | F15: =IF(Inputs!F172="","",Inputs!F172) | G15: =IF($B15="","",IFERROR(INDEX(Inputs!$A$7:$A$156,MATCH($B15,Inputs!$C$7:$C$156,0)),"")) | H15: =IF($B15="","",IFERROR(INDEX(Inputs!$B$7:$B$156,MATCH($B15,Inputs!$C$7:$C$156,0)),"")) | I15: =IF($B15="","",IFERROR(INDEX(Inputs!$E$7:$E$156,MATCH($B15,Inputs!$C$7:$C$156,0)),"")) | J15: =IF($B15="","",IFERROR(INDEX(Inputs!$F$7:$F$156,MATCH($B15,Inputs!$C$7:$C$156,0)),"")) | K15: =IF($B15="","",IFERROR(INDEX(Inputs!$G$7:$G$156,MATCH($B15,Inputs!$C$7:$C$156,0)),"")) | L15: =IF($B15="","",IFERROR(INDEX(Inputs!$H$7:$H$156,MATCH($B15,Inputs!$C$7:$C$156,0)),"")) | M15: =IF($A15="","",IF(OR($E15="",$K15="",$L15=""),"N",IF(OR($E15<$K15,$E15>$L15),"Y","N"))) | N15: =IF($A15="","",IF(Inputs!G172="","",Inputs!G172)) | O15: =IF($A15="","",IF($D15<>"CHARGEABLE","",SUMIFS($E$7:$E$156,$B$7:$B$156,$B15,$D$7:$D$156,"CHARGEABLE",$C$7:$C$156,"<>",$E$7:$E$156,">=0",$F$7:$F$156,"<>"))) | P15: =IF($A15="","",IF($D15<>"CHARGEABLE",IF(OR($D15="NON_PUBLIC_RESEARCH",$D15="CAPITAL",$D15="PENALTIES",$D15="RECOVERED_ELSEWHERE"),0,""),IF(OR($C15="",$E15="",$F15="",$I15="",$J15="",$O15<=0),"",$E15/$O15))) | Q15: =IF($A15="","",IF($D15<>"CHARGEABLE",IF(OR($D15="NON_PUBLIC_RESEARCH",$D15="CAPITAL",$D15="PENALTIES",$D15="RECOVERED_ELSEWHERE"),0,""),IF(OR($P15="",$I15=""),"",$I15*$P15))) | R15: =IF($A15="","",IF($D15<>"CHARGEABLE",IF(OR($D15="NON_PUBLIC_RESEARCH",$D15="CAPITAL",$D15="PENALTIES",$D15="RECOVERED_ELSEWHERE"),0,""),IF($P15="","",ROUND($P15*100,1)/100))) | S15: =IF($A15="","",IF($D15<>"CHARGEABLE",IF(OR($D15="NON_PUBLIC_RESEARCH",$D15="CAPITAL",$D15="PENALTIES",$D15="RECOVERED_ELSEWHERE"),0,""),IF($Q15="","",ROUND($Q15,0)))) | T15: =IF($A15="","",IF(OR($J15="EQUIPMENT_HOURS",$J15="STAFF_HOURS",$J15="FLOOR_AREA"),"Y",IF($J15="METERED","N",""))) | U15: =IF($A15="","",IF($D15="CHARGEABLE","N",IF(OR($D15="NON_PUBLIC_RESEARCH",$D15="CAPITAL",$D15="PENALTIES",$D15="RECOVERED_ELSEWHERE"),"Y",""))) | V15: =IF(OR($G15="",$C15=""),"",$G15&"|"&$C15) | W15: =IF($A15="","",IF($B15="","Missing Cost Pool ID",IF($C15="","Missing Program Code",IF($D15="","Missing Scope Code",IF(AND($D15<>"CHARGEABLE",$D15<>"NON_PUBLIC_RESEARCH",$D15<>"CAPITAL",$D15<>"PENALTIES",$D15<>"RECOVERED_ELSEWHERE"),"Invalid Scope Code",IF($G15="","Missing Methodology ID",IF($J15="","Pool basis unresolved",IF(AND($B15<>"",$C15<>"",COUNTIFS($B$7:$B$156,$B15,$C$7:$C$156,$C15)>1),"Duplicate Cost Pool / Program",IF(AND($V15<>"",COUNTIF($V$7:$V$156,$V15)>1),"Duplicate Methodology / Program",IF(AND($D15="CHARGEABLE",$E15=""),"Missing usage quantity",IF(AND($D15="CHARGEABLE",$F15=""),"Missing evidence reference",IF(AND($D15="CHARGEABLE",NOT(ISNUMBER($E15))),"Usage quantity not numeric",IF(AND($D15="CHARGEABLE",$E15<0),"Usage quantity is negative",IF(AND($U15="Y",Inputs!$H$172=""),"Missing exclusion note","OK")))))))))))))) | X15: =IF($A15="","",IFERROR(INDEX(Checks!$O$7:$O$156,MATCH($B15,Checks!$B$7:$B$156,0)),"FAIL")) | Y15: =IF($A15="","",IFERROR(INDEX(Checks!$Q$7:$Q$156,MATCH($B15,Checks!$B$7:$B$156,0)),"FAIL")) | Z15: =IF($A15="","",IF(OR($Q15="",Publication_Import!$F15=""),"FAIL",IF(ABS($Q15-Publication_Import!$F15)<=0.000001,"PASS","FAIL"))) | AA15: =IF($A15="","",IF(AND($W15="OK",$X15="PASS",$Y15="PASS",$Z15="PASS",IFERROR(INDEX(Checks!$S$7:$S$156,MATCH($B15,Checks!$B$7:$B$156,0)),"HOLD")="READY"),"READY","HOLD")) | AB15: =IF($A15="","",IF($AA15="READY","Ready for publication import",IF($W15<>"OK",$W15,IFERROR(INDEX(Checks!$T$7:$T$156,MATCH($B15,Checks!$B$7:$B$156,0)),"Add a valid cost pool"))))
A16: =IF(COUNTA(Inputs!$A$173:$H$173)>0,"Y","") | B16: =IF(Inputs!A173="","",Inputs!A173) | C16: =IF(Inputs!B173="","",Inputs!B173) | D16: =IF(Inputs!D173="","",Inputs!D173) | E16: =IF(Inputs!E173="","",Inputs!E173) | F16: =IF(Inputs!F173="","",Inputs!F173) | G16: =IF($B16="","",IFERROR(INDEX(Inputs!$A$7:$A$156,MATCH($B16,Inputs!$C$7:$C$156,0)),"")) | H16: =IF($B16="","",IFERROR(INDEX(Inputs!$B$7:$B$156,MATCH($B16,Inputs!$C$7:$C$156,0)),"")) | I16: =IF($B16="","",IFERROR(INDEX(Inputs!$E$7:$E$156,MATCH($B16,Inputs!$C$7:$C$156,0)),"")) | J16: =IF($B16="","",IFERROR(INDEX(Inputs!$F$7:$F$156,MATCH($B16,Inputs!$C$7:$C$156,0)),"")) | K16: =IF($B16="","",IFERROR(INDEX(Inputs!$G$7:$G$156,MATCH($B16,Inputs!$C$7:$C$156,0)),"")) | L16: =IF($B16="","",IFERROR(INDEX(Inputs!$H$7:$H$156,MATCH($B16,Inputs!$C$7:$C$156,0)),"")) | M16: =IF($A16="","",IF(OR($E16="",$K16="",$L16=""),"N",IF(OR($E16<$K16,$E16>$L16),"Y","N"))) | N16: =IF($A16="","",IF(Inputs!G173="","",Inputs!G173)) | O16: =IF($A16="","",IF($D16<>"CHARGEABLE","",SUMIFS($E$7:$E$156,$B$7:$B$156,$B16,$D$7:$D$156,"CHARGEABLE",$C$7:$C$156,"<>",$E$7:$E$156,">=0",$F$7:$F$156,"<>"))) | P16: =IF($A16="","",IF($D16<>"CHARGEABLE",IF(OR($D16="NON_PUBLIC_RESEARCH",$D16="CAPITAL",$D16="PENALTIES",$D16="RECOVERED_ELSEWHERE"),0,""),IF(OR($C16="",$E16="",$F16="",$I16="",$J16="",$O16<=0),"",$E16/$O16))) | Q16: =IF($A16="","",IF($D16<>"CHARGEABLE",IF(OR($D16="NON_PUBLIC_RESEARCH",$D16="CAPITAL",$D16="PENALTIES",$D16="RECOVERED_ELSEWHERE"),0,""),IF(OR($P16="",$I16=""),"",$I16*$P16))) | R16: =IF($A16="","",IF($D16<>"CHARGEABLE",IF(OR($D16="NON_PUBLIC_RESEARCH",$D16="CAPITAL",$D16="PENALTIES",$D16="RECOVERED_ELSEWHERE"),0,""),IF($P16="","",ROUND($P16*100,1)/100))) | S16: =IF($A16="","",IF($D16<>"CHARGEABLE",IF(OR($D16="NON_PUBLIC_RESEARCH",$D16="CAPITAL",$D16="PENALTIES",$D16="RECOVERED_ELSEWHERE"),0,""),IF($Q16="","",ROUND($Q16,0)))) | T16: =IF($A16="","",IF(OR($J16="EQUIPMENT_HOURS",$J16="STAFF_HOURS",$J16="FLOOR_AREA"),"Y",IF($J16="METERED","N",""))) | U16: =IF($A16="","",IF($D16="CHARGEABLE","N",IF(OR($D16="NON_PUBLIC_RESEARCH",$D16="CAPITAL",$D16="PENALTIES",$D16="RECOVERED_ELSEWHERE"),"Y",""))) | V16: =IF(OR($G16="",$C16=""),"",$G16&"|"&$C16) | W16: =IF($A16="","",IF($B16="","Missing Cost Pool ID",IF($C16="","Missing Program Code",IF($D16="","Missing Scope Code",IF(AND($D16<>"CHARGEABLE",$D16<>"NON_PUBLIC_RESEARCH",$D16<>"CAPITAL",$D16<>"PENALTIES",$D16<>"RECOVERED_ELSEWHERE"),"Invalid Scope Code",IF($G16="","Missing Methodology ID",IF($J16="","Pool basis unresolved",IF(AND($B16<>"",$C16<>"",COUNTIFS($B$7:$B$156,$B16,$C$7:$C$156,$C16)>1),"Duplicate Cost Pool / Program",IF(AND($V16<>"",COUNTIF($V$7:$V$156,$V16)>1),"Duplicate Methodology / Program",IF(AND($D16="CHARGEABLE",$E16=""),"Missing usage quantity",IF(AND($D16="CHARGEABLE",$F16=""),"Missing evidence reference",IF(AND($D16="CHARGEABLE",NOT(ISNUMBER($E16))),"Usage quantity not numeric",IF(AND($D16="CHARGEABLE",$E16<0),"Usage quantity is negative",IF(AND($U16="Y",Inputs!$H$173=""),"Missing exclusion note","OK")))))))))))))) | X16: =IF($A16="","",IFERROR(INDEX(Checks!$O$7:$O$156,MATCH($B16,Checks!$B$7:$B$156,0)),"FAIL")) | Y16: =IF($A16="","",IFERROR(INDEX(Checks!$Q$7:$Q$156,MATCH($B16,Checks!$B$7:$B$156,0)),"FAIL")) | Z16: =IF($A16="","",IF(OR($Q16="",Publication_Import!$F16=""),"FAIL",IF(ABS($Q16-Publication_Import!$F16)<=0.000001,"PASS","FAIL"))) | AA16: =IF($A16="","",IF(AND($W16="OK",$X16="PASS",$Y16="PASS",$Z16="PASS",IFERROR(INDEX(Checks!$S$7:$S$156,MATCH($B16,Checks!$B$7:$B$156,0)),"HOLD")="READY"),"READY","HOLD")) | AB16: =IF($A16="","",IF($AA16="READY","Ready for publication import",IF($W16<>"OK",$W16,IFERROR(INDEX(Checks!$T$7:$T$156,MATCH($B16,Checks!$B$7:$B$156,0)),"Add a valid cost pool"))))
A17: =IF(COUNTA(Inputs!$A$174:$H$174)>0,"Y","") | B17: =IF(Inputs!A174="","",Inputs!A174) | C17: =IF(Inputs!B174="","",Inputs!B174) | D17: =IF(Inputs!D174="","",Inputs!D174) | E17: =IF(Inputs!E174="","",Inputs!E174) | F17: =IF(Inputs!F174="","",Inputs!F174) | G17: =IF($B17="","",IFERROR(INDEX(Inputs!$A$7:$A$156,MATCH($B17,Inputs!$C$7:$C$156,0)),"")) | H17: =IF($B17="","",IFERROR(INDEX(Inputs!$B$7:$B$156,MATCH($B17,Inputs!$C$7:$C$156,0)),"")) | I17: =IF($B17="","",IFERROR(INDEX(Inputs!$E$7:$E$156,MATCH($B17,Inputs!$C$7:$C$156,0)),"")) | J17: =IF($B17="","",IFERROR(INDEX(Inputs!$F$7:$F$156,MATCH($B17,Inputs!$C$7:$C$156,0)),"")) | K17: =IF($B17="","",IFERROR(INDEX(Inputs!$G$7:$G$156,MATCH($B17,Inputs!$C$7:$C$156,0)),"")) | L17: =IF($B17="","",IFERROR(INDEX(Inputs!$H$7:$H$156,MATCH($B17,Inputs!$C$7:$C$156,0)),"")) | M17: =IF($A17="","",IF(OR($E17="",$K17="",$L17=""),"N",IF(OR($E17<$K17,$E17>$L17),"Y","N"))) | N17: =IF($A17="","",IF(Inputs!G174="","",Inputs!G174)) | O17: =IF($A17="","",IF($D17<>"CHARGEABLE","",SUMIFS($E$7:$E$156,$B$7:$B$156,$B17,$D$7:$D$156,"CHARGEABLE",$C$7:$C$156,"<>",$E$7:$E$156,">=0",$F$7:$F$156,"<>"))) | P17: =IF($A17="","",IF($D17<>"CHARGEABLE",IF(OR($D17="NON_PUBLIC_RESEARCH",$D17="CAPITAL",$D17="PENALTIES",$D17="RECOVERED_ELSEWHERE"),0,""),IF(OR($C17="",$E17="",$F17="",$I17="",$J17="",$O17<=0),"",$E17/$O17))) | Q17: =IF($A17="","",IF($D17<>"CHARGEABLE",IF(OR($D17="NON_PUBLIC_RESEARCH",$D17="CAPITAL",$D17="PENALTIES",$D17="RECOVERED_ELSEWHERE"),0,""),IF(OR($P17="",$I17=""),"",$I17*$P17))) | R17: =IF($A17="","",IF($D17<>"CHARGEABLE",IF(OR($D17="NON_PUBLIC_RESEARCH",$D17="CAPITAL",$D17="PENALTIES",$D17="RECOVERED_ELSEWHERE"),0,""),IF($P17="","",ROUND($P17*100,1)/100))) | S17: =IF($A17="","",IF($D17<>"CHARGEABLE",IF(OR($D17="NON_PUBLIC_RESEARCH",$D17="CAPITAL",$D17="PENALTIES",$D17="RECOVERED_ELSEWHERE"),0,""),IF($Q17="","",ROUND($Q17,0)))) | T17: =IF($A17="","",IF(OR($J17="EQUIPMENT_HOURS",$J17="STAFF_HOURS",$J17="FLOOR_AREA"),"Y",IF($J17="METERED","N",""))) | U17: =IF($A17="","",IF($D17="CHARGEABLE","N",IF(OR($D17="NON_PUBLIC_RESEARCH",$D17="CAPITAL",$D17="PENALTIES",$D17="RECOVERED_ELSEWHERE"),"Y",""))) | V17: =IF(OR($G17="",$C17=""),"",$G17&"|"&$C17) | W17: =IF($A17="","",IF($B17="","Missing Cost Pool ID",IF($C17="","Missing Program Code",IF($D17="","Missing Scope Code",IF(AND($D17<>"CHARGEABLE",$D17<>"NON_PUBLIC_RESEARCH",$D17<>"CAPITAL",$D17<>"PENALTIES",$D17<>"RECOVERED_ELSEWHERE"),"Invalid Scope Code",IF($G17="","Missing Methodology ID",IF($J17="","Pool basis unresolved",IF(AND($B17<>"",$C17<>"",COUNTIFS($B$7:$B$156,$B17,$C$7:$C$156,$C17)>1),"Duplicate Cost Pool / Program",IF(AND($V17<>"",COUNTIF($V$7:$V$156,$V17)>1),"Duplicate Methodology / Program",IF(AND($D17="CHARGEABLE",$E17=""),"Missing usage quantity",IF(AND($D17="CHARGEABLE",$F17=""),"Missing evidence reference",IF(AND($D17="CHARGEABLE",NOT(ISNUMBER($E17))),"Usage quantity not numeric",IF(AND($D17="CHARGEABLE",$E17<0),"Usage quantity is negative",IF(AND($U17="Y",Inputs!$H$174=""),"Missing exclusion note","OK")))))))))))))) | X17: =IF($A17="","",IFERROR(INDEX(Checks!$O$7:$O$156,MATCH($B17,Checks!$B$7:$B$156,0)),"FAIL")) | Y17: =IF($A17="","",IFERROR(INDEX(Checks!$Q$7:$Q$156,MATCH($B17,Checks!$B$7:$B$156,0)),"FAIL")) | Z17: =IF($A17="","",IF(OR($Q17="",Publication_Import!$F17=""),"FAIL",IF(ABS($Q17-Publication_Import!$F17)<=0.000001,"PASS","FAIL"))) | AA17: =IF($A17="","",IF(AND($W17="OK",$X17="PASS",$Y17="PASS",$Z17="PASS",IFERROR(INDEX(Checks!$S$7:$S$156,MATCH($B17,Checks!$B$7:$B$156,0)),"HOLD")="READY"),"READY","HOLD")) | AB17: =IF($A17="","",IF($AA17="READY","Ready for publication import",IF($W17<>"OK",$W17,IFERROR(INDEX(Checks!$T$7:$T$156,MATCH($B17,Checks!$B$7:$B$156,0)),"Add a valid cost pool"))))
A18: =IF(COUNTA(Inputs!$A$175:$H$175)>0,"Y","") | B18: =IF(Inputs!A175="","",Inputs!A175) | C18: =IF(Inputs!B175="","",Inputs!B175) | D18: =IF(Inputs!D175="","",Inputs!D175) | E18: =IF(Inputs!E175="","",Inputs!E175) | F18: =IF(Inputs!F175="","",Inputs!F175) | G18: =IF($B18="","",IFERROR(INDEX(Inputs!$A$7:$A$156,MATCH($B18,Inputs!$C$7:$C$156,0)),"")) | H18: =IF($B18="","",IFERROR(INDEX(Inputs!$B$7:$B$156,MATCH($B18,Inputs!$C$7:$C$156,0)),"")) | I18: =IF($B18="","",IFERROR(INDEX(Inputs!$E$7:$E$156,MATCH($B18,Inputs!$C$7:$C$156,0)),"")) | J18: =IF($B18="","",IFERROR(INDEX(Inputs!$F$7:$F$156,MATCH($B18,Inputs!$C$7:$C$156,0)),"")) | K18: =IF($B18="","",IFERROR(INDEX(Inputs!$G$7:$G$156,MATCH($B18,Inputs!$C$7:$C$156,0)),"")) | L18: =IF($B18="","",IFERROR(INDEX(Inputs!$H$7:$H$156,MATCH($B18,Inputs!$C$7:$C$156,0)),"")) | M18: =IF($A18="","",IF(OR($E18="",$K18="",$L18=""),"N",IF(OR($E18<$K18,$E18>$L18),"Y","N"))) | N18: =IF($A18="","",IF(Inputs!G175="","",Inputs!G175)) | O18: =IF($A18="","",IF($D18<>"CHARGEABLE","",SUMIFS($E$7:$E$156,$B$7:$B$156,$B18,$D$7:$D$156,"CHARGEABLE",$C$7:$C$156,"<>",$E$7:$E$156,">=0",$F$7:$F$156,"<>"))) | P18: =IF($A18="","",IF($D18<>"CHARGEABLE",IF(OR($D18="NON_PUBLIC_RESEARCH",$D18="CAPITAL",$D18="PENALTIES",$D18="RECOVERED_ELSEWHERE"),0,""),IF(OR($C18="",$E18="",$F18="",$I18="",$J18="",$O18<=0),"",$E18/$O18))) | Q18: =IF($A18="","",IF($D18<>"CHARGEABLE",IF(OR($D18="NON_PUBLIC_RESEARCH",$D18="CAPITAL",$D18="PENALTIES",$D18="RECOVERED_ELSEWHERE"),0,""),IF(OR($P18="",$I18=""),"",$I18*$P18))) | R18: =IF($A18="","",IF($D18<>"CHARGEABLE",IF(OR($D18="NON_PUBLIC_RESEARCH",$D18="CAPITAL",$D18="PENALTIES",$D18="RECOVERED_ELSEWHERE"),0,""),IF($P18="","",ROUND($P18*100,1)/100))) | S18: =IF($A18="","",IF($D18<>"CHARGEABLE",IF(OR($D18="NON_PUBLIC_RESEARCH",$D18="CAPITAL",$D18="PENALTIES",$D18="RECOVERED_ELSEWHERE"),0,""),IF($Q18="","",ROUND($Q18,0)))) | T18: =IF($A18="","",IF(OR($J18="EQUIPMENT_HOURS",$J18="STAFF_HOURS",$J18="FLOOR_AREA"),"Y",IF($J18="METERED","N",""))) | U18: =IF($A18="","",IF($D18="CHARGEABLE","N",IF(OR($D18="NON_PUBLIC_RESEARCH",$D18="CAPITAL",$D18="PENALTIES",$D18="RECOVERED_ELSEWHERE"),"Y",""))) | V18: =IF(OR($G18="",$C18=""),"",$G18&"|"&$C18) | W18: =IF($A18="","",IF($B18="","Missing Cost Pool ID",IF($C18="","Missing Program Code",IF($D18="","Missing Scope Code",IF(AND($D18<>"CHARGEABLE",$D18<>"NON_PUBLIC_RESEARCH",$D18<>"CAPITAL",$D18<>"PENALTIES",$D18<>"RECOVERED_ELSEWHERE"),"Invalid Scope Code",IF($G18="","Missing Methodology ID",IF($J18="","Pool basis unresolved",IF(AND($B18<>"",$C18<>"",COUNTIFS($B$7:$B$156,$B18,$C$7:$C$156,$C18)>1),"Duplicate Cost Pool / Program",IF(AND($V18<>"",COUNTIF($V$7:$V$156,$V18)>1),"Duplicate Methodology / Program",IF(AND($D18="CHARGEABLE",$E18=""),"Missing usage quantity",IF(AND($D18="CHARGEABLE",$F18=""),"Missing evidence reference",IF(AND($D18="CHARGEABLE",NOT(ISNUMBER($E18))),"Usage quantity not numeric",IF(AND($D18="CHARGEABLE",$E18<0),"Usage quantity is negative",IF(AND($U18="Y",Inputs!$H$175=""),"Missing exclusion note","OK")))))))))))))) | X18: =IF($A18="","",IFERROR(INDEX(Checks!$O$7:$O$156,MATCH($B18,Checks!$B$7:$B$156,0)),"FAIL")) | Y18: =IF($A18="","",IFERROR(INDEX(Checks!$Q$7:$Q$156,MATCH($B18,Checks!$B$7:$B$156,0)),"FAIL")) | Z18: =IF($A18="","",IF(OR($Q18="",Publication_Import!$F18=""),"FAIL",IF(ABS($Q18-Publication_Import!$F18)<=0.000001,"PASS","FAIL"))) | AA18: =IF($A18="","",IF(AND($W18="OK",$X18="PASS",$Y18="PASS",$Z18="PASS",IFERROR(INDEX(Checks!$S$7:$S$156,MATCH($B18,Checks!$B$7:$B$156,0)),"HOLD")="READY"),"READY","HOLD")) | AB18: =IF($A18="","",IF($AA18="READY","Ready for publication import",IF($W18<>"OK",$W18,IFERROR(INDEX(Checks!$T$7:$T$156,MATCH($B18,Checks!$B$7:$B$156,0)),"Add a valid cost pool"))))
A19: =IF(COUNTA(Inputs!$A$176:$H$176)>0,"Y","") | B19: =IF(Inputs!A176="","",Inputs!A176) | C19: =IF(Inputs!B176="","",Inputs!B176) | D19: =IF(Inputs!D176="","",Inputs!D176) | E19: =IF(Inputs!E176="","",Inputs!E176) | F19: =IF(Inputs!F176="","",Inputs!F176) | G19: =IF($B19="","",IFERROR(INDEX(Inputs!$A$7:$A$156,MATCH($B19,Inputs!$C$7:$C$156,0)),"")) | H19: =IF($B19="","",IFERROR(INDEX(Inputs!$B$7:$B$156,MATCH($B19,Inputs!$C$7:$C$156,0)),"")) | I19: =IF($B19="","",IFERROR(INDEX(Inputs!$E$7:$E$156,MATCH($B19,Inputs!$C$7:$C$156,0)),"")) | J19: =IF($B19="","",IFERROR(INDEX(Inputs!$F$7:$F$156,MATCH($B19,Inputs!$C$7:$C$156,0)),"")) | K19: =IF($B19="","",IFERROR(INDEX(Inputs!$G$7:$G$156,MATCH($B19,Inputs!$C$7:$C$156,0)),"")) | L19: =IF($B19="","",IFERROR(INDEX(Inputs!$H$7:$H$156,MATCH($B19,Inputs!$C$7:$C$156,0)),"")) | M19: =IF($A19="","",IF(OR($E19="",$K19="",$L19=""),"N",IF(OR($E19<$K19,$E19>$L19),"Y","N"))) | N19: =IF($A19="","",IF(Inputs!G176="","",Inputs!G176)) | O19: =IF($A19="","",IF($D19<>"CHARGEABLE","",SUMIFS($E$7:$E$156,$B$7:$B$156,$B19,$D$7:$D$156,"CHARGEABLE",$C$7:$C$156,"<>",$E$7:$E$156,">=0",$F$7:$F$156,"<>"))) | P19: =IF($A19="","",IF($D19<>"CHARGEABLE",IF(OR($D19="NON_PUBLIC_RESEARCH",$D19="CAPITAL",$D19="PENALTIES",$D19="RECOVERED_ELSEWHERE"),0,""),IF(OR($C19="",$E19="",$F19="",$I19="",$J19="",$O19<=0),"",$E19/$O19))) | Q19: =IF($A19="","",IF($D19<>"CHARGEABLE",IF(OR($D19="NON_PUBLIC_RESEARCH",$D19="CAPITAL",$D19="PENALTIES",$D19="RECOVERED_ELSEWHERE"),0,""),IF(OR($P19="",$I19=""),"",$I19*$P19))) | R19: =IF($A19="","",IF($D19<>"CHARGEABLE",IF(OR($D19="NON_PUBLIC_RESEARCH",$D19="CAPITAL",$D19="PENALTIES",$D19="RECOVERED_ELSEWHERE"),0,""),IF($P19="","",ROUND($P19*100,1)/100))) | S19: =IF($A19="","",IF($D19<>"CHARGEABLE",IF(OR($D19="NON_PUBLIC_RESEARCH",$D19="CAPITAL",$D19="PENALTIES",$D19="RECOVERED_ELSEWHERE"),0,""),IF($Q19="","",ROUND($Q19,0)))) | T19: =IF($A19="","",IF(OR($J19="EQUIPMENT_HOURS",$J19="STAFF_HOURS",$J19="FLOOR_AREA"),"Y",IF($J19="METERED","N",""))) | U19: =IF($A19="","",IF($D19="CHARGEABLE","N",IF(OR($D19="NON_PUBLIC_RESEARCH",$D19="CAPITAL",$D19="PENALTIES",$D19="RECOVERED_ELSEWHERE"),"Y",""))) | V19: =IF(OR($G19="",$C19=""),"",$G19&"|"&$C19) | W19: =IF($A19="","",IF($B19="","Missing Cost Pool ID",IF($C19="","Missing Program Code",IF($D19="","Missing Scope Code",IF(AND($D19<>"CHARGEABLE",$D19<>"NON_PUBLIC_RESEARCH",$D19<>"CAPITAL",$D19<>"PENALTIES",$D19<>"RECOVERED_ELSEWHERE"),"Invalid Scope Code",IF($G19="","Missing Methodology ID",IF($J19="","Pool basis unresolved",IF(AND($B19<>"",$C19<>"",COUNTIFS($B$7:$B$156,$B19,$C$7:$C$156,$C19)>1),"Duplicate Cost Pool / Program",IF(AND($V19<>"",COUNTIF($V$7:$V$156,$V19)>1),"Duplicate Methodology / Program",IF(AND($D19="CHARGEABLE",$E19=""),"Missing usage quantity",IF(AND($D19="CHARGEABLE",$F19=""),"Missing evidence reference",IF(AND($D19="CHARGEABLE",NOT(ISNUMBER($E19))),"Usage quantity not numeric",IF(AND($D19="CHARGEABLE",$E19<0),"Usage quantity is negative",IF(AND($U19="Y",Inputs!$H$176=""),"Missing exclusion note","OK")))))))))))))) | X19: =IF($A19="","",IFERROR(INDEX(Checks!$O$7:$O$156,MATCH($B19,Checks!$B$7:$B$156,0)),"FAIL")) | Y19: =IF($A19="","",IFERROR(INDEX(Checks!$Q$7:$Q$156,MATCH($B19,Checks!$B$7:$B$156,0)),"FAIL")) | Z19: =IF($A19="","",IF(OR($Q19="",Publication_Import!$F19=""),"FAIL",IF(ABS($Q19-Publication_Import!$F19)<=0.000001,"PASS","FAIL"))) | AA19: =IF($A19="","",IF(AND($W19="OK",$X19="PASS",$Y19="PASS",$Z19="PASS",IFERROR(INDEX(Checks!$S$7:$S$156,MATCH($B19,Checks!$B$7:$B$156,0)),"HOLD")="READY"),"READY","HOLD")) | AB19: =IF($A19="","",IF($AA19="READY","Ready for publication import",IF($W19<>"OK",$W19,IFERROR(INDEX(Checks!$T$7:$T$156,MATCH($B19,Checks!$B$7:$B$156,0)),"Add a valid cost pool"))))
