Workbook

Sheet Slip Plan
A1: CUTWATER BASIN 2027 | SLIP PLAN
A2: Working assignment register. Every D Dock slip is unavailable through 31 May 2027; planned occupancy begins after activation.
A4: Slip ID | B4: Dock | C4: Zone | D4: Usable Length ft | E4: Max Beam ft | F4: Outlet | G4: Circuit Group | H4: Circuit Capacity A | I4: Accessible Flag | J4: Disposition | K4: Availability / Closure | L4: Assigned Applicant ID | M4: Boat ID | N4: Boat Length ft | O4: Boat Beam ft | P4: Requested Service | Q4: Demand A | R4: Liveaboard | S4: Effective Occupancy | T4: Fit / Timing Result
A5: A-01 | B5: A | C5: North | D5: 38 | E5: 11 | F5: NONE | G5: FG-01 | H5: 200 | I5: Y | J5: ACCESSIBLE RESERVE | K5: Normal operating window | M5: =IFERROR(VLOOKUP($L5,'Applicant Outcomes'!$A$5:$P$85,2,FALSE()),"") | N5: =IFERROR(VLOOKUP($L5,'Applicant Outcomes'!$A$5:$P$85,7,FALSE()),"") | O5: =IFERROR(VLOOKUP($L5,'Applicant Outcomes'!$A$5:$P$85,8,FALSE()),"") | P5: =IFERROR(VLOOKUP($L5,'Applicant Outcomes'!$A$5:$P$85,9,FALSE()),"") | Q5: =IF(P5="50A",50,IF(P5="30A",30,0)) -> 0 | R5: =IFERROR(VLOOKUP($L5,'Applicant Outcomes'!$A$5:$P$85,10,FALSE()),"") | T5: =IF(J5="ACCESSIBLE RESERVE",IF(L5="","PASS","FAIL - RESERVE OCCUPIED"),IF(L5="","PASS",IF(AND(N5<=D5,O5<=E5,OR(P5="NONE",AND(P5="30A",OR(F5="30A",F5="50A")),AND(P5="50A",F5="50A")),OR(B5<>"D",S5>=DATE(2027,6,1))),"PASS","FAIL"))) -> PASS
A6: A-02 | B6: A | C6: North | D6: 38 | E6: 11 | F6: 30A | G6: FG-01 | H6: 200 | I6: N | J6: ASSIGNED | K6: Normal operating window | L6: R008 | M6: =IFERROR(VLOOKUP($L6,'Applicant Outcomes'!$A$5:$P$85,2,FALSE()),"") -> Boat-R008 | N6: =IFERROR(VLOOKUP($L6,'Applicant Outcomes'!$A$5:$P$85,7,FALSE()),"") -> 30 | O6: =IFERROR(VLOOKUP($L6,'Applicant Outcomes'!$A$5:$P$85,8,FALSE()),"") -> 10 | P6: =IFERROR(VLOOKUP($L6,'Applicant Outcomes'!$A$5:$P$85,9,FALSE()),"") -> 30A | Q6: =IF(P6="50A",50,IF(P6="30A",30,0)) -> 30 | R6: =IFERROR(VLOOKUP($L6,'Applicant Outcomes'!$A$5:$P$85,10,FALSE()),"") -> Y | S6: 46447 | T6: =IF(J6="ACCESSIBLE RESERVE",IF(L6="","PASS","FAIL - RESERVE OCCUPIED"),IF(L6="","PASS",IF(AND(N6<=D6,O6<=E6,OR(P6="NONE",AND(P6="30A",OR(F6="30A",F6="50A")),AND(P6="50A",F6="50A")),OR(B6<>"D",S6>=DATE(2027,6,1))),"PASS","FAIL"))) -> PASS
A7: A-03 | B7: A | C7: North | D7: 38 | E7: 12 | F7: 50A | G7: FG-01 | H7: 200 | I7: N | J7: ASSIGNED | K7: Normal operating window | L7: R006 | M7: =IFERROR(VLOOKUP($L7,'Applicant Outcomes'!$A$5:$P$85,2,FALSE()),"") -> Boat-R006 | N7: =IFERROR(VLOOKUP($L7,'Applicant Outcomes'!$A$5:$P$85,7,FALSE()),"") -> 30 | O7: =IFERROR(VLOOKUP($L7,'Applicant Outcomes'!$A$5:$P$85,8,FALSE()),"") -> 10 | P7: =IFERROR(VLOOKUP($L7,'Applicant Outcomes'!$A$5:$P$85,9,FALSE()),"") -> 50A | Q7: =IF(P7="50A",50,IF(P7="30A",30,0)) -> 50 | R7: =IFERROR(VLOOKUP($L7,'Applicant Outcomes'!$A$5:$P$85,10,FALSE()),"") -> N | S7: 46447 | T7: =IF(J7="ACCESSIBLE RESERVE",IF(L7="","PASS","FAIL - RESERVE OCCUPIED"),IF(L7="","PASS",IF(AND(N7<=D7,O7<=E7,OR(P7="NONE",AND(P7="30A",OR(F7="30A",F7="50A")),AND(P7="50A",F7="50A")),OR(B7<>"D",S7>=DATE(2027,6,1))),"PASS","FAIL"))) -> PASS
A8: A-04 | B8: A | C8: North | D8: 38 | E8: 11 | F8: 30A | G8: FG-01 | H8: 200 | I8: N | J8: ASSIGNED | K8: Normal operating window | L8: R016 | M8: =IFERROR(VLOOKUP($L8,'Applicant Outcomes'!$A$5:$P$85,2,FALSE()),"") -> Boat-R016 | N8: =IFERROR(VLOOKUP($L8,'Applicant Outcomes'!$A$5:$P$85,7,FALSE()),"") -> 30 | O8: =IFERROR(VLOOKUP($L8,'Applicant Outcomes'!$A$5:$P$85,8,FALSE()),"") -> 10 | P8: =IFERROR(VLOOKUP($L8,'Applicant Outcomes'!$A$5:$P$85,9,FALSE()),"") -> 30A | Q8: =IF(P8="50A",50,IF(P8="30A",30,0)) -> 30 | R8: =IFERROR(VLOOKUP($L8,'Applicant Outcomes'!$A$5:$P$85,10,FALSE()),"") -> Y | S8: 46447 | T8: =IF(J8="ACCESSIBLE RESERVE",IF(L8="","PASS","FAIL - RESERVE OCCUPIED"),IF(L8="","PASS",IF(AND(N8<=D8,O8<=E8,OR(P8="NONE",AND(P8="30A",OR(F8="30A",F8="50A")),AND(P8="50A",F8="50A")),OR(B8<>"D",S8>=DATE(2027,6,1))),"PASS","FAIL"))) -> PASS
A9: A-05 | B9: A | C9: North | D9: 38 | E9: 11 | F9: NONE | G9: FG-02 | H9: 200 | I9: N | J9: ASSIGNED | K9: Normal operating window | L9: R013 | M9: =IFERROR(VLOOKUP($L9,'Applicant Outcomes'!$A$5:$P$85,2,FALSE()),"") -> Boat-R013 | N9: =IFERROR(VLOOKUP($L9,'Applicant Outcomes'!$A$5:$P$85,7,FALSE()),"") -> 30 | O9: =IFERROR(VLOOKUP($L9,'Applicant Outcomes'!$A$5:$P$85,8,FALSE()),"") -> 10 | P9: =IFERROR(VLOOKUP($L9,'Applicant Outcomes'!$A$5:$P$85,9,FALSE()),"") -> NONE | Q9: =IF(P9="50A",50,IF(P9="30A",30,0)) -> 0 | R9: =IFERROR(VLOOKUP($L9,'Applicant Outcomes'!$A$5:$P$85,10,FALSE()),"") -> N | S9: 46447 | T9: =IF(J9="ACCESSIBLE RESERVE",IF(L9="","PASS","FAIL - RESERVE OCCUPIED"),IF(L9="","PASS",IF(AND(N9<=D9,O9<=E9,OR(P9="NONE",AND(P9="30A",OR(F9="30A",F9="50A")),AND(P9="50A",F9="50A")),OR(B9<>"D",S9>=DATE(2027,6,1))),"PASS","FAIL"))) -> PASS
A10: A-06 | B10: A | C10: North | D10: 38 | E10: 12 | F10: 50A | G10: FG-02 | H10: 200 | I10: N | J10: ASSIGNED | K10: Normal operating window | L10: R012 | M10: =IFERROR(VLOOKUP($L10,'Applicant Outcomes'!$A$5:$P$85,2,FALSE()),"") -> Boat-R012 | N10: =IFERROR(VLOOKUP($L10,'Applicant Outcomes'!$A$5:$P$85,7,FALSE()),"") -> 30 | O10: =IFERROR(VLOOKUP($L10,'Applicant Outcomes'!$A$5:$P$85,8,FALSE()),"") -> 10 | P10: =IFERROR(VLOOKUP($L10,'Applicant Outcomes'!$A$5:$P$85,9,FALSE()),"") -> 50A | Q10: =IF(P10="50A",50,IF(P10="30A",30,0)) -> 50 | R10: =IFERROR(VLOOKUP($L10,'Applicant Outcomes'!$A$5:$P$85,10,FALSE()),"") -> Y | S10: 46447 | T10: =IF(J10="ACCESSIBLE RESERVE",IF(L10="","PASS","FAIL - RESERVE OCCUPIED"),IF(L10="","PASS",IF(AND(N10<=D10,O10<=E10,OR(P10="NONE",AND(P10="30A",OR(F10="30A",F10="50A")),AND(P10="50A",F10="50A")),OR(B10<>"D",S10>=DATE(2027,6,1))),"PASS","FAIL"))) -> PASS
A11: A-07 | B11: A | C11: North | D11: 38 | E11: 11 | F11: NONE | G11: FG-02 | H11: 200 | I11: N | J11: ASSIGNED | K11: Normal operating window | L11: R017 | M11: =IFERROR(VLOOKUP($L11,'Applicant Outcomes'!$A$5:$P$85,2,FALSE()),"") -> Boat-R017 | N11: =IFERROR(VLOOKUP($L11,'Applicant Outcomes'!$A$5:$P$85,7,FALSE()),"") -> 30 | O11: =IFERROR(VLOOKUP($L11,'Applicant Outcomes'!$A$5:$P$85,8,FALSE()),"") -> 10 | P11: =IFERROR(VLOOKUP($L11,'Applicant Outcomes'!$A$5:$P$85,9,FALSE()),"") -> NONE | Q11: =IF(P11="50A",50,IF(P11="30A",30,0)) -> 0 | R11: =IFERROR(VLOOKUP($L11,'Applicant Outcomes'!$A$5:$P$85,10,FALSE()),"") -> N | S11: 46447 | T11: =IF(J11="ACCESSIBLE RESERVE",IF(L11="","PASS","FAIL - RESERVE OCCUPIED"),IF(L11="","PASS",IF(AND(N11<=D11,O11<=E11,OR(P11="NONE",AND(P11="30A",OR(F11="30A",F11="50A")),AND(P11="50A",F11="50A")),OR(B11<>"D",S11>=DATE(2027,6,1))),"PASS","FAIL"))) -> PASS
A12: A-08 | B12: A | C12: North | D12: 38 | E12: 11 | F12: 30A | G12: FG-02 | H12: 200 | I12: N | J12: ASSIGNED | K12: Normal operating window | L12: R026 | M12: =IFERROR(VLOOKUP($L12,'Applicant Outcomes'!$A$5:$P$85,2,FALSE()),"") -> Boat-R026 | N12: =IFERROR(VLOOKUP($L12,'Applicant Outcomes'!$A$5:$P$85,7,FALSE()),"") -> 30 | O12: =IFERROR(VLOOKUP($L12,'Applicant Outcomes'!$A$5:$P$85,8,FALSE()),"") -> 10 | P12: =IFERROR(VLOOKUP($L12,'Applicant Outcomes'!$A$5:$P$85,9,FALSE()),"") -> 30A | Q12: =IF(P12="50A",50,IF(P12="30A",30,0)) -> 30 | R12: =IFERROR(VLOOKUP($L12,'Applicant Outcomes'!$A$5:$P$85,10,FALSE()),"") -> N | S12: 46447 | T12: =IF(J12="ACCESSIBLE RESERVE",IF(L12="","PASS","FAIL - RESERVE OCCUPIED"),IF(L12="","PASS",IF(AND(N12<=D12,O12<=E12,OR(P12="NONE",AND(P12="30A",OR(F12="30A",F12="50A")),AND(P12="50A",F12="50A")),OR(B12<>"D",S12>=DATE(2027,6,1))),"PASS","FAIL"))) -> PASS
A13: A-09 | B13: A | C13: South | D13: 38 | E13: 12 | F13: 50A | G13: FG-03 | H13: 200 | I13: N | J13: ASSIGNED | K13: Normal operating window | L13: R018 | M13: =IFERROR(VLOOKUP($L13,'Applicant Outcomes'!$A$5:$P$85,2,FALSE()),"") -> Boat-R018 | N13: =IFERROR(VLOOKUP($L13,'Applicant Outcomes'!$A$5:$P$85,7,FALSE()),"") -> 30 | O13: =IFERROR(VLOOKUP($L13,'Applicant Outcomes'!$A$5:$P$85,8,FALSE()),"") -> 10 | P13: =IFERROR(VLOOKUP($L13,'Applicant Outcomes'!$A$5:$P$85,9,FALSE()),"") -> 50A | Q13: =IF(P13="50A",50,IF(P13="30A",30,0)) -> 50 | R13: =IFERROR(VLOOKUP($L13,'Applicant Outcomes'!$A$5:$P$85,10,FALSE()),"") -> N | S13: 46447 | T13: =IF(J13="ACCESSIBLE RESERVE",IF(L13="","PASS","FAIL - RESERVE OCCUPIED"),IF(L13="","PASS",IF(AND(N13<=D13,O13<=E13,OR(P13="NONE",AND(P13="30A",OR(F13="30A",F13="50A")),AND(P13="50A",F13="50A")),OR(B13<>"D",S13>=DATE(2027,6,1))),"PASS","FAIL"))) -> PASS
A14: A-10 | B14: A | C14: South | D14: 38 | E14: 11 | F14: 30A | G14: FG-03 | H14: 200 | I14: N | J14: ASSIGNED | K14: Normal operating window | L14: R004 | M14: =IFERROR(VLOOKUP($L14,'Applicant Outcomes'!$A$5:$P$85,2,FALSE()),"") -> Boat-R004 | N14: =IFERROR(VLOOKUP($L14,'Applicant Outcomes'!$A$5:$P$85,7,FALSE()),"") -> 30 | O14: =IFERROR(VLOOKUP($L14,'Applicant Outcomes'!$A$5:$P$85,8,FALSE()),"") -> 10 | P14: =IFERROR(VLOOKUP($L14,'Applicant Outcomes'!$A$5:$P$85,9,FALSE()),"") -> 30A | Q14: =IF(P14="50A",50,IF(P14="30A",30,0)) -> 30 | R14: =IFERROR(VLOOKUP($L14,'Applicant Outcomes'!$A$5:$P$85,10,FALSE()),"") -> Y | S14: 46447 | T14: =IF(J14="ACCESSIBLE RESERVE",IF(L14="","PASS","FAIL - RESERVE OCCUPIED"),IF(L14="","PASS",IF(AND(N14<=D14,O14<=E14,OR(P14="NONE",AND(P14="30A",OR(F14="30A",F14="50A")),AND(P14="50A",F14="50A")),OR(B14<>"D",S14>=DATE(2027,6,1))),"PASS","FAIL"))) -> PASS
A15: A-11 | B15: A | C15: South | D15: 38 | E15: 11 | F15: NONE | G15: FG-03 | H15: 200 | I15: N | J15: ASSIGNED | K15: Normal operating window | L15: R003 | M15: =IFERROR(VLOOKUP($L15,'Applicant Outcomes'!$A$5:$P$85,2,FALSE()),"") -> Boat-R003 | N15: =IFERROR(VLOOKUP($L15,'Applicant Outcomes'!$A$5:$P$85,7,FALSE()),"") -> 30 | O15: =IFERROR(VLOOKUP($L15,'Applicant Outcomes'!$A$5:$P$85,8,FALSE()),"") -> 10 | P15: =IFERROR(VLOOKUP($L15,'Applicant Outcomes'!$A$5:$P$85,9,FALSE()),"") -> NONE | Q15: =IF(P15="50A",50,IF(P15="30A",30,0)) -> 0 | R15: =IFERROR(VLOOKUP($L15,'Applicant Outcomes'!$A$5:$P$85,10,FALSE()),"") -> N | S15: 46447 | T15: =IF(J15="ACCESSIBLE RESERVE",IF(L15="","PASS","FAIL - RESERVE OCCUPIED"),IF(L15="","PASS",IF(AND(N15<=D15,O15<=E15,OR(P15="NONE",AND(P15="30A",OR(F15="30A",F15="50A")),AND(P15="50A",F15="50A")),OR(B15<>"D",S15>=DATE(2027,6,1))),"PASS","FAIL"))) -> PASS
A16: A-12 | B16: A | C16: South | D16: 38 | E16: 12 | F16: 50A | G16: FG-03 | H16: 200 | I16: N | J16: ASSIGNED | K16: Normal operating window | L16: R024 | M16: =IFERROR(VLOOKUP($L16,'Applicant Outcomes'!$A$5:$P$85,2,FALSE()),"") -> Boat-R024 | N16: =IFERROR(VLOOKUP($L16,'Applicant Outcomes'!$A$5:$P$85,7,FALSE()),"") -> 30 | O16: =IFERROR(VLOOKUP($L16,'Applicant Outcomes'!$A$5:$P$85,8,FALSE()),"") -> 10 | P16: =IFERROR(VLOOKUP($L16,'Applicant Outcomes'!$A$5:$P$85,9,FALSE()),"") -> 50A | Q16: =IF(P16="50A",50,IF(P16="30A",30,0)) -> 50 | R16: =IFERROR(VLOOKUP($L16,'Applicant Outcomes'!$A$5:$P$85,10,FALSE()),"") -> Y | S16: 46447 | T16: =IF(J16="ACCESSIBLE RESERVE",IF(L16="","PASS","FAIL - RESERVE OCCUPIED"),IF(L16="","PASS",IF(AND(N16<=D16,O16<=E16,OR(P16="NONE",AND(P16="30A",OR(F16="30A",F16="50A")),AND(P16="50A",F16="50A")),OR(B16<>"D",S16>=DATE(2027,6,1))),"PASS","FAIL"))) -> PASS
A17: A-13 | B17: A | C17: South | D17: 38 | E17: 11 | F17: NONE | G17: FG-04 | H17: 200 | I17: N | J17: ASSIGNED | K17: Normal operating window | L17: R007 | M17: =IFERROR(VLOOKUP($L17,'Applicant Outcomes'!$A$5:$P$85,2,FALSE()),"") -> Boat-R007 | N17: =IFERROR(VLOOKUP($L17,'Applicant Outcomes'!$A$5:$P$85,7,FALSE()),"") -> 36 | O17: =IFERROR(VLOOKUP($L17,'Applicant Outcomes'!$A$5:$P$85,8,FALSE()),"") -> 10 | P17: =IFERROR(VLOOKUP($L17,'Applicant Outcomes'!$A$5:$P$85,9,FALSE()),"") -> NONE | Q17: =IF(P17="50A",50,IF(P17="30A",30,0)) -> 0 | R17: =IFERROR(VLOOKUP($L17,'Applicant Outcomes'!$A$5:$P$85,10,FALSE()),"") -> N | S17: 46447 | T17: =IF(J17="ACCESSIBLE RESERVE",IF(L17="","PASS","FAIL - RESERVE OCCUPIED"),IF(L17="","PASS",IF(AND(N17<=D17,O17<=E17,OR(P17="NONE",AND(P17="30A",OR(F17="30A",F17="50A")),AND(P17="50A",F17="50A")),OR(B17<>"D",S17>=DATE(2027,6,1))),"PASS","FAIL"))) -> PASS
... A36: B-16 | B36: B | C36: South | D36: 43 | E36: 13 | F36: 50A | G36: FG-08 | H36: 200 | I36: N | J36: ASSIGNED | K36: Normal operating window | L36: R002 | M36: =IFERROR(VLOOKUP($L36,'Applicant Outcomes'!$A$5:$P$85,2,FALSE()),"") -> Boat-R002 | N36: =IFERROR(VLOOKUP($L36,'Applicant Outcomes'!$A$5:$P$85,7,FALSE()),"") -> 42 | O36: =IFERROR(VLOOKUP($L36,'Applicant Outcomes'!$A$5:$P$85,8,FALSE()),"") -> 12.5 | P36: =IFERROR(VLOOKUP($L36,'Applicant Outcomes'!$A$5:$P$85,9,FALSE()),"") -> 50A | Q36: =IF(P36="50A",50,IF(P36="30A",30,0)) -> 50 | R36: =IFERROR(VLOOKUP($L36,'Applicant Outcomes'!$A$5:$P$85,10,FALSE()),"") -> N | S36: 46447 | T36: =IF(J36="ACCESSIBLE RESERVE",IF(L36="","PASS","FAIL - RESERVE OCCUPIED"),IF(L36="","PASS",IF(AND(N36<=D36,O36<=E36,OR(P36="NONE",AND(P36="30A",OR(F36="30A",F36="50A")),AND(P36="50A",F36="50A")),OR(B36<>"D",S36>=DATE(2027,6,1))),"PASS","FAIL"))) -> PASS
A37: C-01 | B37: C | C37: North | D37: 38 | E37: 11 | F37: NONE | G37: FG-09 | H37: 200 | I37: Y | J37: ACCESSIBLE RESERVE | K37: Normal operating window | M37: =IFERROR(VLOOKUP($L37,'Applicant Outcomes'!$A$5:$P$85,2,FALSE()),"") | N37: =IFERROR(VLOOKUP($L37,'Applicant Outcomes'!$A$5:$P$85,7,FALSE()),"") | O37: =IFERROR(VLOOKUP($L37,'Applicant Outcomes'!$A$5:$P$85,8,FALSE()),"") | P37: =IFERROR(VLOOKUP($L37,'Applicant Outcomes'!$A$5:$P$85,9,FALSE()),"") | Q37: =IF(P37="50A",50,IF(P37="30A",30,0)) -> 0 | R37: =IFERROR(VLOOKUP($L37,'Applicant Outcomes'!$A$5:$P$85,10,FALSE()),"") | T37: =IF(J37="ACCESSIBLE RESERVE",IF(L37="","PASS","FAIL - RESERVE OCCUPIED"),IF(L37="","PASS",IF(AND(N37<=D37,O37<=E37,OR(P37="NONE",AND(P37="30A",OR(F37="30A",F37="50A")),AND(P37="50A",F37="50A")),OR(B37<>"D",S37>=DATE(2027,6,1))),"PASS","FAIL"))) -> PASS
A38: C-02 | B38: C | C38: North | D38: 38 | E38: 11 | F38: 30A | G38: FG-09 | H38: 200 | I38: N | J38: ASSIGNED | K38: Normal operating window | L38: R044 | M38: =IFERROR(VLOOKUP($L38,'Applicant Outcomes'!$A$5:$P$85,2,FALSE()),"") -> Boat-R044 | N38: =IFERROR(VLOOKUP($L38,'Applicant Outcomes'!$A$5:$P$85,7,FALSE()),"") -> 30 | O38: =IFERROR(VLOOKUP($L38,'Applicant Outcomes'!$A$5:$P$85,8,FALSE()),"") -> 10 | P38: =IFERROR(VLOOKUP($L38,'Applicant Outcomes'!$A$5:$P$85,9,FALSE()),"") -> 30A | Q38: =IF(P38="50A",50,IF(P38="30A",30,0)) -> 30 | R38: =IFERROR(VLOOKUP($L38,'Applicant Outcomes'!$A$5:$P$85,10,FALSE()),"") -> Y | S38: 46447 | T38: =IF(J38="ACCESSIBLE RESERVE",IF(L38="","PASS","FAIL - RESERVE OCCUPIED"),IF(L38="","PASS",IF(AND(N38<=D38,O38<=E38,OR(P38="NONE",AND(P38="30A",OR(F38="30A",F38="50A")),AND(P38="50A",F38="50A")),OR(B38<>"D",S38>=DATE(2027,6,1))),"PASS","FAIL"))) -> PASS
A39: C-03 | B39: C | C39: North | D39: 38 | E39: 12 | F39: 50A | G39: FG-09 | H39: 200 | I39: N | J39: ASSIGNED | K39: Normal operating window | L39: R020 | M39: =IFERROR(VLOOKUP($L39,'Applicant Outcomes'!$A$5:$P$85,2,FALSE()),"") -> Boat-R020 | N39: =IFERROR(VLOOKUP($L39,'Applicant Outcomes'!$A$5:$P$85,7,FALSE()),"") -> 30 | O39: =IFERROR(VLOOKUP($L39,'Applicant Outcomes'!$A$5:$P$85,8,FALSE()),"") -> 11.5 | P39: =IFERROR(VLOOKUP($L39,'Applicant Outcomes'!$A$5:$P$85,9,FALSE()),"") -> 30A | Q39: =IF(P39="50A",50,IF(P39="30A",30,0)) -> 30 | R39: =IFERROR(VLOOKUP($L39,'Applicant Outcomes'!$A$5:$P$85,10,FALSE()),"") -> Y | S39: 46447 | T39: =IF(J39="ACCESSIBLE RESERVE",IF(L39="","PASS","FAIL - RESERVE OCCUPIED"),IF(L39="","PASS",IF(AND(N39<=D39,O39<=E39,OR(P39="NONE",AND(P39="30A",OR(F39="30A",F39="50A")),AND(P39="50A",F39="50A")),OR(B39<>"D",S39>=DATE(2027,6,1))),"PASS","FAIL"))) -> PASS
A40: C-04 | B40: C | C40: North | D40: 38 | E40: 11 | F40: 30A | G40: FG-09 | H40: 200 | I40: N | J40: ASSIGNED | K40: Normal operating window | L40: R046 | M40: =IFERROR(VLOOKUP($L40,'Applicant Outcomes'!$A$5:$P$85,2,FALSE()),"") -> Boat-R046 | N40: =IFERROR(VLOOKUP($L40,'Applicant Outcomes'!$A$5:$P$85,7,FALSE()),"") -> 30 | O40: =IFERROR(VLOOKUP($L40,'Applicant Outcomes'!$A$5:$P$85,8,FALSE()),"") -> 10 | P40: =IFERROR(VLOOKUP($L40,'Applicant Outcomes'!$A$5:$P$85,9,FALSE()),"") -> 30A | Q40: =IF(P40="50A",50,IF(P40="30A",30,0)) -> 30 | R40: =IFERROR(VLOOKUP($L40,'Applicant Outcomes'!$A$5:$P$85,10,FALSE()),"") -> N | S40: 46447 | T40: =IF(J40="ACCESSIBLE RESERVE",IF(L40="","PASS","FAIL - RESERVE OCCUPIED"),IF(L40="","PASS",IF(AND(N40<=D40,O40<=E40,OR(P40="NONE",AND(P40="30A",OR(F40="30A",F40="50A")),AND(P40="50A",F40="50A")),OR(B40<>"D",S40>=DATE(2027,6,1))),"PASS","FAIL"))) -> PASS
A41: C-05 | B41: C | C41: North | D41: 38 | E41: 11 | F41: NONE | G41: FG-10 | H41: 200 | I41: N | J41: ASSIGNED | K41: Normal operating window | L41: R027 | M41: =IFERROR(VLOOKUP($L41,'Applicant Outcomes'!$A$5:$P$85,2,FALSE()),"") -> Boat-R027 | N41: =IFERROR(VLOOKUP($L41,'Applicant Outcomes'!$A$5:$P$85,7,FALSE()),"") -> 30 | O41: =IFERROR(VLOOKUP($L41,'Applicant Outcomes'!$A$5:$P$85,8,FALSE()),"") -> 10 | P41: =IFERROR(VLOOKUP($L41,'Applicant Outcomes'!$A$5:$P$85,9,FALSE()),"") -> NONE | Q41: =IF(P41="50A",50,IF(P41="30A",30,0)) -> 0 | R41: =IFERROR(VLOOKUP($L41,'Applicant Outcomes'!$A$5:$P$85,10,FALSE()),"") -> N | S41: 46447 | T41: =IF(J41="ACCESSIBLE RESERVE",IF(L41="","PASS","FAIL - RESERVE OCCUPIED"),IF(L41="","PASS",IF(AND(N41<=D41,O41<=E41,OR(P41="NONE",AND(P41="30A",OR(F41="30A",F41="50A")),AND(P41="50A",F41="50A")),OR(B41<>"D",S41>=DATE(2027,6,1))),"PASS","FAIL"))) -> PASS
A42: C-06 | B42: C | C42: North | D42: 38 | E42: 12 | F42: 50A | G42: FG-10 | H42: 200 | I42: N | J42: ASSIGNED | K42: Normal operating window | L42: R040 | M42: =IFERROR(VLOOKUP($L42,'Applicant Outcomes'!$A$5:$P$85,2,FALSE()),"") -> Boat-R040 | N42: =IFERROR(VLOOKUP($L42,'Applicant Outcomes'!$A$5:$P$85,7,FALSE()),"") -> 30 | O42: =IFERROR(VLOOKUP($L42,'Applicant Outcomes'!$A$5:$P$85,8,FALSE()),"") -> 11.5 | P42: =IFERROR(VLOOKUP($L42,'Applicant Outcomes'!$A$5:$P$85,9,FALSE()),"") -> 30A | Q42: =IF(P42="50A",50,IF(P42="30A",30,0)) -> 30 | R42: =IFERROR(VLOOKUP($L42,'Applicant Outcomes'!$A$5:$P$85,10,FALSE()),"") -> Y | S42: 46447 | T42: =IF(J42="ACCESSIBLE RESERVE",IF(L42="","PASS","FAIL - RESERVE OCCUPIED"),IF(L42="","PASS",IF(AND(N42<=D42,O42<=E42,OR(P42="NONE",AND(P42="30A",OR(F42="30A",F42="50A")),AND(P42="50A",F42="50A")),OR(B42<>"D",S42>=DATE(2027,6,1))),"PASS","FAIL"))) -> PASS
A43: C-07 | B43: C | C43: North | D43: 38 | E43: 11 | F43: NONE | G43: FG-10 | H43: 200 | I43: N | J43: ASSIGNED | K43: Normal operating window | L43: R029 | M43: =IFERROR(VLOOKUP($L43,'Applicant Outcomes'!$A$5:$P$85,2,FALSE()),"") -> Boat-R029 | N43: =IFERROR(VLOOKUP($L43,'Applicant Outcomes'!$A$5:$P$85,7,FALSE()),"") -> 30 | O43: =IFERROR(VLOOKUP($L43,'Applicant Outcomes'!$A$5:$P$85,8,FALSE()),"") -> 10 | P43: =IFERROR(VLOOKUP($L43,'Applicant Outcomes'!$A$5:$P$85,9,FALSE()),"") -> NONE | Q43: =IF(P43="50A",50,IF(P43="30A",30,0)) -> 0 | R43: =IFERROR(VLOOKUP($L43,'Applicant Outcomes'!$A$5:$P$85,10,FALSE()),"") -> N | S43: 46447 | T43: =IF(J43="ACCESSIBLE RESERVE",IF(L43="","PASS","FAIL - RESERVE OCCUPIED"),IF(L43="","PASS",IF(AND(N43<=D43,O43<=E43,OR(P43="NONE",AND(P43="30A",OR(F43="30A",F43="50A")),AND(P43="50A",F43="50A")),OR(B43<>"D",S43>=DATE(2027,6,1))),"PASS","FAIL"))) -> PASS
A44: C-08 | B44: C | C44: South | D44: 38 | E44: 11 | F44: 30A | G44: FG-10 | H44: 200 | I44: N | J44: ASSIGNED | K44: Normal operating window | L44: W004 | M44: =IFERROR(VLOOKUP($L44,'Applicant Outcomes'!$A$5:$P$85,2,FALSE()),"") -> Boat-W004 | N44: =IFERROR(VLOOKUP($L44,'Applicant Outcomes'!$A$5:$P$85,7,FALSE()),"") -> 30 | O44: =IFERROR(VLOOKUP($L44,'Applicant Outcomes'!$A$5:$P$85,8,FALSE()),"") -> 10.5 | P44: =IFERROR(VLOOKUP($L44,'Applicant Outcomes'!$A$5:$P$85,9,FALSE()),"") -> 30A | Q44: =IF(P44="50A",50,IF(P44="30A",30,0)) -> 30 | R44: =IFERROR(VLOOKUP($L44,'Applicant Outcomes'!$A$5:$P$85,10,FALSE()),"") -> N | S44: 46447 | T44: =IF(J44="ACCESSIBLE RESERVE",IF(L44="","PASS","FAIL - RESERVE OCCUPIED"),IF(L44="","PASS",IF(AND(N44<=D44,O44<=E44,OR(P44="NONE",AND(P44="30A",OR(F44="30A",F44="50A")),AND(P44="50A",F44="50A")),OR(B44<>"D",S44>=DATE(2027,6,1))),"PASS","FAIL"))) -> PASS
A45: C-09 | B45: C | C45: South | D45: 38 | E45: 12 | F45: 50A | G45: FG-11 | H45: 200 | I45: N | J45: ASSIGNED | K45: Normal operating window | L45: R050 | M45: =IFERROR(VLOOKUP($L45,'Applicant Outcomes'!$A$5:$P$85,2,FALSE()),"") -> Boat-R050 | N45: =IFERROR(VLOOKUP($L45,'Applicant Outcomes'!$A$5:$P$85,7,FALSE()),"") -> 30 | O45: =IFERROR(VLOOKUP($L45,'Applicant Outcomes'!$A$5:$P$85,8,FALSE()),"") -> 11.5 | P45: =IFERROR(VLOOKUP($L45,'Applicant Outcomes'!$A$5:$P$85,9,FALSE()),"") -> 30A | Q45: =IF(P45="50A",50,IF(P45="30A",30,0)) -> 30 | R45: =IFERROR(VLOOKUP($L45,'Applicant Outcomes'!$A$5:$P$85,10,FALSE()),"") -> N | S45: 46447 | T45: =IF(J45="ACCESSIBLE RESERVE",IF(L45="","PASS","FAIL - RESERVE OCCUPIED"),IF(L45="","PASS",IF(AND(N45<=D45,O45<=E45,OR(P45="NONE",AND(P45="30A",OR(F45="30A",F45="50A")),AND(P45="50A",F45="50A")),OR(B45<>"D",S45>=DATE(2027,6,1))),"PASS","FAIL"))) -> PASS
A46: C-10 | B46: C | C46: South | D46: 38 | E46: 11 | F46: 30A | G46: FG-11 | H46: 200 | I46: N | J46: ASSIGNED | K46: Normal operating window | L46: W008 | M46: =IFERROR(VLOOKUP($L46,'Applicant Outcomes'!$A$5:$P$85,2,FALSE()),"") -> Boat-W008 | N46: =IFERROR(VLOOKUP($L46,'Applicant Outcomes'!$A$5:$P$85,7,FALSE()),"") -> 30 | O46: =IFERROR(VLOOKUP($L46,'Applicant Outcomes'!$A$5:$P$85,8,FALSE()),"") -> 10.5 | P46: =IFERROR(VLOOKUP($L46,'Applicant Outcomes'!$A$5:$P$85,9,FALSE()),"") -> 30A | Q46: =IF(P46="50A",50,IF(P46="30A",30,0)) -> 30 | R46: =IFERROR(VLOOKUP($L46,'Applicant Outcomes'!$A$5:$P$85,10,FALSE()),"") -> N | S46: 46447 | T46: =IF(J46="ACCESSIBLE RESERVE",IF(L46="","PASS","FAIL - RESERVE OCCUPIED"),IF(L46="","PASS",IF(AND(N46<=D46,O46<=E46,OR(P46="NONE",AND(P46="30A",OR(F46="30A",F46="50A")),AND(P46="50A",F46="50A")),OR(B46<>"D",S46>=DATE(2027,6,1))),"PASS","FAIL"))) -> PASS
A47: C-11 | B47: C | C47: South | D47: 38 | E47: 11 | F47: NONE | G47: FG-11 | H47: 200 | I47: N | J47: ASSIGNED | K47: Normal operating window | L47: R031 | M47: =IFERROR(VLOOKUP($L47,'Applicant Outcomes'!$A$5:$P$85,2,FALSE()),"") -> Boat-R031 | N47: =IFERROR(VLOOKUP($L47,'Applicant Outcomes'!$A$5:$P$85,7,FALSE()),"") -> 30 | O47: =IFERROR(VLOOKUP($L47,'Applicant Outcomes'!$A$5:$P$85,8,FALSE()),"") -> 10 | P47: =IFERROR(VLOOKUP($L47,'Applicant Outcomes'!$A$5:$P$85,9,FALSE()),"") -> NONE | Q47: =IF(P47="50A",50,IF(P47="30A",30,0)) -> 0 | R47: =IFERROR(VLOOKUP($L47,'Applicant Outcomes'!$A$5:$P$85,10,FALSE()),"") -> N | S47: 46447 | T47: =IF(J47="ACCESSIBLE RESERVE",IF(L47="","PASS","FAIL - RESERVE OCCUPIED"),IF(L47="","PASS",IF(AND(N47<=D47,O47<=E47,OR(P47="NONE",AND(P47="30A",OR(F47="30A",F47="50A")),AND(P47="50A",F47="50A")),OR(B47<>"D",S47>=DATE(2027,6,1))),"PASS","FAIL"))) -> PASS
A48: C-12 | B48: C | C48: South | D48: 38 | E48: 12 | F48: 50A | G48: FG-11 | H48: 200 | I48: N | J48: ASSIGNED | K48: Normal operating window | L48: R005 | M48: =IFERROR(VLOOKUP($L48,'Applicant Outcomes'!$A$5:$P$85,2,FALSE()),"") -> Boat-R005 | N48: =IFERROR(VLOOKUP($L48,'Applicant Outcomes'!$A$5:$P$85,7,FALSE()),"") -> 30 | O48: =IFERROR(VLOOKUP($L48,'Applicant Outcomes'!$A$5:$P$85,8,FALSE()),"") -> 11.5 | P48: =IFERROR(VLOOKUP($L48,'Applicant Outcomes'!$A$5:$P$85,9,FALSE()),"") -> NONE | Q48: =IF(P48="50A",50,IF(P48="30A",30,0)) -> 0 | R48: =IFERROR(VLOOKUP($L48,'Applicant Outcomes'!$A$5:$P$85,10,FALSE()),"") -> N | S48: 46447 | T48: =IF(J48="ACCESSIBLE RESERVE",IF(L48="","PASS","FAIL - RESERVE OCCUPIED"),IF(L48="","PASS",IF(AND(N48<=D48,O48<=E48,OR(P48="NONE",AND(P48="30A",OR(F48="30A",F48="50A")),AND(P48="50A",F48="50A")),OR(B48<>"D",S48>=DATE(2027,6,1))),"PASS","FAIL"))) -> PASS
A49: C-13 | B49: C | C49: South | D49: 38 | E49: 11 | F49: NONE | G49: FG-12 | H49: 200 | I49: N | J49: ASSIGNED | K49: Normal operating window | L49: R033 | M49: =IFERROR(VLOOKUP($L49,'Applicant Outcomes'!$A$5:$P$85,2,FALSE()),"") -> Boat-R033 | N49: =IFERROR(VLOOKUP($L49,'Applicant Outcomes'!$A$5:$P$85,7,FALSE()),"") -> 30 | O49: =IFERROR(VLOOKUP($L49,'Applicant Outcomes'!$A$5:$P$85,8,FALSE()),"") -> 10 | P49: =IFERROR(VLOOKUP($L49,'Applicant Outcomes'!$A$5:$P$85,9,FALSE()),"") -> NONE | Q49: =IF(P49="50A",50,IF(P49="30A",30,0)) -> 0 | R49: =IFERROR(VLOOKUP($L49,'Applicant Outcomes'!$A$5:$P$85,10,FALSE()),"") -> N | S49: 46447 | T49: =IF(J49="ACCESSIBLE RESERVE",IF(L49="","PASS","FAIL - RESERVE OCCUPIED"),IF(L49="","PASS",IF(AND(N49<=D49,O49<=E49,OR(P49="NONE",AND(P49="30A",OR(F49="30A",F49="50A")),AND(P49="50A",F49="50A")),OR(B49<>"D",S49>=DATE(2027,6,1))),"PASS","FAIL"))) -> PASS
... A78: E-12 | B78: E | C78: South | D78: 43 | E78: 13 | F78: 50A | G78: FG-19 | H78: 100 | I78: N | J78: ASSIGNED | K78: Normal operating window | L78: W005 | M78: =IFERROR(VLOOKUP($L78,'Applicant Outcomes'!$A$5:$P$85,2,FALSE()),"") -> Boat-W005 | N78: =IFERROR(VLOOKUP($L78,'Applicant Outcomes'!$A$5:$P$85,7,FALSE()),"") -> 30 | O78: =IFERROR(VLOOKUP($L78,'Applicant Outcomes'!$A$5:$P$85,8,FALSE()),"") -> 10.5 | P78: =IFERROR(VLOOKUP($L78,'Applicant Outcomes'!$A$5:$P$85,9,FALSE()),"") -> NONE | Q78: =IF(P78="50A",50,IF(P78="30A",30,0)) -> 0 | R78: =IFERROR(VLOOKUP($L78,'Applicant Outcomes'!$A$5:$P$85,10,FALSE()),"") -> Y | S78: 46447 | T78: =IF(J78="ACCESSIBLE RESERVE",IF(L78="","PASS","FAIL - RESERVE OCCUPIED"),IF(L78="","PASS",IF(AND(N78<=D78,O78<=E78,OR(P78="NONE",AND(P78="30A",OR(F78="30A",F78="50A")),AND(P78="50A",F78="50A")),OR(B78<>"D",S78>=DATE(2027,6,1))),"PASS","FAIL"))) -> PASS

Sheet Applicant Outcomes
A1: CUTWATER BASIN 2027 | APPLICANT OUTCOMES
A2: Definitive outcome register. Renewal priority and waitlist order applied under Annual Moorage Policy 2027.
A4: Applicant ID | B4: Boat ID | C4: Applicant Type | D4: Waitlist Rank | E4: Tie Break | F4: Eligibility Result | G4: Boat Length ft | H4: Beam ft | I4: Requested Service | J4: Liveaboard | K4: Dock Restriction | L4: Outcome | M4: Reason Code | N4: Assigned Slip | O4: Effective Occupancy | P4: Implementation Note
A5: R001 | B5: Boat-R001 | C5: RENEWAL | E5: 1 | F5: ELIGIBLE | G5: 42 | H5: 12.5 | I5: 50A | J5: N | K5: A | L5: ASSIGNED | M5: ASSIGNED | N5: A-16 | O5: 46447 | P5: Annual occupancy confirmed.
A6: R002 | B6: Boat-R002 | C6: RENEWAL | E6: 2 | F6: ELIGIBLE | G6: 42 | H6: 12.5 | I6: 50A | J6: N | K6: B | L6: ASSIGNED | M6: ASSIGNED | N6: B-16 | O6: 46447 | P6: Annual occupancy confirmed.
A7: R003 | B7: Boat-R003 | C7: RENEWAL | E7: 3 | F7: ELIGIBLE | G7: 30 | H7: 10 | I7: NONE | J7: N | L7: ASSIGNED | M7: ASSIGNED | N7: A-11 | O7: 46447 | P7: Annual occupancy confirmed.
A8: R004 | B8: Boat-R004 | C8: RENEWAL | E8: 4 | F8: ELIGIBLE | G8: 30 | H8: 10 | I8: 30A | J8: Y | L8: ASSIGNED | M8: ASSIGNED | N8: A-10 | O8: 46447 | P8: Annual occupancy confirmed.
A9: R005 | B9: Boat-R005 | C9: RENEWAL | E9: 5 | F9: ELIGIBLE | G9: 30 | H9: 11.5 | I9: NONE | J9: N | L9: ASSIGNED | M9: ASSIGNED | N9: C-12 | O9: 46447 | P9: Annual occupancy confirmed.
A10: R006 | B10: Boat-R006 | C10: RENEWAL | E10: 6 | F10: ELIGIBLE | G10: 30 | H10: 10 | I10: 50A | J10: N | L10: ASSIGNED | M10: ASSIGNED | N10: A-03 | O10: 46447 | P10: Annual occupancy confirmed.
A11: R007 | B11: Boat-R007 | C11: RENEWAL | E11: 7 | F11: ELIGIBLE | G11: 36 | H11: 10 | I11: NONE | J11: N | L11: ASSIGNED | M11: ASSIGNED | N11: A-13 | O11: 46447 | P11: Annual occupancy confirmed.
A12: R008 | B12: Boat-R008 | C12: RENEWAL | E12: 8 | F12: ELIGIBLE | G12: 30 | H12: 10 | I12: 30A | J12: Y | L12: ASSIGNED | M12: ASSIGNED | N12: A-02 | O12: 46447 | P12: Annual occupancy confirmed.
A13: R009 | B13: Boat-R009 | C13: RENEWAL | E13: 9 | F13: ELIGIBLE | G13: 30 | H13: 10 | I13: NONE | J13: N | L13: ASSIGNED | M13: ASSIGNED | N13: B-01 | O13: 46447 | P13: Annual occupancy confirmed.
A14: R010 | B14: Boat-R010 | C14: RENEWAL | E14: 10 | F14: ELIGIBLE | G14: 30 | H14: 11.5 | I14: 30A | J14: N | L14: ASSIGNED | M14: ASSIGNED | N14: B-12 | O14: 46447 | P14: Annual occupancy confirmed.
A15: R011 | B15: Boat-R011 | C15: RENEWAL | E15: 11 | F15: ELIGIBLE | G15: 30 | H15: 10 | I15: NONE | J15: N | L15: ASSIGNED | M15: ASSIGNED | N15: B-11 | O15: 46447 | P15: Annual occupancy confirmed.
A16: R012 | B16: Boat-R012 | C16: RENEWAL | E16: 12 | F16: ELIGIBLE | G16: 30 | H16: 10 | I16: 50A | J16: Y | L16: ASSIGNED | M16: ASSIGNED | N16: A-06 | O16: 46447 | P16: Annual occupancy confirmed.
A17: R013 | B17: Boat-R013 | C17: RENEWAL | E17: 13 | F17: ELIGIBLE | G17: 30 | H17: 10 | I17: NONE | J17: N | L17: ASSIGNED | M17: ASSIGNED | N17: A-05 | O17: 46447 | P17: Annual occupancy confirmed.
A18: R014 | B18: Boat-R014 | C18: RENEWAL | E18: 14 | F18: ELIGIBLE | G18: 36 | H18: 10 | I18: 30A | J18: N | L18: ASSIGNED | M18: ASSIGNED | N18: A-14 | O18: 46447 | P18: Annual occupancy confirmed.
... A54: R050 | B54: Boat-R050 | C54: RENEWAL | E54: 50 | F54: ELIGIBLE | G54: 30 | H54: 11.5 | I54: 30A | J54: N | L54: ASSIGNED | M54: ASSIGNED | N54: C-09 | O54: 46447 | P54: Annual occupancy confirmed.
A55: W001 | B55: Boat-W001 | C55: WAITLIST | D55: 1 | E55: 1 | F55: ELIGIBLE | G55: 42 | H55: 12.5 | I55: 50A | J55: N | K55: D | L55: ASSIGNED | M55: ASSIGNED | N55: D-16 | O55: 46539 | P55: Future D Dock occupancy after activation.
A56: W002 | B56: Boat-W002 | C56: WAITLIST | D56: 2 | E56: 2 | F56: ELIGIBLE | G56: 30 | H56: 10.5 | I56: 30A | J56: N | L56: ASSIGNED | M56: ASSIGNED | N56: D-04 | O56: 46539 | P56: Future D Dock occupancy after activation.
A57: W003 | B57: Boat-W003 | C57: WAITLIST | D57: 3 | E57: 3 | F57: ELIGIBLE | G57: 34 | H57: 10.5 | I57: NONE | J57: N | L57: ASSIGNED | M57: ASSIGNED | N57: D-07 | O57: 46539 | P57: Future D Dock occupancy after activation.
A58: W004 | B58: Boat-W004 | C58: WAITLIST | D58: 4 | E58: 4 | F58: ELIGIBLE | G58: 30 | H58: 10.5 | I58: 30A | J58: N | L58: ASSIGNED | M58: ASSIGNED | N58: C-08 | O58: 46447 | P58: Annual occupancy confirmed.
A59: W005 | B59: Boat-W005 | C59: WAITLIST | D59: 5 | E59: 5 | F59: ELIGIBLE | G59: 30 | H59: 10.5 | I59: NONE | J59: Y | L59: ASSIGNED | M59: ASSIGNED | N59: E-12 | O59: 46447 | P59: Annual occupancy confirmed.
A60: W006 | B60: Boat-W006 | C60: WAITLIST | D60: 6 | E60: 6 | F60: ELIGIBLE | G60: 36 | H60: 12 | I60: 30A | J60: N | L60: ASSIGNED | M60: ASSIGNED | N60: D-15 | O60: 46539 | P60: Future D Dock occupancy after activation.
A61: W007 | B61: Boat-W007 | C61: WAITLIST | D61: 7 | E61: 7 | F61: ELIGIBLE | G61: 30 | H61: 10.5 | I61: NONE | J61: N | L61: ASSIGNED | M61: ASSIGNED | N61: D-08 | O61: 46539 | P61: Future D Dock occupancy after activation.
A62: W008 | B62: Boat-W008 | C62: WAITLIST | D62: 8 | E62: 8 | F62: ELIGIBLE | G62: 30 | H62: 10.5 | I62: 30A | J62: N | L62: ASSIGNED | M62: ASSIGNED | N62: C-10 | O62: 46447 | P62: Annual occupancy confirmed.
A63: W009 | B63: Boat-W009 | C63: WAITLIST | D63: 9 | E63: 9 | F63: ELIGIBLE | G63: 34 | H63: 10.5 | I63: NONE | J63: N | L63: ASSIGNED | M63: ASSIGNED | N63: D-11 | O63: 46539 | P63: Future D Dock occupancy after activation.
A64: W010 | B64: Boat-W010 | C64: WAITLIST | D64: 10 | E64: 10 | F64: ELIGIBLE | G64: 30 | H64: 10.5 | I64: 30A | J64: Y | L64: ASSIGNED | M64: ASSIGNED | N64: C-14 | O64: 46447 | P64: Annual occupancy confirmed.
A65: W011 | B65: Boat-W011 | C65: WAITLIST | D65: 11 | E65: 11 | F65: ELIGIBLE | G65: 30 | H65: 10.5 | I65: NONE | J65: N | L65: ASSIGNED | M65: ASSIGNED | N65: D-10 | O65: 46539 | P65: Future D Dock occupancy after activation.
A66: W012 | B66: Boat-W012 | C66: WAITLIST | D66: 12 | E66: 12 | F66: ELIGIBLE | G66: 36 | H66: 12 | I66: 30A | J66: N | L66: ASSIGNED | M66: ASSIGNED | N66: D-03 | O66: 46539 | P66: Future D Dock occupancy after activation.
A67: W013 | B67: Boat-W013 | C67: WAITLIST | D67: 13 | E67: 13 | F67: ELIGIBLE | G67: 30 | H67: 10.5 | I67: NONE | J67: N | L67: ASSIGNED | M67: ASSIGNED | N67: D-14 | O67: 46539 | P67: Future D Dock occupancy after activation.
... A76: W022 | B76: Boat-W022 | C76: WAITLIST | D76: 22 | E76: 22 | F76: ELIGIBLE | G76: 30 | H76: 10.5 | I76: 30A | J76: N | L76: ASSIGNED | M76: ASSIGNED | N76: E-10 | O76: 46447 | P76: Annual occupancy confirmed.
A77: W023 | B77: Boat-W023 | C77: WAITLIST | D77: 23 | E77: 23 | F77: ELIGIBLE | G77: 30 | H77: 10.5 | I77: NONE | J77: N | L77: NOT OFFERED | M77: LOWER_PRIORITY_NOT_REACHED | P77: Assignable capacity committed to higher-priority eligible applicants.
A78: W024 | B78: Boat-W024 | C78: WAITLIST | D78: 24 | E78: 24 | F78: ELIGIBLE | G78: 36 | H78: 12 | I78: 30A | J78: N | L78: NOT OFFERED | M78: LOWER_PRIORITY_NOT_REACHED | P78: Assignable capacity committed to higher-priority eligible applicants.
A79: W025 | B79: Boat-W025 | C79: WAITLIST | D79: 25 | E79: 25 | F79: ELIGIBLE | G79: 30 | H79: 10.5 | I79: NONE | J79: Y | L79: NOT OFFERED | M79: LOWER_PRIORITY_NOT_REACHED | P79: Assignable capacity committed to higher-priority eligible applicants.
A80: W026 | B80: Boat-W026 | C80: WAITLIST | D80: 26 | E80: 26 | F80: ELIGIBLE | G80: 30 | H80: 10.5 | I80: 30A | J80: N | L80: NOT OFFERED | M80: LOWER_PRIORITY_NOT_REACHED | P80: Assignable capacity committed to higher-priority eligible applicants.
A81: W027 | B81: Boat-W027 | C81: WAITLIST | D81: 27 | E81: 27 | F81: ELIGIBLE | G81: 34 | H81: 10.5 | I81: NONE | J81: N | L81: NOT OFFERED | M81: LOWER_PRIORITY_NOT_REACHED | P81: Assignable capacity committed to higher-priority eligible applicants.
A82: W028 | B82: Boat-W028 | C82: WAITLIST | D82: 28 | E82: 28 | F82: ELIGIBLE | G82: 30 | H82: 10.5 | I82: 30A | J82: N | L82: NOT OFFERED | M82: LOWER_PRIORITY_NOT_REACHED | P82: Assignable capacity committed to higher-priority eligible applicants.
A83: W029 | B83: Boat-W029 | C83: WAITLIST | D83: 29 | E83: 29 | F83: INELIGIBLE | G83: 30 | H83: 10.5 | I83: NONE | J83: N | L83: INELIGIBLE | M83: ELIGIBILITY_FAIL | P83: Mandatory eligibility documentation or standing is incomplete.
A84: W030 | B84: Boat-W030 | C84: WAITLIST | D84: 30 | E84: 30 | F84: INELIGIBLE | G84: 36 | H84: 12 | I84: 30A | J84: Y | L84: INELIGIBLE | M84: ELIGIBILITY_FAIL | P84: Mandatory eligibility documentation or standing is incomplete.
...

Sheet Milestones
A1: CUTWATER BASIN 2027 | IMPLEMENTATION MILESTONES
A2: Executable approval, billing, and D Dock activation schedule. Administrative blackout: 8-9 February 2027.
A4: Milestone Code | B4: Milestone | C4: Start Date | D4: Finish Date | E4: Accountable Owner | F4: Dependency / Minimum Lag | G4: Status
A5: DATA_FREEZE | B5: Assignment data freeze | C5: 46412 | D5: 46412 | E5: Coordinator | F5: None | G5: Complete
A6: DRAFT_COMPLETE | B6: Draft assignment plan complete | C6: 46414 | D6: 46414 | E6: Coordinator | F6: DATA_FREEZE + 2 business days | G6: Complete
A7: ELECTRICAL_REVIEW | B7: Electrical-capacity review | C7: 46415 | D7: 46415 | E7: Electrical Engineer | F7: DRAFT_COMPLETE + 1 business day | G7: Complete
A8: SAFETY_ACCESS_REVIEW | B8: Safety and accessibility review | C8: 46416 | D8: 46416 | E8: Safety Officer | F8: ELECTRICAL_REVIEW complete | G8: Complete
A9: DIRECTOR_APPROVAL | B9: Director approval | C9: 46419 | D9: 46419 | E9: Port Director | F9: SAFETY_ACCESS_REVIEW complete | G9: Planned
A10: RENEWAL_NOTICES | B10: Renewal notices issued | C10: 46419 | D10: 46419 | E10: Coordinator | F10: DIRECTOR_APPROVAL complete | G10: Planned
A11: RENEWAL_RESPONSE_DEADLINE | B11: Renewal response deadline | C11: 46423 | D11: 46423 | E11: Coordinator | F11: RENEWAL_NOTICES + 5 business days inclusive | G11: Planned
A12: WAITLIST_OFFERS | B12: Waitlist offers issued | C12: 46428 | D12: 46428 | E12: Coordinator | F12: RENEWAL_RESPONSE_DEADLINE + 1 business day | G12: Planned
A13: WAITLIST_ACCEPTANCE_DEADLINE | B13: Waitlist acceptance deadline | C13: 46430 | D13: 46430 | E13: Coordinator | F13: WAITLIST_OFFERS + 3 business days inclusive | G13: Planned
A14: INSURANCE_VERIFICATION | B14: Insurance and documentation verification | C14: 46433 | D14: 46433 | E14: Harbor Services | F14: WAITLIST_ACCEPTANCE_DEADLINE complete | G14: Planned
A15: INVOICE_RELEASE | B15: Invoice release | C15: 46433 | D15: 46433 | E15: Finance | F15: INSURANCE_VERIFICATION complete; hard deadline | G15: Planned
A16: D_DOCK_PILE_COMPLETE | B16: D Dock pile-work completion | C16: 46527 | D16: 46527 | E16: Alderwick Consortium | F16: External project commitment | G16: Planned
... A19: D_DOCK_ACTIVATION | B19: D Dock activation | C19: 46539 | D19: 46539 | E19: Harbor Services | F19: Certification and inspection complete; not before 1 Jun | G19: Planned

Sheet Checks
A1: CUTWATER BASIN 2027 | COMPLIANCE CHECKS
A2: Formula-driven controls. Edit Assigned Applicant ID in Slip Plan to recalculate fit and circuit capacity controls.
A4: Control | B4: Measured Value | C4: Limit / Expected | D4: Result | E4: Implementation Note
A5: Inventory disposition count | B5: =COUNTA('Slip Plan'!$A$5:$A$78) -> 74 | C5: 74 | D5: =IF(B5=C5,"PASS","FAIL") -> PASS | E5: Every source slip represented once.
A6: Accessible reserves | B6: =COUNTIF('Slip Plan'!$J$5:$J$78,"ACCESSIBLE RESERVE") -> 2 | C6: 2 | D6: =IF(AND(B6=C6,COUNTIFS('Slip Plan'!$J$5:$J$78,"ACCESSIBLE RESERVE",'Slip Plan'!$L$5:$L$78,"<>")=0),"PASS","FAIL") -> PASS | E6: Reserve slips excluded from occupancy.
A7: Assigned slips | B7: =COUNTIF('Slip Plan'!$J$5:$J$78,"ASSIGNED") -> 72 | C7: 72 | D7: =IF(B7=C7,"PASS","FAIL") -> PASS | E7: Assignable capacity after reserves.
A8: Fit, outlet and timing failures | B8: =COUNTIF('Slip Plan'!$T$5:$T$78,"FAIL*") -> 0 | C8: 0 | D8: =IF(B8=C8,"PASS","FAIL") -> PASS | E8: Row-level fit / D Dock timing control.
A9: D Dock early occupancy | B9: =COUNTIFS('Slip Plan'!$B$5:$B$78,"D",'Slip Plan'!$L$5:$L$78,"<>",'Slip Plan'!$S$5:$S$78,"<"&DATE(2027,6,1)) -> 0 | C9: 0 | D9: =IF(B9=C9,"PASS","FAIL") -> PASS | E9: No occupancy before 1 June.
A10: Liveaboards on Dock A | B10: =COUNTIFS('Slip Plan'!$B$5:$B$78,"A",'Slip Plan'!$R$5:$R$78,"Y") -> 5 | C10: <= 6 | D10: =IF(B10<=6,"PASS","FAIL") -> PASS | E10: Policy cap by dock.
A11: Liveaboards on Dock B | B11: =COUNTIFS('Slip Plan'!$B$5:$B$78,"B",'Slip Plan'!$R$5:$R$78,"Y") -> 4 | C11: <= 6 | D11: =IF(B11<=6,"PASS","FAIL") -> PASS | E11: Policy cap by dock.
A12: Liveaboards on Dock C | B12: =COUNTIFS('Slip Plan'!$B$5:$B$78,"C",'Slip Plan'!$R$5:$R$78,"Y") -> 4 | C12: <= 6 | D12: =IF(B12<=6,"PASS","FAIL") -> PASS | E12: Policy cap by dock.
A13: Liveaboards on Dock D | B13: =COUNTIFS('Slip Plan'!$B$5:$B$78,"D",'Slip Plan'!$R$5:$R$78,"Y") -> 0 | C13: 0 | D13: =IF(B13=0,"PASS","FAIL") -> PASS | E13: D Dock liveaboards prohibited.
A14: Liveaboards on Dock E | B14: =COUNTIFS('Slip Plan'!$B$5:$B$78,"E",'Slip Plan'!$R$5:$R$78,"Y") -> 3 | C14: <= 6 | D14: =IF(B14<=6,"PASS","FAIL") -> PASS | E14: Policy cap by dock.
A17: Circuit group | B17: Demand A | C17: Capacity A | D17: Result | E17: Shared finger-circuit aggregate
A18: FG-01 | B18: =SUMIF('Slip Plan'!$G$5:$G$78,A18,'Slip Plan'!$Q$5:$Q$78) -> 110 | C18: =IF(A18="FG-19",100,200) -> 200 | D18: =IF(B18<=C18,"PASS","FAIL") -> PASS | E18: Demand counted once by actual circuit group.
A19: FG-02 | B19: =SUMIF('Slip Plan'!$G$5:$G$78,A19,'Slip Plan'!$Q$5:$Q$78) -> 80 | C19: =IF(A19="FG-19",100,200) -> 200 | D19: =IF(B19<=C19,"PASS","FAIL") -> PASS | E19: Demand counted once by actual circuit group.
A20: FG-03 | B20: =SUMIF('Slip Plan'!$G$5:$G$78,A20,'Slip Plan'!$Q$5:$Q$78) -> 130 | C20: =IF(A20="FG-19",100,200) -> 200 | D20: =IF(B20<=C20,"PASS","FAIL") -> PASS | E20: Demand counted once by actual circuit group.
A21: FG-04 | B21: =SUMIF('Slip Plan'!$G$5:$G$78,A21,'Slip Plan'!$Q$5:$Q$78) -> 130 | C21: =IF(A21="FG-19",100,200) -> 200 | D21: =IF(B21<=C21,"PASS","FAIL") -> PASS | E21: Demand counted once by actual circuit group.
A22: FG-05 | B22: =SUMIF('Slip Plan'!$G$5:$G$78,A22,'Slip Plan'!$Q$5:$Q$78) -> 110 | C22: =IF(A22="FG-19",100,200) -> 200 | D22: =IF(B22<=C22,"PASS","FAIL") -> PASS | E22: Demand counted once by actual circuit group.
A23: FG-06 | B23: =SUMIF('Slip Plan'!$G$5:$G$78,A23,'Slip Plan'!$Q$5:$Q$78) -> 80 | C23: =IF(A23="FG-19",100,200) -> 200 | D23: =IF(B23<=C23,"PASS","FAIL") -> PASS | E23: Demand counted once by actual circuit group.
A24: FG-07 | B24: =SUMIF('Slip Plan'!$G$5:$G$78,A24,'Slip Plan'!$Q$5:$Q$78) -> 110 | C24: =IF(A24="FG-19",100,200) -> 200 | D24: =IF(B24<=C24,"PASS","FAIL") -> PASS | E24: Demand counted once by actual circuit group.
A25: FG-08 | B25: =SUMIF('Slip Plan'!$G$5:$G$78,A25,'Slip Plan'!$Q$5:$Q$78) -> 80 | C25: =IF(A25="FG-19",100,200) -> 200 | D25: =IF(B25<=C25,"PASS","FAIL") -> PASS | E25: Demand counted once by actual circuit group.
A26: FG-09 | B26: =SUMIF('Slip Plan'!$G$5:$G$78,A26,'Slip Plan'!$Q$5:$Q$78) -> 90 | C26: =IF(A26="FG-19",100,200) -> 200 | D26: =IF(B26<=C26,"PASS","FAIL") -> PASS | E26: Demand counted once by actual circuit group.
A27: FG-10 | B27: =SUMIF('Slip Plan'!$G$5:$G$78,A27,'Slip Plan'!$Q$5:$Q$78) -> 60 | C27: =IF(A27="FG-19",100,200) -> 200 | D27: =IF(B27<=C27,"PASS","FAIL") -> PASS | E27: Demand counted once by actual circuit group.
A28: FG-11 | B28: =SUMIF('Slip Plan'!$G$5:$G$78,A28,'Slip Plan'!$Q$5:$Q$78) -> 60 | C28: =IF(A28="FG-19",100,200) -> 200 | D28: =IF(B28<=C28,"PASS","FAIL") -> PASS | E28: Demand counted once by actual circuit group.
A29: FG-12 | B29: =SUMIF('Slip Plan'!$G$5:$G$78,A29,'Slip Plan'!$Q$5:$Q$78) -> 60 | C29: =IF(A29="FG-19",100,200) -> 200 | D29: =IF(B29<=C29,"PASS","FAIL") -> PASS | E29: Demand counted once by actual circuit group.
... A36: FG-19 | B36: =SUMIF('Slip Plan'!$G$5:$G$78,A36,'Slip Plan'!$Q$5:$Q$78) -> 0 | C36: =IF(A36="FG-19",100,200) -> 100 | D36: =IF(B36<=C36,"PASS","FAIL") -> PASS | E36: Demand counted once by actual circuit group.
A38: Overall hard-constraint state | B38: =IF(COUNTIF($D$5:$D$14,"FAIL")+COUNTIF($D$18:$D$36,"FAIL")=0,"PASS","FAIL") -> PASS

Sheet Publication
A1: CUTWATER BASIN 2027 | APPROVED MOORAGE ASSIGNMENT PLAN
A2: Public release view. D Dock is closed through 31 May 2027; future assignments begin after activation.
A4: Slip | B4: Dock | C4: Public Status | D4: Assigned Boat / Reserve | E4: Effective Occupancy | F4: Electrical Service | G4: Availability Notice
A5: ='Slip Plan'!A5 -> A-01 | B5: ='Slip Plan'!B5 -> A | C5: =IF('Slip Plan'!J5="ACCESSIBLE RESERVE","ACCESSIBLE RESERVE",IF('Slip Plan'!L5="","AVAILABLE","ASSIGNED")) -> ACCESSIBLE RESERVE | D5: =IF('Slip Plan'!J5="ACCESSIBLE RESERVE","ACCESSIBLE RESERVE",'Slip Plan'!M5) -> ACCESSIBLE RESERVE | E5: ='Slip Plan'!S5 -> 0 | F5: ='Slip Plan'!P5 | G5: ='Slip Plan'!K5 -> Normal operating window
A6: ='Slip Plan'!A6 -> A-02 | B6: ='Slip Plan'!B6 -> A | C6: =IF('Slip Plan'!J6="ACCESSIBLE RESERVE","ACCESSIBLE RESERVE",IF('Slip Plan'!L6="","AVAILABLE","ASSIGNED")) -> ASSIGNED | D6: =IF('Slip Plan'!J6="ACCESSIBLE RESERVE","ACCESSIBLE RESERVE",'Slip Plan'!M6) -> Boat-R008 | E6: ='Slip Plan'!S6 -> 46447 | F6: ='Slip Plan'!P6 -> 30A | G6: ='Slip Plan'!K6 -> Normal operating window
A7: ='Slip Plan'!A7 -> A-03 | B7: ='Slip Plan'!B7 -> A | C7: =IF('Slip Plan'!J7="ACCESSIBLE RESERVE","ACCESSIBLE RESERVE",IF('Slip Plan'!L7="","AVAILABLE","ASSIGNED")) -> ASSIGNED | D7: =IF('Slip Plan'!J7="ACCESSIBLE RESERVE","ACCESSIBLE RESERVE",'Slip Plan'!M7) -> Boat-R006 | E7: ='Slip Plan'!S7 -> 46447 | F7: ='Slip Plan'!P7 -> 50A | G7: ='Slip Plan'!K7 -> Normal operating window
A8: ='Slip Plan'!A8 -> A-04 | B8: ='Slip Plan'!B8 -> A | C8: =IF('Slip Plan'!J8="ACCESSIBLE RESERVE","ACCESSIBLE RESERVE",IF('Slip Plan'!L8="","AVAILABLE","ASSIGNED")) -> ASSIGNED | D8: =IF('Slip Plan'!J8="ACCESSIBLE RESERVE","ACCESSIBLE RESERVE",'Slip Plan'!M8) -> Boat-R016 | E8: ='Slip Plan'!S8 -> 46447 | F8: ='Slip Plan'!P8 -> 30A | G8: ='Slip Plan'!K8 -> Normal operating window
A9: ='Slip Plan'!A9 -> A-05 | B9: ='Slip Plan'!B9 -> A | C9: =IF('Slip Plan'!J9="ACCESSIBLE RESERVE","ACCESSIBLE RESERVE",IF('Slip Plan'!L9="","AVAILABLE","ASSIGNED")) -> ASSIGNED | D9: =IF('Slip Plan'!J9="ACCESSIBLE RESERVE","ACCESSIBLE RESERVE",'Slip Plan'!M9) -> Boat-R013 | E9: ='Slip Plan'!S9 -> 46447 | F9: ='Slip Plan'!P9 -> NONE | G9: ='Slip Plan'!K9 -> Normal operating window
A10: ='Slip Plan'!A10 -> A-06 | B10: ='Slip Plan'!B10 -> A | C10: =IF('Slip Plan'!J10="ACCESSIBLE RESERVE","ACCESSIBLE RESERVE",IF('Slip Plan'!L10="","AVAILABLE","ASSIGNED")) -> ASSIGNED | D10: =IF('Slip Plan'!J10="ACCESSIBLE RESERVE","ACCESSIBLE RESERVE",'Slip Plan'!M10) -> Boat-R012 | E10: ='Slip Plan'!S10 -> 46447 | F10: ='Slip Plan'!P10 -> 50A | G10: ='Slip Plan'!K10 -> Normal operating window
A11: ='Slip Plan'!A11 -> A-07 | B11: ='Slip Plan'!B11 -> A | C11: =IF('Slip Plan'!J11="ACCESSIBLE RESERVE","ACCESSIBLE RESERVE",IF('Slip Plan'!L11="","AVAILABLE","ASSIGNED")) -> ASSIGNED | D11: =IF('Slip Plan'!J11="ACCESSIBLE RESERVE","ACCESSIBLE RESERVE",'Slip Plan'!M11) -> Boat-R017 | E11: ='Slip Plan'!S11 -> 46447 | F11: ='Slip Plan'!P11 -> NONE | G11: ='Slip Plan'!K11 -> Normal operating window
A12: ='Slip Plan'!A12 -> A-08 | B12: ='Slip Plan'!B12 -> A | C12: =IF('Slip Plan'!J12="ACCESSIBLE RESERVE","ACCESSIBLE RESERVE",IF('Slip Plan'!L12="","AVAILABLE","ASSIGNED")) -> ASSIGNED | D12: =IF('Slip Plan'!J12="ACCESSIBLE RESERVE","ACCESSIBLE RESERVE",'Slip Plan'!M12) -> Boat-R026 | E12: ='Slip Plan'!S12 -> 46447 | F12: ='Slip Plan'!P12 -> 30A | G12: ='Slip Plan'!K12 -> Normal operating window
A13: ='Slip Plan'!A13 -> A-09 | B13: ='Slip Plan'!B13 -> A | C13: =IF('Slip Plan'!J13="ACCESSIBLE RESERVE","ACCESSIBLE RESERVE",IF('Slip Plan'!L13="","AVAILABLE","ASSIGNED")) -> ASSIGNED | D13: =IF('Slip Plan'!J13="ACCESSIBLE RESERVE","ACCESSIBLE RESERVE",'Slip Plan'!M13) -> Boat-R018 | E13: ='Slip Plan'!S13 -> 46447 | F13: ='Slip Plan'!P13 -> 50A | G13: ='Slip Plan'!K13 -> Normal operating window
A14: ='Slip Plan'!A14 -> A-10 | B14: ='Slip Plan'!B14 -> A | C14: =IF('Slip Plan'!J14="ACCESSIBLE RESERVE","ACCESSIBLE RESERVE",IF('Slip Plan'!L14="","AVAILABLE","ASSIGNED")) -> ASSIGNED | D14: =IF('Slip Plan'!J14="ACCESSIBLE RESERVE","ACCESSIBLE RESERVE",'Slip Plan'!M14) -> Boat-R004 | E14: ='Slip Plan'!S14 -> 46447 | F14: ='Slip Plan'!P14 -> 30A | G14: ='Slip Plan'!K14 -> Normal operating window
A15: ='Slip Plan'!A15 -> A-11 | B15: ='Slip Plan'!B15 -> A | C15: =IF('Slip Plan'!J15="ACCESSIBLE RESERVE","ACCESSIBLE RESERVE",IF('Slip Plan'!L15="","AVAILABLE","ASSIGNED")) -> ASSIGNED | D15: =IF('Slip Plan'!J15="ACCESSIBLE RESERVE","ACCESSIBLE RESERVE",'Slip Plan'!M15) -> Boat-R003 | E15: ='Slip Plan'!S15 -> 46447 | F15: ='Slip Plan'!P15 -> NONE | G15: ='Slip Plan'!K15 -> Normal operating window
A16: ='Slip Plan'!A16 -> A-12 | B16: ='Slip Plan'!B16 -> A | C16: =IF('Slip Plan'!J16="ACCESSIBLE RESERVE","ACCESSIBLE RESERVE",IF('Slip Plan'!L16="","AVAILABLE","ASSIGNED")) -> ASSIGNED | D16: =IF('Slip Plan'!J16="ACCESSIBLE RESERVE","ACCESSIBLE RESERVE",'Slip Plan'!M16) -> Boat-R024 | E16: ='Slip Plan'!S16 -> 46447 | F16: ='Slip Plan'!P16 -> 50A | G16: ='Slip Plan'!K16 -> Normal operating window
... A78: ='Slip Plan'!A78 -> E-12 | B78: ='Slip Plan'!B78 -> E | C78: =IF('Slip Plan'!J78="ACCESSIBLE RESERVE","ACCESSIBLE RESERVE",IF('Slip Plan'!L78="","AVAILABLE","ASSIGNED")) -> ASSIGNED | D78: =IF('Slip Plan'!J78="ACCESSIBLE RESERVE","ACCESSIBLE RESERVE",'Slip Plan'!M78) -> Boat-W005 | E78: ='Slip Plan'!S78 -> 46447 | F78: ='Slip Plan'!P78 -> NONE | G78: ='Slip Plan'!K78 -> Normal operating window
A80: Legend | B80: ASSIGNED = annual assignment; AVAILABLE = unassigned general slip; ACCESSIBLE RESERVE = held open; D Dock closure applies through 31 May 2027.
A83: Approved by: | B83: Jarek Moravec, Port Director | E83: Signature: | F83: ____________________
A84: Date: | B84: ____________________
