Workbook

Sheet Calendar
A1: Corrected case closure calendar
A2: Detailed planned activity schedule. Planned is a scheduling status only; it is not completion evidence.
A3: Decision | B3: Full completion planning: all 36 source cases have a planned FDCR by the 24 November 2027 17:00 cutoff; no case is asserted completed.
A4: Planned case-work effort (hrs) | B4: =SUM(L7:L115) -> 96 | E4: Changeover capacity reserve (hrs) | F4: =SUM(M7:M115) -> 4 | I4: Capacity used (hrs) | J4: =B4+F4 -> 100 | M4: Status convention | N4: Planned = future schedule; Changeover = non-case capacity reservation.
A6: Activity ID | B6: Selected block | C6: Case ID | D6: Activity | E6: Date | F6: Slot | G6: Start | H6: End | I6: Jurisdiction | J6: Owner ID | K6: Owner | L6: Activity effort hrs | M6: Capacity reserved hrs | N6: Dependency | O6: Status | P6: Source trace
A7: CB-10-MI-HAB-2701-TC | B7: CB-10 | C7: MI-HAB-2701 | D7: Tenant Contact | E7: 46695 | F7: AM | G7: 0.35416667 | H7: 0.375 | I7: Michigan | J7: RS-02 | K7: Jordan Wells | L7: 0.5 | M7: 0 | N7: Start of closure sequence | O7: Planned | P7: Candidate Activity Map: CB-10-MI-HAB-2701-TC
A8: CB-01-ON-HAB-2701-TC | B8: CB-01 | C8: ON-HAB-2701 | D8: Tenant Contact | E8: 46695 | F8: AM | G8: 0.35416667 | H8: 0.375 | I8: Ontario | J8: RS-01 | K8: Taylor Baines | L8: 0.5 | M8: 0 | N8: Start of closure sequence | O8: Planned | P8: Candidate Activity Map: CB-01-ON-HAB-2701-TC
A9: CB-10-MI-HAB-2702-TC | B9: CB-10 | C9: MI-HAB-2702 | D9: Tenant Contact | E9: 46695 | F9: AM | G9: 0.375 | H9: 0.39583333 | I9: Michigan | J9: RS-02 | K9: Jordan Wells | L9: 0.5 | M9: 0 | N9: Start of closure sequence | O9: Planned | P9: Candidate Activity Map: CB-10-MI-HAB-2702-TC
A10: CB-01-ON-HAB-2702-TC | B10: CB-01 | C10: ON-HAB-2702 | D10: Tenant Contact | E10: 46695 | F10: AM | G10: 0.375 | H10: 0.39583333 | I10: Ontario | J10: RS-01 | K10: Taylor Baines | L10: 0.5 | M10: 0 | N10: Start of closure sequence | O10: Planned | P10: Candidate Activity Map: CB-01-ON-HAB-2702-TC
A11: CB-11-MI-HAB-2703-TC | B11: CB-11 | C11: MI-HAB-2703 | D11: Tenant Contact | E11: 46695 | F11: AM | G11: 0.41666667 | H11: 0.4375 | I11: Michigan | J11: RS-02 | K11: Jordan Wells | L11: 0.5 | M11: 0 | N11: Start of closure sequence | O11: Planned | P11: Candidate Activity Map: CB-11-MI-HAB-2703-TC
A12: CB-02-ON-HAB-2703-TC | B12: CB-02 | C12: ON-HAB-2703 | D12: Tenant Contact | E12: 46695 | F12: AM | G12: 0.41666667 | H12: 0.4375 | I12: Ontario | J12: RS-01 | K12: Taylor Baines | L12: 0.5 | M12: 0 | N12: Start of closure sequence | O12: Planned | P12: Candidate Activity Map: CB-02-ON-HAB-2703-TC
A13: CB-11-MI-HAB-2704-TC | B13: CB-11 | C13: MI-HAB-2704 | D13: Tenant Contact | E13: 46695 | F13: AM | G13: 0.4375 | H13: 0.45833333 | I13: Michigan | J13: RS-02 | K13: Jordan Wells | L13: 0.5 | M13: 0 | N13: Start of closure sequence | O13: Planned | P13: Candidate Activity Map: CB-11-MI-HAB-2704-TC
A14: CB-02-ON-HAB-2704-TC | B14: CB-02 | C14: ON-HAB-2704 | D14: Tenant Contact | E14: 46695 | F14: AM | G14: 0.4375 | H14: 0.45833333 | I14: Ontario | J14: RS-01 | K14: Taylor Baines | L14: 0.5 | M14: 0 | N14: Start of closure sequence | O14: Planned | P14: Candidate Activity Map: CB-02-ON-HAB-2704-TC
A15: CB-12-MI-HAB-2705-TC | B15: CB-12 | C15: MI-HAB-2705 | D15: Tenant Contact | E15: 46695 | F15: PM | G15: 0.5625 | H15: 0.58333333 | I15: Michigan | J15: RS-02 | K15: Jordan Wells | L15: 0.5 | M15: 0 | N15: Start of closure sequence | O15: Planned | P15: Candidate Activity Map: CB-12-MI-HAB-2705-TC
A16: CB-03-ON-HAB-2705-TC | B16: CB-03 | C16: ON-HAB-2705 | D16: Tenant Contact | E16: 46695 | F16: PM | G16: 0.5625 | H16: 0.58333333 | I16: Ontario | J16: RS-01 | K16: Taylor Baines | L16: 0.5 | M16: 0 | N16: Start of closure sequence | O16: Planned | P16: Candidate Activity Map: CB-03-ON-HAB-2705-TC
A17: CB-12-MI-HAB-2706-TC | B17: CB-12 | C17: MI-HAB-2706 | D17: Tenant Contact | E17: 46695 | F17: PM | G17: 0.58333333 | H17: 0.60416667 | I17: Michigan | J17: RS-02 | K17: Jordan Wells | L17: 0.5 | M17: 0 | N17: Start of closure sequence | O17: Planned | P17: Candidate Activity Map: CB-12-MI-HAB-2706-TC
A18: CB-03-ON-HAB-2706-TC | B18: CB-03 | C18: ON-HAB-2706 | D18: Tenant Contact | E18: 46695 | F18: PM | G18: 0.58333333 | H18: 0.60416667 | I18: Ontario | J18: RS-01 | K18: Taylor Baines | L18: 0.5 | M18: 0 | N18: Start of closure sequence | O18: Planned | P18: Candidate Activity Map: CB-03-ON-HAB-2706-TC
... A115: CB-09-ON-HAB-2718-FDCR | B115: CB-09 | C115: ON-HAB-2718 | D115: Final Determination & Closure Record (FDCR) | E115: 46709 | F115: AM | G115: 0.375 | H115: 0.39583333 | I115: Ontario | J115: RS-01 | K115: Taylor Baines | L115: 0.5 | M115: 0 | N115: Ontario Habitability Inspection (OHI) for ON-HAB-2718 | O115: Planned | P115: Candidate Activity Map: CB-09-ON-HAB-2718-FDCR

Sheet Case Register
A1: Case register and planned closure trace
A2: All 36 source cases are retained. Source facts are separated from the planned schedule fields at right.
A3: Completion decision | B3: Full completion planning. Every case remains Planned until independently supported completion evidence exists.
A4: Source case count | B4: 36 | E4: Mandatory source cases | F4: 19 | I4: Case-work total (hrs) | J4: =SUM(S7:S42) -> 96
A6: Case ID | B6: Source client ref | C6: Site | D6: Jurisdiction | E6: Mandatory? | F6: Opened | G6: Contact hrs | H6: Inspect hrs | I6: Final rec hrs | J6: Source contact status | K6: Source inspection status | L6: Selected block | M6: Contact date | N6: Contact slot | O6: Inspection date | P6: Inspection slot | Q6: FDCR date | R6: FDCR slot | S6: Total case effort hrs | T6: Schedule status | U6: Forecast basis | V6: Source trace
A7: MI-HAB-2701 | B7: SM-MI-101 | C7: Detroit central | D7: Michigan | E7: Yes | F7: 46636 | G7: 0.5 | H7: 1.5 | I7: 0.5 | J7: No contact evidence supplied | K7: No inspection evidence supplied | L7: CB-10 | M7: 46695 | N7: AM | O7: 46696 | P7: PM | Q7: 46699 | R7: PM | S7: =SUMIF(Calendar!$C$7:$C$115,A7,Calendar!$L$7:$L$115) -> 2.5 | T7: Planned | U7: Not applicable - full completion plan | V7: Case Register / CB-10
A8: MI-HAB-2702 | B8: SM-MI-102 | C8: Flint north | D8: Michigan | E8: No | F8: 46639 | G8: 0.5 | H8: 1.5 | I8: 0.5 | J8: No contact evidence supplied | K8: No inspection evidence supplied | L8: CB-10 | M8: 46695 | N8: AM | O8: 46696 | P8: PM | Q8: 46699 | R8: PM | S8: =SUMIF(Calendar!$C$7:$C$115,A8,Calendar!$L$7:$L$115) -> 2.5 | T8: Planned | U8: Not applicable - full completion plan | V8: Case Register / CB-10
A9: MI-HAB-2703 | B9: SM-MI-103 | C9: Grand Rapids west | D9: Michigan | E9: Yes | F9: 46642 | G9: 0.5 | H9: 2 | I9: 0.5 | J9: No contact evidence supplied | K9: No inspection evidence supplied | L9: CB-11 | M9: 46695 | N9: AM | O9: 46699 | P9: AM | Q9: 46700 | R9: PM | S9: =SUMIF(Calendar!$C$7:$C$115,A9,Calendar!$L$7:$L$115) -> 3 | T9: Planned | U9: Not applicable - full completion plan | V9: Case Register / CB-11
A10: MI-HAB-2704 | B10: SM-MI-104 | C10: Lansing east | D10: Michigan | E10: Yes | F10: 46645 | G10: 0.5 | H10: 1.5 | I10: 0.5 | J10: No contact evidence supplied | K10: No inspection evidence supplied | L10: CB-11 | M10: 46695 | N10: AM | O10: 46699 | P10: AM | Q10: 46700 | R10: PM | S10: =SUMIF(Calendar!$C$7:$C$115,A10,Calendar!$L$7:$L$115) -> 2.5 | T10: Planned | U10: Not applicable - full completion plan | V10: Case Register / CB-11
A11: MI-HAB-2705 | B11: SM-MI-105 | C11: Kalamazoo core | D11: Michigan | E11: No | F11: 46648 | G11: 0.5 | H11: 1.5 | I11: 0.5 | J11: No contact evidence supplied | K11: No inspection evidence supplied | L11: CB-12 | M11: 46695 | N11: PM | O11: 46699 | P11: PM | Q11: 46701 | R11: PM | S11: =SUMIF(Calendar!$C$7:$C$115,A11,Calendar!$L$7:$L$115) -> 2.5 | T11: Planned | U11: Not applicable - full completion plan | V11: Case Register / CB-12
A12: MI-HAB-2706 | B12: SM-MI-106 | C12: Saginaw south | D12: Michigan | E12: Yes | F12: 46651 | G12: 0.5 | H12: 2 | I12: 0.5 | J12: No contact evidence supplied | K12: No inspection evidence supplied | L12: CB-12 | M12: 46695 | N12: PM | O12: 46699 | P12: PM | Q12: 46701 | R12: PM | S12: =SUMIF(Calendar!$C$7:$C$115,A12,Calendar!$L$7:$L$115) -> 3 | T12: Planned | U12: Not applicable - full completion plan | V12: Case Register / CB-12
A13: MI-HAB-2707 | B13: SM-MI-107 | C13: Pontiac west | D13: Michigan | E13: No | F13: 46654 | G13: 0.5 | H13: 1.5 | I13: 0.5 | J13: No contact evidence supplied | K13: No inspection evidence supplied | L13: CB-13 | M13: 46695 | N13: PM | O13: 46700 | P13: AM | Q13: 46702 | R13: AM | S13: =SUMIF(Calendar!$C$7:$C$115,A13,Calendar!$L$7:$L$115) -> 2.5 | T13: Planned | U13: Not applicable - full completion plan | V13: Case Register / CB-13
A14: MI-HAB-2708 | B14: SM-MI-108 | C14: Muskegon lake | D14: Michigan | E14: Yes | F14: 46633 | G14: 0.5 | H14: 1.5 | I14: 0.5 | J14: No contact evidence supplied | K14: No inspection evidence supplied | L14: CB-13 | M14: 46695 | N14: PM | O14: 46700 | P14: AM | Q14: 46702 | R14: AM | S14: =SUMIF(Calendar!$C$7:$C$115,A14,Calendar!$L$7:$L$115) -> 2.5 | T14: Planned | U14: Not applicable - full completion plan | V14: Case Register / CB-13
A15: MI-HAB-2709 | B15: SM-MI-109 | C15: Ann Arbor north | D15: Michigan | E15: No | F15: 46636 | G15: 0.5 | H15: 2 | I15: 0.5 | J15: No contact evidence supplied | K15: No inspection evidence supplied | L15: CB-14 | M15: 46696 | N15: AM | O15: 46700 | P15: PM | Q15: 46702 | R15: PM | S15: =SUMIF(Calendar!$C$7:$C$115,A15,Calendar!$L$7:$L$115) -> 3 | T15: Planned | U15: Not applicable - full completion plan | V15: Case Register / CB-14
A16: MI-HAB-2710 | B16: SM-MI-110 | C16: Dearborn central | D16: Michigan | E16: Yes | F16: 46639 | G16: 0.5 | H16: 1.5 | I16: 0.5 | J16: No contact evidence supplied | K16: No inspection evidence supplied | L16: CB-14 | M16: 46696 | N16: AM | O16: 46700 | P16: PM | Q16: 46702 | R16: PM | S16: =SUMIF(Calendar!$C$7:$C$115,A16,Calendar!$L$7:$L$115) -> 2.5 | T16: Planned | U16: Not applicable - full completion plan | V16: Case Register / CB-14
A17: MI-HAB-2711 | B17: SM-MI-111 | C17: Battle Creek east | D17: Michigan | E17: No | F17: 46642 | G17: 0.5 | H17: 1.5 | I17: 0.5 | J17: No contact evidence supplied | K17: No inspection evidence supplied | L17: CB-15 | M17: 46696 | N17: AM | O17: 46701 | P17: AM | Q17: 46703 | R17: PM | S17: =SUMIF(Calendar!$C$7:$C$115,A17,Calendar!$L$7:$L$115) -> 2.5 | T17: Planned | U17: Not applicable - full completion plan | V17: Case Register / CB-15
A18: MI-HAB-2712 | B18: SM-MI-112 | C18: Jackson south | D18: Michigan | E18: No | F18: 46645 | G18: 0.5 | H18: 2 | I18: 0.5 | J18: No contact evidence supplied | K18: No inspection evidence supplied | L18: CB-15 | M18: 46696 | N18: AM | O18: 46701 | P18: AM | Q18: 46703 | R18: PM | S18: =SUMIF(Calendar!$C$7:$C$115,A18,Calendar!$L$7:$L$115) -> 3 | T18: Planned | U18: Not applicable - full completion plan | V18: Case Register / CB-15
... A42: ON-HAB-2718 | B42: SM-ON-118 | C42: St. Catharines north | D42: Ontario | E42: No | F42: 46608 | G42: 0.5 | H42: 2 | I42: 0.5 | J42: No contact evidence supplied | K42: No inspection evidence supplied | L42: CB-09 | M42: 46699 | N42: AM | O42: 46708 | P42: AM | Q42: 46709 | R42: AM | S42: =SUMIF(Calendar!$C$7:$C$115,A42,Calendar!$L$7:$L$115) -> 3 | T42: Planned | U42: Not applicable - full completion plan | V42: Case Register / CB-09

Sheet Selection
A1: Selected closure blocks and capacity trace
A2: Selected subset expands directly to the Calendar. Candidate attributes below are copied from the source option pool.
A3: Selected blocks | B3: 18 | D3: Coverage choice | E3: Full completion: every source case is selected exactly once.
A6: Selected? | B6: Candidate ID | C6: Source case coverage | D6: Jurisdiction | E6: Window start | F6: Window finish | G6: Primary owner | H6: Activity rows | I6: Case effort hrs | J6: Mandatory cases | K6: Ontario OHI control | L6: Michigan MHI control | M6: Source option status | N6: Coverage trace
A7: Yes | B7: CB-10 | C7: MI-HAB-2701; MI-HAB-2702 | D7: Michigan | E7: 46695 | F7: 46699 | G7: Micah Pierce | H7: 6 | I7: 5 | J7: 1 | K7: No | L7: Yes | M7: Proposed | N7: Coverage Matrix: CB-10
A8: Yes | B8: CB-11 | C8: MI-HAB-2703; MI-HAB-2704 | D8: Michigan | E8: 46695 | F8: 46700 | G8: Micah Pierce | H8: 6 | I8: 5.5 | J8: 2 | K8: No | L8: Yes | M8: Proposed | N8: Coverage Matrix: CB-11
A9: Yes | B9: CB-12 | C9: MI-HAB-2705; MI-HAB-2706 | D9: Michigan | E9: 46695 | F9: 46701 | G9: Micah Pierce | H9: 6 | I9: 5.5 | J9: 1 | K9: No | L9: Yes | M9: Proposed | N9: Coverage Matrix: CB-12
A10: Yes | B10: CB-13 | C10: MI-HAB-2707; MI-HAB-2708 | D10: Michigan | E10: 46695 | F10: 46702 | G10: Micah Pierce | H10: 6 | I10: 5 | J10: 1 | K10: No | L10: Yes | M10: Proposed | N10: Coverage Matrix: CB-13
A11: Yes | B11: CB-17 | C11: MI-HAB-2715; MI-HAB-2716 | D11: Michigan | E11: 46696 | F11: 46707 | G11: Micah Pierce | H11: 6 | I11: 5.5 | J11: 1 | K11: No | L11: Yes | M11: Proposed | N11: Coverage Matrix: CB-17
A12: Yes | B12: CB-18 | C12: MI-HAB-2717; MI-HAB-2718 | D12: Michigan | E12: 46699 | F12: 46709 | G12: Micah Pierce | H12: 6 | I12: 5.5 | J12: 0 | K12: No | L12: Yes | M12: Proposed | N12: Coverage Matrix: CB-18
A13: Yes | B13: CB-14 | C13: MI-HAB-2709; MI-HAB-2710 | D13: Michigan | E13: 46696 | F13: 46702 | G13: Micah Pierce | H13: 6 | I13: 5.5 | J13: 1 | K13: No | L13: Yes | M13: Proposed | N13: Coverage Matrix: CB-14
A14: Yes | B14: CB-15 | C14: MI-HAB-2711; MI-HAB-2712 | D14: Michigan | E14: 46696 | F14: 46703 | G14: Micah Pierce | H14: 6 | I14: 5.5 | J14: 0 | K14: No | L14: Yes | M14: Proposed | N14: Coverage Matrix: CB-15
A15: Yes | B15: CB-16 | C15: MI-HAB-2713; MI-HAB-2714 | D15: Michigan | E15: 46696 | F15: 46708 | G15: Rowan Singh | H15: 6 | I15: 5 | J15: 2 | K15: No | L15: Yes | M15: Proposed | N15: Coverage Matrix: CB-16
A16: Yes | B16: CB-01 | C16: ON-HAB-2701; ON-HAB-2702 | D16: Ontario | E16: 46695 | F16: 46699 | G16: Priya Ingram | H16: 6 | I16: 5 | J16: 2 | K16: Yes | L16: No | M16: Proposed | N16: Coverage Matrix: CB-01
A17: Yes | B17: CB-02 | C17: ON-HAB-2703; ON-HAB-2704 | D17: Ontario | E17: 46695 | F17: 46700 | G17: Priya Ingram | H17: 6 | I17: 5.5 | J17: 1 | K17: Yes | L17: No | M17: Proposed | N17: Coverage Matrix: CB-02
A18: Yes | B18: CB-03 | C18: ON-HAB-2705; ON-HAB-2706 | D18: Ontario | E18: 46695 | F18: 46701 | G18: Priya Ingram | H18: 6 | I18: 5.5 | J18: 1 | K18: Yes | L18: No | M18: Proposed | N18: Coverage Matrix: CB-03
... A24: Yes | B24: CB-09 | C24: ON-HAB-2717; ON-HAB-2718 | D24: Ontario | E24: 46699 | F24: 46709 | G24: Priya Ingram | H24: 6 | I24: 5.5 | J24: 1 | K24: Yes | L24: No | M24: Proposed | N24: Coverage Matrix: CB-09
A27: Selection coverage controls
A28: Control | B28: Required | C28: Selected coverage | D28: Result | E28: Trace
A29: All source cases | B29: 36 | C29: 36 | D29: Satisfied | E29: Selection -> Case Register
A30: Mandatory source cases | B30: 19 | C30: 19 | D30: Satisfied | E30: Coverage Matrix mandatory flag
A31: Ontario OHI cases | B31: 18 | C31: 18 | D31: Satisfied | E31: Calendar OHI rows
A32: Michigan MHI cases | B32: 18 | C32: 18 | D32: Satisfied | E32: Calendar MHI rows
A33: Final closure records | B33: 36 | C33: 36 | D33: Satisfied | E33: Calendar FDCR rows
A34: Contacts outside blackout | B34: 36 | C34: 36 | D34: Satisfied | E34: Calendar Tenant Contact rows
A37: Owner workload and capacity indicators
A38: Owner ID | B38: Owner | C38: Case-work workload hrs | D38: Changeover reserve hrs | E38: Capacity used hrs | F38: Daily roster cap | G38: Peak daily capacity used | H38: Capacity status
A39: RS-01 | B39: Taylor Baines | C39: =SUMIF(Calendar!$J$7:$J$115,A39,Calendar!$L$7:$L$115) -> 18 | D39: =SUMIF(Calendar!$J$7:$J$115,A39,Calendar!$M$7:$M$115) -> 0 | E39: =C39+D39 -> 18 | F39: 8 | G39: 4 | H39: Within roster cap
A40: RS-02 | B40: Jordan Wells | C40: =SUMIF(Calendar!$J$7:$J$115,A40,Calendar!$L$7:$L$115) -> 18 | D40: =SUMIF(Calendar!$J$7:$J$115,A40,Calendar!$M$7:$M$115) -> 0 | E40: =C40+D40 -> 18 | F40: 8 | G40: 4 | H40: Within roster cap
A41: RS-03 | B41: Priya Ingram | C41: =SUMIF(Calendar!$J$7:$J$115,A41,Calendar!$L$7:$L$115) -> 27 | D41: =SUMIF(Calendar!$J$7:$J$115,A41,Calendar!$M$7:$M$115) -> 0 | E41: =C41+D41 -> 27 | F41: 8 | G41: 7 | H41: Within roster cap
A42: RS-04 | B42: Rowan Singh | C42: =SUMIF(Calendar!$J$7:$J$115,A42,Calendar!$L$7:$L$115) -> 6 | D42: =SUMIF(Calendar!$J$7:$J$115,A42,Calendar!$M$7:$M$115) -> 4 | E42: =C42+D42 -> 10 | F42: 8 | G42: 7 | H42: Within roster cap
A43: RS-05 | B43: Micah Pierce | C43: =SUMIF(Calendar!$J$7:$J$115,A43,Calendar!$L$7:$L$115) -> 27 | D43: =SUMIF(Calendar!$J$7:$J$115,A43,Calendar!$M$7:$M$115) -> 0 | E43: =C43+D43 -> 27 | F43: 8 | G43: 7 | H43: Within roster cap
A46: Daily capacity check
A47: Date | B47: Owner ID | C47: Owner | D47: Case-work hrs | E47: Changeover reserve hrs | F47: Capacity used hrs | G47: Daily roster cap | H47: Usable case-work hrs after changeover | I47: Result
A48: 46695 | B48: RS-01 | C48: Taylor Baines | D48: 4 | E48: 0 | F48: 4 | G48: 8 | H48: 8 | I48: Within roster cap
A49: 46695 | B49: RS-02 | C49: Jordan Wells | D49: 4 | E49: 0 | F49: 4 | G49: 8 | H49: 8 | I49: Within roster cap
A50: 46696 | B50: RS-01 | C50: Taylor Baines | D50: 4 | E50: 0 | F50: 4 | G50: 8 | H50: 8 | I50: Within roster cap
A51: 46696 | B51: RS-02 | C51: Jordan Wells | D51: 4 | E51: 0 | F51: 4 | G51: 8 | H51: 8 | I51: Within roster cap
A52: 46696 | B52: RS-03 | C52: Priya Ingram | D52: 3 | E52: 0 | F52: 3 | G52: 8 | H52: 8 | I52: Within roster cap
A53: 46696 | B53: RS-05 | C53: Micah Pierce | D53: 3 | E53: 0 | F53: 3 | G53: 8 | H53: 8 | I53: Within roster cap
...

Sheet Changes & Assumptions
A1: Changes and governing assumptions
A2: Comparison is limited to source schedule facts and the controlling memo; it does not add completion evidence or policy recommendations.
A3: Decision | B3: Full completion planning: all 36 cases are planned for Final Determination & Closure Record (FDCR) by 24 November 2027 17:00. Planned does not assert completed closure.
A4: Evidence boundary | B4: No tenant response, inspection result, credential, completion status, or case attribute has been added beyond the supplied sources.
A6: Rejected draft versus corrected calendar
A7: Period | B7: Draft activity count | C7: Draft case-work hrs | D7: Corrected activity count | E7: Corrected case-work hrs | F7: Corrected distinct cases | G7: Material schedule correction
A8: 04-16 Nov 2027 | B8: 70 | C8: 63 | D8: 96 | E8: 85 | F8: 36 | G8: Specific OHI/MHI activity replaces the draft's Generic Property Review and uses the rostered qualified reviewer.
A9: 17-19 Nov 2027 tenant-contact blackout | B9: 14 | C9: 7 | D9: 12 | E9: 11 | F9: 8 | G9: The draft contains Tenant Contact during the blackout; corrected Tenant Contact count is zero and downstream inspection follows the actual contact.
A10: 20-23 Nov 2027 | B10: 24 | C10: 26 | D10: 0 | E10: 0 | F10: 0 | G10: Draft post-blackout review and FDCR work is not carried into this period; corrected case work is scheduled within the permitted earlier slots.
A13: Material changes
A14: Change | B14: Source-supported effect
A15: Jurisdiction inspection correction | B15: The rejected draft uses Generic Property Review and omits the required Ontario Habitability Inspection (OHI) and Michigan Habitability Inspection (MHI). The corrected Calendar shows the required jurisdiction-specific inspection for every source case and assigns it only to a rostered qualified owner.
A16: Tenant-contact blackout correction | B16: The rejected draft contains 12 Tenant Contact activities on 17-19 November. The corrected Calendar contains 0 Tenant Contact activities during the 17-19 November blackout; each inspection is scheduled only after its recorded planned contact.
A17: Jurisdiction-switch capacity correction | B17: The rejected draft contains no Jurisdiction Changeover reservation. The corrected Calendar reserves a full half-day (4.0 capacity hours) for Rowan Singh on 16 November AM between Ontario case work on 15 November PM and Michigan case work on 16 November PM; that interval is unavailable for case work.
A18: Memo precedence | B18: The rejected draft conflicts with the governing memo on inspection wording, blackout treatment, and changeover capacity. The memorandum controls where the draft differs, so the corrected schedule applies the memo rather than treating the draft as an exception.
A22: Governing assumptions and status vocabulary
A23: Topic | B23: Applied treatment | C23: Source
A24: Deadline | B24: Final closure activity is FDCR; the oversight cutoff is 24 November 2027 at 17:00 local time. | C24: Governance memo section 1
A25: Work hours | B25: Only supplied planning dates and AM 08:30-12:30 / PM 13:30-17:30 slots are used. | C25: Governance memo section 1; Resource Availability
A26: Blackout | B26: Tenant Contact is unavailable 17 through 19 November inclusive; downstream inspection follows the actual planned contact. | C26: Governance memo section 2
A27: Changeover | B27: A jurisdiction switch reserves the complete half-day before incoming work, consumes 4.0 capacity hours, and has 0.0 case-activity effort. | C27: Governance memo section 3
A28: Qualifications | B28: OHI and MHI owners are checked against the supplied roster flags; no credentials are inferred. | C28: Governance memo section 2; Resource Roster
A29: Status labels | B29: Planned is future scheduled work; Completed requires source evidence and is not used here. Forecast and Blocked are not used because full completion is planned. Changeover is a non-case capacity reservation. | C29: Governance memo section 4
