Workbook

Sheet Review Control
A1: Packaging Review Control
A2: Planning dates and source-export control fields
A4: Planning as-of date | B4: 45716
A5: Forecast start | B5: 45717
A6: Forecast end | B6: 45838
A7: Export timestamp | B7: 45716.715
A8: Source workbook | B8: Candlewick_Everstead_packaging_review.xlsx
A9: Unique record key statement | B9: Inventory Snapshots: Inventory Record ID; Demand Plans: Demand Record ID; Purchase Orders: PO Line ID; Receipts: Receipt Record ID; Packaging Parameters: Parameter Record ID.
A11: Forecast periods | G11: Named scenarios
A12: Period ID | B12: Period label | C12: Start date | D12: End date | E12: Sequence | G12: Scenario code | H12: Scenario name | I12: Demand basis | J12: Status
A13: P1 | B13: March 2025 | C13: 45717 | D13: 45747 | E13: 1 | G13: BASE | H13: Base Demand | I13: Named demand scenario | J13: Active
A14: P2 | B14: April 2025 | C14: 45748 | D14: 45777 | E14: 2 | G14: PEAK | H14: Peak Demand | I14: Named demand scenario | J14: Active
A15: P3 | B15: May 2025 | C15: 45778 | D15: 45808 | E15: 3
A16: P4 | B16: June 2025 | C16: 45809 | D16: 45838 | E16: 4

Sheet Facility Map
A1: Facility Map
A2: Facility and jurisdiction mapping from the operations master
A4: Exported 2025-02-28 17:10 UTC | Nevada and California packaging review
A5: Facility ID | B5: Facility name | C5: Organization | D5: Jurisdiction | E5: State | F5: Active from | G5: Source Record ID
A6: NV-RENO | B6: Reno Packaging Hub | C6: Candlewick Supply | D6: Nevada | E6: NV | F6: 43831 | G6: FAC-001
A7: CA-FRESNO | B7: Fresno Fulfillment Center | C7: Everstead Systems | D7: California | E7: CA | F7: 43831 | G7: FAC-002

Sheet Materials
A1: Packaging Material Master
A2: Material descriptions and units from the packaging catalog
A4: Exported 2025-02-28 17:10 UTC | Nevada and California packaging review
A5: Material ID | B5: Material description | C5: Stock unit | D5: Category | E5: Active | F5: Source Record ID
A6: MAT-FILM | B6: Stretch Film Roll | C6: roll | D6: Packaging material | E6: Y | F6: MAT-101
A7: MAT-CARTON | B7: Shipping Carton | C7: carton | D7: Packaging material | E7: Y | F7: MAT-102
A8: MAT-LABEL | B8: Pallet Label | C8: label | D8: Packaging material | E8: Y | F8: MAT-103

Sheet Inventory Snapshots
A1: Inventory Snapshots
A2: Count snapshots available to the packaging-material review
A4: Exported 2025-02-28 17:10 UTC | Nevada and California packaging review
A5: Inventory Record ID | B5: Inventory Key | C5: Facility ID | D5: Material ID | E5: Snapshot date | F5: Effective at | G5: Quantity | H5: Unit | I5: Status | J5: Note
A6: INV-0001-OLD | B6: NV-RENO|MAT-FILM|2025-02-28 | C6: NV-RENO | D6: MAT-FILM | E6: 45716 | F6: 45702 | G6: 70 | H6: roll | I6: Superseded | J6: Prior count export
A7: INV-0001 | B7: NV-RENO|MAT-FILM|2025-02-28 | C7: NV-RENO | D7: MAT-FILM | E7: 45716 | F7: 45715 | G7: 95 | H7: roll | I7: Current | J7: Late count posted
A8: INV-0003 | B8: NV-RENO|MAT-CARTON|2025-02-28 | C8: NV-RENO | D8: MAT-CARTON | E8: 45716 | F8: 45715 | G8: 145 | H8: carton | I8: Current
A9: INV-0004 | B9: NV-RENO|MAT-LABEL|2025-02-28 | C9: NV-RENO | D9: MAT-LABEL | E9: 45716 | F9: 45715 | G9: 180 | H9: label | I9: Current
A10: INV-0005 | B10: CA-FRESNO|MAT-FILM|2025-02-28 | C10: CA-FRESNO | D10: MAT-FILM | E10: 45716 | F10: 45715 | G10: 85 | H10: roll | I10: Current
A11: INV-0006 | B11: CA-FRESNO|MAT-CARTON|2025-02-28 | C11: CA-FRESNO | D11: MAT-CARTON | E11: 45716 | F11: 45715 | G11: 125 | H11: carton | I11: Current
A12: INV-0007 | B12: CA-FRESNO|MAT-LABEL|2025-02-28 | C12: CA-FRESNO | D12: MAT-LABEL | E12: 45716 | F12: 45715 | G12: 170 | H12: label | I12: Current

Sheet Demand Plans
A1: Demand Plans
A2: Named scenario demand records with dated versions
A4: Exported 2025-02-28 17:10 UTC | Nevada and California packaging review
A5: Demand Record ID | B5: Demand Key | C5: Facility ID | D5: Material ID | E5: Scenario | F5: Period ID | G5: Period start | H5: Period end | I5: Effective at | J5: Demand quantity | K5: Unit | L5: Status | M5: Source note
A6: DEM-0002-OLD | B6: NV-RENO|MAT-FILM|Base Demand|P2 | C6: NV-RENO | D6: MAT-FILM | E6: Base Demand | F6: P2 | G6: 45748 | H6: 45777 | I6: 45677 | J6: 38 | K6: roll | L6: Superseded | M6: January planning revision
A7: DEM-0001 | B7: NV-RENO|MAT-FILM|Base Demand|P1 | C7: NV-RENO | D7: MAT-FILM | E7: Base Demand | F7: P1 | G7: 45717 | H7: 45747 | I7: 45708 | J7: 24 | K7: roll | L7: Current
A8: DEM-0002 | B8: NV-RENO|MAT-FILM|Base Demand|P2 | C8: NV-RENO | D8: MAT-FILM | E8: Base Demand | F8: P2 | G8: 45748 | H8: 45777 | I8: 45708 | J8: 28 | K8: roll | L8: Current
A9: DEM-0003 | B9: NV-RENO|MAT-FILM|Base Demand|P3 | C9: NV-RENO | D9: MAT-FILM | E9: Base Demand | F9: P3 | G9: 45778 | H9: 45808 | I9: 45708 | J9: 32 | K9: roll | L9: Current
A10: DEM-0004 | B10: NV-RENO|MAT-FILM|Base Demand|P4 | C10: NV-RENO | D10: MAT-FILM | E10: Base Demand | F10: P4 | G10: 45809 | H10: 45838 | I10: 45708 | J10: 36 | K10: roll | L10: Current
A11: DEM-0005 | B11: NV-RENO|MAT-FILM|Peak Demand|P1 | C11: NV-RENO | D11: MAT-FILM | E11: Peak Demand | F11: P1 | G11: 45717 | H11: 45747 | I11: 45708 | J11: 32 | K11: roll | L11: Current
A12: DEM-0006 | B12: NV-RENO|MAT-FILM|Peak Demand|P2 | C12: NV-RENO | D12: MAT-FILM | E12: Peak Demand | F12: P2 | G12: 45748 | H12: 45777 | I12: 45708 | J12: 38 | K12: roll | L12: Current
A13: DEM-0007 | B13: NV-RENO|MAT-FILM|Peak Demand|P3 | C13: NV-RENO | D13: MAT-FILM | E13: Peak Demand | F13: P3 | G13: 45778 | H13: 45808 | I13: 45708 | J13: 44 | K13: roll | L13: Current
A14: DEM-0008 | B14: NV-RENO|MAT-FILM|Peak Demand|P4 | C14: NV-RENO | D14: MAT-FILM | E14: Peak Demand | F14: P4 | G14: 45809 | H14: 45838 | I14: 45708 | J14: 50 | K14: roll | L14: Current
A15: DEM-0009 | B15: NV-RENO|MAT-CARTON|Base Demand|P1 | C15: NV-RENO | D15: MAT-CARTON | E15: Base Demand | F15: P1 | G15: 45717 | H15: 45747 | I15: 45708 | J15: 54 | K15: carton | L15: Current
A16: DEM-0010 | B16: NV-RENO|MAT-CARTON|Base Demand|P2 | C16: NV-RENO | D16: MAT-CARTON | E16: Base Demand | F16: P2 | G16: 45748 | H16: 45777 | I16: 45708 | J16: 60 | K16: carton | L16: Current
A17: DEM-0011 | B17: NV-RENO|MAT-CARTON|Base Demand|P3 | C17: NV-RENO | D17: MAT-CARTON | E17: Base Demand | F17: P3 | G17: 45778 | H17: 45808 | I17: 45708 | J17: 66 | K17: carton | L17: Current
A18: DEM-0012 | B18: NV-RENO|MAT-CARTON|Base Demand|P4 | C18: NV-RENO | D18: MAT-CARTON | E18: Base Demand | F18: P4 | G18: 45809 | H18: 45838 | I18: 45708 | J18: 72 | K18: carton | L18: Current
... A54: DEM-0048 | B54: CA-FRESNO|MAT-LABEL|Peak Demand|P4 | C54: CA-FRESNO | D54: MAT-LABEL | E54: Peak Demand | F54: P4 | G54: 45809 | H54: 45838 | I54: 45708 | J54: 58 | K54: label | L54: Current

Sheet Packaging Parameters
A1: Packaging Parameters
A2: Target ending stock and ordering increments by facility and material
A4: Exported 2025-02-28 17:10 UTC | Nevada and California packaging review
A5: Parameter Record ID | B5: Parameter Key | C5: Facility ID | D5: Material ID | E5: Effective at | F5: Target ending stock | G5: Order multiple | H5: Unit | I5: Status | J5: Note
A6: PAR-0001-OLD | B6: NV-RENO|MAT-FILM | C6: NV-RENO | D6: MAT-FILM | E6: 45672 | F6: 60 | G6: 20 | H6: roll | I6: Superseded | J6: Prior safety stock setting
A7: PAR-0001 | B7: NV-RENO|MAT-FILM | C7: NV-RENO | D7: MAT-FILM | E7: 45689 | F7: 80 | G7: 20 | H7: roll | I7: Current
A8: PAR-0002 | B8: NV-RENO|MAT-CARTON | C8: NV-RENO | D8: MAT-CARTON | E8: 45689 | F8: 120 | G8: 40 | H8: carton | I8: Current
A9: PAR-0003 | B9: NV-RENO|MAT-LABEL | C9: NV-RENO | D9: MAT-LABEL | E9: 45689 | F9: 200 | G9: 100 | H9: label | I9: Current
A10: PAR-0004 | B10: CA-FRESNO|MAT-FILM | C10: CA-FRESNO | D10: MAT-FILM | E10: 45689 | F10: 70 | G10: 20 | H10: roll | I10: Current
A11: PAR-0005 | B11: CA-FRESNO|MAT-CARTON | C11: CA-FRESNO | D11: MAT-CARTON | E11: 45689 | F11: 100 | G11: 40 | H11: carton | I11: Current
A12: PAR-0006 | B12: CA-FRESNO|MAT-LABEL | C12: CA-FRESNO | D12: MAT-LABEL | E12: 45689 | F12: 180 | G12: 100 | H12: label | I12: Current

Sheet Purchase Orders
A1: Purchase Orders
A2: Open packaging-material order lines from purchasing
A4: Exported 2025-02-28 17:10 UTC | Nevada and California packaging review
A5: PO Line ID | B5: Purchase Order | C5: Facility ID | D5: Material ID | E5: Order date | F5: Due date | G5: Packages ordered | H5: Units / package | I5: Unit | J5: Status | K5: Supplier | L5: Buyer note
A6: POL-0001 | B6: PO-7001 | C6: NV-RENO | D6: MAT-FILM | E6: 45694 | F6: 45726 | G6: 1 | H6: 10 | I6: roll | J6: Open | K6: Meridian Packaging Co.
A7: POL-0002 | B7: PO-7002 | C7: NV-RENO | D7: MAT-FILM | E7: 45695 | F7: 45736 | G7: 1 | H7: 10 | I7: roll | J7: Open | K7: Meridian Packaging Co.
A8: POL-0003 | B8: PO-7003 | C8: NV-RENO | D8: MAT-FILM | E8: 45696 | F8: 45757 | G8: 1 | H8: 10 | I8: roll | J8: Open | K8: Meridian Packaging Co.
A9: POL-0004 | B9: PO-7004 | C9: NV-RENO | D9: MAT-FILM | E9: 45697 | F9: 45767 | G9: 1 | H9: 10 | I9: roll | J9: Open | K9: Meridian Packaging Co.
A10: POL-0005 | B10: PO-7005 | C10: NV-RENO | D10: MAT-FILM | E10: 45698 | F10: 45787 | G10: 1 | H10: 10 | I10: roll | J10: Open | K10: Meridian Packaging Co.
A11: POL-0006 | B11: PO-7006 | C11: NV-RENO | D11: MAT-FILM | E11: 45699 | F11: 45797 | G11: 1 | H11: 10 | I11: roll | J11: Open | K11: Meridian Packaging Co.
A12: POL-0007 | B12: PO-7007 | C12: NV-RENO | D12: MAT-FILM | E12: 45700 | F12: 45818 | G12: 1 | H12: 10 | I12: roll | J12: Open | K12: Meridian Packaging Co.
A13: POL-0008 | B13: PO-7008 | C13: NV-RENO | D13: MAT-FILM | E13: 45701 | F13: 45828 | G13: 1 | H13: 10 | I13: roll | J13: Open | K13: Meridian Packaging Co.
A14: POL-0009 | B14: PO-7009 | C14: NV-RENO | D14: MAT-CARTON | E14: 45702 | F14: 45726 | G14: 1 | H14: 20 | I14: carton | J14: Open | K14: Meridian Packaging Co.
A15: POL-0010 | B15: PO-7010 | C15: NV-RENO | D15: MAT-CARTON | E15: 45703 | F15: 45736 | G15: 1 | H15: 20 | I15: carton | J15: Open | K15: Meridian Packaging Co.
A16: POL-0011 | B16: PO-7011 | C16: NV-RENO | D16: MAT-CARTON | E16: 45704 | F16: 45757 | G16: 1 | H16: 20 | I16: carton | J16: Open | K16: Meridian Packaging Co.
A17: POL-0012 | B17: PO-7012 | C17: NV-RENO | D17: MAT-CARTON | E17: 45693 | F17: 45767 | G17: 1 | H17: 20 | I17: carton | J17: Open | K17: Meridian Packaging Co.
... A53: POL-0048 | B53: PO-7048 | C53: CA-FRESNO | D53: MAT-LABEL | E53: 45693 | F53: 45828 | G53: 1 | H53: 10 | I53: label | J53: Open | K53: Meridian Packaging Co.

Sheet Receipts
A1: Receipts
A2: Receipt detail loaded from the Nevada and California docks
A4: Exported 2025-02-28 17:10 UTC | Nevada and California packaging review
A5: Receipt Record ID | B5: Purchase Order | C5: Facility ID | D5: Material ID | E5: Receipt date | F5: Receipt status | G5: Packages received | H5: Units / package | I5: Unit | J5: Note | K5: Received by | L5: Source batch | M5: Calculated quantity
A6: RCV-0001 | B6: PO-7001 | C6: NV-RENO | D6: MAT-FILM | E6: 45726 | F6: Received | G6: 1 | H6: 10 | I6: roll | K6: Dock intake | L6: RCP-25-02 | M6: =G6*H6
A7: RCV-0002 | B7: PO-7002 | C7: NV-RENO | D7: MAT-FILM | E7: 45736 | F7: Received | G7: 1 | H7: 10 | I7: roll | K7: Dock intake | L7: RCP-25-02 | M7: =G7*H7
A8: RCV-0003 | B8: PO-7003 | C8: NV-RENO | D8: MAT-FILM | E8: 45757 | F8: Received | G8: 1 | H8: 10 | I8: roll | K8: Dock intake | L8: RCP-25-02 | M8: =G8*H8
A9: RCV-0004 | B9: PO-7004 | C9: NV-RENO | D9: MAT-FILM | E9: 45767 | F9: Received | G9: 1 | H9: 10 | I9: roll | K9: Dock intake | L9: RCP-25-02 | M9: =G9*H9
A10: RCV-0005 | B10: PO-7005 | C10: NV-RENO | D10: MAT-FILM | E10: 45787 | F10: Received | G10: 1 | H10: 10 | I10: roll | K10: Dock intake | L10: RCP-25-02 | M10: =G10*H10
A11: RCV-0006 | B11: PO-7006 | C11: NV-RENO | D11: MAT-FILM | E11: 45797 | F11: Received | G11: 1 | H11: 10 | I11: roll | K11: Dock intake | L11: RCP-25-02 | M11: =G11*H11
A12: RCV-0007 | B12: PO-7007 | C12: NV-RENO | D12: MAT-FILM | E12: 45818 | F12: Received | G12: 1 | H12: 10 | I12: roll | K12: Dock intake | L12: RCP-25-02 | M12: =G12*H12
A13: RCV-0008 | B13: PO-7008 | C13: NV-RENO | D13: MAT-FILM | E13: 45828 | F13: Received | G13: 1 | H13: 10 | I13: roll | K13: Dock intake | L13: RCP-25-02 | M13: =G13*H13
A14: RCV-0009 | B14: PO-7009 | C14: NV-RENO | D14: MAT-CARTON | E14: 45726 | F14: Received | G14: 1 | H14: 20 | I14: carton | K14: Dock intake | L14: RCP-25-02 | M14: =G14*H14
A15: RCV-0010 | B15: PO-7010 | C15: NV-RENO | D15: MAT-CARTON | E15: 45736 | F15: Received | G15: 1 | H15: 20 | I15: carton | K15: Dock intake | L15: RCP-25-02 | M15: =G15*H15
A16: RCV-0011 | B16: PO-7011 | C16: NV-RENO | D16: MAT-CARTON | E16: 45757 | F16: Received | G16: 1 | H16: 20 | I16: carton | K16: Dock intake | L16: RCP-25-02 | M16: =G16*H16
A17: RCV-0012 | B17: PO-7012 | C17: NV-RENO | D17: MAT-CARTON | E17: 45767 | F17: Received | G17: 1 | H17: 20 | I17: carton | K17: Dock intake | L17: RCP-25-02 | M17: =G17*H17
... A46: RCV-0041 | B46: PO-7041 | C46: CA-FRESNO | D46: MAT-LABEL | E46: 45726 | F46: Received | G46: 1 | H46: 20 | I46: label | K46: Dock intake | L46: RCP-25-02 | M46: =G46*H46
A47: RCV-0042 | B47: po-731a | C47: CA-FRESNO | D47: MAT-LABEL | E47: 45736 | F47: Received | G47: 3 | H47: 21 | I47: label | J47: Use 36, not 63 | K47: Dock intake | L47: RCP-25-02 | M47: =G47*H46
A48: RCV-0043 | B48: PO-7043 | C48: CA-FRESNO | D48: MAT-LABEL | E48: 45757 | F48: Received | G48: 1 | H48: 10 | I48: label | K48: Dock intake | L48: RCP-25-02 | M48: =G48*H48
A49: RCV-0044 | B49: PO-7044 | C49: CA-FRESNO | D49: MAT-LABEL | E49: 45767 | F49: Received | G49: 1 | H49: 10 | I49: label | K49: Dock intake | L49: RCP-25-02 | M49: =G49*H49
A50: RCV-0045 | B50: PO-7045 | C50: CA-FRESNO | D50: MAT-LABEL | E50: 45787 | F50: Received | G50: 1 | H50: 10 | I50: label | K50: Dock intake | L50: RCP-25-02 | M50: =G50*H50
A51: RCV-0046 | B51: PO-7046 | C51: CA-FRESNO | D51: MAT-LABEL | E51: 45797 | F51: Received | G51: 1 | H51: 10 | I51: label | K51: Dock intake | L51: RCP-25-02 | M51: =G51*H51
A52: RCV-0047 | B52: PO-7047 | C52: CA-FRESNO | D52: MAT-LABEL | E52: 45818 | F52: Received | G52: 1 | H52: 10 | I52: label | K52: Dock intake | L52: RCP-25-02 | M52: =G52*H52
A53: RCV-0048 | B53: PO-7048 | C53: CA-FRESNO | D53: MAT-LABEL | E53: 45828 | F53: Received | G53: 1 | H53: 10 | I53: label | K53: Dock intake | L53: RCP-25-02 | M53: =G53*H53
A54: RCV-0010 | B54: PO-7010 | C54: NV-RENO | D54: MAT-CARTON | E54: 45736 | F54: Received | G54: 1 | H54: 20 | I54: carton | K54: Dock intake | L54: RCP-25-02 | M54: =G54*H54

Sheet Forward Plan
A1: Forward Plan
A2: Forward inventory and procurement projection by facility, material, scenario, and forecast period
A3: Blue cells are source-linked facts. Green cells are calculated formulas. Yellow cells provide source lineage. Quantities are shown in the material unit listed on each row.
A6: Line | B6: Jurisdiction | C6: Organization | D6: Facility ID | E6: Material ID | F6: Material | G6: Unit | H6: Scenario | I6: Period ID | J6: Period label | K6: Period start | L6: Period end | M6: Opening stock (units) | N6: Scheduled receipts (units) | O6: Scenario demand (units) | P6: Stock before procurement (units) | Q6: Target ending stock (units) | R6: Order multiple (units) | S6: Unrounded procurement need (units) | T6: Procurement quantity (units) | U6: Projected ending stock (units) | V6: Demand coverage (periods; ending stock / current-period demand) | W6: Inventory source ID | X6: Demand source ID | Y6: Receipt source ID(s) | Z6: Parameter source ID | AA6: Normalized PO key(s) | AB6: Treatment note
A7: 1 | B7: ='Facility Map'!$D$6 | C7: ='Facility Map'!$C$6 | D7: ='Facility Map'!$A$6 | E7: ='Materials'!$A$6 | F7: ='Materials'!$B$6 | G7: ='Materials'!$C$6 | H7: ='Demand Plans'!$E$7 | I7: ='Review Control'!$A$13 | J7: ='Review Control'!$B$13 | K7: ='Review Control'!$C$13 | L7: ='Review Control'!$D$13 | M7: ='Inventory Snapshots'!$G$7 | N7: =SUM('Receipts'!$M$6,'Receipts'!$M$7) | O7: ='Demand Plans'!$J$7 | P7: =M7+N7-O7 | Q7: ='Packaging Parameters'!$F$7 | R7: ='Packaging Parameters'!$G$7 | S7: =MAX(0,Q7-P7) | T7: =IF(S7<=0,0,ROUNDUP(S7/R7,0)*R7) | U7: =P7+T7 | V7: =IF(O7=0,"N/A",U7/O7) | W7: ='Inventory Snapshots'!$A$7 | X7: ='Demand Plans'!$A$7 | Y7: ='Receipts'!$A$6&"; "&'Receipts'!$A$7 | Z7: ='Packaging Parameters'!$A$7 | AA7: =UPPER(TRIM('Receipts'!$B$6))&"; "&UPPER(TRIM('Receipts'!$B$7)) | AB7: Opening stock from current as-of inventory snapshot.
A8: 2 | B8: ='Facility Map'!$D$6 | C8: ='Facility Map'!$C$6 | D8: ='Facility Map'!$A$6 | E8: ='Materials'!$A$6 | F8: ='Materials'!$B$6 | G8: ='Materials'!$C$6 | H8: ='Demand Plans'!$E$8 | I8: ='Review Control'!$A$14 | J8: ='Review Control'!$B$14 | K8: ='Review Control'!$C$14 | L8: ='Review Control'!$D$14 | M8: =U7 | N8: =SUM('Receipts'!$M$8,'Receipts'!$M$9) | O8: ='Demand Plans'!$J$8 | P8: =M8+N8-O8 | Q8: ='Packaging Parameters'!$F$7 | R8: ='Packaging Parameters'!$G$7 | S8: =MAX(0,Q8-P8) | T8: =IF(S8<=0,0,ROUNDUP(S8/R8,0)*R8) | U8: =P8+T8 | V8: =IF(O8=0,"N/A",U8/O8) | W8: ='Inventory Snapshots'!$A$7 | X8: ='Demand Plans'!$A$8 | Y8: ='Receipts'!$A$8&"; "&'Receipts'!$A$9 | Z8: ='Packaging Parameters'!$A$7 | AA8: =UPPER(TRIM('Receipts'!$B$8))&"; "&UPPER(TRIM('Receipts'!$B$9)) | AB8: Opening stock carries from the prior projected ending stock.
A9: 3 | B9: ='Facility Map'!$D$6 | C9: ='Facility Map'!$C$6 | D9: ='Facility Map'!$A$6 | E9: ='Materials'!$A$6 | F9: ='Materials'!$B$6 | G9: ='Materials'!$C$6 | H9: ='Demand Plans'!$E$9 | I9: ='Review Control'!$A$15 | J9: ='Review Control'!$B$15 | K9: ='Review Control'!$C$15 | L9: ='Review Control'!$D$15 | M9: =U8 | N9: =SUM('Receipts'!$M$10,'Receipts'!$M$11) | O9: ='Demand Plans'!$J$9 | P9: =M9+N9-O9 | Q9: ='Packaging Parameters'!$F$7 | R9: ='Packaging Parameters'!$G$7 | S9: =MAX(0,Q9-P9) | T9: =IF(S9<=0,0,ROUNDUP(S9/R9,0)*R9) | U9: =P9+T9 | V9: =IF(O9=0,"N/A",U9/O9) | W9: ='Inventory Snapshots'!$A$7 | X9: ='Demand Plans'!$A$9 | Y9: ='Receipts'!$A$10&"; "&'Receipts'!$A$11 | Z9: ='Packaging Parameters'!$A$7 | AA9: =UPPER(TRIM('Receipts'!$B$10))&"; "&UPPER(TRIM('Receipts'!$B$11)) | AB9: Opening stock carries from the prior projected ending stock.
A10: 4 | B10: ='Facility Map'!$D$6 | C10: ='Facility Map'!$C$6 | D10: ='Facility Map'!$A$6 | E10: ='Materials'!$A$6 | F10: ='Materials'!$B$6 | G10: ='Materials'!$C$6 | H10: ='Demand Plans'!$E$10 | I10: ='Review Control'!$A$16 | J10: ='Review Control'!$B$16 | K10: ='Review Control'!$C$16 | L10: ='Review Control'!$D$16 | M10: =U9 | N10: =SUM('Receipts'!$M$12,'Receipts'!$M$13) | O10: ='Demand Plans'!$J$10 | P10: =M10+N10-O10 | Q10: ='Packaging Parameters'!$F$7 | R10: ='Packaging Parameters'!$G$7 | S10: =MAX(0,Q10-P10) | T10: =IF(S10<=0,0,ROUNDUP(S10/R10,0)*R10) | U10: =P10+T10 | V10: =IF(O10=0,"N/A",U10/O10) | W10: ='Inventory Snapshots'!$A$7 | X10: ='Demand Plans'!$A$10 | Y10: ='Receipts'!$A$12&"; "&'Receipts'!$A$13 | Z10: ='Packaging Parameters'!$A$7 | AA10: =UPPER(TRIM('Receipts'!$B$12))&"; "&UPPER(TRIM('Receipts'!$B$13)) | AB10: Opening stock carries from the prior projected ending stock.
A11: 5 | B11: ='Facility Map'!$D$6 | C11: ='Facility Map'!$C$6 | D11: ='Facility Map'!$A$6 | E11: ='Materials'!$A$6 | F11: ='Materials'!$B$6 | G11: ='Materials'!$C$6 | H11: ='Demand Plans'!$E$11 | I11: ='Review Control'!$A$13 | J11: ='Review Control'!$B$13 | K11: ='Review Control'!$C$13 | L11: ='Review Control'!$D$13 | M11: ='Inventory Snapshots'!$G$7 | N11: =SUM('Receipts'!$M$6,'Receipts'!$M$7) | O11: ='Demand Plans'!$J$11 | P11: =M11+N11-O11 | Q11: ='Packaging Parameters'!$F$7 | R11: ='Packaging Parameters'!$G$7 | S11: =MAX(0,Q11-P11) | T11: =IF(S11<=0,0,ROUNDUP(S11/R11,0)*R11) | U11: =P11+T11 | V11: =IF(O11=0,"N/A",U11/O11) | W11: ='Inventory Snapshots'!$A$7 | X11: ='Demand Plans'!$A$11 | Y11: ='Receipts'!$A$6&"; "&'Receipts'!$A$7 | Z11: ='Packaging Parameters'!$A$7 | AA11: =UPPER(TRIM('Receipts'!$B$6))&"; "&UPPER(TRIM('Receipts'!$B$7)) | AB11: Opening stock from current as-of inventory snapshot.
A12: 6 | B12: ='Facility Map'!$D$6 | C12: ='Facility Map'!$C$6 | D12: ='Facility Map'!$A$6 | E12: ='Materials'!$A$6 | F12: ='Materials'!$B$6 | G12: ='Materials'!$C$6 | H12: ='Demand Plans'!$E$12 | I12: ='Review Control'!$A$14 | J12: ='Review Control'!$B$14 | K12: ='Review Control'!$C$14 | L12: ='Review Control'!$D$14 | M12: =U11 | N12: =SUM('Receipts'!$M$8,'Receipts'!$M$9) | O12: ='Demand Plans'!$J$12 | P12: =M12+N12-O12 | Q12: ='Packaging Parameters'!$F$7 | R12: ='Packaging Parameters'!$G$7 | S12: =MAX(0,Q12-P12) | T12: =IF(S12<=0,0,ROUNDUP(S12/R12,0)*R12) | U12: =P12+T12 | V12: =IF(O12=0,"N/A",U12/O12) | W12: ='Inventory Snapshots'!$A$7 | X12: ='Demand Plans'!$A$12 | Y12: ='Receipts'!$A$8&"; "&'Receipts'!$A$9 | Z12: ='Packaging Parameters'!$A$7 | AA12: =UPPER(TRIM('Receipts'!$B$8))&"; "&UPPER(TRIM('Receipts'!$B$9)) | AB12: Opening stock carries from the prior projected ending stock.
A13: 7 | B13: ='Facility Map'!$D$6 | C13: ='Facility Map'!$C$6 | D13: ='Facility Map'!$A$6 | E13: ='Materials'!$A$6 | F13: ='Materials'!$B$6 | G13: ='Materials'!$C$6 | H13: ='Demand Plans'!$E$13 | I13: ='Review Control'!$A$15 | J13: ='Review Control'!$B$15 | K13: ='Review Control'!$C$15 | L13: ='Review Control'!$D$15 | M13: =U12 | N13: =SUM('Receipts'!$M$10,'Receipts'!$M$11) | O13: ='Demand Plans'!$J$13 | P13: =M13+N13-O13 | Q13: ='Packaging Parameters'!$F$7 | R13: ='Packaging Parameters'!$G$7 | S13: =MAX(0,Q13-P13) | T13: =IF(S13<=0,0,ROUNDUP(S13/R13,0)*R13) | U13: =P13+T13 | V13: =IF(O13=0,"N/A",U13/O13) | W13: ='Inventory Snapshots'!$A$7 | X13: ='Demand Plans'!$A$13 | Y13: ='Receipts'!$A$10&"; "&'Receipts'!$A$11 | Z13: ='Packaging Parameters'!$A$7 | AA13: =UPPER(TRIM('Receipts'!$B$10))&"; "&UPPER(TRIM('Receipts'!$B$11)) | AB13: Opening stock carries from the prior projected ending stock.
A14: 8 | B14: ='Facility Map'!$D$6 | C14: ='Facility Map'!$C$6 | D14: ='Facility Map'!$A$6 | E14: ='Materials'!$A$6 | F14: ='Materials'!$B$6 | G14: ='Materials'!$C$6 | H14: ='Demand Plans'!$E$14 | I14: ='Review Control'!$A$16 | J14: ='Review Control'!$B$16 | K14: ='Review Control'!$C$16 | L14: ='Review Control'!$D$16 | M14: =U13 | N14: =SUM('Receipts'!$M$12,'Receipts'!$M$13) | O14: ='Demand Plans'!$J$14 | P14: =M14+N14-O14 | Q14: ='Packaging Parameters'!$F$7 | R14: ='Packaging Parameters'!$G$7 | S14: =MAX(0,Q14-P14) | T14: =IF(S14<=0,0,ROUNDUP(S14/R14,0)*R14) | U14: =P14+T14 | V14: =IF(O14=0,"N/A",U14/O14) | W14: ='Inventory Snapshots'!$A$7 | X14: ='Demand Plans'!$A$14 | Y14: ='Receipts'!$A$12&"; "&'Receipts'!$A$13 | Z14: ='Packaging Parameters'!$A$7 | AA14: =UPPER(TRIM('Receipts'!$B$12))&"; "&UPPER(TRIM('Receipts'!$B$13)) | AB14: Opening stock carries from the prior projected ending stock.
A15: 9 | B15: ='Facility Map'!$D$6 | C15: ='Facility Map'!$C$6 | D15: ='Facility Map'!$A$6 | E15: ='Materials'!$A$7 | F15: ='Materials'!$B$7 | G15: ='Materials'!$C$7 | H15: ='Demand Plans'!$E$15 | I15: ='Review Control'!$A$13 | J15: ='Review Control'!$B$13 | K15: ='Review Control'!$C$13 | L15: ='Review Control'!$D$13 | M15: ='Inventory Snapshots'!$G$8 | N15: =SUM('Receipts'!$M$14,'Receipts'!$M$15) | O15: ='Demand Plans'!$J$15 | P15: =M15+N15-O15 | Q15: ='Packaging Parameters'!$F$8 | R15: ='Packaging Parameters'!$G$8 | S15: =MAX(0,Q15-P15) | T15: =IF(S15<=0,0,ROUNDUP(S15/R15,0)*R15) | U15: =P15+T15 | V15: =IF(O15=0,"N/A",U15/O15) | W15: ='Inventory Snapshots'!$A$8 | X15: ='Demand Plans'!$A$15 | Y15: ='Receipts'!$A$14&"; "&'Receipts'!$A$15 | Z15: ='Packaging Parameters'!$A$8 | AA15: =UPPER(TRIM('Receipts'!$B$14))&"; "&UPPER(TRIM('Receipts'!$B$15)) | AB15: Opening stock from current as-of inventory snapshot.
A16: 10 | B16: ='Facility Map'!$D$6 | C16: ='Facility Map'!$C$6 | D16: ='Facility Map'!$A$6 | E16: ='Materials'!$A$7 | F16: ='Materials'!$B$7 | G16: ='Materials'!$C$7 | H16: ='Demand Plans'!$E$16 | I16: ='Review Control'!$A$14 | J16: ='Review Control'!$B$14 | K16: ='Review Control'!$C$14 | L16: ='Review Control'!$D$14 | M16: =U15 | N16: =SUM('Receipts'!$M$16,'Receipts'!$M$17) | O16: ='Demand Plans'!$J$16 | P16: =M16+N16-O16 | Q16: ='Packaging Parameters'!$F$8 | R16: ='Packaging Parameters'!$G$8 | S16: =MAX(0,Q16-P16) | T16: =IF(S16<=0,0,ROUNDUP(S16/R16,0)*R16) | U16: =P16+T16 | V16: =IF(O16=0,"N/A",U16/O16) | W16: ='Inventory Snapshots'!$A$8 | X16: ='Demand Plans'!$A$16 | Y16: ='Receipts'!$A$16&"; "&'Receipts'!$A$17 | Z16: ='Packaging Parameters'!$A$8 | AA16: =UPPER(TRIM('Receipts'!$B$16))&"; "&UPPER(TRIM('Receipts'!$B$17)) | AB16: Opening stock carries from the prior projected ending stock.
A17: 11 | B17: ='Facility Map'!$D$6 | C17: ='Facility Map'!$C$6 | D17: ='Facility Map'!$A$6 | E17: ='Materials'!$A$7 | F17: ='Materials'!$B$7 | G17: ='Materials'!$C$7 | H17: ='Demand Plans'!$E$17 | I17: ='Review Control'!$A$15 | J17: ='Review Control'!$B$15 | K17: ='Review Control'!$C$15 | L17: ='Review Control'!$D$15 | M17: =U16 | N17: =SUM('Receipts'!$M$18,'Receipts'!$M$19) | O17: ='Demand Plans'!$J$17 | P17: =M17+N17-O17 | Q17: ='Packaging Parameters'!$F$8 | R17: ='Packaging Parameters'!$G$8 | S17: =MAX(0,Q17-P17) | T17: =IF(S17<=0,0,ROUNDUP(S17/R17,0)*R17) | U17: =P17+T17 | V17: =IF(O17=0,"N/A",U17/O17) | W17: ='Inventory Snapshots'!$A$8 | X17: ='Demand Plans'!$A$17 | Y17: ='Receipts'!$A$18&"; "&'Receipts'!$A$19 | Z17: ='Packaging Parameters'!$A$8 | AA17: =UPPER(TRIM('Receipts'!$B$18))&"; "&UPPER(TRIM('Receipts'!$B$19)) | AB17: Opening stock carries from the prior projected ending stock.
A18: 12 | B18: ='Facility Map'!$D$6 | C18: ='Facility Map'!$C$6 | D18: ='Facility Map'!$A$6 | E18: ='Materials'!$A$7 | F18: ='Materials'!$B$7 | G18: ='Materials'!$C$7 | H18: ='Demand Plans'!$E$18 | I18: ='Review Control'!$A$16 | J18: ='Review Control'!$B$16 | K18: ='Review Control'!$C$16 | L18: ='Review Control'!$D$16 | M18: =U17 | N18: =SUM('Receipts'!$M$20,'Receipts'!$M$21) | O18: ='Demand Plans'!$J$18 | P18: =M18+N18-O18 | Q18: ='Packaging Parameters'!$F$8 | R18: ='Packaging Parameters'!$G$8 | S18: =MAX(0,Q18-P18) | T18: =IF(S18<=0,0,ROUNDUP(S18/R18,0)*R18) | U18: =P18+T18 | V18: =IF(O18=0,"N/A",U18/O18) | W18: ='Inventory Snapshots'!$A$8 | X18: ='Demand Plans'!$A$18 | Y18: ='Receipts'!$A$20&"; "&'Receipts'!$A$21 | Z18: ='Packaging Parameters'!$A$8 | AA18: =UPPER(TRIM('Receipts'!$B$20))&"; "&UPPER(TRIM('Receipts'!$B$21)) | AB18: Opening stock carries from the prior projected ending stock.
A19: 13 | B19: ='Facility Map'!$D$6 | C19: ='Facility Map'!$C$6 | D19: ='Facility Map'!$A$6 | E19: ='Materials'!$A$7 | F19: ='Materials'!$B$7 | G19: ='Materials'!$C$7 | H19: ='Demand Plans'!$E$19 | I19: ='Review Control'!$A$13 | J19: ='Review Control'!$B$13 | K19: ='Review Control'!$C$13 | L19: ='Review Control'!$D$13 | M19: ='Inventory Snapshots'!$G$8 | N19: =SUM('Receipts'!$M$14,'Receipts'!$M$15) | O19: ='Demand Plans'!$J$19 | P19: =M19+N19-O19 | Q19: ='Packaging Parameters'!$F$8 | R19: ='Packaging Parameters'!$G$8 | S19: =MAX(0,Q19-P19) | T19: =IF(S19<=0,0,ROUNDUP(S19/R19,0)*R19) | U19: =P19+T19 | V19: =IF(O19=0,"N/A",U19/O19) | W19: ='Inventory Snapshots'!$A$8 | X19: ='Demand Plans'!$A$19 | Y19: ='Receipts'!$A$14&"; "&'Receipts'!$A$15 | Z19: ='Packaging Parameters'!$A$8 | AA19: =UPPER(TRIM('Receipts'!$B$14))&"; "&UPPER(TRIM('Receipts'!$B$15)) | AB19: Opening stock from current as-of inventory snapshot.
A20: 14 | B20: ='Facility Map'!$D$6 | C20: ='Facility Map'!$C$6 | D20: ='Facility Map'!$A$6 | E20: ='Materials'!$A$7 | F20: ='Materials'!$B$7 | G20: ='Materials'!$C$7 | H20: ='Demand Plans'!$E$20 | I20: ='Review Control'!$A$14 | J20: ='Review Control'!$B$14 | K20: ='Review Control'!$C$14 | L20: ='Review Control'!$D$14 | M20: =U19 | N20: =SUM('Receipts'!$M$16,'Receipts'!$M$17) | O20: ='Demand Plans'!$J$20 | P20: =M20+N20-O20 | Q20: ='Packaging Parameters'!$F$8 | R20: ='Packaging Parameters'!$G$8 | S20: =MAX(0,Q20-P20) | T20: =IF(S20<=0,0,ROUNDUP(S20/R20,0)*R20) | U20: =P20+T20 | V20: =IF(O20=0,"N/A",U20/O20) | W20: ='Inventory Snapshots'!$A$8 | X20: ='Demand Plans'!$A$20 | Y20: ='Receipts'!$A$16&"; "&'Receipts'!$A$17 | Z20: ='Packaging Parameters'!$A$8 | AA20: =UPPER(TRIM('Receipts'!$B$16))&"; "&UPPER(TRIM('Receipts'!$B$17)) | AB20: Opening stock carries from the prior projected ending stock.
A21: 15 | B21: ='Facility Map'!$D$6 | C21: ='Facility Map'!$C$6 | D21: ='Facility Map'!$A$6 | E21: ='Materials'!$A$7 | F21: ='Materials'!$B$7 | G21: ='Materials'!$C$7 | H21: ='Demand Plans'!$E$21 | I21: ='Review Control'!$A$15 | J21: ='Review Control'!$B$15 | K21: ='Review Control'!$C$15 | L21: ='Review Control'!$D$15 | M21: =U20 | N21: =SUM('Receipts'!$M$18,'Receipts'!$M$19) | O21: ='Demand Plans'!$J$21 | P21: =M21+N21-O21 | Q21: ='Packaging Parameters'!$F$8 | R21: ='Packaging Parameters'!$G$8 | S21: =MAX(0,Q21-P21) | T21: =IF(S21<=0,0,ROUNDUP(S21/R21,0)*R21) | U21: =P21+T21 | V21: =IF(O21=0,"N/A",U21/O21) | W21: ='Inventory Snapshots'!$A$8 | X21: ='Demand Plans'!$A$21 | Y21: ='Receipts'!$A$18&"; "&'Receipts'!$A$19 | Z21: ='Packaging Parameters'!$A$8 | AA21: =UPPER(TRIM('Receipts'!$B$18))&"; "&UPPER(TRIM('Receipts'!$B$19)) | AB21: Opening stock carries from the prior projected ending stock.
A22: 16 | B22: ='Facility Map'!$D$6 | C22: ='Facility Map'!$C$6 | D22: ='Facility Map'!$A$6 | E22: ='Materials'!$A$7 | F22: ='Materials'!$B$7 | G22: ='Materials'!$C$7 | H22: ='Demand Plans'!$E$22 | I22: ='Review Control'!$A$16 | J22: ='Review Control'!$B$16 | K22: ='Review Control'!$C$16 | L22: ='Review Control'!$D$16 | M22: =U21 | N22: =SUM('Receipts'!$M$20,'Receipts'!$M$21) | O22: ='Demand Plans'!$J$22 | P22: =M22+N22-O22 | Q22: ='Packaging Parameters'!$F$8 | R22: ='Packaging Parameters'!$G$8 | S22: =MAX(0,Q22-P22) | T22: =IF(S22<=0,0,ROUNDUP(S22/R22,0)*R22) | U22: =P22+T22 | V22: =IF(O22=0,"N/A",U22/O22) | W22: ='Inventory Snapshots'!$A$8 | X22: ='Demand Plans'!$A$22 | Y22: ='Receipts'!$A$20&"; "&'Receipts'!$A$21 | Z22: ='Packaging Parameters'!$A$8 | AA22: =UPPER(TRIM('Receipts'!$B$20))&"; "&UPPER(TRIM('Receipts'!$B$21)) | AB22: Opening stock carries from the prior projected ending stock.
A23: 17 | B23: ='Facility Map'!$D$6 | C23: ='Facility Map'!$C$6 | D23: ='Facility Map'!$A$6 | E23: ='Materials'!$A$8 | F23: ='Materials'!$B$8 | G23: ='Materials'!$C$8 | H23: ='Demand Plans'!$E$23 | I23: ='Review Control'!$A$13 | J23: ='Review Control'!$B$13 | K23: ='Review Control'!$C$13 | L23: ='Review Control'!$D$13 | M23: ='Inventory Snapshots'!$G$9 | N23: =SUM('Receipts'!$M$22,'Receipts'!$M$23) | O23: ='Demand Plans'!$J$23 | P23: =M23+N23-O23 | Q23: ='Packaging Parameters'!$F$9 | R23: ='Packaging Parameters'!$G$9 | S23: =MAX(0,Q23-P23) | T23: =IF(S23<=0,0,ROUNDUP(S23/R23,0)*R23) | U23: =P23+T23 | V23: =IF(O23=0,"N/A",U23/O23) | W23: ='Inventory Snapshots'!$A$9 | X23: ='Demand Plans'!$A$23 | Y23: ='Receipts'!$A$22&"; "&'Receipts'!$A$23 | Z23: ='Packaging Parameters'!$A$9 | AA23: =UPPER(TRIM('Receipts'!$B$22))&"; "&UPPER(TRIM('Receipts'!$B$23)) | AB23: Opening stock from current as-of inventory snapshot.
A24: 18 | B24: ='Facility Map'!$D$6 | C24: ='Facility Map'!$C$6 | D24: ='Facility Map'!$A$6 | E24: ='Materials'!$A$8 | F24: ='Materials'!$B$8 | G24: ='Materials'!$C$8 | H24: ='Demand Plans'!$E$24 | I24: ='Review Control'!$A$14 | J24: ='Review Control'!$B$14 | K24: ='Review Control'!$C$14 | L24: ='Review Control'!$D$14 | M24: =U23 | N24: =SUM('Receipts'!$M$24,'Receipts'!$M$25) | O24: ='Demand Plans'!$J$24 | P24: =M24+N24-O24 | Q24: ='Packaging Parameters'!$F$9 | R24: ='Packaging Parameters'!$G$9 | S24: =MAX(0,Q24-P24) | T24: =IF(S24<=0,0,ROUNDUP(S24/R24,0)*R24) | U24: =P24+T24 | V24: =IF(O24=0,"N/A",U24/O24) | W24: ='Inventory Snapshots'!$A$9 | X24: ='Demand Plans'!$A$24 | Y24: ='Receipts'!$A$24&"; "&'Receipts'!$A$25 | Z24: ='Packaging Parameters'!$A$9 | AA24: =UPPER(TRIM('Receipts'!$B$24))&"; "&UPPER(TRIM('Receipts'!$B$25)) | AB24: Opening stock carries from the prior projected ending stock.
A25: 19 | B25: ='Facility Map'!$D$6 | C25: ='Facility Map'!$C$6 | D25: ='Facility Map'!$A$6 | E25: ='Materials'!$A$8 | F25: ='Materials'!$B$8 | G25: ='Materials'!$C$8 | H25: ='Demand Plans'!$E$25 | I25: ='Review Control'!$A$15 | J25: ='Review Control'!$B$15 | K25: ='Review Control'!$C$15 | L25: ='Review Control'!$D$15 | M25: =U24 | N25: =SUM('Receipts'!$M$26,'Receipts'!$M$27) | O25: ='Demand Plans'!$J$25 | P25: =M25+N25-O25 | Q25: ='Packaging Parameters'!$F$9 | R25: ='Packaging Parameters'!$G$9 | S25: =MAX(0,Q25-P25) | T25: =IF(S25<=0,0,ROUNDUP(S25/R25,0)*R25) | U25: =P25+T25 | V25: =IF(O25=0,"N/A",U25/O25) | W25: ='Inventory Snapshots'!$A$9 | X25: ='Demand Plans'!$A$25 | Y25: ='Receipts'!$A$26&"; "&'Receipts'!$A$27 | Z25: ='Packaging Parameters'!$A$9 | AA25: =UPPER(TRIM('Receipts'!$B$26))&"; "&UPPER(TRIM('Receipts'!$B$27)) | AB25: Opening stock carries from the prior projected ending stock.
A26: 20 | B26: ='Facility Map'!$D$6 | C26: ='Facility Map'!$C$6 | D26: ='Facility Map'!$A$6 | E26: ='Materials'!$A$8 | F26: ='Materials'!$B$8 | G26: ='Materials'!$C$8 | H26: ='Demand Plans'!$E$26 | I26: ='Review Control'!$A$16 | J26: ='Review Control'!$B$16 | K26: ='Review Control'!$C$16 | L26: ='Review Control'!$D$16 | M26: =U25 | N26: =SUM('Receipts'!$M$28,'Receipts'!$M$29) | O26: ='Demand Plans'!$J$26 | P26: =M26+N26-O26 | Q26: ='Packaging Parameters'!$F$9 | R26: ='Packaging Parameters'!$G$9 | S26: =MAX(0,Q26-P26) | T26: =IF(S26<=0,0,ROUNDUP(S26/R26,0)*R26) | U26: =P26+T26 | V26: =IF(O26=0,"N/A",U26/O26) | W26: ='Inventory Snapshots'!$A$9 | X26: ='Demand Plans'!$A$26 | Y26: ='Receipts'!$A$28&"; "&'Receipts'!$A$29 | Z26: ='Packaging Parameters'!$A$9 | AA26: =UPPER(TRIM('Receipts'!$B$28))&"; "&UPPER(TRIM('Receipts'!$B$29)) | AB26: Opening stock carries from the prior projected ending stock.
A27: 21 | B27: ='Facility Map'!$D$6 | C27: ='Facility Map'!$C$6 | D27: ='Facility Map'!$A$6 | E27: ='Materials'!$A$8 | F27: ='Materials'!$B$8 | G27: ='Materials'!$C$8 | H27: ='Demand Plans'!$E$27 | I27: ='Review Control'!$A$13 | J27: ='Review Control'!$B$13 | K27: ='Review Control'!$C$13 | L27: ='Review Control'!$D$13 | M27: ='Inventory Snapshots'!$G$9 | N27: =SUM('Receipts'!$M$22,'Receipts'!$M$23) | O27: ='Demand Plans'!$J$27 | P27: =M27+N27-O27 | Q27: ='Packaging Parameters'!$F$9 | R27: ='Packaging Parameters'!$G$9 | S27: =MAX(0,Q27-P27) | T27: =IF(S27<=0,0,ROUNDUP(S27/R27,0)*R27) | U27: =P27+T27 | V27: =IF(O27=0,"N/A",U27/O27) | W27: ='Inventory Snapshots'!$A$9 | X27: ='Demand Plans'!$A$27 | Y27: ='Receipts'!$A$22&"; "&'Receipts'!$A$23 | Z27: ='Packaging Parameters'!$A$9 | AA27: =UPPER(TRIM('Receipts'!$B$22))&"; "&UPPER(TRIM('Receipts'!$B$23)) | AB27: Opening stock from current as-of inventory snapshot.
A28: 22 | B28: ='Facility Map'!$D$6 | C28: ='Facility Map'!$C$6 | D28: ='Facility Map'!$A$6 | E28: ='Materials'!$A$8 | F28: ='Materials'!$B$8 | G28: ='Materials'!$C$8 | H28: ='Demand Plans'!$E$28 | I28: ='Review Control'!$A$14 | J28: ='Review Control'!$B$14 | K28: ='Review Control'!$C$14 | L28: ='Review Control'!$D$14 | M28: =U27 | N28: =SUM('Receipts'!$M$24,'Receipts'!$M$25) | O28: ='Demand Plans'!$J$28 | P28: =M28+N28-O28 | Q28: ='Packaging Parameters'!$F$9 | R28: ='Packaging Parameters'!$G$9 | S28: =MAX(0,Q28-P28) | T28: =IF(S28<=0,0,ROUNDUP(S28/R28,0)*R28) | U28: =P28+T28 | V28: =IF(O28=0,"N/A",U28/O28) | W28: ='Inventory Snapshots'!$A$9 | X28: ='Demand Plans'!$A$28 | Y28: ='Receipts'!$A$24&"; "&'Receipts'!$A$25 | Z28: ='Packaging Parameters'!$A$9 | AA28: =UPPER(TRIM('Receipts'!$B$24))&"; "&UPPER(TRIM('Receipts'!$B$25)) | AB28: Opening stock carries from the prior projected ending stock.
A29: 23 | B29: ='Facility Map'!$D$6 | C29: ='Facility Map'!$C$6 | D29: ='Facility Map'!$A$6 | E29: ='Materials'!$A$8 | F29: ='Materials'!$B$8 | G29: ='Materials'!$C$8 | H29: ='Demand Plans'!$E$29 | I29: ='Review Control'!$A$15 | J29: ='Review Control'!$B$15 | K29: ='Review Control'!$C$15 | L29: ='Review Control'!$D$15 | M29: =U28 | N29: =SUM('Receipts'!$M$26,'Receipts'!$M$27) | O29: ='Demand Plans'!$J$29 | P29: =M29+N29-O29 | Q29: ='Packaging Parameters'!$F$9 | R29: ='Packaging Parameters'!$G$9 | S29: =MAX(0,Q29-P29) | T29: =IF(S29<=0,0,ROUNDUP(S29/R29,0)*R29) | U29: =P29+T29 | V29: =IF(O29=0,"N/A",U29/O29) | W29: ='Inventory Snapshots'!$A$9 | X29: ='Demand Plans'!$A$29 | Y29: ='Receipts'!$A$26&"; "&'Receipts'!$A$27 | Z29: ='Packaging Parameters'!$A$9 | AA29: =UPPER(TRIM('Receipts'!$B$26))&"; "&UPPER(TRIM('Receipts'!$B$27)) | AB29: Opening stock carries from the prior projected ending stock.
A30: 24 | B30: ='Facility Map'!$D$6 | C30: ='Facility Map'!$C$6 | D30: ='Facility Map'!$A$6 | E30: ='Materials'!$A$8 | F30: ='Materials'!$B$8 | G30: ='Materials'!$C$8 | H30: ='Demand Plans'!$E$30 | I30: ='Review Control'!$A$16 | J30: ='Review Control'!$B$16 | K30: ='Review Control'!$C$16 | L30: ='Review Control'!$D$16 | M30: =U29 | N30: =SUM('Receipts'!$M$28,'Receipts'!$M$29) | O30: ='Demand Plans'!$J$30 | P30: =M30+N30-O30 | Q30: ='Packaging Parameters'!$F$9 | R30: ='Packaging Parameters'!$G$9 | S30: =MAX(0,Q30-P30) | T30: =IF(S30<=0,0,ROUNDUP(S30/R30,0)*R30) | U30: =P30+T30 | V30: =IF(O30=0,"N/A",U30/O30) | W30: ='Inventory Snapshots'!$A$9 | X30: ='Demand Plans'!$A$30 | Y30: ='Receipts'!$A$28&"; "&'Receipts'!$A$29 | Z30: ='Packaging Parameters'!$A$9 | AA30: =UPPER(TRIM('Receipts'!$B$28))&"; "&UPPER(TRIM('Receipts'!$B$29)) | AB30: Opening stock carries from the prior projected ending stock.
A31: 25 | B31: ='Facility Map'!$D$7 | C31: ='Facility Map'!$C$7 | D31: ='Facility Map'!$A$7 | E31: ='Materials'!$A$6 | F31: ='Materials'!$B$6 | G31: ='Materials'!$C$6 | H31: ='Demand Plans'!$E$31 | I31: ='Review Control'!$A$13 | J31: ='Review Control'!$B$13 | K31: ='Review Control'!$C$13 | L31: ='Review Control'!$D$13 | M31: ='Inventory Snapshots'!$G$10 | N31: =SUM('Receipts'!$M$30,'Receipts'!$M$31) | O31: ='Demand Plans'!$J$31 | P31: =M31+N31-O31 | Q31: ='Packaging Parameters'!$F$10 | R31: ='Packaging Parameters'!$G$10 | S31: =MAX(0,Q31-P31) | T31: =IF(S31<=0,0,ROUNDUP(S31/R31,0)*R31) | U31: =P31+T31 | V31: =IF(O31=0,"N/A",U31/O31) | W31: ='Inventory Snapshots'!$A$10 | X31: ='Demand Plans'!$A$31 | Y31: ='Receipts'!$A$30&"; "&'Receipts'!$A$31 | Z31: ='Packaging Parameters'!$A$10 | AA31: =UPPER(TRIM('Receipts'!$B$30))&"; "&UPPER(TRIM('Receipts'!$B$31)) | AB31: Opening stock from current as-of inventory snapshot.
A32: 26 | B32: ='Facility Map'!$D$7 | C32: ='Facility Map'!$C$7 | D32: ='Facility Map'!$A$7 | E32: ='Materials'!$A$6 | F32: ='Materials'!$B$6 | G32: ='Materials'!$C$6 | H32: ='Demand Plans'!$E$32 | I32: ='Review Control'!$A$14 | J32: ='Review Control'!$B$14 | K32: ='Review Control'!$C$14 | L32: ='Review Control'!$D$14 | M32: =U31 | N32: =SUM('Receipts'!$M$32,'Receipts'!$M$33) | O32: ='Demand Plans'!$J$32 | P32: =M32+N32-O32 | Q32: ='Packaging Parameters'!$F$10 | R32: ='Packaging Parameters'!$G$10 | S32: =MAX(0,Q32-P32) | T32: =IF(S32<=0,0,ROUNDUP(S32/R32,0)*R32) | U32: =P32+T32 | V32: =IF(O32=0,"N/A",U32/O32) | W32: ='Inventory Snapshots'!$A$10 | X32: ='Demand Plans'!$A$32 | Y32: ='Receipts'!$A$32&"; "&'Receipts'!$A$33 | Z32: ='Packaging Parameters'!$A$10 | AA32: =UPPER(TRIM('Receipts'!$B$32))&"; "&UPPER(TRIM('Receipts'!$B$33)) | AB32: Opening stock carries from the prior projected ending stock.
A33: 27 | B33: ='Facility Map'!$D$7 | C33: ='Facility Map'!$C$7 | D33: ='Facility Map'!$A$7 | E33: ='Materials'!$A$6 | F33: ='Materials'!$B$6 | G33: ='Materials'!$C$6 | H33: ='Demand Plans'!$E$33 | I33: ='Review Control'!$A$15 | J33: ='Review Control'!$B$15 | K33: ='Review Control'!$C$15 | L33: ='Review Control'!$D$15 | M33: =U32 | N33: =SUM('Receipts'!$M$34,'Receipts'!$M$35) | O33: ='Demand Plans'!$J$33 | P33: =M33+N33-O33 | Q33: ='Packaging Parameters'!$F$10 | R33: ='Packaging Parameters'!$G$10 | S33: =MAX(0,Q33-P33) | T33: =IF(S33<=0,0,ROUNDUP(S33/R33,0)*R33) | U33: =P33+T33 | V33: =IF(O33=0,"N/A",U33/O33) | W33: ='Inventory Snapshots'!$A$10 | X33: ='Demand Plans'!$A$33 | Y33: ='Receipts'!$A$34&"; "&'Receipts'!$A$35 | Z33: ='Packaging Parameters'!$A$10 | AA33: =UPPER(TRIM('Receipts'!$B$34))&"; "&UPPER(TRIM('Receipts'!$B$35)) | AB33: Opening stock carries from the prior projected ending stock.
A34: 28 | B34: ='Facility Map'!$D$7 | C34: ='Facility Map'!$C$7 | D34: ='Facility Map'!$A$7 | E34: ='Materials'!$A$6 | F34: ='Materials'!$B$6 | G34: ='Materials'!$C$6 | H34: ='Demand Plans'!$E$34 | I34: ='Review Control'!$A$16 | J34: ='Review Control'!$B$16 | K34: ='Review Control'!$C$16 | L34: ='Review Control'!$D$16 | M34: =U33 | N34: =SUM('Receipts'!$M$36,'Receipts'!$M$37) | O34: ='Demand Plans'!$J$34 | P34: =M34+N34-O34 | Q34: ='Packaging Parameters'!$F$10 | R34: ='Packaging Parameters'!$G$10 | S34: =MAX(0,Q34-P34) | T34: =IF(S34<=0,0,ROUNDUP(S34/R34,0)*R34) | U34: =P34+T34 | V34: =IF(O34=0,"N/A",U34/O34) | W34: ='Inventory Snapshots'!$A$10 | X34: ='Demand Plans'!$A$34 | Y34: ='Receipts'!$A$36&"; "&'Receipts'!$A$37 | Z34: ='Packaging Parameters'!$A$10 | AA34: =UPPER(TRIM('Receipts'!$B$36))&"; "&UPPER(TRIM('Receipts'!$B$37)) | AB34: Opening stock carries from the prior projected ending stock.
A35: 29 | B35: ='Facility Map'!$D$7 | C35: ='Facility Map'!$C$7 | D35: ='Facility Map'!$A$7 | E35: ='Materials'!$A$6 | F35: ='Materials'!$B$6 | G35: ='Materials'!$C$6 | H35: ='Demand Plans'!$E$35 | I35: ='Review Control'!$A$13 | J35: ='Review Control'!$B$13 | K35: ='Review Control'!$C$13 | L35: ='Review Control'!$D$13 | M35: ='Inventory Snapshots'!$G$10 | N35: =SUM('Receipts'!$M$30,'Receipts'!$M$31) | O35: ='Demand Plans'!$J$35 | P35: =M35+N35-O35 | Q35: ='Packaging Parameters'!$F$10 | R35: ='Packaging Parameters'!$G$10 | S35: =MAX(0,Q35-P35) | T35: =IF(S35<=0,0,ROUNDUP(S35/R35,0)*R35) | U35: =P35+T35 | V35: =IF(O35=0,"N/A",U35/O35) | W35: ='Inventory Snapshots'!$A$10 | X35: ='Demand Plans'!$A$35 | Y35: ='Receipts'!$A$30&"; "&'Receipts'!$A$31 | Z35: ='Packaging Parameters'!$A$10 | AA35: =UPPER(TRIM('Receipts'!$B$30))&"; "&UPPER(TRIM('Receipts'!$B$31)) | AB35: Opening stock from current as-of inventory snapshot.
A36: 30 | B36: ='Facility Map'!$D$7 | C36: ='Facility Map'!$C$7 | D36: ='Facility Map'!$A$7 | E36: ='Materials'!$A$6 | F36: ='Materials'!$B$6 | G36: ='Materials'!$C$6 | H36: ='Demand Plans'!$E$36 | I36: ='Review Control'!$A$14 | J36: ='Review Control'!$B$14 | K36: ='Review Control'!$C$14 | L36: ='Review Control'!$D$14 | M36: =U35 | N36: =SUM('Receipts'!$M$32,'Receipts'!$M$33) | O36: ='Demand Plans'!$J$36 | P36: =M36+N36-O36 | Q36: ='Packaging Parameters'!$F$10 | R36: ='Packaging Parameters'!$G$10 | S36: =MAX(0,Q36-P36) | T36: =IF(S36<=0,0,ROUNDUP(S36/R36,0)*R36) | U36: =P36+T36 | V36: =IF(O36=0,"N/A",U36/O36) | W36: ='Inventory Snapshots'!$A$10 | X36: ='Demand Plans'!$A$36 | Y36: ='Receipts'!$A$32&"; "&'Receipts'!$A$33 | Z36: ='Packaging Parameters'!$A$10 | AA36: =UPPER(TRIM('Receipts'!$B$32))&"; "&UPPER(TRIM('Receipts'!$B$33)) | AB36: Opening stock carries from the prior projected ending stock.
A37: 31 | B37: ='Facility Map'!$D$7 | C37: ='Facility Map'!$C$7 | D37: ='Facility Map'!$A$7 | E37: ='Materials'!$A$6 | F37: ='Materials'!$B$6 | G37: ='Materials'!$C$6 | H37: ='Demand Plans'!$E$37 | I37: ='Review Control'!$A$15 | J37: ='Review Control'!$B$15 | K37: ='Review Control'!$C$15 | L37: ='Review Control'!$D$15 | M37: =U36 | N37: =SUM('Receipts'!$M$34,'Receipts'!$M$35) | O37: ='Demand Plans'!$J$37 | P37: =M37+N37-O37 | Q37: ='Packaging Parameters'!$F$10 | R37: ='Packaging Parameters'!$G$10 | S37: =MAX(0,Q37-P37) | T37: =IF(S37<=0,0,ROUNDUP(S37/R37,0)*R37) | U37: =P37+T37 | V37: =IF(O37=0,"N/A",U37/O37) | W37: ='Inventory Snapshots'!$A$10 | X37: ='Demand Plans'!$A$37 | Y37: ='Receipts'!$A$34&"; "&'Receipts'!$A$35 | Z37: ='Packaging Parameters'!$A$10 | AA37: =UPPER(TRIM('Receipts'!$B$34))&"; "&UPPER(TRIM('Receipts'!$B$35)) | AB37: Opening stock carries from the prior projected ending stock.
A38: 32 | B38: ='Facility Map'!$D$7 | C38: ='Facility Map'!$C$7 | D38: ='Facility Map'!$A$7 | E38: ='Materials'!$A$6 | F38: ='Materials'!$B$6 | G38: ='Materials'!$C$6 | H38: ='Demand Plans'!$E$38 | I38: ='Review Control'!$A$16 | J38: ='Review Control'!$B$16 | K38: ='Review Control'!$C$16 | L38: ='Review Control'!$D$16 | M38: =U37 | N38: =SUM('Receipts'!$M$36,'Receipts'!$M$37) | O38: ='Demand Plans'!$J$38 | P38: =M38+N38-O38 | Q38: ='Packaging Parameters'!$F$10 | R38: ='Packaging Parameters'!$G$10 | S38: =MAX(0,Q38-P38) | T38: =IF(S38<=0,0,ROUNDUP(S38/R38,0)*R38) | U38: =P38+T38 | V38: =IF(O38=0,"N/A",U38/O38) | W38: ='Inventory Snapshots'!$A$10 | X38: ='Demand Plans'!$A$38 | Y38: ='Receipts'!$A$36&"; "&'Receipts'!$A$37 | Z38: ='Packaging Parameters'!$A$10 | AA38: =UPPER(TRIM('Receipts'!$B$36))&"; "&UPPER(TRIM('Receipts'!$B$37)) | AB38: Opening stock carries from the prior projected ending stock.
A39: 33 | B39: ='Facility Map'!$D$7 | C39: ='Facility Map'!$C$7 | D39: ='Facility Map'!$A$7 | E39: ='Materials'!$A$7 | F39: ='Materials'!$B$7 | G39: ='Materials'!$C$7 | H39: ='Demand Plans'!$E$39 | I39: ='Review Control'!$A$13 | J39: ='Review Control'!$B$13 | K39: ='Review Control'!$C$13 | L39: ='Review Control'!$D$13 | M39: ='Inventory Snapshots'!$G$11 | N39: =SUM('Receipts'!$M$38,'Receipts'!$M$39) | O39: ='Demand Plans'!$J$39 | P39: =M39+N39-O39 | Q39: ='Packaging Parameters'!$F$11 | R39: ='Packaging Parameters'!$G$11 | S39: =MAX(0,Q39-P39) | T39: =IF(S39<=0,0,ROUNDUP(S39/R39,0)*R39) | U39: =P39+T39 | V39: =IF(O39=0,"N/A",U39/O39) | W39: ='Inventory Snapshots'!$A$11 | X39: ='Demand Plans'!$A$39 | Y39: ='Receipts'!$A$38&"; "&'Receipts'!$A$39 | Z39: ='Packaging Parameters'!$A$11 | AA39: =UPPER(TRIM('Receipts'!$B$38))&"; "&UPPER(TRIM('Receipts'!$B$39)) | AB39: Opening stock from current as-of inventory snapshot.
A40: 34 | B40: ='Facility Map'!$D$7 | C40: ='Facility Map'!$C$7 | D40: ='Facility Map'!$A$7 | E40: ='Materials'!$A$7 | F40: ='Materials'!$B$7 | G40: ='Materials'!$C$7 | H40: ='Demand Plans'!$E$40 | I40: ='Review Control'!$A$14 | J40: ='Review Control'!$B$14 | K40: ='Review Control'!$C$14 | L40: ='Review Control'!$D$14 | M40: =U39 | N40: =SUM('Receipts'!$M$40,'Receipts'!$M$41) | O40: ='Demand Plans'!$J$40 | P40: =M40+N40-O40 | Q40: ='Packaging Parameters'!$F$11 | R40: ='Packaging Parameters'!$G$11 | S40: =MAX(0,Q40-P40) | T40: =IF(S40<=0,0,ROUNDUP(S40/R40,0)*R40) | U40: =P40+T40 | V40: =IF(O40=0,"N/A",U40/O40) | W40: ='Inventory Snapshots'!$A$11 | X40: ='Demand Plans'!$A$40 | Y40: ='Receipts'!$A$40&"; "&'Receipts'!$A$41 | Z40: ='Packaging Parameters'!$A$11 | AA40: =UPPER(TRIM('Receipts'!$B$40))&"; "&UPPER(TRIM('Receipts'!$B$41)) | AB40: Opening stock carries from the prior projected ending stock.
A41: 35 | B41: ='Facility Map'!$D$7 | C41: ='Facility Map'!$C$7 | D41: ='Facility Map'!$A$7 | E41: ='Materials'!$A$7 | F41: ='Materials'!$B$7 | G41: ='Materials'!$C$7 | H41: ='Demand Plans'!$E$41 | I41: ='Review Control'!$A$15 | J41: ='Review Control'!$B$15 | K41: ='Review Control'!$C$15 | L41: ='Review Control'!$D$15 | M41: =U40 | N41: =SUM('Receipts'!$M$42,'Receipts'!$M$43) | O41: ='Demand Plans'!$J$41 | P41: =M41+N41-O41 | Q41: ='Packaging Parameters'!$F$11 | R41: ='Packaging Parameters'!$G$11 | S41: =MAX(0,Q41-P41) | T41: =IF(S41<=0,0,ROUNDUP(S41/R41,0)*R41) | U41: =P41+T41 | V41: =IF(O41=0,"N/A",U41/O41) | W41: ='Inventory Snapshots'!$A$11 | X41: ='Demand Plans'!$A$41 | Y41: ='Receipts'!$A$42&"; "&'Receipts'!$A$43 | Z41: ='Packaging Parameters'!$A$11 | AA41: =UPPER(TRIM('Receipts'!$B$42))&"; "&UPPER(TRIM('Receipts'!$B$43)) | AB41: Opening stock carries from the prior projected ending stock.
A42: 36 | B42: ='Facility Map'!$D$7 | C42: ='Facility Map'!$C$7 | D42: ='Facility Map'!$A$7 | E42: ='Materials'!$A$7 | F42: ='Materials'!$B$7 | G42: ='Materials'!$C$7 | H42: ='Demand Plans'!$E$42 | I42: ='Review Control'!$A$16 | J42: ='Review Control'!$B$16 | K42: ='Review Control'!$C$16 | L42: ='Review Control'!$D$16 | M42: =U41 | N42: =SUM('Receipts'!$M$44,'Receipts'!$M$45) | O42: ='Demand Plans'!$J$42 | P42: =M42+N42-O42 | Q42: ='Packaging Parameters'!$F$11 | R42: ='Packaging Parameters'!$G$11 | S42: =MAX(0,Q42-P42) | T42: =IF(S42<=0,0,ROUNDUP(S42/R42,0)*R42) | U42: =P42+T42 | V42: =IF(O42=0,"N/A",U42/O42) | W42: ='Inventory Snapshots'!$A$11 | X42: ='Demand Plans'!$A$42 | Y42: ='Receipts'!$A$44&"; "&'Receipts'!$A$45 | Z42: ='Packaging Parameters'!$A$11 | AA42: =UPPER(TRIM('Receipts'!$B$44))&"; "&UPPER(TRIM('Receipts'!$B$45)) | AB42: Opening stock carries from the prior projected ending stock.
...

Sheet Scenario Comparison
A1: Scenario Comparison
A2: Neutral comparison of Nevada and California under each supplied demand scenario
A3: All totals are formula-linked to Forward Plan. Procurement covers every forecast period; ending-stock context is the final supplied period. No scenario is selected here.
A6: Scope | B6: Jurisdiction | C6: Organization | D6: Scenario | E6: Forecast periods | F6: Procurement quantity (units, all periods) | G6: Final-period ending stock (units) | H6: Final-period demand (units) | I6: Final-period coverage (periods) | J6: Zero-demand detail rows
A7: Jurisdiction | B7: Nevada | C7: Candlewick Supply | D7: Base Demand | E7: ='Forward Plan'!$I$7&" to "&'Forward Plan'!$I$54 | F7: =SUMIFS('Forward Plan'!$T$7:$T$54,'Forward Plan'!$B$7:$B$54,B7,'Forward Plan'!$H$7:$H$54,D7) | G7: =SUMIFS('Forward Plan'!$U$7:$U$54,'Forward Plan'!$B$7:$B$54,B7,'Forward Plan'!$H$7:$H$54,D7,'Forward Plan'!$I$7:$I$54,"P4") | H7: =SUMIFS('Forward Plan'!$O$7:$O$54,'Forward Plan'!$B$7:$B$54,B7,'Forward Plan'!$H$7:$H$54,D7,'Forward Plan'!$I$7:$I$54,"P4") | I7: =IF(H7=0,"N/A",G7/H7) | J7: =COUNTIFS('Forward Plan'!$B$7:$B$54,B7,'Forward Plan'!$H$7:$H$54,D7,'Forward Plan'!$O$7:$O$54,0)
A8: Jurisdiction | B8: Nevada | C8: Candlewick Supply | D8: Peak Demand | E8: ='Forward Plan'!$I$7&" to "&'Forward Plan'!$I$54 | F8: =SUMIFS('Forward Plan'!$T$7:$T$54,'Forward Plan'!$B$7:$B$54,B8,'Forward Plan'!$H$7:$H$54,D8) | G8: =SUMIFS('Forward Plan'!$U$7:$U$54,'Forward Plan'!$B$7:$B$54,B8,'Forward Plan'!$H$7:$H$54,D8,'Forward Plan'!$I$7:$I$54,"P4") | H8: =SUMIFS('Forward Plan'!$O$7:$O$54,'Forward Plan'!$B$7:$B$54,B8,'Forward Plan'!$H$7:$H$54,D8,'Forward Plan'!$I$7:$I$54,"P4") | I8: =IF(H8=0,"N/A",G8/H8) | J8: =COUNTIFS('Forward Plan'!$B$7:$B$54,B8,'Forward Plan'!$H$7:$H$54,D8,'Forward Plan'!$O$7:$O$54,0)
A9: Jurisdiction | B9: California | C9: Everstead Systems | D9: Base Demand | E9: ='Forward Plan'!$I$7&" to "&'Forward Plan'!$I$54 | F9: =SUMIFS('Forward Plan'!$T$7:$T$54,'Forward Plan'!$B$7:$B$54,B9,'Forward Plan'!$H$7:$H$54,D9) | G9: =SUMIFS('Forward Plan'!$U$7:$U$54,'Forward Plan'!$B$7:$B$54,B9,'Forward Plan'!$H$7:$H$54,D9,'Forward Plan'!$I$7:$I$54,"P4") | H9: =SUMIFS('Forward Plan'!$O$7:$O$54,'Forward Plan'!$B$7:$B$54,B9,'Forward Plan'!$H$7:$H$54,D9,'Forward Plan'!$I$7:$I$54,"P4") | I9: =IF(H9=0,"N/A",G9/H9) | J9: =COUNTIFS('Forward Plan'!$B$7:$B$54,B9,'Forward Plan'!$H$7:$H$54,D9,'Forward Plan'!$O$7:$O$54,0)
A10: Jurisdiction | B10: California | C10: Everstead Systems | D10: Peak Demand | E10: ='Forward Plan'!$I$7&" to "&'Forward Plan'!$I$54 | F10: =SUMIFS('Forward Plan'!$T$7:$T$54,'Forward Plan'!$B$7:$B$54,B10,'Forward Plan'!$H$7:$H$54,D10) | G10: =SUMIFS('Forward Plan'!$U$7:$U$54,'Forward Plan'!$B$7:$B$54,B10,'Forward Plan'!$H$7:$H$54,D10,'Forward Plan'!$I$7:$I$54,"P4") | H10: =SUMIFS('Forward Plan'!$O$7:$O$54,'Forward Plan'!$B$7:$B$54,B10,'Forward Plan'!$H$7:$H$54,D10,'Forward Plan'!$I$7:$I$54,"P4") | I10: =IF(H10=0,"N/A",G10/H10) | J10: =COUNTIFS('Forward Plan'!$B$7:$B$54,B10,'Forward Plan'!$H$7:$H$54,D10,'Forward Plan'!$O$7:$O$54,0)
A11: Enterprise | B11: All operations | C11: Candlewick Supply + Everstead Systems | D11: Base Demand | E11: ='Forward Plan'!$I$7&" to "&'Forward Plan'!$I$54 | F11: =SUMIF('Forward Plan'!$H$7:$H$54,D11,'Forward Plan'!$T$7:$T$54) | G11: =SUMIFS('Forward Plan'!$U$7:$U$54,'Forward Plan'!$H$7:$H$54,D11,'Forward Plan'!$I$7:$I$54,"P4") | H11: =SUMIFS('Forward Plan'!$O$7:$O$54,'Forward Plan'!$H$7:$H$54,D11,'Forward Plan'!$I$7:$I$54,"P4") | I11: =IF(H11=0,"N/A",G11/H11) | J11: =COUNTIFS('Forward Plan'!$H$7:$H$54,D11,'Forward Plan'!$O$7:$O$54,0)
A12: Enterprise | B12: All operations | C12: Candlewick Supply + Everstead Systems | D12: Peak Demand | E12: ='Forward Plan'!$I$7&" to "&'Forward Plan'!$I$54 | F12: =SUMIF('Forward Plan'!$H$7:$H$54,D12,'Forward Plan'!$T$7:$T$54) | G12: =SUMIFS('Forward Plan'!$U$7:$U$54,'Forward Plan'!$H$7:$H$54,D12,'Forward Plan'!$I$7:$I$54,"P4") | H12: =SUMIFS('Forward Plan'!$O$7:$O$54,'Forward Plan'!$H$7:$H$54,D12,'Forward Plan'!$I$7:$I$54,"P4") | I12: =IF(H12=0,"N/A",G12/H12) | J12: =COUNTIFS('Forward Plan'!$H$7:$H$54,D12,'Forward Plan'!$O$7:$O$54,0)
A15: Between-scenario difference: Peak Demand minus Base Demand
A16: Jurisdiction | B16: Base procurement (units) | C16: Peak procurement (units) | D16: Difference: Peak minus Base (units) | E16: Base final ending stock (units) | F16: Peak final ending stock (units) | G16: Difference: Peak minus Base (units)
A17: Nevada | B17: =F7 | C17: =F8 | D17: =C17-B17 | E17: =G7 | F17: =G8 | G17: =F17-E17
A18: California | B18: =F9 | C18: =F10 | D18: =C18-B18 | E18: =G9 | F18: =G10 | G18: =F18-E18
A19: All operations | B19: =F11 | C19: =F12 | D19: =C19-B19 | E19: =G11 | F19: =G12 | G19: =F19-E19
A22: Final-period material context
A23: Jurisdiction | B23: Scenario | C23: Material | D23: Unit | E23: Procurement quantity (units, all periods) | F23: Final ending stock (units) | G23: Final demand (units) | H23: Final coverage (periods)
A24: Nevada | B24: Base Demand | C24: Stretch Film Roll | D24: =INDEX('Forward Plan'!$G$7:$G$54,MATCH(C24,'Forward Plan'!$F$7:$F$54,0)) | E24: =SUMIFS('Forward Plan'!$T$7:$T$54,'Forward Plan'!$B$7:$B$54,A24,'Forward Plan'!$H$7:$H$54,B24,'Forward Plan'!$F$7:$F$54,C24) | F24: =SUMIFS('Forward Plan'!$U$7:$U$54,'Forward Plan'!$B$7:$B$54,A24,'Forward Plan'!$H$7:$H$54,B24,'Forward Plan'!$F$7:$F$54,C24,'Forward Plan'!$I$7:$I$54,"P4") | G24: =SUMIFS('Forward Plan'!$O$7:$O$54,'Forward Plan'!$B$7:$B$54,A24,'Forward Plan'!$H$7:$H$54,B24,'Forward Plan'!$F$7:$F$54,C24,'Forward Plan'!$I$7:$I$54,"P4") | H24: =IF(G24=0,"N/A",F24/G24)
A25: Nevada | B25: Base Demand | C25: Shipping Carton | D25: =INDEX('Forward Plan'!$G$7:$G$54,MATCH(C25,'Forward Plan'!$F$7:$F$54,0)) | E25: =SUMIFS('Forward Plan'!$T$7:$T$54,'Forward Plan'!$B$7:$B$54,A25,'Forward Plan'!$H$7:$H$54,B25,'Forward Plan'!$F$7:$F$54,C25) | F25: =SUMIFS('Forward Plan'!$U$7:$U$54,'Forward Plan'!$B$7:$B$54,A25,'Forward Plan'!$H$7:$H$54,B25,'Forward Plan'!$F$7:$F$54,C25,'Forward Plan'!$I$7:$I$54,"P4") | G25: =SUMIFS('Forward Plan'!$O$7:$O$54,'Forward Plan'!$B$7:$B$54,A25,'Forward Plan'!$H$7:$H$54,B25,'Forward Plan'!$F$7:$F$54,C25,'Forward Plan'!$I$7:$I$54,"P4") | H25: =IF(G25=0,"N/A",F25/G25)
A26: Nevada | B26: Base Demand | C26: Pallet Label | D26: =INDEX('Forward Plan'!$G$7:$G$54,MATCH(C26,'Forward Plan'!$F$7:$F$54,0)) | E26: =SUMIFS('Forward Plan'!$T$7:$T$54,'Forward Plan'!$B$7:$B$54,A26,'Forward Plan'!$H$7:$H$54,B26,'Forward Plan'!$F$7:$F$54,C26) | F26: =SUMIFS('Forward Plan'!$U$7:$U$54,'Forward Plan'!$B$7:$B$54,A26,'Forward Plan'!$H$7:$H$54,B26,'Forward Plan'!$F$7:$F$54,C26,'Forward Plan'!$I$7:$I$54,"P4") | G26: =SUMIFS('Forward Plan'!$O$7:$O$54,'Forward Plan'!$B$7:$B$54,A26,'Forward Plan'!$H$7:$H$54,B26,'Forward Plan'!$F$7:$F$54,C26,'Forward Plan'!$I$7:$I$54,"P4") | H26: =IF(G26=0,"N/A",F26/G26)
A27: Nevada | B27: Peak Demand | C27: Stretch Film Roll | D27: =INDEX('Forward Plan'!$G$7:$G$54,MATCH(C27,'Forward Plan'!$F$7:$F$54,0)) | E27: =SUMIFS('Forward Plan'!$T$7:$T$54,'Forward Plan'!$B$7:$B$54,A27,'Forward Plan'!$H$7:$H$54,B27,'Forward Plan'!$F$7:$F$54,C27) | F27: =SUMIFS('Forward Plan'!$U$7:$U$54,'Forward Plan'!$B$7:$B$54,A27,'Forward Plan'!$H$7:$H$54,B27,'Forward Plan'!$F$7:$F$54,C27,'Forward Plan'!$I$7:$I$54,"P4") | G27: =SUMIFS('Forward Plan'!$O$7:$O$54,'Forward Plan'!$B$7:$B$54,A27,'Forward Plan'!$H$7:$H$54,B27,'Forward Plan'!$F$7:$F$54,C27,'Forward Plan'!$I$7:$I$54,"P4") | H27: =IF(G27=0,"N/A",F27/G27)
A28: Nevada | B28: Peak Demand | C28: Shipping Carton | D28: =INDEX('Forward Plan'!$G$7:$G$54,MATCH(C28,'Forward Plan'!$F$7:$F$54,0)) | E28: =SUMIFS('Forward Plan'!$T$7:$T$54,'Forward Plan'!$B$7:$B$54,A28,'Forward Plan'!$H$7:$H$54,B28,'Forward Plan'!$F$7:$F$54,C28) | F28: =SUMIFS('Forward Plan'!$U$7:$U$54,'Forward Plan'!$B$7:$B$54,A28,'Forward Plan'!$H$7:$H$54,B28,'Forward Plan'!$F$7:$F$54,C28,'Forward Plan'!$I$7:$I$54,"P4") | G28: =SUMIFS('Forward Plan'!$O$7:$O$54,'Forward Plan'!$B$7:$B$54,A28,'Forward Plan'!$H$7:$H$54,B28,'Forward Plan'!$F$7:$F$54,C28,'Forward Plan'!$I$7:$I$54,"P4") | H28: =IF(G28=0,"N/A",F28/G28)
A29: Nevada | B29: Peak Demand | C29: Pallet Label | D29: =INDEX('Forward Plan'!$G$7:$G$54,MATCH(C29,'Forward Plan'!$F$7:$F$54,0)) | E29: =SUMIFS('Forward Plan'!$T$7:$T$54,'Forward Plan'!$B$7:$B$54,A29,'Forward Plan'!$H$7:$H$54,B29,'Forward Plan'!$F$7:$F$54,C29) | F29: =SUMIFS('Forward Plan'!$U$7:$U$54,'Forward Plan'!$B$7:$B$54,A29,'Forward Plan'!$H$7:$H$54,B29,'Forward Plan'!$F$7:$F$54,C29,'Forward Plan'!$I$7:$I$54,"P4") | G29: =SUMIFS('Forward Plan'!$O$7:$O$54,'Forward Plan'!$B$7:$B$54,A29,'Forward Plan'!$H$7:$H$54,B29,'Forward Plan'!$F$7:$F$54,C29,'Forward Plan'!$I$7:$I$54,"P4") | H29: =IF(G29=0,"N/A",F29/G29)
A30: California | B30: Base Demand | C30: Stretch Film Roll | D30: =INDEX('Forward Plan'!$G$7:$G$54,MATCH(C30,'Forward Plan'!$F$7:$F$54,0)) | E30: =SUMIFS('Forward Plan'!$T$7:$T$54,'Forward Plan'!$B$7:$B$54,A30,'Forward Plan'!$H$7:$H$54,B30,'Forward Plan'!$F$7:$F$54,C30) | F30: =SUMIFS('Forward Plan'!$U$7:$U$54,'Forward Plan'!$B$7:$B$54,A30,'Forward Plan'!$H$7:$H$54,B30,'Forward Plan'!$F$7:$F$54,C30,'Forward Plan'!$I$7:$I$54,"P4") | G30: =SUMIFS('Forward Plan'!$O$7:$O$54,'Forward Plan'!$B$7:$B$54,A30,'Forward Plan'!$H$7:$H$54,B30,'Forward Plan'!$F$7:$F$54,C30,'Forward Plan'!$I$7:$I$54,"P4") | H30: =IF(G30=0,"N/A",F30/G30)
A31: California | B31: Base Demand | C31: Shipping Carton | D31: =INDEX('Forward Plan'!$G$7:$G$54,MATCH(C31,'Forward Plan'!$F$7:$F$54,0)) | E31: =SUMIFS('Forward Plan'!$T$7:$T$54,'Forward Plan'!$B$7:$B$54,A31,'Forward Plan'!$H$7:$H$54,B31,'Forward Plan'!$F$7:$F$54,C31) | F31: =SUMIFS('Forward Plan'!$U$7:$U$54,'Forward Plan'!$B$7:$B$54,A31,'Forward Plan'!$H$7:$H$54,B31,'Forward Plan'!$F$7:$F$54,C31,'Forward Plan'!$I$7:$I$54,"P4") | G31: =SUMIFS('Forward Plan'!$O$7:$O$54,'Forward Plan'!$B$7:$B$54,A31,'Forward Plan'!$H$7:$H$54,B31,'Forward Plan'!$F$7:$F$54,C31,'Forward Plan'!$I$7:$I$54,"P4") | H31: =IF(G31=0,"N/A",F31/G31)
A32: California | B32: Base Demand | C32: Pallet Label | D32: =INDEX('Forward Plan'!$G$7:$G$54,MATCH(C32,'Forward Plan'!$F$7:$F$54,0)) | E32: =SUMIFS('Forward Plan'!$T$7:$T$54,'Forward Plan'!$B$7:$B$54,A32,'Forward Plan'!$H$7:$H$54,B32,'Forward Plan'!$F$7:$F$54,C32) | F32: =SUMIFS('Forward Plan'!$U$7:$U$54,'Forward Plan'!$B$7:$B$54,A32,'Forward Plan'!$H$7:$H$54,B32,'Forward Plan'!$F$7:$F$54,C32,'Forward Plan'!$I$7:$I$54,"P4") | G32: =SUMIFS('Forward Plan'!$O$7:$O$54,'Forward Plan'!$B$7:$B$54,A32,'Forward Plan'!$H$7:$H$54,B32,'Forward Plan'!$F$7:$F$54,C32,'Forward Plan'!$I$7:$I$54,"P4") | H32: =IF(G32=0,"N/A",F32/G32)
A33: California | B33: Peak Demand | C33: Stretch Film Roll | D33: =INDEX('Forward Plan'!$G$7:$G$54,MATCH(C33,'Forward Plan'!$F$7:$F$54,0)) | E33: =SUMIFS('Forward Plan'!$T$7:$T$54,'Forward Plan'!$B$7:$B$54,A33,'Forward Plan'!$H$7:$H$54,B33,'Forward Plan'!$F$7:$F$54,C33) | F33: =SUMIFS('Forward Plan'!$U$7:$U$54,'Forward Plan'!$B$7:$B$54,A33,'Forward Plan'!$H$7:$H$54,B33,'Forward Plan'!$F$7:$F$54,C33,'Forward Plan'!$I$7:$I$54,"P4") | G33: =SUMIFS('Forward Plan'!$O$7:$O$54,'Forward Plan'!$B$7:$B$54,A33,'Forward Plan'!$H$7:$H$54,B33,'Forward Plan'!$F$7:$F$54,C33,'Forward Plan'!$I$7:$I$54,"P4") | H33: =IF(G33=0,"N/A",F33/G33)
