Workbook

Sheet Roster
A1: Clearwater Board — Night Receiving Staffing Plan
A2: Supervisor: Antoni Goodwin | Horizon: 05 Oct–15 Nov 2026 | Use weekly selectors in column B.
A4: Week | B4: Selected Package ID
A5: W1 | B5: W1-P03
A6: W2 | B6: W2-P02
A7: W3 | B7: W3-P04
A8: W4 | B8: W4-P01
A9: W5 | B9: W5-P03
A10: W6 | B10: W6-P02
A12: Week | B12: Rail date | C12: Clerk | D12: Shift | E12: Trainer | F12: Trainee | G12: Counted sign-off hours | H12: Reason code | I12: Selected package | J12: Coverage note | K12: Placement source
A13: W1 | B13: 2026-10-06 | C13: Agnes Pemberton | D13: =IFERROR(INDEX(Data!$E$2:$E$577,MATCH(A13&"|"&INDEX($B$5:$B$10,MATCH(A13,$A$5:$A$10,0))&"|"&B13&"|"&C13,Data!$J$2:$J$577,0)),"") -> Night | E13: =IFERROR(INDEX(Data!$F$2:$F$577,MATCH(A13&"|"&INDEX($B$5:$B$10,MATCH(A13,$A$5:$A$10,0))&"|"&B13&"|"&C13,Data!$J$2:$J$577,0)),"") -> Mirela Wainwright | F13: =IFERROR(INDEX(Data!$G$2:$G$577,MATCH(A13&"|"&INDEX($B$5:$B$10,MATCH(A13,$A$5:$A$10,0))&"|"&B13&"|"&C13,Data!$J$2:$J$577,0)),"") -> Agnes Pemberton | G13: =IFERROR(INDEX(Data!$H$2:$H$577,MATCH(A13&"|"&INDEX($B$5:$B$10,MATCH(A13,$A$5:$A$10,0))&"|"&B13&"|"&C13,Data!$J$2:$J$577,0)),0) -> 8 | H13: =IFERROR(INDEX(Data!$I$2:$I$577,MATCH(A13&"|"&INDEX($B$5:$B$10,MATCH(A13,$A$5:$A$10,0))&"|"&B13&"|"&C13,Data!$J$2:$J$577,0)),"") -> SIGNOFF | I13: =INDEX($B$5:$B$10,MATCH(A13,$A$5:$A$10,0)) -> W1-P03 | J13: =IF(D13="Night","Rail receiving coverage","Day control / qualified backup") -> Rail receiving coverage | K13: ="weekly_staffing_options.xlsx / "&I13&" / Package Details" -> weekly_staffing_options.xlsx / W1-P03 / Package Details
A14: W1 | B14: 2026-10-06 | C14: Pascal Ellingsen | D14: =IFERROR(INDEX(Data!$E$2:$E$577,MATCH(A14&"|"&INDEX($B$5:$B$10,MATCH(A14,$A$5:$A$10,0))&"|"&B14&"|"&C14,Data!$J$2:$J$577,0)),"") -> Day | E14: =IFERROR(INDEX(Data!$F$2:$F$577,MATCH(A14&"|"&INDEX($B$5:$B$10,MATCH(A14,$A$5:$A$10,0))&"|"&B14&"|"&C14,Data!$J$2:$J$577,0)),"") -> 0 | F14: =IFERROR(INDEX(Data!$G$2:$G$577,MATCH(A14&"|"&INDEX($B$5:$B$10,MATCH(A14,$A$5:$A$10,0))&"|"&B14&"|"&C14,Data!$J$2:$J$577,0)),"") -> 0 | G14: =IFERROR(INDEX(Data!$H$2:$H$577,MATCH(A14&"|"&INDEX($B$5:$B$10,MATCH(A14,$A$5:$A$10,0))&"|"&B14&"|"&C14,Data!$J$2:$J$577,0)),0) -> 0 | H14: =IFERROR(INDEX(Data!$I$2:$I$577,MATCH(A14&"|"&INDEX($B$5:$B$10,MATCH(A14,$A$5:$A$10,0))&"|"&B14&"|"&C14,Data!$J$2:$J$577,0)),"") -> DAY_BACKUP | I14: =INDEX($B$5:$B$10,MATCH(A14,$A$5:$A$10,0)) -> W1-P03 | J14: =IF(D14="Night","Rail receiving coverage","Day control / qualified backup") -> Day control / qualified backup | K14: ="weekly_staffing_options.xlsx / "&I14&" / Package Details" -> weekly_staffing_options.xlsx / W1-P03 / Package Details
A15: W1 | B15: 2026-10-06 | C15: Mirela Wainwright | D15: =IFERROR(INDEX(Data!$E$2:$E$577,MATCH(A15&"|"&INDEX($B$5:$B$10,MATCH(A15,$A$5:$A$10,0))&"|"&B15&"|"&C15,Data!$J$2:$J$577,0)),"") -> Night | E15: =IFERROR(INDEX(Data!$F$2:$F$577,MATCH(A15&"|"&INDEX($B$5:$B$10,MATCH(A15,$A$5:$A$10,0))&"|"&B15&"|"&C15,Data!$J$2:$J$577,0)),"") -> Agnes Pemberton | F15: =IFERROR(INDEX(Data!$G$2:$G$577,MATCH(A15&"|"&INDEX($B$5:$B$10,MATCH(A15,$A$5:$A$10,0))&"|"&B15&"|"&C15,Data!$J$2:$J$577,0)),"") -> 0 | G15: =IFERROR(INDEX(Data!$H$2:$H$577,MATCH(A15&"|"&INDEX($B$5:$B$10,MATCH(A15,$A$5:$A$10,0))&"|"&B15&"|"&C15,Data!$J$2:$J$577,0)),0) -> 0 | H15: =IFERROR(INDEX(Data!$I$2:$I$577,MATCH(A15&"|"&INDEX($B$5:$B$10,MATCH(A15,$A$5:$A$10,0))&"|"&B15&"|"&C15,Data!$J$2:$J$577,0)),"") -> TRAINER | I15: =INDEX($B$5:$B$10,MATCH(A15,$A$5:$A$10,0)) -> W1-P03 | J15: =IF(D15="Night","Rail receiving coverage","Day control / qualified backup") -> Rail receiving coverage | K15: ="weekly_staffing_options.xlsx / "&I15&" / Package Details" -> weekly_staffing_options.xlsx / W1-P03 / Package Details
A16: W1 | B16: 2026-10-06 | C16: Ibrahim Reinholt | D16: =IFERROR(INDEX(Data!$E$2:$E$577,MATCH(A16&"|"&INDEX($B$5:$B$10,MATCH(A16,$A$5:$A$10,0))&"|"&B16&"|"&C16,Data!$J$2:$J$577,0)),"") -> Day | E16: =IFERROR(INDEX(Data!$F$2:$F$577,MATCH(A16&"|"&INDEX($B$5:$B$10,MATCH(A16,$A$5:$A$10,0))&"|"&B16&"|"&C16,Data!$J$2:$J$577,0)),"") -> 0 | F16: =IFERROR(INDEX(Data!$G$2:$G$577,MATCH(A16&"|"&INDEX($B$5:$B$10,MATCH(A16,$A$5:$A$10,0))&"|"&B16&"|"&C16,Data!$J$2:$J$577,0)),"") -> 0 | G16: =IFERROR(INDEX(Data!$H$2:$H$577,MATCH(A16&"|"&INDEX($B$5:$B$10,MATCH(A16,$A$5:$A$10,0))&"|"&B16&"|"&C16,Data!$J$2:$J$577,0)),0) -> 0 | H16: =IFERROR(INDEX(Data!$I$2:$I$577,MATCH(A16&"|"&INDEX($B$5:$B$10,MATCH(A16,$A$5:$A$10,0))&"|"&B16&"|"&C16,Data!$J$2:$J$577,0)),"") -> STANDARD_COVER | I16: =INDEX($B$5:$B$10,MATCH(A16,$A$5:$A$10,0)) -> W1-P03 | J16: =IF(D16="Night","Rail receiving coverage","Day control / qualified backup") -> Day control / qualified backup | K16: ="weekly_staffing_options.xlsx / "&I16&" / Package Details" -> weekly_staffing_options.xlsx / W1-P03 / Package Details
A17: W1 | B17: 2026-10-07 | C17: Agnes Pemberton | D17: =IFERROR(INDEX(Data!$E$2:$E$577,MATCH(A17&"|"&INDEX($B$5:$B$10,MATCH(A17,$A$5:$A$10,0))&"|"&B17&"|"&C17,Data!$J$2:$J$577,0)),"") -> Night | E17: =IFERROR(INDEX(Data!$F$2:$F$577,MATCH(A17&"|"&INDEX($B$5:$B$10,MATCH(A17,$A$5:$A$10,0))&"|"&B17&"|"&C17,Data!$J$2:$J$577,0)),"") -> Mirela Wainwright | F17: =IFERROR(INDEX(Data!$G$2:$G$577,MATCH(A17&"|"&INDEX($B$5:$B$10,MATCH(A17,$A$5:$A$10,0))&"|"&B17&"|"&C17,Data!$J$2:$J$577,0)),"") -> Agnes Pemberton | G17: =IFERROR(INDEX(Data!$H$2:$H$577,MATCH(A17&"|"&INDEX($B$5:$B$10,MATCH(A17,$A$5:$A$10,0))&"|"&B17&"|"&C17,Data!$J$2:$J$577,0)),0) -> 8 | H17: =IFERROR(INDEX(Data!$I$2:$I$577,MATCH(A17&"|"&INDEX($B$5:$B$10,MATCH(A17,$A$5:$A$10,0))&"|"&B17&"|"&C17,Data!$J$2:$J$577,0)),"") -> SIGNOFF | I17: =INDEX($B$5:$B$10,MATCH(A17,$A$5:$A$10,0)) -> W1-P03 | J17: =IF(D17="Night","Rail receiving coverage","Day control / qualified backup") -> Rail receiving coverage | K17: ="weekly_staffing_options.xlsx / "&I17&" / Package Details" -> weekly_staffing_options.xlsx / W1-P03 / Package Details
A18: W1 | B18: 2026-10-07 | C18: Pascal Ellingsen | D18: =IFERROR(INDEX(Data!$E$2:$E$577,MATCH(A18&"|"&INDEX($B$5:$B$10,MATCH(A18,$A$5:$A$10,0))&"|"&B18&"|"&C18,Data!$J$2:$J$577,0)),"") -> Day | E18: =IFERROR(INDEX(Data!$F$2:$F$577,MATCH(A18&"|"&INDEX($B$5:$B$10,MATCH(A18,$A$5:$A$10,0))&"|"&B18&"|"&C18,Data!$J$2:$J$577,0)),"") -> 0 | F18: =IFERROR(INDEX(Data!$G$2:$G$577,MATCH(A18&"|"&INDEX($B$5:$B$10,MATCH(A18,$A$5:$A$10,0))&"|"&B18&"|"&C18,Data!$J$2:$J$577,0)),"") -> 0 | G18: =IFERROR(INDEX(Data!$H$2:$H$577,MATCH(A18&"|"&INDEX($B$5:$B$10,MATCH(A18,$A$5:$A$10,0))&"|"&B18&"|"&C18,Data!$J$2:$J$577,0)),0) -> 0 | H18: =IFERROR(INDEX(Data!$I$2:$I$577,MATCH(A18&"|"&INDEX($B$5:$B$10,MATCH(A18,$A$5:$A$10,0))&"|"&B18&"|"&C18,Data!$J$2:$J$577,0)),"") -> DAY_BACKUP | I18: =INDEX($B$5:$B$10,MATCH(A18,$A$5:$A$10,0)) -> W1-P03 | J18: =IF(D18="Night","Rail receiving coverage","Day control / qualified backup") -> Day control / qualified backup | K18: ="weekly_staffing_options.xlsx / "&I18&" / Package Details" -> weekly_staffing_options.xlsx / W1-P03 / Package Details
A19: W1 | B19: 2026-10-07 | C19: Mirela Wainwright | D19: =IFERROR(INDEX(Data!$E$2:$E$577,MATCH(A19&"|"&INDEX($B$5:$B$10,MATCH(A19,$A$5:$A$10,0))&"|"&B19&"|"&C19,Data!$J$2:$J$577,0)),"") -> Night | E19: =IFERROR(INDEX(Data!$F$2:$F$577,MATCH(A19&"|"&INDEX($B$5:$B$10,MATCH(A19,$A$5:$A$10,0))&"|"&B19&"|"&C19,Data!$J$2:$J$577,0)),"") -> Agnes Pemberton | F19: =IFERROR(INDEX(Data!$G$2:$G$577,MATCH(A19&"|"&INDEX($B$5:$B$10,MATCH(A19,$A$5:$A$10,0))&"|"&B19&"|"&C19,Data!$J$2:$J$577,0)),"") -> 0 | G19: =IFERROR(INDEX(Data!$H$2:$H$577,MATCH(A19&"|"&INDEX($B$5:$B$10,MATCH(A19,$A$5:$A$10,0))&"|"&B19&"|"&C19,Data!$J$2:$J$577,0)),0) -> 0 | H19: =IFERROR(INDEX(Data!$I$2:$I$577,MATCH(A19&"|"&INDEX($B$5:$B$10,MATCH(A19,$A$5:$A$10,0))&"|"&B19&"|"&C19,Data!$J$2:$J$577,0)),"") -> TRAINER | I19: =INDEX($B$5:$B$10,MATCH(A19,$A$5:$A$10,0)) -> W1-P03 | J19: =IF(D19="Night","Rail receiving coverage","Day control / qualified backup") -> Rail receiving coverage | K19: ="weekly_staffing_options.xlsx / "&I19&" / Package Details" -> weekly_staffing_options.xlsx / W1-P03 / Package Details
A20: W1 | B20: 2026-10-07 | C20: Ibrahim Reinholt | D20: =IFERROR(INDEX(Data!$E$2:$E$577,MATCH(A20&"|"&INDEX($B$5:$B$10,MATCH(A20,$A$5:$A$10,0))&"|"&B20&"|"&C20,Data!$J$2:$J$577,0)),"") -> Day | E20: =IFERROR(INDEX(Data!$F$2:$F$577,MATCH(A20&"|"&INDEX($B$5:$B$10,MATCH(A20,$A$5:$A$10,0))&"|"&B20&"|"&C20,Data!$J$2:$J$577,0)),"") -> 0 | F20: =IFERROR(INDEX(Data!$G$2:$G$577,MATCH(A20&"|"&INDEX($B$5:$B$10,MATCH(A20,$A$5:$A$10,0))&"|"&B20&"|"&C20,Data!$J$2:$J$577,0)),"") -> 0 | G20: =IFERROR(INDEX(Data!$H$2:$H$577,MATCH(A20&"|"&INDEX($B$5:$B$10,MATCH(A20,$A$5:$A$10,0))&"|"&B20&"|"&C20,Data!$J$2:$J$577,0)),0) -> 0 | H20: =IFERROR(INDEX(Data!$I$2:$I$577,MATCH(A20&"|"&INDEX($B$5:$B$10,MATCH(A20,$A$5:$A$10,0))&"|"&B20&"|"&C20,Data!$J$2:$J$577,0)),"") -> STANDARD_COVER | I20: =INDEX($B$5:$B$10,MATCH(A20,$A$5:$A$10,0)) -> W1-P03 | J20: =IF(D20="Night","Rail receiving coverage","Day control / qualified backup") -> Day control / qualified backup | K20: ="weekly_staffing_options.xlsx / "&I20&" / Package Details" -> weekly_staffing_options.xlsx / W1-P03 / Package Details
A21: W1 | B21: 2026-10-08 | C21: Agnes Pemberton | D21: =IFERROR(INDEX(Data!$E$2:$E$577,MATCH(A21&"|"&INDEX($B$5:$B$10,MATCH(A21,$A$5:$A$10,0))&"|"&B21&"|"&C21,Data!$J$2:$J$577,0)),"") -> Night | E21: =IFERROR(INDEX(Data!$F$2:$F$577,MATCH(A21&"|"&INDEX($B$5:$B$10,MATCH(A21,$A$5:$A$10,0))&"|"&B21&"|"&C21,Data!$J$2:$J$577,0)),"") -> Mirela Wainwright | F21: =IFERROR(INDEX(Data!$G$2:$G$577,MATCH(A21&"|"&INDEX($B$5:$B$10,MATCH(A21,$A$5:$A$10,0))&"|"&B21&"|"&C21,Data!$J$2:$J$577,0)),"") -> Agnes Pemberton | G21: =IFERROR(INDEX(Data!$H$2:$H$577,MATCH(A21&"|"&INDEX($B$5:$B$10,MATCH(A21,$A$5:$A$10,0))&"|"&B21&"|"&C21,Data!$J$2:$J$577,0)),0) -> 8 | H21: =IFERROR(INDEX(Data!$I$2:$I$577,MATCH(A21&"|"&INDEX($B$5:$B$10,MATCH(A21,$A$5:$A$10,0))&"|"&B21&"|"&C21,Data!$J$2:$J$577,0)),"") -> SIGNOFF | I21: =INDEX($B$5:$B$10,MATCH(A21,$A$5:$A$10,0)) -> W1-P03 | J21: =IF(D21="Night","Rail receiving coverage","Day control / qualified backup") -> Rail receiving coverage | K21: ="weekly_staffing_options.xlsx / "&I21&" / Package Details" -> weekly_staffing_options.xlsx / W1-P03 / Package Details
A22: W1 | B22: 2026-10-08 | C22: Pascal Ellingsen | D22: =IFERROR(INDEX(Data!$E$2:$E$577,MATCH(A22&"|"&INDEX($B$5:$B$10,MATCH(A22,$A$5:$A$10,0))&"|"&B22&"|"&C22,Data!$J$2:$J$577,0)),"") -> Day | E22: =IFERROR(INDEX(Data!$F$2:$F$577,MATCH(A22&"|"&INDEX($B$5:$B$10,MATCH(A22,$A$5:$A$10,0))&"|"&B22&"|"&C22,Data!$J$2:$J$577,0)),"") -> 0 | F22: =IFERROR(INDEX(Data!$G$2:$G$577,MATCH(A22&"|"&INDEX($B$5:$B$10,MATCH(A22,$A$5:$A$10,0))&"|"&B22&"|"&C22,Data!$J$2:$J$577,0)),"") -> 0 | G22: =IFERROR(INDEX(Data!$H$2:$H$577,MATCH(A22&"|"&INDEX($B$5:$B$10,MATCH(A22,$A$5:$A$10,0))&"|"&B22&"|"&C22,Data!$J$2:$J$577,0)),0) -> 0 | H22: =IFERROR(INDEX(Data!$I$2:$I$577,MATCH(A22&"|"&INDEX($B$5:$B$10,MATCH(A22,$A$5:$A$10,0))&"|"&B22&"|"&C22,Data!$J$2:$J$577,0)),"") -> DAY_BACKUP | I22: =INDEX($B$5:$B$10,MATCH(A22,$A$5:$A$10,0)) -> W1-P03 | J22: =IF(D22="Night","Rail receiving coverage","Day control / qualified backup") -> Day control / qualified backup | K22: ="weekly_staffing_options.xlsx / "&I22&" / Package Details" -> weekly_staffing_options.xlsx / W1-P03 / Package Details
A23: W1 | B23: 2026-10-08 | C23: Mirela Wainwright | D23: =IFERROR(INDEX(Data!$E$2:$E$577,MATCH(A23&"|"&INDEX($B$5:$B$10,MATCH(A23,$A$5:$A$10,0))&"|"&B23&"|"&C23,Data!$J$2:$J$577,0)),"") -> Night | E23: =IFERROR(INDEX(Data!$F$2:$F$577,MATCH(A23&"|"&INDEX($B$5:$B$10,MATCH(A23,$A$5:$A$10,0))&"|"&B23&"|"&C23,Data!$J$2:$J$577,0)),"") -> Agnes Pemberton | F23: =IFERROR(INDEX(Data!$G$2:$G$577,MATCH(A23&"|"&INDEX($B$5:$B$10,MATCH(A23,$A$5:$A$10,0))&"|"&B23&"|"&C23,Data!$J$2:$J$577,0)),"") -> 0 | G23: =IFERROR(INDEX(Data!$H$2:$H$577,MATCH(A23&"|"&INDEX($B$5:$B$10,MATCH(A23,$A$5:$A$10,0))&"|"&B23&"|"&C23,Data!$J$2:$J$577,0)),0) -> 0 | H23: =IFERROR(INDEX(Data!$I$2:$I$577,MATCH(A23&"|"&INDEX($B$5:$B$10,MATCH(A23,$A$5:$A$10,0))&"|"&B23&"|"&C23,Data!$J$2:$J$577,0)),"") -> TRAINER | I23: =INDEX($B$5:$B$10,MATCH(A23,$A$5:$A$10,0)) -> W1-P03 | J23: =IF(D23="Night","Rail receiving coverage","Day control / qualified backup") -> Rail receiving coverage | K23: ="weekly_staffing_options.xlsx / "&I23&" / Package Details" -> weekly_staffing_options.xlsx / W1-P03 / Package Details
A24: W1 | B24: 2026-10-08 | C24: Ibrahim Reinholt | D24: =IFERROR(INDEX(Data!$E$2:$E$577,MATCH(A24&"|"&INDEX($B$5:$B$10,MATCH(A24,$A$5:$A$10,0))&"|"&B24&"|"&C24,Data!$J$2:$J$577,0)),"") -> Day | E24: =IFERROR(INDEX(Data!$F$2:$F$577,MATCH(A24&"|"&INDEX($B$5:$B$10,MATCH(A24,$A$5:$A$10,0))&"|"&B24&"|"&C24,Data!$J$2:$J$577,0)),"") -> 0 | F24: =IFERROR(INDEX(Data!$G$2:$G$577,MATCH(A24&"|"&INDEX($B$5:$B$10,MATCH(A24,$A$5:$A$10,0))&"|"&B24&"|"&C24,Data!$J$2:$J$577,0)),"") -> 0 | G24: =IFERROR(INDEX(Data!$H$2:$H$577,MATCH(A24&"|"&INDEX($B$5:$B$10,MATCH(A24,$A$5:$A$10,0))&"|"&B24&"|"&C24,Data!$J$2:$J$577,0)),0) -> 0 | H24: =IFERROR(INDEX(Data!$I$2:$I$577,MATCH(A24&"|"&INDEX($B$5:$B$10,MATCH(A24,$A$5:$A$10,0))&"|"&B24&"|"&C24,Data!$J$2:$J$577,0)),"") -> STANDARD_COVER | I24: =INDEX($B$5:$B$10,MATCH(A24,$A$5:$A$10,0)) -> W1-P03 | J24: =IF(D24="Night","Rail receiving coverage","Day control / qualified backup") -> Day control / qualified backup | K24: ="weekly_staffing_options.xlsx / "&I24&" / Package Details" -> weekly_staffing_options.xlsx / W1-P03 / Package Details
... A84: W6 | B84: 2026-11-12 | C84: Ibrahim Reinholt | D84: =IFERROR(INDEX(Data!$E$2:$E$577,MATCH(A84&"|"&INDEX($B$5:$B$10,MATCH(A84,$A$5:$A$10,0))&"|"&B84&"|"&C84,Data!$J$2:$J$577,0)),"") -> Day | E84: =IFERROR(INDEX(Data!$F$2:$F$577,MATCH(A84&"|"&INDEX($B$5:$B$10,MATCH(A84,$A$5:$A$10,0))&"|"&B84&"|"&C84,Data!$J$2:$J$577,0)),"") -> 0 | F84: =IFERROR(INDEX(Data!$G$2:$G$577,MATCH(A84&"|"&INDEX($B$5:$B$10,MATCH(A84,$A$5:$A$10,0))&"|"&B84&"|"&C84,Data!$J$2:$J$577,0)),"") -> 0 | G84: =IFERROR(INDEX(Data!$H$2:$H$577,MATCH(A84&"|"&INDEX($B$5:$B$10,MATCH(A84,$A$5:$A$10,0))&"|"&B84&"|"&C84,Data!$J$2:$J$577,0)),0) -> 0 | H84: =IFERROR(INDEX(Data!$I$2:$I$577,MATCH(A84&"|"&INDEX($B$5:$B$10,MATCH(A84,$A$5:$A$10,0))&"|"&B84&"|"&C84,Data!$J$2:$J$577,0)),"") -> STANDARD_COVER | I84: =INDEX($B$5:$B$10,MATCH(A84,$A$5:$A$10,0)) -> W6-P02 | J84: =IF(D84="Night","Rail receiving coverage","Day control / qualified backup") -> Day control / qualified backup | K84: ="weekly_staffing_options.xlsx / "&I84&" / Package Details" -> weekly_staffing_options.xlsx / W6-P02 / Package Details

Sheet Coverage Check
A1: Coverage Check — Formula-driven status
A2: Jurisdiction | B2: Check | C2: Result | D2: Evidence / formula basis | E2: Shortfall | F2: Owner
A3: Quillhaven Authority | B3: Authorized slot calendar | C3: =IF(COUNTIF(Roster!$B$13:$B$84,"2026-10-27")+COUNTIF(Roster!$B$13:$B$84,"2026-10-28")+COUNTIF(Roster!$B$13:$B$84,"2026-10-29")=0,"PASS","FAIL") -> PASS | D3: Roster dates vs permit | E3: Blackout dates | F3: Gate supervisor
A4: Quillhaven Authority | B4: Two clerks in gate each date | C4: =IF(COUNTIF(Roster!$D$13:$D$84,"Night")=36,"PASS","FAIL") -> PASS | D4: Night rows = 18 × 2 | E4: Night headcount | F4: Gate supervisor
A5: Clearwater Board | B5: Two Night / two Day per rail date | C5: =IF(COUNTIF(Roster!$D$13:$D$84,"Night")=36,"PASS","FAIL") -> PASS | D5: Selected package detail expansion | E5: Shift balance | F5: Antoni Goodwin
A6: Clearwater Board | B6: Agnes witnessed hours by deadline | C6: =IF(SUM(Roster!$G$13:$G$84)>=32,"PASS","FAIL") -> PASS | D6: Starting 8 + eligible sign-off hours | E6: Need 40 total | F6: Training lead
A7: Clearwater Board | B7: Qualified backup retained on Day | C7: =IF(COUNTIF(Roster!$H$13:$H$84,"DAY_BACKUP")>=6,"PASS","FAIL") -> PASS | D7: DAY_BACKUP reason rows | E7: Day backup | F7: Antoni Goodwin
A8: Clearwater Board | B8: Protected adjacent controls | C8: =IF(COUNTIF(Roster!$H$13:$H$84,"DAY_CONTROL")>=2,"PASS","FAIL") -> PASS | D8: DAY_CONTROL placements | E8: Recovery separation | F8: Inventory control
A11: Selected package summary
A12: Week | B12: Selected package | C12: Risk rank | D12: Training shifts | E12: Status | F12: Priority note
A13: W1 | B13: =INDEX(Roster!$B$5:$B$10,MATCH(A13,Roster!$A$5:$A$10,0)) -> W1-P03 | C13: =IFERROR(VLOOKUP(B13,Data!$L$2:$O$49,2,FALSE()),"") -> 3 | D13: =IFERROR(VLOOKUP(B13,Data!$L$2:$O$49,3,FALSE()),"") -> 1 | E13: =IF(B13="","FAIL","Authorized for posting") -> Authorized for posting | F13: Priority hierarchy applied
A14: W2 | B14: =INDEX(Roster!$B$5:$B$10,MATCH(A14,Roster!$A$5:$A$10,0)) -> W2-P02 | C14: =IFERROR(VLOOKUP(B14,Data!$L$2:$O$49,2,FALSE()),"") -> 2 | D14: =IFERROR(VLOOKUP(B14,Data!$L$2:$O$49,3,FALSE()),"") -> 1 | E14: =IF(B14="","FAIL","Authorized for posting") -> Authorized for posting | F14: Priority hierarchy applied
A15: W3 | B15: =INDEX(Roster!$B$5:$B$10,MATCH(A15,Roster!$A$5:$A$10,0)) -> W3-P04 | C15: =IFERROR(VLOOKUP(B15,Data!$L$2:$O$49,2,FALSE()),"") -> 4 | D15: =IFERROR(VLOOKUP(B15,Data!$L$2:$O$49,3,FALSE()),"") -> 1 | E15: =IF(B15="","FAIL","Authorized for posting") -> Authorized for posting | F15: Priority hierarchy applied
A16: W4 | B16: =INDEX(Roster!$B$5:$B$10,MATCH(A16,Roster!$A$5:$A$10,0)) -> W4-P01 | C16: =IFERROR(VLOOKUP(B16,Data!$L$2:$O$49,2,FALSE()),"") -> 1 | D16: =IFERROR(VLOOKUP(B16,Data!$L$2:$O$49,3,FALSE()),"") -> 1 | E16: =IF(B16="","FAIL","Authorized for posting") -> Authorized for posting | F16: Priority hierarchy applied
A17: W5 | B17: =INDEX(Roster!$B$5:$B$10,MATCH(A17,Roster!$A$5:$A$10,0)) -> W5-P03 | C17: =IFERROR(VLOOKUP(B17,Data!$L$2:$O$49,2,FALSE()),"") -> 3 | D17: =IFERROR(VLOOKUP(B17,Data!$L$2:$O$49,3,FALSE()),"") -> 1 | E17: =IF(B17="","FAIL","Authorized for posting") -> Authorized for posting | F17: Priority hierarchy applied
A18: W6 | B18: =INDEX(Roster!$B$5:$B$10,MATCH(A18,Roster!$A$5:$A$10,0)) -> W6-P02 | C18: =IFERROR(VLOOKUP(B18,Data!$L$2:$O$49,2,FALSE()),"") -> 2 | D18: =IFERROR(VLOOKUP(B18,Data!$L$2:$O$49,3,FALSE()),"") -> 1 | E18: =IF(B18="","FAIL","Authorized for posting") -> Authorized for posting | F18: Priority hierarchy applied

Sheet Change Log
A1: Change Log — Package authorization
A3: Week | B3: Package ID | C3: Risk rank | D3: Status | E3: Staffing status changed | F3: Authorization context
A4: W1 | B4: W1-P01 | C4: 1 | D4: =IF(B4=INDEX(Roster!$B$5:$B$10,MATCH(A4,Roster!$A$5:$A$10,0)),"Authorized for posting","Not selected") -> Not selected | E4: =IF(D4="Authorized for posting","Selected night/day pattern approved","Candidate retained for review") -> Candidate retained for review | F4: Antoni Goodwin • six-week horizon
A5: W1 | B5: W1-P02 | C5: 2 | D5: =IF(B5=INDEX(Roster!$B$5:$B$10,MATCH(A5,Roster!$A$5:$A$10,0)),"Authorized for posting","Not selected") -> Not selected | E5: =IF(D5="Authorized for posting","Selected night/day pattern approved","Candidate retained for review") -> Candidate retained for review | F5: Antoni Goodwin • six-week horizon
A6: W1 | B6: W1-P03 | C6: 3 | D6: =IF(B6=INDEX(Roster!$B$5:$B$10,MATCH(A6,Roster!$A$5:$A$10,0)),"Authorized for posting","Not selected") -> Authorized for posting | E6: =IF(D6="Authorized for posting","Selected night/day pattern approved","Candidate retained for review") -> Selected night/day pattern approved | F6: Antoni Goodwin • six-week horizon
A7: W1 | B7: W1-P04 | C7: 4 | D7: =IF(B7=INDEX(Roster!$B$5:$B$10,MATCH(A7,Roster!$A$5:$A$10,0)),"Authorized for posting","Not selected") -> Not selected | E7: =IF(D7="Authorized for posting","Selected night/day pattern approved","Candidate retained for review") -> Candidate retained for review | F7: Antoni Goodwin • six-week horizon
A8: W1 | B8: W1-P05 | C8: 5 | D8: =IF(B8=INDEX(Roster!$B$5:$B$10,MATCH(A8,Roster!$A$5:$A$10,0)),"Authorized for posting","Not selected") -> Not selected | E8: =IF(D8="Authorized for posting","Selected night/day pattern approved","Candidate retained for review") -> Candidate retained for review | F8: Antoni Goodwin • six-week horizon
A9: W1 | B9: W1-P06 | C9: 6 | D9: =IF(B9=INDEX(Roster!$B$5:$B$10,MATCH(A9,Roster!$A$5:$A$10,0)),"Authorized for posting","Not selected") -> Not selected | E9: =IF(D9="Authorized for posting","Selected night/day pattern approved","Candidate retained for review") -> Candidate retained for review | F9: Antoni Goodwin • six-week horizon
A10: W1 | B10: W1-P07 | C10: 7 | D10: =IF(B10=INDEX(Roster!$B$5:$B$10,MATCH(A10,Roster!$A$5:$A$10,0)),"Authorized for posting","Not selected") -> Not selected | E10: =IF(D10="Authorized for posting","Selected night/day pattern approved","Candidate retained for review") -> Candidate retained for review | F10: Antoni Goodwin • six-week horizon
A11: W1 | B11: W1-P08 | C11: 8 | D11: =IF(B11=INDEX(Roster!$B$5:$B$10,MATCH(A11,Roster!$A$5:$A$10,0)),"Authorized for posting","Not selected") -> Not selected | E11: =IF(D11="Authorized for posting","Selected night/day pattern approved","Candidate retained for review") -> Candidate retained for review | F11: Antoni Goodwin • six-week horizon
A12: W2 | B12: W2-P01 | C12: 1 | D12: =IF(B12=INDEX(Roster!$B$5:$B$10,MATCH(A12,Roster!$A$5:$A$10,0)),"Authorized for posting","Not selected") -> Not selected | E12: =IF(D12="Authorized for posting","Selected night/day pattern approved","Candidate retained for review") -> Candidate retained for review | F12: Antoni Goodwin • six-week horizon
A13: W2 | B13: W2-P02 | C13: 2 | D13: =IF(B13=INDEX(Roster!$B$5:$B$10,MATCH(A13,Roster!$A$5:$A$10,0)),"Authorized for posting","Not selected") -> Authorized for posting | E13: =IF(D13="Authorized for posting","Selected night/day pattern approved","Candidate retained for review") -> Selected night/day pattern approved | F13: Antoni Goodwin • six-week horizon
A14: W2 | B14: W2-P03 | C14: 3 | D14: =IF(B14=INDEX(Roster!$B$5:$B$10,MATCH(A14,Roster!$A$5:$A$10,0)),"Authorized for posting","Not selected") -> Not selected | E14: =IF(D14="Authorized for posting","Selected night/day pattern approved","Candidate retained for review") -> Candidate retained for review | F14: Antoni Goodwin • six-week horizon
A15: W2 | B15: W2-P04 | C15: 4 | D15: =IF(B15=INDEX(Roster!$B$5:$B$10,MATCH(A15,Roster!$A$5:$A$10,0)),"Authorized for posting","Not selected") -> Not selected | E15: =IF(D15="Authorized for posting","Selected night/day pattern approved","Candidate retained for review") -> Candidate retained for review | F15: Antoni Goodwin • six-week horizon
... A51: W6 | B51: W6-P08 | C51: 8 | D51: =IF(B51=INDEX(Roster!$B$5:$B$10,MATCH(A51,Roster!$A$5:$A$10,0)),"Authorized for posting","Not selected") -> Not selected | E51: =IF(D51="Authorized for posting","Selected night/day pattern approved","Candidate retained for review") -> Candidate retained for review | F51: Antoni Goodwin • six-week horizon

Sheet Data
A1: Package ID | B1: Week | C1: Rail date | D1: Clerk | E1: Shift | F1: Trainer | G1: Trainee | H1: Counted hours | I1: Reason code | J1: Key | L1: Package ID | M1: Risk | N1: Training shifts | O1: Issue
A2: W1-P01 | B2: W1 | C2: 2026-10-06 | D2: Agnes Pemberton | E2: Day | H2: 0 | I2: STANDARD_COVER | J2: W1|W1-P01|2026-10-06|Agnes Pemberton | L2: W1-P01 | M2: 1 | N2: 0 | P2: W1-P01 | Q2: W2-P01 | R2: W3-P01 | S2: W4-P01 | T2: W5-P01 | U2: W6-P01
A3: W1-P01 | B3: W1 | C3: 2026-10-06 | D3: Pascal Ellingsen | E3: Night | H3: 0 | I3: NIGHT_WMS | J3: W1|W1-P01|2026-10-06|Pascal Ellingsen | L3: W1-P02 | M3: 2 | N3: 0 | P3: W1-P02 | Q3: W2-P02 | R3: W3-P02 | S3: W4-P02 | T3: W5-P02 | U3: W6-P02
A4: W1-P01 | B4: W1 | C4: 2026-10-06 | D4: Mirela Wainwright | E4: Night | H4: 0 | I4: NIGHT_WMS | J4: W1|W1-P01|2026-10-06|Mirela Wainwright | L4: W1-P03 | M4: 3 | N4: 1 | P4: W1-P03 | Q4: W2-P03 | R4: W3-P03 | S4: W4-P03 | T4: W5-P03 | U4: W6-P03
A5: W1-P01 | B5: W1 | C5: 2026-10-06 | D5: Ibrahim Reinholt | E5: Day | H5: 0 | I5: STANDARD_COVER | J5: W1|W1-P01|2026-10-06|Ibrahim Reinholt | L5: W1-P04 | M5: 4 | N5: 0 | P5: W1-P04 | Q5: W2-P04 | R5: W3-P04 | S5: W4-P04 | T5: W5-P04 | U5: W6-P04
A6: W1-P01 | B6: W1 | C6: 2026-10-07 | D6: Agnes Pemberton | E6: Day | H6: 0 | I6: STANDARD_COVER | J6: W1|W1-P01|2026-10-07|Agnes Pemberton | L6: W1-P05 | M6: 5 | N6: 0 | O6: unavailable clerk | P6: W1-P05 | Q6: W2-P05 | R6: W3-P05 | S6: W4-P05 | T6: W5-P05 | U6: W6-P05
A7: W1-P01 | B7: W1 | C7: 2026-10-07 | D7: Pascal Ellingsen | E7: Night | H7: 0 | I7: NIGHT_WMS | J7: W1|W1-P01|2026-10-07|Pascal Ellingsen | L7: W1-P06 | M7: 6 | N7: 0 | O7: no day-qualified backup | P7: W1-P06 | Q7: W2-P06 | R7: W3-P06 | S7: W4-P06 | T7: W5-P06 | U7: W6-P06
A8: W1-P01 | B8: W1 | C8: 2026-10-07 | D8: Mirela Wainwright | E8: Night | H8: 0 | I8: NIGHT_WMS | J8: W1|W1-P01|2026-10-07|Mirela Wainwright | L8: W1-P07 | M8: 7 | N8: 0 | O8: ineligible Agnes trainer | P8: W1-P07 | Q8: W2-P07 | R8: W3-P07 | S8: W4-P07 | T8: W5-P07 | U8: W6-P07
A9: W1-P01 | B9: W1 | C9: 2026-10-07 | D9: Ibrahim Reinholt | E9: Day | H9: 0 | I9: STANDARD_COVER | J9: W1|W1-P01|2026-10-07|Ibrahim Reinholt | L9: W1-P08 | M9: 8 | N9: 0 | O9: gate-access failure | P9: W1-P08 | Q9: W2-P08 | R9: W3-P08 | S9: W4-P08 | T9: W5-P08 | U9: W6-P08
A10: W1-P01 | B10: W1 | C10: 2026-10-08 | D10: Agnes Pemberton | E10: Day | H10: 0 | I10: STANDARD_COVER | J10: W1|W1-P01|2026-10-08|Agnes Pemberton | L10: W2-P01 | M10: 1 | N10: 0
A11: W1-P01 | B11: W1 | C11: 2026-10-08 | D11: Pascal Ellingsen | E11: Night | H11: 0 | I11: NIGHT_WMS | J11: W1|W1-P01|2026-10-08|Pascal Ellingsen | L11: W2-P02 | M11: 2 | N11: 1
A12: W1-P01 | B12: W1 | C12: 2026-10-08 | D12: Mirela Wainwright | E12: Night | H12: 0 | I12: NIGHT_WMS | J12: W1|W1-P01|2026-10-08|Mirela Wainwright | L12: W2-P03 | M12: 3 | N12: 0
A13: W1-P01 | B13: W1 | C13: 2026-10-08 | D13: Ibrahim Reinholt | E13: Day | H13: 0 | I13: STANDARD_COVER | J13: W1|W1-P01|2026-10-08|Ibrahim Reinholt | L13: W2-P04 | M13: 4 | N13: 0
A14: W1-P02 | B14: W1 | C14: 2026-10-06 | D14: Agnes Pemberton | E14: Night | H14: 0 | I14: STANDARD_COVER | J14: W1|W1-P02|2026-10-06|Agnes Pemberton | L14: W2-P05 | M14: 5 | N14: 0 | O14: unavailable clerk
A15: W1-P02 | B15: W1 | C15: 2026-10-06 | D15: Pascal Ellingsen | E15: Night | H15: 0 | I15: NIGHT_WMS | J15: W1|W1-P02|2026-10-06|Pascal Ellingsen | L15: W2-P06 | M15: 6 | N15: 0 | O15: no day-qualified backup
A16: W1-P02 | B16: W1 | C16: 2026-10-06 | D16: Mirela Wainwright | E16: Day | H16: 0 | I16: DAY_BACKUP | J16: W1|W1-P02|2026-10-06|Mirela Wainwright | L16: W2-P07 | M16: 7 | N16: 0 | O16: ineligible Agnes trainer
A17: W1-P02 | B17: W1 | C17: 2026-10-06 | D17: Ibrahim Reinholt | E17: Day | H17: 0 | I17: STANDARD_COVER | J17: W1|W1-P02|2026-10-06|Ibrahim Reinholt | L17: W2-P08 | M17: 8 | N17: 0 | O17: gate-access failure
A18: W1-P02 | B18: W1 | C18: 2026-10-07 | D18: Agnes Pemberton | E18: Night | H18: 0 | I18: STANDARD_COVER | J18: W1|W1-P02|2026-10-07|Agnes Pemberton | L18: W3-P01 | M18: 1 | N18: 0
A19: W1-P02 | B19: W1 | C19: 2026-10-07 | D19: Pascal Ellingsen | E19: Night | H19: 0 | I19: NIGHT_WMS | J19: W1|W1-P02|2026-10-07|Pascal Ellingsen | L19: W3-P02 | M19: 2 | N19: 0
A20: W1-P02 | B20: W1 | C20: 2026-10-07 | D20: Mirela Wainwright | E20: Day | H20: 0 | I20: DAY_BACKUP | J20: W1|W1-P02|2026-10-07|Mirela Wainwright | L20: W3-P03 | M20: 3 | N20: 0
A21: W1-P02 | B21: W1 | C21: 2026-10-07 | D21: Ibrahim Reinholt | E21: Day | H21: 0 | I21: STANDARD_COVER | J21: W1|W1-P02|2026-10-07|Ibrahim Reinholt | L21: W3-P04 | M21: 4 | N21: 1
A22: W1-P02 | B22: W1 | C22: 2026-10-08 | D22: Agnes Pemberton | E22: Night | H22: 0 | I22: STANDARD_COVER | J22: W1|W1-P02|2026-10-08|Agnes Pemberton | L22: W3-P05 | M22: 5 | N22: 0 | O22: unavailable clerk
A23: W1-P02 | B23: W1 | C23: 2026-10-08 | D23: Pascal Ellingsen | E23: Night | H23: 0 | I23: NIGHT_WMS | J23: W1|W1-P02|2026-10-08|Pascal Ellingsen | L23: W3-P06 | M23: 6 | N23: 0 | O23: no day-qualified backup
A24: W1-P02 | B24: W1 | C24: 2026-10-08 | D24: Mirela Wainwright | E24: Day | H24: 0 | I24: DAY_BACKUP | J24: W1|W1-P02|2026-10-08|Mirela Wainwright | L24: W3-P07 | M24: 7 | N24: 0 | O24: ineligible Agnes trainer
A25: W1-P02 | B25: W1 | C25: 2026-10-08 | D25: Ibrahim Reinholt | E25: Day | H25: 0 | I25: STANDARD_COVER | J25: W1|W1-P02|2026-10-08|Ibrahim Reinholt | L25: W3-P08 | M25: 8 | N25: 0 | O25: gate-access failure
A26: W1-P03 | B26: W1 | C26: 2026-10-06 | D26: Agnes Pemberton | E26: Night | F26: Mirela Wainwright | G26: Agnes Pemberton | H26: 8 | I26: SIGNOFF | J26: W1|W1-P03|2026-10-06|Agnes Pemberton | L26: W4-P01 | M26: 1 | N26: 1
A27: W1-P03 | B27: W1 | C27: 2026-10-06 | D27: Mirela Wainwright | E27: Night | F27: Agnes Pemberton | H27: 0 | I27: TRAINER | J27: W1|W1-P03|2026-10-06|Mirela Wainwright | L27: W4-P02 | M27: 2 | N27: 0
A28: W1-P03 | B28: W1 | C28: 2026-10-06 | D28: Pascal Ellingsen | E28: Day | H28: 0 | I28: DAY_BACKUP | J28: W1|W1-P03|2026-10-06|Pascal Ellingsen | L28: W4-P03 | M28: 3 | N28: 0
A29: W1-P03 | B29: W1 | C29: 2026-10-06 | D29: Ibrahim Reinholt | E29: Day | H29: 0 | I29: STANDARD_COVER | J29: W1|W1-P03|2026-10-06|Ibrahim Reinholt | L29: W4-P04 | M29: 4 | N29: 0
A30: W1-P03 | B30: W1 | C30: 2026-10-07 | D30: Agnes Pemberton | E30: Night | F30: Mirela Wainwright | G30: Agnes Pemberton | H30: 8 | I30: SIGNOFF | J30: W1|W1-P03|2026-10-07|Agnes Pemberton | L30: W4-P05 | M30: 5 | N30: 0 | O30: unavailable clerk
A31: W1-P03 | B31: W1 | C31: 2026-10-07 | D31: Mirela Wainwright | E31: Night | F31: Agnes Pemberton | H31: 0 | I31: TRAINER | J31: W1|W1-P03|2026-10-07|Mirela Wainwright | L31: W4-P06 | M31: 6 | N31: 0 | O31: no day-qualified backup
A32: W1-P03 | B32: W1 | C32: 2026-10-07 | D32: Pascal Ellingsen | E32: Day | H32: 0 | I32: DAY_BACKUP | J32: W1|W1-P03|2026-10-07|Pascal Ellingsen | L32: W4-P07 | M32: 7 | N32: 0 | O32: ineligible Agnes trainer
A33: W1-P03 | B33: W1 | C33: 2026-10-07 | D33: Ibrahim Reinholt | E33: Day | H33: 0 | I33: STANDARD_COVER | J33: W1|W1-P03|2026-10-07|Ibrahim Reinholt | L33: W4-P08 | M33: 8 | N33: 0 | O33: gate-access failure
A34: W1-P03 | B34: W1 | C34: 2026-10-08 | D34: Agnes Pemberton | E34: Night | F34: Mirela Wainwright | G34: Agnes Pemberton | H34: 8 | I34: SIGNOFF | J34: W1|W1-P03|2026-10-08|Agnes Pemberton | L34: W5-P01 | M34: 1 | N34: 0
A35: W1-P03 | B35: W1 | C35: 2026-10-08 | D35: Mirela Wainwright | E35: Night | F35: Agnes Pemberton | H35: 0 | I35: TRAINER | J35: W1|W1-P03|2026-10-08|Mirela Wainwright | L35: W5-P02 | M35: 2 | N35: 0
A36: W1-P03 | B36: W1 | C36: 2026-10-08 | D36: Pascal Ellingsen | E36: Day | H36: 0 | I36: DAY_BACKUP | J36: W1|W1-P03|2026-10-08|Pascal Ellingsen | L36: W5-P03 | M36: 3 | N36: 1
A37: W1-P03 | B37: W1 | C37: 2026-10-08 | D37: Ibrahim Reinholt | E37: Day | H37: 0 | I37: STANDARD_COVER | J37: W1|W1-P03|2026-10-08|Ibrahim Reinholt | L37: W5-P04 | M37: 4 | N37: 0
A38: W1-P04 | B38: W1 | C38: 2026-10-06 | D38: Agnes Pemberton | E38: Day | H38: 0 | I38: STANDARD_COVER | J38: W1|W1-P04|2026-10-06|Agnes Pemberton | L38: W5-P05 | M38: 5 | N38: 0 | O38: unavailable clerk
A39: W1-P04 | B39: W1 | C39: 2026-10-06 | D39: Pascal Ellingsen | E39: Night | H39: 0 | I39: NIGHT_WMS | J39: W1|W1-P04|2026-10-06|Pascal Ellingsen | L39: W5-P06 | M39: 6 | N39: 0 | O39: no day-qualified backup
A40: W1-P04 | B40: W1 | C40: 2026-10-06 | D40: Mirela Wainwright | E40: Day | H40: 0 | I40: DAY_BACKUP | J40: W1|W1-P04|2026-10-06|Mirela Wainwright | L40: W5-P07 | M40: 7 | N40: 0 | O40: ineligible Agnes trainer
...
