Workbook
Name AsOfWeek: 'Parameters'!$D$5
Name FullCycleMin: 'Parameters'!$D$6
Name RecentWeeks: 'Parameters'!$D$7
Name PriorWeeks: 'Parameters'!$D$8
Name MinHistory: 'Parameters'!$D$9
Name MinInStockDays: 'Parameters'!$D$10
Name OwnDecline: 'Parameters'!$D$11
Name PeerGapThreshold: 'Parameters'!$D$12
Name LowBaseThreshold: 'Parameters'!$D$13
Name ReorderUplift: 'Parameters'!$D$14
Name WeeksSupplyCap: 'Parameters'!$D$15
Name MaterialThreshold: 'Parameters'!$D$16
Name BroadShare: 'Parameters'!$D$17
Name Weekly_Input_Week_Ending: 'Weekly Input'!$A$5:$A$504
Name Weekly_Input_Master_Check: 'Weekly Input'!$J$5:$J$504

Sheet Read Me
A1: Bellhaven sell-through exception model
A2: Flintridge Consortium | governed blank instrument | Model version 1.0 | Governance source: Bellhaven_launch_governance.xlsx (Version 2026.08, effective 2026-08-25)
A4: Monday operating instructions
A5: 1 | B5: Paste one Sunday-ending EDI 852 row per Store ID + SKU + Week Ending into the blue input columns on Weekly Input. Do not overwrite formula columns, master data, or parameter cells.
A6: 2 | B6: Use the drop-downs and validation prompts. Correct duplicate-key highlights before relying on review outputs. Blank rows are intentional in this reusable instrument.
A7: 3 | B7: Review Parameters for the active, prospectively selected controls and the derived Reporting As-of Week. Never type an as-of date: it is the maximum valid Week Ending in Weekly Input.
A8: 4 | B8: After paste/recalculation, open Exceptions for current latest-week combinations and Review Summary for SKU rollups. Print those two tabs for Elena Bassett’s Monday review.
A9: 5 | B9: Interpret outcomes exactly: Markdown Review = own deterioration plus peer underperformance; Reorder Candidate = uplift with inventory cover within cap; Monitor = eligible but neither action; Noise = weak/absent base; Not Ready = incomplete shelf cycle, history, availability, or master data.
A10: 6 | B10: Human review notes, disposition comments, and sign-off fields are intentionally empty. Enter those only during the meeting; never replace formula outputs.
A13: Governance vocabulary
A14: Statuses | B14: Markdown Review | Reorder Candidate | Monitor | Noise | Not Ready
A15: Actions | B15: Markdown support | Second reorder | Monitor | Hold / collect data | Not ready
A16: Reason precedence | B16: INVALID_MASTER → INCOMPLETE_SHELF_CYCLE → INSUFFICIENT_HISTORY → INSUFFICIENT_IN_STOCK → LOW_BASE_NOISE → NO_PRIOR_BASE → substantive reason

Sheet Parameters
A1: Parameters
A2: Active controls are bounded by Bellhaven_launch_governance.xlsx; blank-state Reporting As-of Week remains blank
A4: Control | B4: Definition | C4: Allowed Range | D4: Selected Value | E4: Unit / Direction | F4: Prospective rationale
A5: Reporting As-of Week | B5: Formula: maximum valid Week Ending in Weekly Input | C5: derived | D5: =IF(COUNTIFS(Weekly_Input_Week_Ending,"<>",Weekly_Input_Master_Check,"OK")=0,"",MAXIFS(Weekly_Input_Week_Ending,Weekly_Input_Master_Check,"OK")) | E5: Sunday | F5: Derived from pasted records; never re-key.
A6: Full shelf-cycle minimum | B6: Elapsed days required for readiness | C6: 21–56 | D6: =28 | E6: days; at least | F6: 28 days gives a complete four-week shelf cycle while avoiding immature launch weeks.
A7: Recent window | B7: Adjacent recent comparison period | C7: 4–6 | D7: =4 | E7: weeks | F7: Four complete weeks balances recency with a stable base.
A8: Prior window | B8: Immediately preceding comparison period | C8: 4–6 | D8: =4 | E8: weeks | F8: Equal prior window supports like-for-like deterioration tests.
A9: Minimum eligible history | B9: Eligible observations across both windows | C9: 6–12 | D9: =8 | E9: weeks; at least | F9: Requires both periods to be represented without fitting unavailable early EDI.
A10: Minimum in-stock days | B10: Availability floor for normalization | C10: 4–7 | D10: =5 | E10: days; at least | F10: Five days limits partial-shelf noise while preserving usable weeks.
A11: Own-decline threshold | B11: Own Change markdown boundary | C11: 10%–40% | D11: =0.20 | E11: decimal decline; at or below | F11: A 20% decline is material prospectively and avoids reacting to routine weekly noise.
A12: Peer-gap threshold | B12: Peer Gap markdown boundary | C12: 10%–40% | D12: =0.15 | E12: decimal under peer; at or below | F12: Fifteen percent below contemporaneous peers identifies relative underperformance.
A13: Low-base threshold | B13: Weak prior velocity gate | C13: 0.25–1.50 | D13: =0.75 | E13: units / normalized week; below | F13: A 0.75-unit base is a conservative noise floor before actioning change.
A14: Reorder uplift threshold | B14: Reorder performance boundary | C14: 10%–50% | D14: =0.15 | E14: decimal uplift; at or above | F14: Fifteen percent uplift is actionable but not tuned to missing early records.
A15: Weeks-of-supply cap | B15: Inventory cover ceiling for reorder | C15: 2–12 | D15: =8 | E15: weeks; at or below | F15: Allows a second reorder only when projected cover remains under eight weeks.
A16: Material-change threshold | B16: SKU variance materiality | C16: 10%–40% | D16: =0.20 | E16: decimal; at or above | F16: Twenty percent separates meeting-worthy SKU movement from ordinary variation.
A17: Broad movement share | B17: Broad driver share | C17: 50%–90% | D17: =0.60 | E17: share; at or above | F17: Sixty percent same-direction movement indicates a broad SKU signal.

Sheet Change Log
A1: Change Log
A2: Prospective control decision authorized for the 12-week review
A4: Control name | B4: Prior pilot value | C4: New selected value | D4: Authorized owner | E4: Effective week | F4: Reason
A5: Own-decline threshold | B5: 0.15 | C5: 0.2 | D5: Olamide Donnelly | E5: 46272 | F5: Authorized prospective move to a 20% boundary to resist low-volume noise without fitting unavailable early EDI.
A6: Peer-gap threshold | B6: 0.1 | C6: 0.15 | D6: Olamide Donnelly | E6: 46272 | F6: Authorized prospective move to a 15% relative gap so markdown support reflects meaningful peer underperformance.
A7: Full shelf-cycle minimum | B7: 28 | C7: 28 | D7: Olamide Donnelly | E7: 46272 | F7: Retained pilot setting pending full 12-week review.
A8: Recent window | B8: 4 | C8: 4 | D8: Olamide Donnelly | E8: 46272 | F8: Retained adjacent comparison window.
A9: Prior window | B9: 4 | C9: 4 | D9: Olamide Donnelly | E9: 46272 | F9: Retained equal prior window.
A10: Minimum eligible history | B10: 8 | C10: 8 | D10: Olamide Donnelly | E10: 46272 | F10: Retained history sufficiency gate.
A11: Minimum in-stock days | B11: 5 | C11: 5 | D11: Olamide Donnelly | E11: 46272 | F11: Retained availability floor.
A12: Low-base threshold | B12: 0.75 | C12: 0.75 | D12: Olamide Donnelly | E12: 46272 | F12: Retained low-volume noise floor.
A13: Reorder uplift threshold | B13: 0.15 | C13: 0.15 | D13: Olamide Donnelly | E13: 46272 | F13: Retained uplift boundary.
A14: Weeks-of-supply cap | B14: 8 | C14: 8 | D14: Olamide Donnelly | E14: 46272 | F14: Retained inventory-cover cap.
A15: Material-change threshold | B15: 0.15 | C15: 0.2 | D15: Olamide Donnelly | E15: 46272 | F15: Prospective increase to keep meeting focus on material movement.
A16: Broad movement share | B16: 0.6 | C16: 0.6 | D16: Olamide Donnelly | E16: 46272 | F16: Retained broad-driver share.

Sheet Master Data
A1: Master Data
A2: Approved store and SKU masters copied from Bellhaven_launch_governance.xlsx
A4: Store master | F4: SKU master
A5: Store ID | B5: Store Name | C5: Region | D5: Shelf-Set Date | F5: SKU | G5: Description | H5: Category | I5: Pack Size
A6: BH-001 | B6: Bellhaven 001 | C6: Midwest | D6: 46031 | F6: FL-AQ-101 | G6: ClearCurrent Filter Media | H6: Aquatics | I6: 12 oz
A7: BH-002 | B7: Bellhaven 002 | C7: South | D7: 46035 | F7: FL-AQ-102 | G7: Tideglass Water Conditioner | H7: Aquatics | I7: 16 fl oz
A8: BH-003 | B8: Bellhaven 003 | C8: West | D8: 46039 | F8: FL-PT-201 | G8: Pawline Dental Chews | H8: Pet Care | I8: 30 ct
A9: BH-004 | B9: Bellhaven 004 | C9: Northeast | D9: 46043 | F9: FL-PT-202 | G9: HarborHound Joint Bites | H9: Pet Care | I9: 60 ct
A10: BH-005 | B10: Bellhaven 005 | C10: Midwest | D10: 46047 | F10: FL-PT-203 | G10: Moss & Mutt Coat Treats | H10: Pet Care | I10: 90 ct
A11: BH-006 | B11: Bellhaven 006 | C11: South | D11: 46051 | F11: FL-PT-204 | G11: WhiskerWell Calming Drops | H11: Pet Care | I11: 1 fl oz
A12: BH-007 | B12: Bellhaven 007 | C12: West | D12: 46055 | F12: FL-GR-301 | G12: Greenfin Staple Pellets | H12: Aquatics | I12: 2 lb
A13: BH-008 | B13: Bellhaven 008 | C13: Northeast | D13: 46059 | F13: FL-GR-302 | G13: ReefReady Shrimp Pellets | H13: Aquatics | I13: 1 lb
A14: BH-009 | B14: Bellhaven 009 | C14: Midwest | D14: 46063
A15: BH-010 | B15: Bellhaven 010 | C15: South | D15: 46067
A16: BH-011 | B16: Bellhaven 011 | C16: West | D16: 46071
A17: BH-012 | B17: Bellhaven 012 | C17: Northeast | D17: 46075
A18: BH-013 | B18: Bellhaven 013 | C18: Midwest | D18: 46079
A19: BH-014 | B19: Bellhaven 014 | C19: South | D19: 46083
A20: BH-015 | B20: Bellhaven 015 | C20: West | D20: 46087
A21: BH-016 | B21: Bellhaven 016 | C21: Northeast | D21: 46091
A22: BH-017 | B22: Bellhaven 017 | C22: Midwest | D22: 46095
A23: BH-018 | B23: Bellhaven 018 | C23: South | D23: 46099
A24: BH-019 | B24: Bellhaven 019 | C24: West | D24: 46103
A25: BH-020 | B25: Bellhaven 020 | C25: Northeast | D25: 46107
... A145: BH-140 | B145: Bellhaven 140 | C145: Northeast | D145: 46043

Sheet Weekly Input
A1: Weekly Input
A2: Paste-only EDI 852 observations in blue columns; calculated checks at right
A4: Week Ending | B4: Store ID | C4: SKU | D4: Units Sold | E4: Net Sales | F4: Receipts | G4: On Hand Qty | H4: In-Stock Days | I4: Duplicate Key Check | J4: Master Check
I5: =IF(COUNTA(A5:C5)=0,"",IF(COUNTIFS($A$5:$A$504,A5,$B$5:$B$504,B5,$C$5:$C$504,C5)>1,"DUPLICATE","OK")) | J5: =IF(COUNTA(A5:C5)=0,"",IF(AND(COUNTIF('Master Data'!$A$6:$A$145,B5)=1,COUNTIF('Master Data'!$F$6:$F$13,C5)=1),"OK","INVALID"))
I6: =IF(COUNTA(A6:C6)=0,"",IF(COUNTIFS($A$5:$A$504,A6,$B$5:$B$504,B6,$C$5:$C$504,C6)>1,"DUPLICATE","OK")) | J6: =IF(COUNTA(A6:C6)=0,"",IF(AND(COUNTIF('Master Data'!$A$6:$A$145,B6)=1,COUNTIF('Master Data'!$F$6:$F$13,C6)=1),"OK","INVALID"))
I7: =IF(COUNTA(A7:C7)=0,"",IF(COUNTIFS($A$5:$A$504,A7,$B$5:$B$504,B7,$C$5:$C$504,C7)>1,"DUPLICATE","OK")) | J7: =IF(COUNTA(A7:C7)=0,"",IF(AND(COUNTIF('Master Data'!$A$6:$A$145,B7)=1,COUNTIF('Master Data'!$F$6:$F$13,C7)=1),"OK","INVALID"))
I8: =IF(COUNTA(A8:C8)=0,"",IF(COUNTIFS($A$5:$A$504,A8,$B$5:$B$504,B8,$C$5:$C$504,C8)>1,"DUPLICATE","OK")) | J8: =IF(COUNTA(A8:C8)=0,"",IF(AND(COUNTIF('Master Data'!$A$6:$A$145,B8)=1,COUNTIF('Master Data'!$F$6:$F$13,C8)=1),"OK","INVALID"))
I9: =IF(COUNTA(A9:C9)=0,"",IF(COUNTIFS($A$5:$A$504,A9,$B$5:$B$504,B9,$C$5:$C$504,C9)>1,"DUPLICATE","OK")) | J9: =IF(COUNTA(A9:C9)=0,"",IF(AND(COUNTIF('Master Data'!$A$6:$A$145,B9)=1,COUNTIF('Master Data'!$F$6:$F$13,C9)=1),"OK","INVALID"))
I10: =IF(COUNTA(A10:C10)=0,"",IF(COUNTIFS($A$5:$A$504,A10,$B$5:$B$504,B10,$C$5:$C$504,C10)>1,"DUPLICATE","OK")) | J10: =IF(COUNTA(A10:C10)=0,"",IF(AND(COUNTIF('Master Data'!$A$6:$A$145,B10)=1,COUNTIF('Master Data'!$F$6:$F$13,C10)=1),"OK","INVALID"))
I11: =IF(COUNTA(A11:C11)=0,"",IF(COUNTIFS($A$5:$A$504,A11,$B$5:$B$504,B11,$C$5:$C$504,C11)>1,"DUPLICATE","OK")) | J11: =IF(COUNTA(A11:C11)=0,"",IF(AND(COUNTIF('Master Data'!$A$6:$A$145,B11)=1,COUNTIF('Master Data'!$F$6:$F$13,C11)=1),"OK","INVALID"))
I12: =IF(COUNTA(A12:C12)=0,"",IF(COUNTIFS($A$5:$A$504,A12,$B$5:$B$504,B12,$C$5:$C$504,C12)>1,"DUPLICATE","OK")) | J12: =IF(COUNTA(A12:C12)=0,"",IF(AND(COUNTIF('Master Data'!$A$6:$A$145,B12)=1,COUNTIF('Master Data'!$F$6:$F$13,C12)=1),"OK","INVALID"))
I13: =IF(COUNTA(A13:C13)=0,"",IF(COUNTIFS($A$5:$A$504,A13,$B$5:$B$504,B13,$C$5:$C$504,C13)>1,"DUPLICATE","OK")) | J13: =IF(COUNTA(A13:C13)=0,"",IF(AND(COUNTIF('Master Data'!$A$6:$A$145,B13)=1,COUNTIF('Master Data'!$F$6:$F$13,C13)=1),"OK","INVALID"))
I14: =IF(COUNTA(A14:C14)=0,"",IF(COUNTIFS($A$5:$A$504,A14,$B$5:$B$504,B14,$C$5:$C$504,C14)>1,"DUPLICATE","OK")) | J14: =IF(COUNTA(A14:C14)=0,"",IF(AND(COUNTIF('Master Data'!$A$6:$A$145,B14)=1,COUNTIF('Master Data'!$F$6:$F$13,C14)=1),"OK","INVALID"))
I15: =IF(COUNTA(A15:C15)=0,"",IF(COUNTIFS($A$5:$A$504,A15,$B$5:$B$504,B15,$C$5:$C$504,C15)>1,"DUPLICATE","OK")) | J15: =IF(COUNTA(A15:C15)=0,"",IF(AND(COUNTIF('Master Data'!$A$6:$A$145,B15)=1,COUNTIF('Master Data'!$F$6:$F$13,C15)=1),"OK","INVALID"))
I16: =IF(COUNTA(A16:C16)=0,"",IF(COUNTIFS($A$5:$A$504,A16,$B$5:$B$504,B16,$C$5:$C$504,C16)>1,"DUPLICATE","OK")) | J16: =IF(COUNTA(A16:C16)=0,"",IF(AND(COUNTIF('Master Data'!$A$6:$A$145,B16)=1,COUNTIF('Master Data'!$F$6:$F$13,C16)=1),"OK","INVALID"))
... I504: =IF(COUNTA(A504:C504)=0,"",IF(COUNTIFS($A$5:$A$504,A504,$B$5:$B$504,B504,$C$5:$C$504,C504)>1,"DUPLICATE","OK")) | J504: =IF(COUNTA(A504:C504)=0,"",IF(AND(COUNTIF('Master Data'!$A$6:$A$145,B504)=1,COUNTIF('Master Data'!$F$6:$F$13,C504)=1),"OK","INVALID"))

Sheet Model
A1: Model
A2: Formula-driven detailed analysis; one row per Weekly Input row, with blanks suppressed until inputs exist
A4: Row Key | B4: Store ID | C4: SKU | D4: Store Name | E4: Category | F4: Week Ending | G4: Shelf-Set Date | H4: Shelf-Cycle Age (days) | I4: Valid Master | J4: In-Stock Sufficient | K4: Full Cycle | L4: Eligible | M4: Normalized Velocity | N4: History Count | O4: Latest Week | P4: Recent Velocity | Q4: Prior Velocity | R4: Own Change | S4: SKU Peer Velocity | T4: Peer Gap | U4: Inventory Cover (weeks) | V4: Outcome | W4: Reason Code | X4: Action | Y4: Severity | Z4: Material Change | AA4: Driver | AB4: Current Row | AC4: Action Priority | AD4: Exception Rank
A5: =IF(COUNTA('Weekly Input'!A5:C5)=0,"",'Weekly Input'!B5&"|"&'Weekly Input'!C5&"|"&TEXT('Weekly Input'!A5,"yyyy-mm-dd")) | B5: ='Weekly Input'!B5 | C5: ='Weekly Input'!C5 | D5: =IF(B5="","",IFERROR(INDEX('Master Data'!$B$6:$B$145,MATCH(B5,'Master Data'!$A$6:$A$145,0)),"")) | E5: =IF(C5="","",IFERROR(INDEX('Master Data'!$H$6:$H$13,MATCH(C5,'Master Data'!$F$6:$F$13,0)),"")) | F5: ='Weekly Input'!A5 | G5: =IF(B5="","",IFERROR(INDEX('Master Data'!$D$6:$D$145,MATCH(B5,'Master Data'!$A$6:$A$145,0)),"")) | H5: =IF(OR(F5="",G5=""),"",F5-G5) | I5: =IF(B5="","",IF('Weekly Input'!J5="OK",TRUE,FALSE)) | J5: =IF(B5="","",'Weekly Input'!H5>=MinInStockDays) | K5: =IF(B5="","",H5>=FullCycleMin) | L5: =IF(B5="","",AND(I5,J5,K5,N5>=MinHistory)) | M5: =IF(OR(B5="",'Weekly Input'!H5=0),"",'Weekly Input'!D5/'Weekly Input'!H5*7) | N5: =IF(B5="","",COUNTIFS($B$5:$B$504,B5,$C$5:$C$504,C5,$I$5:$I$504,TRUE,$J$5:$J$504,TRUE,$K$5:$K$504,TRUE)) | O5: =IF(B5="","",AND(F5=AsOfWeek,AsOfWeek<>"")) | P5: =IF(OR(B5="",AsOfWeek=""),"",IFERROR(SUMIFS($M$5:$M$504,$B$5:$B$504,B5,$C$5:$C$504,C5,$L$5:$L$504,TRUE,$F$5:$F$504,">="&AsOfWeek-7*(RecentWeeks-1),$F$5:$F$504,"<="&AsOfWeek),"")) | Q5: =IF(OR(B5="",AsOfWeek=""),"",IFERROR(SUMIFS($M$5:$M$504,$B$5:$B$504,B5,$C$5:$C$504,C5,$L$5:$L$504,TRUE,$F$5:$F$504,">="&AsOfWeek-7*(RecentWeeks+PriorWeeks-1),$F$5:$F$504,"<"&AsOfWeek-7*(RecentWeeks-1)),"")) | R5: =IF(OR(P5="",Q5="",Q5=0),"",P5/Q5-1) | S5: =IF(OR(C5="",AsOfWeek=""),"",IFERROR(AVERAGEIFS($M$5:$M$504,$C$5:$C$504,C5,$L$5:$L$504,TRUE,$F$5:$F$504,">="&AsOfWeek-7*(RecentWeeks-1),$F$5:$F$504,"<="&AsOfWeek),"")) | T5: =IF(OR(P5="",S5=""),"",P5/S5-1) | U5: =IF(OR(B5="",'Weekly Input'!G5="",P5="",P5=0),"",'Weekly Input'!G5/P5) | V5: =IF(B5="","",IF(NOT(I5),"Not Ready",IF(NOT(K5),"Not Ready",IF(N5<MinHistory,"Not Ready",IF(NOT(J5),"Not Ready",IF(OR(Q5="",Q5=0),"Noise",IF(Q5<LowBaseThreshold,"Noise",IF(AND(R5<=-OwnDecline,T5<=-PeerGapThreshold),"Markdown Review",IF(AND(R5>=ReorderUplift,U5<>"",U5<=WeeksSupplyCap),"Reorder Candidate","Monitor")))))))) | W5: =IF(B5="","",IF(NOT(I5),"INVALID_MASTER",IF(NOT(K5),"INCOMPLETE_SHELF_CYCLE",IF(N5<MinHistory,"INSUFFICIENT_HISTORY",IF(NOT(J5),"INSUFFICIENT_IN_STOCK",IF(OR(Q5="",Q5=0),"NO_PRIOR_BASE",IF(Q5<LowBaseThreshold,"LOW_BASE_NOISE",IF(V5="Markdown Review","MARKDOWN_PEER_GAP",IF(V5="Reorder Candidate","REORDER_UPLIFT_COVER","NO_MATERIAL_CHANGE")))))))) | X5: =IF(V5="Markdown Review","Markdown support",IF(V5="Reorder Candidate","Second reorder",IF(V5="Monitor","Monitor",IF(V5="Noise","Hold / collect data",IF(V5="Not Ready","Not ready",""))))) | Y5: =IF(OR(R5="",T5=""),"",ABS(R5)+ABS(T5)) | Z5: =IF(OR(B5="",NOT(O5),R5=""),"",IF(ABS(R5)>=MaterialThreshold,"Yes","No")) | AA5: =IF(Z5<>"Yes","",IF(ABS(R5)>=MaterialThreshold,IF(ABS(R5)>=BroadShare,"Broad SKU movement","Store-concentrated movement"),"")) | AB5: =IF(O5,IF(COUNTIFS($O$5:O5,TRUE)>0,COUNTIFS($O$5:O5,TRUE),0),0) | AC5: =IF(V5="Markdown Review",1,IF(V5="Reorder Candidate",2,IF(V5="Monitor",3,IF(V5="Noise",4,IF(V5="Not Ready",5,99))))) | AD5: =IF(O5,COUNTIFS($O$5:$O$504,TRUE,$AC$5:$AC$504,"<"&AC5)+COUNTIFS($O$5:O5,TRUE,$AC$5:AC5,AC5,$Y$5:Y5,">"&Y5),0)
A6: =IF(COUNTA('Weekly Input'!A6:C6)=0,"",'Weekly Input'!B6&"|"&'Weekly Input'!C6&"|"&TEXT('Weekly Input'!A6,"yyyy-mm-dd")) | B6: ='Weekly Input'!B6 | C6: ='Weekly Input'!C6 | D6: =IF(B6="","",IFERROR(INDEX('Master Data'!$B$6:$B$145,MATCH(B6,'Master Data'!$A$6:$A$145,0)),"")) | E6: =IF(C6="","",IFERROR(INDEX('Master Data'!$H$6:$H$13,MATCH(C6,'Master Data'!$F$6:$F$13,0)),"")) | F6: ='Weekly Input'!A6 | G6: =IF(B6="","",IFERROR(INDEX('Master Data'!$D$6:$D$145,MATCH(B6,'Master Data'!$A$6:$A$145,0)),"")) | H6: =IF(OR(F6="",G6=""),"",F6-G6) | I6: =IF(B6="","",IF('Weekly Input'!J6="OK",TRUE,FALSE)) | J6: =IF(B6="","",'Weekly Input'!H6>=MinInStockDays) | K6: =IF(B6="","",H6>=FullCycleMin) | L6: =IF(B6="","",AND(I6,J6,K6,N6>=MinHistory)) | M6: =IF(OR(B6="",'Weekly Input'!H6=0),"",'Weekly Input'!D6/'Weekly Input'!H6*7) | N6: =IF(B6="","",COUNTIFS($B$5:$B$504,B6,$C$5:$C$504,C6,$I$5:$I$504,TRUE,$J$5:$J$504,TRUE,$K$5:$K$504,TRUE)) | O6: =IF(B6="","",AND(F6=AsOfWeek,AsOfWeek<>"")) | P6: =IF(OR(B6="",AsOfWeek=""),"",IFERROR(SUMIFS($M$5:$M$504,$B$5:$B$504,B6,$C$5:$C$504,C6,$L$5:$L$504,TRUE,$F$5:$F$504,">="&AsOfWeek-7*(RecentWeeks-1),$F$5:$F$504,"<="&AsOfWeek),"")) | Q6: =IF(OR(B6="",AsOfWeek=""),"",IFERROR(SUMIFS($M$5:$M$504,$B$5:$B$504,B6,$C$5:$C$504,C6,$L$5:$L$504,TRUE,$F$5:$F$504,">="&AsOfWeek-7*(RecentWeeks+PriorWeeks-1),$F$5:$F$504,"<"&AsOfWeek-7*(RecentWeeks-1)),"")) | R6: =IF(OR(P6="",Q6="",Q6=0),"",P6/Q6-1) | S6: =IF(OR(C6="",AsOfWeek=""),"",IFERROR(AVERAGEIFS($M$5:$M$504,$C$5:$C$504,C6,$L$5:$L$504,TRUE,$F$5:$F$504,">="&AsOfWeek-7*(RecentWeeks-1),$F$5:$F$504,"<="&AsOfWeek),"")) | T6: =IF(OR(P6="",S6=""),"",P6/S6-1) | U6: =IF(OR(B6="",'Weekly Input'!G6="",P6="",P6=0),"",'Weekly Input'!G6/P6) | V6: =IF(B6="","",IF(NOT(I6),"Not Ready",IF(NOT(K6),"Not Ready",IF(N6<MinHistory,"Not Ready",IF(NOT(J6),"Not Ready",IF(OR(Q6="",Q6=0),"Noise",IF(Q6<LowBaseThreshold,"Noise",IF(AND(R6<=-OwnDecline,T6<=-PeerGapThreshold),"Markdown Review",IF(AND(R6>=ReorderUplift,U6<>"",U6<=WeeksSupplyCap),"Reorder Candidate","Monitor")))))))) | W6: =IF(B6="","",IF(NOT(I6),"INVALID_MASTER",IF(NOT(K6),"INCOMPLETE_SHELF_CYCLE",IF(N6<MinHistory,"INSUFFICIENT_HISTORY",IF(NOT(J6),"INSUFFICIENT_IN_STOCK",IF(OR(Q6="",Q6=0),"NO_PRIOR_BASE",IF(Q6<LowBaseThreshold,"LOW_BASE_NOISE",IF(V6="Markdown Review","MARKDOWN_PEER_GAP",IF(V6="Reorder Candidate","REORDER_UPLIFT_COVER","NO_MATERIAL_CHANGE")))))))) | X6: =IF(V6="Markdown Review","Markdown support",IF(V6="Reorder Candidate","Second reorder",IF(V6="Monitor","Monitor",IF(V6="Noise","Hold / collect data",IF(V6="Not Ready","Not ready",""))))) | Y6: =IF(OR(R6="",T6=""),"",ABS(R6)+ABS(T6)) | Z6: =IF(OR(B6="",NOT(O6),R6=""),"",IF(ABS(R6)>=MaterialThreshold,"Yes","No")) | AA6: =IF(Z6<>"Yes","",IF(ABS(R6)>=MaterialThreshold,IF(ABS(R6)>=BroadShare,"Broad SKU movement","Store-concentrated movement"),"")) | AB6: =IF(O6,IF(COUNTIFS($O$5:O6,TRUE)>0,COUNTIFS($O$5:O6,TRUE),0),0) | AC6: =IF(V6="Markdown Review",1,IF(V6="Reorder Candidate",2,IF(V6="Monitor",3,IF(V6="Noise",4,IF(V6="Not Ready",5,99))))) | AD6: =IF(O6,COUNTIFS($O$5:$O$504,TRUE,$AC$5:$AC$504,"<"&AC6)+COUNTIFS($O$5:O6,TRUE,$AC$5:AC6,AC6,$Y$5:Y6,">"&Y6),0)
A7: =IF(COUNTA('Weekly Input'!A7:C7)=0,"",'Weekly Input'!B7&"|"&'Weekly Input'!C7&"|"&TEXT('Weekly Input'!A7,"yyyy-mm-dd")) | B7: ='Weekly Input'!B7 | C7: ='Weekly Input'!C7 | D7: =IF(B7="","",IFERROR(INDEX('Master Data'!$B$6:$B$145,MATCH(B7,'Master Data'!$A$6:$A$145,0)),"")) | E7: =IF(C7="","",IFERROR(INDEX('Master Data'!$H$6:$H$13,MATCH(C7,'Master Data'!$F$6:$F$13,0)),"")) | F7: ='Weekly Input'!A7 | G7: =IF(B7="","",IFERROR(INDEX('Master Data'!$D$6:$D$145,MATCH(B7,'Master Data'!$A$6:$A$145,0)),"")) | H7: =IF(OR(F7="",G7=""),"",F7-G7) | I7: =IF(B7="","",IF('Weekly Input'!J7="OK",TRUE,FALSE)) | J7: =IF(B7="","",'Weekly Input'!H7>=MinInStockDays) | K7: =IF(B7="","",H7>=FullCycleMin) | L7: =IF(B7="","",AND(I7,J7,K7,N7>=MinHistory)) | M7: =IF(OR(B7="",'Weekly Input'!H7=0),"",'Weekly Input'!D7/'Weekly Input'!H7*7) | N7: =IF(B7="","",COUNTIFS($B$5:$B$504,B7,$C$5:$C$504,C7,$I$5:$I$504,TRUE,$J$5:$J$504,TRUE,$K$5:$K$504,TRUE)) | O7: =IF(B7="","",AND(F7=AsOfWeek,AsOfWeek<>"")) | P7: =IF(OR(B7="",AsOfWeek=""),"",IFERROR(SUMIFS($M$5:$M$504,$B$5:$B$504,B7,$C$5:$C$504,C7,$L$5:$L$504,TRUE,$F$5:$F$504,">="&AsOfWeek-7*(RecentWeeks-1),$F$5:$F$504,"<="&AsOfWeek),"")) | Q7: =IF(OR(B7="",AsOfWeek=""),"",IFERROR(SUMIFS($M$5:$M$504,$B$5:$B$504,B7,$C$5:$C$504,C7,$L$5:$L$504,TRUE,$F$5:$F$504,">="&AsOfWeek-7*(RecentWeeks+PriorWeeks-1),$F$5:$F$504,"<"&AsOfWeek-7*(RecentWeeks-1)),"")) | R7: =IF(OR(P7="",Q7="",Q7=0),"",P7/Q7-1) | S7: =IF(OR(C7="",AsOfWeek=""),"",IFERROR(AVERAGEIFS($M$5:$M$504,$C$5:$C$504,C7,$L$5:$L$504,TRUE,$F$5:$F$504,">="&AsOfWeek-7*(RecentWeeks-1),$F$5:$F$504,"<="&AsOfWeek),"")) | T7: =IF(OR(P7="",S7=""),"",P7/S7-1) | U7: =IF(OR(B7="",'Weekly Input'!G7="",P7="",P7=0),"",'Weekly Input'!G7/P7) | V7: =IF(B7="","",IF(NOT(I7),"Not Ready",IF(NOT(K7),"Not Ready",IF(N7<MinHistory,"Not Ready",IF(NOT(J7),"Not Ready",IF(OR(Q7="",Q7=0),"Noise",IF(Q7<LowBaseThreshold,"Noise",IF(AND(R7<=-OwnDecline,T7<=-PeerGapThreshold),"Markdown Review",IF(AND(R7>=ReorderUplift,U7<>"",U7<=WeeksSupplyCap),"Reorder Candidate","Monitor")))))))) | W7: =IF(B7="","",IF(NOT(I7),"INVALID_MASTER",IF(NOT(K7),"INCOMPLETE_SHELF_CYCLE",IF(N7<MinHistory,"INSUFFICIENT_HISTORY",IF(NOT(J7),"INSUFFICIENT_IN_STOCK",IF(OR(Q7="",Q7=0),"NO_PRIOR_BASE",IF(Q7<LowBaseThreshold,"LOW_BASE_NOISE",IF(V7="Markdown Review","MARKDOWN_PEER_GAP",IF(V7="Reorder Candidate","REORDER_UPLIFT_COVER","NO_MATERIAL_CHANGE")))))))) | X7: =IF(V7="Markdown Review","Markdown support",IF(V7="Reorder Candidate","Second reorder",IF(V7="Monitor","Monitor",IF(V7="Noise","Hold / collect data",IF(V7="Not Ready","Not ready",""))))) | Y7: =IF(OR(R7="",T7=""),"",ABS(R7)+ABS(T7)) | Z7: =IF(OR(B7="",NOT(O7),R7=""),"",IF(ABS(R7)>=MaterialThreshold,"Yes","No")) | AA7: =IF(Z7<>"Yes","",IF(ABS(R7)>=MaterialThreshold,IF(ABS(R7)>=BroadShare,"Broad SKU movement","Store-concentrated movement"),"")) | AB7: =IF(O7,IF(COUNTIFS($O$5:O7,TRUE)>0,COUNTIFS($O$5:O7,TRUE),0),0) | AC7: =IF(V7="Markdown Review",1,IF(V7="Reorder Candidate",2,IF(V7="Monitor",3,IF(V7="Noise",4,IF(V7="Not Ready",5,99))))) | AD7: =IF(O7,COUNTIFS($O$5:$O$504,TRUE,$AC$5:$AC$504,"<"&AC7)+COUNTIFS($O$5:O7,TRUE,$AC$5:AC7,AC7,$Y$5:Y7,">"&Y7),0)
A8: =IF(COUNTA('Weekly Input'!A8:C8)=0,"",'Weekly Input'!B8&"|"&'Weekly Input'!C8&"|"&TEXT('Weekly Input'!A8,"yyyy-mm-dd")) | B8: ='Weekly Input'!B8 | C8: ='Weekly Input'!C8 | D8: =IF(B8="","",IFERROR(INDEX('Master Data'!$B$6:$B$145,MATCH(B8,'Master Data'!$A$6:$A$145,0)),"")) | E8: =IF(C8="","",IFERROR(INDEX('Master Data'!$H$6:$H$13,MATCH(C8,'Master Data'!$F$6:$F$13,0)),"")) | F8: ='Weekly Input'!A8 | G8: =IF(B8="","",IFERROR(INDEX('Master Data'!$D$6:$D$145,MATCH(B8,'Master Data'!$A$6:$A$145,0)),"")) | H8: =IF(OR(F8="",G8=""),"",F8-G8) | I8: =IF(B8="","",IF('Weekly Input'!J8="OK",TRUE,FALSE)) | J8: =IF(B8="","",'Weekly Input'!H8>=MinInStockDays) | K8: =IF(B8="","",H8>=FullCycleMin) | L8: =IF(B8="","",AND(I8,J8,K8,N8>=MinHistory)) | M8: =IF(OR(B8="",'Weekly Input'!H8=0),"",'Weekly Input'!D8/'Weekly Input'!H8*7) | N8: =IF(B8="","",COUNTIFS($B$5:$B$504,B8,$C$5:$C$504,C8,$I$5:$I$504,TRUE,$J$5:$J$504,TRUE,$K$5:$K$504,TRUE)) | O8: =IF(B8="","",AND(F8=AsOfWeek,AsOfWeek<>"")) | P8: =IF(OR(B8="",AsOfWeek=""),"",IFERROR(SUMIFS($M$5:$M$504,$B$5:$B$504,B8,$C$5:$C$504,C8,$L$5:$L$504,TRUE,$F$5:$F$504,">="&AsOfWeek-7*(RecentWeeks-1),$F$5:$F$504,"<="&AsOfWeek),"")) | Q8: =IF(OR(B8="",AsOfWeek=""),"",IFERROR(SUMIFS($M$5:$M$504,$B$5:$B$504,B8,$C$5:$C$504,C8,$L$5:$L$504,TRUE,$F$5:$F$504,">="&AsOfWeek-7*(RecentWeeks+PriorWeeks-1),$F$5:$F$504,"<"&AsOfWeek-7*(RecentWeeks-1)),"")) | R8: =IF(OR(P8="",Q8="",Q8=0),"",P8/Q8-1) | S8: =IF(OR(C8="",AsOfWeek=""),"",IFERROR(AVERAGEIFS($M$5:$M$504,$C$5:$C$504,C8,$L$5:$L$504,TRUE,$F$5:$F$504,">="&AsOfWeek-7*(RecentWeeks-1),$F$5:$F$504,"<="&AsOfWeek),"")) | T8: =IF(OR(P8="",S8=""),"",P8/S8-1) | U8: =IF(OR(B8="",'Weekly Input'!G8="",P8="",P8=0),"",'Weekly Input'!G8/P8) | V8: =IF(B8="","",IF(NOT(I8),"Not Ready",IF(NOT(K8),"Not Ready",IF(N8<MinHistory,"Not Ready",IF(NOT(J8),"Not Ready",IF(OR(Q8="",Q8=0),"Noise",IF(Q8<LowBaseThreshold,"Noise",IF(AND(R8<=-OwnDecline,T8<=-PeerGapThreshold),"Markdown Review",IF(AND(R8>=ReorderUplift,U8<>"",U8<=WeeksSupplyCap),"Reorder Candidate","Monitor")))))))) | W8: =IF(B8="","",IF(NOT(I8),"INVALID_MASTER",IF(NOT(K8),"INCOMPLETE_SHELF_CYCLE",IF(N8<MinHistory,"INSUFFICIENT_HISTORY",IF(NOT(J8),"INSUFFICIENT_IN_STOCK",IF(OR(Q8="",Q8=0),"NO_PRIOR_BASE",IF(Q8<LowBaseThreshold,"LOW_BASE_NOISE",IF(V8="Markdown Review","MARKDOWN_PEER_GAP",IF(V8="Reorder Candidate","REORDER_UPLIFT_COVER","NO_MATERIAL_CHANGE")))))))) | X8: =IF(V8="Markdown Review","Markdown support",IF(V8="Reorder Candidate","Second reorder",IF(V8="Monitor","Monitor",IF(V8="Noise","Hold / collect data",IF(V8="Not Ready","Not ready",""))))) | Y8: =IF(OR(R8="",T8=""),"",ABS(R8)+ABS(T8)) | Z8: =IF(OR(B8="",NOT(O8),R8=""),"",IF(ABS(R8)>=MaterialThreshold,"Yes","No")) | AA8: =IF(Z8<>"Yes","",IF(ABS(R8)>=MaterialThreshold,IF(ABS(R8)>=BroadShare,"Broad SKU movement","Store-concentrated movement"),"")) | AB8: =IF(O8,IF(COUNTIFS($O$5:O8,TRUE)>0,COUNTIFS($O$5:O8,TRUE),0),0) | AC8: =IF(V8="Markdown Review",1,IF(V8="Reorder Candidate",2,IF(V8="Monitor",3,IF(V8="Noise",4,IF(V8="Not Ready",5,99))))) | AD8: =IF(O8,COUNTIFS($O$5:$O$504,TRUE,$AC$5:$AC$504,"<"&AC8)+COUNTIFS($O$5:O8,TRUE,$AC$5:AC8,AC8,$Y$5:Y8,">"&Y8),0)
A9: =IF(COUNTA('Weekly Input'!A9:C9)=0,"",'Weekly Input'!B9&"|"&'Weekly Input'!C9&"|"&TEXT('Weekly Input'!A9,"yyyy-mm-dd")) | B9: ='Weekly Input'!B9 | C9: ='Weekly Input'!C9 | D9: =IF(B9="","",IFERROR(INDEX('Master Data'!$B$6:$B$145,MATCH(B9,'Master Data'!$A$6:$A$145,0)),"")) | E9: =IF(C9="","",IFERROR(INDEX('Master Data'!$H$6:$H$13,MATCH(C9,'Master Data'!$F$6:$F$13,0)),"")) | F9: ='Weekly Input'!A9 | G9: =IF(B9="","",IFERROR(INDEX('Master Data'!$D$6:$D$145,MATCH(B9,'Master Data'!$A$6:$A$145,0)),"")) | H9: =IF(OR(F9="",G9=""),"",F9-G9) | I9: =IF(B9="","",IF('Weekly Input'!J9="OK",TRUE,FALSE)) | J9: =IF(B9="","",'Weekly Input'!H9>=MinInStockDays) | K9: =IF(B9="","",H9>=FullCycleMin) | L9: =IF(B9="","",AND(I9,J9,K9,N9>=MinHistory)) | M9: =IF(OR(B9="",'Weekly Input'!H9=0),"",'Weekly Input'!D9/'Weekly Input'!H9*7) | N9: =IF(B9="","",COUNTIFS($B$5:$B$504,B9,$C$5:$C$504,C9,$I$5:$I$504,TRUE,$J$5:$J$504,TRUE,$K$5:$K$504,TRUE)) | O9: =IF(B9="","",AND(F9=AsOfWeek,AsOfWeek<>"")) | P9: =IF(OR(B9="",AsOfWeek=""),"",IFERROR(SUMIFS($M$5:$M$504,$B$5:$B$504,B9,$C$5:$C$504,C9,$L$5:$L$504,TRUE,$F$5:$F$504,">="&AsOfWeek-7*(RecentWeeks-1),$F$5:$F$504,"<="&AsOfWeek),"")) | Q9: =IF(OR(B9="",AsOfWeek=""),"",IFERROR(SUMIFS($M$5:$M$504,$B$5:$B$504,B9,$C$5:$C$504,C9,$L$5:$L$504,TRUE,$F$5:$F$504,">="&AsOfWeek-7*(RecentWeeks+PriorWeeks-1),$F$5:$F$504,"<"&AsOfWeek-7*(RecentWeeks-1)),"")) | R9: =IF(OR(P9="",Q9="",Q9=0),"",P9/Q9-1) | S9: =IF(OR(C9="",AsOfWeek=""),"",IFERROR(AVERAGEIFS($M$5:$M$504,$C$5:$C$504,C9,$L$5:$L$504,TRUE,$F$5:$F$504,">="&AsOfWeek-7*(RecentWeeks-1),$F$5:$F$504,"<="&AsOfWeek),"")) | T9: =IF(OR(P9="",S9=""),"",P9/S9-1) | U9: =IF(OR(B9="",'Weekly Input'!G9="",P9="",P9=0),"",'Weekly Input'!G9/P9) | V9: =IF(B9="","",IF(NOT(I9),"Not Ready",IF(NOT(K9),"Not Ready",IF(N9<MinHistory,"Not Ready",IF(NOT(J9),"Not Ready",IF(OR(Q9="",Q9=0),"Noise",IF(Q9<LowBaseThreshold,"Noise",IF(AND(R9<=-OwnDecline,T9<=-PeerGapThreshold),"Markdown Review",IF(AND(R9>=ReorderUplift,U9<>"",U9<=WeeksSupplyCap),"Reorder Candidate","Monitor")))))))) | W9: =IF(B9="","",IF(NOT(I9),"INVALID_MASTER",IF(NOT(K9),"INCOMPLETE_SHELF_CYCLE",IF(N9<MinHistory,"INSUFFICIENT_HISTORY",IF(NOT(J9),"INSUFFICIENT_IN_STOCK",IF(OR(Q9="",Q9=0),"NO_PRIOR_BASE",IF(Q9<LowBaseThreshold,"LOW_BASE_NOISE",IF(V9="Markdown Review","MARKDOWN_PEER_GAP",IF(V9="Reorder Candidate","REORDER_UPLIFT_COVER","NO_MATERIAL_CHANGE")))))))) | X9: =IF(V9="Markdown Review","Markdown support",IF(V9="Reorder Candidate","Second reorder",IF(V9="Monitor","Monitor",IF(V9="Noise","Hold / collect data",IF(V9="Not Ready","Not ready",""))))) | Y9: =IF(OR(R9="",T9=""),"",ABS(R9)+ABS(T9)) | Z9: =IF(OR(B9="",NOT(O9),R9=""),"",IF(ABS(R9)>=MaterialThreshold,"Yes","No")) | AA9: =IF(Z9<>"Yes","",IF(ABS(R9)>=MaterialThreshold,IF(ABS(R9)>=BroadShare,"Broad SKU movement","Store-concentrated movement"),"")) | AB9: =IF(O9,IF(COUNTIFS($O$5:O9,TRUE)>0,COUNTIFS($O$5:O9,TRUE),0),0) | AC9: =IF(V9="Markdown Review",1,IF(V9="Reorder Candidate",2,IF(V9="Monitor",3,IF(V9="Noise",4,IF(V9="Not Ready",5,99))))) | AD9: =IF(O9,COUNTIFS($O$5:$O$504,TRUE,$AC$5:$AC$504,"<"&AC9)+COUNTIFS($O$5:O9,TRUE,$AC$5:AC9,AC9,$Y$5:Y9,">"&Y9),0)
A10: =IF(COUNTA('Weekly Input'!A10:C10)=0,"",'Weekly Input'!B10&"|"&'Weekly Input'!C10&"|"&TEXT('Weekly Input'!A10,"yyyy-mm-dd")) | B10: ='Weekly Input'!B10 | C10: ='Weekly Input'!C10 | D10: =IF(B10="","",IFERROR(INDEX('Master Data'!$B$6:$B$145,MATCH(B10,'Master Data'!$A$6:$A$145,0)),"")) | E10: =IF(C10="","",IFERROR(INDEX('Master Data'!$H$6:$H$13,MATCH(C10,'Master Data'!$F$6:$F$13,0)),"")) | F10: ='Weekly Input'!A10 | G10: =IF(B10="","",IFERROR(INDEX('Master Data'!$D$6:$D$145,MATCH(B10,'Master Data'!$A$6:$A$145,0)),"")) | H10: =IF(OR(F10="",G10=""),"",F10-G10) | I10: =IF(B10="","",IF('Weekly Input'!J10="OK",TRUE,FALSE)) | J10: =IF(B10="","",'Weekly Input'!H10>=MinInStockDays) | K10: =IF(B10="","",H10>=FullCycleMin) | L10: =IF(B10="","",AND(I10,J10,K10,N10>=MinHistory)) | M10: =IF(OR(B10="",'Weekly Input'!H10=0),"",'Weekly Input'!D10/'Weekly Input'!H10*7) | N10: =IF(B10="","",COUNTIFS($B$5:$B$504,B10,$C$5:$C$504,C10,$I$5:$I$504,TRUE,$J$5:$J$504,TRUE,$K$5:$K$504,TRUE)) | O10: =IF(B10="","",AND(F10=AsOfWeek,AsOfWeek<>"")) | P10: =IF(OR(B10="",AsOfWeek=""),"",IFERROR(SUMIFS($M$5:$M$504,$B$5:$B$504,B10,$C$5:$C$504,C10,$L$5:$L$504,TRUE,$F$5:$F$504,">="&AsOfWeek-7*(RecentWeeks-1),$F$5:$F$504,"<="&AsOfWeek),"")) | Q10: =IF(OR(B10="",AsOfWeek=""),"",IFERROR(SUMIFS($M$5:$M$504,$B$5:$B$504,B10,$C$5:$C$504,C10,$L$5:$L$504,TRUE,$F$5:$F$504,">="&AsOfWeek-7*(RecentWeeks+PriorWeeks-1),$F$5:$F$504,"<"&AsOfWeek-7*(RecentWeeks-1)),"")) | R10: =IF(OR(P10="",Q10="",Q10=0),"",P10/Q10-1) | S10: =IF(OR(C10="",AsOfWeek=""),"",IFERROR(AVERAGEIFS($M$5:$M$504,$C$5:$C$504,C10,$L$5:$L$504,TRUE,$F$5:$F$504,">="&AsOfWeek-7*(RecentWeeks-1),$F$5:$F$504,"<="&AsOfWeek),"")) | T10: =IF(OR(P10="",S10=""),"",P10/S10-1) | U10: =IF(OR(B10="",'Weekly Input'!G10="",P10="",P10=0),"",'Weekly Input'!G10/P10) | V10: =IF(B10="","",IF(NOT(I10),"Not Ready",IF(NOT(K10),"Not Ready",IF(N10<MinHistory,"Not Ready",IF(NOT(J10),"Not Ready",IF(OR(Q10="",Q10=0),"Noise",IF(Q10<LowBaseThreshold,"Noise",IF(AND(R10<=-OwnDecline,T10<=-PeerGapThreshold),"Markdown Review",IF(AND(R10>=ReorderUplift,U10<>"",U10<=WeeksSupplyCap),"Reorder Candidate","Monitor")))))))) | W10: =IF(B10="","",IF(NOT(I10),"INVALID_MASTER",IF(NOT(K10),"INCOMPLETE_SHELF_CYCLE",IF(N10<MinHistory,"INSUFFICIENT_HISTORY",IF(NOT(J10),"INSUFFICIENT_IN_STOCK",IF(OR(Q10="",Q10=0),"NO_PRIOR_BASE",IF(Q10<LowBaseThreshold,"LOW_BASE_NOISE",IF(V10="Markdown Review","MARKDOWN_PEER_GAP",IF(V10="Reorder Candidate","REORDER_UPLIFT_COVER","NO_MATERIAL_CHANGE")))))))) | X10: =IF(V10="Markdown Review","Markdown support",IF(V10="Reorder Candidate","Second reorder",IF(V10="Monitor","Monitor",IF(V10="Noise","Hold / collect data",IF(V10="Not Ready","Not ready",""))))) | Y10: =IF(OR(R10="",T10=""),"",ABS(R10)+ABS(T10)) | Z10: =IF(OR(B10="",NOT(O10),R10=""),"",IF(ABS(R10)>=MaterialThreshold,"Yes","No")) | AA10: =IF(Z10<>"Yes","",IF(ABS(R10)>=MaterialThreshold,IF(ABS(R10)>=BroadShare,"Broad SKU movement","Store-concentrated movement"),"")) | AB10: =IF(O10,IF(COUNTIFS($O$5:O10,TRUE)>0,COUNTIFS($O$5:O10,TRUE),0),0) | AC10: =IF(V10="Markdown Review",1,IF(V10="Reorder Candidate",2,IF(V10="Monitor",3,IF(V10="Noise",4,IF(V10="Not Ready",5,99))))) | AD10: =IF(O10,COUNTIFS($O$5:$O$504,TRUE,$AC$5:$AC$504,"<"&AC10)+COUNTIFS($O$5:O10,TRUE,$AC$5:AC10,AC10,$Y$5:Y10,">"&Y10),0)
A11: =IF(COUNTA('Weekly Input'!A11:C11)=0,"",'Weekly Input'!B11&"|"&'Weekly Input'!C11&"|"&TEXT('Weekly Input'!A11,"yyyy-mm-dd")) | B11: ='Weekly Input'!B11 | C11: ='Weekly Input'!C11 | D11: =IF(B11="","",IFERROR(INDEX('Master Data'!$B$6:$B$145,MATCH(B11,'Master Data'!$A$6:$A$145,0)),"")) | E11: =IF(C11="","",IFERROR(INDEX('Master Data'!$H$6:$H$13,MATCH(C11,'Master Data'!$F$6:$F$13,0)),"")) | F11: ='Weekly Input'!A11 | G11: =IF(B11="","",IFERROR(INDEX('Master Data'!$D$6:$D$145,MATCH(B11,'Master Data'!$A$6:$A$145,0)),"")) | H11: =IF(OR(F11="",G11=""),"",F11-G11) | I11: =IF(B11="","",IF('Weekly Input'!J11="OK",TRUE,FALSE)) | J11: =IF(B11="","",'Weekly Input'!H11>=MinInStockDays) | K11: =IF(B11="","",H11>=FullCycleMin) | L11: =IF(B11="","",AND(I11,J11,K11,N11>=MinHistory)) | M11: =IF(OR(B11="",'Weekly Input'!H11=0),"",'Weekly Input'!D11/'Weekly Input'!H11*7) | N11: =IF(B11="","",COUNTIFS($B$5:$B$504,B11,$C$5:$C$504,C11,$I$5:$I$504,TRUE,$J$5:$J$504,TRUE,$K$5:$K$504,TRUE)) | O11: =IF(B11="","",AND(F11=AsOfWeek,AsOfWeek<>"")) | P11: =IF(OR(B11="",AsOfWeek=""),"",IFERROR(SUMIFS($M$5:$M$504,$B$5:$B$504,B11,$C$5:$C$504,C11,$L$5:$L$504,TRUE,$F$5:$F$504,">="&AsOfWeek-7*(RecentWeeks-1),$F$5:$F$504,"<="&AsOfWeek),"")) | Q11: =IF(OR(B11="",AsOfWeek=""),"",IFERROR(SUMIFS($M$5:$M$504,$B$5:$B$504,B11,$C$5:$C$504,C11,$L$5:$L$504,TRUE,$F$5:$F$504,">="&AsOfWeek-7*(RecentWeeks+PriorWeeks-1),$F$5:$F$504,"<"&AsOfWeek-7*(RecentWeeks-1)),"")) | R11: =IF(OR(P11="",Q11="",Q11=0),"",P11/Q11-1) | S11: =IF(OR(C11="",AsOfWeek=""),"",IFERROR(AVERAGEIFS($M$5:$M$504,$C$5:$C$504,C11,$L$5:$L$504,TRUE,$F$5:$F$504,">="&AsOfWeek-7*(RecentWeeks-1),$F$5:$F$504,"<="&AsOfWeek),"")) | T11: =IF(OR(P11="",S11=""),"",P11/S11-1) | U11: =IF(OR(B11="",'Weekly Input'!G11="",P11="",P11=0),"",'Weekly Input'!G11/P11) | V11: =IF(B11="","",IF(NOT(I11),"Not Ready",IF(NOT(K11),"Not Ready",IF(N11<MinHistory,"Not Ready",IF(NOT(J11),"Not Ready",IF(OR(Q11="",Q11=0),"Noise",IF(Q11<LowBaseThreshold,"Noise",IF(AND(R11<=-OwnDecline,T11<=-PeerGapThreshold),"Markdown Review",IF(AND(R11>=ReorderUplift,U11<>"",U11<=WeeksSupplyCap),"Reorder Candidate","Monitor")))))))) | W11: =IF(B11="","",IF(NOT(I11),"INVALID_MASTER",IF(NOT(K11),"INCOMPLETE_SHELF_CYCLE",IF(N11<MinHistory,"INSUFFICIENT_HISTORY",IF(NOT(J11),"INSUFFICIENT_IN_STOCK",IF(OR(Q11="",Q11=0),"NO_PRIOR_BASE",IF(Q11<LowBaseThreshold,"LOW_BASE_NOISE",IF(V11="Markdown Review","MARKDOWN_PEER_GAP",IF(V11="Reorder Candidate","REORDER_UPLIFT_COVER","NO_MATERIAL_CHANGE")))))))) | X11: =IF(V11="Markdown Review","Markdown support",IF(V11="Reorder Candidate","Second reorder",IF(V11="Monitor","Monitor",IF(V11="Noise","Hold / collect data",IF(V11="Not Ready","Not ready",""))))) | Y11: =IF(OR(R11="",T11=""),"",ABS(R11)+ABS(T11)) | Z11: =IF(OR(B11="",NOT(O11),R11=""),"",IF(ABS(R11)>=MaterialThreshold,"Yes","No")) | AA11: =IF(Z11<>"Yes","",IF(ABS(R11)>=MaterialThreshold,IF(ABS(R11)>=BroadShare,"Broad SKU movement","Store-concentrated movement"),"")) | AB11: =IF(O11,IF(COUNTIFS($O$5:O11,TRUE)>0,COUNTIFS($O$5:O11,TRUE),0),0) | AC11: =IF(V11="Markdown Review",1,IF(V11="Reorder Candidate",2,IF(V11="Monitor",3,IF(V11="Noise",4,IF(V11="Not Ready",5,99))))) | AD11: =IF(O11,COUNTIFS($O$5:$O$504,TRUE,$AC$5:$AC$504,"<"&AC11)+COUNTIFS($O$5:O11,TRUE,$AC$5:AC11,AC11,$Y$5:Y11,">"&Y11),0)
A12: =IF(COUNTA('Weekly Input'!A12:C12)=0,"",'Weekly Input'!B12&"|"&'Weekly Input'!C12&"|"&TEXT('Weekly Input'!A12,"yyyy-mm-dd")) | B12: ='Weekly Input'!B12 | C12: ='Weekly Input'!C12 | D12: =IF(B12="","",IFERROR(INDEX('Master Data'!$B$6:$B$145,MATCH(B12,'Master Data'!$A$6:$A$145,0)),"")) | E12: =IF(C12="","",IFERROR(INDEX('Master Data'!$H$6:$H$13,MATCH(C12,'Master Data'!$F$6:$F$13,0)),"")) | F12: ='Weekly Input'!A12 | G12: =IF(B12="","",IFERROR(INDEX('Master Data'!$D$6:$D$145,MATCH(B12,'Master Data'!$A$6:$A$145,0)),"")) | H12: =IF(OR(F12="",G12=""),"",F12-G12) | I12: =IF(B12="","",IF('Weekly Input'!J12="OK",TRUE,FALSE)) | J12: =IF(B12="","",'Weekly Input'!H12>=MinInStockDays) | K12: =IF(B12="","",H12>=FullCycleMin) | L12: =IF(B12="","",AND(I12,J12,K12,N12>=MinHistory)) | M12: =IF(OR(B12="",'Weekly Input'!H12=0),"",'Weekly Input'!D12/'Weekly Input'!H12*7) | N12: =IF(B12="","",COUNTIFS($B$5:$B$504,B12,$C$5:$C$504,C12,$I$5:$I$504,TRUE,$J$5:$J$504,TRUE,$K$5:$K$504,TRUE)) | O12: =IF(B12="","",AND(F12=AsOfWeek,AsOfWeek<>"")) | P12: =IF(OR(B12="",AsOfWeek=""),"",IFERROR(SUMIFS($M$5:$M$504,$B$5:$B$504,B12,$C$5:$C$504,C12,$L$5:$L$504,TRUE,$F$5:$F$504,">="&AsOfWeek-7*(RecentWeeks-1),$F$5:$F$504,"<="&AsOfWeek),"")) | Q12: =IF(OR(B12="",AsOfWeek=""),"",IFERROR(SUMIFS($M$5:$M$504,$B$5:$B$504,B12,$C$5:$C$504,C12,$L$5:$L$504,TRUE,$F$5:$F$504,">="&AsOfWeek-7*(RecentWeeks+PriorWeeks-1),$F$5:$F$504,"<"&AsOfWeek-7*(RecentWeeks-1)),"")) | R12: =IF(OR(P12="",Q12="",Q12=0),"",P12/Q12-1) | S12: =IF(OR(C12="",AsOfWeek=""),"",IFERROR(AVERAGEIFS($M$5:$M$504,$C$5:$C$504,C12,$L$5:$L$504,TRUE,$F$5:$F$504,">="&AsOfWeek-7*(RecentWeeks-1),$F$5:$F$504,"<="&AsOfWeek),"")) | T12: =IF(OR(P12="",S12=""),"",P12/S12-1) | U12: =IF(OR(B12="",'Weekly Input'!G12="",P12="",P12=0),"",'Weekly Input'!G12/P12) | V12: =IF(B12="","",IF(NOT(I12),"Not Ready",IF(NOT(K12),"Not Ready",IF(N12<MinHistory,"Not Ready",IF(NOT(J12),"Not Ready",IF(OR(Q12="",Q12=0),"Noise",IF(Q12<LowBaseThreshold,"Noise",IF(AND(R12<=-OwnDecline,T12<=-PeerGapThreshold),"Markdown Review",IF(AND(R12>=ReorderUplift,U12<>"",U12<=WeeksSupplyCap),"Reorder Candidate","Monitor")))))))) | W12: =IF(B12="","",IF(NOT(I12),"INVALID_MASTER",IF(NOT(K12),"INCOMPLETE_SHELF_CYCLE",IF(N12<MinHistory,"INSUFFICIENT_HISTORY",IF(NOT(J12),"INSUFFICIENT_IN_STOCK",IF(OR(Q12="",Q12=0),"NO_PRIOR_BASE",IF(Q12<LowBaseThreshold,"LOW_BASE_NOISE",IF(V12="Markdown Review","MARKDOWN_PEER_GAP",IF(V12="Reorder Candidate","REORDER_UPLIFT_COVER","NO_MATERIAL_CHANGE")))))))) | X12: =IF(V12="Markdown Review","Markdown support",IF(V12="Reorder Candidate","Second reorder",IF(V12="Monitor","Monitor",IF(V12="Noise","Hold / collect data",IF(V12="Not Ready","Not ready",""))))) | Y12: =IF(OR(R12="",T12=""),"",ABS(R12)+ABS(T12)) | Z12: =IF(OR(B12="",NOT(O12),R12=""),"",IF(ABS(R12)>=MaterialThreshold,"Yes","No")) | AA12: =IF(Z12<>"Yes","",IF(ABS(R12)>=MaterialThreshold,IF(ABS(R12)>=BroadShare,"Broad SKU movement","Store-concentrated movement"),"")) | AB12: =IF(O12,IF(COUNTIFS($O$5:O12,TRUE)>0,COUNTIFS($O$5:O12,TRUE),0),0) | AC12: =IF(V12="Markdown Review",1,IF(V12="Reorder Candidate",2,IF(V12="Monitor",3,IF(V12="Noise",4,IF(V12="Not Ready",5,99))))) | AD12: =IF(O12,COUNTIFS($O$5:$O$504,TRUE,$AC$5:$AC$504,"<"&AC12)+COUNTIFS($O$5:O12,TRUE,$AC$5:AC12,AC12,$Y$5:Y12,">"&Y12),0)
A13: =IF(COUNTA('Weekly Input'!A13:C13)=0,"",'Weekly Input'!B13&"|"&'Weekly Input'!C13&"|"&TEXT('Weekly Input'!A13,"yyyy-mm-dd")) | B13: ='Weekly Input'!B13 | C13: ='Weekly Input'!C13 | D13: =IF(B13="","",IFERROR(INDEX('Master Data'!$B$6:$B$145,MATCH(B13,'Master Data'!$A$6:$A$145,0)),"")) | E13: =IF(C13="","",IFERROR(INDEX('Master Data'!$H$6:$H$13,MATCH(C13,'Master Data'!$F$6:$F$13,0)),"")) | F13: ='Weekly Input'!A13 | G13: =IF(B13="","",IFERROR(INDEX('Master Data'!$D$6:$D$145,MATCH(B13,'Master Data'!$A$6:$A$145,0)),"")) | H13: =IF(OR(F13="",G13=""),"",F13-G13) | I13: =IF(B13="","",IF('Weekly Input'!J13="OK",TRUE,FALSE)) | J13: =IF(B13="","",'Weekly Input'!H13>=MinInStockDays) | K13: =IF(B13="","",H13>=FullCycleMin) | L13: =IF(B13="","",AND(I13,J13,K13,N13>=MinHistory)) | M13: =IF(OR(B13="",'Weekly Input'!H13=0),"",'Weekly Input'!D13/'Weekly Input'!H13*7) | N13: =IF(B13="","",COUNTIFS($B$5:$B$504,B13,$C$5:$C$504,C13,$I$5:$I$504,TRUE,$J$5:$J$504,TRUE,$K$5:$K$504,TRUE)) | O13: =IF(B13="","",AND(F13=AsOfWeek,AsOfWeek<>"")) | P13: =IF(OR(B13="",AsOfWeek=""),"",IFERROR(SUMIFS($M$5:$M$504,$B$5:$B$504,B13,$C$5:$C$504,C13,$L$5:$L$504,TRUE,$F$5:$F$504,">="&AsOfWeek-7*(RecentWeeks-1),$F$5:$F$504,"<="&AsOfWeek),"")) | Q13: =IF(OR(B13="",AsOfWeek=""),"",IFERROR(SUMIFS($M$5:$M$504,$B$5:$B$504,B13,$C$5:$C$504,C13,$L$5:$L$504,TRUE,$F$5:$F$504,">="&AsOfWeek-7*(RecentWeeks+PriorWeeks-1),$F$5:$F$504,"<"&AsOfWeek-7*(RecentWeeks-1)),"")) | R13: =IF(OR(P13="",Q13="",Q13=0),"",P13/Q13-1) | S13: =IF(OR(C13="",AsOfWeek=""),"",IFERROR(AVERAGEIFS($M$5:$M$504,$C$5:$C$504,C13,$L$5:$L$504,TRUE,$F$5:$F$504,">="&AsOfWeek-7*(RecentWeeks-1),$F$5:$F$504,"<="&AsOfWeek),"")) | T13: =IF(OR(P13="",S13=""),"",P13/S13-1) | U13: =IF(OR(B13="",'Weekly Input'!G13="",P13="",P13=0),"",'Weekly Input'!G13/P13) | V13: =IF(B13="","",IF(NOT(I13),"Not Ready",IF(NOT(K13),"Not Ready",IF(N13<MinHistory,"Not Ready",IF(NOT(J13),"Not Ready",IF(OR(Q13="",Q13=0),"Noise",IF(Q13<LowBaseThreshold,"Noise",IF(AND(R13<=-OwnDecline,T13<=-PeerGapThreshold),"Markdown Review",IF(AND(R13>=ReorderUplift,U13<>"",U13<=WeeksSupplyCap),"Reorder Candidate","Monitor")))))))) | W13: =IF(B13="","",IF(NOT(I13),"INVALID_MASTER",IF(NOT(K13),"INCOMPLETE_SHELF_CYCLE",IF(N13<MinHistory,"INSUFFICIENT_HISTORY",IF(NOT(J13),"INSUFFICIENT_IN_STOCK",IF(OR(Q13="",Q13=0),"NO_PRIOR_BASE",IF(Q13<LowBaseThreshold,"LOW_BASE_NOISE",IF(V13="Markdown Review","MARKDOWN_PEER_GAP",IF(V13="Reorder Candidate","REORDER_UPLIFT_COVER","NO_MATERIAL_CHANGE")))))))) | X13: =IF(V13="Markdown Review","Markdown support",IF(V13="Reorder Candidate","Second reorder",IF(V13="Monitor","Monitor",IF(V13="Noise","Hold / collect data",IF(V13="Not Ready","Not ready",""))))) | Y13: =IF(OR(R13="",T13=""),"",ABS(R13)+ABS(T13)) | Z13: =IF(OR(B13="",NOT(O13),R13=""),"",IF(ABS(R13)>=MaterialThreshold,"Yes","No")) | AA13: =IF(Z13<>"Yes","",IF(ABS(R13)>=MaterialThreshold,IF(ABS(R13)>=BroadShare,"Broad SKU movement","Store-concentrated movement"),"")) | AB13: =IF(O13,IF(COUNTIFS($O$5:O13,TRUE)>0,COUNTIFS($O$5:O13,TRUE),0),0) | AC13: =IF(V13="Markdown Review",1,IF(V13="Reorder Candidate",2,IF(V13="Monitor",3,IF(V13="Noise",4,IF(V13="Not Ready",5,99))))) | AD13: =IF(O13,COUNTIFS($O$5:$O$504,TRUE,$AC$5:$AC$504,"<"&AC13)+COUNTIFS($O$5:O13,TRUE,$AC$5:AC13,AC13,$Y$5:Y13,">"&Y13),0)
A14: =IF(COUNTA('Weekly Input'!A14:C14)=0,"",'Weekly Input'!B14&"|"&'Weekly Input'!C14&"|"&TEXT('Weekly Input'!A14,"yyyy-mm-dd")) | B14: ='Weekly Input'!B14 | C14: ='Weekly Input'!C14 | D14: =IF(B14="","",IFERROR(INDEX('Master Data'!$B$6:$B$145,MATCH(B14,'Master Data'!$A$6:$A$145,0)),"")) | E14: =IF(C14="","",IFERROR(INDEX('Master Data'!$H$6:$H$13,MATCH(C14,'Master Data'!$F$6:$F$13,0)),"")) | F14: ='Weekly Input'!A14 | G14: =IF(B14="","",IFERROR(INDEX('Master Data'!$D$6:$D$145,MATCH(B14,'Master Data'!$A$6:$A$145,0)),"")) | H14: =IF(OR(F14="",G14=""),"",F14-G14) | I14: =IF(B14="","",IF('Weekly Input'!J14="OK",TRUE,FALSE)) | J14: =IF(B14="","",'Weekly Input'!H14>=MinInStockDays) | K14: =IF(B14="","",H14>=FullCycleMin) | L14: =IF(B14="","",AND(I14,J14,K14,N14>=MinHistory)) | M14: =IF(OR(B14="",'Weekly Input'!H14=0),"",'Weekly Input'!D14/'Weekly Input'!H14*7) | N14: =IF(B14="","",COUNTIFS($B$5:$B$504,B14,$C$5:$C$504,C14,$I$5:$I$504,TRUE,$J$5:$J$504,TRUE,$K$5:$K$504,TRUE)) | O14: =IF(B14="","",AND(F14=AsOfWeek,AsOfWeek<>"")) | P14: =IF(OR(B14="",AsOfWeek=""),"",IFERROR(SUMIFS($M$5:$M$504,$B$5:$B$504,B14,$C$5:$C$504,C14,$L$5:$L$504,TRUE,$F$5:$F$504,">="&AsOfWeek-7*(RecentWeeks-1),$F$5:$F$504,"<="&AsOfWeek),"")) | Q14: =IF(OR(B14="",AsOfWeek=""),"",IFERROR(SUMIFS($M$5:$M$504,$B$5:$B$504,B14,$C$5:$C$504,C14,$L$5:$L$504,TRUE,$F$5:$F$504,">="&AsOfWeek-7*(RecentWeeks+PriorWeeks-1),$F$5:$F$504,"<"&AsOfWeek-7*(RecentWeeks-1)),"")) | R14: =IF(OR(P14="",Q14="",Q14=0),"",P14/Q14-1) | S14: =IF(OR(C14="",AsOfWeek=""),"",IFERROR(AVERAGEIFS($M$5:$M$504,$C$5:$C$504,C14,$L$5:$L$504,TRUE,$F$5:$F$504,">="&AsOfWeek-7*(RecentWeeks-1),$F$5:$F$504,"<="&AsOfWeek),"")) | T14: =IF(OR(P14="",S14=""),"",P14/S14-1) | U14: =IF(OR(B14="",'Weekly Input'!G14="",P14="",P14=0),"",'Weekly Input'!G14/P14) | V14: =IF(B14="","",IF(NOT(I14),"Not Ready",IF(NOT(K14),"Not Ready",IF(N14<MinHistory,"Not Ready",IF(NOT(J14),"Not Ready",IF(OR(Q14="",Q14=0),"Noise",IF(Q14<LowBaseThreshold,"Noise",IF(AND(R14<=-OwnDecline,T14<=-PeerGapThreshold),"Markdown Review",IF(AND(R14>=ReorderUplift,U14<>"",U14<=WeeksSupplyCap),"Reorder Candidate","Monitor")))))))) | W14: =IF(B14="","",IF(NOT(I14),"INVALID_MASTER",IF(NOT(K14),"INCOMPLETE_SHELF_CYCLE",IF(N14<MinHistory,"INSUFFICIENT_HISTORY",IF(NOT(J14),"INSUFFICIENT_IN_STOCK",IF(OR(Q14="",Q14=0),"NO_PRIOR_BASE",IF(Q14<LowBaseThreshold,"LOW_BASE_NOISE",IF(V14="Markdown Review","MARKDOWN_PEER_GAP",IF(V14="Reorder Candidate","REORDER_UPLIFT_COVER","NO_MATERIAL_CHANGE")))))))) | X14: =IF(V14="Markdown Review","Markdown support",IF(V14="Reorder Candidate","Second reorder",IF(V14="Monitor","Monitor",IF(V14="Noise","Hold / collect data",IF(V14="Not Ready","Not ready",""))))) | Y14: =IF(OR(R14="",T14=""),"",ABS(R14)+ABS(T14)) | Z14: =IF(OR(B14="",NOT(O14),R14=""),"",IF(ABS(R14)>=MaterialThreshold,"Yes","No")) | AA14: =IF(Z14<>"Yes","",IF(ABS(R14)>=MaterialThreshold,IF(ABS(R14)>=BroadShare,"Broad SKU movement","Store-concentrated movement"),"")) | AB14: =IF(O14,IF(COUNTIFS($O$5:O14,TRUE)>0,COUNTIFS($O$5:O14,TRUE),0),0) | AC14: =IF(V14="Markdown Review",1,IF(V14="Reorder Candidate",2,IF(V14="Monitor",3,IF(V14="Noise",4,IF(V14="Not Ready",5,99))))) | AD14: =IF(O14,COUNTIFS($O$5:$O$504,TRUE,$AC$5:$AC$504,"<"&AC14)+COUNTIFS($O$5:O14,TRUE,$AC$5:AC14,AC14,$Y$5:Y14,">"&Y14),0)
A15: =IF(COUNTA('Weekly Input'!A15:C15)=0,"",'Weekly Input'!B15&"|"&'Weekly Input'!C15&"|"&TEXT('Weekly Input'!A15,"yyyy-mm-dd")) | B15: ='Weekly Input'!B15 | C15: ='Weekly Input'!C15 | D15: =IF(B15="","",IFERROR(INDEX('Master Data'!$B$6:$B$145,MATCH(B15,'Master Data'!$A$6:$A$145,0)),"")) | E15: =IF(C15="","",IFERROR(INDEX('Master Data'!$H$6:$H$13,MATCH(C15,'Master Data'!$F$6:$F$13,0)),"")) | F15: ='Weekly Input'!A15 | G15: =IF(B15="","",IFERROR(INDEX('Master Data'!$D$6:$D$145,MATCH(B15,'Master Data'!$A$6:$A$145,0)),"")) | H15: =IF(OR(F15="",G15=""),"",F15-G15) | I15: =IF(B15="","",IF('Weekly Input'!J15="OK",TRUE,FALSE)) | J15: =IF(B15="","",'Weekly Input'!H15>=MinInStockDays) | K15: =IF(B15="","",H15>=FullCycleMin) | L15: =IF(B15="","",AND(I15,J15,K15,N15>=MinHistory)) | M15: =IF(OR(B15="",'Weekly Input'!H15=0),"",'Weekly Input'!D15/'Weekly Input'!H15*7) | N15: =IF(B15="","",COUNTIFS($B$5:$B$504,B15,$C$5:$C$504,C15,$I$5:$I$504,TRUE,$J$5:$J$504,TRUE,$K$5:$K$504,TRUE)) | O15: =IF(B15="","",AND(F15=AsOfWeek,AsOfWeek<>"")) | P15: =IF(OR(B15="",AsOfWeek=""),"",IFERROR(SUMIFS($M$5:$M$504,$B$5:$B$504,B15,$C$5:$C$504,C15,$L$5:$L$504,TRUE,$F$5:$F$504,">="&AsOfWeek-7*(RecentWeeks-1),$F$5:$F$504,"<="&AsOfWeek),"")) | Q15: =IF(OR(B15="",AsOfWeek=""),"",IFERROR(SUMIFS($M$5:$M$504,$B$5:$B$504,B15,$C$5:$C$504,C15,$L$5:$L$504,TRUE,$F$5:$F$504,">="&AsOfWeek-7*(RecentWeeks+PriorWeeks-1),$F$5:$F$504,"<"&AsOfWeek-7*(RecentWeeks-1)),"")) | R15: =IF(OR(P15="",Q15="",Q15=0),"",P15/Q15-1) | S15: =IF(OR(C15="",AsOfWeek=""),"",IFERROR(AVERAGEIFS($M$5:$M$504,$C$5:$C$504,C15,$L$5:$L$504,TRUE,$F$5:$F$504,">="&AsOfWeek-7*(RecentWeeks-1),$F$5:$F$504,"<="&AsOfWeek),"")) | T15: =IF(OR(P15="",S15=""),"",P15/S15-1) | U15: =IF(OR(B15="",'Weekly Input'!G15="",P15="",P15=0),"",'Weekly Input'!G15/P15) | V15: =IF(B15="","",IF(NOT(I15),"Not Ready",IF(NOT(K15),"Not Ready",IF(N15<MinHistory,"Not Ready",IF(NOT(J15),"Not Ready",IF(OR(Q15="",Q15=0),"Noise",IF(Q15<LowBaseThreshold,"Noise",IF(AND(R15<=-OwnDecline,T15<=-PeerGapThreshold),"Markdown Review",IF(AND(R15>=ReorderUplift,U15<>"",U15<=WeeksSupplyCap),"Reorder Candidate","Monitor")))))))) | W15: =IF(B15="","",IF(NOT(I15),"INVALID_MASTER",IF(NOT(K15),"INCOMPLETE_SHELF_CYCLE",IF(N15<MinHistory,"INSUFFICIENT_HISTORY",IF(NOT(J15),"INSUFFICIENT_IN_STOCK",IF(OR(Q15="",Q15=0),"NO_PRIOR_BASE",IF(Q15<LowBaseThreshold,"LOW_BASE_NOISE",IF(V15="Markdown Review","MARKDOWN_PEER_GAP",IF(V15="Reorder Candidate","REORDER_UPLIFT_COVER","NO_MATERIAL_CHANGE")))))))) | X15: =IF(V15="Markdown Review","Markdown support",IF(V15="Reorder Candidate","Second reorder",IF(V15="Monitor","Monitor",IF(V15="Noise","Hold / collect data",IF(V15="Not Ready","Not ready",""))))) | Y15: =IF(OR(R15="",T15=""),"",ABS(R15)+ABS(T15)) | Z15: =IF(OR(B15="",NOT(O15),R15=""),"",IF(ABS(R15)>=MaterialThreshold,"Yes","No")) | AA15: =IF(Z15<>"Yes","",IF(ABS(R15)>=MaterialThreshold,IF(ABS(R15)>=BroadShare,"Broad SKU movement","Store-concentrated movement"),"")) | AB15: =IF(O15,IF(COUNTIFS($O$5:O15,TRUE)>0,COUNTIFS($O$5:O15,TRUE),0),0) | AC15: =IF(V15="Markdown Review",1,IF(V15="Reorder Candidate",2,IF(V15="Monitor",3,IF(V15="Noise",4,IF(V15="Not Ready",5,99))))) | AD15: =IF(O15,COUNTIFS($O$5:$O$504,TRUE,$AC$5:$AC$504,"<"&AC15)+COUNTIFS($O$5:O15,TRUE,$AC$5:AC15,AC15,$Y$5:Y15,">"&Y15),0)
A16: =IF(COUNTA('Weekly Input'!A16:C16)=0,"",'Weekly Input'!B16&"|"&'Weekly Input'!C16&"|"&TEXT('Weekly Input'!A16,"yyyy-mm-dd")) | B16: ='Weekly Input'!B16 | C16: ='Weekly Input'!C16 | D16: =IF(B16="","",IFERROR(INDEX('Master Data'!$B$6:$B$145,MATCH(B16,'Master Data'!$A$6:$A$145,0)),"")) | E16: =IF(C16="","",IFERROR(INDEX('Master Data'!$H$6:$H$13,MATCH(C16,'Master Data'!$F$6:$F$13,0)),"")) | F16: ='Weekly Input'!A16 | G16: =IF(B16="","",IFERROR(INDEX('Master Data'!$D$6:$D$145,MATCH(B16,'Master Data'!$A$6:$A$145,0)),"")) | H16: =IF(OR(F16="",G16=""),"",F16-G16) | I16: =IF(B16="","",IF('Weekly Input'!J16="OK",TRUE,FALSE)) | J16: =IF(B16="","",'Weekly Input'!H16>=MinInStockDays) | K16: =IF(B16="","",H16>=FullCycleMin) | L16: =IF(B16="","",AND(I16,J16,K16,N16>=MinHistory)) | M16: =IF(OR(B16="",'Weekly Input'!H16=0),"",'Weekly Input'!D16/'Weekly Input'!H16*7) | N16: =IF(B16="","",COUNTIFS($B$5:$B$504,B16,$C$5:$C$504,C16,$I$5:$I$504,TRUE,$J$5:$J$504,TRUE,$K$5:$K$504,TRUE)) | O16: =IF(B16="","",AND(F16=AsOfWeek,AsOfWeek<>"")) | P16: =IF(OR(B16="",AsOfWeek=""),"",IFERROR(SUMIFS($M$5:$M$504,$B$5:$B$504,B16,$C$5:$C$504,C16,$L$5:$L$504,TRUE,$F$5:$F$504,">="&AsOfWeek-7*(RecentWeeks-1),$F$5:$F$504,"<="&AsOfWeek),"")) | Q16: =IF(OR(B16="",AsOfWeek=""),"",IFERROR(SUMIFS($M$5:$M$504,$B$5:$B$504,B16,$C$5:$C$504,C16,$L$5:$L$504,TRUE,$F$5:$F$504,">="&AsOfWeek-7*(RecentWeeks+PriorWeeks-1),$F$5:$F$504,"<"&AsOfWeek-7*(RecentWeeks-1)),"")) | R16: =IF(OR(P16="",Q16="",Q16=0),"",P16/Q16-1) | S16: =IF(OR(C16="",AsOfWeek=""),"",IFERROR(AVERAGEIFS($M$5:$M$504,$C$5:$C$504,C16,$L$5:$L$504,TRUE,$F$5:$F$504,">="&AsOfWeek-7*(RecentWeeks-1),$F$5:$F$504,"<="&AsOfWeek),"")) | T16: =IF(OR(P16="",S16=""),"",P16/S16-1) | U16: =IF(OR(B16="",'Weekly Input'!G16="",P16="",P16=0),"",'Weekly Input'!G16/P16) | V16: =IF(B16="","",IF(NOT(I16),"Not Ready",IF(NOT(K16),"Not Ready",IF(N16<MinHistory,"Not Ready",IF(NOT(J16),"Not Ready",IF(OR(Q16="",Q16=0),"Noise",IF(Q16<LowBaseThreshold,"Noise",IF(AND(R16<=-OwnDecline,T16<=-PeerGapThreshold),"Markdown Review",IF(AND(R16>=ReorderUplift,U16<>"",U16<=WeeksSupplyCap),"Reorder Candidate","Monitor")))))))) | W16: =IF(B16="","",IF(NOT(I16),"INVALID_MASTER",IF(NOT(K16),"INCOMPLETE_SHELF_CYCLE",IF(N16<MinHistory,"INSUFFICIENT_HISTORY",IF(NOT(J16),"INSUFFICIENT_IN_STOCK",IF(OR(Q16="",Q16=0),"NO_PRIOR_BASE",IF(Q16<LowBaseThreshold,"LOW_BASE_NOISE",IF(V16="Markdown Review","MARKDOWN_PEER_GAP",IF(V16="Reorder Candidate","REORDER_UPLIFT_COVER","NO_MATERIAL_CHANGE")))))))) | X16: =IF(V16="Markdown Review","Markdown support",IF(V16="Reorder Candidate","Second reorder",IF(V16="Monitor","Monitor",IF(V16="Noise","Hold / collect data",IF(V16="Not Ready","Not ready",""))))) | Y16: =IF(OR(R16="",T16=""),"",ABS(R16)+ABS(T16)) | Z16: =IF(OR(B16="",NOT(O16),R16=""),"",IF(ABS(R16)>=MaterialThreshold,"Yes","No")) | AA16: =IF(Z16<>"Yes","",IF(ABS(R16)>=MaterialThreshold,IF(ABS(R16)>=BroadShare,"Broad SKU movement","Store-concentrated movement"),"")) | AB16: =IF(O16,IF(COUNTIFS($O$5:O16,TRUE)>0,COUNTIFS($O$5:O16,TRUE),0),0) | AC16: =IF(V16="Markdown Review",1,IF(V16="Reorder Candidate",2,IF(V16="Monitor",3,IF(V16="Noise",4,IF(V16="Not Ready",5,99))))) | AD16: =IF(O16,COUNTIFS($O$5:$O$504,TRUE,$AC$5:$AC$504,"<"&AC16)+COUNTIFS($O$5:O16,TRUE,$AC$5:AC16,AC16,$Y$5:Y16,">"&Y16),0)
... A504: =IF(COUNTA('Weekly Input'!A504:C504)=0,"",'Weekly Input'!B504&"|"&'Weekly Input'!C504&"|"&TEXT('Weekly Input'!A504,"yyyy-mm-dd")) | B504: ='Weekly Input'!B504 | C504: ='Weekly Input'!C504 | D504: =IF(B504="","",IFERROR(INDEX('Master Data'!$B$6:$B$145,MATCH(B504,'Master Data'!$A$6:$A$145,0)),"")) | E504: =IF(C504="","",IFERROR(INDEX('Master Data'!$H$6:$H$13,MATCH(C504,'Master Data'!$F$6:$F$13,0)),"")) | F504: ='Weekly Input'!A504 | G504: =IF(B504="","",IFERROR(INDEX('Master Data'!$D$6:$D$145,MATCH(B504,'Master Data'!$A$6:$A$145,0)),"")) | H504: =IF(OR(F504="",G504=""),"",F504-G504) | I504: =IF(B504="","",IF('Weekly Input'!J504="OK",TRUE,FALSE)) | J504: =IF(B504="","",'Weekly Input'!H504>=MinInStockDays) | K504: =IF(B504="","",H504>=FullCycleMin) | L504: =IF(B504="","",AND(I504,J504,K504,N504>=MinHistory)) | M504: =IF(OR(B504="",'Weekly Input'!H504=0),"",'Weekly Input'!D504/'Weekly Input'!H504*7) | N504: =IF(B504="","",COUNTIFS($B$5:$B$504,B504,$C$5:$C$504,C504,$I$5:$I$504,TRUE,$J$5:$J$504,TRUE,$K$5:$K$504,TRUE)) | O504: =IF(B504="","",AND(F504=AsOfWeek,AsOfWeek<>"")) | P504: =IF(OR(B504="",AsOfWeek=""),"",IFERROR(SUMIFS($M$5:$M$504,$B$5:$B$504,B504,$C$5:$C$504,C504,$L$5:$L$504,TRUE,$F$5:$F$504,">="&AsOfWeek-7*(RecentWeeks-1),$F$5:$F$504,"<="&AsOfWeek),"")) | Q504: =IF(OR(B504="",AsOfWeek=""),"",IFERROR(SUMIFS($M$5:$M$504,$B$5:$B$504,B504,$C$5:$C$504,C504,$L$5:$L$504,TRUE,$F$5:$F$504,">="&AsOfWeek-7*(RecentWeeks+PriorWeeks-1),$F$5:$F$504,"<"&AsOfWeek-7*(RecentWeeks-1)),"")) | R504: =IF(OR(P504="",Q504="",Q504=0),"",P504/Q504-1) | S504: =IF(OR(C504="",AsOfWeek=""),"",IFERROR(AVERAGEIFS($M$5:$M$504,$C$5:$C$504,C504,$L$5:$L$504,TRUE,$F$5:$F$504,">="&AsOfWeek-7*(RecentWeeks-1),$F$5:$F$504,"<="&AsOfWeek),"")) | T504: =IF(OR(P504="",S504=""),"",P504/S504-1) | U504: =IF(OR(B504="",'Weekly Input'!G504="",P504="",P504=0),"",'Weekly Input'!G504/P504) | V504: =IF(B504="","",IF(NOT(I504),"Not Ready",IF(NOT(K504),"Not Ready",IF(N504<MinHistory,"Not Ready",IF(NOT(J504),"Not Ready",IF(OR(Q504="",Q504=0),"Noise",IF(Q504<LowBaseThreshold,"Noise",IF(AND(R504<=-OwnDecline,T504<=-PeerGapThreshold),"Markdown Review",IF(AND(R504>=ReorderUplift,U504<>"",U504<=WeeksSupplyCap),"Reorder Candidate","Monitor")))))))) | W504: =IF(B504="","",IF(NOT(I504),"INVALID_MASTER",IF(NOT(K504),"INCOMPLETE_SHELF_CYCLE",IF(N504<MinHistory,"INSUFFICIENT_HISTORY",IF(NOT(J504),"INSUFFICIENT_IN_STOCK",IF(OR(Q504="",Q504=0),"NO_PRIOR_BASE",IF(Q504<LowBaseThreshold,"LOW_BASE_NOISE",IF(V504="Markdown Review","MARKDOWN_PEER_GAP",IF(V504="Reorder Candidate","REORDER_UPLIFT_COVER","NO_MATERIAL_CHANGE")))))))) | X504: =IF(V504="Markdown Review","Markdown support",IF(V504="Reorder Candidate","Second reorder",IF(V504="Monitor","Monitor",IF(V504="Noise","Hold / collect data",IF(V504="Not Ready","Not ready",""))))) | Y504: =IF(OR(R504="",T504=""),"",ABS(R504)+ABS(T504)) | Z504: =IF(OR(B504="",NOT(O504),R504=""),"",IF(ABS(R504)>=MaterialThreshold,"Yes","No")) | AA504: =IF(Z504<>"Yes","",IF(ABS(R504)>=MaterialThreshold,IF(ABS(R504)>=BroadShare,"Broad SKU movement","Store-concentrated movement"),"")) | AB504: =IF(O504,IF(COUNTIFS($O$5:O504,TRUE)>0,COUNTIFS($O$5:O504,TRUE),0),0) | AC504: =IF(V504="Markdown Review",1,IF(V504="Reorder Candidate",2,IF(V504="Monitor",3,IF(V504="Noise",4,IF(V504="Not Ready",5,99))))) | AD504: =IF(O504,COUNTIFS($O$5:$O$504,TRUE,$AC$5:$AC$504,"<"&AC504)+COUNTIFS($O$5:O504,TRUE,$AC$5:AC504,AC504,$Y$5:Y504,">"&Y504),0)

Sheet Exceptions
A1: Exceptions
A2: Formula-driven current register; one row per latest-week SKU-store combination. Human review fields are blank.
A4: Store ID | B4: SKU | C4: Store Name | D4: Category | E4: Week Ending | F4: Shelf-Set Date | G4: Shelf-Cycle Age (days) | H4: Eligible | I4: Recent Velocity | J4: Prior Velocity | K4: Own Change | L4: SKU Peer Velocity | M4: Peer Gap | N4: Inventory Cover (weeks) | O4: Outcome | P4: Reason Code | Q4: Action | R4: Severity | S4: Material Change | T4: Driver | U4: Review Notes | V4: Disposition Comment | W4: Sign-off
A5: =IFERROR(INDEX(Model!$B$5:$B$504,MATCH(ROWS($A$5:A5),Model!$AD$5:$AD$504,0)),"") | B5: =IF(A5="","",INDEX(Model!$C$5:$C$504,MATCH(ROWS($A$5:A5),Model!$AD$5:$AD$504,0))) | C5: =IF(A5="","",INDEX(Model!$D$5:$D$504,MATCH(ROWS($A$5:A5),Model!$AD$5:$AD$504,0))) | D5: =IF(A5="","",INDEX(Model!$E$5:$E$504,MATCH(ROWS($A$5:A5),Model!$AD$5:$AD$504,0))) | E5: =IF(A5="","",INDEX(Model!$F$5:$F$504,MATCH(ROWS($A$5:A5),Model!$AD$5:$AD$504,0))) | F5: =IF(A5="","",INDEX(Model!$G$5:$G$504,MATCH(ROWS($A$5:A5),Model!$AD$5:$AD$504,0))) | G5: =IF(A5="","",INDEX(Model!$H$5:$H$504,MATCH(ROWS($A$5:A5),Model!$AD$5:$AD$504,0))) | H5: =IF(A5="","",INDEX(Model!$L$5:$L$504,MATCH(ROWS($A$5:A5),Model!$AD$5:$AD$504,0))) | I5: =IF(A5="","",INDEX(Model!$P$5:$P$504,MATCH(ROWS($A$5:A5),Model!$AD$5:$AD$504,0))) | J5: =IF(A5="","",INDEX(Model!$Q$5:$Q$504,MATCH(ROWS($A$5:A5),Model!$AD$5:$AD$504,0))) | K5: =IF(A5="","",INDEX(Model!$R$5:$R$504,MATCH(ROWS($A$5:A5),Model!$AD$5:$AD$504,0))) | L5: =IF(A5="","",INDEX(Model!$S$5:$S$504,MATCH(ROWS($A$5:A5),Model!$AD$5:$AD$504,0))) | M5: =IF(A5="","",INDEX(Model!$T$5:$T$504,MATCH(ROWS($A$5:A5),Model!$AD$5:$AD$504,0))) | N5: =IF(A5="","",INDEX(Model!$U$5:$U$504,MATCH(ROWS($A$5:A5),Model!$AD$5:$AD$504,0))) | O5: =IF(A5="","",INDEX(Model!$V$5:$V$504,MATCH(ROWS($A$5:A5),Model!$AD$5:$AD$504,0))) | P5: =IF(A5="","",INDEX(Model!$W$5:$W$504,MATCH(ROWS($A$5:A5),Model!$AD$5:$AD$504,0))) | Q5: =IF(A5="","",INDEX(Model!$X$5:$X$504,MATCH(ROWS($A$5:A5),Model!$AD$5:$AD$504,0))) | R5: =IF(A5="","",INDEX(Model!$Y$5:$Y$504,MATCH(ROWS($A$5:A5),Model!$AD$5:$AD$504,0))) | S5: =IF(A5="","",INDEX(Model!$Z$5:$Z$504,MATCH(ROWS($A$5:A5),Model!$AD$5:$AD$504,0))) | T5: =IF(A5="","",INDEX(Model!$AA$5:$AA$504,MATCH(ROWS($A$5:A5),Model!$AD$5:$AD$504,0)))
