Workbook

Sheet Start Here
A1: Cross-Store Inspection Model
A2: April-May 2026 | Oregon rules current as of 15 January 2026
A4: How to use
A5: 1. Change yellow cells only: Late Oregon swaps here, then inspector and planned date decisions on Assignments.
A6: 2. Green cells calculate. A red FAIL is a mandatory issue; N/A means the Oregon-only rule does not apply to Washington.
A7: 3. Compare options below. Recommendation selects the lowest-cost feasible option; ties choose the first listed option.
A8: 4. Final Roster refreshes from the live recommendation and prints as one monthly posting page per month.
A10: Legend
A11: Yellow = editable decision or assumption | C11: Green = formula result | E11: Red = failed mandatory check
A13: Scenario controls
A14: Late Oregon swaps | B14: 2 | C14: Whole number 0+; ordinary planning band is 0-5. Higher test values are accepted.
A16: Option comparison
A17: Option | B17: Projected total | C17: Failed checks | D17: Coverage | E17: Feasible? | F17: Travel miles | G17: Decision
A18: Option 1 | Lean route | B18: =SUM(Assignments!$AA$5:$AA$22)+$B$14*'Source Data'!$G$95 -> 8479.968 | C18: =SUM(Assignments!$AB$5:$AB$22) -> 1 | D18: =IF(COUNTIFS(Assignments!$A$5:$A$22,A18,Assignments!$B$5:$B$22,"April")=9,IF(COUNTIFS(Assignments!$A$5:$A$22,A18,Assignments!$B$5:$B$22,"May")=9,"Complete","INCOMPLETE"),"INCOMPLETE") -> Complete | E18: =IF(AND(C18=0,D18="Complete"),"FEASIBLE","INFEASIBLE") -> INFEASIBLE | F18: =SUM(Assignments!$N$5:$N$22) -> 2410.4 | G18: =IF(E18="FEASIBLE","Eligible","Excluded") -> Excluded
A19: Option 2 | Compliant balance | B19: =SUM(Assignments!$AA$23:$AA$40)+$B$14*'Source Data'!$G$95 -> 9053.56 | C19: =SUM(Assignments!$AB$23:$AB$40) -> 0 | D19: =IF(COUNTIFS(Assignments!$A$23:$A$40,A19,Assignments!$B$23:$B$40,"April")=9,IF(COUNTIFS(Assignments!$A$23:$A$40,A19,Assignments!$B$23:$B$40,"May")=9,"Complete","INCOMPLETE"),"INCOMPLETE") -> Complete | E19: =IF(AND(C19=0,D19="Complete"),"FEASIBLE","INFEASIBLE") -> FEASIBLE | F19: =SUM(Assignments!$N$23:$N$40) -> 2668 | G19: =IF(E19="FEASIBLE","Eligible","Excluded") -> Eligible
A20: Option 3 | Long-haul cover | B20: =SUM(Assignments!$AA$41:$AA$58)+$B$14*'Source Data'!$G$95 -> 10259.416 | C20: =SUM(Assignments!$AB$41:$AB$58) -> 0 | D20: =IF(COUNTIFS(Assignments!$A$41:$A$58,A20,Assignments!$B$41:$B$58,"April")=9,IF(COUNTIFS(Assignments!$A$41:$A$58,A20,Assignments!$B$41:$B$58,"May")=9,"Complete","INCOMPLETE"),"INCOMPLETE") -> Complete | E20: =IF(AND(C20=0,D20="Complete"),"FEASIBLE","INFEASIBLE") -> FEASIBLE | F20: =SUM(Assignments!$N$41:$N$58) -> 3164.8 | G20: =IF(E20="FEASIBLE","Eligible","Excluded") -> Eligible
A22: Recommended option | B22: =IF(AND(E18="FEASIBLE",OR(E19<>"FEASIBLE",B18<=B19),OR(E20<>"FEASIBLE",B18<=B20)),A18,IF(AND(E19="FEASIBLE",OR(E20<>"FEASIBLE",B19<=B20)),A19,IF(E20="FEASIBLE",A20,"No feasible option"))) -> Option 2 | Compliant balance
A24: Recommendation rationale
A25: =IF(LEFT($B$22,8)="Option 2","Option 2 is recommended: it is feasible, avoids the rest failure in the lean route, and costs "&TEXT(B19,"$#,##0.00")&" versus "&TEXT(B20,"$#,##0.00")&" for the longer-haul feasible cover plan. Option 1 is excluded despite its lower cost because it has "&C18&" failed mandatory check(s).","Review the live comparison: no eligible option is available.") -> Option 2 is recommended: it is feasible, avoids the rest failure in the lean route, and costs $9,053.56 versus $10,259.42 for the longer-haul feasible cover plan. Option 1 is excluded despite its lower cost because it has 1 failed mandatory check(s).
A29: Model rule and cost guide
A30: Self-store | B30: FAIL when the supervisor home store equals the inspected store.
A31: Certified | B31: PASS only when sourced certification is Active and the planned date is within effective/expiry dates.
A32: Availability | B32: PASS only when the full travel-inclusive work period fits the sourced available period.
A33: Window | B33: PASS only when planned date is within that store-month opening and closing date, inclusive.
A34: Rest | B34: Oregon only: both adjacent gaps must be at least 10.00 hours. Washington = N/A. A short gap creates shortfall-hours x regular-rate premium.
A35: Posting | B35: Oregon only: plan finalization must be on/before the month deadline. Washington = N/A.
A36: Cost | B36: Labor = work-period hours x sourced rate. Travel = sourced reimbursable miles x $/mile. Rest premium and option-level late Oregon swaps follow the Oregon brief.
A37: Feasibility | B37: Complete April and May coverage plus zero failed mandatory row checks. The final roster returns one record per store-month from the lowest-cost feasible option.
A40: Sources
A41: goldfinch_inspection_inputs.xlsx | imported on Source Data
A42: oregon_schedule_brief.pdf | Gildenhall Alliance; Oregon rules current as of 15 January 2026

Sheet Source Data
A1: Imported source data | goldfinch_inspection_inputs.xlsx
A2: Rules cross-checked to oregon_schedule_brief.pdf (current as of 15 January 2026)
A4: Store ID | B4: Store | C4: State | D4: Team | F4: Supervisor | G4: Home store | H4: Status | I4: Effective | J4: Expiry | K4: Rate
A5: OR-ROS | B5: Roseburg Farm & Field | C5: OR | D5: 72 | F5: Avery Lane | G5: OR-ROS | H5: Active | I5: 45658 | J5: 46387 | K5: 32
A6: OR-SAL | B6: Salem Ag Supply | C6: OR | D6: 84 | F6: Bianca Chen | G6: OR-SAL | H6: Active | I6: 45717 | J6: 46356 | K6: 34
A7: OR-BEN | B7: Bend Tractor & Turf | C7: OR | D7: 68 | F7: Darnell Fox | G7: OR-BEN | H7: Active | I7: 45809 | J7: 46326 | K7: 31
A8: OR-ONT | B8: Ontario Equipment Depot | C8: OR | D8: 51 | F8: Elena Ruiz | G8: OR-ONT | H8: Active | I8: 45689 | J8: 46387 | K8: 35
A9: OR-MED | B9: Medford Farm Center | C9: OR | D9: 76 | F9: Malik Brooks | G9: WA-YAK | H9: Active | I9: 45658 | J9: 46418 | K9: 33
A10: OR-PEN | B10: Pendleton Ranch Supply | C10: OR | D10: 49
A11: WA-YAK | B11: Yakima Orchard & Field | C11: WA | D11: 63
A12: WA-VAN | B12: Vancouver Farm Supply | C12: WA | D12: 57
A13: WA-WAL | B13: Walla Walla Tractor Co. | C13: WA | D13: 46
A16: Window Key | B16: Month | C16: Store ID | D16: Opens | E16: Closes | G16: Avail Key | H16: Supervisor | I16: Date | J16: Status | K16: From | L16: Through | M16: Prior ends | N16: Next begins | P16: Travel Key | Q16: Home | R16: Destination | S16: One-way hrs | T16: Miles
A17: April|OR-ROS | B17: April | C17: OR-ROS | D17: 46118 | E17: 46140 | G17: Avery Lane|2026-04-07 | H17: Avery Lane | I17: 46119 | J17: Available | K17: 46119.208 | L17: 46119.875 | M17: 46118.792 | N17: 46120.292 | P17: OR-ROS|OR-ROS | Q17: OR-ROS | R17: OR-ROS | S17: 0 | T17: 0
A18: April|OR-SAL | B18: April | C18: OR-SAL | D18: 46118 | E18: 46140 | G18: Avery Lane|2026-04-14 | H18: Avery Lane | I18: 46126 | J18: Available | K18: 46126.208 | L18: 46126.875 | M18: 46125.792 | N18: 46127.292 | P18: OR-ROS|OR-SAL | Q18: OR-ROS | R18: OR-SAL | S18: 0.66666667 | T18: 36.8
A19: April|OR-BEN | B19: April | C19: OR-BEN | D19: 46118 | E19: 46140 | G19: Avery Lane|2026-04-21 | H19: Avery Lane | I19: 46133 | J19: Available | K19: 46133.208 | L19: 46133.875 | M19: 46132.792 | N19: 46134.292 | P19: OR-ROS|OR-BEN | Q19: OR-ROS | R19: OR-BEN | S19: 2.6666667 | T19: 147.2
A20: April|OR-ONT | B20: April | C20: OR-ONT | D20: 46118 | E20: 46140 | G20: Avery Lane|2026-04-28 | H20: Avery Lane | I20: 46140 | J20: Available | K20: 46140.208 | L20: 46140.875 | M20: 46139.792 | N20: 46141.292 | P20: OR-ROS|OR-ONT | Q20: OR-ROS | R20: OR-ONT | S20: 3.5 | T20: 193.2
A21: April|OR-MED | B21: April | C21: OR-MED | D21: 46118 | E21: 46140 | G21: Avery Lane|2026-05-05 | H21: Avery Lane | I21: 46147 | J21: Available | K21: 46147.208 | L21: 46147.875 | M21: 46146.792 | N21: 46148.292 | P21: OR-ROS|OR-MED | Q21: OR-ROS | R21: OR-MED | S21: 4 | T21: 220.8
A22: April|OR-PEN | B22: April | C22: OR-PEN | D22: 46118 | E22: 46140 | G22: Avery Lane|2026-05-12 | H22: Avery Lane | I22: 46154 | J22: Available | K22: 46154.208 | L22: 46154.875 | M22: 46153.792 | N22: 46155.292 | P22: OR-ROS|OR-PEN | Q22: OR-ROS | R22: OR-PEN | S22: 5 | T22: 276
A23: April|WA-YAK | B23: April | C23: WA-YAK | D23: 46118 | E23: 46140 | G23: Avery Lane|2026-05-19 | H23: Avery Lane | I23: 46161 | J23: Available | K23: 46161.208 | L23: 46161.875 | M23: 46160.792 | N23: 46162.292 | P23: OR-ROS|WA-YAK | Q23: OR-ROS | R23: WA-YAK | S23: 3 | T23: 165.6
A24: April|WA-VAN | B24: April | C24: WA-VAN | D24: 46118 | E24: 46140 | G24: Avery Lane|2026-05-26 | H24: Avery Lane | I24: 46168 | J24: Available | K24: 46168.208 | L24: 46168.875 | M24: 46167.792 | N24: 46169.292 | P24: OR-ROS|WA-VAN | Q24: OR-ROS | R24: WA-VAN | S24: 3.3333333 | T24: 184
A25: April|WA-WAL | B25: April | C25: WA-WAL | D25: 46118 | E25: 46140 | G25: Bianca Chen|2026-04-07 | H25: Bianca Chen | I25: 46119 | J25: Available | K25: 46119.208 | L25: 46119.875 | M25: 46118.792 | N25: 46120.292 | P25: OR-ROS|WA-WAL | Q25: OR-ROS | R25: WA-WAL | S25: 4.3333333 | T25: 239.2
A26: May|OR-ROS | B26: May | C26: OR-ROS | D26: 46146 | E26: 46168 | G26: Bianca Chen|2026-04-14 | H26: Bianca Chen | I26: 46126 | J26: Available | K26: 46126.208 | L26: 46126.875 | M26: 46125.792 | N26: 46127.292 | P26: OR-SAL|OR-ROS | Q26: OR-SAL | R26: OR-ROS | S26: 0.66666667 | T26: 36.8
A27: May|OR-SAL | B27: May | C27: OR-SAL | D27: 46146 | E27: 46168 | G27: Bianca Chen|2026-04-21 | H27: Bianca Chen | I27: 46133 | J27: Available | K27: 46133.208 | L27: 46133.875 | M27: 46132.792 | N27: 46134.292 | P27: OR-SAL|OR-SAL | Q27: OR-SAL | R27: OR-SAL | S27: 0 | T27: 0
A28: May|OR-BEN | B28: May | C28: OR-BEN | D28: 46146 | E28: 46168 | G28: Bianca Chen|2026-04-28 | H28: Bianca Chen | I28: 46140 | J28: Available | K28: 46140.208 | L28: 46140.875 | M28: 46139.792 | N28: 46141.292 | P28: OR-SAL|OR-BEN | Q28: OR-SAL | R28: OR-BEN | S28: 2.1666667 | T28: 119.6
... A34: May|WA-WAL | B34: May | C34: WA-WAL | D34: 46146 | E34: 46168 | G34: Darnell Fox|2026-04-14 | H34: Darnell Fox | I34: 46126 | J34: Available | K34: 46126.208 | L34: 46126.875 | M34: 46125.917 | N34: 46127.292 | P34: OR-SAL|WA-WAL | Q34: OR-SAL | R34: WA-WAL | S34: 4.1666667 | T34: 230
G35: Darnell Fox|2026-04-21 | H35: Darnell Fox | I35: 46133 | J35: Available | K35: 46133.208 | L35: 46133.875 | M35: 46132.792 | N35: 46134.292 | P35: OR-BEN|OR-ROS | Q35: OR-BEN | R35: OR-ROS | S35: 2.6666667 | T35: 147.2
G36: Darnell Fox|2026-04-28 | H36: Darnell Fox | I36: 46140 | J36: Available | K36: 46140.208 | L36: 46140.875 | M36: 46139.792 | N36: 46141.292 | P36: OR-BEN|OR-SAL | Q36: OR-BEN | R36: OR-SAL | S36: 2.1666667 | T36: 119.6
G37: Darnell Fox|2026-05-05 | H37: Darnell Fox | I37: 46147 | J37: Available | K37: 46147.208 | L37: 46147.875 | M37: 46146.792 | N37: 46148.292 | P37: OR-BEN|OR-BEN | Q37: OR-BEN | R37: OR-BEN | S37: 0 | T37: 0
G38: Darnell Fox|2026-05-12 | H38: Darnell Fox | I38: 46154 | J38: Available | K38: 46154.208 | L38: 46154.875 | M38: 46153.792 | N38: 46155.292 | P38: OR-BEN|OR-ONT | Q38: OR-BEN | R38: OR-ONT | S38: 3 | T38: 165.6
G39: Darnell Fox|2026-05-19 | H39: Darnell Fox | I39: 46161 | J39: Available | K39: 46161.208 | L39: 46161.875 | M39: 46160.792 | N39: 46162.292 | P39: OR-BEN|OR-MED | Q39: OR-BEN | R39: OR-MED | S39: 3.5 | T39: 193.2
G40: Darnell Fox|2026-05-26 | H40: Darnell Fox | I40: 46168 | J40: Available | K40: 46168.208 | L40: 46168.875 | M40: 46167.792 | N40: 46169.292 | P40: OR-BEN|OR-PEN | Q40: OR-BEN | R40: OR-PEN | S40: 3.25 | T40: 179.4
G41: Elena Ruiz|2026-04-07 | H41: Elena Ruiz | I41: 46119 | J41: Available | K41: 46119.208 | L41: 46119.875 | M41: 46118.792 | N41: 46120.292 | P41: OR-BEN|WA-YAK | Q41: OR-BEN | R41: WA-YAK | S41: 4.3333333 | T41: 239.2
G42: Elena Ruiz|2026-04-14 | H42: Elena Ruiz | I42: 46126 | J42: Available | K42: 46126.208 | L42: 46126.875 | M42: 46125.792 | N42: 46127.292 | P42: OR-BEN|WA-VAN | Q42: OR-BEN | R42: WA-VAN | S42: 4.75 | T42: 262.2
G43: Elena Ruiz|2026-04-21 | H43: Elena Ruiz | I43: 46133 | J43: Available | K43: 46133.208 | L43: 46133.875 | M43: 46132.792 | N43: 46134.292 | P43: OR-BEN|WA-WAL | Q43: OR-BEN | R43: WA-WAL | S43: 4.5833333 | T43: 253
G44: Elena Ruiz|2026-04-28 | H44: Elena Ruiz | I44: 46140 | J44: Available | K44: 46140.208 | L44: 46140.875 | M44: 46139.792 | N44: 46141.292 | P44: OR-ONT|OR-ROS | Q44: OR-ONT | R44: OR-ROS | S44: 3.5 | T44: 193.2
G45: Elena Ruiz|2026-05-05 | H45: Elena Ruiz | I45: 46147 | J45: Available | K45: 46147.208 | L45: 46147.875 | M45: 46146.792 | N45: 46148.292 | P45: OR-ONT|OR-SAL | Q45: OR-ONT | R45: OR-SAL | S45: 3 | T45: 165.6
G46: Elena Ruiz|2026-05-12 | H46: Elena Ruiz | I46: 46154 | J46: Available | K46: 46154.208 | L46: 46154.875 | M46: 46153.792 | N46: 46155.292 | P46: OR-ONT|OR-BEN | Q46: OR-ONT | R46: OR-BEN | S46: 3 | T46: 165.6
... G56: Malik Brooks|2026-05-26 | H56: Malik Brooks | I56: 46168 | J56: Available | K56: 46168.208 | L56: 46168.875 | M56: 46167.792 | N56: 46169.292 | P56: WA-YAK|OR-ONT | Q56: WA-YAK | R56: OR-ONT | S56: 5.1666667 | T56: 285.2
P57: WA-YAK|OR-MED | Q57: WA-YAK | R57: OR-MED | S57: 5 | T57: 276
...

Sheet Assignments
A1: Candidate assignment decisions and live checks
A2: Edit yellow inspector/date cells. All green/white results are locked formulas; failed mandatory tests flag red.
A4: Option | B4: Month | C4: Store ID | D4: Store | E4: State | F4: Window opens | G4: Window closes | H4: Inspector | I4: Planned date | J4: Home store | K4: Cert status | L4: Cert expiry | M4: One-way hrs | N4: Miles | O4: Work begins | P4: Work ends | Q4: Availability | R4: Window | S4: Self-store | T4: Certified | U4: Rest | V4: Posting | W4: Labor | X4: Travel | Y4: Rest premium | Z4: Late change | AA4: Projected total | AB4: Failed checks | AC4: Row feasible | AD4: Record key
A5: Option 1 | Lean route | B5: April | C5: OR-ROS | D5: =VLOOKUP($C5,'Source Data'!$A$5:$D$13,2,FALSE()) -> Roseburg Farm & Field | E5: =VLOOKUP($C5,'Source Data'!$A$5:$D$13,3,FALSE()) -> OR | F5: =VLOOKUP($B5&"|"&$C5,'Source Data'!$A$17:$E$34,4,FALSE()) -> 46118 | G5: =VLOOKUP($B5&"|"&$C5,'Source Data'!$A$17:$E$34,5,FALSE()) -> 46140 | H5: Bianca Chen | I5: 46119 | J5: =VLOOKUP($H5,'Source Data'!$F$5:$K$9,2,FALSE()) -> OR-SAL | K5: =VLOOKUP($H5,'Source Data'!$F$5:$K$9,3,FALSE()) -> Active | L5: =VLOOKUP($H5,'Source Data'!$F$5:$K$9,5,FALSE()) -> 46356 | M5: =VLOOKUP($J5&"|"&$C5,'Source Data'!$P$17:$T$61,4,FALSE()) -> 0.66666667 | N5: =VLOOKUP($J5&"|"&$C5,'Source Data'!$P$17:$T$61,5,FALSE()) -> 36.8 | O5: =$I5+TIME(9,0,0)-$M5/24 -> 46119.347 | P5: =$I5+TIME(9,0,0)+('Source Data'!$G$92+($M5*2))/24 -> 46119.597 | Q5: =IF(AND(VLOOKUP($H5&"|"&TEXT($I5,"yyyy-mm-dd"),'Source Data'!$G$17:$N$56,4,FALSE())="Available",$O5>=VLOOKUP($H5&"|"&TEXT($I5,"yyyy-mm-dd"),'Source Data'!$G$17:$N$56,5,FALSE()),$P5<=VLOOKUP($H5&"|"&TEXT($I5,"yyyy-mm-dd"),'Source Data'!$G$17:$N$56,6,FALSE())),"PASS","FAIL") -> PASS | R5: =IF(AND($I5>=$F5,$I5<=$G5),"PASS","FAIL") -> PASS | S5: =IF($J5=$C5,"FAIL","PASS") -> PASS | T5: =IF(AND($K5="Active",$I5>=VLOOKUP($H5,'Source Data'!$F$5:$K$9,4,FALSE()),$I5<=$L5),"PASS","FAIL") -> PASS | U5: =IF($E5<>"OR","N/A",IF(AND(($O5-VLOOKUP($H5&"|"&TEXT($I5,"yyyy-mm-dd"),'Source Data'!$G$17:$N$56,7,FALSE()))*24>='Source Data'!$G$94,(VLOOKUP($H5&"|"&TEXT($I5,"yyyy-mm-dd"),'Source Data'!$G$17:$N$56,8,FALSE())-$P5)*24>='Source Data'!$G$94),"PASS","FAIL")) -> PASS | V5: =IF($E5<>"OR","N/A",IF('Source Data'!$G$98<=IF($B5="April",'Source Data'!$G$96,'Source Data'!$G$97),"PASS","FAIL")) -> PASS | W5: =($P5-$O5)*24*VLOOKUP($H5,'Source Data'!$F$5:$K$9,6,FALSE()) -> 204 | X5: =$N5*'Source Data'!$G$93 -> 24.656 | Y5: =IF($U5="FAIL",MAX(0,'Source Data'!$G$94-MIN(($O5-VLOOKUP($H5&"|"&TEXT($I5,"yyyy-mm-dd"),'Source Data'!$G$17:$N$56,7,FALSE()))*24,(VLOOKUP($H5&"|"&TEXT($I5,"yyyy-mm-dd"),'Source Data'!$G$17:$N$56,8,FALSE())-$P5)*24))*VLOOKUP($H5,'Source Data'!$F$5:$K$9,6,FALSE()),0) -> 0 | Z5: =0 -> 0 | AA5: =SUM($W5:$Z5) -> 228.656 | AB5: =COUNTIF($Q5:$V5,"FAIL") -> 0 | AC5: =IF($AB5=0,"PASS","FAIL") -> PASS | AD5: =$A5&"|"&$B5&"|"&$C5 -> Option 1 | Lean route|April|OR-ROS
A6: Option 1 | Lean route | B6: April | C6: OR-SAL | D6: =VLOOKUP($C6,'Source Data'!$A$5:$D$13,2,FALSE()) -> Salem Ag Supply | E6: =VLOOKUP($C6,'Source Data'!$A$5:$D$13,3,FALSE()) -> OR | F6: =VLOOKUP($B6&"|"&$C6,'Source Data'!$A$17:$E$34,4,FALSE()) -> 46118 | G6: =VLOOKUP($B6&"|"&$C6,'Source Data'!$A$17:$E$34,5,FALSE()) -> 46140 | H6: Avery Lane | I6: 46133 | J6: =VLOOKUP($H6,'Source Data'!$F$5:$K$9,2,FALSE()) -> OR-ROS | K6: =VLOOKUP($H6,'Source Data'!$F$5:$K$9,3,FALSE()) -> Active | L6: =VLOOKUP($H6,'Source Data'!$F$5:$K$9,5,FALSE()) -> 46387 | M6: =VLOOKUP($J6&"|"&$C6,'Source Data'!$P$17:$T$61,4,FALSE()) -> 0.66666667 | N6: =VLOOKUP($J6&"|"&$C6,'Source Data'!$P$17:$T$61,5,FALSE()) -> 36.8 | O6: =$I6+TIME(9,0,0)-$M6/24 -> 46133.347 | P6: =$I6+TIME(9,0,0)+('Source Data'!$G$92+($M6*2))/24 -> 46133.597 | Q6: =IF(AND(VLOOKUP($H6&"|"&TEXT($I6,"yyyy-mm-dd"),'Source Data'!$G$17:$N$56,4,FALSE())="Available",$O6>=VLOOKUP($H6&"|"&TEXT($I6,"yyyy-mm-dd"),'Source Data'!$G$17:$N$56,5,FALSE()),$P6<=VLOOKUP($H6&"|"&TEXT($I6,"yyyy-mm-dd"),'Source Data'!$G$17:$N$56,6,FALSE())),"PASS","FAIL") -> PASS | R6: =IF(AND($I6>=$F6,$I6<=$G6),"PASS","FAIL") -> PASS | S6: =IF($J6=$C6,"FAIL","PASS") -> PASS | T6: =IF(AND($K6="Active",$I6>=VLOOKUP($H6,'Source Data'!$F$5:$K$9,4,FALSE()),$I6<=$L6),"PASS","FAIL") -> PASS | U6: =IF($E6<>"OR","N/A",IF(AND(($O6-VLOOKUP($H6&"|"&TEXT($I6,"yyyy-mm-dd"),'Source Data'!$G$17:$N$56,7,FALSE()))*24>='Source Data'!$G$94,(VLOOKUP($H6&"|"&TEXT($I6,"yyyy-mm-dd"),'Source Data'!$G$17:$N$56,8,FALSE())-$P6)*24>='Source Data'!$G$94),"PASS","FAIL")) -> PASS | V6: =IF($E6<>"OR","N/A",IF('Source Data'!$G$98<=IF($B6="April",'Source Data'!$G$96,'Source Data'!$G$97),"PASS","FAIL")) -> PASS | W6: =($P6-$O6)*24*VLOOKUP($H6,'Source Data'!$F$5:$K$9,6,FALSE()) -> 192 | X6: =$N6*'Source Data'!$G$93 -> 24.656 | Y6: =IF($U6="FAIL",MAX(0,'Source Data'!$G$94-MIN(($O6-VLOOKUP($H6&"|"&TEXT($I6,"yyyy-mm-dd"),'Source Data'!$G$17:$N$56,7,FALSE()))*24,(VLOOKUP($H6&"|"&TEXT($I6,"yyyy-mm-dd"),'Source Data'!$G$17:$N$56,8,FALSE())-$P6)*24))*VLOOKUP($H6,'Source Data'!$F$5:$K$9,6,FALSE()),0) -> 0 | Z6: =0 -> 0 | AA6: =SUM($W6:$Z6) -> 216.656 | AB6: =COUNTIF($Q6:$V6,"FAIL") -> 0 | AC6: =IF($AB6=0,"PASS","FAIL") -> PASS | AD6: =$A6&"|"&$B6&"|"&$C6 -> Option 1 | Lean route|April|OR-SAL
A7: Option 1 | Lean route | B7: April | C7: OR-BEN | D7: =VLOOKUP($C7,'Source Data'!$A$5:$D$13,2,FALSE()) -> Bend Tractor & Turf | E7: =VLOOKUP($C7,'Source Data'!$A$5:$D$13,3,FALSE()) -> OR | F7: =VLOOKUP($B7&"|"&$C7,'Source Data'!$A$17:$E$34,4,FALSE()) -> 46118 | G7: =VLOOKUP($B7&"|"&$C7,'Source Data'!$A$17:$E$34,5,FALSE()) -> 46140 | H7: Bianca Chen | I7: 46140 | J7: =VLOOKUP($H7,'Source Data'!$F$5:$K$9,2,FALSE()) -> OR-SAL | K7: =VLOOKUP($H7,'Source Data'!$F$5:$K$9,3,FALSE()) -> Active | L7: =VLOOKUP($H7,'Source Data'!$F$5:$K$9,5,FALSE()) -> 46356 | M7: =VLOOKUP($J7&"|"&$C7,'Source Data'!$P$17:$T$61,4,FALSE()) -> 2.1666667 | N7: =VLOOKUP($J7&"|"&$C7,'Source Data'!$P$17:$T$61,5,FALSE()) -> 119.6 | O7: =$I7+TIME(9,0,0)-$M7/24 -> 46140.285 | P7: =$I7+TIME(9,0,0)+('Source Data'!$G$92+($M7*2))/24 -> 46140.722 | Q7: =IF(AND(VLOOKUP($H7&"|"&TEXT($I7,"yyyy-mm-dd"),'Source Data'!$G$17:$N$56,4,FALSE())="Available",$O7>=VLOOKUP($H7&"|"&TEXT($I7,"yyyy-mm-dd"),'Source Data'!$G$17:$N$56,5,FALSE()),$P7<=VLOOKUP($H7&"|"&TEXT($I7,"yyyy-mm-dd"),'Source Data'!$G$17:$N$56,6,FALSE())),"PASS","FAIL") -> PASS | R7: =IF(AND($I7>=$F7,$I7<=$G7),"PASS","FAIL") -> PASS | S7: =IF($J7=$C7,"FAIL","PASS") -> PASS | T7: =IF(AND($K7="Active",$I7>=VLOOKUP($H7,'Source Data'!$F$5:$K$9,4,FALSE()),$I7<=$L7),"PASS","FAIL") -> PASS | U7: =IF($E7<>"OR","N/A",IF(AND(($O7-VLOOKUP($H7&"|"&TEXT($I7,"yyyy-mm-dd"),'Source Data'!$G$17:$N$56,7,FALSE()))*24>='Source Data'!$G$94,(VLOOKUP($H7&"|"&TEXT($I7,"yyyy-mm-dd"),'Source Data'!$G$17:$N$56,8,FALSE())-$P7)*24>='Source Data'!$G$94),"PASS","FAIL")) -> PASS | V7: =IF($E7<>"OR","N/A",IF('Source Data'!$G$98<=IF($B7="April",'Source Data'!$G$96,'Source Data'!$G$97),"PASS","FAIL")) -> PASS | W7: =($P7-$O7)*24*VLOOKUP($H7,'Source Data'!$F$5:$K$9,6,FALSE()) -> 357 | X7: =$N7*'Source Data'!$G$93 -> 80.132 | Y7: =IF($U7="FAIL",MAX(0,'Source Data'!$G$94-MIN(($O7-VLOOKUP($H7&"|"&TEXT($I7,"yyyy-mm-dd"),'Source Data'!$G$17:$N$56,7,FALSE()))*24,(VLOOKUP($H7&"|"&TEXT($I7,"yyyy-mm-dd"),'Source Data'!$G$17:$N$56,8,FALSE())-$P7)*24))*VLOOKUP($H7,'Source Data'!$F$5:$K$9,6,FALSE()),0) -> 0 | Z7: =0 -> 0 | AA7: =SUM($W7:$Z7) -> 437.132 | AB7: =COUNTIF($Q7:$V7,"FAIL") -> 0 | AC7: =IF($AB7=0,"PASS","FAIL") -> PASS | AD7: =$A7&"|"&$B7&"|"&$C7 -> Option 1 | Lean route|April|OR-BEN
A8: Option 1 | Lean route | B8: April | C8: OR-ONT | D8: =VLOOKUP($C8,'Source Data'!$A$5:$D$13,2,FALSE()) -> Ontario Equipment Depot | E8: =VLOOKUP($C8,'Source Data'!$A$5:$D$13,3,FALSE()) -> OR | F8: =VLOOKUP($B8&"|"&$C8,'Source Data'!$A$17:$E$34,4,FALSE()) -> 46118 | G8: =VLOOKUP($B8&"|"&$C8,'Source Data'!$A$17:$E$34,5,FALSE()) -> 46140 | H8: Darnell Fox | I8: 46126 | J8: =VLOOKUP($H8,'Source Data'!$F$5:$K$9,2,FALSE()) -> OR-BEN | K8: =VLOOKUP($H8,'Source Data'!$F$5:$K$9,3,FALSE()) -> Active | L8: =VLOOKUP($H8,'Source Data'!$F$5:$K$9,5,FALSE()) -> 46326 | M8: =VLOOKUP($J8&"|"&$C8,'Source Data'!$P$17:$T$61,4,FALSE()) -> 3 | N8: =VLOOKUP($J8&"|"&$C8,'Source Data'!$P$17:$T$61,5,FALSE()) -> 165.6 | O8: =$I8+TIME(9,0,0)-$M8/24 -> 46126.25 | P8: =$I8+TIME(9,0,0)+('Source Data'!$G$92+($M8*2))/24 -> 46126.792 | Q8: =IF(AND(VLOOKUP($H8&"|"&TEXT($I8,"yyyy-mm-dd"),'Source Data'!$G$17:$N$56,4,FALSE())="Available",$O8>=VLOOKUP($H8&"|"&TEXT($I8,"yyyy-mm-dd"),'Source Data'!$G$17:$N$56,5,FALSE()),$P8<=VLOOKUP($H8&"|"&TEXT($I8,"yyyy-mm-dd"),'Source Data'!$G$17:$N$56,6,FALSE())),"PASS","FAIL") -> PASS | R8: =IF(AND($I8>=$F8,$I8<=$G8),"PASS","FAIL") -> PASS | S8: =IF($J8=$C8,"FAIL","PASS") -> PASS | T8: =IF(AND($K8="Active",$I8>=VLOOKUP($H8,'Source Data'!$F$5:$K$9,4,FALSE()),$I8<=$L8),"PASS","FAIL") -> PASS | U8: =IF($E8<>"OR","N/A",IF(AND(($O8-VLOOKUP($H8&"|"&TEXT($I8,"yyyy-mm-dd"),'Source Data'!$G$17:$N$56,7,FALSE()))*24>='Source Data'!$G$94,(VLOOKUP($H8&"|"&TEXT($I8,"yyyy-mm-dd"),'Source Data'!$G$17:$N$56,8,FALSE())-$P8)*24>='Source Data'!$G$94),"PASS","FAIL")) -> FAIL | V8: =IF($E8<>"OR","N/A",IF('Source Data'!$G$98<=IF($B8="April",'Source Data'!$G$96,'Source Data'!$G$97),"PASS","FAIL")) -> PASS | W8: =($P8-$O8)*24*VLOOKUP($H8,'Source Data'!$F$5:$K$9,6,FALSE()) -> 403 | X8: =$N8*'Source Data'!$G$93 -> 110.952 | Y8: =IF($U8="FAIL",MAX(0,'Source Data'!$G$94-MIN(($O8-VLOOKUP($H8&"|"&TEXT($I8,"yyyy-mm-dd"),'Source Data'!$G$17:$N$56,7,FALSE()))*24,(VLOOKUP($H8&"|"&TEXT($I8,"yyyy-mm-dd"),'Source Data'!$G$17:$N$56,8,FALSE())-$P8)*24))*VLOOKUP($H8,'Source Data'!$F$5:$K$9,6,FALSE()),0) -> 62 | Z8: =0 -> 0 | AA8: =SUM($W8:$Z8) -> 575.952 | AB8: =COUNTIF($Q8:$V8,"FAIL") -> 1 | AC8: =IF($AB8=0,"PASS","FAIL") -> FAIL | AD8: =$A8&"|"&$B8&"|"&$C8 -> Option 1 | Lean route|April|OR-ONT
A9: Option 1 | Lean route | B9: April | C9: OR-MED | D9: =VLOOKUP($C9,'Source Data'!$A$5:$D$13,2,FALSE()) -> Medford Farm Center | E9: =VLOOKUP($C9,'Source Data'!$A$5:$D$13,3,FALSE()) -> OR | F9: =VLOOKUP($B9&"|"&$C9,'Source Data'!$A$17:$E$34,4,FALSE()) -> 46118 | G9: =VLOOKUP($B9&"|"&$C9,'Source Data'!$A$17:$E$34,5,FALSE()) -> 46140 | H9: Avery Lane | I9: 46119 | J9: =VLOOKUP($H9,'Source Data'!$F$5:$K$9,2,FALSE()) -> OR-ROS | K9: =VLOOKUP($H9,'Source Data'!$F$5:$K$9,3,FALSE()) -> Active | L9: =VLOOKUP($H9,'Source Data'!$F$5:$K$9,5,FALSE()) -> 46387 | M9: =VLOOKUP($J9&"|"&$C9,'Source Data'!$P$17:$T$61,4,FALSE()) -> 4 | N9: =VLOOKUP($J9&"|"&$C9,'Source Data'!$P$17:$T$61,5,FALSE()) -> 220.8 | O9: =$I9+TIME(9,0,0)-$M9/24 -> 46119.208 | P9: =$I9+TIME(9,0,0)+('Source Data'!$G$92+($M9*2))/24 -> 46119.875 | Q9: =IF(AND(VLOOKUP($H9&"|"&TEXT($I9,"yyyy-mm-dd"),'Source Data'!$G$17:$N$56,4,FALSE())="Available",$O9>=VLOOKUP($H9&"|"&TEXT($I9,"yyyy-mm-dd"),'Source Data'!$G$17:$N$56,5,FALSE()),$P9<=VLOOKUP($H9&"|"&TEXT($I9,"yyyy-mm-dd"),'Source Data'!$G$17:$N$56,6,FALSE())),"PASS","FAIL") -> PASS | R9: =IF(AND($I9>=$F9,$I9<=$G9),"PASS","FAIL") -> PASS | S9: =IF($J9=$C9,"FAIL","PASS") -> PASS | T9: =IF(AND($K9="Active",$I9>=VLOOKUP($H9,'Source Data'!$F$5:$K$9,4,FALSE()),$I9<=$L9),"PASS","FAIL") -> PASS | U9: =IF($E9<>"OR","N/A",IF(AND(($O9-VLOOKUP($H9&"|"&TEXT($I9,"yyyy-mm-dd"),'Source Data'!$G$17:$N$56,7,FALSE()))*24>='Source Data'!$G$94,(VLOOKUP($H9&"|"&TEXT($I9,"yyyy-mm-dd"),'Source Data'!$G$17:$N$56,8,FALSE())-$P9)*24>='Source Data'!$G$94),"PASS","FAIL")) -> PASS | V9: =IF($E9<>"OR","N/A",IF('Source Data'!$G$98<=IF($B9="April",'Source Data'!$G$96,'Source Data'!$G$97),"PASS","FAIL")) -> PASS | W9: =($P9-$O9)*24*VLOOKUP($H9,'Source Data'!$F$5:$K$9,6,FALSE()) -> 512 | X9: =$N9*'Source Data'!$G$93 -> 147.936 | Y9: =IF($U9="FAIL",MAX(0,'Source Data'!$G$94-MIN(($O9-VLOOKUP($H9&"|"&TEXT($I9,"yyyy-mm-dd"),'Source Data'!$G$17:$N$56,7,FALSE()))*24,(VLOOKUP($H9&"|"&TEXT($I9,"yyyy-mm-dd"),'Source Data'!$G$17:$N$56,8,FALSE())-$P9)*24))*VLOOKUP($H9,'Source Data'!$F$5:$K$9,6,FALSE()),0) -> 0 | Z9: =0 -> 0 | AA9: =SUM($W9:$Z9) -> 659.936 | AB9: =COUNTIF($Q9:$V9,"FAIL") -> 0 | AC9: =IF($AB9=0,"PASS","FAIL") -> PASS | AD9: =$A9&"|"&$B9&"|"&$C9 -> Option 1 | Lean route|April|OR-MED
A10: Option 1 | Lean route | B10: April | C10: OR-PEN | D10: =VLOOKUP($C10,'Source Data'!$A$5:$D$13,2,FALSE()) -> Pendleton Ranch Supply | E10: =VLOOKUP($C10,'Source Data'!$A$5:$D$13,3,FALSE()) -> OR | F10: =VLOOKUP($B10&"|"&$C10,'Source Data'!$A$17:$E$34,4,FALSE()) -> 46118 | G10: =VLOOKUP($B10&"|"&$C10,'Source Data'!$A$17:$E$34,5,FALSE()) -> 46140 | H10: Elena Ruiz | I10: 46133 | J10: =VLOOKUP($H10,'Source Data'!$F$5:$K$9,2,FALSE()) -> OR-ONT | K10: =VLOOKUP($H10,'Source Data'!$F$5:$K$9,3,FALSE()) -> Active | L10: =VLOOKUP($H10,'Source Data'!$F$5:$K$9,5,FALSE()) -> 46387 | M10: =VLOOKUP($J10&"|"&$C10,'Source Data'!$P$17:$T$61,4,FALSE()) -> 2.25 | N10: =VLOOKUP($J10&"|"&$C10,'Source Data'!$P$17:$T$61,5,FALSE()) -> 124.2 | O10: =$I10+TIME(9,0,0)-$M10/24 -> 46133.281 | P10: =$I10+TIME(9,0,0)+('Source Data'!$G$92+($M10*2))/24 -> 46133.729 | Q10: =IF(AND(VLOOKUP($H10&"|"&TEXT($I10,"yyyy-mm-dd"),'Source Data'!$G$17:$N$56,4,FALSE())="Available",$O10>=VLOOKUP($H10&"|"&TEXT($I10,"yyyy-mm-dd"),'Source Data'!$G$17:$N$56,5,FALSE()),$P10<=VLOOKUP($H10&"|"&TEXT($I10,"yyyy-mm-dd"),'Source Data'!$G$17:$N$56,6,FALSE())),"PASS","FAIL") -> PASS | R10: =IF(AND($I10>=$F10,$I10<=$G10),"PASS","FAIL") -> PASS | S10: =IF($J10=$C10,"FAIL","PASS") -> PASS | T10: =IF(AND($K10="Active",$I10>=VLOOKUP($H10,'Source Data'!$F$5:$K$9,4,FALSE()),$I10<=$L10),"PASS","FAIL") -> PASS | U10: =IF($E10<>"OR","N/A",IF(AND(($O10-VLOOKUP($H10&"|"&TEXT($I10,"yyyy-mm-dd"),'Source Data'!$G$17:$N$56,7,FALSE()))*24>='Source Data'!$G$94,(VLOOKUP($H10&"|"&TEXT($I10,"yyyy-mm-dd"),'Source Data'!$G$17:$N$56,8,FALSE())-$P10)*24>='Source Data'!$G$94),"PASS","FAIL")) -> PASS | V10: =IF($E10<>"OR","N/A",IF('Source Data'!$G$98<=IF($B10="April",'Source Data'!$G$96,'Source Data'!$G$97),"PASS","FAIL")) -> PASS | W10: =($P10-$O10)*24*VLOOKUP($H10,'Source Data'!$F$5:$K$9,6,FALSE()) -> 376.25 | X10: =$N10*'Source Data'!$G$93 -> 83.214 | Y10: =IF($U10="FAIL",MAX(0,'Source Data'!$G$94-MIN(($O10-VLOOKUP($H10&"|"&TEXT($I10,"yyyy-mm-dd"),'Source Data'!$G$17:$N$56,7,FALSE()))*24,(VLOOKUP($H10&"|"&TEXT($I10,"yyyy-mm-dd"),'Source Data'!$G$17:$N$56,8,FALSE())-$P10)*24))*VLOOKUP($H10,'Source Data'!$F$5:$K$9,6,FALSE()),0) -> 0 | Z10: =0 -> 0 | AA10: =SUM($W10:$Z10) -> 459.464 | AB10: =COUNTIF($Q10:$V10,"FAIL") -> 0 | AC10: =IF($AB10=0,"PASS","FAIL") -> PASS | AD10: =$A10&"|"&$B10&"|"&$C10 -> Option 1 | Lean route|April|OR-PEN
A11: Option 1 | Lean route | B11: April | C11: WA-YAK | D11: =VLOOKUP($C11,'Source Data'!$A$5:$D$13,2,FALSE()) -> Yakima Orchard & Field | E11: =VLOOKUP($C11,'Source Data'!$A$5:$D$13,3,FALSE()) -> WA | F11: =VLOOKUP($B11&"|"&$C11,'Source Data'!$A$17:$E$34,4,FALSE()) -> 46118 | G11: =VLOOKUP($B11&"|"&$C11,'Source Data'!$A$17:$E$34,5,FALSE()) -> 46140 | H11: Avery Lane | I11: 46126 | J11: =VLOOKUP($H11,'Source Data'!$F$5:$K$9,2,FALSE()) -> OR-ROS | K11: =VLOOKUP($H11,'Source Data'!$F$5:$K$9,3,FALSE()) -> Active | L11: =VLOOKUP($H11,'Source Data'!$F$5:$K$9,5,FALSE()) -> 46387 | M11: =VLOOKUP($J11&"|"&$C11,'Source Data'!$P$17:$T$61,4,FALSE()) -> 3 | N11: =VLOOKUP($J11&"|"&$C11,'Source Data'!$P$17:$T$61,5,FALSE()) -> 165.6 | O11: =$I11+TIME(9,0,0)-$M11/24 -> 46126.25 | P11: =$I11+TIME(9,0,0)+('Source Data'!$G$92+($M11*2))/24 -> 46126.792 | Q11: =IF(AND(VLOOKUP($H11&"|"&TEXT($I11,"yyyy-mm-dd"),'Source Data'!$G$17:$N$56,4,FALSE())="Available",$O11>=VLOOKUP($H11&"|"&TEXT($I11,"yyyy-mm-dd"),'Source Data'!$G$17:$N$56,5,FALSE()),$P11<=VLOOKUP($H11&"|"&TEXT($I11,"yyyy-mm-dd"),'Source Data'!$G$17:$N$56,6,FALSE())),"PASS","FAIL") -> PASS | R11: =IF(AND($I11>=$F11,$I11<=$G11),"PASS","FAIL") -> PASS | S11: =IF($J11=$C11,"FAIL","PASS") -> PASS | T11: =IF(AND($K11="Active",$I11>=VLOOKUP($H11,'Source Data'!$F$5:$K$9,4,FALSE()),$I11<=$L11),"PASS","FAIL") -> PASS | U11: =IF($E11<>"OR","N/A",IF(AND(($O11-VLOOKUP($H11&"|"&TEXT($I11,"yyyy-mm-dd"),'Source Data'!$G$17:$N$56,7,FALSE()))*24>='Source Data'!$G$94,(VLOOKUP($H11&"|"&TEXT($I11,"yyyy-mm-dd"),'Source Data'!$G$17:$N$56,8,FALSE())-$P11)*24>='Source Data'!$G$94),"PASS","FAIL")) -> N/A | V11: =IF($E11<>"OR","N/A",IF('Source Data'!$G$98<=IF($B11="April",'Source Data'!$G$96,'Source Data'!$G$97),"PASS","FAIL")) -> N/A | W11: =($P11-$O11)*24*VLOOKUP($H11,'Source Data'!$F$5:$K$9,6,FALSE()) -> 416 | X11: =$N11*'Source Data'!$G$93 -> 110.952 | Y11: =IF($U11="FAIL",MAX(0,'Source Data'!$G$94-MIN(($O11-VLOOKUP($H11&"|"&TEXT($I11,"yyyy-mm-dd"),'Source Data'!$G$17:$N$56,7,FALSE()))*24,(VLOOKUP($H11&"|"&TEXT($I11,"yyyy-mm-dd"),'Source Data'!$G$17:$N$56,8,FALSE())-$P11)*24))*VLOOKUP($H11,'Source Data'!$F$5:$K$9,6,FALSE()),0) -> 0 | Z11: =0 -> 0 | AA11: =SUM($W11:$Z11) -> 526.952 | AB11: =COUNTIF($Q11:$V11,"FAIL") -> 0 | AC11: =IF($AB11=0,"PASS","FAIL") -> PASS | AD11: =$A11&"|"&$B11&"|"&$C11 -> Option 1 | Lean route|April|WA-YAK
A12: Option 1 | Lean route | B12: April | C12: WA-VAN | D12: =VLOOKUP($C12,'Source Data'!$A$5:$D$13,2,FALSE()) -> Vancouver Farm Supply | E12: =VLOOKUP($C12,'Source Data'!$A$5:$D$13,3,FALSE()) -> WA | F12: =VLOOKUP($B12&"|"&$C12,'Source Data'!$A$17:$E$34,4,FALSE()) -> 46118 | G12: =VLOOKUP($B12&"|"&$C12,'Source Data'!$A$17:$E$34,5,FALSE()) -> 46140 | H12: Malik Brooks | I12: 46140 | J12: =VLOOKUP($H12,'Source Data'!$F$5:$K$9,2,FALSE()) -> WA-YAK | K12: =VLOOKUP($H12,'Source Data'!$F$5:$K$9,3,FALSE()) -> Active | L12: =VLOOKUP($H12,'Source Data'!$F$5:$K$9,5,FALSE()) -> 46418 | M12: =VLOOKUP($J12&"|"&$C12,'Source Data'!$P$17:$T$61,4,FALSE()) -> 3.25 | N12: =VLOOKUP($J12&"|"&$C12,'Source Data'!$P$17:$T$61,5,FALSE()) -> 179.4 | O12: =$I12+TIME(9,0,0)-$M12/24 -> 46140.24 | P12: =$I12+TIME(9,0,0)+('Source Data'!$G$92+($M12*2))/24 -> 46140.812 | Q12: =IF(AND(VLOOKUP($H12&"|"&TEXT($I12,"yyyy-mm-dd"),'Source Data'!$G$17:$N$56,4,FALSE())="Available",$O12>=VLOOKUP($H12&"|"&TEXT($I12,"yyyy-mm-dd"),'Source Data'!$G$17:$N$56,5,FALSE()),$P12<=VLOOKUP($H12&"|"&TEXT($I12,"yyyy-mm-dd"),'Source Data'!$G$17:$N$56,6,FALSE())),"PASS","FAIL") -> PASS | R12: =IF(AND($I12>=$F12,$I12<=$G12),"PASS","FAIL") -> PASS | S12: =IF($J12=$C12,"FAIL","PASS") -> PASS | T12: =IF(AND($K12="Active",$I12>=VLOOKUP($H12,'Source Data'!$F$5:$K$9,4,FALSE()),$I12<=$L12),"PASS","FAIL") -> PASS | U12: =IF($E12<>"OR","N/A",IF(AND(($O12-VLOOKUP($H12&"|"&TEXT($I12,"yyyy-mm-dd"),'Source Data'!$G$17:$N$56,7,FALSE()))*24>='Source Data'!$G$94,(VLOOKUP($H12&"|"&TEXT($I12,"yyyy-mm-dd"),'Source Data'!$G$17:$N$56,8,FALSE())-$P12)*24>='Source Data'!$G$94),"PASS","FAIL")) -> N/A | V12: =IF($E12<>"OR","N/A",IF('Source Data'!$G$98<=IF($B12="April",'Source Data'!$G$96,'Source Data'!$G$97),"PASS","FAIL")) -> N/A | W12: =($P12-$O12)*24*VLOOKUP($H12,'Source Data'!$F$5:$K$9,6,FALSE()) -> 453.75 | X12: =$N12*'Source Data'!$G$93 -> 120.198 | Y12: =IF($U12="FAIL",MAX(0,'Source Data'!$G$94-MIN(($O12-VLOOKUP($H12&"|"&TEXT($I12,"yyyy-mm-dd"),'Source Data'!$G$17:$N$56,7,FALSE()))*24,(VLOOKUP($H12&"|"&TEXT($I12,"yyyy-mm-dd"),'Source Data'!$G$17:$N$56,8,FALSE())-$P12)*24))*VLOOKUP($H12,'Source Data'!$F$5:$K$9,6,FALSE()),0) -> 0 | Z12: =0 -> 0 | AA12: =SUM($W12:$Z12) -> 573.948 | AB12: =COUNTIF($Q12:$V12,"FAIL") -> 0 | AC12: =IF($AB12=0,"PASS","FAIL") -> PASS | AD12: =$A12&"|"&$B12&"|"&$C12 -> Option 1 | Lean route|April|WA-VAN
A13: Option 1 | Lean route | B13: April | C13: WA-WAL | D13: =VLOOKUP($C13,'Source Data'!$A$5:$D$13,2,FALSE()) -> Walla Walla Tractor Co. | E13: =VLOOKUP($C13,'Source Data'!$A$5:$D$13,3,FALSE()) -> WA | F13: =VLOOKUP($B13&"|"&$C13,'Source Data'!$A$17:$E$34,4,FALSE()) -> 46118 | G13: =VLOOKUP($B13&"|"&$C13,'Source Data'!$A$17:$E$34,5,FALSE()) -> 46140 | H13: Malik Brooks | I13: 46133 | J13: =VLOOKUP($H13,'Source Data'!$F$5:$K$9,2,FALSE()) -> WA-YAK | K13: =VLOOKUP($H13,'Source Data'!$F$5:$K$9,3,FALSE()) -> Active | L13: =VLOOKUP($H13,'Source Data'!$F$5:$K$9,5,FALSE()) -> 46418 | M13: =VLOOKUP($J13&"|"&$C13,'Source Data'!$P$17:$T$61,4,FALSE()) -> 2.8333333 | N13: =VLOOKUP($J13&"|"&$C13,'Source Data'!$P$17:$T$61,5,FALSE()) -> 156.4 | O13: =$I13+TIME(9,0,0)-$M13/24 -> 46133.257 | P13: =$I13+TIME(9,0,0)+('Source Data'!$G$92+($M13*2))/24 -> 46133.778 | Q13: =IF(AND(VLOOKUP($H13&"|"&TEXT($I13,"yyyy-mm-dd"),'Source Data'!$G$17:$N$56,4,FALSE())="Available",$O13>=VLOOKUP($H13&"|"&TEXT($I13,"yyyy-mm-dd"),'Source Data'!$G$17:$N$56,5,FALSE()),$P13<=VLOOKUP($H13&"|"&TEXT($I13,"yyyy-mm-dd"),'Source Data'!$G$17:$N$56,6,FALSE())),"PASS","FAIL") -> PASS | R13: =IF(AND($I13>=$F13,$I13<=$G13),"PASS","FAIL") -> PASS | S13: =IF($J13=$C13,"FAIL","PASS") -> PASS | T13: =IF(AND($K13="Active",$I13>=VLOOKUP($H13,'Source Data'!$F$5:$K$9,4,FALSE()),$I13<=$L13),"PASS","FAIL") -> PASS | U13: =IF($E13<>"OR","N/A",IF(AND(($O13-VLOOKUP($H13&"|"&TEXT($I13,"yyyy-mm-dd"),'Source Data'!$G$17:$N$56,7,FALSE()))*24>='Source Data'!$G$94,(VLOOKUP($H13&"|"&TEXT($I13,"yyyy-mm-dd"),'Source Data'!$G$17:$N$56,8,FALSE())-$P13)*24>='Source Data'!$G$94),"PASS","FAIL")) -> N/A | V13: =IF($E13<>"OR","N/A",IF('Source Data'!$G$98<=IF($B13="April",'Source Data'!$G$96,'Source Data'!$G$97),"PASS","FAIL")) -> N/A | W13: =($P13-$O13)*24*VLOOKUP($H13,'Source Data'!$F$5:$K$9,6,FALSE()) -> 412.5 | X13: =$N13*'Source Data'!$G$93 -> 104.788 | Y13: =IF($U13="FAIL",MAX(0,'Source Data'!$G$94-MIN(($O13-VLOOKUP($H13&"|"&TEXT($I13,"yyyy-mm-dd"),'Source Data'!$G$17:$N$56,7,FALSE()))*24,(VLOOKUP($H13&"|"&TEXT($I13,"yyyy-mm-dd"),'Source Data'!$G$17:$N$56,8,FALSE())-$P13)*24))*VLOOKUP($H13,'Source Data'!$F$5:$K$9,6,FALSE()),0) -> 0 | Z13: =0 -> 0 | AA13: =SUM($W13:$Z13) -> 517.288 | AB13: =COUNTIF($Q13:$V13,"FAIL") -> 0 | AC13: =IF($AB13=0,"PASS","FAIL") -> PASS | AD13: =$A13&"|"&$B13&"|"&$C13 -> Option 1 | Lean route|April|WA-WAL
A14: Option 1 | Lean route | B14: May | C14: OR-ROS | D14: =VLOOKUP($C14,'Source Data'!$A$5:$D$13,2,FALSE()) -> Roseburg Farm & Field | E14: =VLOOKUP($C14,'Source Data'!$A$5:$D$13,3,FALSE()) -> OR | F14: =VLOOKUP($B14&"|"&$C14,'Source Data'!$A$17:$E$34,4,FALSE()) -> 46146 | G14: =VLOOKUP($B14&"|"&$C14,'Source Data'!$A$17:$E$34,5,FALSE()) -> 46168 | H14: Bianca Chen | I14: 46147 | J14: =VLOOKUP($H14,'Source Data'!$F$5:$K$9,2,FALSE()) -> OR-SAL | K14: =VLOOKUP($H14,'Source Data'!$F$5:$K$9,3,FALSE()) -> Active | L14: =VLOOKUP($H14,'Source Data'!$F$5:$K$9,5,FALSE()) -> 46356 | M14: =VLOOKUP($J14&"|"&$C14,'Source Data'!$P$17:$T$61,4,FALSE()) -> 0.66666667 | N14: =VLOOKUP($J14&"|"&$C14,'Source Data'!$P$17:$T$61,5,FALSE()) -> 36.8 | O14: =$I14+TIME(9,0,0)-$M14/24 -> 46147.347 | P14: =$I14+TIME(9,0,0)+('Source Data'!$G$92+($M14*2))/24 -> 46147.597 | Q14: =IF(AND(VLOOKUP($H14&"|"&TEXT($I14,"yyyy-mm-dd"),'Source Data'!$G$17:$N$56,4,FALSE())="Available",$O14>=VLOOKUP($H14&"|"&TEXT($I14,"yyyy-mm-dd"),'Source Data'!$G$17:$N$56,5,FALSE()),$P14<=VLOOKUP($H14&"|"&TEXT($I14,"yyyy-mm-dd"),'Source Data'!$G$17:$N$56,6,FALSE())),"PASS","FAIL") -> PASS | R14: =IF(AND($I14>=$F14,$I14<=$G14),"PASS","FAIL") -> PASS | S14: =IF($J14=$C14,"FAIL","PASS") -> PASS | T14: =IF(AND($K14="Active",$I14>=VLOOKUP($H14,'Source Data'!$F$5:$K$9,4,FALSE()),$I14<=$L14),"PASS","FAIL") -> PASS | U14: =IF($E14<>"OR","N/A",IF(AND(($O14-VLOOKUP($H14&"|"&TEXT($I14,"yyyy-mm-dd"),'Source Data'!$G$17:$N$56,7,FALSE()))*24>='Source Data'!$G$94,(VLOOKUP($H14&"|"&TEXT($I14,"yyyy-mm-dd"),'Source Data'!$G$17:$N$56,8,FALSE())-$P14)*24>='Source Data'!$G$94),"PASS","FAIL")) -> PASS | V14: =IF($E14<>"OR","N/A",IF('Source Data'!$G$98<=IF($B14="April",'Source Data'!$G$96,'Source Data'!$G$97),"PASS","FAIL")) -> PASS | W14: =($P14-$O14)*24*VLOOKUP($H14,'Source Data'!$F$5:$K$9,6,FALSE()) -> 204 | X14: =$N14*'Source Data'!$G$93 -> 24.656 | Y14: =IF($U14="FAIL",MAX(0,'Source Data'!$G$94-MIN(($O14-VLOOKUP($H14&"|"&TEXT($I14,"yyyy-mm-dd"),'Source Data'!$G$17:$N$56,7,FALSE()))*24,(VLOOKUP($H14&"|"&TEXT($I14,"yyyy-mm-dd"),'Source Data'!$G$17:$N$56,8,FALSE())-$P14)*24))*VLOOKUP($H14,'Source Data'!$F$5:$K$9,6,FALSE()),0) -> 0 | Z14: =0 -> 0 | AA14: =SUM($W14:$Z14) -> 228.656 | AB14: =COUNTIF($Q14:$V14,"FAIL") -> 0 | AC14: =IF($AB14=0,"PASS","FAIL") -> PASS | AD14: =$A14&"|"&$B14&"|"&$C14 -> Option 1 | Lean route|May|OR-ROS
A15: Option 1 | Lean route | B15: May | C15: OR-SAL | D15: =VLOOKUP($C15,'Source Data'!$A$5:$D$13,2,FALSE()) -> Salem Ag Supply | E15: =VLOOKUP($C15,'Source Data'!$A$5:$D$13,3,FALSE()) -> OR | F15: =VLOOKUP($B15&"|"&$C15,'Source Data'!$A$17:$E$34,4,FALSE()) -> 46146 | G15: =VLOOKUP($B15&"|"&$C15,'Source Data'!$A$17:$E$34,5,FALSE()) -> 46168 | H15: Avery Lane | I15: 46154 | J15: =VLOOKUP($H15,'Source Data'!$F$5:$K$9,2,FALSE()) -> OR-ROS | K15: =VLOOKUP($H15,'Source Data'!$F$5:$K$9,3,FALSE()) -> Active | L15: =VLOOKUP($H15,'Source Data'!$F$5:$K$9,5,FALSE()) -> 46387 | M15: =VLOOKUP($J15&"|"&$C15,'Source Data'!$P$17:$T$61,4,FALSE()) -> 0.66666667 | N15: =VLOOKUP($J15&"|"&$C15,'Source Data'!$P$17:$T$61,5,FALSE()) -> 36.8 | O15: =$I15+TIME(9,0,0)-$M15/24 -> 46154.347 | P15: =$I15+TIME(9,0,0)+('Source Data'!$G$92+($M15*2))/24 -> 46154.597 | Q15: =IF(AND(VLOOKUP($H15&"|"&TEXT($I15,"yyyy-mm-dd"),'Source Data'!$G$17:$N$56,4,FALSE())="Available",$O15>=VLOOKUP($H15&"|"&TEXT($I15,"yyyy-mm-dd"),'Source Data'!$G$17:$N$56,5,FALSE()),$P15<=VLOOKUP($H15&"|"&TEXT($I15,"yyyy-mm-dd"),'Source Data'!$G$17:$N$56,6,FALSE())),"PASS","FAIL") -> PASS | R15: =IF(AND($I15>=$F15,$I15<=$G15),"PASS","FAIL") -> PASS | S15: =IF($J15=$C15,"FAIL","PASS") -> PASS | T15: =IF(AND($K15="Active",$I15>=VLOOKUP($H15,'Source Data'!$F$5:$K$9,4,FALSE()),$I15<=$L15),"PASS","FAIL") -> PASS | U15: =IF($E15<>"OR","N/A",IF(AND(($O15-VLOOKUP($H15&"|"&TEXT($I15,"yyyy-mm-dd"),'Source Data'!$G$17:$N$56,7,FALSE()))*24>='Source Data'!$G$94,(VLOOKUP($H15&"|"&TEXT($I15,"yyyy-mm-dd"),'Source Data'!$G$17:$N$56,8,FALSE())-$P15)*24>='Source Data'!$G$94),"PASS","FAIL")) -> PASS | V15: =IF($E15<>"OR","N/A",IF('Source Data'!$G$98<=IF($B15="April",'Source Data'!$G$96,'Source Data'!$G$97),"PASS","FAIL")) -> PASS | W15: =($P15-$O15)*24*VLOOKUP($H15,'Source Data'!$F$5:$K$9,6,FALSE()) -> 192 | X15: =$N15*'Source Data'!$G$93 -> 24.656 | Y15: =IF($U15="FAIL",MAX(0,'Source Data'!$G$94-MIN(($O15-VLOOKUP($H15&"|"&TEXT($I15,"yyyy-mm-dd"),'Source Data'!$G$17:$N$56,7,FALSE()))*24,(VLOOKUP($H15&"|"&TEXT($I15,"yyyy-mm-dd"),'Source Data'!$G$17:$N$56,8,FALSE())-$P15)*24))*VLOOKUP($H15,'Source Data'!$F$5:$K$9,6,FALSE()),0) -> 0 | Z15: =0 -> 0 | AA15: =SUM($W15:$Z15) -> 216.656 | AB15: =COUNTIF($Q15:$V15,"FAIL") -> 0 | AC15: =IF($AB15=0,"PASS","FAIL") -> PASS | AD15: =$A15&"|"&$B15&"|"&$C15 -> Option 1 | Lean route|May|OR-SAL
A16: Option 1 | Lean route | B16: May | C16: OR-BEN | D16: =VLOOKUP($C16,'Source Data'!$A$5:$D$13,2,FALSE()) -> Bend Tractor & Turf | E16: =VLOOKUP($C16,'Source Data'!$A$5:$D$13,3,FALSE()) -> OR | F16: =VLOOKUP($B16&"|"&$C16,'Source Data'!$A$17:$E$34,4,FALSE()) -> 46146 | G16: =VLOOKUP($B16&"|"&$C16,'Source Data'!$A$17:$E$34,5,FALSE()) -> 46168 | H16: Bianca Chen | I16: 46161 | J16: =VLOOKUP($H16,'Source Data'!$F$5:$K$9,2,FALSE()) -> OR-SAL | K16: =VLOOKUP($H16,'Source Data'!$F$5:$K$9,3,FALSE()) -> Active | L16: =VLOOKUP($H16,'Source Data'!$F$5:$K$9,5,FALSE()) -> 46356 | M16: =VLOOKUP($J16&"|"&$C16,'Source Data'!$P$17:$T$61,4,FALSE()) -> 2.1666667 | N16: =VLOOKUP($J16&"|"&$C16,'Source Data'!$P$17:$T$61,5,FALSE()) -> 119.6 | O16: =$I16+TIME(9,0,0)-$M16/24 -> 46161.285 | P16: =$I16+TIME(9,0,0)+('Source Data'!$G$92+($M16*2))/24 -> 46161.722 | Q16: =IF(AND(VLOOKUP($H16&"|"&TEXT($I16,"yyyy-mm-dd"),'Source Data'!$G$17:$N$56,4,FALSE())="Available",$O16>=VLOOKUP($H16&"|"&TEXT($I16,"yyyy-mm-dd"),'Source Data'!$G$17:$N$56,5,FALSE()),$P16<=VLOOKUP($H16&"|"&TEXT($I16,"yyyy-mm-dd"),'Source Data'!$G$17:$N$56,6,FALSE())),"PASS","FAIL") -> PASS | R16: =IF(AND($I16>=$F16,$I16<=$G16),"PASS","FAIL") -> PASS | S16: =IF($J16=$C16,"FAIL","PASS") -> PASS | T16: =IF(AND($K16="Active",$I16>=VLOOKUP($H16,'Source Data'!$F$5:$K$9,4,FALSE()),$I16<=$L16),"PASS","FAIL") -> PASS | U16: =IF($E16<>"OR","N/A",IF(AND(($O16-VLOOKUP($H16&"|"&TEXT($I16,"yyyy-mm-dd"),'Source Data'!$G$17:$N$56,7,FALSE()))*24>='Source Data'!$G$94,(VLOOKUP($H16&"|"&TEXT($I16,"yyyy-mm-dd"),'Source Data'!$G$17:$N$56,8,FALSE())-$P16)*24>='Source Data'!$G$94),"PASS","FAIL")) -> PASS | V16: =IF($E16<>"OR","N/A",IF('Source Data'!$G$98<=IF($B16="April",'Source Data'!$G$96,'Source Data'!$G$97),"PASS","FAIL")) -> PASS | W16: =($P16-$O16)*24*VLOOKUP($H16,'Source Data'!$F$5:$K$9,6,FALSE()) -> 357 | X16: =$N16*'Source Data'!$G$93 -> 80.132 | Y16: =IF($U16="FAIL",MAX(0,'Source Data'!$G$94-MIN(($O16-VLOOKUP($H16&"|"&TEXT($I16,"yyyy-mm-dd"),'Source Data'!$G$17:$N$56,7,FALSE()))*24,(VLOOKUP($H16&"|"&TEXT($I16,"yyyy-mm-dd"),'Source Data'!$G$17:$N$56,8,FALSE())-$P16)*24))*VLOOKUP($H16,'Source Data'!$F$5:$K$9,6,FALSE()),0) -> 0 | Z16: =0 -> 0 | AA16: =SUM($W16:$Z16) -> 437.132 | AB16: =COUNTIF($Q16:$V16,"FAIL") -> 0 | AC16: =IF($AB16=0,"PASS","FAIL") -> PASS | AD16: =$A16&"|"&$B16&"|"&$C16 -> Option 1 | Lean route|May|OR-BEN
... A58: Option 3 | Long-haul cover | B58: May | C58: WA-WAL | D58: =VLOOKUP($C58,'Source Data'!$A$5:$D$13,2,FALSE()) -> Walla Walla Tractor Co. | E58: =VLOOKUP($C58,'Source Data'!$A$5:$D$13,3,FALSE()) -> WA | F58: =VLOOKUP($B58&"|"&$C58,'Source Data'!$A$17:$E$34,4,FALSE()) -> 46146 | G58: =VLOOKUP($B58&"|"&$C58,'Source Data'!$A$17:$E$34,5,FALSE()) -> 46168 | H58: Malik Brooks | I58: 46161 | J58: =VLOOKUP($H58,'Source Data'!$F$5:$K$9,2,FALSE()) -> WA-YAK | K58: =VLOOKUP($H58,'Source Data'!$F$5:$K$9,3,FALSE()) -> Active | L58: =VLOOKUP($H58,'Source Data'!$F$5:$K$9,5,FALSE()) -> 46418 | M58: =VLOOKUP($J58&"|"&$C58,'Source Data'!$P$17:$T$61,4,FALSE()) -> 2.8333333 | N58: =VLOOKUP($J58&"|"&$C58,'Source Data'!$P$17:$T$61,5,FALSE()) -> 156.4 | O58: =$I58+TIME(9,0,0)-$M58/24 -> 46161.257 | P58: =$I58+TIME(9,0,0)+('Source Data'!$G$92+($M58*2))/24 -> 46161.778 | Q58: =IF(AND(VLOOKUP($H58&"|"&TEXT($I58,"yyyy-mm-dd"),'Source Data'!$G$17:$N$56,4,FALSE())="Available",$O58>=VLOOKUP($H58&"|"&TEXT($I58,"yyyy-mm-dd"),'Source Data'!$G$17:$N$56,5,FALSE()),$P58<=VLOOKUP($H58&"|"&TEXT($I58,"yyyy-mm-dd"),'Source Data'!$G$17:$N$56,6,FALSE())),"PASS","FAIL") -> PASS | R58: =IF(AND($I58>=$F58,$I58<=$G58),"PASS","FAIL") -> PASS | S58: =IF($J58=$C58,"FAIL","PASS") -> PASS | T58: =IF(AND($K58="Active",$I58>=VLOOKUP($H58,'Source Data'!$F$5:$K$9,4,FALSE()),$I58<=$L58),"PASS","FAIL") -> PASS | U58: =IF($E58<>"OR","N/A",IF(AND(($O58-VLOOKUP($H58&"|"&TEXT($I58,"yyyy-mm-dd"),'Source Data'!$G$17:$N$56,7,FALSE()))*24>='Source Data'!$G$94,(VLOOKUP($H58&"|"&TEXT($I58,"yyyy-mm-dd"),'Source Data'!$G$17:$N$56,8,FALSE())-$P58)*24>='Source Data'!$G$94),"PASS","FAIL")) -> N/A | V58: =IF($E58<>"OR","N/A",IF('Source Data'!$G$98<=IF($B58="April",'Source Data'!$G$96,'Source Data'!$G$97),"PASS","FAIL")) -> N/A | W58: =($P58-$O58)*24*VLOOKUP($H58,'Source Data'!$F$5:$K$9,6,FALSE()) -> 412.5 | X58: =$N58*'Source Data'!$G$93 -> 104.788 | Y58: =IF($U58="FAIL",MAX(0,'Source Data'!$G$94-MIN(($O58-VLOOKUP($H58&"|"&TEXT($I58,"yyyy-mm-dd"),'Source Data'!$G$17:$N$56,7,FALSE()))*24,(VLOOKUP($H58&"|"&TEXT($I58,"yyyy-mm-dd"),'Source Data'!$G$17:$N$56,8,FALSE())-$P58)*24))*VLOOKUP($H58,'Source Data'!$F$5:$K$9,6,FALSE()),0) -> 0 | Z58: =0 -> 0 | AA58: =SUM($W58:$Z58) -> 517.288 | AB58: =COUNTIF($Q58:$V58,"FAIL") -> 0 | AC58: =IF($AB58=0,"PASS","FAIL") -> PASS | AD58: =$A58&"|"&$B58&"|"&$C58 -> Option 3 | Long-haul cover|May|WA-WAL

Sheet Final Roster
A1: Goldfinch Agricultural | Final Inspection Roster
A2: APRIL 2026
A3: Oregon posting deadline: 1 March 2026 | Selected by live model recommendation
A5: Recommended option | B5: ='Start Here'!$B$22 -> Option 2 | Compliant balance
A7: Store ID | B7: Store | C7: State | D7: Assigned supervisor | E7: Planned inspection date | F7: Work period | G7: Status
A8: OR-ROS | B8: =INDEX(Assignments!$D$5:$D$58,MATCH($B$5&"|April|"&$A8,Assignments!$AD$5:$AD$58,0)) -> Roseburg Farm & Field | C8: =INDEX(Assignments!$E$5:$E$58,MATCH($B$5&"|April|"&$A8,Assignments!$AD$5:$AD$58,0)) -> OR | D8: =INDEX(Assignments!$H$5:$H$58,MATCH($B$5&"|April|"&$A8,Assignments!$AD$5:$AD$58,0)) -> Bianca Chen | E8: =INDEX(Assignments!$I$5:$I$58,MATCH($B$5&"|April|"&$A8,Assignments!$AD$5:$AD$58,0)) -> 46119 | F8: =TEXT(INDEX(Assignments!$O$5:$O$58,MATCH($B$5&"|April|"&$A8,Assignments!$AD$5:$AD$58,0)),"m/d h:mm AM/PM")&" - "&TEXT(INDEX(Assignments!$P$5:$P$58,MATCH($B$5&"|April|"&$A8,Assignments!$AD$5:$AD$58,0)),"h:mm AM/PM") -> 4/7 8:20 AM - 2:20 PM | G8: =INDEX(Assignments!$AC$5:$AC$58,MATCH($B$5&"|April|"&$A8,Assignments!$AD$5:$AD$58,0)) -> PASS
A9: OR-SAL | B9: =INDEX(Assignments!$D$5:$D$58,MATCH($B$5&"|April|"&$A9,Assignments!$AD$5:$AD$58,0)) -> Salem Ag Supply | C9: =INDEX(Assignments!$E$5:$E$58,MATCH($B$5&"|April|"&$A9,Assignments!$AD$5:$AD$58,0)) -> OR | D9: =INDEX(Assignments!$H$5:$H$58,MATCH($B$5&"|April|"&$A9,Assignments!$AD$5:$AD$58,0)) -> Darnell Fox | E9: =INDEX(Assignments!$I$5:$I$58,MATCH($B$5&"|April|"&$A9,Assignments!$AD$5:$AD$58,0)) -> 46133 | F9: =TEXT(INDEX(Assignments!$O$5:$O$58,MATCH($B$5&"|April|"&$A9,Assignments!$AD$5:$AD$58,0)),"m/d h:mm AM/PM")&" - "&TEXT(INDEX(Assignments!$P$5:$P$58,MATCH($B$5&"|April|"&$A9,Assignments!$AD$5:$AD$58,0)),"h:mm AM/PM") -> 4/21 6:50 AM - 5:20 PM | G9: =INDEX(Assignments!$AC$5:$AC$58,MATCH($B$5&"|April|"&$A9,Assignments!$AD$5:$AD$58,0)) -> PASS
A10: OR-BEN | B10: =INDEX(Assignments!$D$5:$D$58,MATCH($B$5&"|April|"&$A10,Assignments!$AD$5:$AD$58,0)) -> Bend Tractor & Turf | C10: =INDEX(Assignments!$E$5:$E$58,MATCH($B$5&"|April|"&$A10,Assignments!$AD$5:$AD$58,0)) -> OR | D10: =INDEX(Assignments!$H$5:$H$58,MATCH($B$5&"|April|"&$A10,Assignments!$AD$5:$AD$58,0)) -> Elena Ruiz | E10: =INDEX(Assignments!$I$5:$I$58,MATCH($B$5&"|April|"&$A10,Assignments!$AD$5:$AD$58,0)) -> 46140 | F10: =TEXT(INDEX(Assignments!$O$5:$O$58,MATCH($B$5&"|April|"&$A10,Assignments!$AD$5:$AD$58,0)),"m/d h:mm AM/PM")&" - "&TEXT(INDEX(Assignments!$P$5:$P$58,MATCH($B$5&"|April|"&$A10,Assignments!$AD$5:$AD$58,0)),"h:mm AM/PM") -> 4/28 6:00 AM - 7:00 PM | G10: =INDEX(Assignments!$AC$5:$AC$58,MATCH($B$5&"|April|"&$A10,Assignments!$AD$5:$AD$58,0)) -> PASS
A11: OR-ONT | B11: =INDEX(Assignments!$D$5:$D$58,MATCH($B$5&"|April|"&$A11,Assignments!$AD$5:$AD$58,0)) -> Ontario Equipment Depot | C11: =INDEX(Assignments!$E$5:$E$58,MATCH($B$5&"|April|"&$A11,Assignments!$AD$5:$AD$58,0)) -> OR | D11: =INDEX(Assignments!$H$5:$H$58,MATCH($B$5&"|April|"&$A11,Assignments!$AD$5:$AD$58,0)) -> Darnell Fox | E11: =INDEX(Assignments!$I$5:$I$58,MATCH($B$5&"|April|"&$A11,Assignments!$AD$5:$AD$58,0)) -> 46119 | F11: =TEXT(INDEX(Assignments!$O$5:$O$58,MATCH($B$5&"|April|"&$A11,Assignments!$AD$5:$AD$58,0)),"m/d h:mm AM/PM")&" - "&TEXT(INDEX(Assignments!$P$5:$P$58,MATCH($B$5&"|April|"&$A11,Assignments!$AD$5:$AD$58,0)),"h:mm AM/PM") -> 4/7 6:00 AM - 7:00 PM | G11: =INDEX(Assignments!$AC$5:$AC$58,MATCH($B$5&"|April|"&$A11,Assignments!$AD$5:$AD$58,0)) -> PASS
A12: OR-MED | B12: =INDEX(Assignments!$D$5:$D$58,MATCH($B$5&"|April|"&$A12,Assignments!$AD$5:$AD$58,0)) -> Medford Farm Center | C12: =INDEX(Assignments!$E$5:$E$58,MATCH($B$5&"|April|"&$A12,Assignments!$AD$5:$AD$58,0)) -> OR | D12: =INDEX(Assignments!$H$5:$H$58,MATCH($B$5&"|April|"&$A12,Assignments!$AD$5:$AD$58,0)) -> Avery Lane | E12: =INDEX(Assignments!$I$5:$I$58,MATCH($B$5&"|April|"&$A12,Assignments!$AD$5:$AD$58,0)) -> 46126 | F12: =TEXT(INDEX(Assignments!$O$5:$O$58,MATCH($B$5&"|April|"&$A12,Assignments!$AD$5:$AD$58,0)),"m/d h:mm AM/PM")&" - "&TEXT(INDEX(Assignments!$P$5:$P$58,MATCH($B$5&"|April|"&$A12,Assignments!$AD$5:$AD$58,0)),"h:mm AM/PM") -> 4/14 5:00 AM - 9:00 PM | G12: =INDEX(Assignments!$AC$5:$AC$58,MATCH($B$5&"|April|"&$A12,Assignments!$AD$5:$AD$58,0)) -> PASS
A13: OR-PEN | B13: =INDEX(Assignments!$D$5:$D$58,MATCH($B$5&"|April|"&$A13,Assignments!$AD$5:$AD$58,0)) -> Pendleton Ranch Supply | C13: =INDEX(Assignments!$E$5:$E$58,MATCH($B$5&"|April|"&$A13,Assignments!$AD$5:$AD$58,0)) -> OR | D13: =INDEX(Assignments!$H$5:$H$58,MATCH($B$5&"|April|"&$A13,Assignments!$AD$5:$AD$58,0)) -> Elena Ruiz | E13: =INDEX(Assignments!$I$5:$I$58,MATCH($B$5&"|April|"&$A13,Assignments!$AD$5:$AD$58,0)) -> 46133 | F13: =TEXT(INDEX(Assignments!$O$5:$O$58,MATCH($B$5&"|April|"&$A13,Assignments!$AD$5:$AD$58,0)),"m/d h:mm AM/PM")&" - "&TEXT(INDEX(Assignments!$P$5:$P$58,MATCH($B$5&"|April|"&$A13,Assignments!$AD$5:$AD$58,0)),"h:mm AM/PM") -> 4/21 6:45 AM - 5:30 PM | G13: =INDEX(Assignments!$AC$5:$AC$58,MATCH($B$5&"|April|"&$A13,Assignments!$AD$5:$AD$58,0)) -> PASS
A14: WA-YAK | B14: =INDEX(Assignments!$D$5:$D$58,MATCH($B$5&"|April|"&$A14,Assignments!$AD$5:$AD$58,0)) -> Yakima Orchard & Field | C14: =INDEX(Assignments!$E$5:$E$58,MATCH($B$5&"|April|"&$A14,Assignments!$AD$5:$AD$58,0)) -> WA | D14: =INDEX(Assignments!$H$5:$H$58,MATCH($B$5&"|April|"&$A14,Assignments!$AD$5:$AD$58,0)) -> Avery Lane | E14: =INDEX(Assignments!$I$5:$I$58,MATCH($B$5&"|April|"&$A14,Assignments!$AD$5:$AD$58,0)) -> 46126 | F14: =TEXT(INDEX(Assignments!$O$5:$O$58,MATCH($B$5&"|April|"&$A14,Assignments!$AD$5:$AD$58,0)),"m/d h:mm AM/PM")&" - "&TEXT(INDEX(Assignments!$P$5:$P$58,MATCH($B$5&"|April|"&$A14,Assignments!$AD$5:$AD$58,0)),"h:mm AM/PM") -> 4/14 6:00 AM - 7:00 PM | G14: =INDEX(Assignments!$AC$5:$AC$58,MATCH($B$5&"|April|"&$A14,Assignments!$AD$5:$AD$58,0)) -> PASS
A15: WA-VAN | B15: =INDEX(Assignments!$D$5:$D$58,MATCH($B$5&"|April|"&$A15,Assignments!$AD$5:$AD$58,0)) -> Vancouver Farm Supply | C15: =INDEX(Assignments!$E$5:$E$58,MATCH($B$5&"|April|"&$A15,Assignments!$AD$5:$AD$58,0)) -> WA | D15: =INDEX(Assignments!$H$5:$H$58,MATCH($B$5&"|April|"&$A15,Assignments!$AD$5:$AD$58,0)) -> Malik Brooks | E15: =INDEX(Assignments!$I$5:$I$58,MATCH($B$5&"|April|"&$A15,Assignments!$AD$5:$AD$58,0)) -> 46140 | F15: =TEXT(INDEX(Assignments!$O$5:$O$58,MATCH($B$5&"|April|"&$A15,Assignments!$AD$5:$AD$58,0)),"m/d h:mm AM/PM")&" - "&TEXT(INDEX(Assignments!$P$5:$P$58,MATCH($B$5&"|April|"&$A15,Assignments!$AD$5:$AD$58,0)),"h:mm AM/PM") -> 4/28 5:45 AM - 7:30 PM | G15: =INDEX(Assignments!$AC$5:$AC$58,MATCH($B$5&"|April|"&$A15,Assignments!$AD$5:$AD$58,0)) -> PASS
A16: WA-WAL | B16: =INDEX(Assignments!$D$5:$D$58,MATCH($B$5&"|April|"&$A16,Assignments!$AD$5:$AD$58,0)) -> Walla Walla Tractor Co. | C16: =INDEX(Assignments!$E$5:$E$58,MATCH($B$5&"|April|"&$A16,Assignments!$AD$5:$AD$58,0)) -> WA | D16: =INDEX(Assignments!$H$5:$H$58,MATCH($B$5&"|April|"&$A16,Assignments!$AD$5:$AD$58,0)) -> Malik Brooks | E16: =INDEX(Assignments!$I$5:$I$58,MATCH($B$5&"|April|"&$A16,Assignments!$AD$5:$AD$58,0)) -> 46133 | F16: =TEXT(INDEX(Assignments!$O$5:$O$58,MATCH($B$5&"|April|"&$A16,Assignments!$AD$5:$AD$58,0)),"m/d h:mm AM/PM")&" - "&TEXT(INDEX(Assignments!$P$5:$P$58,MATCH($B$5&"|April|"&$A16,Assignments!$AD$5:$AD$58,0)),"h:mm AM/PM") -> 4/21 6:10 AM - 6:40 PM | G16: =INDEX(Assignments!$AC$5:$AC$58,MATCH($B$5&"|April|"&$A16,Assignments!$AD$5:$AD$58,0)) -> PASS
A19: Store teams: prepare recalled-product records and a clear display route before the listed work period.
A28: Goldfinch Agricultural | Final Inspection Roster
A29: MAY 2026
A30: Oregon posting deadline: 1 April 2026 | Selected by live model recommendation
A32: Recommended option | B32: ='Start Here'!$B$22 -> Option 2 | Compliant balance
A34: Store ID | B34: Store | C34: State | D34: Assigned supervisor | E34: Planned inspection date | F34: Work period | G34: Status
A35: OR-ROS | B35: =INDEX(Assignments!$D$5:$D$58,MATCH($B$32&"|May|"&$A35,Assignments!$AD$5:$AD$58,0)) -> Roseburg Farm & Field | C35: =INDEX(Assignments!$E$5:$E$58,MATCH($B$32&"|May|"&$A35,Assignments!$AD$5:$AD$58,0)) -> OR | D35: =INDEX(Assignments!$H$5:$H$58,MATCH($B$32&"|May|"&$A35,Assignments!$AD$5:$AD$58,0)) -> Bianca Chen | E35: =INDEX(Assignments!$I$5:$I$58,MATCH($B$32&"|May|"&$A35,Assignments!$AD$5:$AD$58,0)) -> 46147 | F35: =TEXT(INDEX(Assignments!$O$5:$O$58,MATCH($B$32&"|May|"&$A35,Assignments!$AD$5:$AD$58,0)),"m/d h:mm AM/PM")&" - "&TEXT(INDEX(Assignments!$P$5:$P$58,MATCH($B$32&"|May|"&$A35,Assignments!$AD$5:$AD$58,0)),"h:mm AM/PM") -> 5/5 8:20 AM - 2:20 PM | G35: =INDEX(Assignments!$AC$5:$AC$58,MATCH($B$32&"|May|"&$A35,Assignments!$AD$5:$AD$58,0)) -> PASS
A36: OR-SAL | B36: =INDEX(Assignments!$D$5:$D$58,MATCH($B$32&"|May|"&$A36,Assignments!$AD$5:$AD$58,0)) -> Salem Ag Supply | C36: =INDEX(Assignments!$E$5:$E$58,MATCH($B$32&"|May|"&$A36,Assignments!$AD$5:$AD$58,0)) -> OR | D36: =INDEX(Assignments!$H$5:$H$58,MATCH($B$32&"|May|"&$A36,Assignments!$AD$5:$AD$58,0)) -> Darnell Fox | E36: =INDEX(Assignments!$I$5:$I$58,MATCH($B$32&"|May|"&$A36,Assignments!$AD$5:$AD$58,0)) -> 46154 | F36: =TEXT(INDEX(Assignments!$O$5:$O$58,MATCH($B$32&"|May|"&$A36,Assignments!$AD$5:$AD$58,0)),"m/d h:mm AM/PM")&" - "&TEXT(INDEX(Assignments!$P$5:$P$58,MATCH($B$32&"|May|"&$A36,Assignments!$AD$5:$AD$58,0)),"h:mm AM/PM") -> 5/12 6:50 AM - 5:20 PM | G36: =INDEX(Assignments!$AC$5:$AC$58,MATCH($B$32&"|May|"&$A36,Assignments!$AD$5:$AD$58,0)) -> PASS
A37: OR-BEN | B37: =INDEX(Assignments!$D$5:$D$58,MATCH($B$32&"|May|"&$A37,Assignments!$AD$5:$AD$58,0)) -> Bend Tractor & Turf | C37: =INDEX(Assignments!$E$5:$E$58,MATCH($B$32&"|May|"&$A37,Assignments!$AD$5:$AD$58,0)) -> OR | D37: =INDEX(Assignments!$H$5:$H$58,MATCH($B$32&"|May|"&$A37,Assignments!$AD$5:$AD$58,0)) -> Elena Ruiz | E37: =INDEX(Assignments!$I$5:$I$58,MATCH($B$32&"|May|"&$A37,Assignments!$AD$5:$AD$58,0)) -> 46161 | F37: =TEXT(INDEX(Assignments!$O$5:$O$58,MATCH($B$32&"|May|"&$A37,Assignments!$AD$5:$AD$58,0)),"m/d h:mm AM/PM")&" - "&TEXT(INDEX(Assignments!$P$5:$P$58,MATCH($B$32&"|May|"&$A37,Assignments!$AD$5:$AD$58,0)),"h:mm AM/PM") -> 5/19 6:00 AM - 7:00 PM | G37: =INDEX(Assignments!$AC$5:$AC$58,MATCH($B$32&"|May|"&$A37,Assignments!$AD$5:$AD$58,0)) -> PASS
A38: OR-ONT | B38: =INDEX(Assignments!$D$5:$D$58,MATCH($B$32&"|May|"&$A38,Assignments!$AD$5:$AD$58,0)) -> Ontario Equipment Depot | C38: =INDEX(Assignments!$E$5:$E$58,MATCH($B$32&"|May|"&$A38,Assignments!$AD$5:$AD$58,0)) -> OR | D38: =INDEX(Assignments!$H$5:$H$58,MATCH($B$32&"|May|"&$A38,Assignments!$AD$5:$AD$58,0)) -> Darnell Fox | E38: =INDEX(Assignments!$I$5:$I$58,MATCH($B$32&"|May|"&$A38,Assignments!$AD$5:$AD$58,0)) -> 46168 | F38: =TEXT(INDEX(Assignments!$O$5:$O$58,MATCH($B$32&"|May|"&$A38,Assignments!$AD$5:$AD$58,0)),"m/d h:mm AM/PM")&" - "&TEXT(INDEX(Assignments!$P$5:$P$58,MATCH($B$32&"|May|"&$A38,Assignments!$AD$5:$AD$58,0)),"h:mm AM/PM") -> 5/26 6:00 AM - 7:00 PM | G38: =INDEX(Assignments!$AC$5:$AC$58,MATCH($B$32&"|May|"&$A38,Assignments!$AD$5:$AD$58,0)) -> PASS
A39: OR-MED | B39: =INDEX(Assignments!$D$5:$D$58,MATCH($B$32&"|May|"&$A39,Assignments!$AD$5:$AD$58,0)) -> Medford Farm Center | C39: =INDEX(Assignments!$E$5:$E$58,MATCH($B$32&"|May|"&$A39,Assignments!$AD$5:$AD$58,0)) -> OR | D39: =INDEX(Assignments!$H$5:$H$58,MATCH($B$32&"|May|"&$A39,Assignments!$AD$5:$AD$58,0)) -> Avery Lane | E39: =INDEX(Assignments!$I$5:$I$58,MATCH($B$32&"|May|"&$A39,Assignments!$AD$5:$AD$58,0)) -> 46147 | F39: =TEXT(INDEX(Assignments!$O$5:$O$58,MATCH($B$32&"|May|"&$A39,Assignments!$AD$5:$AD$58,0)),"m/d h:mm AM/PM")&" - "&TEXT(INDEX(Assignments!$P$5:$P$58,MATCH($B$32&"|May|"&$A39,Assignments!$AD$5:$AD$58,0)),"h:mm AM/PM") -> 5/5 5:00 AM - 9:00 PM | G39: =INDEX(Assignments!$AC$5:$AC$58,MATCH($B$32&"|May|"&$A39,Assignments!$AD$5:$AD$58,0)) -> PASS
A40: OR-PEN | B40: =INDEX(Assignments!$D$5:$D$58,MATCH($B$32&"|May|"&$A40,Assignments!$AD$5:$AD$58,0)) -> Pendleton Ranch Supply | C40: =INDEX(Assignments!$E$5:$E$58,MATCH($B$32&"|May|"&$A40,Assignments!$AD$5:$AD$58,0)) -> OR | D40: =INDEX(Assignments!$H$5:$H$58,MATCH($B$32&"|May|"&$A40,Assignments!$AD$5:$AD$58,0)) -> Elena Ruiz | E40: =INDEX(Assignments!$I$5:$I$58,MATCH($B$32&"|May|"&$A40,Assignments!$AD$5:$AD$58,0)) -> 46161 | F40: =TEXT(INDEX(Assignments!$O$5:$O$58,MATCH($B$32&"|May|"&$A40,Assignments!$AD$5:$AD$58,0)),"m/d h:mm AM/PM")&" - "&TEXT(INDEX(Assignments!$P$5:$P$58,MATCH($B$32&"|May|"&$A40,Assignments!$AD$5:$AD$58,0)),"h:mm AM/PM") -> 5/19 6:45 AM - 5:30 PM | G40: =INDEX(Assignments!$AC$5:$AC$58,MATCH($B$32&"|May|"&$A40,Assignments!$AD$5:$AD$58,0)) -> PASS
A41: WA-YAK | B41: =INDEX(Assignments!$D$5:$D$58,MATCH($B$32&"|May|"&$A41,Assignments!$AD$5:$AD$58,0)) -> Yakima Orchard & Field | C41: =INDEX(Assignments!$E$5:$E$58,MATCH($B$32&"|May|"&$A41,Assignments!$AD$5:$AD$58,0)) -> WA | D41: =INDEX(Assignments!$H$5:$H$58,MATCH($B$32&"|May|"&$A41,Assignments!$AD$5:$AD$58,0)) -> Avery Lane | E41: =INDEX(Assignments!$I$5:$I$58,MATCH($B$32&"|May|"&$A41,Assignments!$AD$5:$AD$58,0)) -> 46154 | F41: =TEXT(INDEX(Assignments!$O$5:$O$58,MATCH($B$32&"|May|"&$A41,Assignments!$AD$5:$AD$58,0)),"m/d h:mm AM/PM")&" - "&TEXT(INDEX(Assignments!$P$5:$P$58,MATCH($B$32&"|May|"&$A41,Assignments!$AD$5:$AD$58,0)),"h:mm AM/PM") -> 5/12 6:00 AM - 7:00 PM | G41: =INDEX(Assignments!$AC$5:$AC$58,MATCH($B$32&"|May|"&$A41,Assignments!$AD$5:$AD$58,0)) -> PASS
A42: WA-VAN | B42: =INDEX(Assignments!$D$5:$D$58,MATCH($B$32&"|May|"&$A42,Assignments!$AD$5:$AD$58,0)) -> Vancouver Farm Supply | C42: =INDEX(Assignments!$E$5:$E$58,MATCH($B$32&"|May|"&$A42,Assignments!$AD$5:$AD$58,0)) -> WA | D42: =INDEX(Assignments!$H$5:$H$58,MATCH($B$32&"|May|"&$A42,Assignments!$AD$5:$AD$58,0)) -> Malik Brooks | E42: =INDEX(Assignments!$I$5:$I$58,MATCH($B$32&"|May|"&$A42,Assignments!$AD$5:$AD$58,0)) -> 46168 | F42: =TEXT(INDEX(Assignments!$O$5:$O$58,MATCH($B$32&"|May|"&$A42,Assignments!$AD$5:$AD$58,0)),"m/d h:mm AM/PM")&" - "&TEXT(INDEX(Assignments!$P$5:$P$58,MATCH($B$32&"|May|"&$A42,Assignments!$AD$5:$AD$58,0)),"h:mm AM/PM") -> 5/26 5:45 AM - 7:30 PM | G42: =INDEX(Assignments!$AC$5:$AC$58,MATCH($B$32&"|May|"&$A42,Assignments!$AD$5:$AD$58,0)) -> PASS
A43: WA-WAL | B43: =INDEX(Assignments!$D$5:$D$58,MATCH($B$32&"|May|"&$A43,Assignments!$AD$5:$AD$58,0)) -> Walla Walla Tractor Co. | C43: =INDEX(Assignments!$E$5:$E$58,MATCH($B$32&"|May|"&$A43,Assignments!$AD$5:$AD$58,0)) -> WA | D43: =INDEX(Assignments!$H$5:$H$58,MATCH($B$32&"|May|"&$A43,Assignments!$AD$5:$AD$58,0)) -> Malik Brooks | E43: =INDEX(Assignments!$I$5:$I$58,MATCH($B$32&"|May|"&$A43,Assignments!$AD$5:$AD$58,0)) -> 46161 | F43: =TEXT(INDEX(Assignments!$O$5:$O$58,MATCH($B$32&"|May|"&$A43,Assignments!$AD$5:$AD$58,0)),"m/d h:mm AM/PM")&" - "&TEXT(INDEX(Assignments!$P$5:$P$58,MATCH($B$32&"|May|"&$A43,Assignments!$AD$5:$AD$58,0)),"h:mm AM/PM") -> 5/19 6:10 AM - 6:40 PM | G43: =INDEX(Assignments!$AC$5:$AC$58,MATCH($B$32&"|May|"&$A43,Assignments!$AD$5:$AD$58,0)) -> PASS
A46: Store teams: prepare recalled-product records and a clear display route before the listed work period.
