Workbook

Sheet Recovery dashboard
A1: Retrofit recovery plan
A2: Ambergate Housing Trust | decision position at 11 May 2026
A4: Authorisation status | B4: =IF(COUNTIF($B$21:$B$28,"FAIL")=0,"READY FOR AUTHORISATION","ACTION REQUIRED") -> READY FOR AUTHORISATION
A6: Recovery position | E6: Regulatory milestones
A7: Selected packages | B7: ='Capacity & finance'!F5 -> 7 | C7: Maximum permitted: 7 | E7: Milestone | F7: Planned timestamp | G7: Accountable | H7: Status
A8: Permit criteria covered | B8: =COUNTIF('Permit coverage'!$E$6:$E$17,"COVERED") -> 12 | C8: Required: 12 | E8: Final commissioning evidence | F8: =MAX('Shift plan'!$H$6:$H$27) -> 46170.917 | G8: Lorcan Ibarra | H8: =IF(F8<='Capacity & finance'!$B$10,"ON TIME","LATE") -> ON TIME
A9: Engineer shifts used | B9: ='Capacity & finance'!F10 -> 8 | C9: Listed availability: 8 | E9: Quality review | F9: ='Shift plan'!$G$31 -> 46171.375 | G9: Magda Villanueva | H9: ='Shift plan'!$N$31 -> OK
A10: Daily capacity | B10: =IF(COUNTIF('Capacity & finance'!$G$18:$G$26,"OVER")=0,"WITHIN LIMIT","OVER LIMIT") -> WITHIN LIMIT | C10: 20 May and 26 May are 12h limits | E10: Regulator submission | F10: ='Shift plan'!$G$32 -> 46171.562 | G10: Magda Villanueva | H10: ='Shift plan'!$N$32 -> OK
A11: Delivery cost | B11: ='Capacity & finance'!F12 -> 46224 | C11: Delivery cap excludes exposure | E11: Submission deadline | F11: ='Capacity & finance'!$B$11 -> 46171.583 | G11: Magda Villanueva | H11: =IF(F11<='Capacity & finance'!$B$11,"ON TIME","LATE") -> ON TIME
A12: Forecast exposure | B12: ='Capacity & finance'!F14 -> 47655 | C12: Inclusive calendar-day convention
A13: Combined financial impact | B13: ='Capacity & finance'!F15 -> 93879 | C13: Delivery cost plus exposure
A19: Formula-driven compliance checks
A20: Control | B20: Status | C20: Formula evidence | D20: Meeting focus
A21: Selection eligibility and cap | B21: =IF(AND('Capacity & finance'!$F$5<=7,'Capacity & finance'!$F$5='Capacity & finance'!$F$6,COUNTIFS('Package decision'!$B$6:$B$27,"Yes",'Package decision'!$Z$6:$Z$27,"<>Eligible")=0),"PASS","FAIL") -> PASS | C21: Selected count, eligibility and source conditions | D21: No ineligible or excess package
A22: Permit coverage | B22: =IF(COUNTIF('Permit coverage'!$E$6:$E$17,"COVERED")=12,"PASS","FAIL") -> PASS | C22: All twelve tag rows recompute from source mapping | D22: Every unit has three closures
A23: Access, readiness, dependency and blackout | B23: =IF(COUNTIF('Package decision'!$AA$6:$AA$27,"CHECK")+COUNTIF('Package decision'!$AB$6:$AB$27,"CHECK")+COUNTIF('Package decision'!$AC$6:$AC$27,"CHECK")=0,"PASS","FAIL") -> PASS | C23: Selected package validation columns | D23: Dates must remain in their source windows
A24: Engineer allocation and recalibration | B24: =IF(AND('Capacity & finance'!$F$10<=8,COUNTIF('Capacity & finance'!$L$50:$L$57,"DOUBLE BOOKED")=0,COUNTIF('Capacity & finance'!$M$50:$M$57,"MISSING RECAL")=0,SUM('Capacity & finance'!$J$50:$J$57)='Capacity & finance'!$F$9),"PASS","FAIL") -> PASS | C24: Eight listed engineer shifts and family-transition controls | D24: One dedicated recalibration shift
A25: Daily field capacity | B25: =IF(COUNTIF('Capacity & finance'!$G$18:$G$26,"OVER")=0,"PASS","FAIL") -> PASS | C25: Daily scheduled technician effort vs capacity | D25: Occupied-site caps bind on 20 and 26 May
A26: Testing cutoff | B26: =IF(COUNTIF('Shift plan'!$Q$6:$Q$29,"CHECK")=0,"PASS","FAIL") -> PASS | C26: Intrusive commissioning completion by 23:00 on 28 May | D26: Final test must stay before review
A27: Quality review and submission | B27: =IF(AND('Shift plan'!$N$31="OK",'Shift plan'!$N$32="OK",'Shift plan'!$P$31="OK",'Shift plan'!$P$32="OK"),"PASS","FAIL") -> PASS | C27: Review sequence, workday and deadline formula checks | D27: Quality review before regulator submission
A28: Delivery-cost cap | B28: =IF('Capacity & finance'!$F$12<='Capacity & finance'!$B$8,"PASS","FAIL") -> PASS | C28: Fixed, technician, engineer and recalibration components | D28: Exposure remains outside this cap
A30: Decision | B30: =IF(B4="READY FOR AUTHORISATION","Authorise the grouped Horizon-then-Kestrel portfolio; it closes all permit tags with seven tests and one recalibration shift.","Resolve the failed control before authorisation.") -> Authorise the grouped Horizon-then-Kestrel portfolio; it closes all permit tags with seven tests and one recalibration shift.

Sheet Package decision
A1: Package decision
A2: Authorise only the seven released implementation packages that close all permit tags; inputs are shaded
A3: Selection, plan date and plan shift are the calculation drivers. Source fields are retained for traceability.
A5: Package ID | B5: Select? | C5: Plant room | D5: Equipment family | E5: Work description | F5: Record type | G5: Release status | H5: Superseded by | I5: Evidence | J5: Confidence | K5: Permit tags | L5: Site ready | M5: Access from | N5: Access to | O5: Permitted shift | P5: Predecessor | Q5: Source tech h | R5: Assumption h | S5: Effective tech h | T5: Fixed cost | U5: Engineer test? | V5: Accountable | W5: Comparable ref | X5: Plan date | Y5: Plan shift | Z5: Source eligibility | AA5: Window / readiness | AB5: Dependency | AC5: Blackout | AD5: Completion timestamp | AE5: Decision rationale
A6: CG-101 | B6: Yes | C6: Crossgate | D6: Horizon | E6: Analyzer trim and telemetry prove-out | F6: Implementation | G6: Released | I6: A | J6: 0.92 | K6: CG-AC, CG-TC | L6: 46160 | M6: 46160 | N6: 46160 | O6: PM | Q6: 8 | R6: =IF(Q6="",IFERROR(VLOOKUP(A6,Assumptions!$A$6:$H$8,8,FALSE()),""),"") | S6: =IF(Q6<>"",Q6,R6) -> 8 | T6: 3900 | U6: Yes | V6: Lorcan Ibarra | X6: 46160 | Y6: PM | Z6: =IF(AND(F6="Implementation",G6="Released",H6="",OR(I6="A",I6="B"),J6>=80%),"Eligible","Ineligible") -> Eligible | AA6: =IF(B6<>"Yes","n/a",IF(AND(X6>=L6,X6>=M6,X6<=N6,Y6=O6),"OK","CHECK")) -> OK | AB6: =IF(B6<>"Yes","n/a",IF(P6="","n/a",IFERROR(IF(AND(VLOOKUP(P6,$A$6:$AD$27,2,FALSE())="Yes",VLOOKUP(P6,$A$6:$AD$27,30,FALSE())<=X6+IF(Y6="AM",TIME(8,0,0),TIME(14,0,0))),"OK","CHECK"),"CHECK"))) -> n/a | AC6: =IF(B6<>"Yes","n/a",IF(COUNTIFS(Calendar!$I$6:$I$12,C6,Calendar!$J$6:$J$12,X6,Calendar!$K$6:$K$12,Y6)=0,"OK","CHECK")) -> OK | AD6: =IF(B6="Yes",X6+IF(Y6="AM",TIME(13,0,0),TIME(22,0,0)),"") -> 46160.917 | AE6: Selected: released A-grade opening Horizon test closes Crossgate analyzer and telemetry tags.
A7: CG-102 | B7: Yes | C7: Crossgate | D7: Horizon | E7: Audit trail capture and witnessed evidence | F7: Implementation | G7: Released | I7: B | J7: 0.86 | K7: CG-AW | L7: 46160 | M7: 46161 | N7: 46161 | O7: AM | P7: CG-101 | R7: =IF(Q7="",IFERROR(VLOOKUP(A7,Assumptions!$A$6:$H$8,8,FALSE()),""),"") -> 5 | S7: =IF(Q7<>"",Q7,R7) -> 5 | T7: 2350 | U7: Yes | V7: Lorcan Ibarra | W7: HZN-AUD-02 | X7: 46161 | Y7: AM | Z7: =IF(AND(F7="Implementation",G7="Released",H7="",OR(I7="A",I7="B"),J7>=80%),"Eligible","Ineligible") -> Eligible | AA7: =IF(B7<>"Yes","n/a",IF(AND(X7>=L7,X7>=M7,X7<=N7,Y7=O7),"OK","CHECK")) -> OK | AB7: =IF(B7<>"Yes","n/a",IF(P7="","n/a",IFERROR(IF(AND(VLOOKUP(P7,$A$6:$AD$27,2,FALSE())="Yes",VLOOKUP(P7,$A$6:$AD$27,30,FALSE())<=X7+IF(Y7="AM",TIME(8,0,0),TIME(14,0,0))),"OK","CHECK"),"CHECK"))) -> OK | AC7: =IF(B7<>"Yes","n/a",IF(COUNTIFS(Calendar!$I$6:$I$12,C7,Calendar!$J$6:$J$12,X7,Calendar!$K$6:$K$12,Y7)=0,"OK","CHECK")) -> OK | AD7: =IF(B7="Yes",X7+IF(Y7="AM",TIME(13,0,0),TIME(22,0,0)),"") -> 46161.542 | AE7: Selected: released B-grade witness package closes Crossgate audit tag; comparable-range assumption is stated.
A8: CG-103 | B8: No | C8: Crossgate | D8: Horizon | E8: Alternate analyzer calibration with audit capture | F8: Implementation | G8: Released | I8: A | J8: 0.9 | K8: CG-AC | L8: 46160 | M8: 46160 | N8: 46160 | O8: PM | Q8: 9 | R8: =IF(Q8="",IFERROR(VLOOKUP(A8,Assumptions!$A$6:$H$8,8,FALSE()),""),"") | S8: =IF(Q8<>"",Q8,R8) -> 9 | T8: 4200 | U8: Yes | V8: Lorcan Ibarra | X8: 46160 | Y8: PM | Z8: =IF(AND(F8="Implementation",G8="Released",H8="",OR(I8="A",I8="B"),J8>=80%),"Eligible","Ineligible") -> Eligible | AA8: =IF(B8<>"Yes","n/a",IF(AND(X8>=L8,X8>=M8,X8<=N8,Y8=O8),"OK","CHECK")) -> n/a | AB8: =IF(B8<>"Yes","n/a",IF(P8="","n/a",IFERROR(IF(AND(VLOOKUP(P8,$A$6:$AD$27,2,FALSE())="Yes",VLOOKUP(P8,$A$6:$AD$27,30,FALSE())<=X8+IF(Y8="AM",TIME(8,0,0),TIME(14,0,0))),"OK","CHECK"),"CHECK"))) -> n/a | AC8: =IF(B8<>"Yes","n/a",IF(COUNTIFS(Calendar!$I$6:$I$12,C8,Calendar!$J$6:$J$12,X8,Calendar!$K$6:$K$12,Y8)=0,"OK","CHECK")) -> n/a | AD8: =IF(B8="Yes",X8+IF(Y8="AM",TIME(13,0,0),TIME(22,0,0)),"") | AE8: Excluded: released alternate occupies the same constrained Horizon slot and adds no earlier closure.
A9: CG-104 | B9: No | C9: Crossgate | D9: Horizon | E9: Alternate telemetry and witnessed evidence verification | F9: Implementation | G9: Released | I9: B | J9: 0.85 | K9: CG-TC, CG-AW | L9: 46160 | M9: 46161 | N9: 46161 | O9: AM | P9: CG-103 | R9: =IF(Q9="",IFERROR(VLOOKUP(A9,Assumptions!$A$6:$H$8,8,FALSE()),""),"") -> 5 | S9: =IF(Q9<>"",Q9,R9) -> 5 | T9: 2450 | U9: Yes | V9: Lorcan Ibarra | W9: HZN-AUD-02 | X9: 46161 | Y9: AM | Z9: =IF(AND(F9="Implementation",G9="Released",H9="",OR(I9="A",I9="B"),J9>=80%),"Eligible","Ineligible") -> Eligible | AA9: =IF(B9<>"Yes","n/a",IF(AND(X9>=L9,X9>=M9,X9<=N9,Y9=O9),"OK","CHECK")) -> n/a | AB9: =IF(B9<>"Yes","n/a",IF(P9="","n/a",IFERROR(IF(AND(VLOOKUP(P9,$A$6:$AD$27,2,FALSE())="Yes",VLOOKUP(P9,$A$6:$AD$27,30,FALSE())<=X9+IF(Y9="AM",TIME(8,0,0),TIME(14,0,0))),"OK","CHECK"),"CHECK"))) -> n/a | AC9: =IF(B9<>"Yes","n/a",IF(COUNTIFS(Calendar!$I$6:$I$12,C9,Calendar!$J$6:$J$12,X9,Calendar!$K$6:$K$12,Y9)=0,"OK","CHECK")) -> n/a | AD9: =IF(B9="Yes",X9+IF(Y9="AM",TIME(13,0,0),TIME(22,0,0)),"") | AE9: Excluded: paired alternate is not needed once CG-101/CG-102 close the three Crossgate tags.
A10: MH-201 | B10: Yes | C10: Millhaven | D10: Horizon | E10: Analyzer calibration and evidence chain | F10: Implementation | G10: Released | I10: A | J10: 0.94 | K10: MH-AC, MH-AW | L10: 46162 | M10: 46162 | N10: 46162 | O10: PM | Q10: 12 | R10: =IF(Q10="",IFERROR(VLOOKUP(A10,Assumptions!$A$6:$H$8,8,FALSE()),""),"") | S10: =IF(Q10<>"",Q10,R10) -> 12 | T10: 4800 | U10: Yes | V10: Lorcan Ibarra | X10: 46162 | Y10: PM | Z10: =IF(AND(F10="Implementation",G10="Released",H10="",OR(I10="A",I10="B"),J10>=80%),"Eligible","Ineligible") -> Eligible | AA10: =IF(B10<>"Yes","n/a",IF(AND(X10>=L10,X10>=M10,X10<=N10,Y10=O10),"OK","CHECK")) -> OK | AB10: =IF(B10<>"Yes","n/a",IF(P10="","n/a",IFERROR(IF(AND(VLOOKUP(P10,$A$6:$AD$27,2,FALSE())="Yes",VLOOKUP(P10,$A$6:$AD$27,30,FALSE())<=X10+IF(Y10="AM",TIME(8,0,0),TIME(14,0,0))),"OK","CHECK"),"CHECK"))) -> n/a | AC10: =IF(B10<>"Yes","n/a",IF(COUNTIFS(Calendar!$I$6:$I$12,C10,Calendar!$J$6:$J$12,X10,Calendar!$K$6:$K$12,Y10)=0,"OK","CHECK")) -> OK | AD10: =IF(B10="Yes",X10+IF(Y10="AM",TIME(13,0,0),TIME(22,0,0)),"") -> 46162.917 | AE10: Selected: released A-grade package closes Millhaven analyzer and audit tags in its held occupied-site slot.
A11: MH-202 | B11: Yes | C11: Millhaven | D11: Horizon | E11: Telemetry continuity proving run | F11: Implementation | G11: Released | I11: B | J11: 0.88 | K11: MH-TC | L11: 46162 | M11: 46163 | N11: 46163 | O11: AM | P11: MH-201 | Q11: 6 | R11: =IF(Q11="",IFERROR(VLOOKUP(A11,Assumptions!$A$6:$H$8,8,FALSE()),""),"") | S11: =IF(Q11<>"",Q11,R11) -> 6 | T11: 2100 | U11: Yes | V11: Lorcan Ibarra | X11: 46163 | Y11: AM | Z11: =IF(AND(F11="Implementation",G11="Released",H11="",OR(I11="A",I11="B"),J11>=80%),"Eligible","Ineligible") -> Eligible | AA11: =IF(B11<>"Yes","n/a",IF(AND(X11>=L11,X11>=M11,X11<=N11,Y11=O11),"OK","CHECK")) -> OK | AB11: =IF(B11<>"Yes","n/a",IF(P11="","n/a",IFERROR(IF(AND(VLOOKUP(P11,$A$6:$AD$27,2,FALSE())="Yes",VLOOKUP(P11,$A$6:$AD$27,30,FALSE())<=X11+IF(Y11="AM",TIME(8,0,0),TIME(14,0,0))),"OK","CHECK"),"CHECK"))) -> OK | AC11: =IF(B11<>"Yes","n/a",IF(COUNTIFS(Calendar!$I$6:$I$12,C11,Calendar!$J$6:$J$12,X11,Calendar!$K$6:$K$12,Y11)=0,"OK","CHECK")) -> OK | AD11: =IF(B11="Yes",X11+IF(Y11="AM",TIME(13,0,0),TIME(22,0,0)),"") -> 46163.542 | AE11: Selected: released B-grade telemetry test follows MH-201 and completes Millhaven closure.
A12: MH-203 | B12: No | C12: Millhaven | D12: Horizon | E12: Alternate analyzer and telemetry set-up | F12: Implementation | G12: Released | I12: A | J12: 0.91 | K12: MH-AC, MH-TC | L12: 46162 | M12: 46162 | N12: 46162 | O12: PM | Q12: 12 | R12: =IF(Q12="",IFERROR(VLOOKUP(A12,Assumptions!$A$6:$H$8,8,FALSE()),""),"") | S12: =IF(Q12<>"",Q12,R12) -> 12 | T12: 4950 | U12: Yes | V12: Lorcan Ibarra | X12: 46162 | Y12: PM | Z12: =IF(AND(F12="Implementation",G12="Released",H12="",OR(I12="A",I12="B"),J12>=80%),"Eligible","Ineligible") -> Eligible | AA12: =IF(B12<>"Yes","n/a",IF(AND(X12>=L12,X12>=M12,X12<=N12,Y12=O12),"OK","CHECK")) -> n/a | AB12: =IF(B12<>"Yes","n/a",IF(P12="","n/a",IFERROR(IF(AND(VLOOKUP(P12,$A$6:$AD$27,2,FALSE())="Yes",VLOOKUP(P12,$A$6:$AD$27,30,FALSE())<=X12+IF(Y12="AM",TIME(8,0,0),TIME(14,0,0))),"OK","CHECK"),"CHECK"))) -> n/a | AC12: =IF(B12<>"Yes","n/a",IF(COUNTIFS(Calendar!$I$6:$I$12,C12,Calendar!$J$6:$J$12,X12,Calendar!$K$6:$K$12,Y12)=0,"OK","CHECK")) -> n/a | AD12: =IF(B12="Yes",X12+IF(Y12="AM",TIME(13,0,0),TIME(22,0,0)),"") | AE12: Excluded: alternate uses the same 20 May occupied-site engineer and technician allocation.
A13: MH-204 | B13: No | C13: Millhaven | D13: Horizon | E13: Alternate witnessed audit pack | F13: Implementation | G13: Released | I13: B | J13: 0.84 | K13: MH-AW | L13: 46162 | M13: 46163 | N13: 46163 | O13: AM | P13: MH-203 | Q13: 5 | R13: =IF(Q13="",IFERROR(VLOOKUP(A13,Assumptions!$A$6:$H$8,8,FALSE()),""),"") | S13: =IF(Q13<>"",Q13,R13) -> 5 | T13: 2300 | U13: Yes | V13: Lorcan Ibarra | X13: 46163 | Y13: AM | Z13: =IF(AND(F13="Implementation",G13="Released",H13="",OR(I13="A",I13="B"),J13>=80%),"Eligible","Ineligible") -> Eligible | AA13: =IF(B13<>"Yes","n/a",IF(AND(X13>=L13,X13>=M13,X13<=N13,Y13=O13),"OK","CHECK")) -> n/a | AB13: =IF(B13<>"Yes","n/a",IF(P13="","n/a",IFERROR(IF(AND(VLOOKUP(P13,$A$6:$AD$27,2,FALSE())="Yes",VLOOKUP(P13,$A$6:$AD$27,30,FALSE())<=X13+IF(Y13="AM",TIME(8,0,0),TIME(14,0,0))),"OK","CHECK"),"CHECK"))) -> n/a | AC13: =IF(B13<>"Yes","n/a",IF(COUNTIFS(Calendar!$I$6:$I$12,C13,Calendar!$J$6:$J$12,X13,Calendar!$K$6:$K$12,Y13)=0,"OK","CHECK")) -> n/a | AD13: =IF(B13="Yes",X13+IF(Y13="AM",TIME(13,0,0),TIME(22,0,0)),"") | AE13: Excluded: paired alternate does not improve coverage, capacity, or completion date.
A14: DS-301 | B14: Yes | C14: Docksett | D14: Kestrel | E14: Analyzer trim and telemetry proving run | F14: Implementation | G14: Released | I14: A | J14: 0.93 | K14: DS-AC, DS-TC | L14: 46168 | M14: 46168 | N14: 46168 | O14: PM | Q14: 12 | R14: =IF(Q14="",IFERROR(VLOOKUP(A14,Assumptions!$A$6:$H$8,8,FALSE()),""),"") | S14: =IF(Q14<>"",Q14,R14) -> 12 | T14: 4650 | U14: Yes | V14: Lorcan Ibarra | X14: 46168 | Y14: PM | Z14: =IF(AND(F14="Implementation",G14="Released",H14="",OR(I14="A",I14="B"),J14>=80%),"Eligible","Ineligible") -> Eligible | AA14: =IF(B14<>"Yes","n/a",IF(AND(X14>=L14,X14>=M14,X14<=N14,Y14=O14),"OK","CHECK")) -> OK | AB14: =IF(B14<>"Yes","n/a",IF(P14="","n/a",IFERROR(IF(AND(VLOOKUP(P14,$A$6:$AD$27,2,FALSE())="Yes",VLOOKUP(P14,$A$6:$AD$27,30,FALSE())<=X14+IF(Y14="AM",TIME(8,0,0),TIME(14,0,0))),"OK","CHECK"),"CHECK"))) -> n/a | AC14: =IF(B14<>"Yes","n/a",IF(COUNTIFS(Calendar!$I$6:$I$12,C14,Calendar!$J$6:$J$12,X14,Calendar!$K$6:$K$12,Y14)=0,"OK","CHECK")) -> OK | AD14: =IF(B14="Yes",X14+IF(Y14="AM",TIME(13,0,0),TIME(22,0,0)),"") -> 46168.917 | AE14: Selected: released A-grade Kestrel package uses the held 26 May occupied-site allocation.
A15: DS-302 | B15: Yes | C15: Docksett | D15: Kestrel | E15: Audit trail capture and witnessed evidence | F15: Implementation | G15: Released | I15: B | J15: 0.87 | K15: DS-AW | L15: 46168 | M15: 46169 | N15: 46169 | O15: AM | P15: DS-301 | R15: =IF(Q15="",IFERROR(VLOOKUP(A15,Assumptions!$A$6:$H$8,8,FALSE()),""),"") -> 6 | S15: =IF(Q15<>"",Q15,R15) -> 6 | T15: 2450 | U15: Yes | V15: Lorcan Ibarra | W15: KST-AUD-07 | X15: 46169 | Y15: AM | Z15: =IF(AND(F15="Implementation",G15="Released",H15="",OR(I15="A",I15="B"),J15>=80%),"Eligible","Ineligible") -> Eligible | AA15: =IF(B15<>"Yes","n/a",IF(AND(X15>=L15,X15>=M15,X15<=N15,Y15=O15),"OK","CHECK")) -> OK | AB15: =IF(B15<>"Yes","n/a",IF(P15="","n/a",IFERROR(IF(AND(VLOOKUP(P15,$A$6:$AD$27,2,FALSE())="Yes",VLOOKUP(P15,$A$6:$AD$27,30,FALSE())<=X15+IF(Y15="AM",TIME(8,0,0),TIME(14,0,0))),"OK","CHECK"),"CHECK"))) -> OK | AC15: =IF(B15<>"Yes","n/a",IF(COUNTIFS(Calendar!$I$6:$I$12,C15,Calendar!$J$6:$J$12,X15,Calendar!$K$6:$K$12,Y15)=0,"OK","CHECK")) -> OK | AD15: =IF(B15="Yes",X15+IF(Y15="AM",TIME(13,0,0),TIME(22,0,0)),"") -> 46169.542 | AE15: Selected: released B-grade witness package completes Docksett after DS-301; assumption is stated.
A16: DS-303 | B16: No | C16: Docksett | D16: Kestrel | E16: Alternate analyzer calibration with audit capture | F16: Implementation | G16: Released | I16: A | J16: 0.9 | K16: DS-AC, DS-AW | L16: 46168 | M16: 46168 | N16: 46168 | O16: PM | Q16: 12 | R16: =IF(Q16="",IFERROR(VLOOKUP(A16,Assumptions!$A$6:$H$8,8,FALSE()),""),"") | S16: =IF(Q16<>"",Q16,R16) -> 12 | T16: 5000 | U16: Yes | V16: Lorcan Ibarra | X16: 46168 | Y16: PM | Z16: =IF(AND(F16="Implementation",G16="Released",H16="",OR(I16="A",I16="B"),J16>=80%),"Eligible","Ineligible") -> Eligible | AA16: =IF(B16<>"Yes","n/a",IF(AND(X16>=L16,X16>=M16,X16<=N16,Y16=O16),"OK","CHECK")) -> n/a | AB16: =IF(B16<>"Yes","n/a",IF(P16="","n/a",IFERROR(IF(AND(VLOOKUP(P16,$A$6:$AD$27,2,FALSE())="Yes",VLOOKUP(P16,$A$6:$AD$27,30,FALSE())<=X16+IF(Y16="AM",TIME(8,0,0),TIME(14,0,0))),"OK","CHECK"),"CHECK"))) -> n/a | AC16: =IF(B16<>"Yes","n/a",IF(COUNTIFS(Calendar!$I$6:$I$12,C16,Calendar!$J$6:$J$12,X16,Calendar!$K$6:$K$12,Y16)=0,"OK","CHECK")) -> n/a | AD16: =IF(B16="Yes",X16+IF(Y16="AM",TIME(13,0,0),TIME(22,0,0)),"") | AE16: Excluded: alternate occupies the same Kestrel engineer slot and offers no earlier completion.
A17: DS-304 | B17: No | C17: Docksett | D17: Kestrel | E17: Alternate telemetry continuity verification | F17: Implementation | G17: Released | I17: B | J17: 0.85 | K17: DS-TC | L17: 46168 | M17: 46169 | N17: 46169 | O17: AM | P17: DS-303 | Q17: 5 | R17: =IF(Q17="",IFERROR(VLOOKUP(A17,Assumptions!$A$6:$H$8,8,FALSE()),""),"") | S17: =IF(Q17<>"",Q17,R17) -> 5 | T17: 2300 | U17: Yes | V17: Lorcan Ibarra | X17: 46169 | Y17: AM | Z17: =IF(AND(F17="Implementation",G17="Released",H17="",OR(I17="A",I17="B"),J17>=80%),"Eligible","Ineligible") -> Eligible | AA17: =IF(B17<>"Yes","n/a",IF(AND(X17>=L17,X17>=M17,X17<=N17,Y17=O17),"OK","CHECK")) -> n/a | AB17: =IF(B17<>"Yes","n/a",IF(P17="","n/a",IFERROR(IF(AND(VLOOKUP(P17,$A$6:$AD$27,2,FALSE())="Yes",VLOOKUP(P17,$A$6:$AD$27,30,FALSE())<=X17+IF(Y17="AM",TIME(8,0,0),TIME(14,0,0))),"OK","CHECK"),"CHECK"))) -> n/a | AC17: =IF(B17<>"Yes","n/a",IF(COUNTIFS(Calendar!$I$6:$I$12,C17,Calendar!$J$6:$J$12,X17,Calendar!$K$6:$K$12,Y17)=0,"OK","CHECK")) -> n/a | AD17: =IF(B17="Yes",X17+IF(Y17="AM",TIME(13,0,0),TIME(22,0,0)),"") | AE17: Excluded: paired alternate does not improve permit closure or the grouped family sequence.
A18: LF-401 | B18: Yes | C18: Larkfield | D18: Kestrel | E18: Integrated analyzer, telemetry and witness close-out | F18: Implementation | G18: Released | I18: A | J18: 0.95 | K18: LF-AC, LF-TC, LF-AW | L18: 46170 | M18: 46170 | N18: 46170 | O18: PM | Q18: 18 | R18: =IF(Q18="",IFERROR(VLOOKUP(A18,Assumptions!$A$6:$H$8,8,FALSE()),""),"") | S18: =IF(Q18<>"",Q18,R18) -> 18 | T18: 5100 | U18: Yes | V18: Lorcan Ibarra | X18: 46170 | Y18: PM | Z18: =IF(AND(F18="Implementation",G18="Released",H18="",OR(I18="A",I18="B"),J18>=80%),"Eligible","Ineligible") -> Eligible | AA18: =IF(B18<>"Yes","n/a",IF(AND(X18>=L18,X18>=M18,X18<=N18,Y18=O18),"OK","CHECK")) -> OK | AB18: =IF(B18<>"Yes","n/a",IF(P18="","n/a",IFERROR(IF(AND(VLOOKUP(P18,$A$6:$AD$27,2,FALSE())="Yes",VLOOKUP(P18,$A$6:$AD$27,30,FALSE())<=X18+IF(Y18="AM",TIME(8,0,0),TIME(14,0,0))),"OK","CHECK"),"CHECK"))) -> n/a | AC18: =IF(B18<>"Yes","n/a",IF(COUNTIFS(Calendar!$I$6:$I$12,C18,Calendar!$J$6:$J$12,X18,Calendar!$K$6:$K$12,Y18)=0,"OK","CHECK")) -> OK | AD18: =IF(B18="Yes",X18+IF(Y18="AM",TIME(13,0,0),TIME(22,0,0)),"") -> 46170.917 | AE18: Selected: one released package closes all three Larkfield tags in the final Kestrel test slot.
A19: LF-402 | B19: No | C19: Larkfield | D19: Kestrel | E19: Analyzer-only intervention | F19: Implementation | G19: Released | I19: B | J19: 0.89 | K19: LF-AC | L19: 46170 | M19: 46170 | N19: 46170 | O19: PM | Q19: 6 | R19: =IF(Q19="",IFERROR(VLOOKUP(A19,Assumptions!$A$6:$H$8,8,FALSE()),""),"") | S19: =IF(Q19<>"",Q19,R19) -> 6 | T19: 1650 | U19: Yes | V19: Lorcan Ibarra | X19: 46170 | Y19: PM | Z19: =IF(AND(F19="Implementation",G19="Released",H19="",OR(I19="A",I19="B"),J19>=80%),"Eligible","Ineligible") -> Eligible | AA19: =IF(B19<>"Yes","n/a",IF(AND(X19>=L19,X19>=M19,X19<=N19,Y19=O19),"OK","CHECK")) -> n/a | AB19: =IF(B19<>"Yes","n/a",IF(P19="","n/a",IFERROR(IF(AND(VLOOKUP(P19,$A$6:$AD$27,2,FALSE())="Yes",VLOOKUP(P19,$A$6:$AD$27,30,FALSE())<=X19+IF(Y19="AM",TIME(8,0,0),TIME(14,0,0))),"OK","CHECK"),"CHECK"))) -> n/a | AC19: =IF(B19<>"Yes","n/a",IF(COUNTIFS(Calendar!$I$6:$I$12,C19,Calendar!$J$6:$J$12,X19,Calendar!$K$6:$K$12,Y19)=0,"OK","CHECK")) -> n/a | AD19: =IF(B19="Yes",X19+IF(Y19="AM",TIME(13,0,0),TIME(22,0,0)),"") | AE19: Excluded: partial scope cannot close Larkfield alone; selected integrated package preserves the seven-package cap.
A20: LF-403 | B20: No | C20: Larkfield | D20: Kestrel | E20: Telemetry-only intervention | F20: Implementation | G20: Released | I20: B | J20: 0.88 | K20: LF-TC | L20: 46170 | M20: 46170 | N20: 46170 | O20: PM | Q20: 6 | R20: =IF(Q20="",IFERROR(VLOOKUP(A20,Assumptions!$A$6:$H$8,8,FALSE()),""),"") | S20: =IF(Q20<>"",Q20,R20) -> 6 | T20: 1580 | U20: Yes | V20: Lorcan Ibarra | X20: 46170 | Y20: PM | Z20: =IF(AND(F20="Implementation",G20="Released",H20="",OR(I20="A",I20="B"),J20>=80%),"Eligible","Ineligible") -> Eligible | AA20: =IF(B20<>"Yes","n/a",IF(AND(X20>=L20,X20>=M20,X20<=N20,Y20=O20),"OK","CHECK")) -> n/a | AB20: =IF(B20<>"Yes","n/a",IF(P20="","n/a",IFERROR(IF(AND(VLOOKUP(P20,$A$6:$AD$27,2,FALSE())="Yes",VLOOKUP(P20,$A$6:$AD$27,30,FALSE())<=X20+IF(Y20="AM",TIME(8,0,0),TIME(14,0,0))),"OK","CHECK"),"CHECK"))) -> n/a | AC20: =IF(B20<>"Yes","n/a",IF(COUNTIFS(Calendar!$I$6:$I$12,C20,Calendar!$J$6:$J$12,X20,Calendar!$K$6:$K$12,Y20)=0,"OK","CHECK")) -> n/a | AD20: =IF(B20="Yes",X20+IF(Y20="AM",TIME(13,0,0),TIME(22,0,0)),"") | AE20: Excluded: partial scope cannot close Larkfield alone; no date or coverage benefit.
A21: LF-404 | B21: No | C21: Larkfield | D21: Kestrel | E21: Witness evidence-only intervention | F21: Implementation | G21: Released | I21: B | J21: 0.83 | K21: LF-AW | L21: 46170 | M21: 46170 | N21: 46170 | O21: PM | Q21: 6 | R21: =IF(Q21="",IFERROR(VLOOKUP(A21,Assumptions!$A$6:$H$8,8,FALSE()),""),"") | S21: =IF(Q21<>"",Q21,R21) -> 6 | T21: 1740 | U21: Yes | V21: Lorcan Ibarra | X21: 46170 | Y21: PM | Z21: =IF(AND(F21="Implementation",G21="Released",H21="",OR(I21="A",I21="B"),J21>=80%),"Eligible","Ineligible") -> Eligible | AA21: =IF(B21<>"Yes","n/a",IF(AND(X21>=L21,X21>=M21,X21<=N21,Y21=O21),"OK","CHECK")) -> n/a | AB21: =IF(B21<>"Yes","n/a",IF(P21="","n/a",IFERROR(IF(AND(VLOOKUP(P21,$A$6:$AD$27,2,FALSE())="Yes",VLOOKUP(P21,$A$6:$AD$27,30,FALSE())<=X21+IF(Y21="AM",TIME(8,0,0),TIME(14,0,0))),"OK","CHECK"),"CHECK"))) -> n/a | AC21: =IF(B21<>"Yes","n/a",IF(COUNTIFS(Calendar!$I$6:$I$12,C21,Calendar!$J$6:$J$12,X21,Calendar!$K$6:$K$12,Y21)=0,"OK","CHECK")) -> n/a | AD21: =IF(B21="Yes",X21+IF(Y21="AM",TIME(13,0,0),TIME(22,0,0)),"") | AE21: Excluded: partial scope cannot close Larkfield alone; no date or coverage benefit.
A22: LF-405 | B22: No | C22: Larkfield | D22: Kestrel | E22: Analyzer and telemetry partial intervention | F22: Implementation | G22: Released | I22: A | J22: 0.9 | K22: LF-AC, LF-TC | L22: 46170 | M22: 46170 | N22: 46170 | O22: PM | Q22: 12 | R22: =IF(Q22="",IFERROR(VLOOKUP(A22,Assumptions!$A$6:$H$8,8,FALSE()),""),"") | S22: =IF(Q22<>"",Q22,R22) -> 12 | T22: 3120 | U22: Yes | V22: Lorcan Ibarra | X22: 46170 | Y22: PM | Z22: =IF(AND(F22="Implementation",G22="Released",H22="",OR(I22="A",I22="B"),J22>=80%),"Eligible","Ineligible") -> Eligible | AA22: =IF(B22<>"Yes","n/a",IF(AND(X22>=L22,X22>=M22,X22<=N22,Y22=O22),"OK","CHECK")) -> n/a | AB22: =IF(B22<>"Yes","n/a",IF(P22="","n/a",IFERROR(IF(AND(VLOOKUP(P22,$A$6:$AD$27,2,FALSE())="Yes",VLOOKUP(P22,$A$6:$AD$27,30,FALSE())<=X22+IF(Y22="AM",TIME(8,0,0),TIME(14,0,0))),"OK","CHECK"),"CHECK"))) -> n/a | AC22: =IF(B22<>"Yes","n/a",IF(COUNTIFS(Calendar!$I$6:$I$12,C22,Calendar!$J$6:$J$12,X22,Calendar!$K$6:$K$12,Y22)=0,"OK","CHECK")) -> n/a | AD22: =IF(B22="Yes",X22+IF(Y22="AM",TIME(13,0,0),TIME(22,0,0)),"") | AE22: Excluded: still needs a separate audit package, increasing the portfolio beyond seven packages.
A23: LF-406 | B23: No | C23: Larkfield | D23: Kestrel | E23: Trace-only witness evidence intervention | F23: Implementation | G23: Released | I23: B | J23: 0.82 | K23: LF-AW | L23: 46170 | M23: 46170 | N23: 46170 | O23: PM | Q23: 6 | R23: =IF(Q23="",IFERROR(VLOOKUP(A23,Assumptions!$A$6:$H$8,8,FALSE()),""),"") | S23: =IF(Q23<>"",Q23,R23) -> 6 | T23: 1810 | U23: Yes | V23: Lorcan Ibarra | X23: 46170 | Y23: PM | Z23: =IF(AND(F23="Implementation",G23="Released",H23="",OR(I23="A",I23="B"),J23>=80%),"Eligible","Ineligible") -> Eligible | AA23: =IF(B23<>"Yes","n/a",IF(AND(X23>=L23,X23>=M23,X23<=N23,Y23=O23),"OK","CHECK")) -> n/a | AB23: =IF(B23<>"Yes","n/a",IF(P23="","n/a",IFERROR(IF(AND(VLOOKUP(P23,$A$6:$AD$27,2,FALSE())="Yes",VLOOKUP(P23,$A$6:$AD$27,30,FALSE())<=X23+IF(Y23="AM",TIME(8,0,0),TIME(14,0,0))),"OK","CHECK"),"CHECK"))) -> n/a | AC23: =IF(B23<>"Yes","n/a",IF(COUNTIFS(Calendar!$I$6:$I$12,C23,Calendar!$J$6:$J$12,X23,Calendar!$K$6:$K$12,Y23)=0,"OK","CHECK")) -> n/a | AD23: =IF(B23="Yes",X23+IF(Y23="AM",TIME(13,0,0),TIME(22,0,0)),"") | AE23: Excluded: partial audit-only record; its blank effort has a comparable range but the scope is not required.
A24: CG-105 | B24: No | C24: Crossgate | D24: Horizon | E24: Combined analyzer, telemetry and witness recovery | F24: Implementation | G24: Released | I24: A | J24: 0.79 | K24: CG-AC, CG-TC, CG-AW | L24: 46160 | M24: 46160 | N24: 46160 | O24: PM | Q24: 10 | R24: =IF(Q24="",IFERROR(VLOOKUP(A24,Assumptions!$A$6:$H$8,8,FALSE()),""),"") | S24: =IF(Q24<>"",Q24,R24) -> 10 | T24: 3350 | U24: Yes | V24: Lorcan Ibarra | X24: 46160 | Y24: PM | Z24: =IF(AND(F24="Implementation",G24="Released",H24="",OR(I24="A",I24="B"),J24>=80%),"Eligible","Ineligible") -> Ineligible | AA24: =IF(B24<>"Yes","n/a",IF(AND(X24>=L24,X24>=M24,X24<=N24,Y24=O24),"OK","CHECK")) -> n/a | AB24: =IF(B24<>"Yes","n/a",IF(P24="","n/a",IFERROR(IF(AND(VLOOKUP(P24,$A$6:$AD$27,2,FALSE())="Yes",VLOOKUP(P24,$A$6:$AD$27,30,FALSE())<=X24+IF(Y24="AM",TIME(8,0,0),TIME(14,0,0))),"OK","CHECK"),"CHECK"))) -> n/a | AC24: =IF(B24<>"Yes","n/a",IF(COUNTIFS(Calendar!$I$6:$I$12,C24,Calendar!$J$6:$J$12,X24,Calendar!$K$6:$K$12,Y24)=0,"OK","CHECK")) -> n/a | AD24: =IF(B24="Yes",X24+IF(Y24="AM",TIME(13,0,0),TIME(22,0,0)),"") | AE24: Excluded: confidence is 79%, one percentage point below the permit minimum despite broad coverage.
A25: MH-205 | B25: No | C25: Millhaven | D25: Horizon | E25: Low-cost combined recovery package | F25: Implementation | G25: Released | I25: C | J25: 0.93 | K25: MH-AC, MH-TC, MH-AW | L25: 46162 | M25: 46162 | N25: 46162 | O25: PM | Q25: 10 | R25: =IF(Q25="",IFERROR(VLOOKUP(A25,Assumptions!$A$6:$H$8,8,FALSE()),""),"") | S25: =IF(Q25<>"",Q25,R25) -> 10 | T25: 3250 | U25: Yes | V25: Lorcan Ibarra | X25: 46162 | Y25: PM | Z25: =IF(AND(F25="Implementation",G25="Released",H25="",OR(I25="A",I25="B"),J25>=80%),"Eligible","Ineligible") -> Ineligible | AA25: =IF(B25<>"Yes","n/a",IF(AND(X25>=L25,X25>=M25,X25<=N25,Y25=O25),"OK","CHECK")) -> n/a | AB25: =IF(B25<>"Yes","n/a",IF(P25="","n/a",IFERROR(IF(AND(VLOOKUP(P25,$A$6:$AD$27,2,FALSE())="Yes",VLOOKUP(P25,$A$6:$AD$27,30,FALSE())<=X25+IF(Y25="AM",TIME(8,0,0),TIME(14,0,0))),"OK","CHECK"),"CHECK"))) -> n/a | AC25: =IF(B25<>"Yes","n/a",IF(COUNTIFS(Calendar!$I$6:$I$12,C25,Calendar!$J$6:$J$12,X25,Calendar!$K$6:$K$12,Y25)=0,"OK","CHECK")) -> n/a | AD25: =IF(B25="Yes",X25+IF(Y25="AM",TIME(13,0,0),TIME(22,0,0)),"") | AE25: Excluded: evidence grade C is below the accepted A/B range despite the low fixed cost.
A26: DS-305 | B26: No | C26: Docksett | D26: Kestrel | E26: Broad close-out pack | F26: Implementation | G26: Released | H26: DS-301 | I26: A | J26: 0.96 | K26: DS-AC, DS-TC, DS-AW | L26: 46168 | M26: 46168 | N26: 46168 | O26: PM | Q26: 11 | R26: =IF(Q26="",IFERROR(VLOOKUP(A26,Assumptions!$A$6:$H$8,8,FALSE()),""),"") | S26: =IF(Q26<>"",Q26,R26) -> 11 | T26: 3850 | U26: Yes | V26: Lorcan Ibarra | X26: 46168 | Y26: PM | Z26: =IF(AND(F26="Implementation",G26="Released",H26="",OR(I26="A",I26="B"),J26>=80%),"Eligible","Ineligible") -> Ineligible | AA26: =IF(B26<>"Yes","n/a",IF(AND(X26>=L26,X26>=M26,X26<=N26,Y26=O26),"OK","CHECK")) -> n/a | AB26: =IF(B26<>"Yes","n/a",IF(P26="","n/a",IFERROR(IF(AND(VLOOKUP(P26,$A$6:$AD$27,2,FALSE())="Yes",VLOOKUP(P26,$A$6:$AD$27,30,FALSE())<=X26+IF(Y26="AM",TIME(8,0,0),TIME(14,0,0))),"OK","CHECK"),"CHECK"))) -> n/a | AC26: =IF(B26<>"Yes","n/a",IF(COUNTIFS(Calendar!$I$6:$I$12,C26,Calendar!$J$6:$J$12,X26,Calendar!$K$6:$K$12,Y26)=0,"OK","CHECK")) -> n/a | AD26: =IF(B26="Yes",X26+IF(Y26="AM",TIME(13,0,0),TIME(22,0,0)),"") | AE26: Excluded: explicitly superseded by DS-301; it cannot close Docksett obligations.
A27: LF-407 | B27: No | C27: Larkfield | D27: Kestrel | E27: Integrated close-out package | F27: Implementation | G27: Hold - not released | I27: B | J27: 0.91 | K27: LF-AC, LF-TC, LF-AW | L27: 46170 | M27: 46170 | N27: 46170 | O27: PM | Q27: 16 | R27: =IF(Q27="",IFERROR(VLOOKUP(A27,Assumptions!$A$6:$H$8,8,FALSE()),""),"") | S27: =IF(Q27<>"",Q27,R27) -> 16 | T27: 3450 | U27: Yes | V27: Lorcan Ibarra | X27: 46170 | Y27: PM | Z27: =IF(AND(F27="Implementation",G27="Released",H27="",OR(I27="A",I27="B"),J27>=80%),"Eligible","Ineligible") -> Ineligible | AA27: =IF(B27<>"Yes","n/a",IF(AND(X27>=L27,X27>=M27,X27<=N27,Y27=O27),"OK","CHECK")) -> n/a | AB27: =IF(B27<>"Yes","n/a",IF(P27="","n/a",IFERROR(IF(AND(VLOOKUP(P27,$A$6:$AD$27,2,FALSE())="Yes",VLOOKUP(P27,$A$6:$AD$27,30,FALSE())<=X27+IF(Y27="AM",TIME(8,0,0),TIME(14,0,0))),"OK","CHECK"),"CHECK"))) -> n/a | AC27: =IF(B27<>"Yes","n/a",IF(COUNTIFS(Calendar!$I$6:$I$12,C27,Calendar!$J$6:$J$12,X27,Calendar!$K$6:$K$12,Y27)=0,"OK","CHECK")) -> n/a | AD27: =IF(B27="Yes",X27+IF(Y27="AM",TIME(13,0,0),TIME(22,0,0)),"") | AE27: Excluded: technical content is complete, but release status is Hold - not released.

Sheet Permit coverage
A1: Permit coverage
A2: Tag-level source mapping; a tag is closed only by a selected eligible implementation package
A4: Twelve controlling permit criteria
A5: Permit tag | B5: Plant room | C5: Obligation | D5: Eligible selected packages | E5: Status | F5: Closing package
A6: CG-AC | B6: Crossgate | C6: Analyzer calibration | D6: =COUNTIFS($C$24:$C$62,A6,$F$24:$F$62,"Yes") -> 1 | E6: =IF(D6>0,"COVERED","GAP") -> COVERED | F6: =IFERROR(LOOKUP(2,1/(($C$24:$C$62=A6)*($F$24:$F$62="Yes")),$A$24:$A$62),"") -> CG-101
A7: CG-AW | B7: Crossgate | C7: Audit trail + witness evidence | D7: =COUNTIFS($C$24:$C$62,A7,$F$24:$F$62,"Yes") -> 1 | E7: =IF(D7>0,"COVERED","GAP") -> COVERED | F7: =IFERROR(LOOKUP(2,1/(($C$24:$C$62=A7)*($F$24:$F$62="Yes")),$A$24:$A$62),"") -> CG-102
A8: CG-TC | B8: Crossgate | C8: Telemetry continuity | D8: =COUNTIFS($C$24:$C$62,A8,$F$24:$F$62,"Yes") -> 1 | E8: =IF(D8>0,"COVERED","GAP") -> COVERED | F8: =IFERROR(LOOKUP(2,1/(($C$24:$C$62=A8)*($F$24:$F$62="Yes")),$A$24:$A$62),"") -> CG-101
A9: DS-AC | B9: Docksett | C9: Analyzer calibration | D9: =COUNTIFS($C$24:$C$62,A9,$F$24:$F$62,"Yes") -> 1 | E9: =IF(D9>0,"COVERED","GAP") -> COVERED | F9: =IFERROR(LOOKUP(2,1/(($C$24:$C$62=A9)*($F$24:$F$62="Yes")),$A$24:$A$62),"") -> DS-301
A10: DS-AW | B10: Docksett | C10: Audit trail + witness evidence | D10: =COUNTIFS($C$24:$C$62,A10,$F$24:$F$62,"Yes") -> 1 | E10: =IF(D10>0,"COVERED","GAP") -> COVERED | F10: =IFERROR(LOOKUP(2,1/(($C$24:$C$62=A10)*($F$24:$F$62="Yes")),$A$24:$A$62),"") -> DS-302
A11: DS-TC | B11: Docksett | C11: Telemetry continuity | D11: =COUNTIFS($C$24:$C$62,A11,$F$24:$F$62,"Yes") -> 1 | E11: =IF(D11>0,"COVERED","GAP") -> COVERED | F11: =IFERROR(LOOKUP(2,1/(($C$24:$C$62=A11)*($F$24:$F$62="Yes")),$A$24:$A$62),"") -> DS-301
A12: LF-AC | B12: Larkfield | C12: Analyzer calibration | D12: =COUNTIFS($C$24:$C$62,A12,$F$24:$F$62,"Yes") -> 1 | E12: =IF(D12>0,"COVERED","GAP") -> COVERED | F12: =IFERROR(LOOKUP(2,1/(($C$24:$C$62=A12)*($F$24:$F$62="Yes")),$A$24:$A$62),"") -> LF-401
A13: LF-AW | B13: Larkfield | C13: Audit trail + witness evidence | D13: =COUNTIFS($C$24:$C$62,A13,$F$24:$F$62,"Yes") -> 1 | E13: =IF(D13>0,"COVERED","GAP") -> COVERED | F13: =IFERROR(LOOKUP(2,1/(($C$24:$C$62=A13)*($F$24:$F$62="Yes")),$A$24:$A$62),"") -> LF-401
A14: LF-TC | B14: Larkfield | C14: Telemetry continuity | D14: =COUNTIFS($C$24:$C$62,A14,$F$24:$F$62,"Yes") -> 1 | E14: =IF(D14>0,"COVERED","GAP") -> COVERED | F14: =IFERROR(LOOKUP(2,1/(($C$24:$C$62=A14)*($F$24:$F$62="Yes")),$A$24:$A$62),"") -> LF-401
A15: MH-AC | B15: Millhaven | C15: Analyzer calibration | D15: =COUNTIFS($C$24:$C$62,A15,$F$24:$F$62,"Yes") -> 1 | E15: =IF(D15>0,"COVERED","GAP") -> COVERED | F15: =IFERROR(LOOKUP(2,1/(($C$24:$C$62=A15)*($F$24:$F$62="Yes")),$A$24:$A$62),"") -> MH-201
A16: MH-AW | B16: Millhaven | C16: Audit trail + witness evidence | D16: =COUNTIFS($C$24:$C$62,A16,$F$24:$F$62,"Yes") -> 1 | E16: =IF(D16>0,"COVERED","GAP") -> COVERED | F16: =IFERROR(LOOKUP(2,1/(($C$24:$C$62=A16)*($F$24:$F$62="Yes")),$A$24:$A$62),"") -> MH-201
A17: MH-TC | B17: Millhaven | C17: Telemetry continuity | D17: =COUNTIFS($C$24:$C$62,A17,$F$24:$F$62,"Yes") -> 1 | E17: =IF(D17>0,"COVERED","GAP") -> COVERED | F17: =IFERROR(LOOKUP(2,1/(($C$24:$C$62=A17)*($F$24:$F$62="Yes")),$A$24:$A$62),"") -> MH-202
A22: Source-supported package-to-tag mapping
A23: Package ID | B23: Plant room | C23: Source-supported tag | D23: Selected? | E23: Source eligibility | F23: Counts toward closure | G23: Mapping basis
A24: CG-101 | B24: Crossgate | C24: CG-AC | D24: =VLOOKUP(A24,'Package decision'!$A$6:$Z$27,2,FALSE()) -> Yes | E24: =VLOOKUP(A24,'Package decision'!$A$6:$Z$27,26,FALSE()) -> Eligible | F24: =IF(AND(D24="Yes",E24="Eligible"),"Yes","No") -> Yes | G24: Work-register coverage tag
A25: CG-101 | B25: Crossgate | C25: CG-TC | D25: =VLOOKUP(A25,'Package decision'!$A$6:$Z$27,2,FALSE()) -> Yes | E25: =VLOOKUP(A25,'Package decision'!$A$6:$Z$27,26,FALSE()) -> Eligible | F25: =IF(AND(D25="Yes",E25="Eligible"),"Yes","No") -> Yes | G25: Work-register coverage tag
A26: CG-102 | B26: Crossgate | C26: CG-AW | D26: =VLOOKUP(A26,'Package decision'!$A$6:$Z$27,2,FALSE()) -> Yes | E26: =VLOOKUP(A26,'Package decision'!$A$6:$Z$27,26,FALSE()) -> Eligible | F26: =IF(AND(D26="Yes",E26="Eligible"),"Yes","No") -> Yes | G26: Work-register coverage tag
A27: CG-103 | B27: Crossgate | C27: CG-AC | D27: =VLOOKUP(A27,'Package decision'!$A$6:$Z$27,2,FALSE()) -> No | E27: =VLOOKUP(A27,'Package decision'!$A$6:$Z$27,26,FALSE()) -> Eligible | F27: =IF(AND(D27="Yes",E27="Eligible"),"Yes","No") -> No | G27: Work-register coverage tag
A28: CG-104 | B28: Crossgate | C28: CG-TC | D28: =VLOOKUP(A28,'Package decision'!$A$6:$Z$27,2,FALSE()) -> No | E28: =VLOOKUP(A28,'Package decision'!$A$6:$Z$27,26,FALSE()) -> Eligible | F28: =IF(AND(D28="Yes",E28="Eligible"),"Yes","No") -> No | G28: Work-register coverage tag
A29: CG-104 | B29: Crossgate | C29: CG-AW | D29: =VLOOKUP(A29,'Package decision'!$A$6:$Z$27,2,FALSE()) -> No | E29: =VLOOKUP(A29,'Package decision'!$A$6:$Z$27,26,FALSE()) -> Eligible | F29: =IF(AND(D29="Yes",E29="Eligible"),"Yes","No") -> No | G29: Work-register coverage tag
A30: MH-201 | B30: Millhaven | C30: MH-AC | D30: =VLOOKUP(A30,'Package decision'!$A$6:$Z$27,2,FALSE()) -> Yes | E30: =VLOOKUP(A30,'Package decision'!$A$6:$Z$27,26,FALSE()) -> Eligible | F30: =IF(AND(D30="Yes",E30="Eligible"),"Yes","No") -> Yes | G30: Work-register coverage tag
A31: MH-201 | B31: Millhaven | C31: MH-AW | D31: =VLOOKUP(A31,'Package decision'!$A$6:$Z$27,2,FALSE()) -> Yes | E31: =VLOOKUP(A31,'Package decision'!$A$6:$Z$27,26,FALSE()) -> Eligible | F31: =IF(AND(D31="Yes",E31="Eligible"),"Yes","No") -> Yes | G31: Work-register coverage tag
A32: MH-202 | B32: Millhaven | C32: MH-TC | D32: =VLOOKUP(A32,'Package decision'!$A$6:$Z$27,2,FALSE()) -> Yes | E32: =VLOOKUP(A32,'Package decision'!$A$6:$Z$27,26,FALSE()) -> Eligible | F32: =IF(AND(D32="Yes",E32="Eligible"),"Yes","No") -> Yes | G32: Work-register coverage tag
A33: MH-203 | B33: Millhaven | C33: MH-AC | D33: =VLOOKUP(A33,'Package decision'!$A$6:$Z$27,2,FALSE()) -> No | E33: =VLOOKUP(A33,'Package decision'!$A$6:$Z$27,26,FALSE()) -> Eligible | F33: =IF(AND(D33="Yes",E33="Eligible"),"Yes","No") -> No | G33: Work-register coverage tag
A34: MH-203 | B34: Millhaven | C34: MH-TC | D34: =VLOOKUP(A34,'Package decision'!$A$6:$Z$27,2,FALSE()) -> No | E34: =VLOOKUP(A34,'Package decision'!$A$6:$Z$27,26,FALSE()) -> Eligible | F34: =IF(AND(D34="Yes",E34="Eligible"),"Yes","No") -> No | G34: Work-register coverage tag
A35: MH-204 | B35: Millhaven | C35: MH-AW | D35: =VLOOKUP(A35,'Package decision'!$A$6:$Z$27,2,FALSE()) -> No | E35: =VLOOKUP(A35,'Package decision'!$A$6:$Z$27,26,FALSE()) -> Eligible | F35: =IF(AND(D35="Yes",E35="Eligible"),"Yes","No") -> No | G35: Work-register coverage tag
... A62: LF-407 | B62: Larkfield | C62: LF-AW | D62: =VLOOKUP(A62,'Package decision'!$A$6:$Z$27,2,FALSE()) -> No | E62: =VLOOKUP(A62,'Package decision'!$A$6:$Z$27,26,FALSE()) -> Ineligible | F62: =IF(AND(D62="Yes",E62="Eligible"),"Yes","No") -> No | G62: Work-register coverage tag

Sheet Shift plan
A1: Dated shift plan
A2: Authorised commissioning is grouped by calibration state, followed by quality review and regulator submission
A3: Commissioning completion is shown at the end of the permitted AM/PM shift. Unselected candidates are not authorised and have no execution timestamp.
A5: Activity ID | B5: Activity type | C5: Plant room | D5: Equipment family | E5: Planned date | F5: Shift | G5: Start | H5: Completion | I5: Technician h | J5: Certified engineer? | K5: Accountable owner | L5: Authorisation status | M5: Access / dependency | N5: Schedule check | O5: Blackout | P5: Engineer slot | Q5: Cutoff / milestone check
A6: ='Package decision'!A6 -> CG-101 | B6: =IF('Package decision'!B6="Yes","Commissioning evidence","Candidate not authorised") -> Commissioning evidence | C6: ='Package decision'!C6 -> Crossgate | D6: ='Package decision'!D6 -> Horizon | E6: =IF('Package decision'!B6="Yes",'Package decision'!X6,"") -> 46160 | F6: =IF('Package decision'!B6="Yes",'Package decision'!Y6,"") -> PM | G6: =IF(E6="","",E6+IF(F6="AM",TIME(8,0,0),TIME(14,0,0))) -> 46160.583 | H6: =IF(E6="","",E6+IF(F6="AM",TIME(13,0,0),TIME(22,0,0))) -> 46160.917 | I6: =IF('Package decision'!B6="Yes",'Package decision'!S6,0) -> 8 | J6: =IF('Package decision'!B6="Yes",'Package decision'!U6,"") -> Yes | K6: =IF('Package decision'!B6="Yes",'Package decision'!V6,"") -> Lorcan Ibarra | L6: =IF('Package decision'!B6="Yes","AUTHORIZED - COMMISSION","NOT AUTHORISED") -> AUTHORIZED - COMMISSION | M6: =TEXT('Package decision'!M6,"dd mmm")&" to "&TEXT('Package decision'!N6,"dd mmm")&" / "&'Package decision'!P6 -> 18 May to 18 May / | N6: =IF(L6<>"AUTHORIZED - COMMISSION","n/a",IF(AND('Package decision'!AA6="OK",'Package decision'!AB6<>"CHECK"),"OK","CHECK")) -> OK | O6: =IF(L6<>"AUTHORIZED - COMMISSION","n/a",'Package decision'!AC6) -> OK | P6: =IF(L6<>"AUTHORIZED - COMMISSION","n/a",IF(COUNTIFS(Calendar!$A$6:$A$14,E6,Calendar!$G$6:$G$14,"*"&F6&"*")=1,"OK","CHECK")) -> OK | Q6: =IF(L6<>"AUTHORIZED - COMMISSION","n/a",IF(H6<=DATE(2026,5,28)+TIME(23,0,0),"OK","CHECK")) -> OK
A7: ='Package decision'!A7 -> CG-102 | B7: =IF('Package decision'!B7="Yes","Commissioning evidence","Candidate not authorised") -> Commissioning evidence | C7: ='Package decision'!C7 -> Crossgate | D7: ='Package decision'!D7 -> Horizon | E7: =IF('Package decision'!B7="Yes",'Package decision'!X7,"") -> 46161 | F7: =IF('Package decision'!B7="Yes",'Package decision'!Y7,"") -> AM | G7: =IF(E7="","",E7+IF(F7="AM",TIME(8,0,0),TIME(14,0,0))) -> 46161.333 | H7: =IF(E7="","",E7+IF(F7="AM",TIME(13,0,0),TIME(22,0,0))) -> 46161.542 | I7: =IF('Package decision'!B7="Yes",'Package decision'!S7,0) -> 5 | J7: =IF('Package decision'!B7="Yes",'Package decision'!U7,"") -> Yes | K7: =IF('Package decision'!B7="Yes",'Package decision'!V7,"") -> Lorcan Ibarra | L7: =IF('Package decision'!B7="Yes","AUTHORIZED - COMMISSION","NOT AUTHORISED") -> AUTHORIZED - COMMISSION | M7: =TEXT('Package decision'!M7,"dd mmm")&" to "&TEXT('Package decision'!N7,"dd mmm")&" / "&'Package decision'!P7 -> 19 May to 19 May / CG-101 | N7: =IF(L7<>"AUTHORIZED - COMMISSION","n/a",IF(AND('Package decision'!AA7="OK",'Package decision'!AB7<>"CHECK"),"OK","CHECK")) -> OK | O7: =IF(L7<>"AUTHORIZED - COMMISSION","n/a",'Package decision'!AC7) -> OK | P7: =IF(L7<>"AUTHORIZED - COMMISSION","n/a",IF(COUNTIFS(Calendar!$A$6:$A$14,E7,Calendar!$G$6:$G$14,"*"&F7&"*")=1,"OK","CHECK")) -> OK | Q7: =IF(L7<>"AUTHORIZED - COMMISSION","n/a",IF(H7<=DATE(2026,5,28)+TIME(23,0,0),"OK","CHECK")) -> OK
A8: ='Package decision'!A8 -> CG-103 | B8: =IF('Package decision'!B8="Yes","Commissioning evidence","Candidate not authorised") -> Candidate not authorised | C8: ='Package decision'!C8 -> Crossgate | D8: ='Package decision'!D8 -> Horizon | E8: =IF('Package decision'!B8="Yes",'Package decision'!X8,"") | F8: =IF('Package decision'!B8="Yes",'Package decision'!Y8,"") | G8: =IF(E8="","",E8+IF(F8="AM",TIME(8,0,0),TIME(14,0,0))) | H8: =IF(E8="","",E8+IF(F8="AM",TIME(13,0,0),TIME(22,0,0))) | I8: =IF('Package decision'!B8="Yes",'Package decision'!S8,0) -> 0 | J8: =IF('Package decision'!B8="Yes",'Package decision'!U8,"") | K8: =IF('Package decision'!B8="Yes",'Package decision'!V8,"") | L8: =IF('Package decision'!B8="Yes","AUTHORIZED - COMMISSION","NOT AUTHORISED") -> NOT AUTHORISED | M8: =TEXT('Package decision'!M8,"dd mmm")&" to "&TEXT('Package decision'!N8,"dd mmm")&" / "&'Package decision'!P8 -> 18 May to 18 May / | N8: =IF(L8<>"AUTHORIZED - COMMISSION","n/a",IF(AND('Package decision'!AA8="OK",'Package decision'!AB8<>"CHECK"),"OK","CHECK")) -> n/a | O8: =IF(L8<>"AUTHORIZED - COMMISSION","n/a",'Package decision'!AC8) -> n/a | P8: =IF(L8<>"AUTHORIZED - COMMISSION","n/a",IF(COUNTIFS(Calendar!$A$6:$A$14,E8,Calendar!$G$6:$G$14,"*"&F8&"*")=1,"OK","CHECK")) -> n/a | Q8: =IF(L8<>"AUTHORIZED - COMMISSION","n/a",IF(H8<=DATE(2026,5,28)+TIME(23,0,0),"OK","CHECK")) -> n/a
A9: ='Package decision'!A9 -> CG-104 | B9: =IF('Package decision'!B9="Yes","Commissioning evidence","Candidate not authorised") -> Candidate not authorised | C9: ='Package decision'!C9 -> Crossgate | D9: ='Package decision'!D9 -> Horizon | E9: =IF('Package decision'!B9="Yes",'Package decision'!X9,"") | F9: =IF('Package decision'!B9="Yes",'Package decision'!Y9,"") | G9: =IF(E9="","",E9+IF(F9="AM",TIME(8,0,0),TIME(14,0,0))) | H9: =IF(E9="","",E9+IF(F9="AM",TIME(13,0,0),TIME(22,0,0))) | I9: =IF('Package decision'!B9="Yes",'Package decision'!S9,0) -> 0 | J9: =IF('Package decision'!B9="Yes",'Package decision'!U9,"") | K9: =IF('Package decision'!B9="Yes",'Package decision'!V9,"") | L9: =IF('Package decision'!B9="Yes","AUTHORIZED - COMMISSION","NOT AUTHORISED") -> NOT AUTHORISED | M9: =TEXT('Package decision'!M9,"dd mmm")&" to "&TEXT('Package decision'!N9,"dd mmm")&" / "&'Package decision'!P9 -> 19 May to 19 May / CG-103 | N9: =IF(L9<>"AUTHORIZED - COMMISSION","n/a",IF(AND('Package decision'!AA9="OK",'Package decision'!AB9<>"CHECK"),"OK","CHECK")) -> n/a | O9: =IF(L9<>"AUTHORIZED - COMMISSION","n/a",'Package decision'!AC9) -> n/a | P9: =IF(L9<>"AUTHORIZED - COMMISSION","n/a",IF(COUNTIFS(Calendar!$A$6:$A$14,E9,Calendar!$G$6:$G$14,"*"&F9&"*")=1,"OK","CHECK")) -> n/a | Q9: =IF(L9<>"AUTHORIZED - COMMISSION","n/a",IF(H9<=DATE(2026,5,28)+TIME(23,0,0),"OK","CHECK")) -> n/a
A10: ='Package decision'!A10 -> MH-201 | B10: =IF('Package decision'!B10="Yes","Commissioning evidence","Candidate not authorised") -> Commissioning evidence | C10: ='Package decision'!C10 -> Millhaven | D10: ='Package decision'!D10 -> Horizon | E10: =IF('Package decision'!B10="Yes",'Package decision'!X10,"") -> 46162 | F10: =IF('Package decision'!B10="Yes",'Package decision'!Y10,"") -> PM | G10: =IF(E10="","",E10+IF(F10="AM",TIME(8,0,0),TIME(14,0,0))) -> 46162.583 | H10: =IF(E10="","",E10+IF(F10="AM",TIME(13,0,0),TIME(22,0,0))) -> 46162.917 | I10: =IF('Package decision'!B10="Yes",'Package decision'!S10,0) -> 12 | J10: =IF('Package decision'!B10="Yes",'Package decision'!U10,"") -> Yes | K10: =IF('Package decision'!B10="Yes",'Package decision'!V10,"") -> Lorcan Ibarra | L10: =IF('Package decision'!B10="Yes","AUTHORIZED - COMMISSION","NOT AUTHORISED") -> AUTHORIZED - COMMISSION | M10: =TEXT('Package decision'!M10,"dd mmm")&" to "&TEXT('Package decision'!N10,"dd mmm")&" / "&'Package decision'!P10 -> 20 May to 20 May / | N10: =IF(L10<>"AUTHORIZED - COMMISSION","n/a",IF(AND('Package decision'!AA10="OK",'Package decision'!AB10<>"CHECK"),"OK","CHECK")) -> OK | O10: =IF(L10<>"AUTHORIZED - COMMISSION","n/a",'Package decision'!AC10) -> OK | P10: =IF(L10<>"AUTHORIZED - COMMISSION","n/a",IF(COUNTIFS(Calendar!$A$6:$A$14,E10,Calendar!$G$6:$G$14,"*"&F10&"*")=1,"OK","CHECK")) -> OK | Q10: =IF(L10<>"AUTHORIZED - COMMISSION","n/a",IF(H10<=DATE(2026,5,28)+TIME(23,0,0),"OK","CHECK")) -> OK
A11: ='Package decision'!A11 -> MH-202 | B11: =IF('Package decision'!B11="Yes","Commissioning evidence","Candidate not authorised") -> Commissioning evidence | C11: ='Package decision'!C11 -> Millhaven | D11: ='Package decision'!D11 -> Horizon | E11: =IF('Package decision'!B11="Yes",'Package decision'!X11,"") -> 46163 | F11: =IF('Package decision'!B11="Yes",'Package decision'!Y11,"") -> AM | G11: =IF(E11="","",E11+IF(F11="AM",TIME(8,0,0),TIME(14,0,0))) -> 46163.333 | H11: =IF(E11="","",E11+IF(F11="AM",TIME(13,0,0),TIME(22,0,0))) -> 46163.542 | I11: =IF('Package decision'!B11="Yes",'Package decision'!S11,0) -> 6 | J11: =IF('Package decision'!B11="Yes",'Package decision'!U11,"") -> Yes | K11: =IF('Package decision'!B11="Yes",'Package decision'!V11,"") -> Lorcan Ibarra | L11: =IF('Package decision'!B11="Yes","AUTHORIZED - COMMISSION","NOT AUTHORISED") -> AUTHORIZED - COMMISSION | M11: =TEXT('Package decision'!M11,"dd mmm")&" to "&TEXT('Package decision'!N11,"dd mmm")&" / "&'Package decision'!P11 -> 21 May to 21 May / MH-201 | N11: =IF(L11<>"AUTHORIZED - COMMISSION","n/a",IF(AND('Package decision'!AA11="OK",'Package decision'!AB11<>"CHECK"),"OK","CHECK")) -> OK | O11: =IF(L11<>"AUTHORIZED - COMMISSION","n/a",'Package decision'!AC11) -> OK | P11: =IF(L11<>"AUTHORIZED - COMMISSION","n/a",IF(COUNTIFS(Calendar!$A$6:$A$14,E11,Calendar!$G$6:$G$14,"*"&F11&"*")=1,"OK","CHECK")) -> OK | Q11: =IF(L11<>"AUTHORIZED - COMMISSION","n/a",IF(H11<=DATE(2026,5,28)+TIME(23,0,0),"OK","CHECK")) -> OK
A12: ='Package decision'!A12 -> MH-203 | B12: =IF('Package decision'!B12="Yes","Commissioning evidence","Candidate not authorised") -> Candidate not authorised | C12: ='Package decision'!C12 -> Millhaven | D12: ='Package decision'!D12 -> Horizon | E12: =IF('Package decision'!B12="Yes",'Package decision'!X12,"") | F12: =IF('Package decision'!B12="Yes",'Package decision'!Y12,"") | G12: =IF(E12="","",E12+IF(F12="AM",TIME(8,0,0),TIME(14,0,0))) | H12: =IF(E12="","",E12+IF(F12="AM",TIME(13,0,0),TIME(22,0,0))) | I12: =IF('Package decision'!B12="Yes",'Package decision'!S12,0) -> 0 | J12: =IF('Package decision'!B12="Yes",'Package decision'!U12,"") | K12: =IF('Package decision'!B12="Yes",'Package decision'!V12,"") | L12: =IF('Package decision'!B12="Yes","AUTHORIZED - COMMISSION","NOT AUTHORISED") -> NOT AUTHORISED | M12: =TEXT('Package decision'!M12,"dd mmm")&" to "&TEXT('Package decision'!N12,"dd mmm")&" / "&'Package decision'!P12 -> 20 May to 20 May / | N12: =IF(L12<>"AUTHORIZED - COMMISSION","n/a",IF(AND('Package decision'!AA12="OK",'Package decision'!AB12<>"CHECK"),"OK","CHECK")) -> n/a | O12: =IF(L12<>"AUTHORIZED - COMMISSION","n/a",'Package decision'!AC12) -> n/a | P12: =IF(L12<>"AUTHORIZED - COMMISSION","n/a",IF(COUNTIFS(Calendar!$A$6:$A$14,E12,Calendar!$G$6:$G$14,"*"&F12&"*")=1,"OK","CHECK")) -> n/a | Q12: =IF(L12<>"AUTHORIZED - COMMISSION","n/a",IF(H12<=DATE(2026,5,28)+TIME(23,0,0),"OK","CHECK")) -> n/a
A13: ='Package decision'!A13 -> MH-204 | B13: =IF('Package decision'!B13="Yes","Commissioning evidence","Candidate not authorised") -> Candidate not authorised | C13: ='Package decision'!C13 -> Millhaven | D13: ='Package decision'!D13 -> Horizon | E13: =IF('Package decision'!B13="Yes",'Package decision'!X13,"") | F13: =IF('Package decision'!B13="Yes",'Package decision'!Y13,"") | G13: =IF(E13="","",E13+IF(F13="AM",TIME(8,0,0),TIME(14,0,0))) | H13: =IF(E13="","",E13+IF(F13="AM",TIME(13,0,0),TIME(22,0,0))) | I13: =IF('Package decision'!B13="Yes",'Package decision'!S13,0) -> 0 | J13: =IF('Package decision'!B13="Yes",'Package decision'!U13,"") | K13: =IF('Package decision'!B13="Yes",'Package decision'!V13,"") | L13: =IF('Package decision'!B13="Yes","AUTHORIZED - COMMISSION","NOT AUTHORISED") -> NOT AUTHORISED | M13: =TEXT('Package decision'!M13,"dd mmm")&" to "&TEXT('Package decision'!N13,"dd mmm")&" / "&'Package decision'!P13 -> 21 May to 21 May / MH-203 | N13: =IF(L13<>"AUTHORIZED - COMMISSION","n/a",IF(AND('Package decision'!AA13="OK",'Package decision'!AB13<>"CHECK"),"OK","CHECK")) -> n/a | O13: =IF(L13<>"AUTHORIZED - COMMISSION","n/a",'Package decision'!AC13) -> n/a | P13: =IF(L13<>"AUTHORIZED - COMMISSION","n/a",IF(COUNTIFS(Calendar!$A$6:$A$14,E13,Calendar!$G$6:$G$14,"*"&F13&"*")=1,"OK","CHECK")) -> n/a | Q13: =IF(L13<>"AUTHORIZED - COMMISSION","n/a",IF(H13<=DATE(2026,5,28)+TIME(23,0,0),"OK","CHECK")) -> n/a
A14: ='Package decision'!A14 -> DS-301 | B14: =IF('Package decision'!B14="Yes","Commissioning evidence","Candidate not authorised") -> Commissioning evidence | C14: ='Package decision'!C14 -> Docksett | D14: ='Package decision'!D14 -> Kestrel | E14: =IF('Package decision'!B14="Yes",'Package decision'!X14,"") -> 46168 | F14: =IF('Package decision'!B14="Yes",'Package decision'!Y14,"") -> PM | G14: =IF(E14="","",E14+IF(F14="AM",TIME(8,0,0),TIME(14,0,0))) -> 46168.583 | H14: =IF(E14="","",E14+IF(F14="AM",TIME(13,0,0),TIME(22,0,0))) -> 46168.917 | I14: =IF('Package decision'!B14="Yes",'Package decision'!S14,0) -> 12 | J14: =IF('Package decision'!B14="Yes",'Package decision'!U14,"") -> Yes | K14: =IF('Package decision'!B14="Yes",'Package decision'!V14,"") -> Lorcan Ibarra | L14: =IF('Package decision'!B14="Yes","AUTHORIZED - COMMISSION","NOT AUTHORISED") -> AUTHORIZED - COMMISSION | M14: =TEXT('Package decision'!M14,"dd mmm")&" to "&TEXT('Package decision'!N14,"dd mmm")&" / "&'Package decision'!P14 -> 26 May to 26 May / | N14: =IF(L14<>"AUTHORIZED - COMMISSION","n/a",IF(AND('Package decision'!AA14="OK",'Package decision'!AB14<>"CHECK"),"OK","CHECK")) -> OK | O14: =IF(L14<>"AUTHORIZED - COMMISSION","n/a",'Package decision'!AC14) -> OK | P14: =IF(L14<>"AUTHORIZED - COMMISSION","n/a",IF(COUNTIFS(Calendar!$A$6:$A$14,E14,Calendar!$G$6:$G$14,"*"&F14&"*")=1,"OK","CHECK")) -> OK | Q14: =IF(L14<>"AUTHORIZED - COMMISSION","n/a",IF(H14<=DATE(2026,5,28)+TIME(23,0,0),"OK","CHECK")) -> OK
A15: ='Package decision'!A15 -> DS-302 | B15: =IF('Package decision'!B15="Yes","Commissioning evidence","Candidate not authorised") -> Commissioning evidence | C15: ='Package decision'!C15 -> Docksett | D15: ='Package decision'!D15 -> Kestrel | E15: =IF('Package decision'!B15="Yes",'Package decision'!X15,"") -> 46169 | F15: =IF('Package decision'!B15="Yes",'Package decision'!Y15,"") -> AM | G15: =IF(E15="","",E15+IF(F15="AM",TIME(8,0,0),TIME(14,0,0))) -> 46169.333 | H15: =IF(E15="","",E15+IF(F15="AM",TIME(13,0,0),TIME(22,0,0))) -> 46169.542 | I15: =IF('Package decision'!B15="Yes",'Package decision'!S15,0) -> 6 | J15: =IF('Package decision'!B15="Yes",'Package decision'!U15,"") -> Yes | K15: =IF('Package decision'!B15="Yes",'Package decision'!V15,"") -> Lorcan Ibarra | L15: =IF('Package decision'!B15="Yes","AUTHORIZED - COMMISSION","NOT AUTHORISED") -> AUTHORIZED - COMMISSION | M15: =TEXT('Package decision'!M15,"dd mmm")&" to "&TEXT('Package decision'!N15,"dd mmm")&" / "&'Package decision'!P15 -> 27 May to 27 May / DS-301 | N15: =IF(L15<>"AUTHORIZED - COMMISSION","n/a",IF(AND('Package decision'!AA15="OK",'Package decision'!AB15<>"CHECK"),"OK","CHECK")) -> OK | O15: =IF(L15<>"AUTHORIZED - COMMISSION","n/a",'Package decision'!AC15) -> OK | P15: =IF(L15<>"AUTHORIZED - COMMISSION","n/a",IF(COUNTIFS(Calendar!$A$6:$A$14,E15,Calendar!$G$6:$G$14,"*"&F15&"*")=1,"OK","CHECK")) -> OK | Q15: =IF(L15<>"AUTHORIZED - COMMISSION","n/a",IF(H15<=DATE(2026,5,28)+TIME(23,0,0),"OK","CHECK")) -> OK
A16: ='Package decision'!A16 -> DS-303 | B16: =IF('Package decision'!B16="Yes","Commissioning evidence","Candidate not authorised") -> Candidate not authorised | C16: ='Package decision'!C16 -> Docksett | D16: ='Package decision'!D16 -> Kestrel | E16: =IF('Package decision'!B16="Yes",'Package decision'!X16,"") | F16: =IF('Package decision'!B16="Yes",'Package decision'!Y16,"") | G16: =IF(E16="","",E16+IF(F16="AM",TIME(8,0,0),TIME(14,0,0))) | H16: =IF(E16="","",E16+IF(F16="AM",TIME(13,0,0),TIME(22,0,0))) | I16: =IF('Package decision'!B16="Yes",'Package decision'!S16,0) -> 0 | J16: =IF('Package decision'!B16="Yes",'Package decision'!U16,"") | K16: =IF('Package decision'!B16="Yes",'Package decision'!V16,"") | L16: =IF('Package decision'!B16="Yes","AUTHORIZED - COMMISSION","NOT AUTHORISED") -> NOT AUTHORISED | M16: =TEXT('Package decision'!M16,"dd mmm")&" to "&TEXT('Package decision'!N16,"dd mmm")&" / "&'Package decision'!P16 -> 26 May to 26 May / | N16: =IF(L16<>"AUTHORIZED - COMMISSION","n/a",IF(AND('Package decision'!AA16="OK",'Package decision'!AB16<>"CHECK"),"OK","CHECK")) -> n/a | O16: =IF(L16<>"AUTHORIZED - COMMISSION","n/a",'Package decision'!AC16) -> n/a | P16: =IF(L16<>"AUTHORIZED - COMMISSION","n/a",IF(COUNTIFS(Calendar!$A$6:$A$14,E16,Calendar!$G$6:$G$14,"*"&F16&"*")=1,"OK","CHECK")) -> n/a | Q16: =IF(L16<>"AUTHORIZED - COMMISSION","n/a",IF(H16<=DATE(2026,5,28)+TIME(23,0,0),"OK","CHECK")) -> n/a
A17: ='Package decision'!A17 -> DS-304 | B17: =IF('Package decision'!B17="Yes","Commissioning evidence","Candidate not authorised") -> Candidate not authorised | C17: ='Package decision'!C17 -> Docksett | D17: ='Package decision'!D17 -> Kestrel | E17: =IF('Package decision'!B17="Yes",'Package decision'!X17,"") | F17: =IF('Package decision'!B17="Yes",'Package decision'!Y17,"") | G17: =IF(E17="","",E17+IF(F17="AM",TIME(8,0,0),TIME(14,0,0))) | H17: =IF(E17="","",E17+IF(F17="AM",TIME(13,0,0),TIME(22,0,0))) | I17: =IF('Package decision'!B17="Yes",'Package decision'!S17,0) -> 0 | J17: =IF('Package decision'!B17="Yes",'Package decision'!U17,"") | K17: =IF('Package decision'!B17="Yes",'Package decision'!V17,"") | L17: =IF('Package decision'!B17="Yes","AUTHORIZED - COMMISSION","NOT AUTHORISED") -> NOT AUTHORISED | M17: =TEXT('Package decision'!M17,"dd mmm")&" to "&TEXT('Package decision'!N17,"dd mmm")&" / "&'Package decision'!P17 -> 27 May to 27 May / DS-303 | N17: =IF(L17<>"AUTHORIZED - COMMISSION","n/a",IF(AND('Package decision'!AA17="OK",'Package decision'!AB17<>"CHECK"),"OK","CHECK")) -> n/a | O17: =IF(L17<>"AUTHORIZED - COMMISSION","n/a",'Package decision'!AC17) -> n/a | P17: =IF(L17<>"AUTHORIZED - COMMISSION","n/a",IF(COUNTIFS(Calendar!$A$6:$A$14,E17,Calendar!$G$6:$G$14,"*"&F17&"*")=1,"OK","CHECK")) -> n/a | Q17: =IF(L17<>"AUTHORIZED - COMMISSION","n/a",IF(H17<=DATE(2026,5,28)+TIME(23,0,0),"OK","CHECK")) -> n/a
... A27: ='Package decision'!A27 -> LF-407 | B27: =IF('Package decision'!B27="Yes","Commissioning evidence","Candidate not authorised") -> Candidate not authorised | C27: ='Package decision'!C27 -> Larkfield | D27: ='Package decision'!D27 -> Kestrel | E27: =IF('Package decision'!B27="Yes",'Package decision'!X27,"") | F27: =IF('Package decision'!B27="Yes",'Package decision'!Y27,"") | G27: =IF(E27="","",E27+IF(F27="AM",TIME(8,0,0),TIME(14,0,0))) | H27: =IF(E27="","",E27+IF(F27="AM",TIME(13,0,0),TIME(22,0,0))) | I27: =IF('Package decision'!B27="Yes",'Package decision'!S27,0) -> 0 | J27: =IF('Package decision'!B27="Yes",'Package decision'!U27,"") | K27: =IF('Package decision'!B27="Yes",'Package decision'!V27,"") | L27: =IF('Package decision'!B27="Yes","AUTHORIZED - COMMISSION","NOT AUTHORISED") -> NOT AUTHORISED | M27: =TEXT('Package decision'!M27,"dd mmm")&" to "&TEXT('Package decision'!N27,"dd mmm")&" / "&'Package decision'!P27 -> 28 May to 28 May / | N27: =IF(L27<>"AUTHORIZED - COMMISSION","n/a",IF(AND('Package decision'!AA27="OK",'Package decision'!AB27<>"CHECK"),"OK","CHECK")) -> n/a | O27: =IF(L27<>"AUTHORIZED - COMMISSION","n/a",'Package decision'!AC27) -> n/a | P27: =IF(L27<>"AUTHORIZED - COMMISSION","n/a",IF(COUNTIFS(Calendar!$A$6:$A$14,E27,Calendar!$G$6:$G$14,"*"&F27&"*")=1,"OK","CHECK")) -> n/a | Q27: =IF(L27<>"AUTHORIZED - COMMISSION","n/a",IF(H27<=DATE(2026,5,28)+TIME(23,0,0),"OK","CHECK")) -> n/a
A29: RECAL-01 | B29: =IF('Capacity & finance'!$F$9>0,"Recalibration","No recalibration required") -> Recalibration | C29: All plant rooms | D29: Horizon -> Kestrel | E29: =IF('Capacity & finance'!$F$9>0,DATE(2026,5,22),"") -> 46164 | F29: =IF(E29<>"","AM","") -> AM | G29: =IF(E29="","",E29+TIME(8,0,0)) -> 46164.333 | H29: =IF(E29="","",E29+TIME(13,0,0)) -> 46164.542 | I29: 0 | J29: =IF(E29<>"","Yes","") -> Yes | K29: =IF(E29<>"","Lorcan Ibarra","") -> Lorcan Ibarra | L29: =IF(E29<>"","RESERVED - RECALIBRATION","NOT REQUIRED") -> RESERVED - RECALIBRATION | M29: Whole listed engineer shift; no test may share it | N29: =IF(E29<>"","OK","n/a") -> OK | O29: n/a | P29: =IF(E29<>"",IF(COUNTIFS(Calendar!$A$6:$A$14,E29,Calendar!$G$6:$G$14,"*"&F29&"*")=1,"OK","CHECK"),"n/a") -> OK | Q29: =IF(E29="","n/a",IF(H29<=DATE(2026,5,28)+TIME(23,0,0),"OK","CHECK")) -> OK
A31: MILE-QR | B31: Quality review | C31: Portfolio | D31: - | E31: 46171 | F31: AM | G31: 46171.375 | H31: 46171.458 | I31: 0 | J31: No | K31: Magda Villanueva | L31: MILESTONE | M31: Review after all commissioning evidence | N31: =IF(AND(G31>MAX($H$6:$H$27),G31<$G$32),"OK","CHECK") -> OK | O31: n/a | P31: =IF(COUNTIFS(Calendar!$A$6:$A$14,E31,Calendar!$D$6:$D$14,"*"&F31&"*")=1,"OK","CHECK") -> OK | Q31: =IF(H31<=DATE(2026,5,29)+TIME(14,0,0),"OK","CHECK") -> OK
A32: MILE-SUB | B32: Regulator submission | C32: Portfolio | D32: - | E32: 46171 | F32: AM | G32: 46171.562 | H32: 46171.562 | I32: 0 | J32: No | K32: Magda Villanueva | L32: MILESTONE | M32: Regulator-ready pack submission | N32: =IF(AND(G32>H31,G32<=DATE(2026,5,29)+TIME(14,0,0)),"OK","CHECK") -> OK | O32: n/a | P32: =IF(COUNTIFS(Calendar!$A$6:$A$14,E32,Calendar!$D$6:$D$14,"*"&F32&"*")=1,"OK","CHECK") -> OK | Q32: =IF(G32<=DATE(2026,5,29)+TIME(14,0,0),"OK","CHECK") -> OK

Sheet Capacity & finance
A1: Capacity & finance
A2: Source rates, engineer allocation, daily field capacity, delivery cost and unit exposure
A4: Commercial and timing inputs | E4: Portfolio summary
A5: Technician labour rate | B5: 92 | E5: Selected packages | F5: =COUNTIF('Package decision'!$B$6:$B$27,"Yes") -> 7
A6: Engineer test-shift rate | B6: 1180 | E6: Selected eligible packages | F6: =COUNTIFS('Package decision'!$B$6:$B$27,"Yes",'Package decision'!$Z$6:$Z$27,"Eligible") -> 7
A7: Recalibration charge | B7: 6450 | E7: Selected technician effort | F7: =SUMIFS('Package decision'!$S$6:$S$27,'Package decision'!$B$6:$B$27,"Yes") -> 67
A8: Delivery-cost cap | B8: 47000 | E8: Commissioning test shifts | F8: =COUNTIFS('Package decision'!$B$6:$B$27,"Yes",'Package decision'!$U$6:$U$27,"Yes") -> 7
A9: Exposure start | B9: 46160 | E9: Required recalibration shifts | F9: =SUM($I$50:$I$57) -> 1
