Workbook

Sheet Forecast Inputs
A1: Forecast Inputs — source transcription
A2: Source: five_year_activity_forecast.xlsx | Values reproduced without change; units shown in headings
A4: Scenario | B4: Fiscal year | C4: Screened transactions | D4: Generated alerts | E4: Analyst seats | F4: Source location
A5: Low | B5: FY27 | C5: 900000 | D5: 15000 | E5: 30 | F5: Five-year outlook! row 5
A6: Low | B6: FY28 | C6: 1000000 | D6: 17000 | E6: 32 | F6: Five-year outlook! row 6
A7: Low | B7: FY29 | C7: 1100000 | D7: 19000 | E7: 34 | F7: Five-year outlook! row 7
A8: Low | B8: FY30 | C8: 1200000 | D8: 21000 | E8: 36 | F8: Five-year outlook! row 8
A9: Low | B9: FY31 | C9: 1300000 | D9: 24000 | E9: 38 | F9: Five-year outlook! row 9
A10: Base | B10: FY27 | C10: 1200000 | D10: 20000 | E10: 34 | F10: Five-year outlook! row 10
A11: Base | B11: FY28 | C11: 1350000 | D11: 24000 | E11: 36 | F11: Five-year outlook! row 11
A12: Base | B12: FY29 | C12: 1550000 | D12: 28000 | E12: 38 | F12: Five-year outlook! row 12
A13: Base | B13: FY30 | C13: 1750000 | D13: 33000 | E13: 40 | F13: Five-year outlook! row 13
A14: Base | B14: FY31 | C14: 2000000 | D14: 38000 | E14: 42 | F14: Five-year outlook! row 14
A15: High | B15: FY27 | C15: 1500000 | D15: 26000 | E15: 38 | F15: Five-year outlook! row 15
A16: High | B16: FY28 | C16: 1800000 | D16: 32000 | E16: 41 | F16: Five-year outlook! row 16
... A19: High | B19: FY31 | C19: 2900000 | D19: 59000 | E19: 54 | F19: Five-year outlook! row 19

Sheet False-positive Calc
A1: False-Positive Rate Calculations
A2: Protocol source: monitoring_evaluation_criteria.xlsx | Final dispositions as of 05/31/2026
A4: Platform | B4: Reviewed alerts (denominator) | C4: Final “Closed – no issue” (numerator) | D4: False-positive rate | E4: Source evidence / treatment
A5: BeaconTrace | B5: 20 | C5: 2 | D5: =C5/B5 -> 0.1 | E5: BeaconTrace_proposal.pdf, Validation evidence table
A6: ClaimSphere | B6: 20 | C6: 3 | D6: =C6/B6 -> 0.15 | E6: ClaimSphere_proposal.pdf, Validation evidence table
A7: HarborSignal | B7: 20 | C7: 4 | D7: =C7/B7 -> 0.2 | E7: HarborSignal_proposal.pdf, Validation evidence table
A10: HarborSignal reopened-alert treatment | B10: HS-018 preliminary “Closed – no issue” on 05/02/2026; reopened 05/12/2026; final “Confirmed reportable” 05/20/2026. Final pre-cutoff status is not in numerator. Preliminary snapshot would have been 5/20 (25.00%); final is 4/20 (20.00%).

Sheet BSA Assessment
A1: BSA E-Filing Integration Assessment
A2: Approved definitions from monitoring_evaluation_criteria.xlsx; current demonstrated capability only
A4: Platform | B4: Approved classification | C4: Approved score | D4: Platform-specific evidence | E4: Conclusion basis
A5: BeaconTrace | B5: Roadmap-only / unsupported | C5: 30 | D5: BSA XML export available; submission API connector planned Q4 FY27; no FinCEN sandbox transmission demonstrated. | E5: BeaconTrace_proposal.pdf, Commercial terms / Integration representation
A6: ClaimSphere | B6: Native validated integration | C6: 100 | D6: Native submission and acknowledgement-status receipt included; FinCEN sandbox flow demonstrated 05/28/2026. | E6: ClaimSphere_proposal.pdf, Commercial terms / Integration representation
A7: HarborSignal | B7: Validated connector integration | C7: 70 | D7: Required SecureLink connector submitted filings and retrieved acknowledgements in demonstration 06/02/2026. | E7: HarborSignal_proposal.pdf, Commercial terms / Integration representation

Sheet Five-year Costs
A1: Five-Year Nominal Cost Model
A2: Nominal, undiscounted; implementation charged once in FY27. Source terms cited in Evidence Register.
A4: Scenario | B4: Platform | C4: Cost component | D4: FY27 | E4: FY28 | F4: FY29 | G4: FY30 | H4: FY31 | I4: Five-year total
A5: Low | B5: BeaconTrace | C5: Implementation | D5: =IF(D$4="FY27",180000,0) -> 180000 | E5: =IF(E$4="FY27",180000,0) -> 0 | F5: =IF(F$4="FY27",180000,0) -> 0 | G5: =IF(G$4="FY27",180000,0) -> 0 | H5: =IF(H$4="FY27",180000,0) -> 0 | I5: =SUM(D5:H5) -> 180000
C6: Annual monitoring license | D6: =170000*(1+0.03)^0 -> 170000 | E6: =170000*(1+0.03)^1 -> 175100 | F6: =170000*(1+0.03)^2 -> 180353 | G6: =170000*(1+0.03)^3 -> 185763.59 | H6: =170000*(1+0.03)^4 -> 191336.5 | I6: =SUM(D6:H6) -> 902553.09
C7: Usage charge | D7: =MIN('Forecast Inputs'!C5,1500000)*0.021+MAX('Forecast Inputs'!C5-1500000,0)*0.017 -> 18900 | E7: =MIN('Forecast Inputs'!C6,1500000)*0.021+MAX('Forecast Inputs'!C6-1500000,0)*0.017 -> 21000 | F7: =MIN('Forecast Inputs'!C7,1500000)*0.021+MAX('Forecast Inputs'!C7-1500000,0)*0.017 -> 23100 | G7: =MIN('Forecast Inputs'!C8,1500000)*0.021+MAX('Forecast Inputs'!C8-1500000,0)*0.017 -> 25200 | H7: =MIN('Forecast Inputs'!C9,1500000)*0.021+MAX('Forecast Inputs'!C9-1500000,0)*0.017 -> 27300 | I7: =SUM(D7:H7) -> 115500
C8: Required BSA connector | D8: =0 -> 0 | E8: =0 -> 0 | F8: =0 -> 0 | G8: =0 -> 0 | H8: =0 -> 0 | I8: =SUM(D8:H8) -> 0
C9: TOTAL NOMINAL COST | D9: =SUM(D5:D8) -> 368900 | E9: =SUM(E5:E8) -> 196100 | F9: =SUM(F5:F8) -> 203453 | G9: =SUM(G5:G8) -> 210963.59 | H9: =SUM(H5:H8) -> 218636.5 | I9: =SUM(D9:H9) -> 1198053.1
A10: Low | B10: ClaimSphere | C10: Implementation | D10: =IF(D$4="FY27",140000,0) -> 140000 | E10: =IF(E$4="FY27",140000,0) -> 0 | F10: =IF(F$4="FY27",140000,0) -> 0 | G10: =IF(G$4="FY27",140000,0) -> 0 | H10: =IF(H$4="FY27",140000,0) -> 0 | I10: =SUM(D10:H10) -> 140000
C11: Annual monitoring license | D11: =125000*(1+0.02)^0 -> 125000 | E11: =125000*(1+0.02)^1 -> 127500 | F11: =125000*(1+0.02)^2 -> 130050 | G11: =125000*(1+0.02)^3 -> 132651 | H11: =125000*(1+0.02)^4 -> 135304.02 | I11: =SUM(D11:H11) -> 650505.02
C12: Usage charge | D12: ='Forecast Inputs'!D5*4 -> 60000 | E12: ='Forecast Inputs'!D6*4 -> 68000 | F12: ='Forecast Inputs'!D7*4 -> 76000 | G12: ='Forecast Inputs'!D8*4 -> 84000 | H12: ='Forecast Inputs'!D9*4 -> 96000 | I12: =SUM(D12:H12) -> 384000
C13: Required BSA connector | D13: =0 -> 0 | E13: =0 -> 0 | F13: =0 -> 0 | G13: =0 -> 0 | H13: =0 -> 0 | I13: =SUM(D13:H13) -> 0
C14: TOTAL NOMINAL COST | D14: =SUM(D10:D13) -> 325000 | E14: =SUM(E10:E13) -> 195500 | F14: =SUM(F10:F13) -> 206050 | G14: =SUM(G10:G13) -> 216651 | H14: =SUM(H10:H13) -> 231304.02 | I14: =SUM(D14:H14) -> 1174505
A15: Low | B15: HarborSignal | C15: Implementation | D15: =IF(D$4="FY27",230000,0) -> 230000 | E15: =IF(E$4="FY27",230000,0) -> 0 | F15: =IF(F$4="FY27",230000,0) -> 0 | G15: =IF(G$4="FY27",230000,0) -> 0 | H15: =IF(H$4="FY27",230000,0) -> 0 | I15: =SUM(D15:H15) -> 230000
C16: Annual monitoring license | D16: =95000*(1+0.03)^0 -> 95000 | E16: =95000*(1+0.03)^1 -> 97850 | F16: =95000*(1+0.03)^2 -> 100785.5 | G16: =95000*(1+0.03)^3 -> 103809.07 | H16: =95000*(1+0.03)^4 -> 106923.34 | I16: =SUM(D16:H16) -> 504367.9
C17: Usage charge | D17: =MIN('Forecast Inputs'!C5,1500000)*0.012+MAX('Forecast Inputs'!C5-1500000,0)*0.009 -> 10800 | E17: =MIN('Forecast Inputs'!C6,1500000)*0.012+MAX('Forecast Inputs'!C6-1500000,0)*0.009 -> 12000 | F17: =MIN('Forecast Inputs'!C7,1500000)*0.012+MAX('Forecast Inputs'!C7-1500000,0)*0.009 -> 13200 | G17: =MIN('Forecast Inputs'!C8,1500000)*0.012+MAX('Forecast Inputs'!C8-1500000,0)*0.009 -> 14400 | H17: =MIN('Forecast Inputs'!C9,1500000)*0.012+MAX('Forecast Inputs'!C9-1500000,0)*0.009 -> 15600 | I17: =SUM(D17:H17) -> 66000
C18: Required BSA connector | D18: =28000 -> 28000 | E18: =28000 -> 28000 | F18: =28000 -> 28000 | G18: =28000 -> 28000 | H18: =28000 -> 28000 | I18: =SUM(D18:H18) -> 140000
C19: TOTAL NOMINAL COST | D19: =SUM(D15:D18) -> 363800 | E19: =SUM(E15:E18) -> 137850 | F19: =SUM(F15:F18) -> 141985.5 | G19: =SUM(G15:G18) -> 146209.07 | H19: =SUM(H15:H18) -> 150523.34 | I19: =SUM(D19:H19) -> 940367.9
A20: Base | B20: BeaconTrace | C20: Implementation | D20: =IF(D$4="FY27",180000,0) -> 180000 | E20: =IF(E$4="FY27",180000,0) -> 0 | F20: =IF(F$4="FY27",180000,0) -> 0 | G20: =IF(G$4="FY27",180000,0) -> 0 | H20: =IF(H$4="FY27",180000,0) -> 0 | I20: =SUM(D20:H20) -> 180000
C21: Annual monitoring license | D21: =170000*(1+0.03)^0 -> 170000 | E21: =170000*(1+0.03)^1 -> 175100 | F21: =170000*(1+0.03)^2 -> 180353 | G21: =170000*(1+0.03)^3 -> 185763.59 | H21: =170000*(1+0.03)^4 -> 191336.5 | I21: =SUM(D21:H21) -> 902553.09
C22: Usage charge | D22: =MIN('Forecast Inputs'!C10,1500000)*0.021+MAX('Forecast Inputs'!C10-1500000,0)*0.017 -> 25200 | E22: =MIN('Forecast Inputs'!C11,1500000)*0.021+MAX('Forecast Inputs'!C11-1500000,0)*0.017 -> 28350 | F22: =MIN('Forecast Inputs'!C12,1500000)*0.021+MAX('Forecast Inputs'!C12-1500000,0)*0.017 -> 32350 | G22: =MIN('Forecast Inputs'!C13,1500000)*0.021+MAX('Forecast Inputs'!C13-1500000,0)*0.017 -> 35750 | H22: =MIN('Forecast Inputs'!C14,1500000)*0.021+MAX('Forecast Inputs'!C14-1500000,0)*0.017 -> 40000 | I22: =SUM(D22:H22) -> 161650
C23: Required BSA connector | D23: =0 -> 0 | E23: =0 -> 0 | F23: =0 -> 0 | G23: =0 -> 0 | H23: =0 -> 0 | I23: =SUM(D23:H23) -> 0
C24: TOTAL NOMINAL COST | D24: =SUM(D20:D23) -> 375200 | E24: =SUM(E20:E23) -> 203450 | F24: =SUM(F20:F23) -> 212703 | G24: =SUM(G20:G23) -> 221513.59 | H24: =SUM(H20:H23) -> 231336.5 | I24: =SUM(D24:H24) -> 1244203.1
A25: Base | B25: ClaimSphere | C25: Implementation | D25: =IF(D$4="FY27",140000,0) -> 140000 | E25: =IF(E$4="FY27",140000,0) -> 0 | F25: =IF(F$4="FY27",140000,0) -> 0 | G25: =IF(G$4="FY27",140000,0) -> 0 | H25: =IF(H$4="FY27",140000,0) -> 0 | I25: =SUM(D25:H25) -> 140000
C26: Annual monitoring license | D26: =125000*(1+0.02)^0 -> 125000 | E26: =125000*(1+0.02)^1 -> 127500 | F26: =125000*(1+0.02)^2 -> 130050 | G26: =125000*(1+0.02)^3 -> 132651 | H26: =125000*(1+0.02)^4 -> 135304.02 | I26: =SUM(D26:H26) -> 650505.02
C27: Usage charge | D27: ='Forecast Inputs'!D10*4 -> 80000 | E27: ='Forecast Inputs'!D11*4 -> 96000 | F27: ='Forecast Inputs'!D12*4 -> 112000 | G27: ='Forecast Inputs'!D13*4 -> 132000 | H27: ='Forecast Inputs'!D14*4 -> 152000 | I27: =SUM(D27:H27) -> 572000
C28: Required BSA connector | D28: =0 -> 0 | E28: =0 -> 0 | F28: =0 -> 0 | G28: =0 -> 0 | H28: =0 -> 0 | I28: =SUM(D28:H28) -> 0
C29: TOTAL NOMINAL COST | D29: =SUM(D25:D28) -> 345000 | E29: =SUM(E25:E28) -> 223500 | F29: =SUM(F25:F28) -> 242050 | G29: =SUM(G25:G28) -> 264651 | H29: =SUM(H25:H28) -> 287304.02 | I29: =SUM(D29:H29) -> 1362505
A30: Base | B30: HarborSignal | C30: Implementation | D30: =IF(D$4="FY27",230000,0) -> 230000 | E30: =IF(E$4="FY27",230000,0) -> 0 | F30: =IF(F$4="FY27",230000,0) -> 0 | G30: =IF(G$4="FY27",230000,0) -> 0 | H30: =IF(H$4="FY27",230000,0) -> 0 | I30: =SUM(D30:H30) -> 230000
C31: Annual monitoring license | D31: =95000*(1+0.03)^0 -> 95000 | E31: =95000*(1+0.03)^1 -> 97850 | F31: =95000*(1+0.03)^2 -> 100785.5 | G31: =95000*(1+0.03)^3 -> 103809.07 | H31: =95000*(1+0.03)^4 -> 106923.34 | I31: =SUM(D31:H31) -> 504367.9
C32: Usage charge | D32: =MIN('Forecast Inputs'!C10,1500000)*0.012+MAX('Forecast Inputs'!C10-1500000,0)*0.009 -> 14400 | E32: =MIN('Forecast Inputs'!C11,1500000)*0.012+MAX('Forecast Inputs'!C11-1500000,0)*0.009 -> 16200 | F32: =MIN('Forecast Inputs'!C12,1500000)*0.012+MAX('Forecast Inputs'!C12-1500000,0)*0.009 -> 18450 | G32: =MIN('Forecast Inputs'!C13,1500000)*0.012+MAX('Forecast Inputs'!C13-1500000,0)*0.009 -> 20250 | H32: =MIN('Forecast Inputs'!C14,1500000)*0.012+MAX('Forecast Inputs'!C14-1500000,0)*0.009 -> 22500 | I32: =SUM(D32:H32) -> 91800
C33: Required BSA connector | D33: =28000 -> 28000 | E33: =28000 -> 28000 | F33: =28000 -> 28000 | G33: =28000 -> 28000 | H33: =28000 -> 28000 | I33: =SUM(D33:H33) -> 140000
C34: TOTAL NOMINAL COST | D34: =SUM(D30:D33) -> 367400 | E34: =SUM(E30:E33) -> 142050 | F34: =SUM(F30:F33) -> 147235.5 | G34: =SUM(G30:G33) -> 152059.07 | H34: =SUM(H30:H33) -> 157423.34 | I34: =SUM(D34:H34) -> 966167.9
A35: High | B35: BeaconTrace | C35: Implementation | D35: =IF(D$4="FY27",180000,0) -> 180000 | E35: =IF(E$4="FY27",180000,0) -> 0 | F35: =IF(F$4="FY27",180000,0) -> 0 | G35: =IF(G$4="FY27",180000,0) -> 0 | H35: =IF(H$4="FY27",180000,0) -> 0 | I35: =SUM(D35:H35) -> 180000
C36: Annual monitoring license | D36: =170000*(1+0.03)^0 -> 170000 | E36: =170000*(1+0.03)^1 -> 175100 | F36: =170000*(1+0.03)^2 -> 180353 | G36: =170000*(1+0.03)^3 -> 185763.59 | H36: =170000*(1+0.03)^4 -> 191336.5 | I36: =SUM(D36:H36) -> 902553.09
C37: Usage charge | D37: =MIN('Forecast Inputs'!C15,1500000)*0.021+MAX('Forecast Inputs'!C15-1500000,0)*0.017 -> 31500 | E37: =MIN('Forecast Inputs'!C16,1500000)*0.021+MAX('Forecast Inputs'!C16-1500000,0)*0.017 -> 36600 | F37: =MIN('Forecast Inputs'!C17,1500000)*0.021+MAX('Forecast Inputs'!C17-1500000,0)*0.017 -> 41700 | G37: =MIN('Forecast Inputs'!C18,1500000)*0.021+MAX('Forecast Inputs'!C18-1500000,0)*0.017 -> 48500 | H37: =MIN('Forecast Inputs'!C19,1500000)*0.021+MAX('Forecast Inputs'!C19-1500000,0)*0.017 -> 55300 | I37: =SUM(D37:H37) -> 213600
C38: Required BSA connector | D38: =0 -> 0 | E38: =0 -> 0 | F38: =0 -> 0 | G38: =0 -> 0 | H38: =0 -> 0 | I38: =SUM(D38:H38) -> 0
C39: TOTAL NOMINAL COST | D39: =SUM(D35:D38) -> 381500 | E39: =SUM(E35:E38) -> 211700 | F39: =SUM(F35:F38) -> 222053 | G39: =SUM(G35:G38) -> 234263.59 | H39: =SUM(H35:H38) -> 246636.5 | I39: =SUM(D39:H39) -> 1296153.1
A40: High | B40: ClaimSphere | C40: Implementation | D40: =IF(D$4="FY27",140000,0) -> 140000 | E40: =IF(E$4="FY27",140000,0) -> 0 | F40: =IF(F$4="FY27",140000,0) -> 0 | G40: =IF(G$4="FY27",140000,0) -> 0 | H40: =IF(H$4="FY27",140000,0) -> 0 | I40: =SUM(D40:H40) -> 140000
C41: Annual monitoring license | D41: =125000*(1+0.02)^0 -> 125000 | E41: =125000*(1+0.02)^1 -> 127500 | F41: =125000*(1+0.02)^2 -> 130050 | G41: =125000*(1+0.02)^3 -> 132651 | H41: =125000*(1+0.02)^4 -> 135304.02 | I41: =SUM(D41:H41) -> 650505.02
...

Sheet Evaluation Summary
A1: Platform Evaluation & Recommendation
A2: Approved grid plus one explicit implementation-risk overlay; see Assumptions and Evidence Register
A4: Measure | B4: Weight | C4: BeaconTrace | D4: ClaimSphere | E4: HarborSignal | F4: Source / decision rule
A5: False-positive rate | B5: 0.25 | C5: ='False-positive Calc'!D5 -> 0.1 | D5: ='False-positive Calc'!D6 -> 0.15 | E5: ='False-positive Calc'!D7 -> 0.2 | F5: Approved protocol and FPR bands
A6: FPR criterion score | C6: =IF(C5<=10%,100,IF(C5<=15%,80,IF(C5<=20%,60,30))) -> 100 | D6: =IF(D5<=10%,100,IF(D5<=15%,80,IF(D5<=20%,60,30))) -> 80 | E6: =IF(E5<=10%,100,IF(E5<=15%,80,IF(E5<=20%,60,30))) -> 60 | F6: Approved bands
A7: BSA classification | B7: 0.35 | C7: ='BSA Assessment'!B5 -> Roadmap-only / unsupported | D7: ='BSA Assessment'!B6 -> Native validated integration | E7: ='BSA Assessment'!B7 -> Validated connector integration | F7: Approved definitions; demonstrated current state
A8: BSA criterion score | C8: ='BSA Assessment'!C5 -> 30 | D8: ='BSA Assessment'!C6 -> 100 | E8: ='BSA Assessment'!C7 -> 70 | F8: Approved mapping
A9: Base five-year cost | B9: 0.4 | C9: ='Five-year Costs'!I24 -> 1244203.1 | D9: ='Five-year Costs'!I29 -> 1362505 | E9: ='Five-year Costs'!I34 -> 966167.9 | F9: Base scenario; nominal undiscounted
A10: Cost criterion score | C10: =IF(C9<=1000000,100,IF(C9<=1500000,60,30)) -> 60 | D10: =IF(D9<=1000000,100,IF(D9<=1500000,60,30)) -> 60 | E10: =IF(E9<=1000000,100,IF(E9<=1500000,60,30)) -> 100 | F10: Approved bands
A11: Approved weighted total | C11: =C6*$B$5+C8*$B$7+C10*$B$9 -> 59.5 | D11: =D6*$B$5+D8*$B$7+D10*$B$9 -> 79 | E11: =E6*$B$5+E8*$B$7+E10*$B$9 -> 79.5 | F11: Sum of score × approved weight
A12: Unadjusted rank | C12: =RANK(C11,$C$11:$E$11,0) -> 3 | D12: =RANK(D11,$C$11:$E$11,0) -> 2 | E12: =RANK(E11,$C$11:$E$11,0) -> 1 | F12: Tie convention: equal totals share rank
A13: Implementation-risk adjustment (points) | C13: 0 | D13: 0 | E13: -2 | F13: HarborSignal only; Slateford evidence-based overlay, applied once
A14: Risk-adjusted decision total | C14: =C11+C13 -> 59.5 | D14: =D11+D13 -> 79 | E14: =E11+E13 -> 77.5 | F14: Approved total + adjustment
A15: Adjusted rank | C15: =RANK(C14,$C$14:$E$14,0) -> 3 | D15: =RANK(D14,$C$14:$E$14,0) -> 1 | E15: =RANK(E14,$C$14:$E$14,0) -> 2 | F15: Decision measure
A16: Recommendation | D16: RECOMMEND CLAIMSPHERE | F16: ClaimSphere has highest adjusted decision total
A18: Scenario five-year cost | C18: ='Five-year Costs'!I9 -> 1198053.1 | D18: ='Five-year Costs'!I14 -> 1174505 | E18: ='Five-year Costs'!I19 -> 940367.9 | F18: Low scenario
A19: Scenario five-year cost | C19: ='Five-year Costs'!I24 -> 1244203.1 | D19: ='Five-year Costs'!I29 -> 1362505 | E19: ='Five-year Costs'!I34 -> 966167.9 | F19: Base scenario
A20: Scenario five-year cost | C20: ='Five-year Costs'!I39 -> 1296153.1 | D20: ='Five-year Costs'!I44 -> 1614505 | E20: ='Five-year Costs'!I49 -> 994067.9 | F20: High scenario
A22: Switching / sensitivity | D22: =E11-D11 -> 0.5 | F22: HarborSignal’s unadjusted lead is 0.50 points. A HarborSignal deduction greater than 0.50 points makes ClaimSphere outrank it; selected deduction is 2.00 points.

Sheet Evidence Register
A1: Evidence Register & Source Traceability
A2: Specific source locations for material quantities and evidence used in the workpaper
A4: ID | B4: Input / conclusion | C4: Source file | D4: Specific location / label | E4: Use in workpaper | F4: Included?
A5: E01 | B5: Weights, scoring bands, integration definitions | C5: monitoring_evaluation_criteria.xlsx | D5: Evaluation grid! rows 5–7 | E5: Evaluation Summary | F5: Yes
A6: E02 | B6: Final-status FPR protocol and cutoff | C6: monitoring_evaluation_criteria.xlsx | D6: Evaluation grid! Review protocol row 10 | E6: False-positive Calc | F6: Yes
A7: E03 | B7: Legacy formula error | C7: monitoring_evaluation_criteria.xlsx | D7: Evaluation grid! B12, Legacy calculated total | E7: Excluded; recalculated underlying evidence | F7: No
A8: E04 | B8: Unrelated administrative tracking table | C8: monitoring_evaluation_criteria.xlsx | D8: Evaluation grid! G4:I6 | E8: Excluded from evaluation | F8: No
A9: E05 | B9: All three scenario activity inputs | C9: five_year_activity_forecast.xlsx | D9: Five-year outlook! rows 5–19 | E9: Forecast Inputs / Costs | F9: Yes
A10: E06 | B10: BeaconTrace pricing, BSA representation, alerts | C10: BeaconTrace_proposal.pdf | D10: Commercial terms; Integration representation; Validation evidence pp.1–2 | E10: Costs, BSA, FPR | F10: Yes
A11: E07 | B11: ClaimSphere pricing, BSA representation, alerts | C11: ClaimSphere_proposal.pdf | D11: Commercial terms; Integration representation; Validation evidence pp.1–2 | E11: Costs, BSA, FPR | F11: Yes
A12: E08 | B12: HarborSignal pricing, required connector, HS-018 | C12: HarborSignal_proposal.pdf | D12: Commercial terms; Integration representation; Validation evidence pp.1–2 | E12: Costs, BSA, FPR | F12: Yes
A13: E09 | B13: Slateford Sandpiper delivery history | C13: implementation_reference.docx | D13: Diligence note paragraphs 2–4 | E13: Risk overlay rationale | F13: Yes

Sheet Assumptions
A1: Method Notes, Assumptions & Risk Treatment
A2: Prepared by Sofia Hartnett | 06/20/2026
A4: Topic | B4: Workpaper treatment
A5: Cost basis | B5: Five forecast operating years FY27–FY31 only. Costs are nominal and undiscounted. Contract escalation is applied only to annual licenses, beginning in FY28. Implementation is included once in FY27; HarborSignal’s required connector is included annually without escalation.
A6: Activity scenarios | B6: Low, base, and high source values are copied unchanged. Usage is priced independently each year; no volume averaging. Scenario outputs are planning bounds, not predictions.
A7: False-positive rate | B7: Used final alert disposition as of 05/31/2026. HarborSignal HS-018 is final Confirmed reportable after reopening; therefore excluded from numerator.
A8: Excluded source material | B8: Ignored the residual legacy formula error at Evaluation grid!B12 and recalculated from valid underlying source evidence. Excluded the unrelated administrative tracking table at G4:I6.
A9: Implementation evidence | B9: Sourced fact: Sasha Ellingsen described Slateford’s missed Sandpiper control milestone, staffing turnover, three-month remediation, and January 2024 staged go-live. Inference: this one prior engagement increases delivery-governance risk for HarborSignal; it does not establish future failure probability.
A10: Risk overlay | B10: Applied a single -2.00-point HarborSignal adjustment on the same 100-point scale as approved totals. It is a bounded decision overlay for documented relevance and severity, tempered by completed remediation, elapsed time, and reported (unverified) 2024 changes. It is not embedded in any approved criterion.
A11: Mitigation | B11: If HarborSignal is selected despite this overlay, require named key staff, control-milestone acceptance evidence, weekly reporting, Treasury acceptance rights, and a payment holdback.
