Workbook

Sheet Assignment Register
A1: Fenwick Marsh Environmental — Q3 2026 workload tracker
A2: Decision owner: Rhiannon Setterfield | Client leads confirmed by Friday 26 June 2026 | Q3 ends 25 September 2026
A3: Legend: GREEN = OK, RED = warning/exception. Hours and warnings are formula-driven.
A5: Deliverable ID | B5: Deliverable | C5: Client | D5: Class | E5: Accountable owner | F5: Supporting consultant | G5: Approved submission signatory | H5: Independent reviewer | I5: Required effort (h) | J5: Scheduled effort (h) | K5: Reconciliation | L5: Owner rationale / alternative considered | M5: Control warning
A6: D1 | B6: Saltcombe wetlands permit variation | C6: Saltcombe Provisions | D6: Major | E6: Casimir Oyelowo | F6: Marisol Reinholt | G6: Marisol Reinholt | H6: Chidi Jankowski | I6: 100 | J6: =SUMIF(Allocations!$B$5:$B$43,A6,Allocations!$G$5:$G$43) -> 100 | K6: =IF(I6=J6,"OK","WARNING") -> OK | L6: Casimir owns the only water/wetlands major permit eligible for his W08 supervised-submission commitment; Marisol provides approved discipline sign-off. Chidi is independent reviewer due to water evidence/review competence. Arjun was not selected because air modelling is not the mandatory discipline. | M6: =IF(AND(D6="Major",G6=""),"WARNING: missing signatory",IF(A6="D1",IF(INDEX('Activity Schedule'!$E$5:$E$33,MATCH("D1-F",'Activity Schedule'!$A$5:$A$33,0))=INDEX('Activity Schedule'!$E$5:$E$33,MATCH("D2-F",'Activity Schedule'!$A$5:$A$33,0)),"WARNING: major submissions same week","OK"),"OK")) -> OK
A7: D2 | B7: Westmere air permit variation | C7: Westmere Logistics | D7: Major | E7: Arjun Redmayne | F7: Ravi Moravec | G7: Ravi Moravec | H7: Chidi Jankowski | I7: 98 | J7: =SUMIF(Allocations!$B$5:$B$43,A7,Allocations!$G$5:$G$43) -> 98 | K7: =IF(I7=J7,"OK","WARNING") -> OK | L7: Arjun holds air modelling and emissions competence and can draft the chain; Ravi is the recorded air signatory with Westmere continuity. Marisol was not selected because her approval scope is water/wetlands, not air. | M7: =IF(AND(D7="Major",G7=""),"WARNING: missing signatory",IF(A7="D1",IF(INDEX('Activity Schedule'!$E$5:$E$33,MATCH("D1-F",'Activity Schedule'!$A$5:$A$33,0))=INDEX('Activity Schedule'!$E$5:$E$33,MATCH("D2-F",'Activity Schedule'!$A$5:$A$33,0)),"WARNING: major submissions same week","OK"),"OK")) -> OK
A8: D3 | B8: Saltcombe ecology screening | C8: Saltcombe Provisions | D8: Standard | E8: Chidi Jankowski | I8: 30 | J8: =SUMIF(Allocations!$B$5:$B$43,A8,Allocations!$G$5:$G$43) -> 30 | K8: =IF(I8=J8,"OK","WARNING") -> OK | L8: Chidi has ecology and site evidence competence with Saltcombe continuity; Casimir was not selected because ecology is not recorded in his profile. | M8: =IF(AND(D8="Major",G8=""),"WARNING: missing signatory",IF(A8="D1",IF(INDEX('Activity Schedule'!$E$5:$E$33,MATCH("D1-F",'Activity Schedule'!$A$5:$A$33,0))=INDEX('Activity Schedule'!$E$5:$E$33,MATCH("D2-F",'Activity Schedule'!$A$5:$A$33,0)),"WARNING: major submissions same week","OK"),"OK")) -> OK
A9: D4 | B9: Westmere waste controls | C9: Westmere Logistics | D9: Standard | E9: Lorcan Dimitrov | I9: 42 | J9: =SUMIF(Allocations!$B$5:$B$43,A9,Allocations!$G$5:$G$43) -> 42 | K9: =IF(I9=J9,"OK","WARNING") -> OK | L9: Lorcan has waste operations, audits and controls competence and can complete the client control review without using Ravi's W08 leave week. Arjun was not selected because waste controls are outside his recorded competence. | M9: =IF(AND(D9="Major",G9=""),"WARNING: missing signatory",IF(A9="D1",IF(INDEX('Activity Schedule'!$E$5:$E$33,MATCH("D1-F",'Activity Schedule'!$A$5:$A$33,0))=INDEX('Activity Schedule'!$E$5:$E$33,MATCH("D2-F",'Activity Schedule'!$A$5:$A$33,0)),"WARNING: major submissions same week","OK"),"OK")) -> OK
A10: D5 | B10: Westmere noise assessment | C10: Westmere Logistics | D10: Standard | E10: Arjun Redmayne | I10: 36 | J10: =SUMIF(Allocations!$B$5:$B$43,A10,Allocations!$G$5:$G$43) -> 36 | K10: =IF(I10=J10,"OK","WARNING") -> OK | L10: Arjun has noise and quantitative analysis competence and Westmere continuity; Lorcan was not selected because noise is not in his profile. | M10: =IF(AND(D10="Major",G10=""),"WARNING: missing signatory",IF(A10="D1",IF(INDEX('Activity Schedule'!$E$5:$E$33,MATCH("D1-F",'Activity Schedule'!$A$5:$A$33,0))=INDEX('Activity Schedule'!$E$5:$E$33,MATCH("D2-F",'Activity Schedule'!$A$5:$A$33,0)),"WARNING: major submissions same week","OK"),"OK")) -> OK
A11: D6 | B11: Saltcombe drainage note | C11: Saltcombe Provisions | D11: Standard | E11: Chidi Jankowski | F11: Marisol Reinholt | I11: 40 | J11: =SUMIF(Allocations!$B$5:$B$43,A11,Allocations!$G$5:$G$43) -> 40 | K11: =IF(I11=J11,"OK","WARNING") -> OK | L11: Chidi has drainage competence and Saltcombe continuity; Marisol reviews for water discipline. Casimir was not selected because the review milestone needs independent technical depth. | M11: =IF(AND(D11="Major",G11=""),"WARNING: missing signatory",IF(A11="D1",IF(INDEX('Activity Schedule'!$E$5:$E$33,MATCH("D1-F",'Activity Schedule'!$A$5:$A$33,0))=INDEX('Activity Schedule'!$E$5:$E$33,MATCH("D2-F",'Activity Schedule'!$A$5:$A$33,0)),"WARNING: major submissions same week","OK"),"OK")) -> OK
A12: D7 | B12: Westmere solvent inventory | C12: Westmere Logistics | D12: Standard | E12: Lorcan Dimitrov | I12: 24 | J12: =SUMIF(Allocations!$B$5:$B$43,A12,Allocations!$G$5:$G$43) -> 24 | K12: =IF(I12=J12,"OK","WARNING") -> OK | L12: Lorcan has operational-controls and inventory competence with Westmere continuity; Ravi was retained for signatory work elsewhere. | M12: =IF(AND(D12="Major",G12=""),"WARNING: missing signatory",IF(A12="D1",IF(INDEX('Activity Schedule'!$E$5:$E$33,MATCH("D1-F",'Activity Schedule'!$A$5:$A$33,0))=INDEX('Activity Schedule'!$E$5:$E$33,MATCH("D2-F",'Activity Schedule'!$A$5:$A$33,0)),"WARNING: major submissions same week","OK"),"OK")) -> OK
A13: D8 | B13: Saltcombe trade-effluent pre-application | C13: Saltcombe Provisions | D13: Standard | E13: Casimir Oyelowo | F13: Marisol Reinholt | G13: Marisol Reinholt | I13: 26 | J13: =SUMIF(Allocations!$B$5:$B$43,A13,Allocations!$G$5:$G$43) -> 26 | K13: =IF(I13=J13,"OK","WARNING") -> OK | L13: Casimir has water drafting and client-preparation evidence; Marisol is the approved client-facing signatory. Chidi was not selected to keep the development workload with Casimir and preserve independent review capacity. | M13: =IF(AND(D13="Major",G13=""),"WARNING: missing signatory",IF(A13="D1",IF(INDEX('Activity Schedule'!$E$5:$E$33,MATCH("D1-F",'Activity Schedule'!$A$5:$A$33,0))=INDEX('Activity Schedule'!$E$5:$E$33,MATCH("D2-F",'Activity Schedule'!$A$5:$A$33,0)),"WARNING: major submissions same week","OK"),"OK")) -> OK
A14: D9 | B14: Quarterly permit register | C14: Both | D14: Standard | E14: Lorcan Dimitrov | F14: Ravi Moravec | I14: 32 | J14: =SUMIF(Allocations!$B$5:$B$43,A14,Allocations!$G$5:$G$43) -> 32 | K14: =IF(I14=J14,"OK","WARNING") -> OK | L14: Lorcan has permit-register competence; Ravi performs QA for Westmere-facing control assurance. Chidi was not selected because ecology/drainage time is needed on technical work. | M14: =IF(AND(D14="Major",G14=""),"WARNING: missing signatory",IF(A14="D1",IF(INDEX('Activity Schedule'!$E$5:$E$33,MATCH("D1-F",'Activity Schedule'!$A$5:$A$33,0))=INDEX('Activity Schedule'!$E$5:$E$33,MATCH("D2-F",'Activity Schedule'!$A$5:$A$33,0)),"WARNING: major submissions same week","OK"),"OK")) -> OK

Sheet Activity Schedule
A1: Filterable activity-level weekly schedule
A2: Dates are Monday week starts; dependency and window warnings update when weeks are edited.
A4: Activity ID | B4: Deliverable ID | C4: Activity | D4: Assignee | E4: Week | F4: Week start | G4: Effort (h) | H4: Earliest | I4: Latest | J4: Predecessor | K4: Role / control | L4: Window check | M4: Dependency check | N4: Exclusion check | O4: Status
A5: D1-A | B5: D1 | C5: Scope and requirements | D5: Casimir Oyelowo | E5: W02 | F5: =DATE(2026,6,29)+7*(VALUE(RIGHT(E5,2))-1) -> 46209 | G5: 12 | H5: W02 | I5: W02 | K5: Owner | L5: =IF(AND(VALUE(RIGHT(E5,2))>=VALUE(RIGHT(H5,2)),VALUE(RIGHT(E5,2))<=VALUE(RIGHT(I5,2)),F5<=DATE(2026,9,25)),"OK","WARNING") -> OK | M5: =IF(J5="","OK",IF(COUNTIFS($A$5:$A$33,J5,$E$5:$E$33,"<"&E5)>0,"OK","WARNING")) -> OK | N5: =IF(OR(AND(A5="D1-B",COUNTIFS($A$5:$A$33,"D3-B",$E$5:$E$33,E5)>0),AND(A5="D3-B",COUNTIFS($A$5:$A$33,"D1-B",$E$5:$E$33,E5)>0),AND(A5="D2-B",COUNTIFS($A$5:$A$33,"D4-A",$E$5:$E$33,E5)>0),AND(A5="D4-A",COUNTIFS($A$5:$A$33,"D2-B",$E$5:$E$33,E5)>0),AND(A5="D1-F",COUNTIFS($A$5:$A$33,"D2-F",$E$5:$E$33,E5)>0),AND(A5="D2-F",COUNTIFS($A$5:$A$33,"D1-F",$E$5:$E$33,E5)>0)),"WARNING","OK") -> OK | O5: =IF(COUNTIF(L5:N5,"WARNING")>0,"WARNING","OK") -> OK
A6: D1-B | B6: D1 | C6: Site evidence and walkover | D6: Casimir Oyelowo | E6: W03 | F6: =DATE(2026,6,29)+7*(VALUE(RIGHT(E6,2))-1) -> 46216 | G6: 18 | H6: W03 | I6: W03 | J6: D1-A | K6: Owner | L6: =IF(AND(VALUE(RIGHT(E6,2))>=VALUE(RIGHT(H6,2)),VALUE(RIGHT(E6,2))<=VALUE(RIGHT(I6,2)),F6<=DATE(2026,9,25)),"OK","WARNING") -> OK | M6: =IF(J6="","OK",IF(COUNTIFS($A$5:$A$33,J6,$E$5:$E$33,"<"&E6)>0,"OK","WARNING")) -> OK | N6: =IF(OR(AND(A6="D1-B",COUNTIFS($A$5:$A$33,"D3-B",$E$5:$E$33,E6)>0),AND(A6="D3-B",COUNTIFS($A$5:$A$33,"D1-B",$E$5:$E$33,E6)>0),AND(A6="D2-B",COUNTIFS($A$5:$A$33,"D4-A",$E$5:$E$33,E6)>0),AND(A6="D4-A",COUNTIFS($A$5:$A$33,"D2-B",$E$5:$E$33,E6)>0),AND(A6="D1-F",COUNTIFS($A$5:$A$33,"D2-F",$E$5:$E$33,E6)>0),AND(A6="D2-F",COUNTIFS($A$5:$A$33,"D1-F",$E$5:$E$33,E6)>0)),"WARNING","OK") -> OK | O6: =IF(COUNTIF(L6:N6,"WARNING")>0,"WARNING","OK") -> OK
A7: D1-C | B7: D1 | C7: Technical assessment | D7: Casimir Oyelowo | E7: W04 | F7: =DATE(2026,6,29)+7*(VALUE(RIGHT(E7,2))-1) -> 46223 | G7: 20 | H7: W04 | I7: W04 | J7: D1-B | K7: Owner | L7: =IF(AND(VALUE(RIGHT(E7,2))>=VALUE(RIGHT(H7,2)),VALUE(RIGHT(E7,2))<=VALUE(RIGHT(I7,2)),F7<=DATE(2026,9,25)),"OK","WARNING") -> OK | M7: =IF(J7="","OK",IF(COUNTIFS($A$5:$A$33,J7,$E$5:$E$33,"<"&E7)>0,"OK","WARNING")) -> OK | N7: =IF(OR(AND(A7="D1-B",COUNTIFS($A$5:$A$33,"D3-B",$E$5:$E$33,E7)>0),AND(A7="D3-B",COUNTIFS($A$5:$A$33,"D1-B",$E$5:$E$33,E7)>0),AND(A7="D2-B",COUNTIFS($A$5:$A$33,"D4-A",$E$5:$E$33,E7)>0),AND(A7="D4-A",COUNTIFS($A$5:$A$33,"D2-B",$E$5:$E$33,E7)>0),AND(A7="D1-F",COUNTIFS($A$5:$A$33,"D2-F",$E$5:$E$33,E7)>0),AND(A7="D2-F",COUNTIFS($A$5:$A$33,"D1-F",$E$5:$E$33,E7)>0)),"WARNING","OK") -> OK | O7: =IF(COUNTIF(L7:N7,"WARNING")>0,"WARNING","OK") -> OK
A8: D1-D | B8: D1 | C8: Draft variation pack | D8: Casimir Oyelowo | E8: W05 | F8: =DATE(2026,6,29)+7*(VALUE(RIGHT(E8,2))-1) -> 46230 | G8: 18 | H8: W05 | I8: W05 | J8: D1-C | K8: Owner | L8: =IF(AND(VALUE(RIGHT(E8,2))>=VALUE(RIGHT(H8,2)),VALUE(RIGHT(E8,2))<=VALUE(RIGHT(I8,2)),F8<=DATE(2026,9,25)),"OK","WARNING") -> OK | M8: =IF(J8="","OK",IF(COUNTIFS($A$5:$A$33,J8,$E$5:$E$33,"<"&E8)>0,"OK","WARNING")) -> OK | N8: =IF(OR(AND(A8="D1-B",COUNTIFS($A$5:$A$33,"D3-B",$E$5:$E$33,E8)>0),AND(A8="D3-B",COUNTIFS($A$5:$A$33,"D1-B",$E$5:$E$33,E8)>0),AND(A8="D2-B",COUNTIFS($A$5:$A$33,"D4-A",$E$5:$E$33,E8)>0),AND(A8="D4-A",COUNTIFS($A$5:$A$33,"D2-B",$E$5:$E$33,E8)>0),AND(A8="D1-F",COUNTIFS($A$5:$A$33,"D2-F",$E$5:$E$33,E8)>0),AND(A8="D2-F",COUNTIFS($A$5:$A$33,"D1-F",$E$5:$E$33,E8)>0)),"WARNING","OK") -> OK | O8: =IF(COUNTIF(L8:N8,"WARNING")>0,"WARNING","OK") -> OK
A9: D1-E | B9: D1 | C9: Independent assurance | D9: Chidi Jankowski | E9: W06 | F9: =DATE(2026,6,29)+7*(VALUE(RIGHT(E9,2))-1) -> 46237 | G9: 10 | H9: W06 | I9: W06 | J9: D1-D | K9: Reviewer | L9: =IF(AND(VALUE(RIGHT(E9,2))>=VALUE(RIGHT(H9,2)),VALUE(RIGHT(E9,2))<=VALUE(RIGHT(I9,2)),F9<=DATE(2026,9,25)),"OK","WARNING") -> OK | M9: =IF(J9="","OK",IF(COUNTIFS($A$5:$A$33,J9,$E$5:$E$33,"<"&E9)>0,"OK","WARNING")) -> OK | N9: =IF(OR(AND(A9="D1-B",COUNTIFS($A$5:$A$33,"D3-B",$E$5:$E$33,E9)>0),AND(A9="D3-B",COUNTIFS($A$5:$A$33,"D1-B",$E$5:$E$33,E9)>0),AND(A9="D2-B",COUNTIFS($A$5:$A$33,"D4-A",$E$5:$E$33,E9)>0),AND(A9="D4-A",COUNTIFS($A$5:$A$33,"D2-B",$E$5:$E$33,E9)>0),AND(A9="D1-F",COUNTIFS($A$5:$A$33,"D2-F",$E$5:$E$33,E9)>0),AND(A9="D2-F",COUNTIFS($A$5:$A$33,"D1-F",$E$5:$E$33,E9)>0)),"WARNING","OK") -> OK | O9: =IF(COUNTIF(L9:N9,"WARNING")>0,"WARNING","OK") -> OK
A10: D1-F | B10: D1 | C10: Client submission | D10: Casimir Oyelowo | E10: W08 | F10: =DATE(2026,6,29)+7*(VALUE(RIGHT(E10,2))-1) -> 46251 | G10: 6 | H10: W08 | I10: W08 | J10: D1-E | K10: Submission; supervised | L10: =IF(AND(VALUE(RIGHT(E10,2))>=VALUE(RIGHT(H10,2)),VALUE(RIGHT(E10,2))<=VALUE(RIGHT(I10,2)),F10<=DATE(2026,9,25)),"OK","WARNING") -> OK | M10: =IF(J10="","OK",IF(COUNTIFS($A$5:$A$33,J10,$E$5:$E$33,"<"&E10)>0,"OK","WARNING")) -> OK | N10: =IF(OR(AND(A10="D1-B",COUNTIFS($A$5:$A$33,"D3-B",$E$5:$E$33,E10)>0),AND(A10="D3-B",COUNTIFS($A$5:$A$33,"D1-B",$E$5:$E$33,E10)>0),AND(A10="D2-B",COUNTIFS($A$5:$A$33,"D4-A",$E$5:$E$33,E10)>0),AND(A10="D4-A",COUNTIFS($A$5:$A$33,"D2-B",$E$5:$E$33,E10)>0),AND(A10="D1-F",COUNTIFS($A$5:$A$33,"D2-F",$E$5:$E$33,E10)>0),AND(A10="D2-F",COUNTIFS($A$5:$A$33,"D1-F",$E$5:$E$33,E10)>0)),"WARNING","OK") -> OK | O10: =IF(COUNTIF(L10:N10,"WARNING")>0,"WARNING","OK") -> OK
A11: D2-A | B11: D2 | C11: Scope and requirements | D11: Arjun Redmayne | E11: W03 | F11: =DATE(2026,6,29)+7*(VALUE(RIGHT(E11,2))-1) -> 46216 | G11: 10 | H11: W03 | I11: W03 | K11: Owner | L11: =IF(AND(VALUE(RIGHT(E11,2))>=VALUE(RIGHT(H11,2)),VALUE(RIGHT(E11,2))<=VALUE(RIGHT(I11,2)),F11<=DATE(2026,9,25)),"OK","WARNING") -> OK | M11: =IF(J11="","OK",IF(COUNTIFS($A$5:$A$33,J11,$E$5:$E$33,"<"&E11)>0,"OK","WARNING")) -> OK | N11: =IF(OR(AND(A11="D1-B",COUNTIFS($A$5:$A$33,"D3-B",$E$5:$E$33,E11)>0),AND(A11="D3-B",COUNTIFS($A$5:$A$33,"D1-B",$E$5:$E$33,E11)>0),AND(A11="D2-B",COUNTIFS($A$5:$A$33,"D4-A",$E$5:$E$33,E11)>0),AND(A11="D4-A",COUNTIFS($A$5:$A$33,"D2-B",$E$5:$E$33,E11)>0),AND(A11="D1-F",COUNTIFS($A$5:$A$33,"D2-F",$E$5:$E$33,E11)>0),AND(A11="D2-F",COUNTIFS($A$5:$A$33,"D1-F",$E$5:$E$33,E11)>0)),"WARNING","OK") -> OK | O11: =IF(COUNTIF(L11:N11,"WARNING")>0,"WARNING","OK") -> OK
A12: D2-B | B12: D2 | C12: Site test | D12: Arjun Redmayne | E12: W04 | F12: =DATE(2026,6,29)+7*(VALUE(RIGHT(E12,2))-1) -> 46223 | G12: 16 | H12: W04 | I12: W04 | J12: D2-A | K12: Owner | L12: =IF(AND(VALUE(RIGHT(E12,2))>=VALUE(RIGHT(H12,2)),VALUE(RIGHT(E12,2))<=VALUE(RIGHT(I12,2)),F12<=DATE(2026,9,25)),"OK","WARNING") -> OK | M12: =IF(J12="","OK",IF(COUNTIFS($A$5:$A$33,J12,$E$5:$E$33,"<"&E12)>0,"OK","WARNING")) -> OK | N12: =IF(OR(AND(A12="D1-B",COUNTIFS($A$5:$A$33,"D3-B",$E$5:$E$33,E12)>0),AND(A12="D3-B",COUNTIFS($A$5:$A$33,"D1-B",$E$5:$E$33,E12)>0),AND(A12="D2-B",COUNTIFS($A$5:$A$33,"D4-A",$E$5:$E$33,E12)>0),AND(A12="D4-A",COUNTIFS($A$5:$A$33,"D2-B",$E$5:$E$33,E12)>0),AND(A12="D1-F",COUNTIFS($A$5:$A$33,"D2-F",$E$5:$E$33,E12)>0),AND(A12="D2-F",COUNTIFS($A$5:$A$33,"D1-F",$E$5:$E$33,E12)>0)),"WARNING","OK") -> OK | O12: =IF(COUNTIF(L12:N12,"WARNING")>0,"WARNING","OK") -> OK
A13: D2-C | B13: D2 | C13: Air model and inventory | D13: Arjun Redmayne | E13: W05 | F13: =DATE(2026,6,29)+7*(VALUE(RIGHT(E13,2))-1) -> 46230 | G13: 24 | H13: W05 | I13: W05 | J13: D2-B | K13: Owner | L13: =IF(AND(VALUE(RIGHT(E13,2))>=VALUE(RIGHT(H13,2)),VALUE(RIGHT(E13,2))<=VALUE(RIGHT(I13,2)),F13<=DATE(2026,9,25)),"OK","WARNING") -> OK | M13: =IF(J13="","OK",IF(COUNTIFS($A$5:$A$33,J13,$E$5:$E$33,"<"&E13)>0,"OK","WARNING")) -> OK | N13: =IF(OR(AND(A13="D1-B",COUNTIFS($A$5:$A$33,"D3-B",$E$5:$E$33,E13)>0),AND(A13="D3-B",COUNTIFS($A$5:$A$33,"D1-B",$E$5:$E$33,E13)>0),AND(A13="D2-B",COUNTIFS($A$5:$A$33,"D4-A",$E$5:$E$33,E13)>0),AND(A13="D4-A",COUNTIFS($A$5:$A$33,"D2-B",$E$5:$E$33,E13)>0),AND(A13="D1-F",COUNTIFS($A$5:$A$33,"D2-F",$E$5:$E$33,E13)>0),AND(A13="D2-F",COUNTIFS($A$5:$A$33,"D1-F",$E$5:$E$33,E13)>0)),"WARNING","OK") -> OK | O13: =IF(COUNTIF(L13:N13,"WARNING")>0,"WARNING","OK") -> OK
A14: D2-D | B14: D2 | C14: Draft variation pack | D14: Arjun Redmayne | E14: W06 | F14: =DATE(2026,6,29)+7*(VALUE(RIGHT(E14,2))-1) -> 46237 | G14: 18 | H14: W06 | I14: W06 | J14: D2-C | K14: Owner | L14: =IF(AND(VALUE(RIGHT(E14,2))>=VALUE(RIGHT(H14,2)),VALUE(RIGHT(E14,2))<=VALUE(RIGHT(I14,2)),F14<=DATE(2026,9,25)),"OK","WARNING") -> OK | M14: =IF(J14="","OK",IF(COUNTIFS($A$5:$A$33,J14,$E$5:$E$33,"<"&E14)>0,"OK","WARNING")) -> OK | N14: =IF(OR(AND(A14="D1-B",COUNTIFS($A$5:$A$33,"D3-B",$E$5:$E$33,E14)>0),AND(A14="D3-B",COUNTIFS($A$5:$A$33,"D1-B",$E$5:$E$33,E14)>0),AND(A14="D2-B",COUNTIFS($A$5:$A$33,"D4-A",$E$5:$E$33,E14)>0),AND(A14="D4-A",COUNTIFS($A$5:$A$33,"D2-B",$E$5:$E$33,E14)>0),AND(A14="D1-F",COUNTIFS($A$5:$A$33,"D2-F",$E$5:$E$33,E14)>0),AND(A14="D2-F",COUNTIFS($A$5:$A$33,"D1-F",$E$5:$E$33,E14)>0)),"WARNING","OK") -> OK | O14: =IF(COUNTIF(L14:N14,"WARNING")>0,"WARNING","OK") -> OK
A15: D2-E | B15: D2 | C15: Independent assurance | D15: Chidi Jankowski | E15: W08 | F15: =DATE(2026,6,29)+7*(VALUE(RIGHT(E15,2))-1) -> 46251 | G15: 10 | H15: W08 | I15: W08 | J15: D2-D | K15: Reviewer | L15: =IF(AND(VALUE(RIGHT(E15,2))>=VALUE(RIGHT(H15,2)),VALUE(RIGHT(E15,2))<=VALUE(RIGHT(I15,2)),F15<=DATE(2026,9,25)),"OK","WARNING") -> OK | M15: =IF(J15="","OK",IF(COUNTIFS($A$5:$A$33,J15,$E$5:$E$33,"<"&E15)>0,"OK","WARNING")) -> OK | N15: =IF(OR(AND(A15="D1-B",COUNTIFS($A$5:$A$33,"D3-B",$E$5:$E$33,E15)>0),AND(A15="D3-B",COUNTIFS($A$5:$A$33,"D1-B",$E$5:$E$33,E15)>0),AND(A15="D2-B",COUNTIFS($A$5:$A$33,"D4-A",$E$5:$E$33,E15)>0),AND(A15="D4-A",COUNTIFS($A$5:$A$33,"D2-B",$E$5:$E$33,E15)>0),AND(A15="D1-F",COUNTIFS($A$5:$A$33,"D2-F",$E$5:$E$33,E15)>0),AND(A15="D2-F",COUNTIFS($A$5:$A$33,"D1-F",$E$5:$E$33,E15)>0)),"WARNING","OK") -> OK | O15: =IF(COUNTIF(L15:N15,"WARNING")>0,"WARNING","OK") -> OK
A16: D2-F | B16: D2 | C16: Client submission | D16: Arjun Redmayne | E16: W11 | F16: =DATE(2026,6,29)+7*(VALUE(RIGHT(E16,2))-1) -> 46272 | G16: 6 | H16: W11 | I16: W11 | J16: D2-E | K16: Submission | L16: =IF(AND(VALUE(RIGHT(E16,2))>=VALUE(RIGHT(H16,2)),VALUE(RIGHT(E16,2))<=VALUE(RIGHT(I16,2)),F16<=DATE(2026,9,25)),"OK","WARNING") -> OK | M16: =IF(J16="","OK",IF(COUNTIFS($A$5:$A$33,J16,$E$5:$E$33,"<"&E16)>0,"OK","WARNING")) -> OK | N16: =IF(OR(AND(A16="D1-B",COUNTIFS($A$5:$A$33,"D3-B",$E$5:$E$33,E16)>0),AND(A16="D3-B",COUNTIFS($A$5:$A$33,"D1-B",$E$5:$E$33,E16)>0),AND(A16="D2-B",COUNTIFS($A$5:$A$33,"D4-A",$E$5:$E$33,E16)>0),AND(A16="D4-A",COUNTIFS($A$5:$A$33,"D2-B",$E$5:$E$33,E16)>0),AND(A16="D1-F",COUNTIFS($A$5:$A$33,"D2-F",$E$5:$E$33,E16)>0),AND(A16="D2-F",COUNTIFS($A$5:$A$33,"D1-F",$E$5:$E$33,E16)>0)),"WARNING","OK") -> OK | O16: =IF(COUNTIF(L16:N16,"WARNING")>0,"WARNING","OK") -> OK
A17: D3-A | B17: D3 | C17: Ecology scope | D17: Chidi Jankowski | E17: W01 | F17: =DATE(2026,6,29)+7*(VALUE(RIGHT(E17,2))-1) -> 46202 | G17: 8 | H17: W01 | I17: W01 | K17: Owner | L17: =IF(AND(VALUE(RIGHT(E17,2))>=VALUE(RIGHT(H17,2)),VALUE(RIGHT(E17,2))<=VALUE(RIGHT(I17,2)),F17<=DATE(2026,9,25)),"OK","WARNING") -> OK | M17: =IF(J17="","OK",IF(COUNTIFS($A$5:$A$33,J17,$E$5:$E$33,"<"&E17)>0,"OK","WARNING")) -> OK | N17: =IF(OR(AND(A17="D1-B",COUNTIFS($A$5:$A$33,"D3-B",$E$5:$E$33,E17)>0),AND(A17="D3-B",COUNTIFS($A$5:$A$33,"D1-B",$E$5:$E$33,E17)>0),AND(A17="D2-B",COUNTIFS($A$5:$A$33,"D4-A",$E$5:$E$33,E17)>0),AND(A17="D4-A",COUNTIFS($A$5:$A$33,"D2-B",$E$5:$E$33,E17)>0),AND(A17="D1-F",COUNTIFS($A$5:$A$33,"D2-F",$E$5:$E$33,E17)>0),AND(A17="D2-F",COUNTIFS($A$5:$A$33,"D1-F",$E$5:$E$33,E17)>0)),"WARNING","OK") -> OK | O17: =IF(COUNTIF(L17:N17,"WARNING")>0,"WARNING","OK") -> OK
A18: D3-B | B18: D3 | C18: Ecology walkover | D18: Chidi Jankowski | E18: W05 | F18: =DATE(2026,6,29)+7*(VALUE(RIGHT(E18,2))-1) -> 46230 | G18: 12 | H18: W05 | I18: W05 | J18: D3-A | K18: Owner | L18: =IF(AND(VALUE(RIGHT(E18,2))>=VALUE(RIGHT(H18,2)),VALUE(RIGHT(E18,2))<=VALUE(RIGHT(I18,2)),F18<=DATE(2026,9,25)),"OK","WARNING") -> OK | M18: =IF(J18="","OK",IF(COUNTIFS($A$5:$A$33,J18,$E$5:$E$33,"<"&E18)>0,"OK","WARNING")) -> OK | N18: =IF(OR(AND(A18="D1-B",COUNTIFS($A$5:$A$33,"D3-B",$E$5:$E$33,E18)>0),AND(A18="D3-B",COUNTIFS($A$5:$A$33,"D1-B",$E$5:$E$33,E18)>0),AND(A18="D2-B",COUNTIFS($A$5:$A$33,"D4-A",$E$5:$E$33,E18)>0),AND(A18="D4-A",COUNTIFS($A$5:$A$33,"D2-B",$E$5:$E$33,E18)>0),AND(A18="D1-F",COUNTIFS($A$5:$A$33,"D2-F",$E$5:$E$33,E18)>0),AND(A18="D2-F",COUNTIFS($A$5:$A$33,"D1-F",$E$5:$E$33,E18)>0)),"WARNING","OK") -> OK | O18: =IF(COUNTIF(L18:N18,"WARNING")>0,"WARNING","OK") -> OK
A19: D3-C | B19: D3 | C19: Screening memo | D19: Chidi Jankowski | E19: W06 | F19: =DATE(2026,6,29)+7*(VALUE(RIGHT(E19,2))-1) -> 46237 | G19: 10 | H19: W06 | I19: W06 | J19: D3-B | K19: Owner | L19: =IF(AND(VALUE(RIGHT(E19,2))>=VALUE(RIGHT(H19,2)),VALUE(RIGHT(E19,2))<=VALUE(RIGHT(I19,2)),F19<=DATE(2026,9,25)),"OK","WARNING") -> OK | M19: =IF(J19="","OK",IF(COUNTIFS($A$5:$A$33,J19,$E$5:$E$33,"<"&E19)>0,"OK","WARNING")) -> OK | N19: =IF(OR(AND(A19="D1-B",COUNTIFS($A$5:$A$33,"D3-B",$E$5:$E$33,E19)>0),AND(A19="D3-B",COUNTIFS($A$5:$A$33,"D1-B",$E$5:$E$33,E19)>0),AND(A19="D2-B",COUNTIFS($A$5:$A$33,"D4-A",$E$5:$E$33,E19)>0),AND(A19="D4-A",COUNTIFS($A$5:$A$33,"D2-B",$E$5:$E$33,E19)>0),AND(A19="D1-F",COUNTIFS($A$5:$A$33,"D2-F",$E$5:$E$33,E19)>0),AND(A19="D2-F",COUNTIFS($A$5:$A$33,"D1-F",$E$5:$E$33,E19)>0)),"WARNING","OK") -> OK | O19: =IF(COUNTIF(L19:N19,"WARNING")>0,"WARNING","OK") -> OK
A20: D4-A | B20: D4 | C20: Waste audit | D20: Lorcan Dimitrov | E20: W06 | F20: =DATE(2026,6,29)+7*(VALUE(RIGHT(E20,2))-1) -> 46237 | G20: 14 | H20: W06 | I20: W06 | K20: Owner | L20: =IF(AND(VALUE(RIGHT(E20,2))>=VALUE(RIGHT(H20,2)),VALUE(RIGHT(E20,2))<=VALUE(RIGHT(I20,2)),F20<=DATE(2026,9,25)),"OK","WARNING") -> OK | M20: =IF(J20="","OK",IF(COUNTIFS($A$5:$A$33,J20,$E$5:$E$33,"<"&E20)>0,"OK","WARNING")) -> OK | N20: =IF(OR(AND(A20="D1-B",COUNTIFS($A$5:$A$33,"D3-B",$E$5:$E$33,E20)>0),AND(A20="D3-B",COUNTIFS($A$5:$A$33,"D1-B",$E$5:$E$33,E20)>0),AND(A20="D2-B",COUNTIFS($A$5:$A$33,"D4-A",$E$5:$E$33,E20)>0),AND(A20="D4-A",COUNTIFS($A$5:$A$33,"D2-B",$E$5:$E$33,E20)>0),AND(A20="D1-F",COUNTIFS($A$5:$A$33,"D2-F",$E$5:$E$33,E20)>0),AND(A20="D2-F",COUNTIFS($A$5:$A$33,"D1-F",$E$5:$E$33,E20)>0)),"WARNING","OK") -> OK | O20: =IF(COUNTIF(L20:N20,"WARNING")>0,"WARNING","OK") -> OK
A21: D4-B | B21: D4 | C21: Control design | D21: Lorcan Dimitrov | E21: W07 | F21: =DATE(2026,6,29)+7*(VALUE(RIGHT(E21,2))-1) -> 46244 | G21: 16 | H21: W07 | I21: W07 | J21: D4-A | K21: Owner | L21: =IF(AND(VALUE(RIGHT(E21,2))>=VALUE(RIGHT(H21,2)),VALUE(RIGHT(E21,2))<=VALUE(RIGHT(I21,2)),F21<=DATE(2026,9,25)),"OK","WARNING") -> OK | M21: =IF(J21="","OK",IF(COUNTIFS($A$5:$A$33,J21,$E$5:$E$33,"<"&E21)>0,"OK","WARNING")) -> OK | N21: =IF(OR(AND(A21="D1-B",COUNTIFS($A$5:$A$33,"D3-B",$E$5:$E$33,E21)>0),AND(A21="D3-B",COUNTIFS($A$5:$A$33,"D1-B",$E$5:$E$33,E21)>0),AND(A21="D2-B",COUNTIFS($A$5:$A$33,"D4-A",$E$5:$E$33,E21)>0),AND(A21="D4-A",COUNTIFS($A$5:$A$33,"D2-B",$E$5:$E$33,E21)>0),AND(A21="D1-F",COUNTIFS($A$5:$A$33,"D2-F",$E$5:$E$33,E21)>0),AND(A21="D2-F",COUNTIFS($A$5:$A$33,"D1-F",$E$5:$E$33,E21)>0)),"WARNING","OK") -> OK | O21: =IF(COUNTIF(L21:N21,"WARNING")>0,"WARNING","OK") -> OK
A22: D4-C | B22: D4 | C22: Client control review | D22: Lorcan Dimitrov | E22: W08 | F22: =DATE(2026,6,29)+7*(VALUE(RIGHT(E22,2))-1) -> 46251 | G22: 6 | H22: W08 | I22: W08 | J22: D4-B | K22: Reviewer | L22: =IF(AND(VALUE(RIGHT(E22,2))>=VALUE(RIGHT(H22,2)),VALUE(RIGHT(E22,2))<=VALUE(RIGHT(I22,2)),F22<=DATE(2026,9,25)),"OK","WARNING") -> OK | M22: =IF(J22="","OK",IF(COUNTIFS($A$5:$A$33,J22,$E$5:$E$33,"<"&E22)>0,"OK","WARNING")) -> OK | N22: =IF(OR(AND(A22="D1-B",COUNTIFS($A$5:$A$33,"D3-B",$E$5:$E$33,E22)>0),AND(A22="D3-B",COUNTIFS($A$5:$A$33,"D1-B",$E$5:$E$33,E22)>0),AND(A22="D2-B",COUNTIFS($A$5:$A$33,"D4-A",$E$5:$E$33,E22)>0),AND(A22="D4-A",COUNTIFS($A$5:$A$33,"D2-B",$E$5:$E$33,E22)>0),AND(A22="D1-F",COUNTIFS($A$5:$A$33,"D2-F",$E$5:$E$33,E22)>0),AND(A22="D2-F",COUNTIFS($A$5:$A$33,"D1-F",$E$5:$E$33,E22)>0)),"WARNING","OK") -> OK | O22: =IF(COUNTIF(L22:N22,"WARNING")>0,"WARNING","OK") -> OK
A23: D5-A | B23: D5 | C23: Noise survey | D23: Arjun Redmayne | E23: W02 | F23: =DATE(2026,6,29)+7*(VALUE(RIGHT(E23,2))-1) -> 46209 | G23: 12 | H23: W02 | I23: W02 | K23: Owner | L23: =IF(AND(VALUE(RIGHT(E23,2))>=VALUE(RIGHT(H23,2)),VALUE(RIGHT(E23,2))<=VALUE(RIGHT(I23,2)),F23<=DATE(2026,9,25)),"OK","WARNING") -> OK | M23: =IF(J23="","OK",IF(COUNTIFS($A$5:$A$33,J23,$E$5:$E$33,"<"&E23)>0,"OK","WARNING")) -> OK | N23: =IF(OR(AND(A23="D1-B",COUNTIFS($A$5:$A$33,"D3-B",$E$5:$E$33,E23)>0),AND(A23="D3-B",COUNTIFS($A$5:$A$33,"D1-B",$E$5:$E$33,E23)>0),AND(A23="D2-B",COUNTIFS($A$5:$A$33,"D4-A",$E$5:$E$33,E23)>0),AND(A23="D4-A",COUNTIFS($A$5:$A$33,"D2-B",$E$5:$E$33,E23)>0),AND(A23="D1-F",COUNTIFS($A$5:$A$33,"D2-F",$E$5:$E$33,E23)>0),AND(A23="D2-F",COUNTIFS($A$5:$A$33,"D1-F",$E$5:$E$33,E23)>0)),"WARNING","OK") -> OK | O23: =IF(COUNTIF(L23:N23,"WARNING")>0,"WARNING","OK") -> OK
A24: D5-B | B24: D5 | C24: Noise assessment | D24: Arjun Redmayne | E24: W03 | F24: =DATE(2026,6,29)+7*(VALUE(RIGHT(E24,2))-1) -> 46216 | G24: 16 | H24: W03 | I24: W03 | J24: D5-A | K24: Owner | L24: =IF(AND(VALUE(RIGHT(E24,2))>=VALUE(RIGHT(H24,2)),VALUE(RIGHT(E24,2))<=VALUE(RIGHT(I24,2)),F24<=DATE(2026,9,25)),"OK","WARNING") -> OK | M24: =IF(J24="","OK",IF(COUNTIFS($A$5:$A$33,J24,$E$5:$E$33,"<"&E24)>0,"OK","WARNING")) -> OK | N24: =IF(OR(AND(A24="D1-B",COUNTIFS($A$5:$A$33,"D3-B",$E$5:$E$33,E24)>0),AND(A24="D3-B",COUNTIFS($A$5:$A$33,"D1-B",$E$5:$E$33,E24)>0),AND(A24="D2-B",COUNTIFS($A$5:$A$33,"D4-A",$E$5:$E$33,E24)>0),AND(A24="D4-A",COUNTIFS($A$5:$A$33,"D2-B",$E$5:$E$33,E24)>0),AND(A24="D1-F",COUNTIFS($A$5:$A$33,"D2-F",$E$5:$E$33,E24)>0),AND(A24="D2-F",COUNTIFS($A$5:$A$33,"D1-F",$E$5:$E$33,E24)>0)),"WARNING","OK") -> OK | O24: =IF(COUNTIF(L24:N24,"WARNING")>0,"WARNING","OK") -> OK
A25: D5-C | B25: D5 | C25: Noise memo | D25: Arjun Redmayne | E25: W04 | F25: =DATE(2026,6,29)+7*(VALUE(RIGHT(E25,2))-1) -> 46223 | G25: 8 | H25: W04 | I25: W04 | J25: D5-B | K25: Owner | L25: =IF(AND(VALUE(RIGHT(E25,2))>=VALUE(RIGHT(H25,2)),VALUE(RIGHT(E25,2))<=VALUE(RIGHT(I25,2)),F25<=DATE(2026,9,25)),"OK","WARNING") -> OK | M25: =IF(J25="","OK",IF(COUNTIFS($A$5:$A$33,J25,$E$5:$E$33,"<"&E25)>0,"OK","WARNING")) -> OK | N25: =IF(OR(AND(A25="D1-B",COUNTIFS($A$5:$A$33,"D3-B",$E$5:$E$33,E25)>0),AND(A25="D3-B",COUNTIFS($A$5:$A$33,"D1-B",$E$5:$E$33,E25)>0),AND(A25="D2-B",COUNTIFS($A$5:$A$33,"D4-A",$E$5:$E$33,E25)>0),AND(A25="D4-A",COUNTIFS($A$5:$A$33,"D2-B",$E$5:$E$33,E25)>0),AND(A25="D1-F",COUNTIFS($A$5:$A$33,"D2-F",$E$5:$E$33,E25)>0),AND(A25="D2-F",COUNTIFS($A$5:$A$33,"D1-F",$E$5:$E$33,E25)>0)),"WARNING","OK") -> OK | O25: =IF(COUNTIF(L25:N25,"WARNING")>0,"WARNING","OK") -> OK
A26: D6-A | B26: D6 | C26: Drainage desktop review | D26: Chidi Jankowski | E26: W01 | F26: =DATE(2026,6,29)+7*(VALUE(RIGHT(E26,2))-1) -> 46202 | G26: 10 | H26: W01 | I26: W01 | K26: Owner | L26: =IF(AND(VALUE(RIGHT(E26,2))>=VALUE(RIGHT(H26,2)),VALUE(RIGHT(E26,2))<=VALUE(RIGHT(I26,2)),F26<=DATE(2026,9,25)),"OK","WARNING") -> OK | M26: =IF(J26="","OK",IF(COUNTIFS($A$5:$A$33,J26,$E$5:$E$33,"<"&E26)>0,"OK","WARNING")) -> OK | N26: =IF(OR(AND(A26="D1-B",COUNTIFS($A$5:$A$33,"D3-B",$E$5:$E$33,E26)>0),AND(A26="D3-B",COUNTIFS($A$5:$A$33,"D1-B",$E$5:$E$33,E26)>0),AND(A26="D2-B",COUNTIFS($A$5:$A$33,"D4-A",$E$5:$E$33,E26)>0),AND(A26="D4-A",COUNTIFS($A$5:$A$33,"D2-B",$E$5:$E$33,E26)>0),AND(A26="D1-F",COUNTIFS($A$5:$A$33,"D2-F",$E$5:$E$33,E26)>0),AND(A26="D2-F",COUNTIFS($A$5:$A$33,"D1-F",$E$5:$E$33,E26)>0)),"WARNING","OK") -> OK | O26: =IF(COUNTIF(L26:N26,"WARNING")>0,"WARNING","OK") -> OK
A27: D6-B | B27: D6 | C27: Drainage design note | D27: Chidi Jankowski | E27: W02 | F27: =DATE(2026,6,29)+7*(VALUE(RIGHT(E27,2))-1) -> 46209 | G27: 18 | H27: W02 | I27: W02 | J27: D6-A | K27: Owner | L27: =IF(AND(VALUE(RIGHT(E27,2))>=VALUE(RIGHT(H27,2)),VALUE(RIGHT(E27,2))<=VALUE(RIGHT(I27,2)),F27<=DATE(2026,9,25)),"OK","WARNING") -> OK | M27: =IF(J27="","OK",IF(COUNTIFS($A$5:$A$33,J27,$E$5:$E$33,"<"&E27)>0,"OK","WARNING")) -> OK | N27: =IF(OR(AND(A27="D1-B",COUNTIFS($A$5:$A$33,"D3-B",$E$5:$E$33,E27)>0),AND(A27="D3-B",COUNTIFS($A$5:$A$33,"D1-B",$E$5:$E$33,E27)>0),AND(A27="D2-B",COUNTIFS($A$5:$A$33,"D4-A",$E$5:$E$33,E27)>0),AND(A27="D4-A",COUNTIFS($A$5:$A$33,"D2-B",$E$5:$E$33,E27)>0),AND(A27="D1-F",COUNTIFS($A$5:$A$33,"D2-F",$E$5:$E$33,E27)>0),AND(A27="D2-F",COUNTIFS($A$5:$A$33,"D1-F",$E$5:$E$33,E27)>0)),"WARNING","OK") -> OK | O27: =IF(COUNTIF(L27:N27,"WARNING")>0,"WARNING","OK") -> OK
A28: D6-C | B28: D6 | C28: Water discipline review | D28: Marisol Reinholt | E28: W03 | F28: =DATE(2026,6,29)+7*(VALUE(RIGHT(E28,2))-1) -> 46216 | G28: 6 | H28: W03 | I28: W03 | J28: D6-B | K28: Reviewer | L28: =IF(AND(VALUE(RIGHT(E28,2))>=VALUE(RIGHT(H28,2)),VALUE(RIGHT(E28,2))<=VALUE(RIGHT(I28,2)),F28<=DATE(2026,9,25)),"OK","WARNING") -> OK | M28: =IF(J28="","OK",IF(COUNTIFS($A$5:$A$33,J28,$E$5:$E$33,"<"&E28)>0,"OK","WARNING")) -> OK | N28: =IF(OR(AND(A28="D1-B",COUNTIFS($A$5:$A$33,"D3-B",$E$5:$E$33,E28)>0),AND(A28="D3-B",COUNTIFS($A$5:$A$33,"D1-B",$E$5:$E$33,E28)>0),AND(A28="D2-B",COUNTIFS($A$5:$A$33,"D4-A",$E$5:$E$33,E28)>0),AND(A28="D4-A",COUNTIFS($A$5:$A$33,"D2-B",$E$5:$E$33,E28)>0),AND(A28="D1-F",COUNTIFS($A$5:$A$33,"D2-F",$E$5:$E$33,E28)>0),AND(A28="D2-F",COUNTIFS($A$5:$A$33,"D1-F",$E$5:$E$33,E28)>0)),"WARNING","OK") -> OK | O28: =IF(COUNTIF(L28:N28,"WARNING")>0,"WARNING","OK") -> OK
A29: D7-A | B29: D7 | C29: Solvent inventory | D29: Lorcan Dimitrov | E29: W02 | F29: =DATE(2026,6,29)+7*(VALUE(RIGHT(E29,2))-1) -> 46209 | G29: 12 | H29: W02 | I29: W02 | K29: Owner | L29: =IF(AND(VALUE(RIGHT(E29,2))>=VALUE(RIGHT(H29,2)),VALUE(RIGHT(E29,2))<=VALUE(RIGHT(I29,2)),F29<=DATE(2026,9,25)),"OK","WARNING") -> OK | M29: =IF(J29="","OK",IF(COUNTIFS($A$5:$A$33,J29,$E$5:$E$33,"<"&E29)>0,"OK","WARNING")) -> OK | N29: =IF(OR(AND(A29="D1-B",COUNTIFS($A$5:$A$33,"D3-B",$E$5:$E$33,E29)>0),AND(A29="D3-B",COUNTIFS($A$5:$A$33,"D1-B",$E$5:$E$33,E29)>0),AND(A29="D2-B",COUNTIFS($A$5:$A$33,"D4-A",$E$5:$E$33,E29)>0),AND(A29="D4-A",COUNTIFS($A$5:$A$33,"D2-B",$E$5:$E$33,E29)>0),AND(A29="D1-F",COUNTIFS($A$5:$A$33,"D2-F",$E$5:$E$33,E29)>0),AND(A29="D2-F",COUNTIFS($A$5:$A$33,"D1-F",$E$5:$E$33,E29)>0)),"WARNING","OK") -> OK | O29: =IF(COUNTIF(L29:N29,"WARNING")>0,"WARNING","OK") -> OK
A30: D7-B | B30: D7 | C30: Risk note | D30: Lorcan Dimitrov | E30: W03 | F30: =DATE(2026,6,29)+7*(VALUE(RIGHT(E30,2))-1) -> 46216 | G30: 12 | H30: W03 | I30: W03 | J30: D7-A | K30: Owner | L30: =IF(AND(VALUE(RIGHT(E30,2))>=VALUE(RIGHT(H30,2)),VALUE(RIGHT(E30,2))<=VALUE(RIGHT(I30,2)),F30<=DATE(2026,9,25)),"OK","WARNING") -> OK | M30: =IF(J30="","OK",IF(COUNTIFS($A$5:$A$33,J30,$E$5:$E$33,"<"&E30)>0,"OK","WARNING")) -> OK | N30: =IF(OR(AND(A30="D1-B",COUNTIFS($A$5:$A$33,"D3-B",$E$5:$E$33,E30)>0),AND(A30="D3-B",COUNTIFS($A$5:$A$33,"D1-B",$E$5:$E$33,E30)>0),AND(A30="D2-B",COUNTIFS($A$5:$A$33,"D4-A",$E$5:$E$33,E30)>0),AND(A30="D4-A",COUNTIFS($A$5:$A$33,"D2-B",$E$5:$E$33,E30)>0),AND(A30="D1-F",COUNTIFS($A$5:$A$33,"D2-F",$E$5:$E$33,E30)>0),AND(A30="D2-F",COUNTIFS($A$5:$A$33,"D1-F",$E$5:$E$33,E30)>0)),"WARNING","OK") -> OK | O30: =IF(COUNTIF(L30:N30,"WARNING")>0,"WARNING","OK") -> OK
A31: D8-A | B31: D8 | C31: Trade-effluent pre-app draft | D31: Casimir Oyelowo | E31: W09 | F31: =DATE(2026,6,29)+7*(VALUE(RIGHT(E31,2))-1) -> 46258 | G31: 14 | H31: W09 | I31: W09 | K31: Owner | L31: =IF(AND(VALUE(RIGHT(E31,2))>=VALUE(RIGHT(H31,2)),VALUE(RIGHT(E31,2))<=VALUE(RIGHT(I31,2)),F31<=DATE(2026,9,25)),"OK","WARNING") -> OK | M31: =IF(J31="","OK",IF(COUNTIFS($A$5:$A$33,J31,$E$5:$E$33,"<"&E31)>0,"OK","WARNING")) -> OK | N31: =IF(OR(AND(A31="D1-B",COUNTIFS($A$5:$A$33,"D3-B",$E$5:$E$33,E31)>0),AND(A31="D3-B",COUNTIFS($A$5:$A$33,"D1-B",$E$5:$E$33,E31)>0),AND(A31="D2-B",COUNTIFS($A$5:$A$33,"D4-A",$E$5:$E$33,E31)>0),AND(A31="D4-A",COUNTIFS($A$5:$A$33,"D2-B",$E$5:$E$33,E31)>0),AND(A31="D1-F",COUNTIFS($A$5:$A$33,"D2-F",$E$5:$E$33,E31)>0),AND(A31="D2-F",COUNTIFS($A$5:$A$33,"D1-F",$E$5:$E$33,E31)>0)),"WARNING","OK") -> OK | O31: =IF(COUNTIF(L31:N31,"WARNING")>0,"WARNING","OK") -> OK
A32: D8-B | B32: D8 | C32: Client pre-application | D32: Marisol Reinholt | E32: W10 | F32: =DATE(2026,6,29)+7*(VALUE(RIGHT(E32,2))-1) -> 46265 | G32: 6 | H32: W10 | I32: W10 | J32: D8-A | K32: Signatory | L32: =IF(AND(VALUE(RIGHT(E32,2))>=VALUE(RIGHT(H32,2)),VALUE(RIGHT(E32,2))<=VALUE(RIGHT(I32,2)),F32<=DATE(2026,9,25)),"OK","WARNING") -> OK | M32: =IF(J32="","OK",IF(COUNTIFS($A$5:$A$33,J32,$E$5:$E$33,"<"&E32)>0,"OK","WARNING")) -> OK | N32: =IF(OR(AND(A32="D1-B",COUNTIFS($A$5:$A$33,"D3-B",$E$5:$E$33,E32)>0),AND(A32="D3-B",COUNTIFS($A$5:$A$33,"D1-B",$E$5:$E$33,E32)>0),AND(A32="D2-B",COUNTIFS($A$5:$A$33,"D4-A",$E$5:$E$33,E32)>0),AND(A32="D4-A",COUNTIFS($A$5:$A$33,"D2-B",$E$5:$E$33,E32)>0),AND(A32="D1-F",COUNTIFS($A$5:$A$33,"D2-F",$E$5:$E$33,E32)>0),AND(A32="D2-F",COUNTIFS($A$5:$A$33,"D1-F",$E$5:$E$33,E32)>0)),"WARNING","OK") -> OK | O32: =IF(COUNTIF(L32:N32,"WARNING")>0,"WARNING","OK") -> OK
A33: D9-A | B33: D9 | C33: Register compilation | D33: Lorcan Dimitrov | E33: W09 | F33: =DATE(2026,6,29)+7*(VALUE(RIGHT(E33,2))-1) -> 46258 | G33: 16 | H33: W09 | I33: W09 | K33: Owner | L33: =IF(AND(VALUE(RIGHT(E33,2))>=VALUE(RIGHT(H33,2)),VALUE(RIGHT(E33,2))<=VALUE(RIGHT(I33,2)),F33<=DATE(2026,9,25)),"OK","WARNING") -> OK | M33: =IF(J33="","OK",IF(COUNTIFS($A$5:$A$33,J33,$E$5:$E$33,"<"&E33)>0,"OK","WARNING")) -> OK | N33: =IF(OR(AND(A33="D1-B",COUNTIFS($A$5:$A$33,"D3-B",$E$5:$E$33,E33)>0),AND(A33="D3-B",COUNTIFS($A$5:$A$33,"D1-B",$E$5:$E$33,E33)>0),AND(A33="D2-B",COUNTIFS($A$5:$A$33,"D4-A",$E$5:$E$33,E33)>0),AND(A33="D4-A",COUNTIFS($A$5:$A$33,"D2-B",$E$5:$E$33,E33)>0),AND(A33="D1-F",COUNTIFS($A$5:$A$33,"D2-F",$E$5:$E$33,E33)>0),AND(A33="D2-F",COUNTIFS($A$5:$A$33,"D1-F",$E$5:$E$33,E33)>0)),"WARNING","OK") -> OK | O33: =IF(COUNTIF(L33:N33,"WARNING")>0,"WARNING","OK") -> OK
A34: D9-B | B34: D9 | C34: Register QA | D34: Ravi Moravec | E34: W10 | F34: =DATE(2026,6,29)+7*(VALUE(RIGHT(E34,2))-1) -> 46265 | G34: 8 | H34: W10 | I34: W10 | J34: D9-A | K34: Reviewer | L34: =IF(AND(VALUE(RIGHT(E34,2))>=VALUE(RIGHT(H34,2)),VALUE(RIGHT(E34,2))<=VALUE(RIGHT(I34,2)),F34<=DATE(2026,9,25)),"OK","WARNING") -> OK | M34: =IF(J34="","OK",IF(COUNTIFS($A$5:$A$33,J34,$E$5:$E$33,"<"&E34)>0,"OK","WARNING")) -> OK | N34: =IF(OR(AND(A34="D1-B",COUNTIFS($A$5:$A$33,"D3-B",$E$5:$E$33,E34)>0),AND(A34="D3-B",COUNTIFS($A$5:$A$33,"D1-B",$E$5:$E$33,E34)>0),AND(A34="D2-B",COUNTIFS($A$5:$A$33,"D4-A",$E$5:$E$33,E34)>0),AND(A34="D4-A",COUNTIFS($A$5:$A$33,"D2-B",$E$5:$E$33,E34)>0),AND(A34="D1-F",COUNTIFS($A$5:$A$33,"D2-F",$E$5:$E$33,E34)>0),AND(A34="D2-F",COUNTIFS($A$5:$A$33,"D1-F",$E$5:$E$33,E34)>0)),"WARNING","OK") -> OK | O34: =IF(COUNTIF(L34:N34,"WARNING")>0,"WARNING","OK") -> OK

Sheet Allocations
A1: Normalised allocation ledger — every activity, review, supervision and signatory hour
A2: One row per person-role allocation; summaries use SUMIFS so edits remain live.
A4: Allocation ID | B4: Deliverable ID | C4: Activity ID | D4: Week | E4: Consultant | F4: Role | G4: Planned hours | H4: Control / note
A5: D1-A-OWN | B5: D1 | C5: D1-A | D5: W02 | E5: Casimir Oyelowo | F5: Activity / owner | G5: 12
A6: D1-B-OWN | B6: D1 | C6: D1-B | D6: W03 | E6: Casimir Oyelowo | F6: Activity / owner | G6: 18
A7: D1-C-OWN | B7: D1 | C7: D1-C | D7: W04 | E7: Casimir Oyelowo | F7: Activity / owner | G7: 20
A8: D1-D-OWN | B8: D1 | C8: D1-D | D8: W05 | E8: Casimir Oyelowo | F8: Activity / owner | G8: 18
A9: D1-E-OWN | B9: D1 | C9: D1-E | D9: W06 | E9: Chidi Jankowski | F9: Activity / owner | G9: 10
A10: D1-E-REV | B10: D1 | C10: D1-E | D10: W06 | E10: Chidi Jankowski | F10: Independent reviewer | G10: 10 | H10: Independent from Casimir drafter
A11: D1-F-OWN | B11: D1 | C11: D1-F | D11: W08 | E11: Casimir Oyelowo | F11: Activity / owner | G11: 6
A12: D1-F-SUP | B12: D1 | C12: D1-F | D12: W08 | E12: Marisol Reinholt | F12: Approved supervisor | G12: 2 | H12: Supervised submission
A13: D1-F-SIG | B13: D1 | C13: D1-F | D13: W08 | E13: Marisol Reinholt | F13: Submission signatory | G13: 4 | H13: Water/wetlands approval
A14: D2-A-OWN | B14: D2 | C14: D2-A | D14: W03 | E14: Arjun Redmayne | F14: Activity / owner | G14: 10
A15: D2-B-OWN | B15: D2 | C15: D2-B | D15: W04 | E15: Arjun Redmayne | F15: Activity / owner | G15: 16
A16: D2-C-OWN | B16: D2 | C16: D2-C | D16: W05 | E16: Arjun Redmayne | F16: Activity / owner | G16: 24
A17: D2-D-OWN | B17: D2 | C17: D2-D | D17: W06 | E17: Arjun Redmayne | F17: Activity / owner | G17: 18
A18: D2-E-OWN | B18: D2 | C18: D2-E | D18: W08 | E18: Chidi Jankowski | F18: Activity / owner | G18: 10
A19: D2-E-REV | B19: D2 | C19: D2-E | D19: W08 | E19: Chidi Jankowski | F19: Independent reviewer | G19: 10 | H19: Independent from Arjun drafter
A20: D2-F-OWN | B20: D2 | C20: D2-F | D20: W11 | E20: Arjun Redmayne | F20: Activity / owner | G20: 6
A21: D2-F-SIG | B21: D2 | C21: D2-F | D21: W11 | E21: Ravi Moravec | F21: Submission signatory | G21: 4 | H21: Air approval
A22: D3-A-OWN | B22: D3 | C22: D3-A | D22: W01 | E22: Chidi Jankowski | F22: Activity / owner | G22: 8
A23: D3-B-OWN | B23: D3 | C23: D3-B | D23: W05 | E23: Chidi Jankowski | F23: Activity / owner | G23: 12
A24: D3-C-OWN | B24: D3 | C24: D3-C | D24: W06 | E24: Chidi Jankowski | F24: Activity / owner | G24: 10
A25: D4-A-OWN | B25: D4 | C25: D4-A | D25: W06 | E25: Lorcan Dimitrov | F25: Activity / owner | G25: 14
A26: D4-B-OWN | B26: D4 | C26: D4-B | D26: W07 | E26: Lorcan Dimitrov | F26: Activity / owner | G26: 16
A27: D4-C-OWN | B27: D4 | C27: D4-C | D27: W08 | E27: Lorcan Dimitrov | F27: Activity / owner | G27: 6
A28: D4-C-REV | B28: D4 | C28: D4-C | D28: W08 | E28: Lorcan Dimitrov | F28: Client-facing reviewer | G28: 6 | H28: Waste control review
A29: D5-A-OWN | B29: D5 | C29: D5-A | D29: W02 | E29: Arjun Redmayne | F29: Activity / owner | G29: 12
A30: D5-B-OWN | B30: D5 | C30: D5-B | D30: W03 | E30: Arjun Redmayne | F30: Activity / owner | G30: 16
A31: D5-C-OWN | B31: D5 | C31: D5-C | D31: W04 | E31: Arjun Redmayne | F31: Activity / owner | G31: 8
A32: D6-A-OWN | B32: D6 | C32: D6-A | D32: W01 | E32: Chidi Jankowski | F32: Activity / owner | G32: 10
A33: D6-B-OWN | B33: D6 | C33: D6-B | D33: W02 | E33: Chidi Jankowski | F33: Activity / owner | G33: 18
A34: D6-C-OWN | B34: D6 | C34: D6-C | D34: W03 | E34: Marisol Reinholt | F34: Activity / owner | G34: 6
A35: D6-C-REV | B35: D6 | C35: D6-C | D35: W03 | E35: Marisol Reinholt | F35: Water discipline reviewer | G35: 6 | H35: Water review
A36: D7-A-OWN | B36: D7 | C36: D7-A | D36: W02 | E36: Lorcan Dimitrov | F36: Activity / owner | G36: 12
A37: D7-B-OWN | B37: D7 | C37: D7-B | D37: W03 | E37: Lorcan Dimitrov | F37: Activity / owner | G37: 12
A38: D8-A-OWN | B38: D8 | C38: D8-A | D38: W09 | E38: Casimir Oyelowo | F38: Activity / owner | G38: 14
A39: D8-B-OWN | B39: D8 | C39: D8-B | D39: W10 | E39: Marisol Reinholt | F39: Activity / owner | G39: 6
A40: D8-B-SIG | B40: D8 | C40: D8-B | D40: W10 | E40: Marisol Reinholt | F40: Submission signatory | G40: 6 | H40: Water pre-application
A41: D9-A-OWN | B41: D9 | C41: D9-A | D41: W09 | E41: Lorcan Dimitrov | F41: Activity / owner | G41: 16
...

Sheet Consultant Summary
A1: Consultant capacity and utilisation
A2: Planned hours include activity, reviewer, supervisor and signatory duties.
A4: Consultant | B4: W01 | C4: W02 | D4: W03 | E4: W04 | F4: W05 | G4: W06 | H4: W07 | I4: W08 | J4: W09 | K4: W10 | L4: W11 | M4: W12 | N4: W13 | O4: Quarter planned | P4: Quarter available | Q4: Utilisation % | R4: Remaining / overload | S4: Status
A5: Marisol Reinholt | B5: =SUMIFS(Allocations!$G$5:$G$43,Allocations!$E$5:$E$43,$A5,Allocations!$D$5:$D$43,B$4) -> 0 | C5: =SUMIFS(Allocations!$G$5:$G$43,Allocations!$E$5:$E$43,$A5,Allocations!$D$5:$D$43,C$4) -> 0 | D5: =SUMIFS(Allocations!$G$5:$G$43,Allocations!$E$5:$E$43,$A5,Allocations!$D$5:$D$43,D$4) -> 12 | E5: =SUMIFS(Allocations!$G$5:$G$43,Allocations!$E$5:$E$43,$A5,Allocations!$D$5:$D$43,E$4) -> 0 | F5: =SUMIFS(Allocations!$G$5:$G$43,Allocations!$E$5:$E$43,$A5,Allocations!$D$5:$D$43,F$4) -> 0 | G5: =SUMIFS(Allocations!$G$5:$G$43,Allocations!$E$5:$E$43,$A5,Allocations!$D$5:$D$43,G$4) -> 0 | H5: =SUMIFS(Allocations!$G$5:$G$43,Allocations!$E$5:$E$43,$A5,Allocations!$D$5:$D$43,H$4) -> 0 | I5: =SUMIFS(Allocations!$G$5:$G$43,Allocations!$E$5:$E$43,$A5,Allocations!$D$5:$D$43,I$4) -> 6 | ... N5: =SUMIFS(Allocations!$G$5:$G$43,Allocations!$E$5:$E$43,$A5,Allocations!$D$5:$D$43,N$4) -> 0 | O5: =SUM(B5:N5) -> 30 | P5: =32*13-0-24 -> 392 | Q5: =IFERROR(O5/P5,0) -> 0.076530612 | R5: =P5-O5 -> 362 | S5: =IF(MIN(B5:N5)<0,"WARNING",IF(MAX(B5:N5)>MAX(0,32),"WARNING","OK")) -> OK
A6: Ravi Moravec | B6: =SUMIFS(Allocations!$G$5:$G$43,Allocations!$E$5:$E$43,$A6,Allocations!$D$5:$D$43,B$4) -> 0 | C6: =SUMIFS(Allocations!$G$5:$G$43,Allocations!$E$5:$E$43,$A6,Allocations!$D$5:$D$43,C$4) -> 0 | D6: =SUMIFS(Allocations!$G$5:$G$43,Allocations!$E$5:$E$43,$A6,Allocations!$D$5:$D$43,D$4) -> 0 | E6: =SUMIFS(Allocations!$G$5:$G$43,Allocations!$E$5:$E$43,$A6,Allocations!$D$5:$D$43,E$4) -> 0 | F6: =SUMIFS(Allocations!$G$5:$G$43,Allocations!$E$5:$E$43,$A6,Allocations!$D$5:$D$43,F$4) -> 0 | G6: =SUMIFS(Allocations!$G$5:$G$43,Allocations!$E$5:$E$43,$A6,Allocations!$D$5:$D$43,G$4) -> 0 | H6: =SUMIFS(Allocations!$G$5:$G$43,Allocations!$E$5:$E$43,$A6,Allocations!$D$5:$D$43,H$4) -> 0 | I6: =SUMIFS(Allocations!$G$5:$G$43,Allocations!$E$5:$E$43,$A6,Allocations!$D$5:$D$43,I$4) -> 0 | ... N6: =SUMIFS(Allocations!$G$5:$G$43,Allocations!$E$5:$E$43,$A6,Allocations!$D$5:$D$43,N$4) -> 0 | O6: =SUM(B6:N6) -> 20 | P6: =30*13-0-20 -> 370 | Q6: =IFERROR(O6/P6,0) -> 0.054054054 | R6: =P6-O6 -> 350 | S6: =IF(MIN(B6:N6)<0,"WARNING",IF(MAX(B6:N6)>MAX(0,30),"WARNING","OK")) -> OK
A7: Chidi Jankowski | B7: =SUMIFS(Allocations!$G$5:$G$43,Allocations!$E$5:$E$43,$A7,Allocations!$D$5:$D$43,B$4) -> 18 | C7: =SUMIFS(Allocations!$G$5:$G$43,Allocations!$E$5:$E$43,$A7,Allocations!$D$5:$D$43,C$4) -> 18 | D7: =SUMIFS(Allocations!$G$5:$G$43,Allocations!$E$5:$E$43,$A7,Allocations!$D$5:$D$43,D$4) -> 0 | E7: =SUMIFS(Allocations!$G$5:$G$43,Allocations!$E$5:$E$43,$A7,Allocations!$D$5:$D$43,E$4) -> 0 | F7: =SUMIFS(Allocations!$G$5:$G$43,Allocations!$E$5:$E$43,$A7,Allocations!$D$5:$D$43,F$4) -> 12 | G7: =SUMIFS(Allocations!$G$5:$G$43,Allocations!$E$5:$E$43,$A7,Allocations!$D$5:$D$43,G$4) -> 30 | H7: =SUMIFS(Allocations!$G$5:$G$43,Allocations!$E$5:$E$43,$A7,Allocations!$D$5:$D$43,H$4) -> 0 | I7: =SUMIFS(Allocations!$G$5:$G$43,Allocations!$E$5:$E$43,$A7,Allocations!$D$5:$D$43,I$4) -> 20 | ... N7: =SUMIFS(Allocations!$G$5:$G$43,Allocations!$E$5:$E$43,$A7,Allocations!$D$5:$D$43,N$4) -> 0 | O7: =SUM(B7:N7) -> 98 | P7: =34*13-20 -> 422 | Q7: =IFERROR(O7/P7,0) -> 0.23222749 | R7: =P7-O7 -> 324 | S7: =IF(MIN(B7:N7)<0,"WARNING",IF(MAX(B7:N7)>MAX(0,34),"WARNING","OK")) -> OK
A8: Arjun Redmayne | B8: =SUMIFS(Allocations!$G$5:$G$43,Allocations!$E$5:$E$43,$A8,Allocations!$D$5:$D$43,B$4) -> 0 | C8: =SUMIFS(Allocations!$G$5:$G$43,Allocations!$E$5:$E$43,$A8,Allocations!$D$5:$D$43,C$4) -> 12 | D8: =SUMIFS(Allocations!$G$5:$G$43,Allocations!$E$5:$E$43,$A8,Allocations!$D$5:$D$43,D$4) -> 26 | E8: =SUMIFS(Allocations!$G$5:$G$43,Allocations!$E$5:$E$43,$A8,Allocations!$D$5:$D$43,E$4) -> 24 | F8: =SUMIFS(Allocations!$G$5:$G$43,Allocations!$E$5:$E$43,$A8,Allocations!$D$5:$D$43,F$4) -> 24 | G8: =SUMIFS(Allocations!$G$5:$G$43,Allocations!$E$5:$E$43,$A8,Allocations!$D$5:$D$43,G$4) -> 18 | H8: =SUMIFS(Allocations!$G$5:$G$43,Allocations!$E$5:$E$43,$A8,Allocations!$D$5:$D$43,H$4) -> 0 | I8: =SUMIFS(Allocations!$G$5:$G$43,Allocations!$E$5:$E$43,$A8,Allocations!$D$5:$D$43,I$4) -> 0 | ... N8: =SUMIFS(Allocations!$G$5:$G$43,Allocations!$E$5:$E$43,$A8,Allocations!$D$5:$D$43,N$4) -> 0 | O8: =SUM(B8:N8) -> 110 | P8: =32*13-24 -> 392 | Q8: =IFERROR(O8/P8,0) -> 0.28061224 | R8: =P8-O8 -> 282 | S8: =IF(MIN(B8:N8)<0,"WARNING",IF(MAX(B8:N8)>MAX(0,32),"WARNING","OK")) -> OK
A9: Lorcan Dimitrov | B9: =SUMIFS(Allocations!$G$5:$G$43,Allocations!$E$5:$E$43,$A9,Allocations!$D$5:$D$43,B$4) -> 0 | C9: =SUMIFS(Allocations!$G$5:$G$43,Allocations!$E$5:$E$43,$A9,Allocations!$D$5:$D$43,C$4) -> 12 | D9: =SUMIFS(Allocations!$G$5:$G$43,Allocations!$E$5:$E$43,$A9,Allocations!$D$5:$D$43,D$4) -> 12 | E9: =SUMIFS(Allocations!$G$5:$G$43,Allocations!$E$5:$E$43,$A9,Allocations!$D$5:$D$43,E$4) -> 0 | F9: =SUMIFS(Allocations!$G$5:$G$43,Allocations!$E$5:$E$43,$A9,Allocations!$D$5:$D$43,F$4) -> 0 | G9: =SUMIFS(Allocations!$G$5:$G$43,Allocations!$E$5:$E$43,$A9,Allocations!$D$5:$D$43,G$4) -> 14 | H9: =SUMIFS(Allocations!$G$5:$G$43,Allocations!$E$5:$E$43,$A9,Allocations!$D$5:$D$43,H$4) -> 16 | I9: =SUMIFS(Allocations!$G$5:$G$43,Allocations!$E$5:$E$43,$A9,Allocations!$D$5:$D$43,I$4) -> 12 | ... N9: =SUMIFS(Allocations!$G$5:$G$43,Allocations!$E$5:$E$43,$A9,Allocations!$D$5:$D$43,N$4) -> 0 | O9: =SUM(B9:N9) -> 82 | P9: =34*13-18 -> 424 | Q9: =IFERROR(O9/P9,0) -> 0.19339623 | R9: =P9-O9 -> 342 | S9: =IF(MIN(B9:N9)<0,"WARNING",IF(MAX(B9:N9)>MAX(0,34),"WARNING","OK")) -> OK
A10: Casimir Oyelowo | B10: =SUMIFS(Allocations!$G$5:$G$43,Allocations!$E$5:$E$43,$A10,Allocations!$D$5:$D$43,B$4) -> 0 | C10: =SUMIFS(Allocations!$G$5:$G$43,Allocations!$E$5:$E$43,$A10,Allocations!$D$5:$D$43,C$4) -> 12 | D10: =SUMIFS(Allocations!$G$5:$G$43,Allocations!$E$5:$E$43,$A10,Allocations!$D$5:$D$43,D$4) -> 18 | E10: =SUMIFS(Allocations!$G$5:$G$43,Allocations!$E$5:$E$43,$A10,Allocations!$D$5:$D$43,E$4) -> 20 | F10: =SUMIFS(Allocations!$G$5:$G$43,Allocations!$E$5:$E$43,$A10,Allocations!$D$5:$D$43,F$4) -> 18 | G10: =SUMIFS(Allocations!$G$5:$G$43,Allocations!$E$5:$E$43,$A10,Allocations!$D$5:$D$43,G$4) -> 0 | H10: =SUMIFS(Allocations!$G$5:$G$43,Allocations!$E$5:$E$43,$A10,Allocations!$D$5:$D$43,H$4) -> 0 | I10: =SUMIFS(Allocations!$G$5:$G$43,Allocations!$E$5:$E$43,$A10,Allocations!$D$5:$D$43,I$4) -> 6 | ... N10: =SUMIFS(Allocations!$G$5:$G$43,Allocations!$E$5:$E$43,$A10,Allocations!$D$5:$D$43,N$4) -> 0 | O10: =SUM(B10:N10) -> 88 | P10: =30*13-24 -> 366 | Q10: =IFERROR(O10/P10,0) -> 0.24043716 | R10: =P10-O10 -> 278 | S10: =IF(MIN(B10:N10)<0,"WARNING",IF(MAX(B10:N10)>MAX(0,30),"WARNING","OK")) -> OK

Sheet Deliverable Summary
A1: Deliverable effort reconciliation
A2: Required effort comes from source records; scheduled effort is live from Allocations.
A4: Deliverable ID | B4: Deliverable | C4: Required effort (h) | D4: Scheduled effort (h) | E4: Owner hours | F4: Support / review / signatory hours | G4: Variance | H4: Status
A5: D1 | B5: Saltcombe wetlands permit variation | C5: =SUMIF('Assignment Register'!$A$6:$A$14,A5,'Assignment Register'!$I$6:$I$14) -> 100 | D5: =SUMIF(Allocations!$B$5:$B$43,A5,Allocations!$G$5:$G$43) -> 100 | E5: =SUMIFS(Allocations!$G$5:$G$43,Allocations!$B$5:$B$43,A5,Allocations!$F$5:$F$43,"Activity / owner") -> 84 | F5: =D5-E5 -> 16 | G5: =D5-C5 -> 0 | H5: =IF(G5=0,"OK","WARNING") -> OK
A6: D2 | B6: Westmere air permit variation | C6: =SUMIF('Assignment Register'!$A$6:$A$14,A6,'Assignment Register'!$I$6:$I$14) -> 98 | D6: =SUMIF(Allocations!$B$5:$B$43,A6,Allocations!$G$5:$G$43) -> 98 | E6: =SUMIFS(Allocations!$G$5:$G$43,Allocations!$B$5:$B$43,A6,Allocations!$F$5:$F$43,"Activity / owner") -> 84 | F6: =D6-E6 -> 14 | G6: =D6-C6 -> 0 | H6: =IF(G6=0,"OK","WARNING") -> OK
A7: D3 | B7: Saltcombe ecology screening | C7: =SUMIF('Assignment Register'!$A$6:$A$14,A7,'Assignment Register'!$I$6:$I$14) -> 30 | D7: =SUMIF(Allocations!$B$5:$B$43,A7,Allocations!$G$5:$G$43) -> 30 | E7: =SUMIFS(Allocations!$G$5:$G$43,Allocations!$B$5:$B$43,A7,Allocations!$F$5:$F$43,"Activity / owner") -> 30 | F7: =D7-E7 -> 0 | G7: =D7-C7 -> 0 | H7: =IF(G7=0,"OK","WARNING") -> OK
A8: D4 | B8: Westmere waste controls | C8: =SUMIF('Assignment Register'!$A$6:$A$14,A8,'Assignment Register'!$I$6:$I$14) -> 42 | D8: =SUMIF(Allocations!$B$5:$B$43,A8,Allocations!$G$5:$G$43) -> 42 | E8: =SUMIFS(Allocations!$G$5:$G$43,Allocations!$B$5:$B$43,A8,Allocations!$F$5:$F$43,"Activity / owner") -> 36 | F8: =D8-E8 -> 6 | G8: =D8-C8 -> 0 | H8: =IF(G8=0,"OK","WARNING") -> OK
A9: D5 | B9: Westmere noise assessment | C9: =SUMIF('Assignment Register'!$A$6:$A$14,A9,'Assignment Register'!$I$6:$I$14) -> 36 | D9: =SUMIF(Allocations!$B$5:$B$43,A9,Allocations!$G$5:$G$43) -> 36 | E9: =SUMIFS(Allocations!$G$5:$G$43,Allocations!$B$5:$B$43,A9,Allocations!$F$5:$F$43,"Activity / owner") -> 36 | F9: =D9-E9 -> 0 | G9: =D9-C9 -> 0 | H9: =IF(G9=0,"OK","WARNING") -> OK
A10: D6 | B10: Saltcombe drainage note | C10: =SUMIF('Assignment Register'!$A$6:$A$14,A10,'Assignment Register'!$I$6:$I$14) -> 40 | D10: =SUMIF(Allocations!$B$5:$B$43,A10,Allocations!$G$5:$G$43) -> 40 | E10: =SUMIFS(Allocations!$G$5:$G$43,Allocations!$B$5:$B$43,A10,Allocations!$F$5:$F$43,"Activity / owner") -> 34 | F10: =D10-E10 -> 6 | G10: =D10-C10 -> 0 | H10: =IF(G10=0,"OK","WARNING") -> OK
A11: D7 | B11: Westmere solvent inventory | C11: =SUMIF('Assignment Register'!$A$6:$A$14,A11,'Assignment Register'!$I$6:$I$14) -> 24 | D11: =SUMIF(Allocations!$B$5:$B$43,A11,Allocations!$G$5:$G$43) -> 24 | E11: =SUMIFS(Allocations!$G$5:$G$43,Allocations!$B$5:$B$43,A11,Allocations!$F$5:$F$43,"Activity / owner") -> 24 | F11: =D11-E11 -> 0 | G11: =D11-C11 -> 0 | H11: =IF(G11=0,"OK","WARNING") -> OK
A12: D8 | B12: Saltcombe trade-effluent pre-application | C12: =SUMIF('Assignment Register'!$A$6:$A$14,A12,'Assignment Register'!$I$6:$I$14) -> 26 | D12: =SUMIF(Allocations!$B$5:$B$43,A12,Allocations!$G$5:$G$43) -> 26 | E12: =SUMIFS(Allocations!$G$5:$G$43,Allocations!$B$5:$B$43,A12,Allocations!$F$5:$F$43,"Activity / owner") -> 20 | F12: =D12-E12 -> 6 | G12: =D12-C12 -> 0 | H12: =IF(G12=0,"OK","WARNING") -> OK
A13: D9 | B13: Quarterly permit register | C13: =SUMIF('Assignment Register'!$A$6:$A$14,A13,'Assignment Register'!$I$6:$I$14) -> 32 | D13: =SUMIF(Allocations!$B$5:$B$43,A13,Allocations!$G$5:$G$43) -> 32 | E13: =SUMIFS(Allocations!$G$5:$G$43,Allocations!$B$5:$B$43,A13,Allocations!$F$5:$F$43,"Activity / owner") -> 24 | F13: =D13-E13 -> 8 | G13: =D13-C13 -> 0 | H13: =IF(G13=0,"OK","WARNING") -> OK

Sheet Assumptions & Decisions
A1: Assumptions and decision record
A3: Date / ID | B3: Decision or assumption | C3: Reason / evidence | D3: Impact / warning
A4: 15-May-2026 | B4: Use Monday-start workweeks W01–W13; latest completion is Friday 25-Sep-2026. | C4: Matches source reporting convention and quarter horizon. | D4: Dates formula-driven from Week field.
A5: DEC-01 | B5: Casimir owns D1 and submits under Marisol supervision by W08. | C5: Only qualifying water/wetlands major permit matches his competence and development commitment. | D5: D1 submission is W08; Marisol supervisor/signatory hours are explicit.
A6: DEC-02 | B6: D1 and D2 submissions separated (W08 and W11). | C6: Source mutual exclusion rule for major submissions. | D6: Status warning flags if weeks are edited to collide.
A7: DEC-03 | B7: D1-B/D3-B and D2-B/D4-A site activities placed in different weeks. | C7: Source shared-site access exclusion pairs. | D7: Exclusion check is live in Activity Schedule.
A8: DEC-04 | B8: Independent reviewers differ from drafters; signatory status is not treated as ownership requirement. | C8: England control note effective 15-May-2026. | D8: Reviewer/signatory roles are separately allocated.
A9: DEC-05 | B9: No extra people or capacity; listed weekly capacity is net of committed work. | C9: Explicit request instruction. | D9: Capacity summary warns on overloads.
