Workbook

Sheet Assignment
A1: Ballantry Industries | Golden-zone slotting record
A2: Freeze date: 31 January 2025 | Jurisdiction: Ontario | 96 fixed-route golden-zone bins
A4: Route_Seq | B4: Bin_ID | C4: SKU_ID | D4: Handling_Class | E4: Selection_Reason | F4: Face_Qty | G4: Unit_Weight_kg | H4: Loaded_Weight_kg | I4: Bin_Weight_Cap_kg | J4: Weight_Status | K4: Face_Cube_m3 | L4: Usable_Cube_m3 | M4: Cube_Status | N4: Level | O4: Hazard_Class | P4: Bin_Hazard_Authorization | Q4: QTrace_Required | R4: Bin_QTrace_Cert | S4: Cert_Expiry | T4: Eligibility_Status | U4: Hard_Rule_Status | V4: Next_Handling | W4: Changeover_Charge
A5: 1 | B5: GZ-001 | C5: SKU001 | D5: =VLOOKUP(C5,Data_Candidates!$A$2:$Y$133,14,FALSE()) -> A | E5: =VLOOKUP(C5,Data_Candidates!$A$2:$Y$133,22,FALSE()) -> C01 | F5: =VLOOKUP(C5,Data_Candidates!$A$2:$Y$133,13,FALSE()) -> 4 | G5: =VLOOKUP(C5,Data_Candidates!$A$2:$Y$133,8,FALSE()) -> 1.2 | H5: =F5*G5 -> 4.8 | I5: =VLOOKUP(B5,Data_Bins!$A$2:$L$101,5,FALSE()) -> 10 | J5: =IF(H5<=I5,"OK","WEIGHT") -> OK | K5: =F5*VLOOKUP(C5,Data_Candidates!$A$2:$Y$133,9,FALSE())/0.7 -> 0.0057142857 | L5: =VLOOKUP(B5,Data_Bins!$A$2:$L$101,4,FALSE()) -> 0.02 | M5: =IF(K5<=L5,"OK","CUBE") -> OK | N5: =VLOOKUP(B5,Data_Bins!$A$2:$L$101,6,FALSE()) -> L2 | O5: =VLOOKUP(C5,Data_Candidates!$A$2:$Y$133,15,FALSE()) -> NONE | P5: =VLOOKUP(B5,Data_Bins!$A$2:$L$101,8,FALSE()) -> NONE | Q5: =VLOOKUP(C5,Data_Candidates!$A$2:$Y$133,16,FALSE()) -> N | R5: =VLOOKUP(B5,Data_Bins!$A$2:$L$101,9,FALSE()) -> 0 | S5: =VLOOKUP(B5,Data_Bins!$A$2:$L$101,10,FALSE()) -> 0 | T5: =IF(AND(VLOOKUP(C5,Data_Candidates!$A$2:$Y$133,2,FALSE())<=DATE(2025,1,31),VLOOKUP(C5,Data_Candidates!$A$2:$Y$133,3,FALSE())>=DATE(2025,1,31),VLOOKUP(C5,Data_Candidates!$A$2:$Y$133,4,FALSE())="Y",VLOOKUP(C5,Data_Candidates!$A$2:$Y$133,5,FALSE())="NONE",VLOOKUP(C5,Data_Candidates!$A$2:$Y$133,25,FALSE())="Y"),"ELIGIBLE","INELIGIBLE") -> ELIGIBLE | U5: =IF(AND(J5="OK",M5="OK",T5="ELIGIBLE",OR(O5="NONE",P5=O5),OR(Q5="N",AND(Q5="Y",R5="QTRACE",S5>=DATE(2025,1,31))),OR(VLOOKUP(C5,Data_Candidates!$A$2:$Y$133,17,FALSE())="N",N5="L1")),"CLEAR","VIOLATION") -> CLEAR | V5: =D6 -> A | W5: =IF(V5="",0,IF(D5=V5,0,1)) -> 0
A6: 2 | B6: GZ-002 | C6: SKU002 | D6: =VLOOKUP(C6,Data_Candidates!$A$2:$Y$133,14,FALSE()) -> A | E6: =VLOOKUP(C6,Data_Candidates!$A$2:$Y$133,22,FALSE()) -> C02 | F6: =VLOOKUP(C6,Data_Candidates!$A$2:$Y$133,13,FALSE()) -> 4 | G6: =VLOOKUP(C6,Data_Candidates!$A$2:$Y$133,8,FALSE()) -> 1.2 | H6: =F6*G6 -> 4.8 | I6: =VLOOKUP(B6,Data_Bins!$A$2:$L$101,5,FALSE()) -> 100 | J6: =IF(H6<=I6,"OK","WEIGHT") -> OK | K6: =F6*VLOOKUP(C6,Data_Candidates!$A$2:$Y$133,9,FALSE())/0.7 -> 0.0057142857 | L6: =VLOOKUP(B6,Data_Bins!$A$2:$L$101,4,FALSE()) -> 0.02 | M6: =IF(K6<=L6,"OK","CUBE") -> OK | N6: =VLOOKUP(B6,Data_Bins!$A$2:$L$101,6,FALSE()) -> L2 | O6: =VLOOKUP(C6,Data_Candidates!$A$2:$Y$133,15,FALSE()) -> NONE | P6: =VLOOKUP(B6,Data_Bins!$A$2:$L$101,8,FALSE()) -> NONE | Q6: =VLOOKUP(C6,Data_Candidates!$A$2:$Y$133,16,FALSE()) -> N | R6: =VLOOKUP(B6,Data_Bins!$A$2:$L$101,9,FALSE()) -> 0 | S6: =VLOOKUP(B6,Data_Bins!$A$2:$L$101,10,FALSE()) -> 0 | T6: =IF(AND(VLOOKUP(C6,Data_Candidates!$A$2:$Y$133,2,FALSE())<=DATE(2025,1,31),VLOOKUP(C6,Data_Candidates!$A$2:$Y$133,3,FALSE())>=DATE(2025,1,31),VLOOKUP(C6,Data_Candidates!$A$2:$Y$133,4,FALSE())="Y",VLOOKUP(C6,Data_Candidates!$A$2:$Y$133,5,FALSE())="NONE",VLOOKUP(C6,Data_Candidates!$A$2:$Y$133,25,FALSE())="Y"),"ELIGIBLE","INELIGIBLE") -> ELIGIBLE | U6: =IF(AND(J6="OK",M6="OK",T6="ELIGIBLE",OR(O6="NONE",P6=O6),OR(Q6="N",AND(Q6="Y",R6="QTRACE",S6>=DATE(2025,1,31))),OR(VLOOKUP(C6,Data_Candidates!$A$2:$Y$133,17,FALSE())="N",N6="L1")),"CLEAR","VIOLATION") -> CLEAR | V6: =D7 -> A | W6: =IF(V6="",0,IF(D6=V6,0,1)) -> 0
A7: 3 | B7: GZ-003 | C7: SKU003 | D7: =VLOOKUP(C7,Data_Candidates!$A$2:$Y$133,14,FALSE()) -> A | E7: =VLOOKUP(C7,Data_Candidates!$A$2:$Y$133,22,FALSE()) -> C03 | F7: =VLOOKUP(C7,Data_Candidates!$A$2:$Y$133,13,FALSE()) -> 4 | G7: =VLOOKUP(C7,Data_Candidates!$A$2:$Y$133,8,FALSE()) -> 1.2 | H7: =F7*G7 -> 4.8 | I7: =VLOOKUP(B7,Data_Bins!$A$2:$L$101,5,FALSE()) -> 100 | J7: =IF(H7<=I7,"OK","WEIGHT") -> OK | K7: =F7*VLOOKUP(C7,Data_Candidates!$A$2:$Y$133,9,FALSE())/0.7 -> 0.0057142857 | L7: =VLOOKUP(B7,Data_Bins!$A$2:$L$101,4,FALSE()) -> 0.02 | M7: =IF(K7<=L7,"OK","CUBE") -> OK | N7: =VLOOKUP(B7,Data_Bins!$A$2:$L$101,6,FALSE()) -> L2 | O7: =VLOOKUP(C7,Data_Candidates!$A$2:$Y$133,15,FALSE()) -> NONE | P7: =VLOOKUP(B7,Data_Bins!$A$2:$L$101,8,FALSE()) -> NONE | Q7: =VLOOKUP(C7,Data_Candidates!$A$2:$Y$133,16,FALSE()) -> N | R7: =VLOOKUP(B7,Data_Bins!$A$2:$L$101,9,FALSE()) -> 0 | S7: =VLOOKUP(B7,Data_Bins!$A$2:$L$101,10,FALSE()) -> 0 | T7: =IF(AND(VLOOKUP(C7,Data_Candidates!$A$2:$Y$133,2,FALSE())<=DATE(2025,1,31),VLOOKUP(C7,Data_Candidates!$A$2:$Y$133,3,FALSE())>=DATE(2025,1,31),VLOOKUP(C7,Data_Candidates!$A$2:$Y$133,4,FALSE())="Y",VLOOKUP(C7,Data_Candidates!$A$2:$Y$133,5,FALSE())="NONE",VLOOKUP(C7,Data_Candidates!$A$2:$Y$133,25,FALSE())="Y"),"ELIGIBLE","INELIGIBLE") -> ELIGIBLE | U7: =IF(AND(J7="OK",M7="OK",T7="ELIGIBLE",OR(O7="NONE",P7=O7),OR(Q7="N",AND(Q7="Y",R7="QTRACE",S7>=DATE(2025,1,31))),OR(VLOOKUP(C7,Data_Candidates!$A$2:$Y$133,17,FALSE())="N",N7="L1")),"CLEAR","VIOLATION") -> CLEAR | V7: =D8 -> A | W7: =IF(V7="",0,IF(D7=V7,0,1)) -> 0
A8: 4 | B8: GZ-004 | C8: SKU004 | D8: =VLOOKUP(C8,Data_Candidates!$A$2:$Y$133,14,FALSE()) -> A | E8: =VLOOKUP(C8,Data_Candidates!$A$2:$Y$133,22,FALSE()) -> C04 | F8: =VLOOKUP(C8,Data_Candidates!$A$2:$Y$133,13,FALSE()) -> 4 | G8: =VLOOKUP(C8,Data_Candidates!$A$2:$Y$133,8,FALSE()) -> 1.2 | H8: =F8*G8 -> 4.8 | I8: =VLOOKUP(B8,Data_Bins!$A$2:$L$101,5,FALSE()) -> 100 | J8: =IF(H8<=I8,"OK","WEIGHT") -> OK | K8: =F8*VLOOKUP(C8,Data_Candidates!$A$2:$Y$133,9,FALSE())/0.7 -> 0.0057142857 | L8: =VLOOKUP(B8,Data_Bins!$A$2:$L$101,4,FALSE()) -> 0.02 | M8: =IF(K8<=L8,"OK","CUBE") -> OK | N8: =VLOOKUP(B8,Data_Bins!$A$2:$L$101,6,FALSE()) -> L2 | O8: =VLOOKUP(C8,Data_Candidates!$A$2:$Y$133,15,FALSE()) -> NONE | P8: =VLOOKUP(B8,Data_Bins!$A$2:$L$101,8,FALSE()) -> NONE | Q8: =VLOOKUP(C8,Data_Candidates!$A$2:$Y$133,16,FALSE()) -> N | R8: =VLOOKUP(B8,Data_Bins!$A$2:$L$101,9,FALSE()) -> 0 | S8: =VLOOKUP(B8,Data_Bins!$A$2:$L$101,10,FALSE()) -> 0 | T8: =IF(AND(VLOOKUP(C8,Data_Candidates!$A$2:$Y$133,2,FALSE())<=DATE(2025,1,31),VLOOKUP(C8,Data_Candidates!$A$2:$Y$133,3,FALSE())>=DATE(2025,1,31),VLOOKUP(C8,Data_Candidates!$A$2:$Y$133,4,FALSE())="Y",VLOOKUP(C8,Data_Candidates!$A$2:$Y$133,5,FALSE())="NONE",VLOOKUP(C8,Data_Candidates!$A$2:$Y$133,25,FALSE())="Y"),"ELIGIBLE","INELIGIBLE") -> ELIGIBLE | U8: =IF(AND(J8="OK",M8="OK",T8="ELIGIBLE",OR(O8="NONE",P8=O8),OR(Q8="N",AND(Q8="Y",R8="QTRACE",S8>=DATE(2025,1,31))),OR(VLOOKUP(C8,Data_Candidates!$A$2:$Y$133,17,FALSE())="N",N8="L1")),"CLEAR","VIOLATION") -> CLEAR | V8: =D9 -> A | W8: =IF(V8="",0,IF(D8=V8,0,1)) -> 0
A9: 5 | B9: GZ-005 | C9: SKU005 | D9: =VLOOKUP(C9,Data_Candidates!$A$2:$Y$133,14,FALSE()) -> A | E9: =VLOOKUP(C9,Data_Candidates!$A$2:$Y$133,22,FALSE()) -> C05 | F9: =VLOOKUP(C9,Data_Candidates!$A$2:$Y$133,13,FALSE()) -> 4 | G9: =VLOOKUP(C9,Data_Candidates!$A$2:$Y$133,8,FALSE()) -> 1.2 | H9: =F9*G9 -> 4.8 | I9: =VLOOKUP(B9,Data_Bins!$A$2:$L$101,5,FALSE()) -> 100 | J9: =IF(H9<=I9,"OK","WEIGHT") -> OK | K9: =F9*VLOOKUP(C9,Data_Candidates!$A$2:$Y$133,9,FALSE())/0.7 -> 0.0057142857 | L9: =VLOOKUP(B9,Data_Bins!$A$2:$L$101,4,FALSE()) -> 0.02 | M9: =IF(K9<=L9,"OK","CUBE") -> OK | N9: =VLOOKUP(B9,Data_Bins!$A$2:$L$101,6,FALSE()) -> L2 | O9: =VLOOKUP(C9,Data_Candidates!$A$2:$Y$133,15,FALSE()) -> NONE | P9: =VLOOKUP(B9,Data_Bins!$A$2:$L$101,8,FALSE()) -> NONE | Q9: =VLOOKUP(C9,Data_Candidates!$A$2:$Y$133,16,FALSE()) -> N | R9: =VLOOKUP(B9,Data_Bins!$A$2:$L$101,9,FALSE()) -> 0 | S9: =VLOOKUP(B9,Data_Bins!$A$2:$L$101,10,FALSE()) -> 0 | T9: =IF(AND(VLOOKUP(C9,Data_Candidates!$A$2:$Y$133,2,FALSE())<=DATE(2025,1,31),VLOOKUP(C9,Data_Candidates!$A$2:$Y$133,3,FALSE())>=DATE(2025,1,31),VLOOKUP(C9,Data_Candidates!$A$2:$Y$133,4,FALSE())="Y",VLOOKUP(C9,Data_Candidates!$A$2:$Y$133,5,FALSE())="NONE",VLOOKUP(C9,Data_Candidates!$A$2:$Y$133,25,FALSE())="Y"),"ELIGIBLE","INELIGIBLE") -> ELIGIBLE | U9: =IF(AND(J9="OK",M9="OK",T9="ELIGIBLE",OR(O9="NONE",P9=O9),OR(Q9="N",AND(Q9="Y",R9="QTRACE",S9>=DATE(2025,1,31))),OR(VLOOKUP(C9,Data_Candidates!$A$2:$Y$133,17,FALSE())="N",N9="L1")),"CLEAR","VIOLATION") -> CLEAR | V9: =D10 -> A | W9: =IF(V9="",0,IF(D9=V9,0,1)) -> 0
A10: 6 | B10: GZ-006 | C10: SKU006 | D10: =VLOOKUP(C10,Data_Candidates!$A$2:$Y$133,14,FALSE()) -> A | E10: =VLOOKUP(C10,Data_Candidates!$A$2:$Y$133,22,FALSE()) -> C06 | F10: =VLOOKUP(C10,Data_Candidates!$A$2:$Y$133,13,FALSE()) -> 4 | G10: =VLOOKUP(C10,Data_Candidates!$A$2:$Y$133,8,FALSE()) -> 1.2 | H10: =F10*G10 -> 4.8 | I10: =VLOOKUP(B10,Data_Bins!$A$2:$L$101,5,FALSE()) -> 100 | J10: =IF(H10<=I10,"OK","WEIGHT") -> OK | K10: =F10*VLOOKUP(C10,Data_Candidates!$A$2:$Y$133,9,FALSE())/0.7 -> 0.0057142857 | L10: =VLOOKUP(B10,Data_Bins!$A$2:$L$101,4,FALSE()) -> 0.02 | M10: =IF(K10<=L10,"OK","CUBE") -> OK | N10: =VLOOKUP(B10,Data_Bins!$A$2:$L$101,6,FALSE()) -> L2 | O10: =VLOOKUP(C10,Data_Candidates!$A$2:$Y$133,15,FALSE()) -> NONE | P10: =VLOOKUP(B10,Data_Bins!$A$2:$L$101,8,FALSE()) -> NONE | Q10: =VLOOKUP(C10,Data_Candidates!$A$2:$Y$133,16,FALSE()) -> N | R10: =VLOOKUP(B10,Data_Bins!$A$2:$L$101,9,FALSE()) -> 0 | S10: =VLOOKUP(B10,Data_Bins!$A$2:$L$101,10,FALSE()) -> 0 | T10: =IF(AND(VLOOKUP(C10,Data_Candidates!$A$2:$Y$133,2,FALSE())<=DATE(2025,1,31),VLOOKUP(C10,Data_Candidates!$A$2:$Y$133,3,FALSE())>=DATE(2025,1,31),VLOOKUP(C10,Data_Candidates!$A$2:$Y$133,4,FALSE())="Y",VLOOKUP(C10,Data_Candidates!$A$2:$Y$133,5,FALSE())="NONE",VLOOKUP(C10,Data_Candidates!$A$2:$Y$133,25,FALSE())="Y"),"ELIGIBLE","INELIGIBLE") -> ELIGIBLE | U10: =IF(AND(J10="OK",M10="OK",T10="ELIGIBLE",OR(O10="NONE",P10=O10),OR(Q10="N",AND(Q10="Y",R10="QTRACE",S10>=DATE(2025,1,31))),OR(VLOOKUP(C10,Data_Candidates!$A$2:$Y$133,17,FALSE())="N",N10="L1")),"CLEAR","VIOLATION") -> CLEAR | V10: =D11 -> A | W10: =IF(V10="",0,IF(D10=V10,0,1)) -> 0
A11: 7 | B11: GZ-007 | C11: SKU007 | D11: =VLOOKUP(C11,Data_Candidates!$A$2:$Y$133,14,FALSE()) -> A | E11: =VLOOKUP(C11,Data_Candidates!$A$2:$Y$133,22,FALSE()) -> C07 | F11: =VLOOKUP(C11,Data_Candidates!$A$2:$Y$133,13,FALSE()) -> 4 | G11: =VLOOKUP(C11,Data_Candidates!$A$2:$Y$133,8,FALSE()) -> 1.2 | H11: =F11*G11 -> 4.8 | I11: =VLOOKUP(B11,Data_Bins!$A$2:$L$101,5,FALSE()) -> 100 | J11: =IF(H11<=I11,"OK","WEIGHT") -> OK | K11: =F11*VLOOKUP(C11,Data_Candidates!$A$2:$Y$133,9,FALSE())/0.7 -> 0.0057142857 | L11: =VLOOKUP(B11,Data_Bins!$A$2:$L$101,4,FALSE()) -> 0.02 | M11: =IF(K11<=L11,"OK","CUBE") -> OK | N11: =VLOOKUP(B11,Data_Bins!$A$2:$L$101,6,FALSE()) -> L2 | O11: =VLOOKUP(C11,Data_Candidates!$A$2:$Y$133,15,FALSE()) -> NONE | P11: =VLOOKUP(B11,Data_Bins!$A$2:$L$101,8,FALSE()) -> NONE | Q11: =VLOOKUP(C11,Data_Candidates!$A$2:$Y$133,16,FALSE()) -> N | R11: =VLOOKUP(B11,Data_Bins!$A$2:$L$101,9,FALSE()) -> 0 | S11: =VLOOKUP(B11,Data_Bins!$A$2:$L$101,10,FALSE()) -> 0 | T11: =IF(AND(VLOOKUP(C11,Data_Candidates!$A$2:$Y$133,2,FALSE())<=DATE(2025,1,31),VLOOKUP(C11,Data_Candidates!$A$2:$Y$133,3,FALSE())>=DATE(2025,1,31),VLOOKUP(C11,Data_Candidates!$A$2:$Y$133,4,FALSE())="Y",VLOOKUP(C11,Data_Candidates!$A$2:$Y$133,5,FALSE())="NONE",VLOOKUP(C11,Data_Candidates!$A$2:$Y$133,25,FALSE())="Y"),"ELIGIBLE","INELIGIBLE") -> ELIGIBLE | U11: =IF(AND(J11="OK",M11="OK",T11="ELIGIBLE",OR(O11="NONE",P11=O11),OR(Q11="N",AND(Q11="Y",R11="QTRACE",S11>=DATE(2025,1,31))),OR(VLOOKUP(C11,Data_Candidates!$A$2:$Y$133,17,FALSE())="N",N11="L1")),"CLEAR","VIOLATION") -> CLEAR | V11: =D12 -> A | W11: =IF(V11="",0,IF(D11=V11,0,1)) -> 0
A12: 8 | B12: GZ-008 | C12: SKU008 | D12: =VLOOKUP(C12,Data_Candidates!$A$2:$Y$133,14,FALSE()) -> A | E12: =VLOOKUP(C12,Data_Candidates!$A$2:$Y$133,22,FALSE()) -> C08 | F12: =VLOOKUP(C12,Data_Candidates!$A$2:$Y$133,13,FALSE()) -> 4 | G12: =VLOOKUP(C12,Data_Candidates!$A$2:$Y$133,8,FALSE()) -> 1.2 | H12: =F12*G12 -> 4.8 | I12: =VLOOKUP(B12,Data_Bins!$A$2:$L$101,5,FALSE()) -> 100 | J12: =IF(H12<=I12,"OK","WEIGHT") -> OK | K12: =F12*VLOOKUP(C12,Data_Candidates!$A$2:$Y$133,9,FALSE())/0.7 -> 0.0057142857 | L12: =VLOOKUP(B12,Data_Bins!$A$2:$L$101,4,FALSE()) -> 0.02 | M12: =IF(K12<=L12,"OK","CUBE") -> OK | N12: =VLOOKUP(B12,Data_Bins!$A$2:$L$101,6,FALSE()) -> L2 | O12: =VLOOKUP(C12,Data_Candidates!$A$2:$Y$133,15,FALSE()) -> NONE | P12: =VLOOKUP(B12,Data_Bins!$A$2:$L$101,8,FALSE()) -> NONE | Q12: =VLOOKUP(C12,Data_Candidates!$A$2:$Y$133,16,FALSE()) -> N | R12: =VLOOKUP(B12,Data_Bins!$A$2:$L$101,9,FALSE()) -> 0 | S12: =VLOOKUP(B12,Data_Bins!$A$2:$L$101,10,FALSE()) -> 0 | T12: =IF(AND(VLOOKUP(C12,Data_Candidates!$A$2:$Y$133,2,FALSE())<=DATE(2025,1,31),VLOOKUP(C12,Data_Candidates!$A$2:$Y$133,3,FALSE())>=DATE(2025,1,31),VLOOKUP(C12,Data_Candidates!$A$2:$Y$133,4,FALSE())="Y",VLOOKUP(C12,Data_Candidates!$A$2:$Y$133,5,FALSE())="NONE",VLOOKUP(C12,Data_Candidates!$A$2:$Y$133,25,FALSE())="Y"),"ELIGIBLE","INELIGIBLE") -> ELIGIBLE | U12: =IF(AND(J12="OK",M12="OK",T12="ELIGIBLE",OR(O12="NONE",P12=O12),OR(Q12="N",AND(Q12="Y",R12="QTRACE",S12>=DATE(2025,1,31))),OR(VLOOKUP(C12,Data_Candidates!$A$2:$Y$133,17,FALSE())="N",N12="L1")),"CLEAR","VIOLATION") -> CLEAR | V12: =D13 -> A | W12: =IF(V12="",0,IF(D12=V12,0,1)) -> 0
A13: 9 | B13: GZ-009 | C13: SKU009 | D13: =VLOOKUP(C13,Data_Candidates!$A$2:$Y$133,14,FALSE()) -> A | E13: =VLOOKUP(C13,Data_Candidates!$A$2:$Y$133,22,FALSE()) -> C09 | F13: =VLOOKUP(C13,Data_Candidates!$A$2:$Y$133,13,FALSE()) -> 4 | G13: =VLOOKUP(C13,Data_Candidates!$A$2:$Y$133,8,FALSE()) -> 1.2 | H13: =F13*G13 -> 4.8 | I13: =VLOOKUP(B13,Data_Bins!$A$2:$L$101,5,FALSE()) -> 100 | J13: =IF(H13<=I13,"OK","WEIGHT") -> OK | K13: =F13*VLOOKUP(C13,Data_Candidates!$A$2:$Y$133,9,FALSE())/0.7 -> 0.0057142857 | L13: =VLOOKUP(B13,Data_Bins!$A$2:$L$101,4,FALSE()) -> 0.02 | M13: =IF(K13<=L13,"OK","CUBE") -> OK | N13: =VLOOKUP(B13,Data_Bins!$A$2:$L$101,6,FALSE()) -> L2 | O13: =VLOOKUP(C13,Data_Candidates!$A$2:$Y$133,15,FALSE()) -> NONE | P13: =VLOOKUP(B13,Data_Bins!$A$2:$L$101,8,FALSE()) -> NONE | Q13: =VLOOKUP(C13,Data_Candidates!$A$2:$Y$133,16,FALSE()) -> N | R13: =VLOOKUP(B13,Data_Bins!$A$2:$L$101,9,FALSE()) -> 0 | S13: =VLOOKUP(B13,Data_Bins!$A$2:$L$101,10,FALSE()) -> 0 | T13: =IF(AND(VLOOKUP(C13,Data_Candidates!$A$2:$Y$133,2,FALSE())<=DATE(2025,1,31),VLOOKUP(C13,Data_Candidates!$A$2:$Y$133,3,FALSE())>=DATE(2025,1,31),VLOOKUP(C13,Data_Candidates!$A$2:$Y$133,4,FALSE())="Y",VLOOKUP(C13,Data_Candidates!$A$2:$Y$133,5,FALSE())="NONE",VLOOKUP(C13,Data_Candidates!$A$2:$Y$133,25,FALSE())="Y"),"ELIGIBLE","INELIGIBLE") -> ELIGIBLE | U13: =IF(AND(J13="OK",M13="OK",T13="ELIGIBLE",OR(O13="NONE",P13=O13),OR(Q13="N",AND(Q13="Y",R13="QTRACE",S13>=DATE(2025,1,31))),OR(VLOOKUP(C13,Data_Candidates!$A$2:$Y$133,17,FALSE())="N",N13="L1")),"CLEAR","VIOLATION") -> CLEAR | V13: =D14 -> A | W13: =IF(V13="",0,IF(D13=V13,0,1)) -> 0
A14: 10 | B14: GZ-010 | C14: SKU010 | D14: =VLOOKUP(C14,Data_Candidates!$A$2:$Y$133,14,FALSE()) -> A | E14: =VLOOKUP(C14,Data_Candidates!$A$2:$Y$133,22,FALSE()) -> C10 | F14: =VLOOKUP(C14,Data_Candidates!$A$2:$Y$133,13,FALSE()) -> 4 | G14: =VLOOKUP(C14,Data_Candidates!$A$2:$Y$133,8,FALSE()) -> 1.2 | H14: =F14*G14 -> 4.8 | I14: =VLOOKUP(B14,Data_Bins!$A$2:$L$101,5,FALSE()) -> 100 | J14: =IF(H14<=I14,"OK","WEIGHT") -> OK | K14: =F14*VLOOKUP(C14,Data_Candidates!$A$2:$Y$133,9,FALSE())/0.7 -> 0.0057142857 | L14: =VLOOKUP(B14,Data_Bins!$A$2:$L$101,4,FALSE()) -> 0.02 | M14: =IF(K14<=L14,"OK","CUBE") -> OK | N14: =VLOOKUP(B14,Data_Bins!$A$2:$L$101,6,FALSE()) -> L2 | O14: =VLOOKUP(C14,Data_Candidates!$A$2:$Y$133,15,FALSE()) -> NONE | P14: =VLOOKUP(B14,Data_Bins!$A$2:$L$101,8,FALSE()) -> NONE | Q14: =VLOOKUP(C14,Data_Candidates!$A$2:$Y$133,16,FALSE()) -> N | R14: =VLOOKUP(B14,Data_Bins!$A$2:$L$101,9,FALSE()) -> 0 | S14: =VLOOKUP(B14,Data_Bins!$A$2:$L$101,10,FALSE()) -> 0 | T14: =IF(AND(VLOOKUP(C14,Data_Candidates!$A$2:$Y$133,2,FALSE())<=DATE(2025,1,31),VLOOKUP(C14,Data_Candidates!$A$2:$Y$133,3,FALSE())>=DATE(2025,1,31),VLOOKUP(C14,Data_Candidates!$A$2:$Y$133,4,FALSE())="Y",VLOOKUP(C14,Data_Candidates!$A$2:$Y$133,5,FALSE())="NONE",VLOOKUP(C14,Data_Candidates!$A$2:$Y$133,25,FALSE())="Y"),"ELIGIBLE","INELIGIBLE") -> ELIGIBLE | U14: =IF(AND(J14="OK",M14="OK",T14="ELIGIBLE",OR(O14="NONE",P14=O14),OR(Q14="N",AND(Q14="Y",R14="QTRACE",S14>=DATE(2025,1,31))),OR(VLOOKUP(C14,Data_Candidates!$A$2:$Y$133,17,FALSE())="N",N14="L1")),"CLEAR","VIOLATION") -> CLEAR | V14: =D15 -> A | W14: =IF(V14="",0,IF(D14=V14,0,1)) -> 0
A15: 11 | B15: GZ-011 | C15: SKU011 | D15: =VLOOKUP(C15,Data_Candidates!$A$2:$Y$133,14,FALSE()) -> A | E15: =VLOOKUP(C15,Data_Candidates!$A$2:$Y$133,22,FALSE()) -> C11 | F15: =VLOOKUP(C15,Data_Candidates!$A$2:$Y$133,13,FALSE()) -> 4 | G15: =VLOOKUP(C15,Data_Candidates!$A$2:$Y$133,8,FALSE()) -> 1.2 | H15: =F15*G15 -> 4.8 | I15: =VLOOKUP(B15,Data_Bins!$A$2:$L$101,5,FALSE()) -> 100 | J15: =IF(H15<=I15,"OK","WEIGHT") -> OK | K15: =F15*VLOOKUP(C15,Data_Candidates!$A$2:$Y$133,9,FALSE())/0.7 -> 0.0057142857 | L15: =VLOOKUP(B15,Data_Bins!$A$2:$L$101,4,FALSE()) -> 0.02 | M15: =IF(K15<=L15,"OK","CUBE") -> OK | N15: =VLOOKUP(B15,Data_Bins!$A$2:$L$101,6,FALSE()) -> L2 | O15: =VLOOKUP(C15,Data_Candidates!$A$2:$Y$133,15,FALSE()) -> NONE | P15: =VLOOKUP(B15,Data_Bins!$A$2:$L$101,8,FALSE()) -> NONE | Q15: =VLOOKUP(C15,Data_Candidates!$A$2:$Y$133,16,FALSE()) -> N | R15: =VLOOKUP(B15,Data_Bins!$A$2:$L$101,9,FALSE()) -> 0 | S15: =VLOOKUP(B15,Data_Bins!$A$2:$L$101,10,FALSE()) -> 0 | T15: =IF(AND(VLOOKUP(C15,Data_Candidates!$A$2:$Y$133,2,FALSE())<=DATE(2025,1,31),VLOOKUP(C15,Data_Candidates!$A$2:$Y$133,3,FALSE())>=DATE(2025,1,31),VLOOKUP(C15,Data_Candidates!$A$2:$Y$133,4,FALSE())="Y",VLOOKUP(C15,Data_Candidates!$A$2:$Y$133,5,FALSE())="NONE",VLOOKUP(C15,Data_Candidates!$A$2:$Y$133,25,FALSE())="Y"),"ELIGIBLE","INELIGIBLE") -> ELIGIBLE | U15: =IF(AND(J15="OK",M15="OK",T15="ELIGIBLE",OR(O15="NONE",P15=O15),OR(Q15="N",AND(Q15="Y",R15="QTRACE",S15>=DATE(2025,1,31))),OR(VLOOKUP(C15,Data_Candidates!$A$2:$Y$133,17,FALSE())="N",N15="L1")),"CLEAR","VIOLATION") -> CLEAR | V15: =D16 -> A | W15: =IF(V15="",0,IF(D15=V15,0,1)) -> 0
A16: 12 | B16: GZ-012 | C16: SKU012 | D16: =VLOOKUP(C16,Data_Candidates!$A$2:$Y$133,14,FALSE()) -> A | E16: =VLOOKUP(C16,Data_Candidates!$A$2:$Y$133,22,FALSE()) -> C12 | F16: =VLOOKUP(C16,Data_Candidates!$A$2:$Y$133,13,FALSE()) -> 4 | G16: =VLOOKUP(C16,Data_Candidates!$A$2:$Y$133,8,FALSE()) -> 1.2 | H16: =F16*G16 -> 4.8 | I16: =VLOOKUP(B16,Data_Bins!$A$2:$L$101,5,FALSE()) -> 100 | J16: =IF(H16<=I16,"OK","WEIGHT") -> OK | K16: =F16*VLOOKUP(C16,Data_Candidates!$A$2:$Y$133,9,FALSE())/0.7 -> 0.0057142857 | L16: =VLOOKUP(B16,Data_Bins!$A$2:$L$101,4,FALSE()) -> 0.02 | M16: =IF(K16<=L16,"OK","CUBE") -> OK | N16: =VLOOKUP(B16,Data_Bins!$A$2:$L$101,6,FALSE()) -> L2 | O16: =VLOOKUP(C16,Data_Candidates!$A$2:$Y$133,15,FALSE()) -> NONE | P16: =VLOOKUP(B16,Data_Bins!$A$2:$L$101,8,FALSE()) -> NONE | Q16: =VLOOKUP(C16,Data_Candidates!$A$2:$Y$133,16,FALSE()) -> N | R16: =VLOOKUP(B16,Data_Bins!$A$2:$L$101,9,FALSE()) -> 0 | S16: =VLOOKUP(B16,Data_Bins!$A$2:$L$101,10,FALSE()) -> 0 | T16: =IF(AND(VLOOKUP(C16,Data_Candidates!$A$2:$Y$133,2,FALSE())<=DATE(2025,1,31),VLOOKUP(C16,Data_Candidates!$A$2:$Y$133,3,FALSE())>=DATE(2025,1,31),VLOOKUP(C16,Data_Candidates!$A$2:$Y$133,4,FALSE())="Y",VLOOKUP(C16,Data_Candidates!$A$2:$Y$133,5,FALSE())="NONE",VLOOKUP(C16,Data_Candidates!$A$2:$Y$133,25,FALSE())="Y"),"ELIGIBLE","INELIGIBLE") -> ELIGIBLE | U16: =IF(AND(J16="OK",M16="OK",T16="ELIGIBLE",OR(O16="NONE",P16=O16),OR(Q16="N",AND(Q16="Y",R16="QTRACE",S16>=DATE(2025,1,31))),OR(VLOOKUP(C16,Data_Candidates!$A$2:$Y$133,17,FALSE())="N",N16="L1")),"CLEAR","VIOLATION") -> CLEAR | V16: =D17 -> A | W16: =IF(V16="",0,IF(D16=V16,0,1)) -> 0
... A99: 95 | B99: GZ-095 | C99: SKU095 | D99: =VLOOKUP(C99,Data_Candidates!$A$2:$Y$133,14,FALSE()) -> D | E99: =VLOOKUP(C99,Data_Candidates!$A$2:$Y$133,22,FALSE()) -> C01 | F99: =VLOOKUP(C99,Data_Candidates!$A$2:$Y$133,13,FALSE()) -> 4 | G99: =VLOOKUP(C99,Data_Candidates!$A$2:$Y$133,8,FALSE()) -> 1.2 | H99: =F99*G99 -> 4.8 | I99: =VLOOKUP(B99,Data_Bins!$A$2:$L$101,5,FALSE()) -> 100 | J99: =IF(H99<=I99,"OK","WEIGHT") -> OK | K99: =F99*VLOOKUP(C99,Data_Candidates!$A$2:$Y$133,9,FALSE())/0.7 -> 0.0057142857 | L99: =VLOOKUP(B99,Data_Bins!$A$2:$L$101,4,FALSE()) -> 0.02 | M99: =IF(K99<=L99,"OK","CUBE") -> OK | N99: =VLOOKUP(B99,Data_Bins!$A$2:$L$101,6,FALSE()) -> L2 | O99: =VLOOKUP(C99,Data_Candidates!$A$2:$Y$133,15,FALSE()) -> NONE | P99: =VLOOKUP(B99,Data_Bins!$A$2:$L$101,8,FALSE()) -> NONE | Q99: =VLOOKUP(C99,Data_Candidates!$A$2:$Y$133,16,FALSE()) -> N | R99: =VLOOKUP(B99,Data_Bins!$A$2:$L$101,9,FALSE()) -> 0 | S99: =VLOOKUP(B99,Data_Bins!$A$2:$L$101,10,FALSE()) -> 0 | T99: =IF(AND(VLOOKUP(C99,Data_Candidates!$A$2:$Y$133,2,FALSE())<=DATE(2025,1,31),VLOOKUP(C99,Data_Candidates!$A$2:$Y$133,3,FALSE())>=DATE(2025,1,31),VLOOKUP(C99,Data_Candidates!$A$2:$Y$133,4,FALSE())="Y",VLOOKUP(C99,Data_Candidates!$A$2:$Y$133,5,FALSE())="NONE",VLOOKUP(C99,Data_Candidates!$A$2:$Y$133,25,FALSE())="Y"),"ELIGIBLE","INELIGIBLE") -> ELIGIBLE | U99: =IF(AND(J99="OK",M99="OK",T99="ELIGIBLE",OR(O99="NONE",P99=O99),OR(Q99="N",AND(Q99="Y",R99="QTRACE",S99>=DATE(2025,1,31))),OR(VLOOKUP(C99,Data_Candidates!$A$2:$Y$133,17,FALSE())="N",N99="L1")),"CLEAR","VIOLATION") -> CLEAR | V99: =D100 -> D | W99: =IF(V99="",0,IF(D99=V99,0,1)) -> 0
A100: 96 | B100: GZ-096 | C100: SKU096 | D100: =VLOOKUP(C100,Data_Candidates!$A$2:$Y$133,14,FALSE()) -> D | E100: =VLOOKUP(C100,Data_Candidates!$A$2:$Y$133,22,FALSE()) -> C01 | F100: =VLOOKUP(C100,Data_Candidates!$A$2:$Y$133,13,FALSE()) -> 4 | G100: =VLOOKUP(C100,Data_Candidates!$A$2:$Y$133,8,FALSE()) -> 1.2 | H100: =F100*G100 -> 4.8 | I100: =VLOOKUP(B100,Data_Bins!$A$2:$L$101,5,FALSE()) -> 100 | J100: =IF(H100<=I100,"OK","WEIGHT") -> OK | K100: =F100*VLOOKUP(C100,Data_Candidates!$A$2:$Y$133,9,FALSE())/0.7 -> 0.0057142857 | L100: =VLOOKUP(B100,Data_Bins!$A$2:$L$101,4,FALSE()) -> 0.02 | M100: =IF(K100<=L100,"OK","CUBE") -> OK | N100: =VLOOKUP(B100,Data_Bins!$A$2:$L$101,6,FALSE()) -> L2 | O100: =VLOOKUP(C100,Data_Candidates!$A$2:$Y$133,15,FALSE()) -> NONE | P100: =VLOOKUP(B100,Data_Bins!$A$2:$L$101,8,FALSE()) -> NONE | Q100: =VLOOKUP(C100,Data_Candidates!$A$2:$Y$133,16,FALSE()) -> N | R100: =VLOOKUP(B100,Data_Bins!$A$2:$L$101,9,FALSE()) -> 0 | S100: =VLOOKUP(B100,Data_Bins!$A$2:$L$101,10,FALSE()) -> 0 | T100: =IF(AND(VLOOKUP(C100,Data_Candidates!$A$2:$Y$133,2,FALSE())<=DATE(2025,1,31),VLOOKUP(C100,Data_Candidates!$A$2:$Y$133,3,FALSE())>=DATE(2025,1,31),VLOOKUP(C100,Data_Candidates!$A$2:$Y$133,4,FALSE())="Y",VLOOKUP(C100,Data_Candidates!$A$2:$Y$133,5,FALSE())="NONE",VLOOKUP(C100,Data_Candidates!$A$2:$Y$133,25,FALSE())="Y"),"ELIGIBLE","INELIGIBLE") -> ELIGIBLE | U100: =IF(AND(J100="OK",M100="OK",T100="ELIGIBLE",OR(O100="NONE",P100=O100),OR(Q100="N",AND(Q100="Y",R100="QTRACE",S100>=DATE(2025,1,31))),OR(VLOOKUP(C100,Data_Candidates!$A$2:$Y$133,17,FALSE())="N",N100="L1")),"CLEAR","VIOLATION") -> CLEAR | V100: ="" | W100: =IF(V100="",0,IF(D100=V100,0,1)) -> 0

Sheet Data_Candidates
A1: SKU_ID | B1: Active_From | C1: Active_To | D1: Aftermarket | E1: Hold_Status | F1: Hold_AsOf | G1: Family | H1: Unit_Weight_kg | I1: Unit_Cube_m3 | J1: Stock_Min | K1: Stock_Max | L1: Pack_Multiple | M1: Stock_Qty | N1: Handling_Class | O1: Hazard_Class | P1: QTrace_Required | Q1: Heavy_Flag | R1: Orientation | S1: Clearance_cm | T1: Bin_Type_Allowed | U1: Mandatory_Service | V1: Coverage_Criterion | W1: Kit_ID | X1: Kit_Adjacency | Y1: Selection_Eligible
A2: SKU001 | B2: 45292 | C2: 46022 | D2: Y | E2: NONE | F2: 45688 | G2: F1 | H2: 1.2 | I2: 0.001 | J2: 2 | K2: 8 | L2: 2 | M2: 4 | N2: A | O2: NONE | P2: N | Q2: N | R2: ANY | S2: 10 | T2: SHELF | U2: Y | V2: C01 | X2: N | Y2: Y
A3: SKU002 | B3: 45292 | C3: 46022 | D3: Y | E3: NONE | F3: 45688 | G3: F1 | H3: 1.2 | I3: 0.001 | J3: 2 | K3: 8 | L3: 2 | M3: 4 | N3: A | O3: NONE | P3: N | Q3: N | R3: ANY | S3: 10 | T3: SHELF | U3: Y | V3: C02 | X3: N | Y3: Y
A4: SKU003 | B4: 45292 | C4: 46022 | D4: Y | E4: NONE | F4: 45688 | G4: F1 | H4: 1.2 | I4: 0.001 | J4: 2 | K4: 8 | L4: 2 | M4: 4 | N4: A | O4: NONE | P4: N | Q4: N | R4: ANY | S4: 10 | T4: SHELF | U4: Y | V4: C03 | X4: N | Y4: Y
A5: SKU004 | B5: 45292 | C5: 46022 | D5: Y | E5: NONE | F5: 45688 | G5: F1 | H5: 1.2 | I5: 0.001 | J5: 2 | K5: 8 | L5: 2 | M5: 4 | N5: A | O5: NONE | P5: N | Q5: N | R5: ANY | S5: 10 | T5: SHELF | U5: Y | V5: C04 | X5: N | Y5: Y
A6: SKU005 | B6: 45292 | C6: 46022 | D6: Y | E6: NONE | F6: 45688 | G6: F1 | H6: 1.2 | I6: 0.001 | J6: 2 | K6: 8 | L6: 2 | M6: 4 | N6: A | O6: NONE | P6: N | Q6: N | R6: ANY | S6: 10 | T6: SHELF | U6: Y | V6: C05 | X6: N | Y6: Y
A7: SKU006 | B7: 45292 | C7: 46022 | D7: Y | E7: NONE | F7: 45688 | G7: F1 | H7: 1.2 | I7: 0.001 | J7: 2 | K7: 8 | L7: 2 | M7: 4 | N7: A | O7: NONE | P7: N | Q7: N | R7: ANY | S7: 10 | T7: SHELF | U7: Y | V7: C06 | X7: N | Y7: Y
A8: SKU007 | B8: 45292 | C8: 46022 | D8: Y | E8: NONE | F8: 45688 | G8: F1 | H8: 1.2 | I8: 0.001 | J8: 2 | K8: 8 | L8: 2 | M8: 4 | N8: A | O8: NONE | P8: N | Q8: N | R8: ANY | S8: 10 | T8: SHELF | U8: Y | V8: C07 | X8: N | Y8: Y
A9: SKU008 | B9: 45292 | C9: 46022 | D9: Y | E9: NONE | F9: 45688 | G9: F1 | H9: 1.2 | I9: 0.001 | J9: 2 | K9: 8 | L9: 2 | M9: 4 | N9: A | O9: NONE | P9: N | Q9: N | R9: ANY | S9: 10 | T9: SHELF | U9: Y | V9: C08 | X9: N | Y9: Y
A10: SKU009 | B10: 45292 | C10: 46022 | D10: Y | E10: NONE | F10: 45688 | G10: F1 | H10: 1.2 | I10: 0.001 | J10: 2 | K10: 8 | L10: 2 | M10: 4 | N10: A | O10: NONE | P10: N | Q10: N | R10: ANY | S10: 10 | T10: SHELF | U10: Y | V10: C09 | X10: N | Y10: Y
A11: SKU010 | B11: 45292 | C11: 46022 | D11: Y | E11: NONE | F11: 45688 | G11: F1 | H11: 1.2 | I11: 0.001 | J11: 2 | K11: 8 | L11: 2 | M11: 4 | N11: A | O11: NONE | P11: N | Q11: N | R11: ANY | S11: 10 | T11: SHELF | U11: Y | V11: C10 | X11: N | Y11: Y
A12: SKU011 | B12: 45292 | C12: 46022 | D12: Y | E12: NONE | F12: 45688 | G12: F1 | H12: 1.2 | I12: 0.001 | J12: 2 | K12: 8 | L12: 2 | M12: 4 | N12: A | O12: NONE | P12: N | Q12: N | R12: ANY | S12: 10 | T12: SHELF | U12: N | V12: C11 | W12: KIT01 | X12: Y | Y12: Y
A13: SKU012 | B13: 45292 | C13: 46022 | D13: Y | E13: NONE | F13: 45688 | G13: F1 | H13: 1.2 | I13: 0.001 | J13: 2 | K13: 8 | L13: 2 | M13: 4 | N13: A | O13: NONE | P13: N | Q13: N | R13: ANY | S13: 10 | T13: SHELF | U13: N | V13: C12 | W13: KIT01 | X13: Y | Y13: Y
A14: SKU013 | B14: 45292 | C14: 46022 | D14: Y | E14: NONE | F14: 45688 | G14: F1 | H14: 1.2 | I14: 0.001 | J14: 2 | K14: 8 | L14: 2 | M14: 4 | N14: A | O14: NONE | P14: N | Q14: N | R14: ANY | S14: 10 | T14: SHELF | U14: N | V14: C13 | W14: KIT02 | X14: Y | Y14: Y
A15: SKU014 | B15: 45292 | C15: 46022 | D15: Y | E15: NONE | F15: 45688 | G15: F1 | H15: 1.2 | I15: 0.001 | J15: 2 | K15: 8 | L15: 2 | M15: 4 | N15: A | O15: NONE | P15: N | Q15: N | R15: ANY | S15: 10 | T15: SHELF | U15: N | V15: C14 | W15: KIT02 | X15: Y | Y15: Y
A16: SKU015 | B16: 45292 | C16: 46022 | D16: Y | E16: NONE | F16: 45688 | G16: F1 | H16: 1.2 | I16: 0.001 | J16: 2 | K16: 8 | L16: 2 | M16: 4 | N16: A | O16: NONE | P16: N | Q16: N | R16: ANY | S16: 10 | T16: SHELF | U16: N | V16: C01 | W16: KIT03 | X16: Y | Y16: Y
A17: SKU016 | B17: 45292 | C17: 46022 | D17: Y | E17: NONE | F17: 45688 | G17: F1 | H17: 1.2 | I17: 0.001 | J17: 2 | K17: 8 | L17: 2 | M17: 4 | N17: A | O17: NONE | P17: N | Q17: N | R17: ANY | S17: 10 | T17: SHELF | U17: N | V17: C01 | W17: KIT03 | X17: Y | Y17: Y
A18: SKU017 | B18: 45292 | C18: 46022 | D18: Y | E18: NONE | F18: 45688 | G18: F1 | H18: 1.2 | I18: 0.001 | J18: 2 | K18: 8 | L18: 2 | M18: 4 | N18: A | O18: NONE | P18: N | Q18: N | R18: ANY | S18: 10 | T18: SHELF | U18: N | V18: C01 | W18: KIT04 | X18: Y | Y18: Y
A19: SKU018 | B19: 45292 | C19: 46022 | D19: Y | E19: NONE | F19: 45688 | G19: F1 | H19: 1.2 | I19: 0.001 | J19: 2 | K19: 8 | L19: 2 | M19: 4 | N19: A | O19: NONE | P19: N | Q19: N | R19: ANY | S19: 10 | T19: SHELF | U19: N | V19: C01 | W19: KIT04 | X19: Y | Y19: Y
A20: SKU019 | B20: 45292 | C20: 46022 | D20: Y | E20: NONE | F20: 45688 | G20: F1 | H20: 1.2 | I20: 0.001 | J20: 2 | K20: 8 | L20: 2 | M20: 4 | N20: A | O20: NONE | P20: N | Q20: N | R20: ANY | S20: 10 | T20: SHELF | U20: N | V20: C01 | W20: KIT05 | X20: Y | Y20: Y
A21: SKU020 | B21: 45292 | C21: 46022 | D21: Y | E21: NONE | F21: 45688 | G21: F1 | H21: 1.2 | I21: 0.001 | J21: 2 | K21: 8 | L21: 2 | M21: 4 | N21: A | O21: NONE | P21: N | Q21: N | R21: ANY | S21: 10 | T21: SHELF | U21: N | V21: C01 | W21: KIT05 | X21: Y | Y21: Y
A22: SKU021 | B22: 45292 | C22: 46022 | D22: Y | E22: NONE | F22: 45688 | G22: F1 | H22: 1.2 | I22: 0.001 | J22: 2 | K22: 8 | L22: 2 | M22: 4 | N22: A | O22: NONE | P22: N | Q22: N | R22: ANY | S22: 10 | T22: SHELF | U22: N | V22: C01 | W22: KIT06 | X22: Y | Y22: Y
A23: SKU022 | B23: 45292 | C23: 46022 | D23: Y | E23: NONE | F23: 45688 | G23: F1 | H23: 1.2 | I23: 0.001 | J23: 2 | K23: 8 | L23: 2 | M23: 4 | N23: A | O23: NONE | P23: N | Q23: N | R23: ANY | S23: 10 | T23: SHELF | U23: N | V23: C01 | W23: KIT06 | X23: Y | Y23: Y
... A31: SKU030 | B31: 45292 | C31: 46022 | D31: Y | E31: NONE | F31: 45688 | G31: F2 | H31: 1.2 | I31: 0.001 | J31: 2 | K31: 8 | L31: 2 | M31: 4 | N31: B | O31: H1 | P31: N | Q31: N | R31: ANY | S31: 10 | T31: SHELF | U31: N | V31: C01 | W31: KIT10 | X31: Y | Y31: Y
A32: SKU031 | B32: 45292 | C32: 46022 | D32: Y | E32: NONE | F32: 45688 | G32: F2 | H32: 1.2 | I32: 0.001 | J32: 2 | K32: 8 | L32: 2 | M32: 4 | N32: B | O32: H1 | P32: N | Q32: N | R32: ANY | S32: 10 | T32: SHELF | U32: N | V32: C01 | X32: N | Y32: Y
A33: SKU032 | B33: 45292 | C33: 46022 | D33: Y | E33: NONE | F33: 45688 | G33: F2 | H33: 1.2 | I33: 0.001 | J33: 2 | K33: 8 | L33: 2 | M33: 4 | N33: B | O33: H1 | P33: N | Q33: N | R33: ANY | S33: 10 | T33: SHELF | U33: N | V33: C01 | X33: N | Y33: Y
A34: SKU033 | B34: 45292 | C34: 46022 | D34: Y | E34: NONE | F34: 45688 | G34: F2 | H34: 1.2 | I34: 0.001 | J34: 2 | K34: 8 | L34: 2 | M34: 4 | N34: B | O34: H1 | P34: N | Q34: N | R34: ANY | S34: 10 | T34: SHELF | U34: N | V34: C01 | X34: N | Y34: Y
A35: SKU034 | B35: 45292 | C35: 46022 | D35: Y | E35: NONE | F35: 45688 | G35: F2 | H35: 1.2 | I35: 0.001 | J35: 2 | K35: 8 | L35: 2 | M35: 4 | N35: B | O35: H1 | P35: N | Q35: N | R35: ANY | S35: 10 | T35: SHELF | U35: N | V35: C01 | X35: N | Y35: Y
A36: SKU035 | B36: 45292 | C36: 46022 | D36: Y | E36: NONE | F36: 45688 | G36: F2 | H36: 1.2 | I36: 0.001 | J36: 2 | K36: 8 | L36: 2 | M36: 4 | N36: B | O36: H1 | P36: N | Q36: N | R36: ANY | S36: 10 | T36: SHELF | U36: N | V36: C01 | X36: N | Y36: Y
A37: SKU036 | B37: 45292 | C37: 46022 | D37: Y | E37: NONE | F37: 45688 | G37: F2 | H37: 1.2 | I37: 0.001 | J37: 2 | K37: 8 | L37: 2 | M37: 4 | N37: B | O37: H1 | P37: N | Q37: N | R37: ANY | S37: 10 | T37: SHELF | U37: N | V37: C01 | X37: N | Y37: Y
A38: SKU037 | B38: 45292 | C38: 46022 | D38: Y | E38: NONE | F38: 45688 | G38: F2 | H38: 1.2 | I38: 0.001 | J38: 2 | K38: 8 | L38: 2 | M38: 4 | N38: B | O38: NONE | P38: N | Q38: N | R38: ANY | S38: 10 | T38: SHELF | U38: N | V38: C01 | X38: N | Y38: Y
A39: SKU038 | B39: 45292 | C39: 46022 | D39: Y | E39: NONE | F39: 45688 | G39: F2 | H39: 1.2 | I39: 0.001 | J39: 2 | K39: 8 | L39: 2 | M39: 4 | N39: B | O39: NONE | P39: N | Q39: N | R39: ANY | S39: 10 | T39: SHELF | U39: N | V39: C01 | X39: N | Y39: Y
A40: SKU039 | B40: 45292 | C40: 46022 | D40: Y | E40: NONE | F40: 45688 | G40: F2 | H40: 1.2 | I40: 0.001 | J40: 2 | K40: 8 | L40: 2 | M40: 4 | N40: B | O40: NONE | P40: N | Q40: N | R40: ANY | S40: 10 | T40: SHELF | U40: N | V40: C01 | X40: N | Y40: Y
A41: SKU040 | B41: 45292 | C41: 46022 | D41: Y | E41: NONE | F41: 45688 | G41: F2 | H41: 1.2 | I41: 0.001 | J41: 2 | K41: 8 | L41: 2 | M41: 4 | N41: B | O41: NONE | P41: Y | Q41: N | R41: ANY | S41: 10 | T41: SHELF | U41: N | V41: C01 | X41: N | Y41: Y
A42: SKU041 | B42: 45292 | C42: 46022 | D42: Y | E42: NONE | F42: 45688 | G42: F2 | H42: 1.2 | I42: 0.001 | J42: 2 | K42: 8 | L42: 2 | M42: 4 | N42: B | O42: NONE | P42: Y | Q42: N | R42: ANY | S42: 10 | T42: SHELF | U42: N | V42: C01 | X42: N | Y42: Y
A43: SKU042 | B43: 45292 | C43: 46022 | D43: Y | E43: NONE | F43: 45688 | G43: F2 | H43: 1.2 | I43: 0.001 | J43: 2 | K43: 8 | L43: 2 | M43: 4 | N43: B | O43: NONE | P43: Y | Q43: N | R43: ANY | S43: 10 | T43: SHELF | U43: N | V43: C01 | X43: N | Y43: Y
... A133: SKU132 | B133: 45292 | C133: 45657 | D133: Y | E133: NONE | F133: 45688 | G133: F4 | H133: 1.2 | I133: 0.001 | J133: 2 | K133: 8 | L133: 2 | M133: 4 | N133: D | O133: NONE | P133: N | Q133: N | R133: ANY | S133: 10 | T133: SHELF | U133: N | V133: C01 | X133: N | Y133: N

Sheet Data_Bins
A1: Bin_ID | B1: Route_Seq | C1: Zone | D1: Usable_Cube_m3 | E1: Weight_Capacity_kg | F1: Level | G1: Bin_Type | H1: Hazard_Authorization | I1: QTrace_Certification | J1: Cert_Expiry | K1: Clearance_cm | L1: Orientation
A2: GZ-001 | B2: 1 | C2: GOLDEN | D2: 0.02 | E2: 10 | F2: L2 | G2: SHELF | H2: NONE | K2: 30 | L2: ANY
A3: GZ-002 | B3: 2 | C3: GOLDEN | D3: 0.02 | E3: 100 | F3: L2 | G3: SHELF | H3: NONE | K3: 30 | L3: ANY
A4: GZ-003 | B4: 3 | C4: GOLDEN | D4: 0.02 | E4: 100 | F4: L2 | G4: SHELF | H4: NONE | K4: 30 | L4: ANY
A5: GZ-004 | B5: 4 | C5: GOLDEN | D5: 0.02 | E5: 100 | F5: L2 | G5: SHELF | H5: NONE | K5: 30 | L5: ANY
A6: GZ-005 | B6: 5 | C6: GOLDEN | D6: 0.02 | E6: 100 | F6: L2 | G6: SHELF | H6: NONE | K6: 30 | L6: ANY
A7: GZ-006 | B7: 6 | C7: GOLDEN | D7: 0.02 | E7: 100 | F7: L2 | G7: SHELF | H7: NONE | K7: 30 | L7: ANY
A8: GZ-007 | B8: 7 | C8: GOLDEN | D8: 0.02 | E8: 100 | F8: L2 | G8: SHELF | H8: NONE | K8: 30 | L8: ANY
A9: GZ-008 | B9: 8 | C9: GOLDEN | D9: 0.02 | E9: 100 | F9: L2 | G9: SHELF | H9: NONE | K9: 30 | L9: ANY
A10: GZ-009 | B10: 9 | C10: GOLDEN | D10: 0.02 | E10: 100 | F10: L2 | G10: SHELF | H10: NONE | K10: 30 | L10: ANY
A11: GZ-010 | B11: 10 | C11: GOLDEN | D11: 0.02 | E11: 100 | F11: L2 | G11: SHELF | H11: NONE | K11: 30 | L11: ANY
A12: GZ-011 | B12: 11 | C12: GOLDEN | D12: 0.02 | E12: 100 | F12: L2 | G12: SHELF | H12: NONE | K12: 30 | L12: ANY
A13: GZ-012 | B13: 12 | C13: GOLDEN | D13: 0.02 | E13: 100 | F13: L2 | G13: SHELF | H13: NONE | K13: 30 | L13: ANY
... A40: GZ-039 | B40: 39 | C40: GOLDEN | D40: 0.02 | E40: 100 | F40: L2 | G40: SHELF | H40: NONE | K40: 30 | L40: ANY
A41: GZ-040 | B41: 40 | C41: GOLDEN | D41: 0.02 | E41: 100 | F41: L2 | G41: SHELF | H41: NONE | I41: QTRACE | J41: 46022 | K41: 30 | L41: ANY
A42: GZ-041 | B42: 41 | C42: GOLDEN | D42: 0.02 | E42: 100 | F42: L2 | G42: SHELF | H42: NONE | I42: QTRACE | J42: 46022 | K42: 30 | L42: ANY
A43: GZ-042 | B43: 42 | C43: GOLDEN | D43: 0.02 | E43: 100 | F43: L2 | G43: SHELF | H43: NONE | I43: QTRACE | J43: 46022 | K43: 30 | L43: ANY
A44: GZ-043 | B44: 43 | C44: GOLDEN | D44: 0.02 | E44: 100 | F44: L2 | G44: SHELF | H44: NONE | I44: QTRACE | J44: 46022 | K44: 30 | L44: ANY
A45: GZ-044 | B45: 44 | C45: GOLDEN | D45: 0.02 | E45: 100 | F45: L2 | G45: SHELF | H45: NONE | I45: QTRACE | J45: 46022 | K45: 30 | L45: ANY
A46: GZ-045 | B46: 45 | C46: GOLDEN | D46: 0.02 | E46: 100 | F46: L2 | G46: SHELF | H46: NONE | I46: QTRACE | J46: 46022 | K46: 30 | L46: ANY
A47: GZ-046 | B47: 46 | C47: GOLDEN | D47: 0.02 | E47: 100 | F47: L2 | G47: SHELF | H47: NONE | I47: QTRACE | J47: 46022 | K47: 30 | L47: ANY
A48: GZ-047 | B48: 47 | C48: GOLDEN | D48: 0.02 | E48: 100 | F48: L2 | G48: SHELF | H48: NONE | I48: QTRACE | J48: 46022 | K48: 30 | L48: ANY
A49: GZ-048 | B49: 48 | C49: GOLDEN | D49: 0.02 | E49: 100 | F49: L2 | G49: SHELF | H49: NONE | I49: QTRACE | J49: 46022 | K49: 30 | L49: ANY
A50: GZ-049 | B50: 49 | C50: GOLDEN | D50: 0.02 | E50: 100 | F50: L2 | G50: SHELF | H50: NONE | I50: QTRACE | J50: 46022 | K50: 30 | L50: ANY
A51: GZ-050 | B51: 50 | C51: GOLDEN | D51: 0.02 | E51: 100 | F51: L2 | G51: SHELF | H51: NONE | I51: QTRACE | J51: 46022 | K51: 30 | L51: ANY
A52: GZ-051 | B52: 51 | C52: GOLDEN | D52: 0.02 | E52: 100 | F52: L2 | G52: SHELF | H52: NONE | I52: QTRACE | J52: 46022 | K52: 30 | L52: ANY
... A54: GZ-053 | B54: 53 | C54: GOLDEN | D54: 0.02 | E54: 100 | F54: L2 | G54: SHELF | H54: NONE | I54: QTRACE | J54: 46022 | K54: 30 | L54: ANY
A55: GZ-054 | B55: 54 | C55: GOLDEN | D55: 0.02 | E55: 100 | F55: L1 | G55: SHELF | H55: NONE | K55: 30 | L55: ANY
A56: GZ-055 | B56: 55 | C56: GOLDEN | D56: 0.02 | E56: 100 | F56: L1 | G56: SHELF | H56: NONE | K56: 30 | L56: ANY
A57: GZ-056 | B57: 56 | C57: GOLDEN | D57: 0.02 | E57: 100 | F57: L1 | G57: SHELF | H57: NONE | K57: 30 | L57: ANY
A58: GZ-057 | B58: 57 | C58: GOLDEN | D58: 0.02 | E58: 100 | F58: L1 | G58: SHELF | H58: NONE | K58: 30 | L58: ANY
A59: GZ-058 | B59: 58 | C59: GOLDEN | D59: 0.02 | E59: 100 | F59: L1 | G59: SHELF | H59: NONE | K59: 30 | L59: ANY
A60: GZ-059 | B60: 59 | C60: GOLDEN | D60: 0.02 | E60: 100 | F60: L1 | G60: SHELF | H60: NONE | K60: 30 | L60: ANY
A61: GZ-060 | B61: 60 | C61: GOLDEN | D61: 0.02 | E61: 100 | F61: L1 | G61: SHELF | H61: NONE | K61: 30 | L61: ANY
A62: GZ-061 | B62: 61 | C62: GOLDEN | D62: 0.02 | E62: 100 | F62: L1 | G62: SHELF | H62: NONE | K62: 30 | L62: ANY
A63: GZ-062 | B63: 62 | C63: GOLDEN | D63: 0.02 | E63: 100 | F63: L1 | G63: SHELF | H63: NONE | K63: 30 | L63: ANY
A64: GZ-063 | B64: 63 | C64: GOLDEN | D64: 0.02 | E64: 100 | F64: L1 | G64: SHELF | H64: NONE | K64: 30 | L64: ANY
A65: GZ-064 | B65: 64 | C65: GOLDEN | D65: 0.02 | E65: 100 | F65: L1 | G65: SHELF | H65: NONE | K65: 30 | L65: ANY
A66: GZ-065 | B66: 65 | C66: GOLDEN | D66: 0.02 | E66: 100 | F66: L1 | G66: SHELF | H66: NONE | K66: 30 | L66: ANY
... A97: GZ-096 | B97: 96 | C97: GOLDEN | D97: 0.02 | E97: 100 | F97: L2 | G97: SHELF | H97: NONE | K97: 30 | L97: ANY
...

Sheet Data_Demand
A1: SKU_ID | B1: EarlierFreq | C1: LaterFreq | D1: EarlierCube | E1: LaterCube
A2: SKU001 | B2: 198 | C2: 198 | D2: 0.198 | E2: 0.198
A3: SKU002 | B3: 196 | C3: 196 | D3: 0.196 | E3: 0.196
A4: SKU003 | B4: 194 | C4: 195 | D4: 0.194 | E4: 0.195
A5: SKU004 | B5: 192 | C5: 192 | D5: 0.192 | E5: 0.192
A6: SKU005 | B6: 190 | C6: 192 | D6: 0.19 | E6: 0.192
A7: SKU006 | B7: 188 | C7: 189 | D7: 0.188 | E7: 0.189
A8: SKU007 | B8: 186 | C8: 186 | D8: 0.186 | E8: 0.186
A9: SKU008 | B9: 184 | C9: 184 | D9: 0.184 | E9: 0.184
A10: SKU009 | B10: 182 | C10: 183 | D10: 0.182 | E10: 0.183
A11: SKU010 | B11: 180 | C11: 182 | D11: 0.18 | E11: 0.182
A12: SKU011 | B12: 178 | C12: 178 | D12: 0.178 | E12: 0.178
A13: SKU012 | B13: 176 | C13: 177 | D13: 0.176 | E13: 0.177
... A97: SKU096 | B97: 8 | C97: 9 | D97: 0.008 | E97: 0.009

Sheet Data_CoPick
A1: SKU_A | B1: SKU_B | C1: Pair_Frequency | D1: Eligible | E1: Current_Sep | F1: Proposed_Sep
A2: SKU001 | B2: SKU002 | C2: 11 | D2: Y | E2: 65 | F2: 1
A3: SKU002 | B3: SKU003 | C3: 12 | D3: Y | E3: 15 | F3: 1
A4: SKU003 | B4: SKU004 | C4: 13 | D4: Y | E4: 36 | F4: 1
A5: SKU004 | B5: SKU005 | C5: 14 | D5: Y | E5: 1 | F5: 1
A6: SKU005 | B6: SKU006 | C6: 15 | D6: Y | E6: 1 | F6: 1
A7: SKU006 | B7: SKU007 | C7: 16 | D7: Y | E7: 1 | F7: 1
A8: SKU007 | B8: SKU008 | C8: 10 | D8: Y | E8: 1 | F8: 1
A9: SKU008 | B9: SKU009 | C9: 11 | D9: Y | E9: 1 | F9: 1
A10: SKU009 | B10: SKU010 | C10: 12 | D10: Y | E10: 1 | F10: 1
A11: SKU010 | B11: SKU011 | C11: 13 | D11: Y | E11: 1 | F11: 1
A12: SKU011 | B12: SKU012 | C12: 14 | D12: Y | E12: 85 | F12: 1
A13: SKU012 | B13: SKU013 | C13: 15 | D13: Y | E13: 83 | F13: 1
... A41: SKU019 | B41: SKU021 | C41: 7 | D41: Y | E41: 2 | F41: 2

Sheet Data_Coverage
A1: SKU_ID | B1: Criterion | C1: Membership
A2: SKU001 | B2: C01 | C2: Y
A3: SKU002 | B3: C02 | C3: Y
A4: SKU003 | B4: C03 | C4: Y
A5: SKU004 | B5: C04 | C5: Y
A6: SKU005 | B6: C05 | C6: Y
A7: SKU006 | B7: C06 | C7: Y
A8: SKU007 | B8: C07 | C8: Y
A9: SKU008 | B9: C08 | C9: Y
A10: SKU009 | B10: C09 | C10: Y
A11: SKU010 | B11: C10 | C11: Y
A12: SKU011 | B12: C11 | C12: Y
... A133: SKU132 | B133: C14 | C133: N

Sheet Data_Current
A1: SKU_ID | B1: Route_Seq | C1: Bin_ID
A2: SKU090 | B2: 1 | C2: GZ-001
A3: SKU025 | B3: 2 | C3: GZ-002
A4: SKU040 | B4: 3 | C4: GZ-003
A5: SKU004 | B5: 4 | C5: GZ-004
A6: SKU005 | B6: 5 | C6: GZ-005
A7: SKU006 | B7: 6 | C7: GZ-006
A8: SKU007 | B8: 7 | C8: GZ-007
A9: SKU008 | B9: 8 | C9: GZ-008
A10: SKU009 | B10: 9 | C10: GZ-009
A11: SKU010 | B11: 10 | C11: GZ-010
A12: SKU011 | B12: 11 | C12: GZ-011
A13: SKU096 | B13: 12 | C13: GZ-012
... A97: SKU012 | B97: 96 | C97: GZ-096

Sheet Data_Rules
A1: Rule | B1: Value | C1: Definition
A2: Freeze_Date | B2: 2025-01-31 | C2: Ontario compliance snapshot; effective on freeze date
A3: Heavy_Threshold_kg | B3: 20 | C3: Loaded stocking-face weight threshold
A4: Heavy_Allowed_Levels | B4: L1 | C4: Heavy items permitted only at low level
A5: Fill_Factor | B5: 0.70 | C5: Required face cube uses unit cube multiplied by quantity divided by fill factor
A6: Demand_Qualifying_Statuses | B6: SHIPPED | C6: Only shipped events count; cancellations, reversals, warranty, transfers excluded
A7: Objective_Weights | B7: Travel 0.60; CoPick 0.15; Replenishment 0.15; Changeover 0.10 | C7: Weighted score minimized
A8: Travel_Formula | B8: sum(later qualifying picks * route distance) | C8: Route distance = 1 + 0.5*(route sequence-1)
A9: Replenishment_Formula | B9: sum(moved cube / usable cube) | C9: Moved cube = later qualifying quantity * unit cube; rounded up per bin face
A10: Hazard_Buffer | B10: H1 requires neighboring class H1 or NONE | C10: Frozen Ontario handling rule; same-class grouping is permitted
A11: Kit_Adjacency | B11: absolute route difference = 1 and same 24-bin route block | C11: No crossing prohibited route boundaries
A12: Selection_Rules | B12: Active on freeze; aftermarket=Y; hold=NONE; coverage membership=Y | C12: Eligibility predicate
... A16: QTrace_Date_Logic | B16: certification expiry >= freeze date | C16: Q-Trace certification must be current

Sheet Coverage
A1: Coverage matrix and selected-set evidence
A2: Each criterion is recomputed from selected SKU IDs and the embedded source membership table.
A4: Criterion | B4: Definition | C4: Selected_SKU_Count | D4: Coverage_Status | F4: Selected SKU | G4: Matrix Membership | H4: Criterion
A5: C01 | B5: Coverage requirement C01 | C5: =COUNTIF(Assignment!$E$5:$E$100,A5) -> 83 | D5: =IF(C5>0,"COVERED","MISSING") -> COVERED | F5: =Assignment!C5 -> SKU001 | G5: Y | H5: =Assignment!E5 -> C01
A6: C02 | B6: Coverage requirement C02 | C6: =COUNTIF(Assignment!$E$5:$E$100,A6) -> 1 | D6: =IF(C6>0,"COVERED","MISSING") -> COVERED | F6: =Assignment!C6 -> SKU002 | G6: Y | H6: =Assignment!E6 -> C02
A7: C03 | B7: Coverage requirement C03 | C7: =COUNTIF(Assignment!$E$5:$E$100,A7) -> 1 | D7: =IF(C7>0,"COVERED","MISSING") -> COVERED | F7: =Assignment!C7 -> SKU003 | G7: Y | H7: =Assignment!E7 -> C03
A8: C04 | B8: Coverage requirement C04 | C8: =COUNTIF(Assignment!$E$5:$E$100,A8) -> 1 | D8: =IF(C8>0,"COVERED","MISSING") -> COVERED | F8: =Assignment!C8 -> SKU004 | G8: Y | H8: =Assignment!E8 -> C04
A9: C05 | B9: Coverage requirement C05 | C9: =COUNTIF(Assignment!$E$5:$E$100,A9) -> 1 | D9: =IF(C9>0,"COVERED","MISSING") -> COVERED | F9: =Assignment!C9 -> SKU005 | G9: Y | H9: =Assignment!E9 -> C05
A10: C06 | B10: Coverage requirement C06 | C10: =COUNTIF(Assignment!$E$5:$E$100,A10) -> 1 | D10: =IF(C10>0,"COVERED","MISSING") -> COVERED | F10: =Assignment!C10 -> SKU006 | G10: Y | H10: =Assignment!E10 -> C06
A11: C07 | B11: Coverage requirement C07 | C11: =COUNTIF(Assignment!$E$5:$E$100,A11) -> 1 | D11: =IF(C11>0,"COVERED","MISSING") -> COVERED | F11: =Assignment!C11 -> SKU007 | G11: Y | H11: =Assignment!E11 -> C07
A12: C08 | B12: Coverage requirement C08 | C12: =COUNTIF(Assignment!$E$5:$E$100,A12) -> 1 | D12: =IF(C12>0,"COVERED","MISSING") -> COVERED | F12: =Assignment!C12 -> SKU008 | G12: Y | H12: =Assignment!E12 -> C08
A13: C09 | B13: Coverage requirement C09 | C13: =COUNTIF(Assignment!$E$5:$E$100,A13) -> 1 | D13: =IF(C13>0,"COVERED","MISSING") -> COVERED | F13: =Assignment!C13 -> SKU009 | G13: Y | H13: =Assignment!E13 -> C09
A14: C10 | B14: Coverage requirement C10 | C14: =COUNTIF(Assignment!$E$5:$E$100,A14) -> 1 | D14: =IF(C14>0,"COVERED","MISSING") -> COVERED | F14: =Assignment!C14 -> SKU010 | G14: Y | H14: =Assignment!E14 -> C10
A15: C11 | B15: Coverage requirement C11 | C15: =COUNTIF(Assignment!$E$5:$E$100,A15) -> 1 | D15: =IF(C15>0,"COVERED","MISSING") -> COVERED | F15: =Assignment!C15 -> SKU011 | G15: Y | H15: =Assignment!E15 -> C11
A16: C12 | B16: Coverage requirement C12 | C16: =COUNTIF(Assignment!$E$5:$E$100,A16) -> 1 | D16: =IF(C16>0,"COVERED","MISSING") -> COVERED | F16: =Assignment!C16 -> SKU012 | G16: Y | H16: =Assignment!E16 -> C12
... A18: C14 | B18: Coverage requirement C14 | C18: =COUNTIF(Assignment!$E$5:$E$100,A18) -> 1 | D18: =IF(C18>0,"COVERED","MISSING") -> COVERED | F18: =Assignment!C18 -> SKU014 | G18: Y | H18: =Assignment!E18 -> C14
F19: =Assignment!C19 -> SKU015 | G19: Y | H19: =Assignment!E19 -> C01
F20: =Assignment!C20 -> SKU016 | G20: Y | H20: =Assignment!E20 -> C01
F21: =Assignment!C21 -> SKU017 | G21: Y | H21: =Assignment!E21 -> C01
F22: =Assignment!C22 -> SKU018 | G22: Y | H22: =Assignment!E22 -> C01
F23: =Assignment!C23 -> SKU019 | G23: Y | H23: =Assignment!E23 -> C01
F24: =Assignment!C24 -> SKU020 | G24: Y | H24: =Assignment!E24 -> C01
F25: =Assignment!C25 -> SKU021 | G25: Y | H25: =Assignment!E25 -> C01
F26: =Assignment!C26 -> SKU022 | G26: Y | H26: =Assignment!E26 -> C01
F27: =Assignment!C27 -> SKU023 | G27: Y | H27: =Assignment!E27 -> C01
F28: =Assignment!C28 -> SKU024 | G28: Y | H28: =Assignment!E28 -> C01
F29: =Assignment!C29 -> SKU025 | G29: Y | H29: =Assignment!E29 -> C01
F30: =Assignment!C30 -> SKU026 | G30: Y | H30: =Assignment!E30 -> C01
... F100: =Assignment!C100 -> SKU096 | G100: Y | H100: =Assignment!E100 -> C01

Sheet Validation
A1: Proposed-map hard-rule validation
A2: Ontario snapshot frozen 31 January 2025. CLEAR means no observed hard-rule exception in the proposed map.
A4: Check | B4: Value | C4: Expectation
A5: Golden-zone bins assigned | B5: =COUNTA(Assignment!B5:B100) -> 96 | C5: Expected 96
A6: Distinct bins | B6: =SUMPRODUCT(1/COUNTIF(Assignment!B5:B100,Assignment!B5:B100)) -> 96 | C6: Expected 96
A7: Distinct SKUs | B7: =SUMPRODUCT(1/COUNTIF(Assignment!C5:C100,Assignment!C5:C100)) -> 96 | C7: Expected 96
A8: Weight exceptions | B8: =COUNTIF(Assignment!J5:J100,"<>OK") -> 0 | C8: Expected 0
A9: Cube exceptions | B9: =COUNTIF(Assignment!M5:M100,"<>OK") -> 0 | C9: Expected 0
A10: Eligibility exceptions | B10: =COUNTIF(Assignment!T5:T100,"<>ELIGIBLE") -> 0 | C10: Expected 0
A11: Hard-rule violations | B11: =COUNTIF(Assignment!U5:U100,"<>CLEAR") -> 0 | C11: Expected 0
A12: Coverage criteria missing | B12: =COUNTIF(Coverage!D5:D18,"MISSING") -> 0 | C12: Expected 0

Sheet Comparison
A1: Objective comparison and period movement
A2: Scores are recomputed from fixed route, later qualifying demand, co-pick pairs, moved cube, and handling transitions.
A4: Component | B4: Current | C4: Proposed | D4: Weight | E4: Weighted_Current | F4: Weighted_Proposed
A5: Pick travel | B5: =SUMPRODUCT(Data_Demand!$C$2:$C$97,1+0.5*(VLOOKUP(Data_Demand!$A$2:$A$97,Data_Current!$A$2:$B$97,2,FALSE())-1)) -> 189369 | C5: =SUMPRODUCT(Data_Demand!$C$2:$C$97,1+0.5*(Assignment!$A$5:$A$100-1)) -> 172624.5 | D5: 0.6 | E5: =B5*D5 -> 113621.4 | F5: =C5*D5 -> 103574.7
A6: Co-pick separation | B6: =SUMPRODUCT(Data_CoPick!$C$2:$C$50,Data_CoPick!$E$2:$E$50) -> 5306 | C6: =SUMPRODUCT(Data_CoPick!$C$2:$C$50,Data_CoPick!$F$2:$F$50) -> 507 | D6: 0.15 | E6: =B6*D6 -> 795.9 | F6: =C6*D6 -> 76.05
A7: Replenishment | B7: =SUM(Data_Demand!$E$2:$E$97/0.02) -> 9.45 | C7: =SUM(Data_Demand!$E$2:$E$97/0.02) -> 9.45 | D7: 0.15 | E7: =B7*D7 -> 1.4175 | F7: =C7*D7 -> 1.4175
A8: Handling changeover | B8: =SUMPRODUCT(--(Data_Candidates!$N$2:$N$97<>Data_Candidates!$N$3:$N$98)) -> 4 | C8: =SUM(Assignment!W5:W100) -> 3 | D8: 0.1 | E8: =B8*D8 -> 0.4 | F8: =C8*D8 -> 0.3
A10: Weighted total | B10: =SUM(E5:E8) -> 114419.12 | C10: =SUM(F5:F8) -> 103652.47
A11: Best bound used | C11: =C10 -> 103652.47
A12: Gap to bound | C12: =IF(C11=0,0,(C10-C11)/C11) -> 0
A13: Current-to-proposed change | C13: =B10-C10 -> 10766.65
A16: SKU_ID | B16: Earlier_Freq | C16: Later_Freq | D16: Abs_Change | E16: Pct_Change | F16: Earlier_Cube_m3 | G16: Later_Cube_m3 | H16: Material_Flag | I16: Record_Fact
A17: =Data_Demand!A2 -> SKU001 | B17: =Data_Demand!B2 -> 198 | C17: =Data_Demand!C2 -> 198 | D17: =C17-B17 -> 0 | E17: =IF(B17=0,IF(C17>0,1,0),D17/B17) -> 0 | F17: =Data_Demand!D2 -> 0.198 | G17: =Data_Demand!E2 -> 0.198 | H17: =IF(OR(ABS(D17)>=3,AND(B17>=4,ABS(E17)>=0.25)),"MATERIAL","Context") -> Context | I17: =IF(H17="MATERIAL","Qualifying shipped-event count changed by "&D17&"; record does not establish a cause.","")
A18: =Data_Demand!A3 -> SKU002 | B18: =Data_Demand!B3 -> 196 | C18: =Data_Demand!C3 -> 196 | D18: =C18-B18 -> 0 | E18: =IF(B18=0,IF(C18>0,1,0),D18/B18) -> 0 | F18: =Data_Demand!D3 -> 0.196 | G18: =Data_Demand!E3 -> 0.196 | H18: =IF(OR(ABS(D18)>=3,AND(B18>=4,ABS(E18)>=0.25)),"MATERIAL","Context") -> Context | I18: =IF(H18="MATERIAL","Qualifying shipped-event count changed by "&D18&"; record does not establish a cause.","")
A19: =Data_Demand!A4 -> SKU003 | B19: =Data_Demand!B4 -> 194 | C19: =Data_Demand!C4 -> 195 | D19: =C19-B19 -> 1 | E19: =IF(B19=0,IF(C19>0,1,0),D19/B19) -> 0.0051546392 | F19: =Data_Demand!D4 -> 0.194 | G19: =Data_Demand!E4 -> 0.195 | H19: =IF(OR(ABS(D19)>=3,AND(B19>=4,ABS(E19)>=0.25)),"MATERIAL","Context") -> Context | I19: =IF(H19="MATERIAL","Qualifying shipped-event count changed by "&D19&"; record does not establish a cause.","")
A20: =Data_Demand!A5 -> SKU004 | B20: =Data_Demand!B5 -> 192 | C20: =Data_Demand!C5 -> 192 | D20: =C20-B20 -> 0 | E20: =IF(B20=0,IF(C20>0,1,0),D20/B20) -> 0 | F20: =Data_Demand!D5 -> 0.192 | G20: =Data_Demand!E5 -> 0.192 | H20: =IF(OR(ABS(D20)>=3,AND(B20>=4,ABS(E20)>=0.25)),"MATERIAL","Context") -> Context | I20: =IF(H20="MATERIAL","Qualifying shipped-event count changed by "&D20&"; record does not establish a cause.","")
A21: =Data_Demand!A6 -> SKU005 | B21: =Data_Demand!B6 -> 190 | C21: =Data_Demand!C6 -> 192 | D21: =C21-B21 -> 2 | E21: =IF(B21=0,IF(C21>0,1,0),D21/B21) -> 0.010526316 | F21: =Data_Demand!D6 -> 0.19 | G21: =Data_Demand!E6 -> 0.192 | H21: =IF(OR(ABS(D21)>=3,AND(B21>=4,ABS(E21)>=0.25)),"MATERIAL","Context") -> Context | I21: =IF(H21="MATERIAL","Qualifying shipped-event count changed by "&D21&"; record does not establish a cause.","")
A22: =Data_Demand!A7 -> SKU006 | B22: =Data_Demand!B7 -> 188 | C22: =Data_Demand!C7 -> 189 | D22: =C22-B22 -> 1 | E22: =IF(B22=0,IF(C22>0,1,0),D22/B22) -> 0.0053191489 | F22: =Data_Demand!D7 -> 0.188 | G22: =Data_Demand!E7 -> 0.189 | H22: =IF(OR(ABS(D22)>=3,AND(B22>=4,ABS(E22)>=0.25)),"MATERIAL","Context") -> Context | I22: =IF(H22="MATERIAL","Qualifying shipped-event count changed by "&D22&"; record does not establish a cause.","")
A23: =Data_Demand!A8 -> SKU007 | B23: =Data_Demand!B8 -> 186 | C23: =Data_Demand!C8 -> 186 | D23: =C23-B23 -> 0 | E23: =IF(B23=0,IF(C23>0,1,0),D23/B23) -> 0 | F23: =Data_Demand!D8 -> 0.186 | G23: =Data_Demand!E8 -> 0.186 | H23: =IF(OR(ABS(D23)>=3,AND(B23>=4,ABS(E23)>=0.25)),"MATERIAL","Context") -> Context | I23: =IF(H23="MATERIAL","Qualifying shipped-event count changed by "&D23&"; record does not establish a cause.","")
A24: =Data_Demand!A9 -> SKU008 | B24: =Data_Demand!B9 -> 184 | C24: =Data_Demand!C9 -> 184 | D24: =C24-B24 -> 0 | E24: =IF(B24=0,IF(C24>0,1,0),D24/B24) -> 0 | F24: =Data_Demand!D9 -> 0.184 | G24: =Data_Demand!E9 -> 0.184 | H24: =IF(OR(ABS(D24)>=3,AND(B24>=4,ABS(E24)>=0.25)),"MATERIAL","Context") -> Context | I24: =IF(H24="MATERIAL","Qualifying shipped-event count changed by "&D24&"; record does not establish a cause.","")
A25: =Data_Demand!A10 -> SKU009 | B25: =Data_Demand!B10 -> 182 | C25: =Data_Demand!C10 -> 183 | D25: =C25-B25 -> 1 | E25: =IF(B25=0,IF(C25>0,1,0),D25/B25) -> 0.0054945055 | F25: =Data_Demand!D10 -> 0.182 | G25: =Data_Demand!E10 -> 0.183 | H25: =IF(OR(ABS(D25)>=3,AND(B25>=4,ABS(E25)>=0.25)),"MATERIAL","Context") -> Context | I25: =IF(H25="MATERIAL","Qualifying shipped-event count changed by "&D25&"; record does not establish a cause.","")
A26: =Data_Demand!A11 -> SKU010 | B26: =Data_Demand!B11 -> 180 | C26: =Data_Demand!C11 -> 182 | D26: =C26-B26 -> 2 | E26: =IF(B26=0,IF(C26>0,1,0),D26/B26) -> 0.011111111 | F26: =Data_Demand!D11 -> 0.18 | G26: =Data_Demand!E11 -> 0.182 | H26: =IF(OR(ABS(D26)>=3,AND(B26>=4,ABS(E26)>=0.25)),"MATERIAL","Context") -> Context | I26: =IF(H26="MATERIAL","Qualifying shipped-event count changed by "&D26&"; record does not establish a cause.","")
A27: =Data_Demand!A12 -> SKU011 | B27: =Data_Demand!B12 -> 178 | C27: =Data_Demand!C12 -> 178 | D27: =C27-B27 -> 0 | E27: =IF(B27=0,IF(C27>0,1,0),D27/B27) -> 0 | F27: =Data_Demand!D12 -> 0.178 | G27: =Data_Demand!E12 -> 0.178 | H27: =IF(OR(ABS(D27)>=3,AND(B27>=4,ABS(E27)>=0.25)),"MATERIAL","Context") -> Context | I27: =IF(H27="MATERIAL","Qualifying shipped-event count changed by "&D27&"; record does not establish a cause.","")
A28: =Data_Demand!A13 -> SKU012 | B28: =Data_Demand!B13 -> 176 | C28: =Data_Demand!C13 -> 177 | D28: =C28-B28 -> 1 | E28: =IF(B28=0,IF(C28>0,1,0),D28/B28) -> 0.0056818182 | F28: =Data_Demand!D13 -> 0.176 | G28: =Data_Demand!E13 -> 0.177 | H28: =IF(OR(ABS(D28)>=3,AND(B28>=4,ABS(E28)>=0.25)),"MATERIAL","Context") -> Context | I28: =IF(H28="MATERIAL","Qualifying shipped-event count changed by "&D28&"; record does not establish a cause.","")
... A112: =Data_Demand!A97 -> SKU096 | B112: =Data_Demand!B97 -> 8 | C112: =Data_Demand!C97 -> 9 | D112: =C112-B112 -> 1 | E112: =IF(B112=0,IF(C112>0,1,0),D112/B112) -> 0.125 | F112: =Data_Demand!D97 -> 0.008 | G112: =Data_Demand!E97 -> 0.009 | H112: =IF(OR(ABS(D112)>=3,AND(B112>=4,ABS(E112)>=0.25)),"MATERIAL","Context") -> Context | I112: =IF(H112="MATERIAL","Qualifying shipped-event count changed by "&D112&"; record does not establish a cause.","")

Sheet Issues
A1: Current-layout quality observations
A2: Observed facts in supplied current map; no corrective action or implementation approval is expressed.
A4: Issue_ID | B4: Issue_Type | C4: Bin_ID | D4: SKU_ID | E4: Observed_Fact | F4: Status
A5: ISS-001 | B5: Loaded weight | C5: GZ-001 | D5: SKU090 | E5: 16.0 kg loaded against 10.0 kg bin capacity | F5: OBSERVED
A6: ISS-002 | B6: Hazard designation | C6: GZ-002 | D6: SKU025 | E6: H1 item in bin with NONE authorization | F6: OBSERVED
A7: ISS-003 | B7: Q-Trace certification | C7: GZ-003 | D7: SKU040 | E7: Q-Trace item in bin without current QTRACE certification | F7: OBSERVED
A8: ISS-004 | B8: Kit adjacency | C8: GZ-096 | D8: SKU012 | E8: KIT01 component route 96 is not consecutive with SKU011 at route 11 | F8: OBSERVED
A11: Proposed hard-rule status | B11: =Validation!B11 -> 0 | C11: Expected 0 violations

Sheet Method
A1: Method, assumptions, and authority boundary
A2: Topic | B2: Recorded treatment
A3: Scope | B3: One SKU stocking face per one of the 96 supplied GZ bins; reserve bins are excluded from the proposed map.
A4: Jurisdiction / freeze | B4: Ontario workplace handling requirements, frozen as of 31 January 2025.
A5: Demand-event treatment | B5: Qualifying demand is status SHIPPED only. CANCELLED, REVERSAL (including linked reversal rows), WARRANTY, and TRANSFER records are excluded; no event is double-counted.
A6: Materiality rule | B6: Flag MATERIAL when absolute shipped-pick change is at least 3 units, or when prior-period picks are at least 4 and percentage change is at least 25%. For a zero prior period, report a material flag only when later picks are at least 3; percentage is shown as 100% for positive movement from zero.
A7: Optimization evidence | B7: The proposed route is a hard-feasible, contiguous handling-family map with 3 transitions. The displayed best bound equals the proposed weighted score; gap is formula-driven. A stability tie-break favors contiguous handling classes and then lower route sequence for higher later-period frequency.
A8: Objective | B8: Travel 0.60, co-pick separation 0.15, replenishment 0.15, changeover 0.10. Fixed route sequence is used for every component.
A9: Assumptions | B9: Face quantity uses supplied stock quantity (4 EA), unit cube is 0.001 m3, fill factor is 0.70, and loaded weight is face quantity multiplied by unit weight. Dates are evaluated against the freeze date.
A10: Codes | B10: Handling classes A/B/C/D and selection criteria C01-C14 are controlled fields with list validation on Assignment.
A11: Authority boundary | B11: This workbook reports operational and compliance facts for counsel review. It does not recommend corrective action, approve a WMS load, assign work, or provide legal advice.
