Workbook

Sheet Executive Memo
A1: Bellhaven Manufacturing — Q3 2025 Operating Cash Placement Review
A2: To: Sofia Crowther, Controller | From: Noor Arriaga, Peatmoor Systems | Decision horizon: coming production quarter
A4: Recommendation | B4: Recommend the government money market fund for the coming quarter. This is a placement recommendation only; no trade instruction or provider outreach is requested.
A5: Why | B5: Government risk-adjusted quarterly income is $573,400, ranking first, versus prime $562,977 and ladder $553,673. Prime’s approved 4.51% yield leads government by 15 bps and ladder by 30 bps, but quantified current-regime exposure reverses the headline order. Government offers same-day redemption with next-business-day settlement, meeting the five-business-day payroll requirement. The ladder can meet timing only with active maturity alignment, an operational tradeoff.
A6: Prime exposure priced | B6: One payroll-week redemption is $8.640m. At the current 1.25% fee rate, one imposed-fee scenario loss is $108,000. Three imposed-fee events in 20 complete, comparable current-regime observations imply a soft 15.0% probability and $16,200 expected fee cost. A qualifying temporary restriction is separately modeled at 1.5 days × $186,000/day = $279,000 scenario loss. One qualifying gate in the same 20 observations implies a soft 5.0% probability and $13,950 expected gate cost. Total expected prime risk cost is $30,150.
A7: Decision sensitivity | B7: Risk-adjusted annualized yields are Prime 4.281%, Government 4.360%, Ladder 4.210%. Prime ceases to outperform government at a fee-event probability of 5.3%, holding the 5.0% gate assumption constant; observed fee probability is 15.0%.
A8: History and uncertainty | B8: Prime moved 4.28% → 4.45% → 4.51%; government moved 4.12% → 4.29% → 4.36% (the Q2 quote uses the supplied 429-bps rebate-adjusted override). The Q2 ladder quote is missing and excluded. The base rate excludes the pre-current incomplete observation and a provider test with no client redemption. The small, nonuniform history makes both probabilities soft decision assumptions, not robust forecasts. Scenario losses are one-event amounts; expected losses are probability-weighted costs.
A9: Validation before placement | B9: Sofia Crowther should validate the $8.640m payroll run, five-business-day access need, $186,000/day delay consequence, and 1.5-day gate assumption with Bellhaven payroll/treasury before the supplied placement deadline. Noor can then refresh the review; this memo does not claim validation has occurred.
A12: Prepared for internal quarterly review • Amounts rounded to nearest dollar; yields annualized.

Sheet Comparison
A1: Q3 2025 Decision Comparison
A2: Placement balance $52,750,000 | 91 days / 365 | recommendation: Government fund
A4: Alternative | B4: Current yield (annualized) | C4: Base quarterly income ($) | D4: Liquidity access | E4: Fees / restrictions | F4: Expected fee cost ($) | G4: Expected gate cost ($) | H4: Risk-adjusted income ($) | I4: Risk-adjusted yield | J4: Rank
A5: Institutional prime money market fund | B5: =Support!D22 -> 0.0451 | C5: =Support!E22 -> 593126.78 | D5: Same day; next-business-day settlement | E5: 1.25% fee trigger; temporary gate may apply | F5: =Support!C58 -> 16200 | G5: =Support!C62 -> 13950 | H5: =Support!C64 -> 562976.78 | I5: =Support!C65 -> 0.042807463 | J5: 2
A6: Government money market fund | B6: =Support!D23 -> 0.0436 | C6: =Support!E23 -> 573399.73 | D6: Same day; next-business-day settlement | E6: No supplied fee or gate term | F6: 0 | G6: 0 | H6: =Support!C66 -> 573399.73 | I6: =H6/Support!$B$5*Support!$B$8/Support!$B$7 -> 0.0436 | J6: 1
A7: Short Treasury-bill-and-repo ladder | B7: =Support!D24 -> 0.0421 | C7: =Support!E24 -> 553672.67 | D7: Maturity-aligned; active roll required | E7: Operational alignment tradeoff; no supplied fee | F7: 0 | G7: 0 | H7: =Support!C67 -> 553672.67 | I7: =H7/Support!$B$5*Support!$B$8/Support!$B$7 -> 0.0421 | J7: 3
A10: Historical normalized yields (annualized) and change
A11: Alternative | B11: Q1 2025 | C11: Q2 2025 | D11: Q3 2025 proposed | E11: Q1→Q2 (bps) | F11: Q2→Q3 (bps)
A12: Prime fund | B12: 0.0428 | C12: 0.0445 | D12: 0.0451 | E12: 0.0017 | F12: 0.0006
A13: Government fund | B13: 0.0412 | C13: 0.0429 | D13: 0.0436 | E13: 0.0017 | F13: 0.0007
A14: Bill-and-repo ladder | B14: 0.0398 | D14: 0.0421
A17: Prime spread: +15 bps vs government; +30 bps vs ladder
A18: Fee probability 15.0% (3/20); gate probability 5.0% (1/20). One-event losses: $108,000 fee; $279,000 gate. Expected costs shown separately above.

Sheet Support
A1: Support — transparent calculations, source labels, assumptions and exclusions
A3: Normalized inputs
A4: Input | B4: Value | C4: Unit / formula | D4: Source label / treatment
A5: Placement balance | B5: 52750000 | C5: USD | D5: Inputs!D34
A6: Payroll-week redemption | B6: 8640000 | C6: USD | D6: Inputs!D35; Notes override
A7: Quarter days | B7: 91 | C7: days | D7: Inputs!D39
A8: Day-count denominator | B8: 365 | C8: days | D8: Inputs!D40
A9: Fee rate | B9: 0.0125 | C9: decimal | D9: Inputs!B26 current regime
A10: Delay cost/day | B10: 186000 | C10: USD/day | D10: Inputs!D37
A11: Gate duration | B11: 1.5 | C11: days | D11: Inputs!D38
A14: Final normalized quotes and base income
A15: Period | B15: Alternative | C15: Final quote (bps) | D15: Annualized yield | E15: Base income formula / result | F15: Source / override
A16: Q1 2025 | B16: Prime | C16: 428 | D16: 0.0428 | E16: =IF(D16="","",$B$5*D16*$B$7/$B$8) -> 562878.63 | F16: Inputs!row 6
A17: Q1 2025 | B17: Government | C17: 412 | D17: 0.0412 | E17: =IF(D17="","",$B$5*D17*$B$7/$B$8) -> 541836.44 | F17: Inputs!row 7
A18: Q1 2025 | B18: Ladder | C18: 398 | D18: 0.0398 | E18: =IF(D18="","",$B$5*D18*$B$7/$B$8) -> 523424.52 | F18: Inputs!row 8
A19: Q2 2025 | B19: Prime | C19: 445 | D19: 0.0445 | E19: =IF(D19="","",$B$5*D19*$B$7/$B$8) -> 585235.96 | F19: Inputs!row 9
A20: Q2 2025 | B20: Government | C20: 429 | D20: 0.0429 | E20: =IF(D20="","",$B$5*D20*$B$7/$B$8) -> 564193.77 | F20: Inputs!row 10; note override
A21: Q2 2025 | B21: Ladder | E21: =IF(D21="","",$B$5*D21*$B$7/$B$8) | F21: Inputs!row 11; note
A22: Q3 2025 | B22: Prime | C22: 451 | D22: 0.0451 | E22: =IF(D22="","",$B$5*D22*$B$7/$B$8) -> 593126.78 | F22: approved close override
A23: Q3 2025 | B23: Government | C23: 436 | D23: 0.0436 | E23: =IF(D23="","",$B$5*D23*$B$7/$B$8) -> 573399.73 | F23: Inputs!row 13
A24: Q3 2025 | B24: Ladder | C24: 421 | D24: 0.0421 | E24: =IF(D24="","",$B$5*D24*$B$7/$B$8) -> 553672.67 | F24: Inputs!row 14
A27: Stress population and event classification
A28: Observation | B28: Date | C28: Regime | D28: Complete | E28: Client redemption | F28: Fee imposed | G28: Gate qualifying | H28: Included? | I28: Exclusion / source note
A29: CR-01 | B29: 45676 | C29: Current | D29: Yes | E29: Yes | F29: Yes | G29: No | H29: Yes | I29: Inputs!stress log
A30: CR-02 | B30: 45685 | C30: Current | D30: Yes | E30: Yes | F30: No | G30: No | H30: Yes | I30: Inputs!stress log
A31: CR-03 | B31: 45694 | C31: Current | D31: Yes | E31: Yes | F31: No | G31: No | H31: Yes | I31: Inputs!stress log
A32: CR-04 | B32: 45703 | C32: Current | D32: Yes | E32: Yes | F32: No | G32: No | H32: Yes | I32: Inputs!stress log
A33: CR-05 | B33: 45712 | C33: Current | D33: Yes | E33: Yes | F33: No | G33: No | H33: Yes | I33: Inputs!stress log
A34: CR-06 | B34: 45721 | C34: Current | D34: Yes | E34: Yes | F34: No | G34: No | H34: Yes | I34: Inputs!stress log
A35: CR-07 | B35: 45730 | C35: Current | D35: Yes | E35: Yes | F35: Yes | G35: Yes | H35: Yes | I35: Inputs!stress log
A36: CR-08 | B36: 45739 | C36: Current | D36: Yes | E36: Yes | F36: No | G36: No | H36: Yes | I36: Inputs!stress log
A37: CR-09 | B37: 45748 | C37: Current | D37: Yes | E37: Yes | F37: No | G37: No | H37: Yes | I37: Inputs!stress log
A38: CR-10 | B38: 45757 | C38: Current | D38: Yes | E38: Yes | F38: No | G38: No | H38: Yes | I38: Inputs!stress log
A39: CR-11 | B39: 45766 | C39: Current | D39: Yes | E39: Yes | F39: No | G39: No | H39: Yes | I39: Inputs!stress log
A40: CR-12 | B40: 45775 | C40: Current | D40: Yes | E40: Yes | F40: No | G40: No | H40: Yes | I40: Inputs!stress log
... A50: OLD-01 | B50: 45580 | C50: Pre-current | D50: No | E50: Yes | F50: Yes | G50: No | H50: No | I50: Older rule; incomplete loss amount and outside current regime.
A52: Risk calculations
A53: Metric | B53: Formula / inputs | C53: Result | D53: Interpretation
A54: Eligible observations | B54: =COUNTIF(H29:H50,"Yes") -> 20 | C54: =COUNTIF(H29:H50,"Yes") -> 20 | D54: Complete current-regime comparable observations; excludes provider test and pre-regime
A55: Fee events | B55: =COUNTIFS(H29:H50,"Yes",F29:F50,"Yes") -> 3 | C55: =COUNTIFS(H29:H50,"Yes",F29:F50,"Yes") -> 3 | D55: Policy-defined imposed fee
...
