Workbook

Sheet Duty Schedule
A1: Ballantyne Market Co-op | interim meat & seafood duty schedule
A2: Coverage: 06 Jul 2026 - 11 Oct 2026 (14 operational weeks) | H2: Prepared for 24 Jun board meeting
A4: Operational Week | B4: Duty ID | C4: Duty | D4: Workflow | E4: Owner | F4: Start | G4: Finish | H4: Hours | I4: Predecessor | J4: Handoff Evidence | K4: Backup or Escalation | L4: Compliance Status
A5: 46209 | B5: ORD_FORECAST | C5: Demand forecast | D5: Ordering | E5: Marisol Reyes | F5: 46209.333 | G5: 46209.417 | H5: =ROUND((G5-F5)*24,2) -> 2 | J5: Forecast workbook | K5: Amara Draganov | L5: =IF(AND(F5>=DATE(2026,7,6)+TIME(8,0,0),G5<=DATE(2026,7,6)+TIME(10,0,0),ABS(H5-2)<0.001,TRUE()),"COMPLIANT","EXCEPTION") -> COMPLIANT
A6: 46209 | B6: ORD_DRAFT | C6: Purchase-order draft | D6: Ordering | E6: Marisol Reyes | F6: 46209.417 | G6: 46209.542 | H6: =ROUND((G6-F6)*24,2) -> 3 | I6: ORD_FORECAST | J6: Draft PO | K6: Amara Draganov | L6: =IF(AND(F6>=DATE(2026,7,6)+TIME(10,0,0),G6<=DATE(2026,7,6)+TIME(13,0,0),ABS(H6-3)<0.001,AND(F6>=G5,F6-G5<=TIME(0,30,0))),"COMPLIANT","EXCEPTION") -> COMPLIANT
A7: 46209 | B7: ORD_HACCP | C7: HACCP order review | D7: Ordering | E7: Emeric Novak | F7: 46209.542 | G7: 46209.583 | H7: =ROUND((G7-F7)*24,2) -> 1 | I7: ORD_DRAFT | J7: HACCP initials | K7: NO QUALIFIED BACKUP — GM ESCALATION | L7: =IF(AND(F7>=DATE(2026,7,6)+TIME(13,0,0),G7<=DATE(2026,7,6)+TIME(14,0,0),ABS(H7-1)<0.001,AND(F7>=G6,F7-G6<=TIME(0,30,0))),"COMPLIANT","EXCEPTION") -> COMPLIANT
A8: 46209 | B8: ORD_RELEASE | C8: Vendor order release | D8: Ordering | E8: Marisol Reyes | F8: 46209.583 | G8: 46209.625 | H8: =ROUND((G8-F8)*24,2) -> 1 | I8: ORD_HACCP | J8: Vendor release confirmation | K8: NO QUALIFIED BACKUP — GM ESCALATION | L8: =IF(AND(F8>=DATE(2026,7,6)+TIME(14,0,0),G8<=DATE(2026,7,6)+TIME(15,0,0),ABS(H8-1)<0.001,AND(F8>=G7,F8-G7<=TIME(0,30,0))),"COMPLIANT","EXCEPTION") -> COMPLIANT
A9: 46209 | B9: RCV_VERIFY | C9: Delivery verification | D9: Receiving | E9: Yusuf Gasparyan | F9: 46212.25 | G9: 46212.333 | H9: =ROUND((G9-F9)*24,2) -> 2 | J9: Receiving log | K9: Emeric Novak | L9: =IF(AND(F9>=DATE(2026,7,9)+TIME(6,0,0),G9<=DATE(2026,7,9)+TIME(8,0,0),ABS(H9-2)<0.001,TRUE()),"COMPLIANT","EXCEPTION") -> COMPLIANT
A10: 46209 | B10: RCV_DISPOSITION | C10: HACCP disposition | D10: Receiving | E10: Emeric Novak | F10: 46212.333 | G10: 46212.375 | H10: =ROUND((G10-F10)*24,2) -> 1 | I10: RCV_VERIFY | J10: Disposition entry | K10: NO QUALIFIED BACKUP — GM ESCALATION | L10: =IF(AND(F10>=DATE(2026,7,9)+TIME(8,0,0),G10<=DATE(2026,7,9)+TIME(9,0,0),ABS(H10-1)<0.001,AND(F10>=G9,F10-G9<=TIME(0,30,0))),"COMPLIANT","EXCEPTION") -> COMPLIANT
A11: 46209 | B11: RCV_TRACE | C11: Lot traceability closeout | D11: Receiving | E11: Emeric Novak | F11: 46212.375 | G11: 46212.417 | H11: =ROUND((G11-F11)*24,2) -> 1 | I11: RCV_DISPOSITION | J11: Lot traceability closeout | K11: NO QUALIFIED BACKUP — GM ESCALATION | L11: =IF(AND(F11>=DATE(2026,7,9)+TIME(9,0,0),G11<=DATE(2026,7,9)+TIME(10,0,0),ABS(H11-1)<0.001,AND(F11>=G10,F11-G10<=TIME(0,30,0))),"COMPLIANT","EXCEPTION") -> COMPLIANT
A12: 46209 | B12: PROD_PLAN | C12: Production cut plan | D12: Production training | E12: Amara Draganov | F12: 46210.292 | G12: 46210.417 | H12: =ROUND((G12-F12)*24,2) -> 3 | J12: Cut plan | K12: NO QUALIFIED BACKUP — GM ESCALATION | L12: =IF(AND(F12>=DATE(2026,7,7)+TIME(7,0,0),G12<=DATE(2026,7,7)+TIME(10,0,0),ABS(H12-3)<0.001,TRUE()),"COMPLIANT","EXCEPTION") -> COMPLIANT
A13: 46209 | B13: PROD_DEMO | C13: Closing-crew demonstration | D13: Production training | E13: Amara Draganov | F13: 46210.417 | G13: 46210.458 | H13: =ROUND((G13-F13)*24,2) -> 1 | I13: PROD_PLAN | J13: Crew demonstration acknowledgment | K13: NO QUALIFIED BACKUP — GM ESCALATION | L13: =IF(AND(F13>=DATE(2026,7,7)+TIME(10,0,0),G13<=DATE(2026,7,7)+TIME(11,0,0),ABS(H13-1)<0.001,AND(F13>=G12,F13-G12<=TIME(0,30,0))),"COMPLIANT","EXCEPTION") -> COMPLIANT
A14: 46209 | B14: PROD_RECORD | C14: Competency record | D14: Production training | E14: Amara Draganov | F14: 46210.458 | G14: 46210.5 | H14: =ROUND((G14-F14)*24,2) -> 1 | I14: PROD_DEMO | J14: Competency record | K14: NO QUALIFIED BACKUP — GM ESCALATION | L14: =IF(AND(F14>=DATE(2026,7,7)+TIME(11,0,0),G14<=DATE(2026,7,7)+TIME(12,0,0),ABS(H14-1)<0.001,AND(F14>=G13,F14-G13<=TIME(0,30,0))),"COMPLIANT","EXCEPTION") -> COMPLIANT
A15: 46209 | B15: INV_COUNT | C15: Cycle count | D15: Inventory | E15: Yusuf Gasparyan | F15: 46211.292 | G15: 46211.417 | H15: =ROUND((G15-F15)*24,2) -> 3 | J15: Count sheet | K15: Marisol Reyes | L15: =IF(AND(F15>=DATE(2026,7,8)+TIME(7,0,0),G15<=DATE(2026,7,8)+TIME(10,0,0),ABS(H15-3)<0.001,TRUE()),"COMPLIANT","EXCEPTION") -> COMPLIANT
A16: 46209 | B16: INV_VARIANCE | C16: Variance review | D16: Inventory | E16: Yusuf Gasparyan | F16: 46211.417 | G16: 46211.5 | H16: =ROUND((G16-F16)*24,2) -> 2 | I16: INV_COUNT | J16: Variance log | K16: Marisol Reyes | L16: =IF(AND(F16>=DATE(2026,7,8)+TIME(10,0,0),G16<=DATE(2026,7,8)+TIME(12,0,0),ABS(H16-2)<0.001,AND(F16>=G15,F16-G15<=TIME(0,30,0))),"COMPLIANT","EXCEPTION") -> COMPLIANT
A17: 46209 | B17: INV_SHRINK | C17: Shrink brief | D17: Inventory | E17: Yusuf Gasparyan | F17: 46211.5 | G17: 46211.542 | H17: =ROUND((G17-F17)*24,2) -> 1 | I17: INV_VARIANCE | J17: Shrink brief acknowledgment | K17: Marisol Reyes | L17: =IF(AND(F17>=DATE(2026,7,8)+TIME(12,0,0),G17<=DATE(2026,7,8)+TIME(13,0,0),ABS(H17-1)<0.001,AND(F17>=G16,F17-G16<=TIME(0,30,0))),"COMPLIANT","EXCEPTION") -> COMPLIANT
A18: 46209 | B18: SAN_VERIFY | C18: Sanitation verification | D18: Sanitation | E18: Emeric Novak | F18: 46213.625 | G18: 46213.708 | H18: =ROUND((G18-F18)*24,2) -> 2 | J18: Sanitation verification log | K18: NO QUALIFIED BACKUP — GM ESCALATION | L18: =IF(AND(F18>=DATE(2026,7,10)+TIME(15,0,0),G18<=DATE(2026,7,10)+TIME(17,0,0),ABS(H18-2)<0.001,TRUE()),"COMPLIANT","EXCEPTION") -> COMPLIANT
A19: 46216 | B19: ORD_FORECAST | C19: Demand forecast | D19: Ordering | E19: Marisol Reyes | F19: 46216.333 | G19: 46216.417 | H19: =ROUND((G19-F19)*24,2) -> 2 | J19: Forecast workbook | K19: Amara Draganov | L19: =IF(AND(F19>=DATE(2026,7,13)+TIME(8,0,0),G19<=DATE(2026,7,13)+TIME(10,0,0),ABS(H19-2)<0.001,TRUE()),"COMPLIANT","EXCEPTION") -> COMPLIANT
A20: 46216 | B20: ORD_DRAFT | C20: Purchase-order draft | D20: Ordering | E20: Marisol Reyes | F20: 46216.417 | G20: 46216.542 | H20: =ROUND((G20-F20)*24,2) -> 3 | I20: ORD_FORECAST | J20: Draft PO | K20: Amara Draganov | L20: =IF(AND(F20>=DATE(2026,7,13)+TIME(10,0,0),G20<=DATE(2026,7,13)+TIME(13,0,0),ABS(H20-3)<0.001,AND(F20>=G19,F20-G19<=TIME(0,30,0))),"COMPLIANT","EXCEPTION") -> COMPLIANT
A21: 46216 | B21: ORD_HACCP | C21: HACCP order review | D21: Ordering | E21: Emeric Novak | F21: 46216.542 | G21: 46216.583 | H21: =ROUND((G21-F21)*24,2) -> 1 | I21: ORD_DRAFT | J21: HACCP initials | K21: NO QUALIFIED BACKUP — GM ESCALATION | L21: =IF(AND(F21>=DATE(2026,7,13)+TIME(13,0,0),G21<=DATE(2026,7,13)+TIME(14,0,0),ABS(H21-1)<0.001,AND(F21>=G20,F21-G20<=TIME(0,30,0))),"COMPLIANT","EXCEPTION") -> COMPLIANT
A22: 46216 | B22: ORD_RELEASE | C22: Vendor order release | D22: Ordering | E22: Marisol Reyes | F22: 46216.583 | G22: 46216.625 | H22: =ROUND((G22-F22)*24,2) -> 1 | I22: ORD_HACCP | J22: Vendor release confirmation | K22: NO QUALIFIED BACKUP — GM ESCALATION | L22: =IF(AND(F22>=DATE(2026,7,13)+TIME(14,0,0),G22<=DATE(2026,7,13)+TIME(15,0,0),ABS(H22-1)<0.001,AND(F22>=G21,F22-G21<=TIME(0,30,0))),"COMPLIANT","EXCEPTION") -> COMPLIANT
A23: 46216 | B23: RCV_VERIFY | C23: Delivery verification | D23: Receiving | E23: Yusuf Gasparyan | F23: 46219.25 | G23: 46219.333 | H23: =ROUND((G23-F23)*24,2) -> 2 | J23: Receiving log | K23: Emeric Novak | L23: =IF(AND(F23>=DATE(2026,7,16)+TIME(6,0,0),G23<=DATE(2026,7,16)+TIME(8,0,0),ABS(H23-2)<0.001,TRUE()),"COMPLIANT","EXCEPTION") -> COMPLIANT
A24: 46216 | B24: RCV_DISPOSITION | C24: HACCP disposition | D24: Receiving | E24: Emeric Novak | F24: 46219.333 | G24: 46219.375 | H24: =ROUND((G24-F24)*24,2) -> 1 | I24: RCV_VERIFY | J24: Disposition entry | K24: NO QUALIFIED BACKUP — GM ESCALATION | L24: =IF(AND(F24>=DATE(2026,7,16)+TIME(8,0,0),G24<=DATE(2026,7,16)+TIME(9,0,0),ABS(H24-1)<0.001,AND(F24>=G23,F24-G23<=TIME(0,30,0))),"COMPLIANT","EXCEPTION") -> COMPLIANT
A25: 46216 | B25: RCV_TRACE | C25: Lot traceability closeout | D25: Receiving | E25: Emeric Novak | F25: 46219.375 | G25: 46219.417 | H25: =ROUND((G25-F25)*24,2) -> 1 | I25: RCV_DISPOSITION | J25: Lot traceability closeout | K25: NO QUALIFIED BACKUP — GM ESCALATION | L25: =IF(AND(F25>=DATE(2026,7,16)+TIME(9,0,0),G25<=DATE(2026,7,16)+TIME(10,0,0),ABS(H25-1)<0.001,AND(F25>=G24,F25-G24<=TIME(0,30,0))),"COMPLIANT","EXCEPTION") -> COMPLIANT
A26: 46216 | B26: PROD_PLAN | C26: Production cut plan | D26: Production training | E26: Amara Draganov | F26: 46217.292 | G26: 46217.417 | H26: =ROUND((G26-F26)*24,2) -> 3 | J26: Cut plan | K26: NO QUALIFIED BACKUP — GM ESCALATION | L26: =IF(AND(F26>=DATE(2026,7,14)+TIME(7,0,0),G26<=DATE(2026,7,14)+TIME(10,0,0),ABS(H26-3)<0.001,TRUE()),"COMPLIANT","EXCEPTION") -> COMPLIANT
A27: 46216 | B27: PROD_DEMO | C27: Closing-crew demonstration | D27: Production training | E27: Amara Draganov | F27: 46217.417 | G27: 46217.458 | H27: =ROUND((G27-F27)*24,2) -> 1 | I27: PROD_PLAN | J27: Crew demonstration acknowledgment | K27: NO QUALIFIED BACKUP — GM ESCALATION | L27: =IF(AND(F27>=DATE(2026,7,14)+TIME(10,0,0),G27<=DATE(2026,7,14)+TIME(11,0,0),ABS(H27-1)<0.001,AND(F27>=G26,F27-G26<=TIME(0,30,0))),"COMPLIANT","EXCEPTION") -> COMPLIANT
A28: 46216 | B28: PROD_RECORD | C28: Competency record | D28: Production training | E28: Amara Draganov | F28: 46217.458 | G28: 46217.5 | H28: =ROUND((G28-F28)*24,2) -> 1 | I28: PROD_DEMO | J28: Competency record | K28: NO QUALIFIED BACKUP — GM ESCALATION | L28: =IF(AND(F28>=DATE(2026,7,14)+TIME(11,0,0),G28<=DATE(2026,7,14)+TIME(12,0,0),ABS(H28-1)<0.001,AND(F28>=G27,F28-G27<=TIME(0,30,0))),"COMPLIANT","EXCEPTION") -> COMPLIANT
A29: 46216 | B29: INV_COUNT | C29: Cycle count | D29: Inventory | E29: Yusuf Gasparyan | F29: 46218.292 | G29: 46218.417 | H29: =ROUND((G29-F29)*24,2) -> 3 | J29: Count sheet | K29: Marisol Reyes | L29: =IF(AND(F29>=DATE(2026,7,15)+TIME(7,0,0),G29<=DATE(2026,7,15)+TIME(10,0,0),ABS(H29-3)<0.001,TRUE()),"COMPLIANT","EXCEPTION") -> COMPLIANT
A30: 46216 | B30: INV_VARIANCE | C30: Variance review | D30: Inventory | E30: Yusuf Gasparyan | F30: 46218.417 | G30: 46218.5 | H30: =ROUND((G30-F30)*24,2) -> 2 | I30: INV_COUNT | J30: Variance log | K30: Marisol Reyes | L30: =IF(AND(F30>=DATE(2026,7,15)+TIME(10,0,0),G30<=DATE(2026,7,15)+TIME(12,0,0),ABS(H30-2)<0.001,AND(F30>=G29,F30-G29<=TIME(0,30,0))),"COMPLIANT","EXCEPTION") -> COMPLIANT
A31: 46216 | B31: INV_SHRINK | C31: Shrink brief | D31: Inventory | E31: Yusuf Gasparyan | F31: 46218.5 | G31: 46218.542 | H31: =ROUND((G31-F31)*24,2) -> 1 | I31: INV_VARIANCE | J31: Shrink brief acknowledgment | K31: Marisol Reyes | L31: =IF(AND(F31>=DATE(2026,7,15)+TIME(12,0,0),G31<=DATE(2026,7,15)+TIME(13,0,0),ABS(H31-1)<0.001,AND(F31>=G30,F31-G30<=TIME(0,30,0))),"COMPLIANT","EXCEPTION") -> COMPLIANT
A32: 46216 | B32: SAN_VERIFY | C32: Sanitation verification | D32: Sanitation | E32: Emeric Novak | F32: 46220.625 | G32: 46220.708 | H32: =ROUND((G32-F32)*24,2) -> 2 | J32: Sanitation verification log | K32: NO QUALIFIED BACKUP — GM ESCALATION | L32: =IF(AND(F32>=DATE(2026,7,17)+TIME(15,0,0),G32<=DATE(2026,7,17)+TIME(17,0,0),ABS(H32-2)<0.001,TRUE()),"COMPLIANT","EXCEPTION") -> COMPLIANT
A33: 46223 | B33: ORD_FORECAST | C33: Demand forecast | D33: Ordering | E33: Marisol Reyes | F33: 46223.333 | G33: 46223.417 | H33: =ROUND((G33-F33)*24,2) -> 2 | J33: Forecast workbook | K33: Amara Draganov | L33: =IF(AND(F33>=DATE(2026,7,20)+TIME(8,0,0),G33<=DATE(2026,7,20)+TIME(10,0,0),ABS(H33-2)<0.001,TRUE()),"COMPLIANT","EXCEPTION") -> COMPLIANT
A34: 46223 | B34: ORD_DRAFT | C34: Purchase-order draft | D34: Ordering | E34: Marisol Reyes | F34: 46223.417 | G34: 46223.542 | H34: =ROUND((G34-F34)*24,2) -> 3 | I34: ORD_FORECAST | J34: Draft PO | K34: Amara Draganov | L34: =IF(AND(F34>=DATE(2026,7,20)+TIME(10,0,0),G34<=DATE(2026,7,20)+TIME(13,0,0),ABS(H34-3)<0.001,AND(F34>=G33,F34-G33<=TIME(0,30,0))),"COMPLIANT","EXCEPTION") -> COMPLIANT
A35: 46223 | B35: ORD_HACCP | C35: HACCP order review | D35: Ordering | E35: Emeric Novak | F35: 46223.542 | G35: 46223.583 | H35: =ROUND((G35-F35)*24,2) -> 1 | I35: ORD_DRAFT | J35: HACCP initials | K35: NO QUALIFIED BACKUP — GM ESCALATION | L35: =IF(AND(F35>=DATE(2026,7,20)+TIME(13,0,0),G35<=DATE(2026,7,20)+TIME(14,0,0),ABS(H35-1)<0.001,AND(F35>=G34,F35-G34<=TIME(0,30,0))),"COMPLIANT","EXCEPTION") -> COMPLIANT
A36: 46223 | B36: ORD_RELEASE | C36: Vendor order release | D36: Ordering | E36: Marisol Reyes | F36: 46223.583 | G36: 46223.625 | H36: =ROUND((G36-F36)*24,2) -> 1 | I36: ORD_HACCP | J36: Vendor release confirmation | K36: NO QUALIFIED BACKUP — GM ESCALATION | L36: =IF(AND(F36>=DATE(2026,7,20)+TIME(14,0,0),G36<=DATE(2026,7,20)+TIME(15,0,0),ABS(H36-1)<0.001,AND(F36>=G35,F36-G35<=TIME(0,30,0))),"COMPLIANT","EXCEPTION") -> COMPLIANT
A37: 46223 | B37: RCV_VERIFY | C37: Delivery verification | D37: Receiving | E37: Yusuf Gasparyan | F37: 46226.25 | G37: 46226.333 | H37: =ROUND((G37-F37)*24,2) -> 2 | J37: Receiving log | K37: Emeric Novak | L37: =IF(AND(F37>=DATE(2026,7,23)+TIME(6,0,0),G37<=DATE(2026,7,23)+TIME(8,0,0),ABS(H37-2)<0.001,TRUE()),"COMPLIANT","EXCEPTION") -> COMPLIANT
A38: 46223 | B38: RCV_DISPOSITION | C38: HACCP disposition | D38: Receiving | E38: Emeric Novak | F38: 46226.333 | G38: 46226.375 | H38: =ROUND((G38-F38)*24,2) -> 1 | I38: RCV_VERIFY | J38: Disposition entry | K38: NO QUALIFIED BACKUP — GM ESCALATION | L38: =IF(AND(F38>=DATE(2026,7,23)+TIME(8,0,0),G38<=DATE(2026,7,23)+TIME(9,0,0),ABS(H38-1)<0.001,AND(F38>=G37,F38-G37<=TIME(0,30,0))),"COMPLIANT","EXCEPTION") -> COMPLIANT
A39: 46223 | B39: RCV_TRACE | C39: Lot traceability closeout | D39: Receiving | E39: Emeric Novak | F39: 46226.375 | G39: 46226.417 | H39: =ROUND((G39-F39)*24,2) -> 1 | I39: RCV_DISPOSITION | J39: Lot traceability closeout | K39: NO QUALIFIED BACKUP — GM ESCALATION | L39: =IF(AND(F39>=DATE(2026,7,23)+TIME(9,0,0),G39<=DATE(2026,7,23)+TIME(10,0,0),ABS(H39-1)<0.001,AND(F39>=G38,F39-G38<=TIME(0,30,0))),"COMPLIANT","EXCEPTION") -> COMPLIANT
A40: 46223 | B40: PROD_PLAN | C40: Production cut plan | D40: Production training | E40: Amara Draganov | F40: 46224.292 | G40: 46224.417 | H40: =ROUND((G40-F40)*24,2) -> 3 | J40: Cut plan | K40: NO QUALIFIED BACKUP — GM ESCALATION | L40: =IF(AND(F40>=DATE(2026,7,21)+TIME(7,0,0),G40<=DATE(2026,7,21)+TIME(10,0,0),ABS(H40-3)<0.001,TRUE()),"COMPLIANT","EXCEPTION") -> COMPLIANT
A41: 46223 | B41: PROD_DEMO | C41: Closing-crew demonstration | D41: Production training | E41: Amara Draganov | F41: 46224.417 | G41: 46224.458 | H41: =ROUND((G41-F41)*24,2) -> 1 | I41: PROD_PLAN | J41: Crew demonstration acknowledgment | K41: NO QUALIFIED BACKUP — GM ESCALATION | L41: =IF(AND(F41>=DATE(2026,7,21)+TIME(10,0,0),G41<=DATE(2026,7,21)+TIME(11,0,0),ABS(H41-1)<0.001,AND(F41>=G40,F41-G40<=TIME(0,30,0))),"COMPLIANT","EXCEPTION") -> COMPLIANT
...

Sheet Weekly Controls
A1: Weekly Hours by Owner and compliance controls
A2: Formula controls recalculate from Duty Schedule; capacities from current people extract.
A4: Operational Week | B4: Owner | C4: Weekly Hours by Owner | D4: Interim cap | E4: Hours Status | F4: Timing Status | G4: Weekly Control
A5: 46209 | B5: Emeric Novak | C5: =ROUND(SUMIFS('Duty Schedule'!$H$5:$H$200,'Duty Schedule'!$A$5:$A$200,A5,'Duty Schedule'!$E$5:$E$200,B5),2) -> 5 | D5: 5 | E5: =IF(C5<=D5,"COMPLIANT","EXCEPTION") -> COMPLIANT | F5: =IF(COUNTIFS('Duty Schedule'!$A$5:$A$200,A5,'Duty Schedule'!$E$5:$E$200,B5,'Duty Schedule'!$L$5:$L$200,"EXCEPTION")=0,"COMPLIANT","EXCEPTION") -> COMPLIANT | G5: =IF(AND(E5="COMPLIANT",F5="COMPLIANT"),"COMPLIANT","EXCEPTION") -> COMPLIANT
A6: 46209 | B6: Marisol Reyes | C6: =ROUND(SUMIFS('Duty Schedule'!$H$5:$H$200,'Duty Schedule'!$A$5:$A$200,A6,'Duty Schedule'!$E$5:$E$200,B6),2) -> 6 | D6: 7 | E6: =IF(C6<=D6,"COMPLIANT","EXCEPTION") -> COMPLIANT | F6: =IF(COUNTIFS('Duty Schedule'!$A$5:$A$200,A6,'Duty Schedule'!$E$5:$E$200,B6,'Duty Schedule'!$L$5:$L$200,"EXCEPTION")=0,"COMPLIANT","EXCEPTION") -> COMPLIANT | G6: =IF(AND(E6="COMPLIANT",F6="COMPLIANT"),"COMPLIANT","EXCEPTION") -> COMPLIANT
A7: 46209 | B7: Amara Draganov | C7: =ROUND(SUMIFS('Duty Schedule'!$H$5:$H$200,'Duty Schedule'!$A$5:$A$200,A7,'Duty Schedule'!$E$5:$E$200,B7),2) -> 5 | D7: 6 | E7: =IF(C7<=D7,"COMPLIANT","EXCEPTION") -> COMPLIANT | F7: =IF(COUNTIFS('Duty Schedule'!$A$5:$A$200,A7,'Duty Schedule'!$E$5:$E$200,B7,'Duty Schedule'!$L$5:$L$200,"EXCEPTION")=0,"COMPLIANT","EXCEPTION") -> COMPLIANT | G7: =IF(AND(E7="COMPLIANT",F7="COMPLIANT"),"COMPLIANT","EXCEPTION") -> COMPLIANT
A8: 46209 | B8: Yusuf Gasparyan | C8: =ROUND(SUMIFS('Duty Schedule'!$H$5:$H$200,'Duty Schedule'!$A$5:$A$200,A8,'Duty Schedule'!$E$5:$E$200,B8),2) -> 8 | D8: 8 | E8: =IF(C8<=D8,"COMPLIANT","EXCEPTION") -> COMPLIANT | F8: =IF(COUNTIFS('Duty Schedule'!$A$5:$A$200,A8,'Duty Schedule'!$E$5:$E$200,B8,'Duty Schedule'!$L$5:$L$200,"EXCEPTION")=0,"COMPLIANT","EXCEPTION") -> COMPLIANT | G8: =IF(AND(E8="COMPLIANT",F8="COMPLIANT"),"COMPLIANT","EXCEPTION") -> COMPLIANT
A9: 46216 | B9: Emeric Novak | C9: =ROUND(SUMIFS('Duty Schedule'!$H$5:$H$200,'Duty Schedule'!$A$5:$A$200,A9,'Duty Schedule'!$E$5:$E$200,B9),2) -> 5 | D9: 5 | E9: =IF(C9<=D9,"COMPLIANT","EXCEPTION") -> COMPLIANT | F9: =IF(COUNTIFS('Duty Schedule'!$A$5:$A$200,A9,'Duty Schedule'!$E$5:$E$200,B9,'Duty Schedule'!$L$5:$L$200,"EXCEPTION")=0,"COMPLIANT","EXCEPTION") -> COMPLIANT | G9: =IF(AND(E9="COMPLIANT",F9="COMPLIANT"),"COMPLIANT","EXCEPTION") -> COMPLIANT
A10: 46216 | B10: Marisol Reyes | C10: =ROUND(SUMIFS('Duty Schedule'!$H$5:$H$200,'Duty Schedule'!$A$5:$A$200,A10,'Duty Schedule'!$E$5:$E$200,B10),2) -> 6 | D10: 7 | E10: =IF(C10<=D10,"COMPLIANT","EXCEPTION") -> COMPLIANT | F10: =IF(COUNTIFS('Duty Schedule'!$A$5:$A$200,A10,'Duty Schedule'!$E$5:$E$200,B10,'Duty Schedule'!$L$5:$L$200,"EXCEPTION")=0,"COMPLIANT","EXCEPTION") -> COMPLIANT | G10: =IF(AND(E10="COMPLIANT",F10="COMPLIANT"),"COMPLIANT","EXCEPTION") -> COMPLIANT
A11: 46216 | B11: Amara Draganov | C11: =ROUND(SUMIFS('Duty Schedule'!$H$5:$H$200,'Duty Schedule'!$A$5:$A$200,A11,'Duty Schedule'!$E$5:$E$200,B11),2) -> 5 | D11: 6 | E11: =IF(C11<=D11,"COMPLIANT","EXCEPTION") -> COMPLIANT | F11: =IF(COUNTIFS('Duty Schedule'!$A$5:$A$200,A11,'Duty Schedule'!$E$5:$E$200,B11,'Duty Schedule'!$L$5:$L$200,"EXCEPTION")=0,"COMPLIANT","EXCEPTION") -> COMPLIANT | G11: =IF(AND(E11="COMPLIANT",F11="COMPLIANT"),"COMPLIANT","EXCEPTION") -> COMPLIANT
A12: 46216 | B12: Yusuf Gasparyan | C12: =ROUND(SUMIFS('Duty Schedule'!$H$5:$H$200,'Duty Schedule'!$A$5:$A$200,A12,'Duty Schedule'!$E$5:$E$200,B12),2) -> 8 | D12: 8 | E12: =IF(C12<=D12,"COMPLIANT","EXCEPTION") -> COMPLIANT | F12: =IF(COUNTIFS('Duty Schedule'!$A$5:$A$200,A12,'Duty Schedule'!$E$5:$E$200,B12,'Duty Schedule'!$L$5:$L$200,"EXCEPTION")=0,"COMPLIANT","EXCEPTION") -> COMPLIANT | G12: =IF(AND(E12="COMPLIANT",F12="COMPLIANT"),"COMPLIANT","EXCEPTION") -> COMPLIANT
A13: 46223 | B13: Emeric Novak | C13: =ROUND(SUMIFS('Duty Schedule'!$H$5:$H$200,'Duty Schedule'!$A$5:$A$200,A13,'Duty Schedule'!$E$5:$E$200,B13),2) -> 5 | D13: 5 | E13: =IF(C13<=D13,"COMPLIANT","EXCEPTION") -> COMPLIANT | F13: =IF(COUNTIFS('Duty Schedule'!$A$5:$A$200,A13,'Duty Schedule'!$E$5:$E$200,B13,'Duty Schedule'!$L$5:$L$200,"EXCEPTION")=0,"COMPLIANT","EXCEPTION") -> COMPLIANT | G13: =IF(AND(E13="COMPLIANT",F13="COMPLIANT"),"COMPLIANT","EXCEPTION") -> COMPLIANT
A14: 46223 | B14: Marisol Reyes | C14: =ROUND(SUMIFS('Duty Schedule'!$H$5:$H$200,'Duty Schedule'!$A$5:$A$200,A14,'Duty Schedule'!$E$5:$E$200,B14),2) -> 6 | D14: 7 | E14: =IF(C14<=D14,"COMPLIANT","EXCEPTION") -> COMPLIANT | F14: =IF(COUNTIFS('Duty Schedule'!$A$5:$A$200,A14,'Duty Schedule'!$E$5:$E$200,B14,'Duty Schedule'!$L$5:$L$200,"EXCEPTION")=0,"COMPLIANT","EXCEPTION") -> COMPLIANT | G14: =IF(AND(E14="COMPLIANT",F14="COMPLIANT"),"COMPLIANT","EXCEPTION") -> COMPLIANT
A15: 46223 | B15: Amara Draganov | C15: =ROUND(SUMIFS('Duty Schedule'!$H$5:$H$200,'Duty Schedule'!$A$5:$A$200,A15,'Duty Schedule'!$E$5:$E$200,B15),2) -> 5 | D15: 6 | E15: =IF(C15<=D15,"COMPLIANT","EXCEPTION") -> COMPLIANT | F15: =IF(COUNTIFS('Duty Schedule'!$A$5:$A$200,A15,'Duty Schedule'!$E$5:$E$200,B15,'Duty Schedule'!$L$5:$L$200,"EXCEPTION")=0,"COMPLIANT","EXCEPTION") -> COMPLIANT | G15: =IF(AND(E15="COMPLIANT",F15="COMPLIANT"),"COMPLIANT","EXCEPTION") -> COMPLIANT
A16: 46223 | B16: Yusuf Gasparyan | C16: =ROUND(SUMIFS('Duty Schedule'!$H$5:$H$200,'Duty Schedule'!$A$5:$A$200,A16,'Duty Schedule'!$E$5:$E$200,B16),2) -> 8 | D16: 8 | E16: =IF(C16<=D16,"COMPLIANT","EXCEPTION") -> COMPLIANT | F16: =IF(COUNTIFS('Duty Schedule'!$A$5:$A$200,A16,'Duty Schedule'!$E$5:$E$200,B16,'Duty Schedule'!$L$5:$L$200,"EXCEPTION")=0,"COMPLIANT","EXCEPTION") -> COMPLIANT | G16: =IF(AND(E16="COMPLIANT",F16="COMPLIANT"),"COMPLIANT","EXCEPTION") -> COMPLIANT
... A60: 46300 | B60: Yusuf Gasparyan | C60: =ROUND(SUMIFS('Duty Schedule'!$H$5:$H$200,'Duty Schedule'!$A$5:$A$200,A60,'Duty Schedule'!$E$5:$E$200,B60),2) -> 8 | D60: 8 | E60: =IF(C60<=D60,"COMPLIANT","EXCEPTION") -> COMPLIANT | F60: =IF(COUNTIFS('Duty Schedule'!$A$5:$A$200,A60,'Duty Schedule'!$E$5:$E$200,B60,'Duty Schedule'!$L$5:$L$200,"EXCEPTION")=0,"COMPLIANT","EXCEPTION") -> COMPLIANT | G60: =IF(AND(E60="COMPLIANT",F60="COMPLIANT"),"COMPLIANT","EXCEPTION") -> COMPLIANT
